Workbook

Sheet README
A1: Bowmaster — DPS Calculator: How to Use This Workbook
A3: How to use this workbook
A4: Only edit the yellow-highlighted cells on the Inputs sheet — every other sheet is computed from those values and will be overwritten if you rebuild the workbook.
A5: Summary shows Total DPS, a Per-Skill DPS Breakdown (damage-dealing skills only — buffs/passives that never deal their own damage are omitted), and a Marginal DPS & Stat Value table showing the DPS gained per +1 of each stat.
A6: Sensitivity has the full detail behind that marginal-value table — one self-contained block per stat, showing exactly how bumping that stat by +1 changes every downstream number.
A7: CubeData/PotentialCubes model your current gear's Potential Cube lines and drive cube-reroll expected-value decisions. For the full standalone Potential Cube EV calculator (exact optimal-stopping math, works from this workbook alone), see tools/potential_cubes_ev.py in the project repo.
A9: Design decisions & assumptions
A10: Critical Shot, Archer Mastery, Bow Acceleration, Physical Training, Bow Mastery, Extreme Archery/Reckless Hunt: Bow's own Final Damage component, Armor Break, Bow Expert, and Soul Arrow: Bow's own DEX/Attack bonuses are always-on passives assumed to already be reflected in your own Inputs stat entries — only their Sensitivity marginal delta (what changes if their mastery level differs from what you assumed) is modeled live, matching this project's established convention (see build_shadower_workbook.py's own README). Soul Arrow: Bow's flat DEX bonus specifically has NO Sensitivity delta row (no percentage-bucket exists for a flat sub-stat bonus in this template) — just assume your own Inputs!Flat DEX already includes it.
A11: Concentration ("Focused Fury" in the Aug 13 patch notes — same skill, wiki and Nexon's own English patch notes use different names) and Mortal Blow are both modeled at steady-state maximum stacks/uptime once unlocked, not as exact stack-timer/hit-counter state machines — the same simplification tier as every other accumulating-stack mechanic in this project.
A12: Arrow Platter's per-level damage curve is confirmed via idle.maplestorywiki.net/w/Quiver_Flow (the skill's real curve lives under an old/alternate page name — its current-name page, .../w/Arrow_Platter, is a wiki content bug rendering Wind Arrow II's data instead). Its real cooldown (40s, not 60s) came from that same page's infobox.
A13: Quiver Cartridge's Attack-Speed-scaled tick rate uses the English wiki wording ('up to 0.4 times based on Attack Speed') over the Korean text's disagreeing 'up to 2x', per user direction — tick multiplier = 1+0.4*(TotalAS%/150), same 150%-AS cap as Actions Per Second. Flash Mirage's own Attack-Speed-scaled activation-chance text is separately still too vague/self-contradictory (English vs. Korean disagree) to model precisely — it uses a flat, non-AS-scaled proc rate instead, flagged as a simplification.
A14: Final Attack: Bow + Advanced Final Attack are folded into Arrow Stream's own coefficient as a steady-state average addition, not modeled as an independent damage pipeline with its own separate Final Damage chain.
... A17: Not modeled (out of scope): all forms of crowd control, Accuracy, Evasion, Defense reduction/penetration debuffs on the character's own Defense stat, movement speed, Illusion Step's own Evasion/damage-taken-reduction phase, and Companion Summoning Time.

Sheet Inputs
A1: Bowmaster — DPS Calculator Inputs | N1: (none)
C2: Chapter Boss | D2: Breakthrough | E2: PvP | F2: EXP Dungeon | G2: Equipment Dungeon | H2: Weapon Dungeon | I2: Enhancement Dungeon | J2: Hero Dungeon | K2: World Boss | L2: Chapter Hunt | N2: Charm of the Undead
A3: Character Level | B3: 200 | N3: Pig's Ribbon
A4: Content Type | B4: Chapter Boss | N4: Shamaness Marble
A5: Chapter-Stage — 'chapter-substage' (e.g. '28-9') for Breakthrough/Chapter Hunt, just the chapter number for Chapter Boss, or just the stage number for Weapon/Equipment/Enhancement/EXP/Hero Dungeon. Not applicable to World Boss/PvP. | B5: =INDEX($C$5:$L$5,MATCH($B$4,$C$2:$L$2,0)) | C5: 28 | D5: 28-9 | F5: 80 | G5: 80 | H5: 80 | I5: 80 | J5: 80 | L5: 28-9 | N5: The Contract of Darkness
A6: Flat ATTACK | B6: =INDEX($C$6:$L$6,MATCH($B$4,$C$2:$L$2,0)) | C6: 10000 | D6: 10000 | E6: 10000 | F6: 10000 | G6: 10000 | H6: 10000 | I6: 10000 | J6: 10000 | K6: 10000 | L6: 10000 | N6: Rainbow-colored Snail Shell
A7: ATTACK % | B7: =INDEX($C$7:$L$7,MATCH($B$4,$C$2:$L$2,0)) | C7: 0 | D7: 0 | E7: 0 | F7: 0 | G7: 0 | H7: 0 | I7: 0 | J7: 0 | K7: 0 | L7: 0 | N7: Hexagon Necklace
A8: Defense (your own DEF stat; PvP assumes the opponent has the same Defense as you) | B8: =INDEX($C$8:$L$8,MATCH($B$4,$C$2:$L$2,0)) | C8: 0 | D8: 0 | E8: 0 | F8: 0 | G8: 0 | H8: 0 | I8: 0 | J8: 0 | K8: 0 | L8: 0 | N8: Arwen's Glass Shoes
A9: CRIT_RATE % | B9: =INDEX($C$9:$L$9,MATCH($B$4,$C$2:$L$2,0)) | C9: 0 | D9: 0 | E9: 0 | F9: 0 | G9: 0 | H9: 0 | I9: 0 | J9: 0 | K9: 0 | L9: 0 | N9: Mushmom's Cap
A10: CRIT_DAMAGE % | B10: =INDEX($C$10:$L$10,MATCH($B$4,$C$2:$L$2,0)) | C10: 0 | D10: 0 | E10: 0 | F10: 0 | G10: 0 | H10: 0 | I10: 0 | J10: 0 | K10: 0 | L10: 0 | N10: Clear Spring Water
A11: ATTACK_SPEED % (base, excludes Archer Mastery/Bow Acceleration) | B11: =INDEX($C$11:$L$11,MATCH($B$4,$C$2:$L$2,0)) | C11: 0 | D11: 0 | E11: 0 | F11: 0 | G11: 0 | H11: 0 | I11: 0 | J11: 0 | K11: 0 | L11: 0 | N11: Athena Pierce's Old Gloves
A12: Flat DEX (include Soul Arrow: Bow's own bonus if unlocked) | B12: =INDEX($C$12:$L$12,MATCH($B$4,$C$2:$L$2,0)) | C12: 0 | D12: 0 | E12: 0 | F12: 0 | G12: 0 | H12: 0 | I12: 0 | J12: 0 | K12: 0 | L12: 0 | N12: Zakum's Stone Piece
A13: DEX % | B13: =INDEX($C$13:$L$13,MATCH($B$4,$C$2:$L$2,0)) | C13: 0 | D13: 0 | E13: 0 | F13: 0 | G13: 0 | H13: 0 | I13: 0 | J13: 0 | K13: 0 | L13: 0 | N13: Horntail's Scale
A14: STR | B14: =INDEX($C$14:$L$14,MATCH($B$4,$C$2:$L$2,0)) | C14: 0 | D14: 0 | E14: 0 | F14: 0 | G14: 0 | H14: 0 | I14: 0 | J14: 0 | K14: 0 | L14: 0 | N14: Pink Bean's Giant Rib
A15: DAMAGE % | B15: =INDEX($C$15:$L$15,MATCH($B$4,$C$2:$L$2,0)) | C15: 0 | D15: 0 | E15: 0 | F15: 0 | G15: 0 | H15: 0 | I15: 0 | J15: 0 | K15: 0 | L15: 0 | N15: Chalice
A16: DAMAGE_AMP % | B16: =INDEX($C$16:$L$16,MATCH($B$4,$C$2:$L$2,0)) | C16: 0 | D16: 0 | E16: 0 | F16: 0 | G16: 0 | H16: 0 | I16: 0 | J16: 0 | K16: 0 | L16: 0 | N16: Old Music Box
A17: BASIC_ATTACK_DAMAGE % | B17: =INDEX($C$17:$L$17,MATCH($B$4,$C$2:$L$2,0)) | C17: 0 | D17: 0 | E17: 0 | F17: 0 | G17: 0 | H17: 0 | I17: 0 | J17: 0 | K17: 0 | L17: 0 | N17: Silver Pendant
A18: SKILL_DAMAGE % | B18: =INDEX($C$18:$L$18,MATCH($B$4,$C$2:$L$2,0)) | C18: 0 | D18: 0 | E18: 0 | F18: 0 | G18: 0 | H18: 0 | I18: 0 | J18: 0 | K18: 0 | L18: 0 | N18: Star Rock
A19: DEF_PEN % | B19: =INDEX($C$19:$L$19,MATCH($B$4,$C$2:$L$2,0)) | C19: 0 | D19: 0 | E19: 0 | F19: 0 | G19: 0 | H19: 0 | I19: 0 | J19: 0 | K19: 0 | L19: 0 | N19: Book of Ancient
A20: BOSS_DAMAGE % | B20: =INDEX($C$20:$L$20,MATCH($B$4,$C$2:$L$2,0)) | C20: 0 | D20: 0 | E20: 0 | F20: 0 | G20: 0 | H20: 0 | I20: 0 | J20: 0 | K20: 0 | L20: 0 | N20: Lunar Dew
A21: NORMAL_DAMAGE % | B21: =INDEX($C$21:$L$21,MATCH($B$4,$C$2:$L$2,0)) | C21: 0 | D21: 0 | E21: 0 | F21: 0 | G21: 0 | H21: 0 | I21: 0 | J21: 0 | K21: 0 | L21: 0 | N21: Fire Flower
A22: MIN_DAMAGE % | B22: =INDEX($C$22:$L$22,MATCH($B$4,$C$2:$L$2,0)) | C22: 100 | D22: 100 | E22: 100 | F22: 100 | G22: 100 | H22: 100 | I22: 100 | J22: 100 | K22: 100 | L22: 100 | N22: Soul Contract
A23: MAX_DAMAGE % | B23: =INDEX($C$23:$L$23,MATCH($B$4,$C$2:$L$2,0)) | C23: 100 | D23: 100 | E23: 100 | F23: 100 | G23: 100 | H23: 100 | I23: 100 | J23: 100 | K23: 100 | L23: 100 | N23: Lit Lamp
A24: FINAL_DAMAGE % (base) | B24: =INDEX($C$24:$L$24,MATCH($B$4,$C$2:$L$2,0)) | C24: 0 | D24: 0 | E24: 0 | F24: 0 | G24: 0 | H24: 0 | I24: 0 | J24: 0 | K24: 0 | L24: 0 | N24: Soul Pouch
A25: Skill Level Bonus — 1st Job | B25: =INDEX($C$25:$L$25,MATCH($B$4,$C$2:$L$2,0)) | C25: 0 | D25: 0 | E25: 0 | F25: 0 | G25: 0 | H25: 0 | I25: 0 | J25: 0 | K25: 0 | L25: 0 | N25: Ancient Text Piece
A26: Skill Level Bonus — 2nd Job | B26: =INDEX($C$26:$L$26,MATCH($B$4,$C$2:$L$2,0)) | C26: 0 | D26: 0 | E26: 0 | F26: 0 | G26: 0 | H26: 0 | I26: 0 | J26: 0 | K26: 0 | L26: 0 | N26: Icy Soul Rock
A27: Skill Level Bonus — 3rd Job | B27: =INDEX($C$27:$L$27,MATCH($B$4,$C$2:$L$2,0)) | C27: 0 | D27: 0 | E27: 0 | F27: 0 | G27: 0 | H27: 0 | I27: 0 | J27: 0 | K27: 0 | L27: 0 | N27: Flaming Lava
A28: Skill Level Bonus — 4th Job | B28: =INDEX($C$28:$L$28,MATCH($B$4,$C$2:$L$2,0)) | C28: 0 | D28: 0 | E28: 0 | F28: 0 | G28: 0 | H28: 0 | I28: 0 | J28: 0 | K28: 0 | L28: 0 | N28: Sayram's Necklace
A29: Skill Level Bonus — All Skills | B29: =INDEX($C$29:$L$29,MATCH($B$4,$C$2:$L$2,0)) | C29: 0 | D29: 0 | E29: 0 | F29: 0 | G29: 0 | H29: 0 | I29: 0 | J29: 0 | K29: 0 | L29: 0 | N29: Bottle of Emotion
N30: Peach Tree Herb Pouch
A31: Additional Bonuses | N31: Candle
A32: Skill Cooldown Decrease (seconds, only skills/buffs the character actively casts) | B32: =INDEX($C$32:$L$32,MATCH($B$4,$C$2:$L$2,0)) | C32: 0 | D32: 0 | E32: 0 | F32: 0 | G32: 0 | H32: 0 | I32: 0 | J32: 0 | K32: 0 | L32: 0 | N32: Alliance Badge
A33: Basic Attack Target Increase (flat, adds to the 6-target normal-monster base) | B33: =INDEX($C$33:$L$33,MATCH($B$4,$C$2:$L$2,0)) | C33: 1 | D33: 1 | E33: 1 | F33: 1 | G33: 1 | H33: 1 | I33: 1 | J33: 1 | K33: 1 | L33: 1 | N33: Horn Flute
A34: Buff Duration Increase % | B34: =INDEX($C$34:$L$34,MATCH($B$4,$C$2:$L$2,0)) | C34: 0 | D34: 0 | E34: 0 | F34: 0 | G34: 0 | H34: 0 | I34: 0 | J34: 0 | K34: 0 | L34: 0 | N34: Cursed Doll
A35: Companion Summoning Time Increase % (companions not modeled — always 0 DPS impact) | B35: =INDEX($C$35:$L$35,MATCH($B$4,$C$2:$L$2,0)) | C35: 0 | D35: 0 | E35: 0 | F35: 0 | G35: 0 | H35: 0 | I35: 0 | J35: 0 | K35: 0 | L35: 0 | N35: Reindeer's Spear
A36: Boss/Normal Emphasis (Breakthrough/Hero Dungeon only) | B36: =INDEX($C$36:$L$36,MATCH($B$4,$C$2:$L$2,0)) | D36: A Little More Normal | J36: A Little More Normal | N36: Secret Map
A37: Max Enemies Actually In Range (normal-monster content only; default 999 = uncapped) | B37: =INDEX($C$37:$L$37,MATCH($B$4,$C$2:$L$2,0)) | D37: 999 | F37: 999 | G37: 999 | J37: 999 | L37: 999 | N37: Ring of Cycles
A38: Monster Type (auto-computed from Content Type) — computed, do not edit | B38: =IF(Inputs!$B$4="PvP","pvp",IF(OR(Inputs!$B$4="Breakthrough",Inputs!$B$4="Hero Dungeon"),"breakthrough",IF(OR(Inputs!$B$4="EXP Dungeon",Inputs!$B$4="Equipment Dungeon",Inputs!$B$4="Chapter Hunt"),"normal","boss")))
A39: Chapter (parsed from Chapter-Stage) — computed, do not edit | B39: =IFERROR(IF(ISNUMBER(FIND("-",Inputs!$B$5)),VALUE(LEFT(Inputs!$B$5,FIND("-",Inputs!$B$5)-1)),VALUE(Inputs!$B$5)),28)
A40: Stage (parsed from Chapter-Stage) — computed, do not edit | B40: =IFERROR(IF(ISNUMBER(FIND("-",Inputs!$B$5)),VALUE(MID(Inputs!$B$5,FIND("-",Inputs!$B$5)+1,50)),VALUE(Inputs!$B$5)),9)
...

Sheet FactorTable
A1: Level | B1: F0 | C1: F1 | D1: F2 | E1: F3 | F1: F4 | G1: F5 | H1: F6 | I1: F7 | J1: F8 | K1: F9 | L1: F10 | M1: F11 | N1: F12 | O1: F13 | P1: F14 | Q1: F15 | R1: F16 | S1: F17 | T1: F18 | U1: F19 | V1: F20 | W1: F21 | X1: F22 | Y1: F23
A2: 1 | B2: 0 | C2: 1000 | D2: 1000 | E2: 1000 | F2: 1000 | G2: 1000 | H2: 1000 | I2: 1000 | J2: 1000 | K2: 1000 | L2: 1000 | M2: 1000 | N2: 1000 | O2: 1000 | P2: 1000 | Q2: 1000 | R2: 1000 | S2: 1000 | T2: 1000 | U2: 1000 | V2: 1000 | W2: 1000 | X2: 1000 | Y2: 1000
A3: 2 | B3: 0 | C3: 1015 | D3: 1020 | E3: 1030 | F3: 1040 | G3: 1050 | H3: 1060 | I3: 1070 | J3: 1020 | K3: 1020 | L3: 1020 | M3: 1000 | N3: 1010 | O3: 1020 | P3: 1030 | Q3: 1040 | R3: 1050 | S3: 1060 | T3: 1070 | U3: 1080 | V3: 1010 | W3: 1008 | X3: 1006 | Y3: 1100
A4: 3 | B4: 0 | C4: 1031 | D4: 1041 | E4: 1061 | F4: 1082 | G4: 1103 | H4: 1124 | I4: 1145 | J4: 1030 | K4: 1041 | L4: 1030 | M4: 1000 | N4: 1015 | O4: 1030 | P4: 1045 | Q4: 1060 | R4: 1075 | S4: 1090 | T4: 1105 | U4: 1120 | V4: 1020 | W4: 1012 | X4: 1009 | Y4: 1150
A5: 4 | B5: 0 | C5: 1047 | D5: 1062 | E5: 1093 | F5: 1126 | G5: 1159 | H5: 1192 | I5: 1226 | J5: 1040 | K5: 1062 | L5: 1040 | M5: 1000 | N5: 1020 | O5: 1040 | P5: 1060 | Q5: 1080 | R5: 1100 | S5: 1120 | T5: 1140 | U5: 1160 | V5: 1030 | W5: 1016 | X5: 1012 | Y5: 1200
A6: 5 | B6: 0 | C6: 1063 | D6: 1084 | E6: 1126 | F6: 1172 | G6: 1217 | H6: 1264 | I6: 1312 | J6: 1050 | K6: 1084 | L6: 1050 | M6: 1000 | N6: 1025 | O6: 1050 | P6: 1075 | Q6: 1100 | R6: 1125 | S6: 1150 | T6: 1175 | U6: 1200 | V6: 1040 | W6: 1020 | X6: 1015 | Y6: 1250
A7: 6 | B7: 0 | C7: 1079 | D7: 1106 | E7: 1160 | F7: 1219 | G7: 1278 | H7: 1340 | I7: 1404 | J7: 1060 | K7: 1106 | L7: 1060 | M7: 1000 | N7: 1030 | O7: 1060 | P7: 1090 | Q7: 1120 | R7: 1150 | S7: 1180 | T7: 1210 | U7: 1240 | V7: 1050 | W7: 1024 | X7: 1018 | Y7: 1300
A8: 7 | B8: 0 | C8: 1096 | D8: 1129 | E8: 1195 | F8: 1268 | G8: 1342 | H8: 1421 | I8: 1503 | J8: 1070 | K8: 1129 | L8: 1070 | M8: 1000 | N8: 1035 | O8: 1070 | P8: 1105 | Q8: 1140 | R8: 1175 | S8: 1210 | T8: 1245 | U8: 1280 | V8: 1060 | W8: 1028 | X8: 1021 | Y8: 1350
A9: 8 | B9: 0 | C9: 1113 | D9: 1152 | E9: 1231 | F9: 1319 | G9: 1410 | H9: 1507 | I9: 1609 | J9: 1080 | K9: 1152 | L9: 1080 | M9: 1000 | N9: 1040 | O9: 1080 | P9: 1120 | Q9: 1160 | R9: 1200 | S9: 1240 | T9: 1280 | U9: 1320 | V9: 1070 | W9: 1032 | X9: 1024 | Y9: 1400
A10: 9 | B10: 0 | C10: 1130 | D10: 1176 | E10: 1268 | F10: 1372 | G10: 1481 | H10: 1598 | I10: 1722 | J10: 1090 | K10: 1176 | L10: 1090 | M10: 1000 | N10: 1045 | O10: 1090 | P10: 1135 | Q10: 1180 | R10: 1225 | S10: 1270 | T10: 1315 | U10: 1360 | V10: 1080 | W10: 1036 | X10: 1027 | Y10: 1450
A11: 10 | B11: 0 | C11: 1147 | D11: 1200 | E11: 1307 | F11: 1427 | G11: 1556 | H11: 1694 | I11: 1843 | J11: 1100 | K11: 1200 | L11: 1100 | M11: 1000 | N11: 1050 | O11: 1100 | P11: 1150 | Q11: 1200 | R11: 1250 | S11: 1300 | T11: 1350 | U11: 1400 | V11: 1090 | W11: 1040 | X11: 1030 | Y11: 1500
A12: 11 | B12: 0 | C12: 1165 | D12: 1224 | E12: 1347 | F12: 1485 | G12: 1634 | H12: 1796 | I12: 1973 | J12: 1110 | K12: 1224 | L12: 1110 | M12: 1000 | N12: 1055 | O12: 1110 | P12: 1165 | Q12: 1220 | R12: 1275 | S12: 1330 | T12: 1385 | U12: 1440 | V12: 1100 | W12: 1044 | X12: 1033 | Y12: 1550
A13: 12 | B13: 0 | C13: 1183 | D13: 1249 | E13: 1388 | F13: 1545 | G13: 1716 | H13: 1904 | I13: 2112 | J13: 1120 | K13: 1249 | L13: 1120 | M13: 1000 | N13: 1060 | O13: 1120 | P13: 1180 | Q13: 1240 | R13: 1300 | S13: 1360 | T13: 1420 | U13: 1480 | V13: 1110 | W13: 1048 | X13: 1036 | Y13: 1600
... A301: 300 | B301: 0 | C301: 88573 | D301: 381637 | E301: 6991522 | F301: 125363453 | G301: 2185120762 | H301: 37157073039 | I301: 614631863830 | J301: 2000 | K301: 53326 | L301: 2500 | M301: 1100 | N301: 2500 | O301: 4000 | P301: 5500 | Q301: 7000 | R301: 8500 | S301: 10000 | T301: 11500 | U301: 13000 | V301: 7558 | W301: 2200 | X301: 1900 | Y301: 8800

Sheet Skills
A1: Key | B1: Name | C1: JobStep | D1: Cooldown(s) | E1: CostsActionSlot | F1: ActionsPerCast | G1: HitsPerCast | H1: ICD(s) | I1: ActiveWindow(s) | J1: ProcChance% | K1: RollsPerCast | L1: BaseDamage(tenths%) | M1: FactorIndex | N1: ScalesWithLevel | O1: SkillMasteryBonus% | P1: MasteryBossDamage% | Q1: MasteryNormalDamage% | R1: NormalMonsterTargets | S1: BuffTargetStat | T1: BuffDuration(s) | U1: MapleHeroBase(tenths%) | V1: MapleHeroFactorIndex | W1: Note
A2: ARROW_STREAM | B2: Arrow Stream | C2: 4 | E2: FALSE | F2: 1 | G2: =IF(Inputs!$B$3>=134,6,5) | H2: 0 | I2: 0 | J2: 100 | K2: 1 | L2: 2900 | M2: 21 | N2: TRUE | O2: =SUMPRODUCT((Inputs!$B$3>={98,104,113,118,126,130})*{10,1,1,1,1,1}) | P2: =SUMPRODUCT((Inputs!$B$3>={108,122})*{10,10}) | Q2: 0 | R2: =6+Inputs!$B$33 | T2: 0 | W2: 4th-job basic-attack effect (supersedes Wind Arrow/Wind Arrow II/Arrow Blow, confirmed identical wiki wording — 290% damage to 6 target(s) in front 5 time(s) — to every other class's own 4th-job basic attack). factorIndex 21, baseDamage 2900 tenths%. HitsPerCast = 5 (the wiki's own 'time(s)' figure), bumping to 6 once Mastery Lv.134 'Arrow Stream - Strike' unlocks — same pattern/level as Night Lord's own Showdown mastery. SkillMasteryBonus% is ONLY the real Arrow Stream - Damage mastery chain (98/104/113/118/126/130, cumulative +10/11/12/13/14/15%) — Final Attack: Bow's own contribution moved to its own FINAL_ATTACK_BOW row (see there for why). MasteryBossDamage% is the real 2-tier Arrow Stream - Boss Monster Damage chain (108, 122), each independently +10%, totaling +20% — this and the Damage mastery chain above were both caught missing entirely during the Marksman build's own shared-skill cross-check (Verification item 5) and fixed here.
A3: FINAL_ATTACK_BOW | B3: Final Attack: Bow | C3: 2 | D3: =1/Summary!$B$17 | E3: FALSE | F3: 1 | G3: 1 | H3: 0 | I3: 0 | J3: 25 | K3: 1 | L3: 350 | M3: 21 | N3: TRUE | O3: =SUMPRODUCT((Inputs!$B$3>={54})*{50}) | P3: 0 | Q3: 0 | R3: =6+Inputs!$B$33 | T3: 0 | W3: Previously folded into Arrow Stream's own coefficient as a steady-state average addition — split out into its own independent row per a Discord bug report/user direction, since Final Attack is affected by Skill Damage%, not Basic Attack Damage% (Arrow Stream's own bucket). Real proc: 25% chance 'when attacking' to deal 35%->49% additional damage (levels 1-100) to the same target(s) that attack just hit. Modeled as a real ProcChance%=25 tested against the character's own total attack-LINE rate (Cooldown(s) = 1/Summary!APS — one attack line per cast, across every active-slot skill, per user direction; earlier versions of this row incorrectly multiplied by Arrow Stream's own HitsPerCast, over-counting each of its 5-6 individual arrows as a separate attack line). factorIndex 21, baseDamage 350 tenths%. Mastery 'Final Attack - Damage' +50% at Lv.54 (RESOLVED this session via maplestoryidle.info/jobs.html — the wiki's own Mastery page had this at Lv.52, confirmed wrong by the new source). Its own Final Damage bonus (Advanced Final Attack, +500%->900% FD to Final Attack specifically) is a separate multiplicative term from ADVANCED_FINAL_ATTACK_HELPER (same shape as Quiver Cartridge/Enchanted Quiver or Flash Mirage/Flash Mirage II's own extra_fd_term pattern).
A4: ADVANCED_FINAL_ATTACK_HELPER | B4: Advanced Final Attack (helper) | C4: 4 | E4: FALSE | F4: 1 | G4: 1 | H4: 0 | I4: 0 | J4: 100 | K4: 1 | L4: 5000 | M4: 21 | N4: TRUE | O4: =SUMPRODUCT((Inputs!$B$3>={113})*{50}) | P4: 0 | Q4: 0 | R4: 0 | T4: 0 | W4: Helper row only — feeds FINAL_ATTACK_BOW's own K-column extra Final Damage term (Final Attack's own Final Damage bonus, not a global bucket). +500%->900% FD (levels 1-200). factorIndex 21, baseDamage 5000 tenths%. Mastery 'Advanced Final Attack - Enhance' +50% at Lv.113 (RESOLVED this session via maplestoryidle.info/jobs.html — the wiki's own Mastery page had this at Lv.111, confirmed wrong by the new source).
A5: COVERING_FIRE | B5: Covering Fire | C5: 1 | D5: 19 | E5: TRUE | F5: 1 | G5: 3 | H5: 0 | I5: 0 | J5: 100 | K5: 1 | L5: 2500 | M5: 12 | N5: TRUE | O5: =SUMPRODUCT((Inputs!$B$3>={39})*{50}) | P5: 0 | Q5: 0 | R5: 1 | T5: 0 | U5: 250 | V5: 0 | W5: Shared verbatim w/ Marksman (identical name AND numbers both classes, confirmed via the patch notes' own shared 'Covering Fire' entry). 250%->375% damage x3 hits (levels 1-100), 19s cooldown. factorIndex 12, baseDamage 2500 tenths%. Mastery Lv.39 'Covering Fire - Damage' +50% (real SkillMasteryBonus%). Patched: skill use range +~20% (not modeled). Maple Hero target — see MAPLE_HERO_RATIOS (biggest share, 4x Arrow Platter's own share).
A6: QUIVER_CARTRIDGE | B6: Quiver Cartridge | C6: 3 | D6: =1/(1+(Summary!$B$17-1)*4/15) | E6: FALSE | F6: 1 | G6: =3+IF(Inputs!$B$3>=107,3,0) | H6: 0 | I6: 0 | J6: 100 | K6: 1 | L6: 500 | M6: 21 | N6: TRUE | O6: 0 | P6: 0 | Q6: 200 | R6: =3+IF(Inputs!$B$3>=107,3,0) | T6: 0 | W6: Background periodic DoT, same shape as FP-Mage's Ignite (CostsActionSlot=False, 'always maintained'), but with a real AS-scaled tick rate per user direction to use the English wiki wording ('activation speed increases up to 0.4 times based on Attack Speed') over the self-contradictory Korean text ('up to 2x'). Modeled as: tick multiplier = 1+0.4*(TotalAS%/150), i.e. up to +40% faster ticking at the same 150%-AS cap already used by Summary!Actions Per Second (R_APS) — Cooldown(s) = 1/tick_multiplier, base 1s at 0% AS down to ~0.7143s at the 150% AS cap. PATCHED: base damage 22%->50% (curve rescaled 50/22=2.2727x before reverse-engineering — factorIndex 21, baseDamage 500 tenths% already reflects the patched value), targets 1->3, +3 more once Enchanted Quiver unlocks at Lv.107 (see ENCHANTED_QUIVER_HELPER). Flat +8% Attack (patch-added) assumed already reflected in your own Inputs — see SOUL_ARROW_BOW_ATK's own Note (same treatment, both are flat unconditional Attack% bonuses).
A7: ENCHANTED_QUIVER_HELPER | B7: Enchanted Quiver (helper) | C7: 4 | E7: FALSE | F7: 1 | G7: 1 | H7: 0 | I7: 0 | J7: 100 | K7: 1 | L7: 3000 | M7: 21 | N7: TRUE | O7: 0 | P7: 0 | Q7: 0 | R7: 0 | T7: 0 | W7: Helper row only — feeds Quiver Cartridge's own K-column extra Final Damage term (see QUIVER_CARTRIDGE's own targets formula for the +3 targets side). PATCHED: FD 500%->300% (curve rescaled 300/500=0.6x before reverse-engineering — factorIndex 21, baseDamage 3000 tenths% already reflects the patched value).
A8: PHOENIX | B8: Phoenix | C8: 3 | D8: =IF(Inputs!$B$3>=102,60*0.6,60) | E8: TRUE | F8: 1 | G8: 1 | H8: =IF(Inputs!$B$3>=80,3*0.7,3) | I8: =IF(Inputs!$B$3>=102,30,20) | J8: 100 | K8: 1 | L8: 6000 | M8: 12 | N8: TRUE | O8: 0 | P8: 0 | Q8: =IF(Inputs!$B$3>=92,100,0) | R8: =5+IF(Inputs!$B$3>=76,3,0) | T8: 0 | U8: 250 | V8: 0 | W8: Summons Phoenix, attacks nearby targets on a periodic tick (EffectiveHits = HitsPerCast x (ActiveWindow/ICD), same mechanism as FP-Mage/ILM's own summon rows). PATCHED: duration 20s->30s (target detection range +~25% not modeled), cooldown 60s (Mastery Lv.102 'Phoenix - Reuse' -50%->-40% per the patch, baked into the Cooldown(s) formula). factorIndex 12, baseDamage 6000 tenths% (600%->1200%, levels 1-200) — not itself patched (only duration/detection range changed). Mastery Lv.76 '+3 targets', Lv.80 '-30% strike interval' (baked into ICD(s)), Lv.92 '+100%p Normal Monster Damage' (own MasteryNormalDamage%, scoped to this row only — not the global bucket). Maple Hero target — see MAPLE_HERO_RATIOS.
A9: ARROW_PLATTER | B9: Arrow Platter | C9: 3 | D9: 40 | E9: TRUE | F9: 1 | G9: 1 | H9: 0.3 | I9: 60 | J9: 100 | K9: 1 | L9: 500 | M9: 12 | N9: TRUE | O9: 0 | P9: 0 | Q9: 200 | R9: =3+IF(Inputs!$B$3>=98,1,0) | T9: 0 | U9: 250 | V9: 0 | W9: RESOLVED this session — idle.maplestorywiki.net/w/Arrow_Platter is a confirmed wiki content bug (renders Wind Arrow II's data under Arrow Platter's own infobox), but the skill's real current-name page is 'Quiver Flow' (idle.maplestorywiki.net/w/Quiver_Flow, per user direction — an old/alternate name the wiki still hosts the real curve under), which gives the full level 1-200 curve (50%->100%, linear +2.5% per 10 levels) resolving cleanly to factorIndex 12/baseDamage 500 tenths% (0% residual), plus the real Cooldown=40s (its own infobox — NOT 60s, which was this session's earlier unconfirmed guess matching the skill's own 60s active-duration instead of its actual cooldown). Duration(60s) > Cooldown(40s) so it's maintained at 100% uptime once off cooldown (re-placed immediately). Stationary turret: fires every 0.3s for 60s (EffectiveHits = 60/0.3=200/cast). PATCHED: base targets 1->3, +1 more once Lv.98 mastery unlocks (patched from +2). Own +200% Normal Monster Damage baked into MasteryNormalDamage% (scoped to this row only, per its own skill description, not the global bucket). Maple Hero target — see MAPLE_HERO_RATIOS.
A10: HURRICANE | B10: Hurricane | C10: 4 | D10: 40 | E10: TRUE | F10: 1 | G10: =20+IF(Inputs!$B$3>=134,15,0) | H10: 0 | I10: 0 | J10: 100 | K10: 1 | L10: 8000 | M10: 12 | N10: TRUE | O10: =SUMPRODUCT((Inputs!$B$3>={108})*{50}) | P10: 0 | Q10: 0 | R10: 7 | T10: 0 | W10: Previously entirely missing from this workbook — found and added after a Discord bug report flagged it absent from the DPS breakdown. Real Lv.103 4th-job active skill. idle.maplestorywiki.net/w/Hurricane's own numbers turned out wrong (confirmed by a second Discord report and cross-referenced against maplestoryidle.info/jobs.html, the new authoritative source used to fix this): the wiki claimed 20 hits, 7% damage 'to the target' (single-target); the real skill is 20 hits, **800%** damage to **up to 7 enemies** in front. FactorIndex corrected from an earlier 0 (non-scaling) — that assumption came from the wiki's own per-level table showing a uniform value at every sampled level, which we now know is unreliable for this skill (the same page also had the damage/target numbers themselves wrong, likely the same underlying data corruption). Real factorIndex 12 (per user direction — the same multi-hit-active-skill curve already used by Covering Fire/Phoenix/Arrow Platter, the closest mechanical siblings), baseDamage 8000 tenths% treated as the level-1 anchor (FLAGGED ASSUMPTION — maplestoryidle.info gives only a single snapshot value with no level context, no independently-confirmed second data point exists to verify which level this value anchors to). Real Cooldown=40s (matches both sources), CostsActionSlot=True (Active type). Not one of Maple Hero's 3 buffed skills (Arrow Platter/Phoenix/Covering Fire only) — no MapleHeroBase/FactorIndex. Two real mastery bonuses, level thresholds also corrected against maplestoryidle.info/jobs.html (the wiki's own Mastery page had these 2 levels lower each): Lv.108 'Hurricane - Damage' +50% (flat SkillMasteryBonus%), Lv.134 'Hurricane - Extend' raises hit count 20->35 (baked into the HitsPerCast formula, same level-gated-hit-count-flip pattern as Dark Knight's Gungnir's Descent). Its own 'fire faster with higher Attack Speed' text is the same category of too-vague-to-model-precisely ambiguity already flagged for this class's own Flash Mirage — FLAGGED, not modeled, real 40s Cooldown(s) used unmodified by Attack Speed.
A11: MAPLE_HERO_HELPER | B11: Maple Hero (helper) | C11: 4 | E11: FALSE | F11: 1 | G11: 1 | H11: 0 | I11: 0 | J11: 100 | K11: 1 | L11: 250 | M11: 23 | N11: TRUE | O11: 0 | P11: 0 | Q11: 0 | R11: 0 | T11: 0 | W11: Shared ratio-feeder row (see MAPLE_HERO_RATIOS) for Arrow Platter/Phoenix/Covering Fire's own Final Damage chains — mirrors Shadower's own MAPLE_HERO_SHADOWER mechanism. RESOLVED this session via idle.maplestorywiki.net/w/Maple_Hero_(Bowmaster) (full level 1-200 curve, resolves to factorIndex 23/baseDamage 250 tenths%, 0% residual). No independent DPS row of its own (Calc columns J-N blank/0, only D/E/F computed, read directly by each target row's own K-column formula — same 'no independent row' pattern as Shadower's own Maple Hero).
A12: FLASH_MIRAGE | B12: Flash Mirage | C12: 3 | D12: =5+1/(((20+30*(Summary!$B$17-1)*100/150)/100)*Summary!$B$17) | E12: FALSE | F12: 1 | G12: 1 | H12: 0 | I12: 0 | J12: 100 | K12: 1 | L12: 5500 | M12: 21 | N12: TRUE | O12: =SUMPRODUCT((Inputs!$B$3>={68})*{50}) | P12: 0 | Q12: 0 | R12: =5+IF(Inputs!$B$3>=136,1,0) | T12: 0 | W12: Passive proc, real mechanic per maplestoryidle.info/jobs.html (used to fix two real data errors found via Discord bug reports — the wiki's own numbers here were badly wrong): 'When attacking, an illusion is created with a 20% chance to attack up to 5 nearby enemies around the target and deal 550% damage. The activation chance increases up to 50% based on Attack Speed.' PATCHED from the wiki's own (confirmed wrong) 5%/flat-20% — baseDamage now 5500 tenths%, and the chance is a real live AS-scaling formula (20%->50%, linear with Attack Speed 0%->150%, per user direction). FactorIndex corrected from an earlier 0 (non-scaling) — that assumption came from the wiki's own per-level table showing a uniform value at every sampled level, unreliable for the same reason as Hurricane's own factorIndex correction above (the same page's damage/target numbers were also wrong, likely the same underlying data corruption). Real factorIndex 21 (per user direction — the same curve as this class's own Final Attack: Bow/Advanced Final Attack, both also Type=Passive skills that deal a direct % damage proc, the closest mechanical siblings), baseDamage 5500 tenths% treated as the level-1 anchor (FLAGGED ASSUMPTION — same caveat as Hurricane's own: maplestoryidle.info gives only a single snapshot value with no level context). The wiki's own infobox 'Cooldown: 5 sec' claim turned out to be real after all (a mid-session correction wrongly discarded it, inferring 'no cooldown' purely from maplestoryidle.info's schema not listing one — caught by a user follow-up question) — modeled as a genuine 5s floor between procs, with the chance re-rolling on every attack line once the floor expires (per user direction on the exact combination mechanic), folded into Cooldown(s) as 5+1/(chance*Summary!APS) with ProcChance%=100 (see the comment above this row for why it can't cleanly decompose into separate Cooldown/ProcChance columns here). Also added a real, previously-unmodeled mastery: 'Flash Mirage - Damage' +50% at Lv.68. Wiki calls this skill 'Flash Mirage'; the Aug 13 patch notes call the SAME skill 'Speed Mirage' (confirmed via mechanic match — targets 5->7, detection range +~14%). Flash Mirage II (Lv.110, see FLASH_MIRAGE_II_HELPER) adds +targets/+FD once unlocked, baked into NormalMonsterTargets/K-column.
A13: FLASH_MIRAGE_II_HELPER | B13: Flash Mirage II (helper) | C13: 4 | E13: FALSE | F13: 1 | G13: 1 | H13: 0 | I13: 0 | J13: 100 | K13: 1 | L13: 4000 | M13: 21 | N13: TRUE | O13: 0 | P13: 0 | Q13: 0 | R13: 0 | T13: 0 | W13: Helper row only — feeds Flash Mirage's own K-column extra Final Damage term (see FLASH_MIRAGE's own targets formula for the +4 targets side, +1 more once Mastery Lv.138 unlocks, patched from +3). +400%->720% FD (levels 1-200), not itself patched (only the Lv.138 mastery's own target-count bonus changed, 3->1).
A14: MARKSMANSHIP_BASE | B14: Marksmanship (unconditional half) | C14: 3 | E14: FALSE | F14: 1 | G14: 1 | H14: 0 | I14: 0 | J14: 100 | K14: 1 | L14: 100 | M14: 22 | N14: TRUE | O14: 0 | P14: 0 | Q14: 0 | R14: 0 | S14: ATTACK | T14: 0 | W14: PATCHED: 'Base Attack +10%, additional +10% when 1 target' replaces the old flat '+20% at 1 target only' wording — modeled as two separate rows (this unconditional half + MARKSMANSHIP_COND's conditional half), summed additively into the same Attack% bucket as Illusion Step (Verification item 6 — these must never multiply against each other). Half of the wiki's own pre-patch curve (10%->16%, levels 1-200), assumed symmetric 50/50 split at every level (the patch note only confirms the level-1 split, 10/10) — factorIndex 22, baseDamage 100 tenths%. Shared verbatim w/ Marksman (identical name, wording, and numbers confirmed both classes via the patch notes' own shared 'Marksmanship' entry).
A15: MARKSMANSHIP_COND | B15: Marksmanship (conditional half, 1 target) | C15: 3 | E15: FALSE | F15: 1 | G15: 1 | H15: 0 | I15: 0 | J15: 100 | K15: 1 | L15: 100 | M15: 22 | N15: TRUE | O15: 0 | P15: 0 | Q15: 0 | R15: 0 | S15: ATTACK_COND_1TARGET | T15: 0 | W15: Conditional half of Marksmanship's own patched Attack% bonus — blended via the same monster_blend_expr helper already used for Boss/Normal Monster Damage% (boss/pvp -> full value, normal -> 0, breakthrough -> weighted), applied to the Attack% bucket instead. Same curve/tuple as MARKSMANSHIP_BASE (factorIndex 22, baseDamage 100 tenths%).
A16: ILLUSION_STEP | B16: Illusion Step | C16: 4 | D16: 24 | E16: FALSE | F16: 1 | G16: 1 | H16: 0 | I16: 0 | J16: 100 | K16: 1 | L16: 140 | M16: 22 | N16: TRUE | O16: 0 | P16: 0 | Q16: 0 | R16: 0 | S16: ATTACK | T16: 15 | W16: Cycling passive: Attack+14%->22.4% for 15s, then swaps to Evasion+15->24/damage taken -10%->16% for 9s (not modeled — those components have no mechanic anywhere in this calculator). Modeled as a duty-cycled buff (Cooldown(s)=24 = full 15+9s cycle length, BuffDuration(s)=15 = the Attack-active portion, giving a 0.625 duty-cycle uptime) — same buff_uptime machinery as every other timed buff in this project. factorIndex 22, baseDamage 140 tenths%. Not patched. Shared verbatim w/ Marksman.
A17: SHARP_EYES | B17: Sharp Eyes | C17: 4 | D17: 35 | E17: TRUE | F17: 1 | G17: 1 | H17: 0 | I17: 0 | J17: 100 | K17: 1 | L17: 400 | M17: 21 | N17: TRUE | O17: 0 | P17: 0 | Q17: 0 | R17: 0 | S17: CRIT_DAMAGE | T17: 18 | W17: Self-inclusive ally buff (matches Bishop's own 'allied players' precedent) — flat +20% Crit Rate (non-scaling, not represented in this row's own BaseDamage/FactorIndex; added directly as a hardcoded 20 in the Crit-Rate-bonus accumulator formula in build_summary_sheet) + scaling Crit Damage +40%->72% (levels 1-200, this row's own curve — factorIndex 21, baseDamage 400 tenths%) for 18s, cooldown 35s. Not patched. Shared verbatim w/ Marksman.
A18: CONCENTRATION | B18: Concentration | C18: 3 | E18: FALSE | F18: 1 | G18: 1 | H18: 0 | I18: 0 | J18: 100 | K18: 1 | L18: 0 | M18: 0 | N18: FALSE | O18: 0 | P18: 0 | Q18: 0 | R18: 0 | S18: CRIT_DAMAGE | T18: 0 | W18: Wiki name 'Concentration' = Aug 13 patch notes' 'Focused Fury' (same skill — both wiki's own Concentration page and the Bowmaster/Skills overview show '+1 Accuracy/+3% Crit Damage for 4 sec, stacking up to 10 times' at level 1, matching the patch's own pre-patch values with an already-correct 10-stack max, confirmed directly against the live wiki this session — not 7 as an earlier session's notes mistakenly recorded). Modeled at steady-state maximum stacks (10 x 3% = 30% Crit Damage, flat, once unlocked at Lv.66) — same convention as every other accumulating-stack passive in this project. PATCHED: duration 4s->6s, Accuracy +1->+3/stack (Accuracy not modeled either way). BaseDamage/FactorIndex left blank/0 (unused placeholder) since this row contributes a flat 30 directly via the R_CONCENTRATION_BONUS accumulator, not a level-scaled Calc!F value.
A19: MORTAL_BLOW | B19: Mortal Blow | C19: 3 | E19: FALSE | F19: 1 | G19: 1 | H19: 0 | I19: 0 | J19: 100 | K19: 1 | L19: 120 | M19: 22 | N19: TRUE | O19: 0 | P19: 0 | Q19: 0 | R19: 0 | S19: FINAL_DAMAGE | T19: 0 | W19: Upon attacking a target directly 40 times, +10%->16%(pre-patch curve) FD for 5s. Modeled at steady state (assumed always active once unlocked), not an exact hit-counter/timer state machine — same simplification tier as Concentration above. PATCHED: base 10%->12% (curve rescaled 12/10=1.2x before reverse-engineering — factorIndex 22, baseDamage 120 tenths% already reflects the patched value). Shared verbatim w/ Marksman.
A20: NIMBLE_FEET | B20: Nimble Feet | C20: 1 | D20: 60 | E20: TRUE | F20: 1 | G20: 1 | H20: 0 | I20: 0 | J20: 100 | K20: 1 | L20: 150 | M20: 0 | N20: FALSE | O20: 0 | P20: 0 | Q20: 0 | R20: 1 | S20: ATTACK_SPEED | T20: 15 | W20: Shared cross-tree verbatim w/ Night Lord/Shadower/FP-Mage (byte-identical wiki wording — '+15% Attack Speed, +10% Speed for 15 sec'). Flat +15% Attack Speed / +10% Speed for 15s, 60s cooldown, non-scaling. FactorIndex unused placeholder.
A21: CRITICAL_SHOT | B21: Critical Shot | C21: 1 | E21: FALSE | F21: 1 | G21: 1 | H21: 0 | I21: 0 | J21: 100 | K21: 1 | L21: 50 | M21: 22 | N21: TRUE | O21: 0 | P21: 0 | Q21: 0 | R21: 0 | S21: CRIT_RATE | T21: 0 | W21: Magic Critical pattern — already baked into Inputs!CRIT_RATE%; feeds the 1st-Job Skill Level Bonus delta. factorIndex 22, baseDamage 50 tenths% (5%->6.5%, levels 1-100).
A22: ARCHER_MASTERY | B22: Archer Mastery (Attack Speed) | C22: 1 | E22: FALSE | F22: 1 | G22: 1 | H22: 0 | I22: 0 | J22: 100 | K22: 1 | L22: 50 | M22: 22 | N22: TRUE | O22: 0 | P22: 0 | Q22: 0 | R22: 0 | S22: ATTACK_SPEED | T22: 0 | W22: Magic Critical pattern — already baked into Inputs!ATTACK_SPEED%; feeds the 1st-Job Skill Level Bonus delta. factorIndex 22, baseDamage 50 tenths% (5%->6.5%, levels 1-100). Own Speed component not modeled.
A23: BOW_ACCELERATION | B23: Bow Acceleration | C23: 2 | E23: FALSE | F23: 1 | G23: 1 | H23: 0 | I23: 0 | J23: 100 | K23: 1 | L23: 50 | M23: 22 | N23: TRUE | O23: 0 | P23: 0 | Q23: 0 | R23: 0 | S23: ATTACK_SPEED | T23: 0 | W23: Magic Critical pattern — already baked into Inputs!ATTACK_SPEED%; feeds the 2nd-Job Skill Level Bonus delta. factorIndex 22, baseDamage 50 tenths% (5%->6.5%, levels 1-100).
A24: PHYSICAL_TRAINING | B24: Physical Training | C24: 2 | E24: FALSE | F24: 1 | G24: 1 | H24: 0 | I24: 0 | J24: 100 | K24: 1 | L24: 100 | M24: 22 | N24: TRUE | O24: 0 | P24: 0 | Q24: 0 | R24: 0 | S24: BASIC_ATTACK_DAMAGE | T24: 0 | W24: Magic Critical pattern — already baked into Inputs!BASIC_ATTACK_DAMAGE%; feeds the 2nd-Job Skill Level Bonus delta. factorIndex 22, baseDamage 100 tenths% (10%->13%, levels 1-100).
A25: BOW_MASTERY | B25: Bow Mastery | C25: 2 | E25: FALSE | F25: 1 | G25: 1 | H25: 0 | I25: 0 | J25: 100 | K25: 1 | L25: 150 | M25: 22 | N25: TRUE | O25: 0 | P25: 0 | Q25: 0 | R25: 0 | S25: MIN_DAMAGE | T25: 0 | W25: Magic Critical pattern — already baked into Inputs!MIN_DAMAGE%; feeds the 2nd-Job Skill Level Bonus delta. factorIndex 22, baseDamage 150 tenths% (15%->19.5%, levels 1-100).
A26: EXTREME_ARCHERY_BOW | B26: Extreme Archery / Reckless Hunt: Bow | C26: 3 | E26: FALSE | F26: 1 | G26: 1 | H26: 0 | I26: 0 | J26: 100 | K26: 1 | L26: 150 | M26: 22 | N26: TRUE | O26: 0 | P26: 0 | Q26: 0 | R26: 0 | S26: FINAL_DAMAGE | T26: 0 | W26: Own Final Damage component only (Defense reduction not modeled — no Defense mechanic exists anywhere in this calculator). Magic Critical pattern — already baked into Inputs!FINAL_DAMAGE%; feeds the 3rd-Job Skill Level Bonus delta. factorIndex 22, baseDamage 150 tenths% (15%->24%, levels 1-200). PATCHED name: wiki still shows 'Extreme Archery: Bow', Aug 13 patch notes confirm current name 'Reckless Hunt: Bow' (-10%->-5% Defense, not modeled either way; FD component itself unpatched).
A27: ARMOR_BREAK_FD | B27: Armor Break (Final Damage) | C27: 4 | E27: FALSE | F27: 1 | G27: 1 | H27: 0 | I27: 0 | J27: 100 | K27: 1 | L27: 100 | M27: 22 | N27: TRUE | O27: 0 | P27: 0 | Q27: 0 | R27: 0 | S27: FINAL_DAMAGE | T27: 0 | W27: Magic Critical pattern — already baked into Inputs!FINAL_DAMAGE%; feeds the 4th-Job Skill Level Bonus delta (Final Damage side). factorIndex 22, baseDamage 100 tenths% (10%->16%, levels 1-200). Not patched. Marksman's own equivalent-slot skill ('Last Man Standing') is a genuinely different mechanic, not shared.
A28: ARMOR_BREAK_DEFPEN | B28: Armor Break (Defense Penetration) | C28: 4 | E28: FALSE | F28: 1 | G28: 1 | H28: 0 | I28: 0 | J28: 100 | K28: 1 | L28: 100 | M28: 22 | N28: TRUE | O28: 0 | P28: 0 | Q28: 0 | R28: 0 | S28: DEF_PEN | T28: 0 | W28: Same skill as Armor Break (Final Damage) above, +10%->16% Defense Penetration. Magic Critical pattern — already baked into Inputs!DEF_PEN%; feeds the 4th-Job Skill Level Bonus delta (Defense Penetration side). factorIndex 22, baseDamage 100 tenths%.
A29: BOW_EXPERT_SKILL | B29: Bow Expert (Skill Damage) | C29: 4 | E29: FALSE | F29: 1 | G29: 1 | H29: 0 | I29: 0 | J29: 100 | K29: 1 | L29: 150 | M29: 22 | N29: TRUE | O29: 0 | P29: 0 | Q29: 0 | R29: 0 | S29: SKILL_DAMAGE | T29: 0 | W29: Magic Critical pattern — already baked into Inputs!SKILL_DAMAGE%; feeds the 4th-Job Skill Level Bonus delta (Skill Damage side). factorIndex 22, baseDamage 150 tenths% (15%->24%, levels 1-200). Not patched.
A30: BOW_EXPERT_MAXDMG | B30: Bow Expert (Max Damage Multiplier) | C30: 4 | E30: FALSE | F30: 1 | G30: 1 | H30: 0 | I30: 0 | J30: 100 | K30: 1 | L30: 200 | M30: 22 | N30: TRUE | O30: 0 | P30: 0 | Q30: 0 | R30: 0 | S30: MAX_DAMAGE | T30: 0 | W30: Same skill as Bow Expert (Skill Damage) above, +20%->32% Max Damage Multiplier. Magic Critical pattern — already baked into Inputs!MAX_DAMAGE%; feeds the 4th-Job Skill Level Bonus delta (Max Damage Multiplier side). factorIndex 22, baseDamage 200 tenths%.
A31: SOUL_ARROW_BOW_ATK | B31: Soul Arrow: Bow (Attack%) | C31: 2 | E31: FALSE | F31: 1 | G31: 1 | H31: 0 | I31: 0 | J31: 100 | K31: 1 | L31: 80 | M31: 22 | N31: TRUE | O31: 0 | P31: 0 | Q31: 0 | R31: 0 | S31: ATTACK | T31: 0 | W31: Own flat +8% Attack component only (patch-added; the DEX+150->900(AS-scaled) component has NO row here at all — assume your own Inputs!Flat DEX already includes it, per the README; no percentage-bucket exists in this template for a flat sub-stat bonus, a deliberate scope-reduction). Magic Critical pattern — already baked into Inputs!ATTACK_PCT (folds into the attack_mult delta bucket, same slot as Shadower's own Channel Karma); feeds the 2nd-Job Skill Level Bonus delta. factorIndex 22 (per user direction — every OTHER 'Magic Critical pattern' row in this file, e.g. ARMOR_BREAK_FD/BOW_EXPERT_SKILL, already uses 22; this row was an inconsistent outlier at 0/non-scaling, corrected), baseDamage 80 tenths% treated as the level-1 anchor.

Sheet Artifacts
A1: Fire/Poison Arch Mage — Artifacts (Equip Effect)
A3: Book of Ancient — Crit Damage (from Crit Rate, reference only) | B3: =IF(ArtifactsInput!$M$24,CHOOSE(ArtifactsInput!$N$24+1,30,36,42,48,54,60)/100*(Inputs!$B$9+B5+B29),0)
A4: Ring of Cycles — Threshold Crit Rate (excl. self) | B4: =Inputs!$B$9+B29
A5: Ring of Cycles — Crit Rate (if threshold < 100%) | B5: =IF(AND(ArtifactsInput!$M$42,B4<100),CHOOSE(ArtifactsInput!$N$42+1,30,36,42,48,54,60),0)
A6: Ring of Cycles — Skill Damage (if threshold >= 100%) | B6: =IF(AND(ArtifactsInput!$M$42,B4>=100),CHOOSE(ArtifactsInput!$N$42+1,40,48,56,64,72,80),0)
A7: Ring of Cycles — Excess-100% Points (capped at 100) | B7: =IF(AND(ArtifactsInput!$M$42,B4>=100),MIN(100,B4-100),0)
A8: Ring of Cycles — Basic Attack Damage (excess points x per-point) | B8: =B7*CHOOSE(ArtifactsInput!$N$42+1,0.6,0.72,0.84,0.96,1.08,1.2)
A9: Candle — Effective Fight Duration | B9: =IF(Inputs!$B$38="pvp",15,Inputs!$B$43)
A10: Candle — Effective Active (fixed-duration or PvP) | B10: =IF(Inputs!$B$38="pvp",TRUE,AND(Inputs!$B$38<>"pvp",Inputs!$B$43>0))
A11: Candle — Final Damage (100% uptime, patched) | B11: =IF(AND(ArtifactsInput!$M$36,B10),CHOOSE(ArtifactsInput!$N$36+1,8,9.6,11.2,12.8,14.4,16),0)
A12: Candle — Boss Monster Damage (20-40s window / boss-present-time uptime, patched) | B12: =IF(AND(ArtifactsInput!$M$36,B10),MAX(0,MIN(40,B9)-MAX(20,B41))/(B9-B41)*CHOOSE(ArtifactsInput!$N$36+1,30,36,42,48,54,60),0)
A13: Peach Tree Herb Pouch — Proc Rate (per second) | B13: =0.2*Summary!$B$17
A14: Peach Tree Herb Pouch — Uptime (refreshing 5s timer) | B14: =1-EXP(-B13*5)
A15: Peach Tree Herb Pouch — Enemy Damage Taken | B15: =IF(AND(ArtifactsInput!$M$35,Inputs!$B$4<>"Chapter Hunt"),CHOOSE(ArtifactsInput!$N$35+1,15,18,21,24,27,30)*B14,0)
A16: Silver Pendant — Offered Load (rho = lambda x duration) | B16: =0.15*Summary!$B$17*5
A17: Silver Pendant — Erlang Loss Weight (n=0) | B17: =B16^0/1
A18: Silver Pendant — Erlang Loss Weight (n=1) | B18: =B16^1/1
A19: Silver Pendant — Erlang Loss Weight (n=2) | B19: =B16^2/2
A20: Silver Pendant — Erlang Loss Weight (n=3) | B20: =B16^3/6
A21: Silver Pendant — Erlang Loss Weight (n=4) | B21: =B16^4/24
A22: Silver Pendant — Erlang Loss Weight (n=5) | B22: =B16^5/120
A23: Silver Pendant — Average Stacks (Erlang-loss mean) | B23: =(0*B17+1*B18+2*B19+3*B20+4*B21+5*B22)/(B17+B18+B19+B20+B21+B22)
A24: Silver Pendant — Enemy Damage Taken | B24: =IF(AND(ArtifactsInput!$M$22,Inputs!$B$4<>"Chapter Hunt"),CHOOSE(ArtifactsInput!$N$22+1,10,12,14,16,18,20)*B23,0)
A25: Athena Pierce's Old Gloves — Max Damage (from Attack Speed, reference only) | B25: =IF(ArtifactsInput!$M$15,CHOOSE(ArtifactsInput!$N$15+1,25,30,35,40,45,50)/100*Inputs!$B$11,0)
A26: Hexagon Necklace — Average Stacks | B26: =IF(AND(Inputs!$B$38<>"pvp",Inputs!$B$43=0),3,IF(IF(Inputs!$B$38="pvp",15,Inputs!$B$43)<=20,0,IF(IF(Inputs!$B$38="pvp",15,Inputs!$B$43)<=40,(IF(Inputs!$B$38="pvp",15,Inputs!$B$43)-20)/IF(Inputs!$B$38="pvp",15,Inputs!$B$43),IF(IF(Inputs!$B$38="pvp",15,Inputs!$B$43)<=60,(2*IF(Inputs!$B$38="pvp",15,Inputs!$B$43)-60)/IF(Inputs!$B$38="pvp",15,Inputs!$B$43),(3*IF(Inputs!$B$38="pvp",15,Inputs!$B$43)-120)/IF(Inputs!$B$38="pvp",15,Inputs!$B$43)))))
A27: Hexagon Necklace — Damage % | B27: =IF(ArtifactsInput!$M$11,CHOOSE(ArtifactsInput!$N$11+1,15,18,21,24,27,30)*B26,0)
A28: Rainbow-colored Snail Shell — Uptime (0-15s window) | B28: =IF(Inputs!$B$38="pvp",MIN(15,15)/15,IF(AND(Inputs!$B$38<>"pvp",Inputs!$B$43>0),MIN(15,Inputs!$B$43)/Inputs!$B$43,0))
A29: Rainbow-colored Snail Shell — Crit Rate | B29: =IF(ArtifactsInput!$M$10,CHOOSE(ArtifactsInput!$N$10+1,15,18,21,24,27,30)*B28,0)
A30: Rainbow-colored Snail Shell — Crit Damage | B30: =IF(ArtifactsInput!$M$10,CHOOSE(ArtifactsInput!$N$10+1,20,24,28,32,36,40)*B28,0)
A32: TOTAL — Artifact Crit Rate Bonus | B32: =B5+B29
A33: TOTAL — Artifact Crit Damage Bonus | B33: =B30+B47
A34: TOTAL — Artifact Final Damage Bonus (equivalent %, each real source combines MULTIPLICATIVELY — Candle x Flaming Lava x Horn Flute, not summed) | B34: =((1+B11/100)*(1+B46/100)*(1+B55/100)-1)*100
A35: TOTAL — Artifact Boss Monster Damage Bonus | B35: =B12+B60
A36: TOTAL — Artifact Enemy Damage Taken Bonus | B36: =B15+B24
A38: TOTAL — Artifact Damage Bonus (own separate final multiplier, like Magic Guard/Meditation's Average Buff Multiplier — not blended into Inputs!DAMAGE%) | B38: =B27
A39: TOTAL — Artifact Skill Damage Bonus | B39: =B6
A40: TOTAL — Artifact Basic Attack Damage Bonus | B40: =B8
A41: Candle — Boss Appear Time (Breakthrough/Hero Dungeon only) | B41: =IF(Inputs!$B$4="Breakthrough",20,IF(Inputs!$B$4="Hero Dungeon",30,0))
A42: Clear Spring Water — Final Damage (reference only, Growth Dungeon types) | B42: =IF(AND(ArtifactsInput!$M$14,OR(Inputs!$B$4="Weapon Dungeon",Inputs!$B$4="Equipment Dungeon",Inputs!$B$4="Enhancement Dungeon",Inputs!$B$4="EXP Dungeon",Inputs!$B$4="Hero Dungeon")),CHOOSE(ArtifactsInput!$N$14+1,10,12,14,16,18,20),0)
A43: Old Music Box — Attack % (content-type uptime assumption) | B43: =IF(ArtifactsInput!$M$21,CHOOSE(ArtifactsInput!$N$21+1,25,30,35,40,45,50)*(IF(OR(Inputs!$B$4="Chapter Hunt",Inputs!$B$4="Breakthrough",Inputs!$B$4="Weapon Dungeon",Inputs!$B$4="Equipment Dungeon",Inputs!$B$4="Enhancement Dungeon",Inputs!$B$4="EXP Dungeon",Inputs!$B$4="Hero Dungeon"),0,IF(OR(Inputs!$B$4="World Boss",Inputs!$B$4="PvP"),1,IF(Inputs!$B$4="Chapter Boss",60/70,0)))),0)
...

Sheet Calc
A1: Key | B1: Name | C1: Unlocked | D1: InputLevel | E1: Factor | F1: CoefficientPercent | G1: EffectiveHits | H1: ProcProbability | I1: MapleHeroMultiplier | J1: BaseDamage | K1: BaseHitDamage | L1: NonCritAvg | M1: CritAvg | N1: ExpectedDamage(perHit) | O1: DPS | P1: % of Total | Q1: InvCooldown | R1: CastsInFight | S1: HitRate(perSec) | T1: BossOnlyDPS | V1: NormalOnlyDPS
A2: =Skills!A2 | B2: =Skills!B2 | C2: =Inputs!$B$3>=100 | F2: =Summary!$B$10+Skills!O2 | G2: =Skills!G2*IF(Skills!H2>0,Skills!I2/Skills!H2,1) | H2: =1-(1-Skills!J2/100)^Skills!K2 | I2: 1 | J2: =Summary!$B$6*(F2/100) | K2: =J2*(1+Summary!$B$7/100)*(1+Inputs!$B$15/100)*(1+Inputs!$B$16/100)*(5000/(6000+Inputs!$B$42*(1-Inputs!$B$19/100)))*(1+(Inputs!$B$24+Summary!$B$21)/100)*(1+Artifacts!$B$34/100)*(1+(IF(Skills!A2="ARROW_STREAM",Inputs!$B$17+Artifacts!$B$40,Inputs!$B$18+Artifacts!$B$39))/100)*(Summary!$B$13*(1+Artifacts!$B$38/100)*I2) | L2: =K2*(MIN(Inputs!$B$22,Inputs!$B$23)/100+Inputs!$B$23/100)/2 | M2: =L2*(1+(Inputs!$B$10+Summary!$B$20+Artifacts!$B$33)/100) | N2: =L2*(1-MIN((Inputs!$B$9+Summary!$B$14+Artifacts!$B$32),100)/100)+M2*(MIN((Inputs!$B$9+Summary!$B$14+Artifacts!$B$32),100)/100) | O2: =(1-Summary!$B$11)*T2+Summary!$B$11*V2 | P2: =IF(Summary!$B$3=0,0,O2/Summary!$B$3) | Q2: 0 | R2: 0 | S2: =IFERROR(O2/N2,0) | T2: =IF(C2,(Skills!G2*N2*Summary!$B$19)*IF(Inputs!$B$38="pvp",1,1+(Inputs!$B$20+Skills!P2+Summary!$B$15+Artifacts!$B$35)/100)*((((5000/(6000+Inputs!$B$42*(1-(100*(1-(1-Inputs!$B$19/100)*(1-Artifacts!$B$51/100)^IF(Inputs!$B$38="pvp",1,2)))/100)))/(5000/(6000+Inputs!$B$42*(1-Inputs!$B$19/100))))*((L2*(1-MIN(100,(Inputs!$B$9+Summary!$B$14+Artifacts!$B$32)+Artifacts!$B$69)/100)+M2*(MIN(100,(Inputs!$B$9+Summary!$B$14+Artifacts!$B$32)+Artifacts!$B$69)/100))/(L2*(1-MIN(100,(Inputs!$B$9+Summary!$B$14+Artifacts!$B$32))/100)+M2*(MIN(100,(Inputs!$B$9+Summary!$B$14+Artifacts!$B$32))/100)))*(1+Artifacts!$B$81/100))),0) | V2: =IF(C2,(Skills!G2*N2*Summary!$B$19)*IF(Inputs!$B$38="pvp",1,(1+(Inputs!$B$21+Skills!Q2+Summary!$B$15+Artifacts!$B$80)/100)*(MIN(Skills!R2,Inputs!$B$37)))*((1+Artifacts!$B$53/100)),0)
A3: =Skills!A3 | B3: =Skills!B3 | C3: =Inputs!$B$3>=50 | D3: =IF(Skills!C3=1,60+Inputs!$B$25+Inputs!$B$29,IF(Skills!C3=2,90+Inputs!$B$26+Inputs!$B$29,IF(Skills!C3=3,120+Inputs!$B$27+Inputs!$B$29,MAX(0,(Inputs!$B$3-100)*3)+Inputs!$B$28+Inputs!$B$29))) | E3: =INDEX(FactorTable!$B$2:$Y$301, MATCH(ROUND(MIN(300,MAX(1,D3)),0), FactorTable!$A$2:$A$301,0), Skills!M3+1) | F3: =IF(Skills!N3=TRUE,(Skills!L3/10)*(E3/1000),Skills!L3/10)+Skills!O3 | G3: =Skills!G3*IF(Skills!H3>0,Skills!I3/Skills!H3,1) | H3: =1-(1-Skills!J3/100)^Skills!K3 | I3: 1 | J3: =Summary!$B$6*(F3/100) | K3: =J3*(1+Summary!$B$7/100)*(1+Inputs!$B$15/100)*(1+Inputs!$B$16/100)*(5000/(6000+Inputs!$B$42*(1-Inputs!$B$19/100)))*(1+(Inputs!$B$24+Summary!$B$21)/100)*(1+Artifacts!$B$34/100)*(1+IF(C4=TRUE,F4,0)/100)*(1+(IF(Skills!A3="ARROW_STREAM",Inputs!$B$17+Artifacts!$B$40,Inputs!$B$18+Artifacts!$B$39))/100)*(Summary!$B$13*(1+Artifacts!$B$38/100)*I3) | L3: =K3*(MIN(Inputs!$B$22,Inputs!$B$23)/100+Inputs!$B$23/100)/2 | M3: =L3*(1+(Inputs!$B$10+Summary!$B$20+Artifacts!$B$33)/100) | N3: =L3*(1-MIN((Inputs!$B$9+Summary!$B$14+Artifacts!$B$32),100)/100)+M3*(MIN((Inputs!$B$9+Summary!$B$14+Artifacts!$B$32),100)/100) | O3: =(1-Summary!$B$11)*T3+Summary!$B$11*V3 | P3: =IF(Summary!$B$3=0,0,O3/Summary!$B$3) | Q3: =IFERROR(1/(IF(Inputs!$B$38="pvp",15,MAX(0.1,Skills!D3-IF(Skills!E3=TRUE,Inputs!$B$32,0)))*(1-IF(AND(ArtifactsInput!$M$27,Inputs!$B$4="Chapter Hunt"),CHOOSE(ArtifactsInput!$N$27+1,20,24,28,32,36,40),0)/100)),0) | R3: =IF(AND(Inputs!$B$38<>"pvp",Inputs!$B$43>0),IF(MAX(0,Inputs!$B$43-Summary!$B$23)<=0,0,(INT(MAX(0,Inputs!$B$43-Summary!$B$23)/(IF(Inputs!$B$38="pvp",15,MAX(0.1,Skills!D3-IF(Skills!E3=TRUE,Inputs!$B$32,0)))*(1-IF(AND(ArtifactsInput!$M$27,Inputs!$B$4="Chapter Hunt"),CHOOSE(ArtifactsInput!$N$27+1,20,24,28,32,36,40),0)/100)))+1)),0) | S3: =IFERROR(O3/N3,0) | T3: =IF(C3,(H3*N3*IF(AND(Inputs!$B$38<>"pvp",Inputs!$B$43>0),((Skills!G3*((R3-1)*IF(Skills!H3>0,Skills!I3/Skills!H3,1)+IF(Skills!H3>0,MIN(Skills!I3,MAX(0,MAX(0,Inputs!$B$43-Summary!$B$23)-((R3-1)*(IF(Inputs!$B$38="pvp",15,MAX(0.1,Skills!D3-IF(Skills!E3=TRUE,Inputs!$B$32,0)))*(1-IF(AND(ArtifactsInput!$M$27,Inputs!$B$4="Chapter Hunt"),CHOOSE(ArtifactsInput!$N$27+1,20,24,28,32,36,40),0)/100)))))/Skills!H3,1)))/Inputs!$B$43),G3*Q3))*IF(Inputs!$B$38="pvp",1,1+(Inputs!$B$20+Skills!P3+Summary!$B$15+Artifacts!$B$35)/100)*((((5000/(6000+Inputs!$B$42*(1-(100*(1-(1-Inputs!$B$19/100)*(1-Artifacts!$B$51/100)^IF(Inputs!$B$38="pvp",1,2)))/100)))/(5000/(6000+Inputs!$B$42*(1-Inputs!$B$19/100))))*((L3*(1-MIN(100,(Inputs!$B$9+Summary!$B$14+Artifacts!$B$32)+Artifacts!$B$69)/100)+M3*(MIN(100,(Inputs!$B$9+Summary!$B$14+Artifacts!$B$32)+Artifacts!$B$69)/100))/(L3*(1-MIN(100,(Inputs!$B$9+Summary!$B$14+Artifacts!$B$32))/100)+M3*(MIN(100,(Inputs!$B$9+Summary!$B$14+Artifacts!$B$32))/100)))*(1+Artifacts!$B$81/100))),0) | V3: =IF(C3,(H3*N3*IF(AND(Inputs!$B$38<>"pvp",Inputs!$B$43>0),((Skills!G3*((R3-1)*IF(Skills!H3>0,Skills!I3/Skills!H3,1)+IF(Skills!H3>0,MIN(Skills!I3,MAX(0,MAX(0,Inputs!$B$43-Summary!$B$23)-((R3-1)*(IF(Inputs!$B$38="pvp",15,MAX(0.1,Skills!D3-IF(Skills!E3=TRUE,Inputs!$B$32,0)))*(1-IF(AND(ArtifactsInput!$M$27,Inputs!$B$4="Chapter Hunt"),CHOOSE(ArtifactsInput!$N$27+1,20,24,28,32,36,40),0)/100)))))/Skills!H3,1)))/Inputs!$B$43),G3*Q3))*IF(Inputs!$B$38="pvp",1,(1+(Inputs!$B$21+Skills!Q3+Summary!$B$15+Artifacts!$B$80)/100)*(MIN(Skills!R3,Inputs!$B$37)))*((1+Artifacts!$B$53/100)),0)
A4: =Skills!A4 | B4: =Skills!B4 | C4: =Inputs!$B$3>=105 | D4: =IF(Skills!C4=1,60+Inputs!$B$25+Inputs!$B$29,IF(Skills!C4=2,90+Inputs!$B$26+Inputs!$B$29,IF(Skills!C4=3,120+Inputs!$B$27+Inputs!$B$29,MAX(0,(Inputs!$B$3-100)*3)+Inputs!$B$28+Inputs!$B$29))) | E4: =INDEX(FactorTable!$B$2:$Y$301, MATCH(ROUND(MIN(300,MAX(1,D4)),0), FactorTable!$A$2:$A$301,0), Skills!M4+1) | F4: =IF(Skills!N4=TRUE,(Skills!L4/10)*(E4/1000),Skills!L4/10)+Skills!O4 | I4: 1
A5: =Skills!A5 | B5: =Skills!B5 | C5: =Inputs!$B$3>=35 | D5: =IF(Skills!C5=1,60+Inputs!$B$25+Inputs!$B$29,IF(Skills!C5=2,90+Inputs!$B$26+Inputs!$B$29,IF(Skills!C5=3,120+Inputs!$B$27+Inputs!$B$29,MAX(0,(Inputs!$B$3-100)*3)+Inputs!$B$28+Inputs!$B$29))) | E5: =INDEX(FactorTable!$B$2:$Y$301, MATCH(ROUND(MIN(300,MAX(1,D5)),0), FactorTable!$A$2:$A$301,0), Skills!M5+1) | F5: =IF(Skills!N5=TRUE,(Skills!L5/10)*(E5/1000),Skills!L5/10)+Skills!O5 | G5: =Skills!G5*IF(Skills!H5>0,Skills!I5/Skills!H5,1) | H5: =1-(1-Skills!J5/100)^Skills!K5 | I5: 1 | J5: =Summary!$B$6*(F5/100) | K5: =J5*(1+Summary!$B$7/100)*(1+Inputs!$B$15/100)*(1+Inputs!$B$16/100)*(5000/(6000+Inputs!$B$42*(1-Inputs!$B$19/100)))*(1+(Inputs!$B$24+Summary!$B$21)/100)*(1+Artifacts!$B$34/100)*(1+4.0*IF(C11=TRUE,F11,0)/100)*(1+(IF(Skills!A5="ARROW_STREAM",Inputs!$B$17+Artifacts!$B$40,Inputs!$B$18+Artifacts!$B$39))/100)*(Summary!$B$13*(1+Artifacts!$B$38/100)*I5) | L5: =K5*(MIN(Inputs!$B$22,Inputs!$B$23)/100+Inputs!$B$23/100)/2 | M5: =L5*(1+(Inputs!$B$10+Summary!$B$20+Artifacts!$B$33)/100) | N5: =L5*(1-MIN((Inputs!$B$9+Summary!$B$14+Artifacts!$B$32),100)/100)+M5*(MIN((Inputs!$B$9+Summary!$B$14+Artifacts!$B$32),100)/100) | O5: =(1-Summary!$B$11)*T5+Summary!$B$11*V5 | P5: =IF(Summary!$B$3=0,0,O5/Summary!$B$3) | Q5: =IFERROR(1/(IF(Inputs!$B$38="pvp",15,MAX(0.1,Skills!D5-IF(Skills!E5=TRUE,Inputs!$B$32,0)))*(1-IF(AND(ArtifactsInput!$M$27,Inputs!$B$4="Chapter Hunt"),CHOOSE(ArtifactsInput!$N$27+1,20,24,28,32,36,40),0)/100)),0) | R5: =IF(AND(Inputs!$B$38<>"pvp",Inputs!$B$43>0),IF(MAX(0,Inputs!$B$43-Summary!$B$23)<=0,0,(INT(MAX(0,Inputs!$B$43-Summary!$B$23)/(IF(Inputs!$B$38="pvp",15,MAX(0.1,Skills!D5-IF(Skills!E5=TRUE,Inputs!$B$32,0)))*(1-IF(AND(ArtifactsInput!$M$27,Inputs!$B$4="Chapter Hunt"),CHOOSE(ArtifactsInput!$N$27+1,20,24,28,32,36,40),0)/100)))+1)),0) | S5: =IFERROR(O5/N5,0) | T5: =IF(C5,(H5*N5*IF(AND(Inputs!$B$38<>"pvp",Inputs!$B$43>0),((Skills!G5*((R5-1)*IF(Skills!H5>0,Skills!I5/Skills!H5,1)+IF(Skills!H5>0,MIN(Skills!I5,MAX(0,MAX(0,Inputs!$B$43-Summary!$B$23)-((R5-1)*(IF(Inputs!$B$38="pvp",15,MAX(0.1,Skills!D5-IF(Skills!E5=TRUE,Inputs!$B$32,0)))*(1-IF(AND(ArtifactsInput!$M$27,Inputs!$B$4="Chapter Hunt"),CHOOSE(ArtifactsInput!$N$27+1,20,24,28,32,36,40),0)/100)))))/Skills!H5,1)))/Inputs!$B$43),G5*Q5))*IF(Inputs!$B$38="pvp",1,1+(Inputs!$B$20+Skills!P5+Summary!$B$15+Artifacts!$B$35)/100)*((((5000/(6000+Inputs!$B$42*(1-(100*(1-(1-Inputs!$B$19/100)*(1-Artifacts!$B$51/100)^IF(Inputs!$B$38="pvp",1,2)))/100)))/(5000/(6000+Inputs!$B$42*(1-Inputs!$B$19/100))))*((L5*(1-MIN(100,(Inputs!$B$9+Summary!$B$14+Artifacts!$B$32)+Artifacts!$B$69)/100)+M5*(MIN(100,(Inputs!$B$9+Summary!$B$14+Artifacts!$B$32)+Artifacts!$B$69)/100))/(L5*(1-MIN(100,(Inputs!$B$9+Summary!$B$14+Artifacts!$B$32))/100)+M5*(MIN(100,(Inputs!$B$9+Summary!$B$14+Artifacts!$B$32))/100)))*(1+Artifacts!$B$81/100))),0) | V5: =IF(C5,(H5*N5*IF(AND(Inputs!$B$38<>"pvp",Inputs!$B$43>0),((Skills!G5*((R5-1)*IF(Skills!H5>0,Skills!I5/Skills!H5,1)+IF(Skills!H5>0,MIN(Skills!I5,MAX(0,MAX(0,Inputs!$B$43-Summary!$B$23)-((R5-1)*(IF(Inputs!$B$38="pvp",15,MAX(0.1,Skills!D5-IF(Skills!E5=TRUE,Inputs!$B$32,0)))*(1-IF(AND(ArtifactsInput!$M$27,Inputs!$B$4="Chapter Hunt"),CHOOSE(ArtifactsInput!$N$27+1,20,24,28,32,36,40),0)/100)))))/Skills!H5,1)))/Inputs!$B$43),G5*Q5))*IF(Inputs!$B$38="pvp",1,(1+(Inputs!$B$21+Skills!Q5+Summary!$B$15+Artifacts!$B$80)/100)*(MIN(Skills!R5,Inputs!$B$37)))*((1+Artifacts!$B$53/100)),0)
A6: =Skills!A6 | B6: =Skills!B6 | C6: =Inputs!$B$3>=40 | D6: =IF(Skills!C6=1,60+Inputs!$B$25+Inputs!$B$29,IF(Skills!C6=2,90+Inputs!$B$26+Inputs!$B$29,IF(Skills!C6=3,120+Inputs!$B$27+Inputs!$B$29,MAX(0,(Inputs!$B$3-100)*3)+Inputs!$B$28+Inputs!$B$29))) | E6: =INDEX(FactorTable!$B$2:$Y$301, MATCH(ROUND(MIN(300,MAX(1,D6)),0), FactorTable!$A$2:$A$301,0), Skills!M6+1) | F6: =IF(Skills!N6=TRUE,(Skills!L6/10)*(E6/1000),Skills!L6/10)+Skills!O6 | G6: =Skills!G6*IF(Skills!H6>0,Skills!I6/Skills!H6,1) | H6: =1-(1-Skills!J6/100)^Skills!K6 | I6: 1 | J6: =Summary!$B$6*(F6/100) | K6: =J6*(1+Summary!$B$7/100)*(1+Inputs!$B$15/100)*(1+Inputs!$B$16/100)*(5000/(6000+Inputs!$B$42*(1-Inputs!$B$19/100)))*(1+(Inputs!$B$24+Summary!$B$21)/100)*(1+Artifacts!$B$34/100)*(1+IF(C7=TRUE,F7,0)/100)*(1+(IF(Skills!A6="ARROW_STREAM",Inputs!$B$17+Artifacts!$B$40,Inputs!$B$18+Artifacts!$B$39))/100)*(Summary!$B$13*(1+Artifacts!$B$38/100)*I6) | L6: =K6*(MIN(Inputs!$B$22,Inputs!$B$23)/100+Inputs!$B$23/100)/2 | M6: =L6*(1+(Inputs!$B$10+Summary!$B$20+Artifacts!$B$33)/100) | N6: =L6*(1-MIN((Inputs!$B$9+Summary!$B$14+Artifacts!$B$32),100)/100)+M6*(MIN((Inputs!$B$9+Summary!$B$14+Artifacts!$B$32),100)/100) | O6: =(1-Summary!$B$11)*T6+Summary!$B$11*V6 | P6: =IF(Summary!$B$3=0,0,O6/Summary!$B$3) | Q6: =IFERROR(1/(IF(Inputs!$B$38="pvp",15,MAX(0.1,Skills!D6-IF(Skills!E6=TRUE,Inputs!$B$32,0)))*(1-IF(AND(ArtifactsInput!$M$27,Inputs!$B$4="Chapter Hunt"),CHOOSE(ArtifactsInput!$N$27+1,20,24,28,32,36,40),0)/100)),0) | R6: =IF(AND(Inputs!$B$38<>"pvp",Inputs!$B$43>0),IF(MAX(0,Inputs!$B$43-Summary!$B$23)<=0,0,(INT(MAX(0,Inputs!$B$43-Summary!$B$23)/(IF(Inputs!$B$38="pvp",15,MAX(0.1,Skills!D6-IF(Skills!E6=TRUE,Inputs!$B$32,0)))*(1-IF(AND(ArtifactsInput!$M$27,Inputs!$B$4="Chapter Hunt"),CHOOSE(ArtifactsInput!$N$27+1,20,24,28,32,36,40),0)/100)))+1)),0) | S6: =IFERROR(O6/N6,0) | T6: =IF(C6,(H6*N6*IF(AND(Inputs!$B$38<>"pvp",Inputs!$B$43>0),((Skills!G6*((R6-1)*IF(Skills!H6>0,Skills!I6/Skills!H6,1)+IF(Skills!H6>0,MIN(Skills!I6,MAX(0,MAX(0,Inputs!$B$43-Summary!$B$23)-((R6-1)*(IF(Inputs!$B$38="pvp",15,MAX(0.1,Skills!D6-IF(Skills!E6=TRUE,Inputs!$B$32,0)))*(1-IF(AND(ArtifactsInput!$M$27,Inputs!$B$4="Chapter Hunt"),CHOOSE(ArtifactsInput!$N$27+1,20,24,28,32,36,40),0)/100)))))/Skills!H6,1)))/Inputs!$B$43),G6*Q6))*IF(Inputs!$B$38="pvp",1,1+(Inputs!$B$20+Skills!P6+Summary!$B$15+Artifacts!$B$35)/100)*((((5000/(6000+Inputs!$B$42*(1-(100*(1-(1-Inputs!$B$19/100)*(1-Artifacts!$B$51/100)^IF(Inputs!$B$38="pvp",1,2)))/100)))/(5000/(6000+Inputs!$B$42*(1-Inputs!$B$19/100))))*((L6*(1-MIN(100,(Inputs!$B$9+Summary!$B$14+Artifacts!$B$32)+Artifacts!$B$69)/100)+M6*(MIN(100,(Inputs!$B$9+Summary!$B$14+Artifacts!$B$32)+Artifacts!$B$69)/100))/(L6*(1-MIN(100,(Inputs!$B$9+Summary!$B$14+Artifacts!$B$32))/100)+M6*(MIN(100,(Inputs!$B$9+Summary!$B$14+Artifacts!$B$32))/100)))*(1+Artifacts!$B$81/100))),0) | V6: =IF(C6,(H6*N6*IF(AND(Inputs!$B$38<>"pvp",Inputs!$B$43>0),((Skills!G6*((R6-1)*IF(Skills!H6>0,Skills!I6/Skills!H6,1)+IF(Skills!H6>0,MIN(Skills!I6,MAX(0,MAX(0,Inputs!$B$43-Summary!$B$23)-((R6-1)*(IF(Inputs!$B$38="pvp",15,MAX(0.1,Skills!D6-IF(Skills!E6=TRUE,Inputs!$B$32,0)))*(1-IF(AND(ArtifactsInput!$M$27,Inputs!$B$4="Chapter Hunt"),CHOOSE(ArtifactsInput!$N$27+1,20,24,28,32,36,40),0)/100)))))/Skills!H6,1)))/Inputs!$B$43),G6*Q6))*IF(Inputs!$B$38="pvp",1,(1+(Inputs!$B$21+Skills!Q6+Summary!$B$15+Artifacts!$B$80)/100)*(MIN(Skills!R6,Inputs!$B$37)))*((1+Artifacts!$B$53/100)),0)
A7: =Skills!A7 | B7: =Skills!B7 | C7: =Inputs!$B$3>=107 | D7: =IF(Skills!C7=1,60+Inputs!$B$25+Inputs!$B$29,IF(Skills!C7=2,90+Inputs!$B$26+Inputs!$B$29,IF(Skills!C7=3,120+Inputs!$B$27+Inputs!$B$29,MAX(0,(Inputs!$B$3-100)*3)+Inputs!$B$28+Inputs!$B$29))) | E7: =INDEX(FactorTable!$B$2:$Y$301, MATCH(ROUND(MIN(300,MAX(1,D7)),0), FactorTable!$A$2:$A$301,0), Skills!M7+1) | F7: =IF(Skills!N7=TRUE,(Skills!L7/10)*(E7/1000),Skills!L7/10)+Skills!O7 | I7: 1
