Workbook

Sheet README
A1: Bishop — DPS Calculator: How to Use This Workbook
A3: How to use this workbook
A4: Only edit the yellow-highlighted cells on the Inputs sheet — every other sheet is computed from those values and will be overwritten if you rebuild the workbook.
A5: Summary shows Total DPS, a Per-Skill DPS Breakdown (damage-dealing skills only — buffs/passives that never deal their own damage are omitted), and a Marginal DPS & Stat Value table showing the DPS gained per +1 of each stat.
A6: Sensitivity has the full detail behind that marginal-value table — one self-contained block per stat, showing exactly how bumping that stat by +1 changes every downstream number.
A7: CubeData/PotentialCubes model your current gear's Potential Cube lines and drive cube-reroll expected-value decisions. For the full standalone Potential Cube EV calculator (exact optimal-stopping math, works from this workbook alone), see tools/potential_cubes_ev.py in the project repo.
A9: Design decisions & assumptions
A10: Blood of the Divine's HP-scaling Crit Damage bonus is assumed active at 100% HP (the best case), since HP fluctuation isn't otherwise modeled.
A11: Crit Rate pushed above 100% (e.g. by cube potential lines) automatically redirects its stat-value to Crit Damage's own per-unit DPS value on the PotentialCubes sheet, since excess Crit Rate cannot do anything past 100%.
A12: Buffs (Magic Guard, Heal, Bless, Holy Magic Shell, Advanced Blessing, Infinity) are modeled at steady-state duty-cycle average uptime, not as an exact moment-to-moment state machine. Heal's own self-Attack% component is assumed active whenever target HP >= 70%.
A13: Triumph Feather's two-stage proc and Angel Ray's boss-only proc are modeled as steady-state average multipliers rather than an exact proc-by-proc simulation.
A14: Monster Type blends Boss/Normal Monster Damage% by the Chapter Breakthrough weight %; PvP forces a fixed 15-second window regardless of the Fixed Fight Duration input.
A15: Not modeled (out of scope): crowd control, Accuracy/Evasion/Defense reduction, movement speed, the character's own Defense stat, and Companion Summoning Time.

Sheet Inputs
A1: Bishop — DPS Calculator Inputs
A3: Character Level | B3: 114
A4: Monster Type ("boss", "normal", "breakthrough", or "pvp") | B4: boss
A5: Flat ATTACK | B5: 859335
A6: ATTACK % | B6: 27490.1
A7: Monster Defense (flat, post-x100/x10 scaling) | B7: 3500
A8: CRIT_RATE % | B8: 116.4
A9: CRIT_DAMAGE % | B9: 264
A10: ATTACK_SPEED % (base, excludes Nimble Feet/MP Eater/Blood of the Divine) | B10: 61.7
A11: Flat INT | B11: 56628
A12: INT % | B12: 257.9
A13: LUK | B13: 762
A14: DAMAGE % | B14: 839.6
A15: DAMAGE_AMP % | B15: 66.2
A16: BASIC_ATTACK_DAMAGE % | B16: 45.6
... A28: Skill Level Bonus — All Skills | B28: 55
A30: Additional Bonuses
A31: Skill Cooldown Decrease (seconds, only skills/buffs the character actively casts) | B31: 0
A32: Basic Attack Target Increase (flat, adds to the 6-target normal-monster base) | B32: 1
A33: Buff Duration Increase % | B33: 0
A34: Companion Summoning Time Increase % (companions not modeled — always 0 DPS impact) | B34: 0
A35: Fixed Fight Duration (seconds, boss or normal — leave 0 for steady-state DPS; ignored for pvp) | B35: 0
A36: Chapter Breakthrough: Normal-Monster Weight % (only used when Monster Type = breakthrough) | B36: 60
A37: Max Enemies Actually In Range (normal monsters only; default 999 = uncapped) | B37: 999

Sheet FactorTable
A1: Level | B1: F0 | C1: F1 | D1: F2 | E1: F3 | F1: F4 | G1: F5 | H1: F6 | I1: F7 | J1: F8 | K1: F9 | L1: F10 | M1: F11 | N1: F12 | O1: F13 | P1: F14 | Q1: F15 | R1: F16 | S1: F17 | T1: F18 | U1: F19 | V1: F20 | W1: F21 | X1: F22 | Y1: F23
A2: 1 | B2: 0 | C2: 1000 | D2: 1000 | E2: 1000 | F2: 1000 | G2: 1000 | H2: 1000 | I2: 1000 | J2: 1000 | K2: 1000 | L2: 1000 | M2: 1000 | N2: 1000 | O2: 1000 | P2: 1000 | Q2: 1000 | R2: 1000 | S2: 1000 | T2: 1000 | U2: 1000 | V2: 1000 | W2: 1000 | X2: 1000 | Y2: 1000
A3: 2 | B3: 0 | C3: 1015 | D3: 1020 | E3: 1030 | F3: 1040 | G3: 1050 | H3: 1060 | I3: 1070 | J3: 1020 | K3: 1020 | L3: 1020 | M3: 1000 | N3: 1010 | O3: 1020 | P3: 1030 | Q3: 1040 | R3: 1050 | S3: 1060 | T3: 1070 | U3: 1080 | V3: 1010 | W3: 1008 | X3: 1006 | Y3: 1100
A4: 3 | B4: 0 | C4: 1031 | D4: 1041 | E4: 1061 | F4: 1082 | G4: 1103 | H4: 1124 | I4: 1145 | J4: 1030 | K4: 1041 | L4: 1030 | M4: 1000 | N4: 1015 | O4: 1030 | P4: 1045 | Q4: 1060 | R4: 1075 | S4: 1090 | T4: 1105 | U4: 1120 | V4: 1020 | W4: 1012 | X4: 1009 | Y4: 1150
A5: 4 | B5: 0 | C5: 1047 | D5: 1062 | E5: 1093 | F5: 1126 | G5: 1159 | H5: 1192 | I5: 1226 | J5: 1040 | K5: 1062 | L5: 1040 | M5: 1000 | N5: 1020 | O5: 1040 | P5: 1060 | Q5: 1080 | R5: 1100 | S5: 1120 | T5: 1140 | U5: 1160 | V5: 1030 | W5: 1016 | X5: 1012 | Y5: 1200
A6: 5 | B6: 0 | C6: 1063 | D6: 1084 | E6: 1126 | F6: 1172 | G6: 1217 | H6: 1264 | I6: 1312 | J6: 1050 | K6: 1084 | L6: 1050 | M6: 1000 | N6: 1025 | O6: 1050 | P6: 1075 | Q6: 1100 | R6: 1125 | S6: 1150 | T6: 1175 | U6: 1200 | V6: 1040 | W6: 1020 | X6: 1015 | Y6: 1250
A7: 6 | B7: 0 | C7: 1079 | D7: 1106 | E7: 1160 | F7: 1219 | G7: 1278 | H7: 1340 | I7: 1404 | J7: 1060 | K7: 1106 | L7: 1060 | M7: 1000 | N7: 1030 | O7: 1060 | P7: 1090 | Q7: 1120 | R7: 1150 | S7: 1180 | T7: 1210 | U7: 1240 | V7: 1050 | W7: 1024 | X7: 1018 | Y7: 1300
A8: 7 | B8: 0 | C8: 1096 | D8: 1129 | E8: 1195 | F8: 1268 | G8: 1342 | H8: 1421 | I8: 1503 | J8: 1070 | K8: 1129 | L8: 1070 | M8: 1000 | N8: 1035 | O8: 1070 | P8: 1105 | Q8: 1140 | R8: 1175 | S8: 1210 | T8: 1245 | U8: 1280 | V8: 1060 | W8: 1028 | X8: 1021 | Y8: 1350
A9: 8 | B9: 0 | C9: 1113 | D9: 1152 | E9: 1231 | F9: 1319 | G9: 1410 | H9: 1507 | I9: 1609 | J9: 1080 | K9: 1152 | L9: 1080 | M9: 1000 | N9: 1040 | O9: 1080 | P9: 1120 | Q9: 1160 | R9: 1200 | S9: 1240 | T9: 1280 | U9: 1320 | V9: 1070 | W9: 1032 | X9: 1024 | Y9: 1400
A10: 9 | B10: 0 | C10: 1130 | D10: 1176 | E10: 1268 | F10: 1372 | G10: 1481 | H10: 1598 | I10: 1722 | J10: 1090 | K10: 1176 | L10: 1090 | M10: 1000 | N10: 1045 | O10: 1090 | P10: 1135 | Q10: 1180 | R10: 1225 | S10: 1270 | T10: 1315 | U10: 1360 | V10: 1080 | W10: 1036 | X10: 1027 | Y10: 1450
A11: 10 | B11: 0 | C11: 1147 | D11: 1200 | E11: 1307 | F11: 1427 | G11: 1556 | H11: 1694 | I11: 1843 | J11: 1100 | K11: 1200 | L11: 1100 | M11: 1000 | N11: 1050 | O11: 1100 | P11: 1150 | Q11: 1200 | R11: 1250 | S11: 1300 | T11: 1350 | U11: 1400 | V11: 1090 | W11: 1040 | X11: 1030 | Y11: 1500
A12: 11 | B12: 0 | C12: 1165 | D12: 1224 | E12: 1347 | F12: 1485 | G12: 1634 | H12: 1796 | I12: 1973 | J12: 1110 | K12: 1224 | L12: 1110 | M12: 1000 | N12: 1055 | O12: 1110 | P12: 1165 | Q12: 1220 | R12: 1275 | S12: 1330 | T12: 1385 | U12: 1440 | V12: 1100 | W12: 1044 | X12: 1033 | Y12: 1550
A13: 12 | B13: 0 | C13: 1183 | D13: 1249 | E13: 1388 | F13: 1545 | G13: 1716 | H13: 1904 | I13: 2112 | J13: 1120 | K13: 1249 | L13: 1120 | M13: 1000 | N13: 1060 | O13: 1120 | P13: 1180 | Q13: 1240 | R13: 1300 | S13: 1360 | T13: 1420 | U13: 1480 | V13: 1110 | W13: 1048 | X13: 1036 | Y13: 1600
... A301: 300 | B301: 0 | C301: 88573 | D301: 381637 | E301: 6991522 | F301: 125363453 | G301: 2185120762 | H301: 37157073039 | I301: 614631863830 | J301: 2000 | K301: 53326 | L301: 2500 | M301: 1100 | N301: 2500 | O301: 4000 | P301: 5500 | Q301: 7000 | R301: 8500 | S301: 10000 | T301: 11500 | U301: 13000 | V301: 7558 | W301: 2200 | X301: 1900 | Y301: 8800

Sheet Skills
A1: Key | B1: Name | C1: JobStep | D1: Cooldown(s) | E1: CostsActionSlot | F1: HitsPerCast | G1: ICD(s) | H1: ActiveWindow(s) | I1: ProcChance% | J1: RollsPerCast | K1: BaseDamage(tenths%) | L1: FactorIndex | M1: ScalesWithLevel | N1: SkillMasteryBonus% | O1: MasteryBossDamage% | P1: MasteryNormalDamage% | Q1: NormalMonsterTargets | R1: BuffTargetStat | S1: BuffDuration(s) | T1: MapleHeroBase(tenths%) | U1: MapleHeroFactorIndex | V1: Stacks | W1: Note
A2: BIG_BANG | B2: Big Bang | C2: 4 | E2: FALSE | F2: =IF(Inputs!$B$3>=136,6,5) | G2: 0 | H2: 0 | I2: 100 | J2: 1 | M2: TRUE | N2: =SUMPRODUCT((Inputs!$B$3>={102,106,116,120,128,132})*{10,1,1,1,1,1}) | O2: =SUMPRODUCT((Inputs!$B$3>={111,124})*{10,10}) | P2: 0 | Q2: =6+Inputs!$B$32 | S2: 0 | W2: 4th-job basic-attack effect (supersedes Energy Bolt/Holy Arrow/Shining Ray). HIGH-CONFIDENCE REUSE (not independently reverse-engineered — Bishop has no individual skill wiki pages at all): level-1 text ('290% damage to 6 target(s) 5 time(s)') is word-for-word identical to Ice-Lightning-Mage's own Chain Lightning, so this reuses that exact factorIndex 21/baseDamage 2900 tenths% pair, matching Inputs!skill_coefficient (=290*basic_factor/1000) exactly, same mechanism as every sibling class's own basic-attack row. SkillMasteryBonus% is the 6-tier 'Big Bang - Damage' mastery chain (102/106/116/120/128/132, cumulative totals 10%->15%, DELTA increments 10 then +1 five times). MasteryBossDamage% is the 2-tier 'Big Bang - Boss Monster Damage' chain (111/124, +10% each, +20% total). HitsPerCast 5->6 once the level-136 'Strike' mastery unlocks.
A3: MAGIC_GUARD | B3: Magic Guard | C3: 1 | D3: =IF(Inputs!$B$3>=21,30*0.7,30) | E3: TRUE | F3: 1 | G3: 0 | H3: 0 | I3: 100 | J3: 1 | K3: 120 | L3: 21 | M3: TRUE | N3: 0 | O3: 0 | P3: 0 | Q3: 1 | R3: ATTACK | S3: 15 | W3: Self-buff, +12%->16.8% Attack, 15s duration/30s cooldown (Mastery Lv.21 -30% cooldown -> 21s). factorIndex 21, baseDamage 120 tenths%. Shared verbatim w/ FP-Mage/Ice-Lightning-Mage (identical wiki wording and numbers).
A4: HEAL | B4: Heal (self Attack%) | C4: 2 | D4: 18 | E4: TRUE | F4: 1 | G4: 0 | H4: 0 | I4: 100 | J4: 1 | K4: 100 | L4: 22 | M4: TRUE | N4: =SUMPRODUCT((Inputs!$B$3>={54})*{8}) | O4: 0 | P4: 0 | Q4: 1 | R4: ATTACK | S4: =IF(Inputs!$B$3>=39,10*1.5,10) | W4: FLAGGED ASSUMPTION (no wiki curve — only the level-1 value is known): factorIndex 22 (buff/passive convention), baseDamage 100 tenths% (10% level-1). Heal's own HP-recovery component is entirely out of scope (no HP tracking anywhere in this calculator). The conditional '+10% Attack while target HP>=70%' component is modeled always-on (steady-state 'healthy' assumption, same tier as Ice-Lightning-Mage's always-5-Frost-stacks convention). Self-inclusive ('allied players' — matches Meditation's own established self-inclusive precedent in FP-Mage/Ice-Lightning-Mage). Duration 10s (Mastery Lv.39 'Heal - Persistence' +50% -> 15s), cooldown 18s. SkillMasteryBonus% is the SEPARATE Mastery Lv.54 'Heal - Attack' (+8% Attack when the caster's OWN HP>=50%) — a distinct mastery from the base skill's own conditional effect, also modeled always-on under the same 100%-HP assumption.
A5: BLESS | B5: Bless | C5: 2 | D5: 24 | E5: TRUE | F5: 1 | G5: 0 | H5: 0 | I5: 100 | J5: 1 | K5: 160 | L5: 22 | M5: TRUE | N5: 0 | O5: 0 | P5: 0 | Q5: 1 | R5: ATTACK | S5: =IF(Inputs!$B$3>=44,15*1.3,15) | W5: FLAGGED ASSUMPTION: factorIndex 22, baseDamage 160 tenths% (16% level-1). Bishop's own Meditation-equivalent (near-identical wording: 'Increases the Attack of allied players by 16% for 15 sec'), self-inclusive. Duration 15s (Mastery Lv.44 'Bless - Persistence' +30% -> 19.5s), cooldown 24s.
A6: ANGEL_RAY | B6: Angel Ray | C6: 4 | D6: 17 | E6: TRUE | F6: 6 | G6: 0 | H6: 0 | I6: 100 | J6: 1 | K6: 6800 | L6: 12 | M6: TRUE | N6: =SUMPRODUCT((Inputs!$B$3>={108})*{50}) | O6: 0 | P6: 0 | Q6: 1 | S6: 0 | W6: FLAGGED ASSUMPTION: factorIndex 12 (burst convention), baseDamage 6800 tenths% (680% level-1). Wiki: 'Attacks the target with a holy sword 3 times to deal 680% damage 2 time(s) each' — read as 6 total hits (3 strikes x 2), single-target (no target count given, stun not modeled). Cooldown 17s. Mastery Lv.108 'Angel Ray - Damage' +50% (real SkillMasteryBonus%, separate from the Lv.122 Boss Monster Damage proc mastery).
A7: ANGEL_RAY_BOSS_PROC | B7: Angel Ray - Boss Monster Damage (Mastery Lv.122) | C7: 4 | D7: =Skills!D6 | E7: FALSE | F7: 1 | G7: 0 | H7: 0 | I7: 100 | J7: 1 | K7: 6800 | L7: 12 | M7: TRUE | N7: 0 | O7: 0 | P7: 0 | Q7: 1 | S7: 0 | W7: FLAGGED ASSUMPTION: factorIndex 12 (same as its parent), baseDamage 6800 tenths% (matches the mastery's own stated 680%, which the wiki confirms 'increases with Angel Ray skill level' — i.e. it scales, not a flat bonus). Standalone proc row mirroring Ice-Lightning-Mage's Blizzard - Final Attack precedent: shares Angel Ray's own live Cooldown(s) cell. Unconditional on a boss hit (not a percentage roll — the wiki's own wording is 'when hitting a boss monster', no chance given), so ProcChance%=100 here is a placeholder; the boss-only condition is applied directly in this row's own bespoke Calc!O formula via (1-Inputs!normal_weight_frac) instead of the generic target-multiplier, since it must be 1 for boss AND pvp (both single-target) but 0 for pure normal-monster fights.
A8: GENESIS | B8: Genesis | C8: 4 | D8: =IF(Inputs!$B$3>=126,23*0.7,23) | E8: TRUE | F8: 6 | G8: 0 | H8: 0 | I8: 100 | J8: 1 | K8: 7000 | L8: 12 | M8: TRUE | N8: =SUMPRODUCT((Inputs!$B$3>={118})*{50}) | O8: 0 | P8: 0 | Q8: 10 | S8: 0 | W8: FLAGGED ASSUMPTION: factorIndex 12, baseDamage 7000 tenths% (700% level-1). Wiki: 'Drops a pillar of holy light on 10 nearby target(s) to deal 700% damage 6 time(s)' — burst, not a DoT (no duration/tick-interval given). Cooldown 23s. Mastery Lv.118 'Genesis - Damage' +50% (real SkillMasteryBonus%), Lv.126 'Genesis - Reuse' -30% cooldown (baked into the Cooldown(s) formula).
A9: BAHAMUT | B9: Bahamut | C9: 4 | D9: =IF(Inputs!$B$3>=138,80*0.7,80) | E9: TRUE | F9: 1 | G9: 4 | H9: 30 | I9: 100 | J9: 1 | K9: 35000 | L9: 12 | M9: TRUE | N9: =SUMPRODUCT((Inputs!$B$3>={130})*{50}) | O9: 0 | P9: 0 | Q9: =IF(Inputs!$B$3>=130,6,3) | S9: 0 | W9: HIGH-CONFIDENCE REUSE (see BIG_BANG's own note on the data-gap situation): level-1 text ('3500% damage every 4 sec to 3 target(s)... 30 sec... 80 sec cooldown') is word-for-word identical to Ice-Lightning-Mage's own Elquines, so this reuses that exact factorIndex 12/baseDamage 35000 tenths% pair. Mastery Lv.130 'Bahamut - Damage & Target' +50% dmg AND +3 max targets (3->6, baked into the NormalMonsterTargets formula), Lv.138 'Bahamut - Reuse' -30% cooldown.
A10: HOLY_FOUNTAIN | B10: Holy Fountain (Boss Dmg mastery only) | C10: 3 | D10: 30 | E10: TRUE | F10: 1 | G10: 0 | H10: 0 | I10: 100 | J10: 1 | M10: FALSE | N10: 0 | O10: 0 | P10: 0 | Q10: 1 | S10: 0 | W10: Holy Fountain's own base skill is pure HP recovery — entirely out of scope (no HP tracking anywhere in this calculator), so this row carries no BaseDamage/FactorIndex of its own; it exists only to hold a live Cooldown(s) cell (patched 40s->30s per the Aug 13 2026 patch note — the wiki page itself is stale) for Mastery Lv.68's own duty-cycle uptime reference (see build_summary_sheet) and to participate correctly in the cast-rate action-economy sum (CostsActionSlot=True). Mastery Lv.68 'Holy Fountain - Boss Monster Damage' (patched 10%->20%, confirmed in the Aug 13 2026 patch PDF) is a flat, non-scaling bonus (matches every other '-Boss Monster Damage' mastery elsewhere in this project, which are all flat level_gated_sum values, not factor-curve-scaled) — modeled as a duty-cycle-averaged self Boss Monster Damage buff tied to this row's own cooldown, mirroring Ice-Lightning-Mage's Freezing Breath - Weaken treatment exactly.
A11: HOLY_MAGIC_SHELL | B11: Holy Magic Shell (self Attack%) | C11: 3 | D11: 27 | E11: TRUE | F11: 1 | G11: 0 | H11: 0 | I11: 100 | J11: 1 | K11: 150 | L11: 22 | M11: TRUE | N11: 0 | O11: 0 | P11: 0 | Q11: 1 | R11: ATTACK | S11: 22 | W11: FLAGGED ASSUMPTION: factorIndex 22, baseDamage 150 tenths% (15% level-1). Wiki: 'Increases Attack by 15%... decreases damage taken by allied players by 5%' — the damage-taken reduction is defensive, out of scope (same exclusion precedent as Ice-Lightning-Mage's Frozen Break -5%-damage-taken note). Attack component modeled like Magic Guard, self-inclusive. Duration 22s, cooldown 27s. Mastery Lv.82 'Purification' (removes 1 debuff) not modeled — no debuff mechanic exists anywhere in this calculator.
A12: HOLY_SYMBOL | B12: Holy Symbol | C12: 3 | D12: 28 | E12: FALSE | F12: 1 | G12: 0 | H12: 0 | I12: 100 | J12: 1 | K12: 150 | L12: 22 | M12: TRUE | N12: 0 | O12: =SUMPRODUCT((Inputs!$B$3>={90})*{25}) | P12: 0 | Q12: 1 | S12: =IF(Inputs!$B$3>=98,14*1.5,14) | W12: FLAGGED ASSUMPTION: factorIndex 22, baseDamage 150 tenths% (15% level-1). Wiki: 'Increases allied players' Normal Monster Damage by 15%... every 28 sec' — auto-triggering passive, not player-cast (CostsActionSlot=False). Duration 14s (Mastery Lv.98 'Holy Symbol - Persistence' +50% -> 21s). This row's own F-value feeds a duty-cycle-averaged bespoke Normal-Monster-only global bonus in build_summary_sheet (a new R_NORMAL_DMG_BONUS slot, structurally the normal-monster-only mirror of R_MONSTER_DMG_BONUS/Freezing Breath - Weaken), NOT the generic BuffTargetStat mechanism (left blank here since NM-only doesn't map onto any existing generic target). Debuff Tolerance component not modeled (no debuff mechanic exists). MasteryBossDamage% here holds Mastery Lv.90 'Holy Symbol - Damage Boost' (+25% flat Damage% if allied players excluding self <=2) — ALWAYS TRUE for a solo player, so this becomes an unconditional flat Damage% bonus once unlocked, folded into the same Summary R_DAMAGE_BONUS-style slot Ice-Lightning-Mage's Frozen Break/Frost Clutch use (NOT consumed as MasteryBossDamage% normally would be — this row isn't a DAMAGE_ROW_KEYS row at all, so that field is otherwise unused here, safe to reuse purely as storage. Deliberately NOT stored in SkillMasteryBonus% — that field IS consumed unconditionally by the generic F-column formula for every row, which would have silently contaminated this row's own F-value (also legitimately used above for the Normal Monster Damage bonus calculation) — caught via the categorical monster_type sweep, not by the default-boss verification alone.
A13: ADVANCED_BLESSING | B13: Advanced Blessing | C13: 4 | D13: 26 | E13: TRUE | F13: 1 | G13: 0 | H13: 0 | I13: 100 | J13: 1 | K13: 70 | L13: 22 | M13: TRUE | N13: =SUMPRODUCT((Inputs!$B$3>={113})*{4}) | O13: 0 | P13: 0 | Q13: 1 | R13: FINAL_DAMAGE | S13: 20 | W13: FLAGGED ASSUMPTION: factorIndex 22, baseDamage 70 tenths% (7% level-1). Wiki: 'Increases Final Damage of allied players by 7%... decreases their MP Cost by 7%' — MP-cost reduction out of scope (MP not tracked). Self-inclusive, FINAL_DAMAGE target (joins the Average Buff Multiplier chain in Summary alongside Magic Guard/Heal/Bless/Holy Magic Shell/Infinity). Duration 20s, cooldown 26s. Mastery Lv.113 '+4% Final Damage while MP>=50%' modeled always-on (MP-condition-ignored, same decision as MP Eater/Element Amplification) — folded additively into this row's own SkillMasteryBonus%.
A14: TRIUMPH_FEATHER | B14: Triumph Feather | C14: 3 | E14: FALSE | F14: =IF(Inputs!$B$3>=104,3,2) | G14: 1 | H14: 0 | I14: 35 | J14: 1 | K14: 1500 | L14: 12 | M14: TRUE | N14: =SUMPRODUCT((Inputs!$B$3>={73})*{50}) | O14: 0 | P14: 0 | Q14: =IF(Inputs!$B$3>=94,7,1) | S14: 0 | W14: FLAGGED ASSUMPTION: factorIndex 12, baseDamage 1500 tenths% (150% level-1). Genuinely new 2-stage-proc mechanic: wiki says 'When attacking, harnesses the power of the angel for 10 sec with a 15% chance [Mastery Lv.78 +10%p -> 25%]. While harnessing, 35% chance/attack to create angel feathers dealing 150% additional damage 2 time(s), 1s ICD per target (treated as a single global ICD in this per-second-DPS model, not per-target).' Modeled as: this row's own ProcChance%=35 is stage 2's chance; stage 1's own steady-state busy-fraction (chance 15%/25%, duration 10s, driven by the character's own attack rate) is computed in build_calc_sheet as a bespoke multiplier on this row's own Calc!O formula, mirroring the queueing-rate approximation FP-Mage's own Meteor Proc uses — NOT the generic H-column ProcProbability-only pattern every other row uses, since this needs BOTH stages combined. Mastery Lv.73 +50% dmg (real SkillMasteryBonus%), Lv.94 'Harnessing' removes the 1s-per-target activation limit and spreads to 7 random targets (modeled here purely as the already-uncapped ICD assumption plus NormalMonsterTargets 1->7 — the ICD-removal itself is a known simplification, effectively a no-op under the already-global-ICD treatment, flagged as a known simplification), Lv.104 'Triumph Feather - Strike' +1 hit count (2->3, baked into the HitsPerCast formula — same convention as every other Strike+1 mastery elsewhere in this project). Maple Hero (Bishop's own, different mechanic shape — see MAPLE_HERO_BISHOP row) feeds this row's own Final Damage chain directly, not the generic MapleHeroMultiplier (I) column.
A15: MAPLE_HERO_BISHOP | B15: Maple Hero | C15: 4 | E15: FALSE | F15: 1 | G15: 0 | H15: 0 | I15: 100 | J15: 1 | K15: 500 | L15: 23 | M15: TRUE | N15: 0 | O15: 0 | P15: 0 | Q15: 1 | S15: 0 | W15: FLAGGED ASSUMPTION: factorIndex 23 (Maple Hero convention, matching every other class's own Maple Hero factorIndex), baseDamage 500 tenths% (50% level-1). Bishop's own Maple Hero targets Triumph Feather with a DIFFERENT mechanic shape than every other class's Maple Hero: 'Increases Final Damage of [Triumph Feather] by 50%' — a genuine Final-Damage-chain additive term (like Element Amplification), NOT a MapleHeroBase-scaled 'additional damage%' multiplier. No independent DPS row of its own (Calc columns J-N stay blank/0, same 'no independent row' pattern as Night Lord's own Night Lord's Mark) — only D/E/F (its own scaling coefficient) are computed, read directly by Triumph Feather's own Calc!K formula. Also increases HP Recovery of Heal/Holy Fountain (out of scope, no HP tracking).
A16: MP_EATER_MP_BOOST | B16: MP Eater - MP Boost (Mastery Lv.49) | C16: 2 | E16: FALSE | F16: 1 | G16: 0 | H16: 0 | I16: 100 | J16: 1 | K16: 70 | L16: 0 | M16: FALSE | N16: 0 | O16: 0 | P16: 0 | Q16: 1 | S16: 0 | W16: Shared verbatim w/ FP-Mage/Ice-Lightning-Mage: flat always-on +7% Attack Speed once unlocked (MP>=50%(patched 35%) condition ignored per the always-on decision). Real, always-on contributor (NOT baked into Inputs) — folds into the Attack Speed diminishing-returns stack in Summary once unlocked, no uptime averaging (not a timed buff). FactorIndex is an unused placeholder (ScalesWithLevel=False).
A17: ELEMENT_AMPLIFICATION | B17: Element Amplification | C17: 3 | E17: FALSE | F17: 1 | G17: 0 | H17: 0 | I17: 100 | J17: 1 | K17: 150 | L17: 22 | M17: TRUE | N17: 0 | O17: 0 | P17: 0 | Q17: 1 | R17: FINAL_DAMAGE | S17: 0 | W17: Shared verbatim w/ FP-Mage/Ice-Lightning-Mage: +15%->24% Final Damage, unconditional (ignore the MP>=50%(patched 35%) condition per the same always-on decision applied everywhere else). Not reflected in Inputs — added directly into the Final Damage chain.
A18: INFINITY | B18: Infinity | C18: 4 | D18: 30 | E18: TRUE | F18: 1 | G18: 0 | H18: 0 | I18: 100 | J18: 1 | K18: 150 | L18: 21 | M18: TRUE | N18: 0 | O18: 0 | P18: 0 | Q18: 1 | R18: FINAL_DAMAGE | S18: 15 | W18: Shared verbatim w/ Ice-Lightning-Mage: base +15%->27% Final Damage for 15s, additionally +1%->1.8%/sec stacking up to 10 times — time-averaged total collapses to base*64/45 exactly (reverse-engineered for Ice-Lightning-Mage, identical wiki wording here). This row's own Calc!F needs the same bespoke base*64/45 formula in build_calc_sheet as every other class's Infinity, not the generic F-column formula.
A19: BLOOD_OF_THE_DIVINE | B19: Blood of the Divine | C19: 4 | E19: FALSE | F19: 1 | G19: 0 | H19: 0 | I19: 100 | J19: 1 | K19: 50 | L19: 22 | M19: TRUE | N19: 0 | O19: 0 | P19: 0 | Q19: 1 | S19: 0 | W19: FLAGGED ASSUMPTION: factorIndex 22, baseDamage 50 tenths% (5% level-1, the Final Damage component). HP-scaling passive — HP isn't tracked anywhere in this calculator, so modeled assuming permanently 100% HP (steady-state favorable assumption, same tier as Ice-Lightning-Mage's always-5-Frost-stacks convention). Wiki: 'Increases Final Damage by 5%. For every 10% of current HP increases Critical Damage by 2%' -> at 100% HP, +20% Crit Damage, modeled as 4x this row's own F-value (preserving the level-1 5%FD:20%CD ratio across the same factor curve, a further simplification since no separate curve data exists for the Crit Damage component) — feeds a new Summary R_CRIT_DAMAGE_BONUS slot (mirrors Night Lord's own R_CRIT_DAMAGE_BONUS for Frailty Curse). Final Damage component feeds the Final Damage chain directly (like Element Amplification). Mastery Lv.134 '+1.5% Attack Speed per 10% HP' -> flat +15% Attack Speed at 100% HP, modeled as a FLAT non-scaling addition (matches how masteries are typically flat elsewhere in this project, independent of this row's own F-value) once level>=134, folded into the same always-on AS_BONUS slot MP_EATER_MP_BOOST feeds.
A20: MAGIC_ACCELERATION | B20: Magic Acceleration | C20: 2 | E20: FALSE | F20: 1 | G20: 0 | H20: 0 | I20: 100 | J20: 1 | K20: 50 | L20: 22 | M20: TRUE | N20: 0 | O20: 0 | P20: 0 | Q20: 1 | R20: ATTACK_SPEED | S20: 0 | W20: Shared verbatim w/ FP-Mage/Ice-Lightning-Mage: Magic Critical pattern, already baked into Inputs!ATTACK_SPEED%; feeds the 2nd-Job Skill Level Bonus Sensitivity delta only.
A21: SPELL_MASTERY | B21: Spell Mastery | C21: 2 | E21: FALSE | F21: 1 | G21: 0 | H21: 0 | I21: 100 | J21: 1 | K21: 150 | L21: 22 | M21: TRUE | N21: 0 | O21: 0 | P21: 0 | Q21: 1 | R21: MIN_DAMAGE | S21: 0 | W21: Shared verbatim w/ FP-Mage/Ice-Lightning-Mage: Magic Critical pattern, already baked into Inputs!MIN_DAMAGE%; feeds the 2nd-Job Skill Level Bonus delta.
A22: HIGH_WISDOM | B22: High Wisdom | C22: 2 | E22: FALSE | F22: 1 | G22: 0 | H22: 0 | I22: 100 | J22: 1 | K22: 80 | L22: 22 | M22: TRUE | N22: 0 | O22: 0 | P22: 0 | Q22: 1 | R22: CRIT_RATE | S22: 0 | W22: Shared verbatim w/ Ice-Lightning-Mage: Magic Critical pattern, already baked into Inputs!CRIT_RATE% (jointly with Magic Critical (Crit Rate) below); feeds the 2nd-Job Skill Level Bonus delta.
A23: MAGIC_CRITICAL_RATE | B23: Magic Critical (Crit Rate) | C23: 3 | E23: FALSE | F23: 1 | G23: 0 | H23: 0 | I23: 100 | J23: 1 | K23: 80 | L23: 22 | M23: TRUE | N23: 0 | O23: 0 | P23: 0 | Q23: 1 | R23: CRIT_RATE | S23: 0 | W23: Shared verbatim w/ FP-Mage/Ice-Lightning-Mage: Magic Critical pattern, already baked into Inputs!CRIT_RATE%; feeds the 3rd-Job Skill Level Bonus delta.
A24: MAGIC_CRITICAL_DAMAGE | B24: Magic Critical (Crit Damage) | C24: 3 | E24: FALSE | F24: 1 | G24: 0 | H24: 0 | I24: 100 | J24: 1 | K24: 120 | L24: 22 | M24: TRUE | N24: 0 | O24: 0 | P24: 0 | Q24: 1 | R24: CRIT_DAMAGE | S24: 0 | W24: Shared verbatim w/ FP-Mage/Ice-Lightning-Mage: Magic Critical pattern, already baked into Inputs!CRIT_DAMAGE%; feeds the 3rd-Job Skill Level Bonus delta.
A25: BUFF_MASTERY | B25: Buff Mastery | C25: 4 | E25: FALSE | F25: 1 | G25: 0 | H25: 0 | I25: 100 | J25: 1 | K25: 100 | L25: 22 | M25: TRUE | N25: 0 | O25: 0 | P25: 0 | Q25: 1 | S25: 0 | W25: Shared verbatim w/ FP-Mage/Ice-Lightning-Mage: feeds bdi_with_buff_mastery_expr (Buff Duration Increase %) at unlock level 117 — not reflected in Inputs.
A26: ARCANE_AIM | B26: Arcane Aim | C26: 4 | E26: FALSE | F26: 1 | G26: 0 | H26: 0 | I26: 100 | J26: 1 | K26: 30 | L26: 22 | M26: TRUE | N26: 0 | O26: 0 | P26: 0 | Q26: 1 | S26: 0 | W26: Shared verbatim w/ FP-Mage/Ice-Lightning-Mage: 25% chance, +Final Damage% for 10s, stacks x5 — modeled always at max 5 stacks, combined multiplicatively as (1+Calc!F/100)^5.

Sheet Calc
A1: Key | B1: Name | C1: Unlocked | D1: InputLevel | E1: Factor | F1: CoefficientPercent | G1: EffectiveHits | H1: ProcProbability | I1: MapleHeroMultiplier | J1: BaseDamage | K1: BaseHitDamage | L1: NonCritAvg | M1: CritAvg | N1: ExpectedDamage(perHit) | O1: DPS | P1: % of Total | Q1: InvCooldown | R1: CastsInFight | Z1: Maple Hero helper (unused — see Note on MAPLE_HERO_BISHOP row)
A2: =Skills!A2 | B2: =Skills!B2 | C2: =Inputs!$B$3>=100 | F2: =Summary!$B$47+Skills!N2 | G2: =Skills!F2*IF(Skills!G2>0,Skills!H2/Skills!G2,1) | H2: =1-(1-Skills!I2/100)^Skills!J2 | I2: =IF(Skills!T2<>"",1+(Skills!T2/10)*($Z$3/1000)/100,1) | J2: =Summary!$B$43*(F2/100) | K2: =J2*(1+Summary!$B$44/100)*(1+(Inputs!$B$14+Summary!$B$53)/100)*(1+IF(Inputs!$B$4="pvp",0,(1-Summary!$B$48)*(Inputs!$B$19+Skills!O2+Summary!$B$51)+Summary!$B$48*(Inputs!$B$20+Skills!P2+Summary!$B$52))/100)*(1+Inputs!$B$15/100)*(5000/(6000+Inputs!$B$7*(1-Inputs!$B$18/100)))*(1+Inputs!$B$23/100)*(1+IF(C17=TRUE,F17,0)/100)*(1+IF(C19=TRUE,F19,0)/100)*(1+IF(Skills!A2="TRIUMPH_FEATHER",IF(C15=TRUE,F15,0),0)/100)*(1+IF(C26=TRUE,F26,0)/100)^5*(1+(IF(Skills!A2="BIG_BANG",Inputs!$B$16,Inputs!$B$17))/100)*(Summary!$B$50*I2) | L2: =K2*(MIN(Inputs!$B$21,Inputs!$B$22)/100+Inputs!$B$22/100)/2 | M2: =L2*(1+(Inputs!$B$9+Summary!$B$54)/100) | N2: =L2*(1-MIN(Inputs!$B$8,100)/100)+M2*(MIN(Inputs!$B$8,100)/100) | O2: =IF(C2,Skills!F2*N2*Summary!$B$58*IF(Inputs!$B$4="pvp",1,(1-Summary!$B$48)*(1)+Summary!$B$48*(MIN(Skills!Q2,Inputs!$B$37))),0) | P2: =IF(Summary!$B$3=0,0,O2/Summary!$B$3) | Q2: =IFERROR(1/IF(Inputs!$B$4="pvp",15,MAX(0.1,Skills!D2-IF(Skills!E2=TRUE,Inputs!$B$31,0))),0) | R2: 0 | Z2: =MAX(0,(Inputs!$B$3-100)*3)+Inputs!$B$27+Inputs!$B$28
A3: =Skills!A3 | B3: =Skills!B3 | C3: =Inputs!$B$3>=15 | D3: =IF(Skills!C3=1,60+Inputs!$B$24+Inputs!$B$28,IF(Skills!C3=2,90+Inputs!$B$25+Inputs!$B$28,IF(Skills!C3=3,120+Inputs!$B$26+Inputs!$B$28,MAX(0,(Inputs!$B$3-100)*3)+Inputs!$B$27+Inputs!$B$28))) | E3: =INDEX(FactorTable!$B$2:$Y$301, MATCH(ROUND(MIN(300,MAX(1,D3)),0), FactorTable!$A$2:$A$301,0), Skills!L3+1) | F3: =IF(Skills!M3=TRUE,(Skills!K3/10)*(E3/1000),Skills!K3/10)+Skills!N3 | G3: =Skills!F3*IF(Skills!G3>0,Skills!H3/Skills!G3,1) | H3: =1-(1-Skills!I3/100)^Skills!J3 | I3: =IF(Skills!T3<>"",1+(Skills!T3/10)*($Z$3/1000)/100,1) | O3: 0 | P3: =IF(Summary!$B$3=0,0,O3/Summary!$B$3) | Q3: =IFERROR(1/IF(Inputs!$B$4="pvp",15,MAX(0.1,Skills!D3-IF(Skills!E3=TRUE,Inputs!$B$31,0))),0) | R3: =IF(AND(Inputs!$B$4<>"pvp",Inputs!$B$35>0),(INT(Inputs!$B$35/IF(Inputs!$B$4="pvp",15,MAX(0.1,Skills!D3-IF(Skills!E3=TRUE,Inputs!$B$31,0))))+1),0) | Z3: =INDEX(FactorTable!$B$2:$Y$301, MATCH(ROUND(MIN(300,MAX(1,Z2)),0), FactorTable!$A$2:$A$301,0), 24)
A4: =Skills!A4 | B4: =Skills!B4 | C4: =Inputs!$B$3>=38 | D4: =IF(Skills!C4=1,60+Inputs!$B$24+Inputs!$B$28,IF(Skills!C4=2,90+Inputs!$B$25+Inputs!$B$28,IF(Skills!C4=3,120+Inputs!$B$26+Inputs!$B$28,MAX(0,(Inputs!$B$3-100)*3)+Inputs!$B$27+Inputs!$B$28))) | E4: =INDEX(FactorTable!$B$2:$Y$301, MATCH(ROUND(MIN(300,MAX(1,D4)),0), FactorTable!$A$2:$A$301,0), Skills!L4+1) | F4: =IF(Skills!M4=TRUE,(Skills!K4/10)*(E4/1000),Skills!K4/10)+Skills!N4 | G4: =Skills!F4*IF(Skills!G4>0,Skills!H4/Skills!G4,1) | H4: =1-(1-Skills!I4/100)^Skills!J4 | I4: =IF(Skills!T4<>"",1+(Skills!T4/10)*($Z$3/1000)/100,1) | O4: 0 | P4: =IF(Summary!$B$3=0,0,O4/Summary!$B$3) | Q4: =IFERROR(1/IF(Inputs!$B$4="pvp",15,MAX(0.1,Skills!D4-IF(Skills!E4=TRUE,Inputs!$B$31,0))),0) | R4: =IF(AND(Inputs!$B$4<>"pvp",Inputs!$B$35>0),(INT(Inputs!$B$35/IF(Inputs!$B$4="pvp",15,MAX(0.1,Skills!D4-IF(Skills!E4=TRUE,Inputs!$B$31,0))))+1),0)
A5: =Skills!A5 | B5: =Skills!B5 | C5: =Inputs!$B$3>=40 | D5: =IF(Skills!C5=1,60+Inputs!$B$24+Inputs!$B$28,IF(Skills!C5=2,90+Inputs!$B$25+Inputs!$B$28,IF(Skills!C5=3,120+Inputs!$B$26+Inputs!$B$28,MAX(0,(Inputs!$B$3-100)*3)+Inputs!$B$27+Inputs!$B$28))) | E5: =INDEX(FactorTable!$B$2:$Y$301, MATCH(ROUND(MIN(300,MAX(1,D5)),0), FactorTable!$A$2:$A$301,0), Skills!L5+1) | F5: =IF(Skills!M5=TRUE,(Skills!K5/10)*(E5/1000),Skills!K5/10)+Skills!N5 | G5: =Skills!F5*IF(Skills!G5>0,Skills!H5/Skills!G5,1) | H5: =1-(1-Skills!I5/100)^Skills!J5 | I5: =IF(Skills!T5<>"",1+(Skills!T5/10)*($Z$3/1000)/100,1) | O5: 0 | P5: =IF(Summary!$B$3=0,0,O5/Summary!$B$3) | Q5: =IFERROR(1/IF(Inputs!$B$4="pvp",15,MAX(0.1,Skills!D5-IF(Skills!E5=TRUE,Inputs!$B$31,0))),0) | R5: =IF(AND(Inputs!$B$4<>"pvp",Inputs!$B$35>0),(INT(Inputs!$B$35/IF(Inputs!$B$4="pvp",15,MAX(0.1,Skills!D5-IF(Skills!E5=TRUE,Inputs!$B$31,0))))+1),0)
A6: =Skills!A6 | B6: =Skills!B6 | C6: =Inputs!$B$3>=103 | D6: =IF(Skills!C6=1,60+Inputs!$B$24+Inputs!$B$28,IF(Skills!C6=2,90+Inputs!$B$25+Inputs!$B$28,IF(Skills!C6=3,120+Inputs!$B$26+Inputs!$B$28,MAX(0,(Inputs!$B$3-100)*3)+Inputs!$B$27+Inputs!$B$28))) | E6: =INDEX(FactorTable!$B$2:$Y$301, MATCH(ROUND(MIN(300,MAX(1,D6)),0), FactorTable!$A$2:$A$301,0), Skills!L6+1) | F6: =IF(Skills!M6=TRUE,(Skills!K6/10)*(E6/1000),Skills!K6/10)+Skills!N6 | G6: =Skills!F6*IF(Skills!G6>0,Skills!H6/Skills!G6,1) | H6: =1-(1-Skills!I6/100)^Skills!J6 | I6: =IF(Skills!T6<>"",1+(Skills!T6/10)*($Z$3/1000)/100,1) | J6: =Summary!$B$43*(F6/100) | K6: =J6*(1+Summary!$B$44/100)*(1+(Inputs!$B$14+Summary!$B$53)/100)*(1+IF(Inputs!$B$4="pvp",0,(1-Summary!$B$48)*(Inputs!$B$19+Skills!O6+Summary!$B$51)+Summary!$B$48*(Inputs!$B$20+Skills!P6+Summary!$B$52))/100)*(1+Inputs!$B$15/100)*(5000/(6000+Inputs!$B$7*(1-Inputs!$B$18/100)))*(1+Inputs!$B$23/100)*(1+IF(C17=TRUE,F17,0)/100)*(1+IF(C19=TRUE,F19,0)/100)*(1+IF(Skills!A6="TRIUMPH_FEATHER",IF(C15=TRUE,F15,0),0)/100)*(1+IF(C26=TRUE,F26,0)/100)^5*(1+(IF(Skills!A6="BIG_BANG",Inputs!$B$16,Inputs!$B$17))/100)*(Summary!$B$50*I6) | L6: =K6*(MIN(Inputs!$B$21,Inputs!$B$22)/100+Inputs!$B$22/100)/2 | M6: =L6*(1+(Inputs!$B$9+Summary!$B$54)/100) | N6: =L6*(1-MIN(Inputs!$B$8,100)/100)+M6*(MIN(Inputs!$B$8,100)/100) | O6: =IF(C6,H6*N6*IF(AND(Inputs!$B$4<>"pvp",Inputs!$B$35>0),((Skills!F6*((R6-1)*IF(Skills!G6>0,Skills!H6/Skills!G6,1)+IF(Skills!G6>0,MIN(Skills!H6,MAX(0,Inputs!$B$35-((R6-1)*IF(Inputs!$B$4="pvp",15,MAX(0.1,Skills!D6-IF(Skills!E6=TRUE,Inputs!$B$31,0))))))/Skills!G6,1)))/Inputs!$B$35),G6*Q6)*IF(Inputs!$B$4="pvp",1,(1-Summary!$B$48)*(1)+Summary!$B$48*(MIN(Skills!Q6,Inputs!$B$37))),0) | P6: =IF(Summary!$B$3=0,0,O6/Summary!$B$3) | Q6: =IFERROR(1/IF(Inputs!$B$4="pvp",15,MAX(0.1,Skills!D6-IF(Skills!E6=TRUE,Inputs!$B$31,0))),0) | R6: =IF(AND(Inputs!$B$4<>"pvp",Inputs!$B$35>0),(INT(Inputs!$B$35/IF(Inputs!$B$4="pvp",15,MAX(0.1,Skills!D6-IF(Skills!E6=TRUE,Inputs!$B$31,0))))+1),0)
A7: =Skills!A7 | B7: =Skills!B7 | C7: =Inputs!$B$3>=122 | D7: =IF(Skills!C7=1,60+Inputs!$B$24+Inputs!$B$28,IF(Skills!C7=2,90+Inputs!$B$25+Inputs!$B$28,IF(Skills!C7=3,120+Inputs!$B$26+Inputs!$B$28,MAX(0,(Inputs!$B$3-100)*3)+Inputs!$B$27+Inputs!$B$28))) | E7: =INDEX(FactorTable!$B$2:$Y$301, MATCH(ROUND(MIN(300,MAX(1,D7)),0), FactorTable!$A$2:$A$301,0), Skills!L7+1) | F7: =IF(Skills!M7=TRUE,(Skills!K7/10)*(E7/1000),Skills!K7/10)+Skills!N7 | G7: =Skills!F7*IF(Skills!G7>0,Skills!H7/Skills!G7,1) | H7: =1-(1-Skills!I7/100)^Skills!J7 | I7: =IF(Skills!T7<>"",1+(Skills!T7/10)*($Z$3/1000)/100,1) | J7: =Summary!$B$43*(F7/100) | K7: =J7*(1+Summary!$B$44/100)*(1+(Inputs!$B$14+Summary!$B$53)/100)*(1+IF(Inputs!$B$4="pvp",0,(1-Summary!$B$48)*(Inputs!$B$19+Skills!O7+Summary!$B$51)+Summary!$B$48*(Inputs!$B$20+Skills!P7+Summary!$B$52))/100)*(1+Inputs!$B$15/100)*(5000/(6000+Inputs!$B$7*(1-Inputs!$B$18/100)))*(1+Inputs!$B$23/100)*(1+IF(C17=TRUE,F17,0)/100)*(1+IF(C19=TRUE,F19,0)/100)*(1+IF(Skills!A7="TRIUMPH_FEATHER",IF(C15=TRUE,F15,0),0)/100)*(1+IF(C26=TRUE,F26,0)/100)^5*(1+(IF(Skills!A7="BIG_BANG",Inputs!$B$16,Inputs!$B$17))/100)*(Summary!$B$50*I7) | L7: =K7*(MIN(Inputs!$B$21,Inputs!$B$22)/100+Inputs!$B$22/100)/2 | M7: =L7*(1+(Inputs!$B$9+Summary!$B$54)/100) | N7: =L7*(1-MIN(Inputs!$B$8,100)/100)+M7*(MIN(Inputs!$B$8,100)/100) | O7: =IF(C7,H7*N7*IF(AND(Inputs!$B$4<>"pvp",Inputs!$B$35>0),((Skills!F7*((R7-1)*IF(Skills!G7>0,Skills!H7/Skills!G7,1)+IF(Skills!G7>0,MIN(Skills!H7,MAX(0,Inputs!$B$35-((R7-1)*IF(Inputs!$B$4="pvp",15,MAX(0.1,Skills!D7-IF(Skills!E6=TRUE,Inputs!$B$31,0))))))/Skills!G7,1)))/Inputs!$B$35),G7*Q7)*(1-Summary!$B$48),0) | P7: =IF(Summary!$B$3=0,0,O7/Summary!$B$3) | Q7: =IFERROR(1/IF(Inputs!$B$4="pvp",15,MAX(0.1,Skills!D7-IF(Skills!E6=TRUE,Inputs!$B$31,0))),0) | R7: =IF(AND(Inputs!$B$4<>"pvp",Inputs!$B$35>0),(INT(Inputs!$B$35/IF(Inputs!$B$4="pvp",15,MAX(0.1,Skills!D7-IF(Skills!E6=TRUE,Inputs!$B$31,0))))+1),0)
A8: =Skills!A8 | B8: =Skills!B8 | C8: =Inputs!$B$3>=105 | D8: =IF(Skills!C8=1,60+Inputs!$B$24+Inputs!$B$28,IF(Skills!C8=2,90+Inputs!$B$25+Inputs!$B$28,IF(Skills!C8=3,120+Inputs!$B$26+Inputs!$B$28,MAX(0,(Inputs!$B$3-100)*3)+Inputs!$B$27+Inputs!$B$28))) | E8: =INDEX(FactorTable!$B$2:$Y$301, MATCH(ROUND(MIN(300,MAX(1,D8)),0), FactorTable!$A$2:$A$301,0), Skills!L8+1) | F8: =IF(Skills!M8=TRUE,(Skills!K8/10)*(E8/1000),Skills!K8/10)+Skills!N8 | G8: =Skills!F8*IF(Skills!G8>0,Skills!H8/Skills!G8,1) | H8: =1-(1-Skills!I8/100)^Skills!J8 | I8: =IF(Skills!T8<>"",1+(Skills!T8/10)*($Z$3/1000)/100,1) | J8: =Summary!$B$43*(F8/100) | K8: =J8*(1+Summary!$B$44/100)*(1+(Inputs!$B$14+Summary!$B$53)/100)*(1+IF(Inputs!$B$4="pvp",0,(1-Summary!$B$48)*(Inputs!$B$19+Skills!O8+Summary!$B$51)+Summary!$B$48*(Inputs!$B$20+Skills!P8+Summary!$B$52))/100)*(1+Inputs!$B$15/100)*(5000/(6000+Inputs!$B$7*(1-Inputs!$B$18/100)))*(1+Inputs!$B$23/100)*(1+IF(C17=TRUE,F17,0)/100)*(1+IF(C19=TRUE,F19,0)/100)*(1+IF(Skills!A8="TRIUMPH_FEATHER",IF(C15=TRUE,F15,0),0)/100)*(1+IF(C26=TRUE,F26,0)/100)^5*(1+(IF(Skills!A8="BIG_BANG",Inputs!$B$16,Inputs!$B$17))/100)*(Summary!$B$50*I8) | L8: =K8*(MIN(Inputs!$B$21,Inputs!$B$22)/100+Inputs!$B$22/100)/2 | M8: =L8*(1+(Inputs!$B$9+Summary!$B$54)/100) | N8: =L8*(1-MIN(Inputs!$B$8,100)/100)+M8*(MIN(Inputs!$B$8,100)/100) | O8: =IF(C8,H8*N8*IF(AND(Inputs!$B$4<>"pvp",Inputs!$B$35>0),((Skills!F8*((R8-1)*IF(Skills!G8>0,Skills!H8/Skills!G8,1)+IF(Skills!G8>0,MIN(Skills!H8,MAX(0,Inputs!$B$35-((R8-1)*IF(Inputs!$B$4="pvp",15,MAX(0.1,Skills!D8-IF(Skills!E8=TRUE,Inputs!$B$31,0))))))/Skills!G8,1)))/Inputs!$B$35),G8*Q8)*IF(Inputs!$B$4="pvp",1,(1-Summary!$B$48)*(1)+Summary!$B$48*(MIN(Skills!Q8,Inputs!$B$37))),0) | P8: =IF(Summary!$B$3=0,0,O8/Summary!$B$3) | Q8: =IFERROR(1/IF(Inputs!$B$4="pvp",15,MAX(0.1,Skills!D8-IF(Skills!E8=TRUE,Inputs!$B$31,0))),0) | R8: =IF(AND(Inputs!$B$4<>"pvp",Inputs!$B$35>0),(INT(Inputs!$B$35/IF(Inputs!$B$4="pvp",15,MAX(0.1,Skills!D8-IF(Skills!E8=TRUE,Inputs!$B$31,0))))+1),0)
A9: =Skills!A9 | B9: =Skills!B9 | C9: =Inputs!$B$3>=115 | D9: =IF(Skills!C9=1,60+Inputs!$B$24+Inputs!$B$28,IF(Skills!C9=2,90+Inputs!$B$25+Inputs!$B$28,IF(Skills!C9=3,120+Inputs!$B$26+Inputs!$B$28,MAX(0,(Inputs!$B$3-100)*3)+Inputs!$B$27+Inputs!$B$28))) | E9: =INDEX(FactorTable!$B$2:$Y$301, MATCH(ROUND(MIN(300,MAX(1,D9)),0), FactorTable!$A$2:$A$301,0), Skills!L9+1) | F9: =IF(Skills!M9=TRUE,(Skills!K9/10)*(E9/1000),Skills!K9/10)+Skills!N9 | G9: =Skills!F9*IF(Skills!G9>0,Skills!H9/Skills!G9,1) | H9: =1-(1-Skills!I9/100)^Skills!J9 | I9: =IF(Skills!T9<>"",1+(Skills!T9/10)*($Z$3/1000)/100,1) | J9: =Summary!$B$43*(F9/100) | K9: =J9*(1+Summary!$B$44/100)*(1+(Inputs!$B$14+Summary!$B$53)/100)*(1+IF(Inputs!$B$4="pvp",0,(1-Summary!$B$48)*(Inputs!$B$19+Skills!O9+Summary!$B$51)+Summary!$B$48*(Inputs!$B$20+Skills!P9+Summary!$B$52))/100)*(1+Inputs!$B$15/100)*(5000/(6000+Inputs!$B$7*(1-Inputs!$B$18/100)))*(1+Inputs!$B$23/100)*(1+IF(C17=TRUE,F17,0)/100)*(1+IF(C19=TRUE,F19,0)/100)*(1+IF(Skills!A9="TRIUMPH_FEATHER",IF(C15=TRUE,F15,0),0)/100)*(1+IF(C26=TRUE,F26,0)/100)^5*(1+(IF(Skills!A9="BIG_BANG",Inputs!$B$16,Inputs!$B$17))/100)*(Summary!$B$50*I9) | L9: =K9*(MIN(Inputs!$B$21,Inputs!$B$22)/100+Inputs!$B$22/100)/2 | M9: =L9*(1+(Inputs!$B$9+Summary!$B$54)/100) | N9: =L9*(1-MIN(Inputs!$B$8,100)/100)+M9*(MIN(Inputs!$B$8,100)/100) | O9: =IF(C9,H9*N9*IF(AND(Inputs!$B$4<>"pvp",Inputs!$B$35>0),((Skills!F9*((R9-1)*IF(Skills!G9>0,Skills!H9/Skills!G9,1)+IF(Skills!G9>0,MIN(Skills!H9,MAX(0,Inputs!$B$35-((R9-1)*IF(Inputs!$B$4="pvp",15,MAX(0.1,Skills!D9-IF(Skills!E9=TRUE,Inputs!$B$31,0))))))/Skills!G9,1)))/Inputs!$B$35),G9*Q9)*IF(Inputs!$B$4="pvp",1,(1-Summary!$B$48)*(1)+Summary!$B$48*(MIN(Skills!Q9,Inputs!$B$37))),0) | P9: =IF(Summary!$B$3=0,0,O9/Summary!$B$3) | Q9: =IFERROR(1/IF(Inputs!$B$4="pvp",15,MAX(0.1,Skills!D9-IF(Skills!E9=TRUE,Inputs!$B$31,0))),0) | R9: =IF(AND(Inputs!$B$4<>"pvp",Inputs!$B$35>0),(INT(Inputs!$B$35/IF(Inputs!$B$4="pvp",15,MAX(0.1,Skills!D9-IF(Skills!E9=TRUE,Inputs!$B$31,0))))+1),0)
A10: =Skills!A10 | B10: =Skills!B10 | C10: =Inputs!$B$3>=66 | D10: =IF(Skills!C10=1,60+Inputs!$B$24+Inputs!$B$28,IF(Skills!C10=2,90+Inputs!$B$25+Inputs!$B$28,IF(Skills!C10=3,120+Inputs!$B$26+Inputs!$B$28,MAX(0,(Inputs!$B$3-100)*3)+Inputs!$B$27+Inputs!$B$28))) | E10: =INDEX(FactorTable!$B$2:$Y$301, MATCH(ROUND(MIN(300,MAX(1,D10)),0), FactorTable!$A$2:$A$301,0), Skills!L10+1) | F10: 0 | G10: =Skills!F10*IF(Skills!G10>0,Skills!H10/Skills!G10,1) | H10: =1-(1-Skills!I10/100)^Skills!J10 | I10: =IF(Skills!T10<>"",1+(Skills!T10/10)*($Z$3/1000)/100,1) | O10: 0 | P10: =IF(Summary!$B$3=0,0,O10/Summary!$B$3) | Q10: =IFERROR(1/IF(Inputs!$B$4="pvp",15,MAX(0.1,Skills!D10-IF(Skills!E10=TRUE,Inputs!$B$31,0))),0) | R10: =IF(AND(Inputs!$B$4<>"pvp",Inputs!$B$35>0),(INT(Inputs!$B$35/IF(Inputs!$B$4="pvp",15,MAX(0.1,Skills!D10-IF(Skills!E10=TRUE,Inputs!$B$31,0))))+1),0)
A11: =Skills!A11 | B11: =Skills!B11 | C11: =Inputs!$B$3>=69 | D11: =IF(Skills!C11=1,60+Inputs!$B$24+Inputs!$B$28,IF(Skills!C11=2,90+Inputs!$B$25+Inputs!$B$28,IF(Skills!C11=3,120+Inputs!$B$26+Inputs!$B$28,MAX(0,(Inputs!$B$3-100)*3)+Inputs!$B$27+Inputs!$B$28))) | E11: =INDEX(FactorTable!$B$2:$Y$301, MATCH(ROUND(MIN(300,MAX(1,D11)),0), FactorTable!$A$2:$A$301,0), Skills!L11+1) | F11: =IF(Skills!M11=TRUE,(Skills!K11/10)*(E11/1000),Skills!K11/10)+Skills!N11 | G11: =Skills!F11*IF(Skills!G11>0,Skills!H11/Skills!G11,1) | H11: =1-(1-Skills!I11/100)^Skills!J11 | I11: =IF(Skills!T11<>"",1+(Skills!T11/10)*($Z$3/1000)/100,1) | O11: 0 | P11: =IF(Summary!$B$3=0,0,O11/Summary!$B$3) | Q11: =IFERROR(1/IF(Inputs!$B$4="pvp",15,MAX(0.1,Skills!D11-IF(Skills!E11=TRUE,Inputs!$B$31,0))),0) | R11: =IF(AND(Inputs!$B$4<>"pvp",Inputs!$B$35>0),(INT(Inputs!$B$35/IF(Inputs!$B$4="pvp",15,MAX(0.1,Skills!D11-IF(Skills!E11=TRUE,Inputs!$B$31,0))))+1),0)
A12: =Skills!A12 | B12: =Skills!B12 | C12: =Inputs!$B$3>=72 | D12: =IF(Skills!C12=1,60+Inputs!$B$24+Inputs!$B$28,IF(Skills!C12=2,90+Inputs!$B$25+Inputs!$B$28,IF(Skills!C12=3,120+Inputs!$B$26+Inputs!$B$28,MAX(0,(Inputs!$B$3-100)*3)+Inputs!$B$27+Inputs!$B$28))) | E12: =INDEX(FactorTable!$B$2:$Y$301, MATCH(ROUND(MIN(300,MAX(1,D12)),0), FactorTable!$A$2:$A$301,0), Skills!L12+1) | F12: =IF(Skills!M12=TRUE,(Skills!K12/10)*(E12/1000),Skills!K12/10)+Skills!N12 | G12: =Skills!F12*IF(Skills!G12>0,Skills!H12/Skills!G12,1) | H12: =1-(1-Skills!I12/100)^Skills!J12 | I12: =IF(Skills!T12<>"",1+(Skills!T12/10)*($Z$3/1000)/100,1) | O12: 0 | P12: =IF(Summary!$B$3=0,0,O12/Summary!$B$3) | Q12: =IFERROR(1/IF(Inputs!$B$4="pvp",15,MAX(0.1,Skills!D12-IF(Skills!E12=TRUE,Inputs!$B$31,0))),0) | R12: =IF(AND(Inputs!$B$4<>"pvp",Inputs!$B$35>0),(INT(Inputs!$B$35/IF(Inputs!$B$4="pvp",15,MAX(0.1,Skills!D12-IF(Skills!E12=TRUE,Inputs!$B$31,0))))+1),0)
A13: =Skills!A13 | B13: =Skills!B13 | C13: =Inputs!$B$3>=107 | D13: =IF(Skills!C13=1,60+Inputs!$B$24+Inputs!$B$28,IF(Skills!C13=2,90+Inputs!$B$25+Inputs!$B$28,IF(Skills!C13=3,120+Inputs!$B$26+Inputs!$B$28,MAX(0,(Inputs!$B$3-100)*3)+Inputs!$B$27+Inputs!$B$28))) | E13: =INDEX(FactorTable!$B$2:$Y$301, MATCH(ROUND(MIN(300,MAX(1,D13)),0), FactorTable!$A$2:$A$301,0), Skills!L13+1) | F13: =IF(Skills!M13=TRUE,(Skills!K13/10)*(E13/1000),Skills!K13/10)+Skills!N13 | G13: =Skills!F13*IF(Skills!G13>0,Skills!H13/Skills!G13,1) | H13: =1-(1-Skills!I13/100)^Skills!J13 | I13: =IF(Skills!T13<>"",1+(Skills!T13/10)*($Z$3/1000)/100,1) | O13: 0 | P13: =IF(Summary!$B$3=0,0,O13/Summary!$B$3) | Q13: =IFERROR(1/IF(Inputs!$B$4="pvp",15,MAX(0.1,Skills!D13-IF(Skills!E13=TRUE,Inputs!$B$31,0))),0) | R13: =IF(AND(Inputs!$B$4<>"pvp",Inputs!$B$35>0),(INT(Inputs!$B$35/IF(Inputs!$B$4="pvp",15,MAX(0.1,Skills!D13-IF(Skills!E13=TRUE,Inputs!$B$31,0))))+1),0)
A14: =Skills!A14 | B14: =Skills!B14 | C14: =Inputs!$B$3>=63 | D14: =IF(Skills!C14=1,60+Inputs!$B$24+Inputs!$B$28,IF(Skills!C14=2,90+Inputs!$B$25+Inputs!$B$28,IF(Skills!C14=3,120+Inputs!$B$26+Inputs!$B$28,MAX(0,(Inputs!$B$3-100)*3)+Inputs!$B$27+Inputs!$B$28))) | E14: =INDEX(FactorTable!$B$2:$Y$301, MATCH(ROUND(MIN(300,MAX(1,D14)),0), FactorTable!$A$2:$A$301,0), Skills!L14+1) | F14: =IF(Skills!M14=TRUE,(Skills!K14/10)*(E14/1000),Skills!K14/10)+Skills!N14 | G14: =Skills!F14*IF(Skills!G14>0,Skills!H14/Skills!G14,1) | H14: =1-(1-Skills!I14/100)^Skills!J14 | I14: =IF(Skills!T14<>"",1+(Skills!T14/10)*($Z$3/1000)/100,1) | J14: =Summary!$B$43*(F14/100) | K14: =J14*(1+Summary!$B$44/100)*(1+(Inputs!$B$14+Summary!$B$53)/100)*(1+IF(Inputs!$B$4="pvp",0,(1-Summary!$B$48)*(Inputs!$B$19+Skills!O14+Summary!$B$51)+Summary!$B$48*(Inputs!$B$20+Skills!P14+Summary!$B$52))/100)*(1+Inputs!$B$15/100)*(5000/(6000+Inputs!$B$7*(1-Inputs!$B$18/100)))*(1+Inputs!$B$23/100)*(1+IF(C17=TRUE,F17,0)/100)*(1+IF(C19=TRUE,F19,0)/100)*(1+IF(Skills!A14="TRIUMPH_FEATHER",IF(C15=TRUE,F15,0),0)/100)*(1+IF(C26=TRUE,F26,0)/100)^5*(1+(IF(Skills!A14="BIG_BANG",Inputs!$B$16,Inputs!$B$17))/100)*(Summary!$B$50*I14) | L14: =K14*(MIN(Inputs!$B$21,Inputs!$B$22)/100+Inputs!$B$22/100)/2 | M14: =L14*(1+(Inputs!$B$9+Summary!$B$54)/100) | N14: =L14*(1-MIN(Inputs!$B$8,100)/100)+M14*(MIN(Inputs!$B$8,100)/100) | O14: =IF(C14,Skills!F14*N14*((IF(Inputs!$B$3>=78,25,15)/100*Summary!$B$56*10)/(1+IF(Inputs!$B$3>=78,25,15)/100*Summary!$B$56*10))*(Skills!I14/100*Summary!$B$56)/(1+Skills!G14*Skills!I14/100*Summary!$B$56)*IF(Inputs!$B$4="pvp",1,(1-Summary!$B$48)*(1)+Summary!$B$48*(MIN(Skills!Q14,Inputs!$B$37))),0) | P14: =IF(Summary!$B$3=0,0,O14/Summary!$B$3) | Q14: =IFERROR(1/IF(Inputs!$B$4="pvp",15,MAX(0.1,Skills!D14-IF(Skills!E14=TRUE,Inputs!$B$31,0))),0) | R14: 0
A15: =Skills!A15 | B15: =Skills!B15 | C15: =Inputs!$B$3>=100 | D15: =IF(Skills!C15=1,60+Inputs!$B$24+Inputs!$B$28,IF(Skills!C15=2,90+Inputs!$B$25+Inputs!$B$28,IF(Skills!C15=3,120+Inputs!$B$26+Inputs!$B$28,MAX(0,(Inputs!$B$3-100)*3)+Inputs!$B$27+Inputs!$B$28))) | E15: =INDEX(FactorTable!$B$2:$Y$301, MATCH(ROUND(MIN(300,MAX(1,D15)),0), FactorTable!$A$2:$A$301,0), Skills!L15+1) | F15: =IF(Skills!M15=TRUE,(Skills!K15/10)*(E15/1000),Skills!K15/10)+Skills!N15 | G15: =Skills!F15*IF(Skills!G15>0,Skills!H15/Skills!G15,1) | H15: =1-(1-Skills!I15/100)^Skills!J15 | I15: =IF(Skills!T15<>"",1+(Skills!T15/10)*($Z$3/1000)/100,1) | O15: 0 | P15: =IF(Summary!$B$3=0,0,O15/Summary!$B$3) | Q15: =IFERROR(1/IF(Inputs!$B$4="pvp",15,MAX(0.1,Skills!D15-IF(Skills!E15=TRUE,Inputs!$B$31,0))),0) | R15: 0
A16: =Skills!A16 | B16: =Skills!B16 | C16: =Inputs!$B$3>=49 | D16: =IF(Skills!C16=1,60+Inputs!$B$24+Inputs!$B$28,IF(Skills!C16=2,90+Inputs!$B$25+Inputs!$B$28,IF(Skills!C16=3,120+Inputs!$B$26+Inputs!$B$28,MAX(0,(Inputs!$B$3-100)*3)+Inputs!$B$27+Inputs!$B$28))) | E16: =INDEX(FactorTable!$B$2:$Y$301, MATCH(ROUND(MIN(300,MAX(1,D16)),0), FactorTable!$A$2:$A$301,0), Skills!L16+1) | F16: =IF(Skills!M16=TRUE,(Skills!K16/10)*(E16/1000),Skills!K16/10)+Skills!N16 | G16: =Skills!F16*IF(Skills!G16>0,Skills!H16/Skills!G16,1) | H16: =1-(1-Skills!I16/100)^Skills!J16 | I16: =IF(Skills!T16<>"",1+(Skills!T16/10)*($Z$3/1000)/100,1) | O16: 0 | P16: =IF(Summary!$B$3=0,0,O16/Summary!$B$3) | Q16: =IFERROR(1/IF(Inputs!$B$4="pvp",15,MAX(0.1,Skills!D16-IF(Skills!E16=TRUE,Inputs!$B$31,0))),0) | R16: 0
A17: =Skills!A17 | B17: =Skills!B17 | C17: =Inputs!$B$3>=75 | D17: =IF(Skills!C17=1,60+Inputs!$B$24+Inputs!$B$28,IF(Skills!C17=2,90+Inputs!$B$25+Inputs!$B$28,IF(Skills!C17=3,120+Inputs!$B$26+Inputs!$B$28,MAX(0,(Inputs!$B$3-100)*3)+Inputs!$B$27+Inputs!$B$28))) | E17: =INDEX(FactorTable!$B$2:$Y$301, MATCH(ROUND(MIN(300,MAX(1,D17)),0), FactorTable!$A$2:$A$301,0), Skills!L17+1) | F17: =IF(Skills!M17=TRUE,(Skills!K17/10)*(E17/1000),Skills!K17/10)+Skills!N17 | G17: =Skills!F17*IF(Skills!G17>0,Skills!H17/Skills!G17,1) | H17: =1-(1-Skills!I17/100)^Skills!J17 | I17: =IF(Skills!T17<>"",1+(Skills!T17/10)*($Z$3/1000)/100,1) | O17: 0 | P17: =IF(Summary!$B$3=0,0,O17/Summary!$B$3) | Q17: =IFERROR(1/IF(Inputs!$B$4="pvp",15,MAX(0.1,Skills!D17-IF(Skills!E17=TRUE,Inputs!$B$31,0))),0) | R17: 0
A18: =Skills!A18 | B18: =Skills!B18 | C18: =Inputs!$B$3>=110 | D18: =IF(Skills!C18=1,60+Inputs!$B$24+Inputs!$B$28,IF(Skills!C18=2,90+Inputs!$B$25+Inputs!$B$28,IF(Skills!C18=3,120+Inputs!$B$26+Inputs!$B$28,MAX(0,(Inputs!$B$3-100)*3)+Inputs!$B$27+Inputs!$B$28))) | E18: =INDEX(FactorTable!$B$2:$Y$301, MATCH(ROUND(MIN(300,MAX(1,D18)),0), FactorTable!$A$2:$A$301,0), Skills!L18+1) | F18: =(Skills!K18/10)*(E18/1000)*64/45+Skills!N18 | G18: =Skills!F18*IF(Skills!G18>0,Skills!H18/Skills!G18,1) | H18: =1-(1-Skills!I18/100)^Skills!J18 | I18: =IF(Skills!T18<>"",1+(Skills!T18/10)*($Z$3/1000)/100,1) | O18: 0 | P18: =IF(Summary!$B$3=0,0,O18/Summary!$B$3) | Q18: =IFERROR(1/IF(Inputs!$B$4="pvp",15,MAX(0.1,Skills!D18-IF(Skills!E18=TRUE,Inputs!$B$31,0))),0) | R18: =IF(AND(Inputs!$B$4<>"pvp",Inputs!$B$35>0),(INT(Inputs!$B$35/IF(Inputs!$B$4="pvp",15,MAX(0.1,Skills!D18-IF(Skills!E18=TRUE,Inputs!$B$31,0))))+1),0)
A19: =Skills!A19 | B19: =Skills!B19 | C19: =Inputs!$B$3>=125 | D19: =IF(Skills!C19=1,60+Inputs!$B$24+Inputs!$B$28,IF(Skills!C19=2,90+Inputs!$B$25+Inputs!$B$28,IF(Skills!C19=3,120+Inputs!$B$26+Inputs!$B$28,MAX(0,(Inputs!$B$3-100)*3)+Inputs!$B$27+Inputs!$B$28))) | E19: =INDEX(FactorTable!$B$2:$Y$301, MATCH(ROUND(MIN(300,MAX(1,D19)),0), FactorTable!$A$2:$A$301,0), Skills!L19+1) | F19: =IF(Skills!M19=TRUE,(Skills!K19/10)*(E19/1000),Skills!K19/10)+Skills!N19 | G19: =Skills!F19*IF(Skills!G19>0,Skills!H19/Skills!G19,1) | H19: =1-(1-Skills!I19/100)^Skills!J19 | I19: =IF(Skills!T19<>"",1+(Skills!T19/10)*($Z$3/1000)/100,1) | O19: 0 | P19: =IF(Summary!$B$3=0,0,O19/Summary!$B$3) | Q19: =IFERROR(1/IF(Inputs!$B$4="pvp",15,MAX(0.1,Skills!D19-IF(Skills!E19=TRUE,Inputs!$B$31,0))),0) | R19: 0
A20: =Skills!A20 | B20: =Skills!B20 | C20: =Inputs!$B$3>=33 | D20: =IF(Skills!C20=1,60+Inputs!$B$24+Inputs!$B$28,IF(Skills!C20=2,90+Inputs!$B$25+Inputs!$B$28,IF(Skills!C20=3,120+Inputs!$B$26+Inputs!$B$28,MAX(0,(Inputs!$B$3-100)*3)+Inputs!$B$27+Inputs!$B$28))) | E20: =INDEX(FactorTable!$B$2:$Y$301, MATCH(ROUND(MIN(300,MAX(1,D20)),0), FactorTable!$A$2:$A$301,0), Skills!L20+1) | F20: =IF(Skills!M20=TRUE,(Skills!K20/10)*(E20/1000),Skills!K20/10)+Skills!N20 | G20: =Skills!F20*IF(Skills!G20>0,Skills!H20/Skills!G20,1) | H20: =1-(1-Skills!I20/100)^Skills!J20 | I20: =IF(Skills!T20<>"",1+(Skills!T20/10)*($Z$3/1000)/100,1) | O20: 0 | P20: =IF(Summary!$B$3=0,0,O20/Summary!$B$3) | Q20: =IFERROR(1/IF(Inputs!$B$4="pvp",15,MAX(0.1,Skills!D20-IF(Skills!E20=TRUE,Inputs!$B$31,0))),0) | R20: 0
A21: =Skills!A21 | B21: =Skills!B21 | C21: =Inputs!$B$3>=43 | D21: =IF(Skills!C21=1,60+Inputs!$B$24+Inputs!$B$28,IF(Skills!C21=2,90+Inputs!$B$25+Inputs!$B$28,IF(Skills!C21=3,120+Inputs!$B$26+Inputs!$B$28,MAX(0,(Inputs!$B$3-100)*3)+Inputs!$B$27+Inputs!$B$28))) | E21: =INDEX(FactorTable!$B$2:$Y$301, MATCH(ROUND(MIN(300,MAX(1,D21)),0), FactorTable!$A$2:$A$301,0), Skills!L21+1) | F21: =IF(Skills!M21=TRUE,(Skills!K21/10)*(E21/1000),Skills!K21/10)+Skills!N21 | G21: =Skills!F21*IF(Skills!G21>0,Skills!H21/Skills!G21,1) | H21: =1-(1-Skills!I21/100)^Skills!J21 | I21: =IF(Skills!T21<>"",1+(Skills!T21/10)*($Z$3/1000)/100,1) | O21: 0 | P21: =IF(Summary!$B$3=0,0,O21/Summary!$B$3) | Q21: =IFERROR(1/IF(Inputs!$B$4="pvp",15,MAX(0.1,Skills!D21-IF(Skills!E21=TRUE,Inputs!$B$31,0))),0) | R21: 0
A22: =Skills!A22 | B22: =Skills!B22 | C22: =Inputs!$B$3>=50 | D22: =IF(Skills!C22=1,60+Inputs!$B$24+Inputs!$B$28,IF(Skills!C22=2,90+Inputs!$B$25+Inputs!$B$28,IF(Skills!C22=3,120+Inputs!$B$26+Inputs!$B$28,MAX(0,(Inputs!$B$3-100)*3)+Inputs!$B$27+Inputs!$B$28))) | E22: =INDEX(FactorTable!$B$2:$Y$301, MATCH(ROUND(MIN(300,MAX(1,D22)),0), FactorTable!$A$2:$A$301,0), Skills!L22+1) | F22: =IF(Skills!M22=TRUE,(Skills!K22/10)*(E22/1000),Skills!K22/10)+Skills!N22 | G22: =Skills!F22*IF(Skills!G22>0,Skills!H22/Skills!G22,1) | H22: =1-(1-Skills!I22/100)^Skills!J22 | I22: =IF(Skills!T22<>"",1+(Skills!T22/10)*($Z$3/1000)/100,1) | O22: 0 | P22: =IF(Summary!$B$3=0,0,O22/Summary!$B$3) | Q22: =IFERROR(1/IF(Inputs!$B$4="pvp",15,MAX(0.1,Skills!D22-IF(Skills!E22=TRUE,Inputs!$B$31,0))),0) | R22: 0
A23: =Skills!A23 | B23: =Skills!B23 | C23: =Inputs!$B$3>=74 | D23: =IF(Skills!C23=1,60+Inputs!$B$24+Inputs!$B$28,IF(Skills!C23=2,90+Inputs!$B$25+Inputs!$B$28,IF(Skills!C23=3,120+Inputs!$B$26+Inputs!$B$28,MAX(0,(Inputs!$B$3-100)*3)+Inputs!$B$27+Inputs!$B$28))) | E23: =INDEX(FactorTable!$B$2:$Y$301, MATCH(ROUND(MIN(300,MAX(1,D23)),0), FactorTable!$A$2:$A$301,0), Skills!L23+1) | F23: =IF(Skills!M23=TRUE,(Skills!K23/10)*(E23/1000),Skills!K23/10)+Skills!N23 | G23: =Skills!F23*IF(Skills!G23>0,Skills!H23/Skills!G23,1) | H23: =1-(1-Skills!I23/100)^Skills!J23 | I23: =IF(Skills!T23<>"",1+(Skills!T23/10)*($Z$3/1000)/100,1) | O23: 0 | P23: =IF(Summary!$B$3=0,0,O23/Summary!$B$3) | Q23: =IFERROR(1/IF(Inputs!$B$4="pvp",15,MAX(0.1,Skills!D23-IF(Skills!E23=TRUE,Inputs!$B$31,0))),0) | R23: 0
A24: =Skills!A24 | B24: =Skills!B24 | C24: =Inputs!$B$3>=74 | D24: =IF(Skills!C24=1,60+Inputs!$B$24+Inputs!$B$28,IF(Skills!C24=2,90+Inputs!$B$25+Inputs!$B$28,IF(Skills!C24=3,120+Inputs!$B$26+Inputs!$B$28,MAX(0,(Inputs!$B$3-100)*3)+Inputs!$B$27+Inputs!$B$28))) | E24: =INDEX(FactorTable!$B$2:$Y$301, MATCH(ROUND(MIN(300,MAX(1,D24)),0), FactorTable!$A$2:$A$301,0), Skills!L24+1) | F24: =IF(Skills!M24=TRUE,(Skills!K24/10)*(E24/1000),Skills!K24/10)+Skills!N24 | G24: =Skills!F24*IF(Skills!G24>0,Skills!H24/Skills!G24,1) | H24: =1-(1-Skills!I24/100)^Skills!J24 | I24: =IF(Skills!T24<>"",1+(Skills!T24/10)*($Z$3/1000)/100,1) | O24: 0 | P24: =IF(Summary!$B$3=0,0,O24/Summary!$B$3) | Q24: =IFERROR(1/IF(Inputs!$B$4="pvp",15,MAX(0.1,Skills!D24-IF(Skills!E24=TRUE,Inputs!$B$31,0))),0) | R24: 0
A25: =Skills!A25 | B25: =Skills!B25 | C25: =Inputs!$B$3>=117 | D25: =IF(Skills!C25=1,60+Inputs!$B$24+Inputs!$B$28,IF(Skills!C25=2,90+Inputs!$B$25+Inputs!$B$28,IF(Skills!C25=3,120+Inputs!$B$26+Inputs!$B$28,MAX(0,(Inputs!$B$3-100)*3)+Inputs!$B$27+Inputs!$B$28))) | E25: =INDEX(FactorTable!$B$2:$Y$301, MATCH(ROUND(MIN(300,MAX(1,D25)),0), FactorTable!$A$2:$A$301,0), Skills!L25+1) | F25: =IF(Skills!M25=TRUE,(Skills!K25/10)*(E25/1000),Skills!K25/10)+Skills!N25 | G25: =Skills!F25*IF(Skills!G25>0,Skills!H25/Skills!G25,1) | H25: =1-(1-Skills!I25/100)^Skills!J25 | I25: =IF(Skills!T25<>"",1+(Skills!T25/10)*($Z$3/1000)/100,1) | O25: 0 | P25: =IF(Summary!$B$3=0,0,O25/Summary!$B$3) | Q25: =IFERROR(1/IF(Inputs!$B$4="pvp",15,MAX(0.1,Skills!D25-IF(Skills!E25=TRUE,Inputs!$B$31,0))),0) | R25: 0
A26: =Skills!A26 | B26: =Skills!B26 | C26: =Inputs!$B$3>=120 | D26: =IF(Skills!C26=1,60+Inputs!$B$24+Inputs!$B$28,IF(Skills!C26=2,90+Inputs!$B$25+Inputs!$B$28,IF(Skills!C26=3,120+Inputs!$B$26+Inputs!$B$28,MAX(0,(Inputs!$B$3-100)*3)+Inputs!$B$27+Inputs!$B$28))) | E26: =INDEX(FactorTable!$B$2:$Y$301, MATCH(ROUND(MIN(300,MAX(1,D26)),0), FactorTable!$A$2:$A$301,0), Skills!L26+1) | F26: =IF(Skills!M26=TRUE,(Skills!K26/10)*(E26/1000),Skills!K26/10)+Skills!N26 | G26: =Skills!F26*IF(Skills!G26>0,Skills!H26/Skills!G26,1) | H26: =1-(1-Skills!I26/100)^Skills!J26 | I26: =IF(Skills!T26<>"",1+(Skills!T26/10)*($Z$3/1000)/100,1) | O26: 0 | P26: =IF(Summary!$B$3=0,0,O26/Summary!$B$3) | Q26: =IFERROR(1/IF(Inputs!$B$4="pvp",15,MAX(0.1,Skills!D26-IF(Skills!E26=TRUE,Inputs!$B$31,0))),0) | R26: 0

Sheet Summary
A1: Bishop — DPS Summary
A3: TOTAL DPS | B3: =SUM(Calc!O2:O26)
A5: Per-Skill DPS Breakdown
A6: Skill | B6: DPS | C6: % of Total
A7: =Calc!B2 | B7: =Calc!O2 | C7: =Calc!P2*100
A8: =Calc!B6 | B8: =Calc!O6 | C8: =Calc!P6*100
A9: =Calc!B7 | B9: =Calc!O7 | C9: =Calc!P7*100
A10: =Calc!B8 | B10: =Calc!O8 | C10: =Calc!P8*100
A11: =Calc!B9 | B11: =Calc!O9 | C11: =Calc!P9*100
A12: =Calc!B14 | B12: =Calc!O14 | C12: =Calc!P14*100
A13: Marginal DPS & Stat Value (see Sensitivity for full detail)
A15: Stat | B15: DPS per +1 | C15: Units per +1% DPS
A16: =Sensitivity!A5 | B16: =Sensitivity!H5 | C16: =Sensitivity!B5
A17: =Sensitivity!A6 | B17: =Sensitivity!H6 | C17: =Sensitivity!B6
A18: =Sensitivity!A7 | B18: =Sensitivity!H7 | C18: =Sensitivity!B7
A19: =Sensitivity!A8 | B19: =Sensitivity!H8 | C19: =Sensitivity!B8
A20: =Sensitivity!A9 | B20: =Sensitivity!H9 | C20: =Sensitivity!B9
A21: =Sensitivity!A10 | B21: =Sensitivity!H10 | C21: =Sensitivity!B10
A22: =Sensitivity!A11 | B22: =Sensitivity!H11 | C22: =Sensitivity!B11
A23: =Sensitivity!A12 | B23: =Sensitivity!H12 | C23: =Sensitivity!B12
A24: =Sensitivity!A13 | B24: =Sensitivity!H13 | C24: =Sensitivity!B13
A25: =Sensitivity!A14 | B25: =Sensitivity!H14 | C25: =Sensitivity!B14
A26: =Sensitivity!A15 | B26: =Sensitivity!H15 | C26: =Sensitivity!B15
A27: =Sensitivity!A16 | B27: =Sensitivity!H16 | C27: =Sensitivity!B16
... A40: =Sensitivity!A29 | B40: =Sensitivity!H29 | C40: =Sensitivity!B29
A42: Derived Values (read-only, computed from Inputs)
A43: ATTACK (= Flat ATTACK x (1+ATTACK%/100)) | B43: =Inputs!$B$5*(1+Inputs!$B$6/100)
A44: STAT_DAMAGE % (= 1% of total INT + 0.25% of LUK) | B44: =(Inputs!$B$11*(1+Inputs!$B$12/100))*0.01+Inputs!$B$13*0.0025
A45: Basic Attack (Big Bang) Input Level (4th job formula) | B45: =MAX(0,(Inputs!$B$3-100)*3)+Inputs!$B$27+Inputs!$B$28
A46: Basic Attack Factor (factorIndex 21, from Big Bang == Chain Lightning reuse) | B46: =INDEX(FactorTable!$B$2:$Y$301, MATCH(ROUND(MIN(300,MAX(1,Summary!$B$45)),0), FactorTable!$A$2:$A$301,0), 22)
A47: SKILL_COEFFICIENT — Big Bang base coefficient % (before Skill Mastery) | B47: =290*Summary!$B$46/1000
A48: Normal-Monster Weight (= 0 for boss, 1 for normal, Breakthrough Normal Weight % for breakthrough, 0 for pvp) | B48: =IF(Inputs!$B$4="normal",1,IF(Inputs!$B$4="breakthrough",Inputs!$B$36/100,0))
