Workbook

Sheet README
A1: Buccaneer — DPS Calculator: How to Use This Workbook
A3: How to use this workbook
A4: Only edit the yellow-highlighted cells on the Inputs sheet — every other sheet is computed from those values and will be overwritten if you rebuild the workbook.
A5: Summary shows Total DPS, a Per-Skill DPS Breakdown (damage-dealing skills only — buffs/passives that never deal their own damage are omitted), and a Marginal DPS & Stat Value table showing the DPS gained per +1 of each stat.
A6: Sensitivity has the full detail behind that marginal-value table — one self-contained block per stat, showing exactly how bumping that stat by +1 changes every downstream number.
A7: CubeData/PotentialCubes model your current gear's Potential Cube lines and drive cube-reroll expected-value decisions. For the full standalone Potential Cube EV calculator (exact optimal-stopping math, works from this workbook alone), see tools/potential_cubes_ev.py in the project repo.
A9: Design decisions & assumptions
A10: Shadow Heart, Quick Motion's AS component, Agile Knuckles, Dark Clarity, Knuckle Mastery, and Physical Training are always-on passives assumed to already be reflected in your own Inputs stat entries — only their Sensitivity marginal delta is modeled live, matching this project's established convention. Perseverance's own HP-regen has no DPS mechanic; its Mastery Lv.49 '+5% Attack when HP>=50%' needs HP tracking that doesn't exist anywhere in this project — not modeled, flagged. Admiral's Wings (damage-taken reduction) is purely defensive, not modeled. Mastery Lv.54 'Advanced Dash - Protection' references a skill absent from the entire skill overview list — flagged, unmodeled, no base skill to attach it to.
A11: This class has NO individual wiki pages at all (worse than Bishop) — every scaling skill's (baseDamage, factorIndex) is a FLAGGED ASSUMPTION derived from its single known level-1 value using the per-skill-type factorIndex convention, not a verified curve. Hook Bomber (basic attack) is the one exception, reusing the universal cross-class 4th-job-basic-attack constant (2900, 21). The Mastery table (Lv.12-138) IS real and confirmed — its discrete level-gated deltas are layered on top of the assumed base curves as genuine SkillMasteryBonus%/MasteryBossDamage% contributions.
A12: Sea Serpent Burst / Serpent Assault / Serpent Scale model Buccaneer's 'Assault Mode' resource economy (5 Serpent Scales -> 10s Assault Mode, swapping the basic-attack proc and adding +25% Final Damage) as a steady-state duty cycle, not an exact stack-gain/mode-toggle state machine — a documented approximation, reusing the existing ProcChance% machinery rather than inventing new state tracking. Because Corkscrew Blow (Lv.73+) costs its own action-slot time, unlocking it slightly *reduces* total DPS at that exact level boundary (verified numerically, not a bug) — it eats into Hook Bomber's own cast rate, which lowers Assault Mode uptime, and Serpent Assault loses more DPS from that than Corkscrew Blow itself adds.
A13: Octopunch + Sea Serpent's Rage + Raging Serpent Assault: Sea Serpent's Rage triggers unconditionally on every Octopunch cast (folded additively into Octopunch's own coefficient) plus its own extra-hits tick (Raging Serpent Assault) gated by the same Assault-Mode-uptime fraction above, since it only fires while in Assault Mode.
A14: Nautilus Strike (1950% dmg/15 targets/5 hits) is confirmed SHARED verbatim with Corsair (byte-identical wiki description) — a FLAGGED ASSUMPTION tuple (no cooldown stated anywhere either, 45s assumed by convention), reused directly by Corsair's own build rather than re-derived. Its own Mastery 'Nautilus Strike - Final Attack' (Lv.113, patched 15%->30% trigger chance, cooldown set to 1s) procs off basic attacks, modeled as its own row, same machinery as Bowmaster's Flash Mirage.
... A19: Not modeled (out of scope): all forms of crowd control (Corkscrew Blow's stun), Accuracy, Evasion, Defense, HP recovery, movement speed, and Companion Summoning Time.

Sheet Inputs
A1: Buccaneer — DPS Calculator Inputs
A3: Character Level | B3: 200
A4: Monster Type ("boss", "normal", "breakthrough", or "pvp") | B4: boss
A5: Flat ATTACK | B5: 10000
A6: ATTACK % | B6: 0
A7: Monster Defense (flat, post-x100/x10 scaling) | B7: 0
A8: CRIT_RATE % | B8: 0
A9: CRIT_DAMAGE % | B9: 0
A10: ATTACK_SPEED % (base, excludes Weapon Acceleration) | B10: 0
A11: Flat STR (include Iron Body's own +30 if unlocked) | B11: 0
A12: STR % | B12: 0
A13: DEX | B13: 0
A14: DAMAGE % | B14: 0
A15: DAMAGE_AMP % | B15: 0
A16: BASIC_ATTACK_DAMAGE % | B16: 0
... A28: Skill Level Bonus — All Skills | B28: 0
A30: Additional Bonuses
A31: Skill Cooldown Decrease (seconds, only skills/buffs the character actively casts) | B31: 0
A32: Basic Attack Target Increase (flat, adds to the 6-target normal-monster base) | B32: 1
A33: Buff Duration Increase % | B33: 0
A34: Companion Summoning Time Increase % (companions not modeled — always 0 DPS impact) | B34: 0
A35: Fixed Fight Duration (seconds, boss or normal — leave 0 for steady-state DPS; ignored for pvp) | B35: 0
A36: Chapter Breakthrough: Normal-Monster Weight % (only used when Monster Type = breakthrough) | B36: 60
A37: Max Enemies Actually In Range (normal monsters only; default 999 = uncapped) | B37: 999

Sheet FactorTable
A1: Level | B1: F0 | C1: F1 | D1: F2 | E1: F3 | F1: F4 | G1: F5 | H1: F6 | I1: F7 | J1: F8 | K1: F9 | L1: F10 | M1: F11 | N1: F12 | O1: F13 | P1: F14 | Q1: F15 | R1: F16 | S1: F17 | T1: F18 | U1: F19 | V1: F20 | W1: F21 | X1: F22 | Y1: F23
A2: 1 | B2: 0 | C2: 1000 | D2: 1000 | E2: 1000 | F2: 1000 | G2: 1000 | H2: 1000 | I2: 1000 | J2: 1000 | K2: 1000 | L2: 1000 | M2: 1000 | N2: 1000 | O2: 1000 | P2: 1000 | Q2: 1000 | R2: 1000 | S2: 1000 | T2: 1000 | U2: 1000 | V2: 1000 | W2: 1000 | X2: 1000 | Y2: 1000
A3: 2 | B3: 0 | C3: 1015 | D3: 1020 | E3: 1030 | F3: 1040 | G3: 1050 | H3: 1060 | I3: 1070 | J3: 1020 | K3: 1020 | L3: 1020 | M3: 1000 | N3: 1010 | O3: 1020 | P3: 1030 | Q3: 1040 | R3: 1050 | S3: 1060 | T3: 1070 | U3: 1080 | V3: 1010 | W3: 1008 | X3: 1006 | Y3: 1100
A4: 3 | B4: 0 | C4: 1031 | D4: 1041 | E4: 1061 | F4: 1082 | G4: 1103 | H4: 1124 | I4: 1145 | J4: 1030 | K4: 1041 | L4: 1030 | M4: 1000 | N4: 1015 | O4: 1030 | P4: 1045 | Q4: 1060 | R4: 1075 | S4: 1090 | T4: 1105 | U4: 1120 | V4: 1020 | W4: 1012 | X4: 1009 | Y4: 1150
A5: 4 | B5: 0 | C5: 1047 | D5: 1062 | E5: 1093 | F5: 1126 | G5: 1159 | H5: 1192 | I5: 1226 | J5: 1040 | K5: 1062 | L5: 1040 | M5: 1000 | N5: 1020 | O5: 1040 | P5: 1060 | Q5: 1080 | R5: 1100 | S5: 1120 | T5: 1140 | U5: 1160 | V5: 1030 | W5: 1016 | X5: 1012 | Y5: 1200
A6: 5 | B6: 0 | C6: 1063 | D6: 1084 | E6: 1126 | F6: 1172 | G6: 1217 | H6: 1264 | I6: 1312 | J6: 1050 | K6: 1084 | L6: 1050 | M6: 1000 | N6: 1025 | O6: 1050 | P6: 1075 | Q6: 1100 | R6: 1125 | S6: 1150 | T6: 1175 | U6: 1200 | V6: 1040 | W6: 1020 | X6: 1015 | Y6: 1250
A7: 6 | B7: 0 | C7: 1079 | D7: 1106 | E7: 1160 | F7: 1219 | G7: 1278 | H7: 1340 | I7: 1404 | J7: 1060 | K7: 1106 | L7: 1060 | M7: 1000 | N7: 1030 | O7: 1060 | P7: 1090 | Q7: 1120 | R7: 1150 | S7: 1180 | T7: 1210 | U7: 1240 | V7: 1050 | W7: 1024 | X7: 1018 | Y7: 1300
A8: 7 | B8: 0 | C8: 1096 | D8: 1129 | E8: 1195 | F8: 1268 | G8: 1342 | H8: 1421 | I8: 1503 | J8: 1070 | K8: 1129 | L8: 1070 | M8: 1000 | N8: 1035 | O8: 1070 | P8: 1105 | Q8: 1140 | R8: 1175 | S8: 1210 | T8: 1245 | U8: 1280 | V8: 1060 | W8: 1028 | X8: 1021 | Y8: 1350
A9: 8 | B9: 0 | C9: 1113 | D9: 1152 | E9: 1231 | F9: 1319 | G9: 1410 | H9: 1507 | I9: 1609 | J9: 1080 | K9: 1152 | L9: 1080 | M9: 1000 | N9: 1040 | O9: 1080 | P9: 1120 | Q9: 1160 | R9: 1200 | S9: 1240 | T9: 1280 | U9: 1320 | V9: 1070 | W9: 1032 | X9: 1024 | Y9: 1400
A10: 9 | B10: 0 | C10: 1130 | D10: 1176 | E10: 1268 | F10: 1372 | G10: 1481 | H10: 1598 | I10: 1722 | J10: 1090 | K10: 1176 | L10: 1090 | M10: 1000 | N10: 1045 | O10: 1090 | P10: 1135 | Q10: 1180 | R10: 1225 | S10: 1270 | T10: 1315 | U10: 1360 | V10: 1080 | W10: 1036 | X10: 1027 | Y10: 1450
A11: 10 | B11: 0 | C11: 1147 | D11: 1200 | E11: 1307 | F11: 1427 | G11: 1556 | H11: 1694 | I11: 1843 | J11: 1100 | K11: 1200 | L11: 1100 | M11: 1000 | N11: 1050 | O11: 1100 | P11: 1150 | Q11: 1200 | R11: 1250 | S11: 1300 | T11: 1350 | U11: 1400 | V11: 1090 | W11: 1040 | X11: 1030 | Y11: 1500
A12: 11 | B12: 0 | C12: 1165 | D12: 1224 | E12: 1347 | F12: 1485 | G12: 1634 | H12: 1796 | I12: 1973 | J12: 1110 | K12: 1224 | L12: 1110 | M12: 1000 | N12: 1055 | O12: 1110 | P12: 1165 | Q12: 1220 | R12: 1275 | S12: 1330 | T12: 1385 | U12: 1440 | V12: 1100 | W12: 1044 | X12: 1033 | Y12: 1550
A13: 12 | B13: 0 | C13: 1183 | D13: 1249 | E13: 1388 | F13: 1545 | G13: 1716 | H13: 1904 | I13: 2112 | J13: 1120 | K13: 1249 | L13: 1120 | M13: 1000 | N13: 1060 | O13: 1120 | P13: 1180 | Q13: 1240 | R13: 1300 | S13: 1360 | T13: 1420 | U13: 1480 | V13: 1110 | W13: 1048 | X13: 1036 | Y13: 1600
... A301: 300 | B301: 0 | C301: 88573 | D301: 381637 | E301: 6991522 | F301: 125363453 | G301: 2185120762 | H301: 37157073039 | I301: 614631863830 | J301: 2000 | K301: 53326 | L301: 2500 | M301: 1100 | N301: 2500 | O301: 4000 | P301: 5500 | Q301: 7000 | R301: 8500 | S301: 10000 | T301: 11500 | U301: 13000 | V301: 7558 | W301: 2200 | X301: 1900 | Y301: 8800

Sheet Skills
A1: Key | B1: Name | C1: JobStep | D1: Cooldown(s) | E1: CostsActionSlot | F1: ActionsPerCast | G1: HitsPerCast | H1: ICD(s) | I1: ActiveWindow(s) | J1: ProcChance% | K1: RollsPerCast | L1: BaseDamage(tenths%) | M1: FactorIndex | N1: ScalesWithLevel | O1: SkillMasteryBonus% | P1: MasteryBossDamage% | Q1: MasteryNormalDamage% | R1: NormalMonsterTargets | S1: BuffTargetStat | T1: BuffDuration(s) | U1: MapleHeroBase(tenths%) | V1: MapleHeroFactorIndex | W1: Note
A2: HOOK_BOMBER | B2: Hook Bomber | C2: 4 | E2: FALSE | F2: 1 | G2: =IF(Inputs!$B$3>=136,6,5) | H2: 0 | I2: 0 | J2: 100 | K2: 1 | L2: 2900 | M2: 21 | N2: TRUE | O2: =SUMPRODUCT((Inputs!$B$3>={102,106,116,120,128,132})*{10,1,1,1,1,1}) | P2: =SUMPRODUCT((Inputs!$B$3>={111,124})*{10,10}) | Q2: 0 | R2: =6+Inputs!$B$32 | T2: 0 | W2: 4th-job basic-attack effect (supersedes Somersault Kick/Shotgun Punch/Turning Kick, confirmed identical wiki wording — 290% damage to 6 target(s) in front 5 time(s) — to every other class's own 4th-job basic attack). factorIndex 21, baseDamage 2900 tenths%. HitsPerCast=5, bumping to 6 once Mastery Lv.136 'Hook Bomber - Strike' unlocks. Real Damage mastery chain (102/106/116/120/128/132, DELTAS not cumulative) and Boss Monster Damage chain (111/124, +10% each) — same level breakpoints as Hero's own Hook Bomber chain. No 'Final Attack' skill exists anywhere in Buccaneer's own kit, so unlike Hero/Dark Knight/Bowmaster/Marksman there is no two-stage Final-Attack-folding helper needed here.
A3: SEA_SERPENT_BURST | B3: Sea Serpent Burst | C3: 2 | E3: FALSE | F3: 1 | G3: 2 | H3: 0 | I3: 0 | J3: =100*(1-((10+IF(Inputs!$B$3>=94,5,0))/((10+IF(Inputs!$B$3>=94,5,0))+5/(Summary!$B$63*(1+IF(Inputs!$B$3>=104,1,0)))))) | K3: 1 | L3: 1300 | M3: 12 | N3: TRUE | O3: 0 | P3: 0 | Q3: 0 | R3: 5 | T3: 0 | W3: FLAGGED ASSUMPTION (no individual wiki page exists — only the level-1 value is known): 'When attacking with Basic Attack, Sea Serpent's waves spread...to deal 130% additional damage to 5 target(s) in front 2 time(s).' factorIndex 12 (burst convention), baseDamage 1300 tenths%. PATCHED: 40% chance -> guaranteed on basic attack. Modeled as the 'out of Assault Mode' half of this project's own Assault-Mode duty-cycle approximation (see assault_uptime_expr) — ProcChance% below is set to 100*(1-uptime), reusing the existing ProcProbability machinery to represent 'fraction of basic attacks NOT spent in Assault Mode' rather than a flat RNG chance. Greater Sea Serpent I (a slottable upgrade skill, not a mastery-table row — assumed always-equipped once unlocked, same convention as every other permanent passive-if-equipped skill in this project) changes targets to 7 and damage to 430% — folded directly into this row's own baseDamage/targets rather than modeled as a separate row, since it's a straight replacement of Sea Serpent Burst's own numbers, not an additive bonus.
A4: SERPENT_ASSAULT | B4: Serpent Assault | C4: 2 | E4: FALSE | F4: 1 | G4: 3 | H4: 0 | I4: 0 | J4: =100*((10+IF(Inputs!$B$3>=94,5,0))/((10+IF(Inputs!$B$3>=94,5,0))+5/(Summary!$B$63*(1+IF(Inputs!$B$3>=104,1,0))))) | K4: 1 | L4: 4800 | M4: 12 | N4: TRUE | O4: 0 | P4: 0 | Q4: 0 | R4: 12 | T4: 0 | U4: 600 | V4: 23 | W4: FLAGGED ASSUMPTION (no individual wiki page exists): 'When attacking with Basic Attack in Assault Mode, activates instead of Sea Serpent Burst to deal 480% additional damage to 12 nearby target(s) 3 time(s).' factorIndex 12, baseDamage 4800 tenths%. ProcChance% below is set to 100*uptime (see assault_uptime_expr) — the complementary half of Sea Serpent Burst's own duty-cycle split. Greater Sea Serpent II (slottable upgrade, assumed always-equipped once unlocked) adds +100% Final Damage and more targets ('spreads farther', exact new target count not stated anywhere on the wiki) — the +100% FD is folded in as a flat x2 multiplier baked into this row's own baseDamage (4800 already reflects it: raw level-1 value would be 2400, doubled here) since the target-count increase has no stated number to use. Maple Hero target (own confirmed 60% share, ratio 1.0) — see MAPLE_HERO_RATIOS.
A5: SERPENT_SCALE_FD | B5: Serpent Scale (Assault Mode Final Damage) | C5: 2 | E5: FALSE | F5: 1 | G5: 1 | H5: 0 | I5: 0 | J5: 100 | K5: 1 | L5: 250 | M5: 22 | N5: TRUE | O5: 0 | P5: 0 | Q5: 0 | R5: 0 | S5: FINAL_DAMAGE | T5: 0 | W5: FLAGGED ASSUMPTION (no individual wiki page exists): '[5 Serpent Scales Required] Consumes all Serpent Scales to enter Assault Mode...increases Final Damage by 25%.' factorIndex 22, baseDamage 250 tenths%. Modeled as active for exactly the assault_uptime_expr() fraction of the time (NOT the standard cooldown-driven buff_uptime() helper — this is a resource-stack economy, not a player cooldown, same category of deviation as Bowmaster's own AS-scaled Quiver Cartridge cooldown). The OTHER stated effect ('[Serpent Scale in Slot] when Sea Serpent Burst is activated, obtains Serpent Scale and increases Final Damage by 2%, stacks up to 5 times' — a SEPARATE, smaller FD buff active BEFORE reaching Assault Mode) is NOT modeled — stacking an approximation on top of an already-approximated resource economy was judged out of scope for this session.
A6: CORKSCREW_BLOW | B6: Corkscrew Blow | C6: 3 | D6: 20 | E6: TRUE | F6: 1 | G6: 2 | H6: 0 | I6: 0 | J6: 100 | K6: 1 | L6: 3400 | M6: 12 | N6: TRUE | O6: =SUMPRODUCT((Inputs!$B$3>={73})*{80}) | P6: 0 | Q6: 0 | R6: 7 | T6: 0 | W6: FLAGGED ASSUMPTION (no individual wiki page exists, no cooldown stated anywhere on the wiki either — 20s assumed by convention matching similarly-shaped 3rd-job burst skills elsewhere in this project): 'Charges to the front...to deal 340% damage to 7 target(s) 2 time(s) and stun them' (stun not modeled). factorIndex 12, baseDamage 3400 tenths%. Mastery Lv.73 'Corkscrew Blow - Damage' +80% (real SkillMasteryBonus%). CONFIRMED, EXPLAINED level-boundary DPS DIP at unlock (Lv.63, not a bug): this skill's own CostsActionSlot=True consumes basic-attack action-slot time, lowering Hook Bomber's own cast rate (Summary!$B$R_BAPS) — which the Assault-Mode duty cycle (assault_uptime_expr) is inversely sensitive to, since regen_time=5/(BAPS*scalesPerProc) grows as BAPS shrinks. Because Serpent Assault (riding on that same uptime) deals far more DPS than Corkscrew Blow itself adds, the net effect at Lv.63 is a small TOTAL DPS decrease versus Lv.62 — verified directly (Lv.62: 153242 total, uptime 0.6667; Lv.63: 148737 total, uptime 0.6552, Corkscrew Blow's own +5476 outweighed by Serpent Assault's -9725 and Sea Serpent Burst's -256). A genuine emergent consequence of the resource-economy approximation interacting with the shared action-slot budget, not a coding error — flagged explicitly here rather than silently accepted or hidden, per this project's own level-boundary-sweep rigor bar.
A7: OCTOPUNCH | B7: Octopunch | C7: 4 | D7: 15 | E7: TRUE | F7: 1 | G7: =3+IF(OR(Inputs!$B$4="boss",Inputs!$B$4="pvp"),2,0) | H7: 0 | I7: 0 | J7: 100 | K7: 1 | L7: 9000 | M7: 12 | N7: TRUE | O7: =SUMPRODUCT((Inputs!$B$3>={108})*{50}) | P7: 0 | Q7: 0 | R7: 4 | T7: 0 | W7: FLAGGED ASSUMPTION (no individual wiki page exists, no cooldown stated — 15s assumed by convention matching similarly-shaped 4th-job burst skills elsewhere): 'Throws a series of punches to deal 900% damage to 4 target(s) in front 3 time(s).' factorIndex 12, baseDamage 9000 tenths%. Mastery Lv.108 'Octopunch - Damage' +50% (real SkillMasteryBonus%). The skill's own 'if the target is a boss, deals the same damage 2 more time(s)' clause is modeled via HitsPerCast (see below), NOT via this row's own NormalMonsterTargets field.
A8: SEA_SERPENTS_RAGE | B8: Sea Serpent's Rage | C8: 4 | D8: 15 | E8: FALSE | F8: 1 | G8: 2 | H8: 0 | I8: 0 | J8: 100 | K8: 1 | L8: 17000 | M8: 12 | N8: TRUE | O8: 0 | P8: 0 | Q8: 0 | R8: 8 | T8: 0 | W8: FLAGGED ASSUMPTION (no individual wiki page exists): 'When Octopunch is activated, a Sea Serpent appears and deals 1700% additional damage to 8 target(s) in front 2 time(s)' — UNCONDITIONAL on every Octopunch cast (own damage-taken-increase debuff on hit targets, 15% for 5s, not modeled). Modeled as its own row sharing Octopunch's own Cooldown(s) value with CostsActionSlot=False and effectively guaranteed (ProcChance 100, RollsPerCast 1) — same 'shares parent's cast timing, doesn't double-count in the action economy' pattern as Hero's own PUNCTURE_WOUND sharing PUNCTURE's cooldown, chosen over folding into Octopunch's own coefficient because the two skills' target counts/hit counts differ (4/3 vs 8/2) and coefficient-folding assumes a shared target/hit shape. factorIndex 12, baseDamage 17000 tenths%.
A9: RAGING_SERPENT_ASSAULT | B9: Raging Serpent Assault | C9: 4 | D9: 15 | E9: FALSE | F9: 1 | G9: 1 | H9: 1 | I9: 5 | J9: =100*((10+IF(Inputs!$B$3>=94,5,0))/((10+IF(Inputs!$B$3>=94,5,0))+5/(Summary!$B$63*(1+IF(Inputs!$B$3>=104,1,0))))) | K9: 1 | L9: 13000 | M9: 12 | N9: TRUE | O9: 0 | P9: 0 | Q9: 0 | R9: 9 | T9: 0 | W9: FLAGGED ASSUMPTION (no individual wiki page exists): 'When attacking with Sea Serpent's Rage in Assault Mode, calls upon an enraged Sea Serpent...to deal 1300% damage to 9 nearby target(s) every 1 sec' for 5 sec (EffectiveHits = ActiveWindow/ICD = 5 ticks/cast). Shares SEA_SERPENTS_RAGE's own Cooldown(s) (same cast timing, CostsActionSlot=False) — gated ADDITIONALLY by the SAME Assault-Mode-uptime fraction as SEA_SERPENT_BURST/SERPENT_ASSAULT (ProcChance% = 100*uptime, see assault_uptime_expr) since this effect only fires while in Assault Mode, on top of Sea Serpent's Rage's own already-guaranteed trigger. factorIndex 12, baseDamage 13000 tenths%.
A10: NAUTILUS_STRIKE | B10: Nautilus Strike | C10: 4 | D10: 45 | E10: TRUE | F10: 1 | G10: 5 | H10: 0 | I10: 0 | J10: 100 | K10: 1 | L10: 19500 | M10: 12 | N10: TRUE | O10: 0 | P10: 0 | Q10: 0 | R10: 15 | T10: 0 | W10: FLAGGED ASSUMPTION (no individual wiki page exists, no cooldown stated — 45s assumed by convention matching similarly-shaped big single-cast 4th-job nukes elsewhere): 'Orders the Nautilus to attack to deal 1950% damage to 15 nearby target(s) 5 time(s).' factorIndex 12, baseDamage 19500 tenths%. CONFIRMED SHARED VERBATIM WITH CORSAIR (byte-identical wiki description on both classes' overview pages) — Corsair's own build should reuse this exact (19500, 12) tuple directly rather than re-deriving it.
A11: NAUTILUS_FINAL_ATTACK | B11: Nautilus Strike - Final Attack | C11: 4 | D11: 1 | E11: FALSE | F11: 1 | G11: 1 | H11: 0 | I11: 0 | J11: 30 | K11: 1 | L11: 8500 | M11: 21 | N11: TRUE | O11: 0 | P11: 0 | Q11: 0 | R11: 1 | T11: 0 | W11: Mastery Lv.113 proc, not a base skill: '[Nautilus Strike in Slot] When attacking, deals 850% additional damage' — PATCHED: trigger chance 15%->30%, 'cooldown set to 1s' (both baked in directly: ProcChance%=30, Cooldown(s)=1). Triggers off basic attacks generically (same Cooldown+ProcChance-gated machinery as Bowmaster's own Flash Mirage), CostsActionSlot=False so it doesn't compete with Hook Bomber's own action economy. factorIndex 21 (Final-Attack-style convention, matching every other 'additional damage on attack' proc in this project), baseDamage 8500 tenths%. Gated at Lv.113 (the mastery's own unlock level, not Nautilus Strike's base unlock) since the proc doesn't exist until this specific mastery tier is slotted.
A12: MAPLE_HERO_HELPER | B12: Maple Hero (helper) | C12: 4 | E12: FALSE | F12: 1 | G12: 1 | H12: 0 | I12: 0 | J12: 100 | K12: 1 | L12: 600 | M12: 23 | N12: TRUE | O12: 0 | P12: 0 | Q12: 0 | R12: 0 | T12: 0 | W12: Shared ratio-feeder row (see MAPLE_HERO_RATIOS) for Serpent Assault's own Final Damage chain — mirrors every other class's own Maple Hero mechanism. FLAGGED ASSUMPTION: the wiki's own source text for this row is genuinely TRUNCATED mid-sentence ('Serpent Assault 60%, Corkscrew...') and no individual Maple_Hero_(Buccaneer) page exists to confirm a real growth curve — factorIndex 23 assumed by convention (matches the universal Maple Hero 'growth-reduction after Lv.120' shape confirmed on every other class), baseDamage 600 tenths% anchored to the one confirmed level-1 value (60%). Corkscrew Blow's own share and a likely third buffed skill are completely unmodeled — a known incomplete gap, not guessed, per direct user decision. No independent DPS row of its own (Calc columns J-N blank/0, only D/E/F computed, read directly by Serpent Assault's own K-column formula).
A13: ROLL_OF_THE_DICE_DICE | B13: Roll of the Dice (dice component) | C13: 2 | E13: FALSE | F13: 1 | G13: 1 | H13: 0 | I13: 0 | J13: 100 | K13: 1 | L13: 25 | M13: 0 | N13: FALSE | O13: 0 | P13: 0 | Q13: 0 | R13: 0 | S13: ATTACK | T13: 0 | W13: FLAGGED ASSUMPTION (no individual wiki page exists, no cooldown stated): 'Rolls a six-sided die every 7 sec to increase Attack by 0-5% in proportion to the number on the die for 5 sec.' The flat, unconditional '+20% Attack' base effect of this same skill is Magic-Critical-pattern (assumed already reflected in your own Inputs!ATTACK_PCT, see PASSIVE_DELTA_SLOT) — this row models ONLY the random dice component, approximated at its average roll (2.5%, the midpoint of 0-5%) treated as an always-active flat bonus once unlocked, rather than an actual RNG/duty-cycle process (the 'no repeat within 30s' rule and the 7s-roll/5s-duration timing are not modeled). factorIndex 0 (non-scaling placeholder — no data exists on whether the 0-5% range itself grows with level), baseDamage 25 tenths%.
A14: CROSSBONES_FD | B14: Crossbones | C14: 4 | E14: FALSE | F14: 1 | G14: 1 | H14: 0 | I14: 0 | J14: 100 | K14: 1 | L14: 100 | M14: 22 | N14: TRUE | O14: 0 | P14: 0 | Q14: 0 | R14: 0 | S14: FINAL_DAMAGE | T14: 0 | W14: FLAGGED ASSUMPTION (no individual wiki page exists, no cooldown/duration mechanics stated beyond 'for 12 sec' — modeled as always-active steady-state once unlocked rather than duty-cycled, since no cooldown is known to compute a real uptime fraction): 'Increases Final Damage by 10% and Defense Penetration by 5% for 12 sec.' Only the Final Damage component is modeled — this project has no live per-skill Defense-Penetration-bucket mechanism anywhere to reuse (Def Pen is normally a static Inputs field with its own diminishing-returns formula, not something a skill can contribute to live). factorIndex 22, baseDamage 100 tenths%.
A15: TIME_LEAP_FD | B15: Time Leap | C15: 4 | E15: FALSE | F15: 1 | G15: 1 | H15: 0 | I15: 0 | J15: 100 | K15: 1 | L15: 150 | M15: 22 | N15: TRUE | O15: 0 | P15: 0 | Q15: 0 | R15: 0 | S15: FINAL_DAMAGE | T15: 0 | W15: FLAGGED ASSUMPTION (no individual wiki page exists, no real cooldown stated beyond 'a 12-sec cooldown is applied at the start of battle when this skill is in slot' — modeled as always-active steady-state once unlocked after that initial delay, since no repeat-cast cooldown is known): 'Instantly decreases the cooldown of Active Skills by 50% and increases Final Damage by 30% for 40 sec.' PATCHED: Final Damage 30%->15% (a nerf) — modeled value already reflects the patch. The cooldown-reduction-for-other-skills effect is not modeled (no mechanic exists in this project for one skill's cooldown to modify another's). factorIndex 22, baseDamage 150 tenths% (already the patched 15%).
A16: SHADOW_HEART | B16: Shadow Heart | C16: 1 | E16: FALSE | F16: 1 | G16: 1 | H16: 0 | I16: 0 | J16: 100 | K16: 1 | L16: 50 | M16: 22 | N16: TRUE | O16: 0 | P16: 0 | Q16: 0 | R16: 0 | S16: CRIT_RATE | T16: 0 | W16: Magic Critical pattern — already baked into Inputs!CRIT_RATE%; feeds the 1st-Job Skill Level Bonus delta. FLAGGED ASSUMPTION (no individual wiki page exists): 'Increases Critical Rate by 5%.' factorIndex 22, baseDamage 50 tenths%.
A17: QUICK_MOTION | B17: Quick Motion | C17: 1 | E17: FALSE | F17: 1 | G17: 1 | H17: 0 | I17: 0 | J17: 100 | K17: 1 | L17: 60 | M17: 22 | N17: TRUE | O17: 0 | P17: 0 | Q17: 0 | R17: 0 | S17: ATTACK_SPEED | T17: 0 | W17: Magic Critical pattern — already baked into Inputs!ATTACK_SPEED%; feeds the 1st-Job Skill Level Bonus delta. FLAGGED ASSUMPTION (no individual wiki page exists): 'Increases Attack Speed by 6% and Speed by 8%' (Speed component not modeled). Unlike every other class in this project, Buccaneer has NO Nimble-Feet-style live AS buff at all — Quick Motion is a flat passive instead, confirmed by its own overview text having no duration/cooldown language whatsoever (unlike Nimble Feet's explicit 'for 15 sec'). factorIndex 22, baseDamage 60 tenths%.
A18: AGILE_KNUCKLES | B18: Agile Knuckles | C18: 2 | E18: FALSE | F18: 1 | G18: 1 | H18: 0 | I18: 0 | J18: 100 | K18: 1 | L18: 50 | M18: 22 | N18: TRUE | O18: =SUMPRODUCT((Inputs!$B$3>={44})*{7}) | P18: 0 | Q18: 0 | R18: 0 | S18: ATTACK_SPEED | T18: 0 | W18: Magic Critical pattern — already baked into Inputs!ATTACK_SPEED%; feeds the 2nd-Job Skill Level Bonus delta. FLAGGED ASSUMPTION (no individual wiki page exists): 'Increases Attack Speed by 5%.' factorIndex 22, baseDamage 50 tenths%. Mastery Lv.44 'Agile Knuckles - Speed' +7 (percentage points, real SkillMasteryBonus%).
A19: DARK_CLARITY | B19: Dark Clarity | C19: 2 | E19: FALSE | F19: 1 | G19: 1 | H19: 0 | I19: 0 | J19: 100 | K19: 1 | L19: 120 | M19: 22 | N19: TRUE | O19: 0 | P19: 0 | Q19: 0 | R19: 0 | S19: ATTACK | T19: 0 | W19: Magic Critical pattern — already baked into Inputs!ATTACK_PCT (folds into the attack_mult delta bucket, same slot as Shadower's own Channel Karma/Bowmaster's own Soul Arrow: Bow). FLAGGED ASSUMPTION (no individual wiki page exists): 'Increases Attack by 12%.' factorIndex 22, baseDamage 120 tenths%.
A20: KNUCKLE_MASTERY | B20: Knuckle Mastery | C20: 2 | E20: FALSE | F20: 1 | G20: 1 | H20: 0 | I20: 0 | J20: 100 | K20: 1 | L20: 150 | M20: 22 | N20: TRUE | O20: 0 | P20: 0 | Q20: 0 | R20: 0 | S20: MIN_DAMAGE | T20: 0 | W20: Magic Critical pattern — already baked into Inputs!MIN_DAMAGE%; feeds the 2nd-Job Skill Level Bonus delta. FLAGGED ASSUMPTION (no individual wiki page exists): 'Increases Min Damage Multiplier by 15%.' factorIndex 22, baseDamage 150 tenths%.
A21: PHYSICAL_TRAINING | B21: Physical Training | C21: 2 | E21: FALSE | F21: 1 | G21: 1 | H21: 0 | I21: 0 | J21: 100 | K21: 1 | L21: 100 | M21: 22 | N21: TRUE | O21: 0 | P21: 0 | Q21: 0 | R21: 0 | S21: BASIC_ATTACK_DAMAGE | T21: 0 | W21: Magic Critical pattern — already baked into Inputs!BASIC_ATTACK_DAMAGE%; feeds the 2nd-Job Skill Level Bonus delta. FLAGGED ASSUMPTION (no individual wiki page exists, though byte-identical wording to every other class's own Physical Training): 'Increases Basic Attack Damage by 10%.' factorIndex 22, baseDamage 100 tenths%.
A22: GROGGY_MASTERY_FD | B22: Groggy Mastery | C22: 2 | E22: FALSE | F22: 1 | G22: 1 | H22: 0 | I22: 0 | J22: 100 | K22: 1 | L22: 80 | M22: 22 | N22: TRUE | O22: 0 | P22: 0 | Q22: 0 | R22: 0 | S22: FINAL_DAMAGE | T22: 0 | W22: PATCHED — a mechanic-TYPE change, not just a number: pre-patch text reads 'Increases Status Effect Damage by 15% and damage by 25%' (generic damage bucket); the patch changes the second clause to 'Final Damage +8%' specifically. Modeled as +8% Final Damage per the patch (Status Effect Damage component not modeled, no such mechanic exists in this project). Magic Critical pattern — already baked into Inputs!FINAL_DAMAGE%; feeds the 2nd-Job Skill Level Bonus delta. FLAGGED ASSUMPTION (no individual wiki page exists). factorIndex 22, baseDamage 80 tenths% (already the patched 8%).

Sheet Calc
A1: Key | B1: Name | C1: Unlocked | D1: InputLevel | E1: Factor | F1: CoefficientPercent | G1: EffectiveHits | H1: ProcProbability | I1: MapleHeroMultiplier | J1: BaseDamage | K1: BaseHitDamage | L1: NonCritAvg | M1: CritAvg | N1: ExpectedDamage(perHit) | O1: DPS | P1: % of Total | Q1: InvCooldown | R1: CastsInFight | S1: HitRate(perSec)
A2: =Skills!A2 | B2: =Skills!B2 | C2: =Inputs!$B$3>=100 | F2: =Summary!$B$54+Skills!O2 | G2: =Skills!G2*IF(Skills!H2>0,Skills!I2/Skills!H2,1) | H2: =1-(1-Skills!J2/100)^Skills!K2 | I2: 1 | J2: =Summary!$B$50*(F2/100) | K2: =J2*(1+Summary!$B$51/100)*(1+Inputs!$B$14/100)*(1+IF(Inputs!$B$4="pvp",0,(1-Summary!$B$55)*(Inputs!$B$19+Skills!P2+Summary!$B$59)+Summary!$B$55*(Inputs!$B$20+Skills!Q2+Summary!$B$59))/100)*(1+Inputs!$B$15/100)*(5000/(6000+Inputs!$B$7*(1-Inputs!$B$18/100)))*(1+(Inputs!$B$23+Summary!$B$65)/100)*(1+(IF(Skills!A2="HOOK_BOMBER",Inputs!$B$16,Inputs!$B$17))/100)*(Summary!$B$57*I2) | L2: =K2*(MIN(Inputs!$B$21,Inputs!$B$22)/100+Inputs!$B$22/100)/2 | M2: =L2*(1+(Inputs!$B$9+Summary!$B$64)/100) | N2: =L2*(1-MIN((Inputs!$B$8+Summary!$B$58),100)/100)+M2*(MIN((Inputs!$B$8+Summary!$B$58),100)/100) | O2: =IF(C2,Skills!G2*N2*Summary!$B$63*IF(Inputs!$B$4="pvp",1,(1-Summary!$B$55)*(1)+Summary!$B$55*(MIN(Skills!R2,Inputs!$B$37))),0) | P2: =IF(Summary!$B$3=0,0,O2/Summary!$B$3) | Q2: 0 | R2: 0 | S2: =IFERROR(O2/N2,0)
A3: =Skills!A3 | B3: =Skills!B3 | C3: =Inputs!$B$3>=35 | D3: =IF(Skills!C3=1,60+Inputs!$B$24+Inputs!$B$28,IF(Skills!C3=2,90+Inputs!$B$25+Inputs!$B$28,IF(Skills!C3=3,120+Inputs!$B$26+Inputs!$B$28,MAX(0,(Inputs!$B$3-100)*3)+Inputs!$B$27+Inputs!$B$28))) | E3: =INDEX(FactorTable!$B$2:$Y$301, MATCH(ROUND(MIN(300,MAX(1,D3)),0), FactorTable!$A$2:$A$301,0), Skills!M3+1) | F3: =IF(Skills!N3=TRUE,(Skills!L3/10)*(E3/1000),Skills!L3/10)+Skills!O3 | G3: =Skills!G3*IF(Skills!H3>0,Skills!I3/Skills!H3,1) | H3: =1-(1-Skills!J3/100)^Skills!K3 | I3: 1 | J3: =Summary!$B$50*(F3/100) | K3: =J3*(1+Summary!$B$51/100)*(1+Inputs!$B$14/100)*(1+IF(Inputs!$B$4="pvp",0,(1-Summary!$B$55)*(Inputs!$B$19+Skills!P3+Summary!$B$59)+Summary!$B$55*(Inputs!$B$20+Skills!Q3+Summary!$B$59))/100)*(1+Inputs!$B$15/100)*(5000/(6000+Inputs!$B$7*(1-Inputs!$B$18/100)))*(1+(Inputs!$B$23+Summary!$B$65)/100)*(1+(IF(Skills!A3="HOOK_BOMBER",Inputs!$B$16,Inputs!$B$17))/100)*(Summary!$B$57*I3) | L3: =K3*(MIN(Inputs!$B$21,Inputs!$B$22)/100+Inputs!$B$22/100)/2 | M3: =L3*(1+(Inputs!$B$9+Summary!$B$64)/100) | N3: =L3*(1-MIN((Inputs!$B$8+Summary!$B$58),100)/100)+M3*(MIN((Inputs!$B$8+Summary!$B$58),100)/100) | O3: =IF(C3,Skills!G3*H3*N3*Summary!$B$63*IF(Inputs!$B$4="pvp",1,(1-Summary!$B$55)*(1)+Summary!$B$55*(MIN(Skills!R3,Inputs!$B$37))),0) | P3: =IF(Summary!$B$3=0,0,O3/Summary!$B$3) | Q3: 0 | R3: 0 | S3: =IFERROR(O3/N3,0)
A4: =Skills!A4 | B4: =Skills!B4 | C4: =Inputs!$B$3>=60 | D4: =IF(Skills!C4=1,60+Inputs!$B$24+Inputs!$B$28,IF(Skills!C4=2,90+Inputs!$B$25+Inputs!$B$28,IF(Skills!C4=3,120+Inputs!$B$26+Inputs!$B$28,MAX(0,(Inputs!$B$3-100)*3)+Inputs!$B$27+Inputs!$B$28))) | E4: =INDEX(FactorTable!$B$2:$Y$301, MATCH(ROUND(MIN(300,MAX(1,D4)),0), FactorTable!$A$2:$A$301,0), Skills!M4+1) | F4: =IF(Skills!N4=TRUE,(Skills!L4/10)*(E4/1000),Skills!L4/10)+Skills!O4 | G4: =Skills!G4*IF(Skills!H4>0,Skills!I4/Skills!H4,1) | H4: =1-(1-Skills!J4/100)^Skills!K4 | I4: 1 | J4: =Summary!$B$50*(F4/100) | K4: =J4*(1+Summary!$B$51/100)*(1+Inputs!$B$14/100)*(1+IF(Inputs!$B$4="pvp",0,(1-Summary!$B$55)*(Inputs!$B$19+Skills!P4+Summary!$B$59)+Summary!$B$55*(Inputs!$B$20+Skills!Q4+Summary!$B$59))/100)*(1+Inputs!$B$15/100)*(5000/(6000+Inputs!$B$7*(1-Inputs!$B$18/100)))*(1+(Inputs!$B$23+Summary!$B$65)/100)*(1+1.0*IF(C12=TRUE,F12,0)/100)*(1+(IF(Skills!A4="HOOK_BOMBER",Inputs!$B$16,Inputs!$B$17))/100)*(Summary!$B$57*I4) | L4: =K4*(MIN(Inputs!$B$21,Inputs!$B$22)/100+Inputs!$B$22/100)/2 | M4: =L4*(1+(Inputs!$B$9+Summary!$B$64)/100) | N4: =L4*(1-MIN((Inputs!$B$8+Summary!$B$58),100)/100)+M4*(MIN((Inputs!$B$8+Summary!$B$58),100)/100) | O4: =IF(C4,Skills!G4*H4*N4*Summary!$B$63*IF(Inputs!$B$4="pvp",1,(1-Summary!$B$55)*(1)+Summary!$B$55*(MIN(Skills!R4,Inputs!$B$37))),0) | P4: =IF(Summary!$B$3=0,0,O4/Summary!$B$3) | Q4: 0 | R4: 0 | S4: =IFERROR(O4/N4,0)
A5: =Skills!A5 | B5: =Skills!B5 | C5: =Inputs!$B$3>=60 | D5: =IF(Skills!C5=1,60+Inputs!$B$24+Inputs!$B$28,IF(Skills!C5=2,90+Inputs!$B$25+Inputs!$B$28,IF(Skills!C5=3,120+Inputs!$B$26+Inputs!$B$28,MAX(0,(Inputs!$B$3-100)*3)+Inputs!$B$27+Inputs!$B$28))) | E5: =INDEX(FactorTable!$B$2:$Y$301, MATCH(ROUND(MIN(300,MAX(1,D5)),0), FactorTable!$A$2:$A$301,0), Skills!M5+1) | F5: =IF(Skills!N5=TRUE,(Skills!L5/10)*(E5/1000),Skills!L5/10)+Skills!O5 | G5: =Skills!G5*IF(Skills!H5>0,Skills!I5/Skills!H5,1) | H5: =1-(1-Skills!J5/100)^Skills!K5 | I5: 1 | O5: 0 | P5: =IF(Summary!$B$3=0,0,O5/Summary!$B$3) | Q5: 0 | R5: 0 | S5: =IFERROR(O5/N5,0)
A6: =Skills!A6 | B6: =Skills!B6 | C6: =Inputs!$B$3>=63 | D6: =IF(Skills!C6=1,60+Inputs!$B$24+Inputs!$B$28,IF(Skills!C6=2,90+Inputs!$B$25+Inputs!$B$28,IF(Skills!C6=3,120+Inputs!$B$26+Inputs!$B$28,MAX(0,(Inputs!$B$3-100)*3)+Inputs!$B$27+Inputs!$B$28))) | E6: =INDEX(FactorTable!$B$2:$Y$301, MATCH(ROUND(MIN(300,MAX(1,D6)),0), FactorTable!$A$2:$A$301,0), Skills!M6+1) | F6: =IF(Skills!N6=TRUE,(Skills!L6/10)*(E6/1000),Skills!L6/10)+Skills!O6 | G6: =Skills!G6*IF(Skills!H6>0,Skills!I6/Skills!H6,1) | H6: =1-(1-Skills!J6/100)^Skills!K6 | I6: 1 | J6: =Summary!$B$50*(F6/100) | K6: =J6*(1+Summary!$B$51/100)*(1+Inputs!$B$14/100)*(1+IF(Inputs!$B$4="pvp",0,(1-Summary!$B$55)*(Inputs!$B$19+Skills!P6+Summary!$B$59)+Summary!$B$55*(Inputs!$B$20+Skills!Q6+Summary!$B$59))/100)*(1+Inputs!$B$15/100)*(5000/(6000+Inputs!$B$7*(1-Inputs!$B$18/100)))*(1+(Inputs!$B$23+Summary!$B$65)/100)*(1+(IF(Skills!A6="HOOK_BOMBER",Inputs!$B$16,Inputs!$B$17))/100)*(Summary!$B$57*I6) | L6: =K6*(MIN(Inputs!$B$21,Inputs!$B$22)/100+Inputs!$B$22/100)/2 | M6: =L6*(1+(Inputs!$B$9+Summary!$B$64)/100) | N6: =L6*(1-MIN((Inputs!$B$8+Summary!$B$58),100)/100)+M6*(MIN((Inputs!$B$8+Summary!$B$58),100)/100) | O6: =IF(C6,H6*N6*IF(AND(Inputs!$B$4<>"pvp",Inputs!$B$35>0),((Skills!G6*((R6-1)*IF(Skills!H6>0,Skills!I6/Skills!H6,1)+IF(Skills!H6>0,MIN(Skills!I6,MAX(0,Inputs!$B$35-((R6-1)*IF(Inputs!$B$4="pvp",15,MAX(0.1,Skills!D6-IF(Skills!E6=TRUE,Inputs!$B$31,0))))))/Skills!H6,1)))/Inputs!$B$35),G6*Q6)*IF(Inputs!$B$4="pvp",1,(1-Summary!$B$55)*(1)+Summary!$B$55*(MIN(Skills!R6,Inputs!$B$37))),0) | P6: =IF(Summary!$B$3=0,0,O6/Summary!$B$3) | Q6: =IFERROR(1/IF(Inputs!$B$4="pvp",15,MAX(0.1,Skills!D6-IF(Skills!E6=TRUE,Inputs!$B$31,0))),0) | R6: =IF(AND(Inputs!$B$4<>"pvp",Inputs!$B$35>0),(INT(Inputs!$B$35/IF(Inputs!$B$4="pvp",15,MAX(0.1,Skills!D6-IF(Skills!E6=TRUE,Inputs!$B$31,0))))+1),0) | S6: =IFERROR(O6/N6,0)
A7: =Skills!A7 | B7: =Skills!B7 | C7: =Inputs!$B$3>=100 | D7: =IF(Skills!C7=1,60+Inputs!$B$24+Inputs!$B$28,IF(Skills!C7=2,90+Inputs!$B$25+Inputs!$B$28,IF(Skills!C7=3,120+Inputs!$B$26+Inputs!$B$28,MAX(0,(Inputs!$B$3-100)*3)+Inputs!$B$27+Inputs!$B$28))) | E7: =INDEX(FactorTable!$B$2:$Y$301, MATCH(ROUND(MIN(300,MAX(1,D7)),0), FactorTable!$A$2:$A$301,0), Skills!M7+1) | F7: =IF(Skills!N7=TRUE,(Skills!L7/10)*(E7/1000),Skills!L7/10)+Skills!O7 | G7: =Skills!G7*IF(Skills!H7>0,Skills!I7/Skills!H7,1) | H7: =1-(1-Skills!J7/100)^Skills!K7 | I7: 1 | J7: =Summary!$B$50*(F7/100) | K7: =J7*(1+Summary!$B$51/100)*(1+Inputs!$B$14/100)*(1+IF(Inputs!$B$4="pvp",0,(1-Summary!$B$55)*(Inputs!$B$19+Skills!P7+Summary!$B$59)+Summary!$B$55*(Inputs!$B$20+Skills!Q7+Summary!$B$59))/100)*(1+Inputs!$B$15/100)*(5000/(6000+Inputs!$B$7*(1-Inputs!$B$18/100)))*(1+(Inputs!$B$23+Summary!$B$65)/100)*(1+(IF(Skills!A7="HOOK_BOMBER",Inputs!$B$16,Inputs!$B$17))/100)*(Summary!$B$57*I7) | L7: =K7*(MIN(Inputs!$B$21,Inputs!$B$22)/100+Inputs!$B$22/100)/2 | M7: =L7*(1+(Inputs!$B$9+Summary!$B$64)/100) | N7: =L7*(1-MIN((Inputs!$B$8+Summary!$B$58),100)/100)+M7*(MIN((Inputs!$B$8+Summary!$B$58),100)/100) | O7: =IF(C7,H7*N7*IF(AND(Inputs!$B$4<>"pvp",Inputs!$B$35>0),((Skills!G7*((R7-1)*IF(Skills!H7>0,Skills!I7/Skills!H7,1)+IF(Skills!H7>0,MIN(Skills!I7,MAX(0,Inputs!$B$35-((R7-1)*IF(Inputs!$B$4="pvp",15,MAX(0.1,Skills!D7-IF(Skills!E7=TRUE,Inputs!$B$31,0))))))/Skills!H7,1)))/Inputs!$B$35),G7*Q7)*IF(Inputs!$B$4="pvp",1,(1-Summary!$B$55)*(1)+Summary!$B$55*(MIN(Skills!R7,Inputs!$B$37))),0) | P7: =IF(Summary!$B$3=0,0,O7/Summary!$B$3) | Q7: =IFERROR(1/IF(Inputs!$B$4="pvp",15,MAX(0.1,Skills!D7-IF(Skills!E7=TRUE,Inputs!$B$31,0))),0) | R7: =IF(AND(Inputs!$B$4<>"pvp",Inputs!$B$35>0),(INT(Inputs!$B$35/IF(Inputs!$B$4="pvp",15,MAX(0.1,Skills!D7-IF(Skills!E7=TRUE,Inputs!$B$31,0))))+1),0) | S7: =IFERROR(O7/N7,0)
A8: =Skills!A8 | B8: =Skills!B8 | C8: =Inputs!$B$3>=110 | D8: =IF(Skills!C8=1,60+Inputs!$B$24+Inputs!$B$28,IF(Skills!C8=2,90+Inputs!$B$25+Inputs!$B$28,IF(Skills!C8=3,120+Inputs!$B$26+Inputs!$B$28,MAX(0,(Inputs!$B$3-100)*3)+Inputs!$B$27+Inputs!$B$28))) | E8: =INDEX(FactorTable!$B$2:$Y$301, MATCH(ROUND(MIN(300,MAX(1,D8)),0), FactorTable!$A$2:$A$301,0), Skills!M8+1) | F8: =IF(Skills!N8=TRUE,(Skills!L8/10)*(E8/1000),Skills!L8/10)+Skills!O8 | G8: =Skills!G8*IF(Skills!H8>0,Skills!I8/Skills!H8,1) | H8: =1-(1-Skills!J8/100)^Skills!K8 | I8: 1 | J8: =Summary!$B$50*(F8/100) | K8: =J8*(1+Summary!$B$51/100)*(1+Inputs!$B$14/100)*(1+IF(Inputs!$B$4="pvp",0,(1-Summary!$B$55)*(Inputs!$B$19+Skills!P8+Summary!$B$59)+Summary!$B$55*(Inputs!$B$20+Skills!Q8+Summary!$B$59))/100)*(1+Inputs!$B$15/100)*(5000/(6000+Inputs!$B$7*(1-Inputs!$B$18/100)))*(1+(Inputs!$B$23+Summary!$B$65)/100)*(1+(IF(Skills!A8="HOOK_BOMBER",Inputs!$B$16,Inputs!$B$17))/100)*(Summary!$B$57*I8) | L8: =K8*(MIN(Inputs!$B$21,Inputs!$B$22)/100+Inputs!$B$22/100)/2 | M8: =L8*(1+(Inputs!$B$9+Summary!$B$64)/100) | N8: =L8*(1-MIN((Inputs!$B$8+Summary!$B$58),100)/100)+M8*(MIN((Inputs!$B$8+Summary!$B$58),100)/100) | O8: =IF(C8,H8*N8*IF(AND(Inputs!$B$4<>"pvp",Inputs!$B$35>0),((Skills!G8*((R8-1)*IF(Skills!H8>0,Skills!I8/Skills!H8,1)+IF(Skills!H8>0,MIN(Skills!I8,MAX(0,Inputs!$B$35-((R8-1)*IF(Inputs!$B$4="pvp",15,MAX(0.1,Skills!D8-IF(Skills!E8=TRUE,Inputs!$B$31,0))))))/Skills!H8,1)))/Inputs!$B$35),G8*Q8)*IF(Inputs!$B$4="pvp",1,(1-Summary!$B$55)*(1)+Summary!$B$55*(MIN(Skills!R8,Inputs!$B$37))),0) | P8: =IF(Summary!$B$3=0,0,O8/Summary!$B$3) | Q8: =IFERROR(1/IF(Inputs!$B$4="pvp",15,MAX(0.1,Skills!D8-IF(Skills!E8=TRUE,Inputs!$B$31,0))),0) | R8: =IF(AND(Inputs!$B$4<>"pvp",Inputs!$B$35>0),(INT(Inputs!$B$35/IF(Inputs!$B$4="pvp",15,MAX(0.1,Skills!D8-IF(Skills!E8=TRUE,Inputs!$B$31,0))))+1),0) | S8: =IFERROR(O8/N8,0)
A9: =Skills!A9 | B9: =Skills!B9 | C9: =Inputs!$B$3>=110 | D9: =IF(Skills!C9=1,60+Inputs!$B$24+Inputs!$B$28,IF(Skills!C9=2,90+Inputs!$B$25+Inputs!$B$28,IF(Skills!C9=3,120+Inputs!$B$26+Inputs!$B$28,MAX(0,(Inputs!$B$3-100)*3)+Inputs!$B$27+Inputs!$B$28))) | E9: =INDEX(FactorTable!$B$2:$Y$301, MATCH(ROUND(MIN(300,MAX(1,D9)),0), FactorTable!$A$2:$A$301,0), Skills!M9+1) | F9: =IF(Skills!N9=TRUE,(Skills!L9/10)*(E9/1000),Skills!L9/10)+Skills!O9 | G9: =Skills!G9*IF(Skills!H9>0,Skills!I9/Skills!H9,1) | H9: =1-(1-Skills!J9/100)^Skills!K9 | I9: 1 | J9: =Summary!$B$50*(F9/100) | K9: =J9*(1+Summary!$B$51/100)*(1+Inputs!$B$14/100)*(1+IF(Inputs!$B$4="pvp",0,(1-Summary!$B$55)*(Inputs!$B$19+Skills!P9+Summary!$B$59)+Summary!$B$55*(Inputs!$B$20+Skills!Q9+Summary!$B$59))/100)*(1+Inputs!$B$15/100)*(5000/(6000+Inputs!$B$7*(1-Inputs!$B$18/100)))*(1+(Inputs!$B$23+Summary!$B$65)/100)*(1+(IF(Skills!A9="HOOK_BOMBER",Inputs!$B$16,Inputs!$B$17))/100)*(Summary!$B$57*I9) | L9: =K9*(MIN(Inputs!$B$21,Inputs!$B$22)/100+Inputs!$B$22/100)/2 | M9: =L9*(1+(Inputs!$B$9+Summary!$B$64)/100) | N9: =L9*(1-MIN((Inputs!$B$8+Summary!$B$58),100)/100)+M9*(MIN((Inputs!$B$8+Summary!$B$58),100)/100) | O9: =IF(C9,H9*N9*IF(AND(Inputs!$B$4<>"pvp",Inputs!$B$35>0),((Skills!G9*((R9-1)*IF(Skills!H9>0,Skills!I9/Skills!H9,1)+IF(Skills!H9>0,MIN(Skills!I9,MAX(0,Inputs!$B$35-((R9-1)*IF(Inputs!$B$4="pvp",15,MAX(0.1,Skills!D9-IF(Skills!E9=TRUE,Inputs!$B$31,0))))))/Skills!H9,1)))/Inputs!$B$35),G9*Q9)*IF(Inputs!$B$4="pvp",1,(1-Summary!$B$55)*(1)+Summary!$B$55*(MIN(Skills!R9,Inputs!$B$37))),0) | P9: =IF(Summary!$B$3=0,0,O9/Summary!$B$3) | Q9: =IFERROR(1/IF(Inputs!$B$4="pvp",15,MAX(0.1,Skills!D9-IF(Skills!E9=TRUE,Inputs!$B$31,0))),0) | R9: =IF(AND(Inputs!$B$4<>"pvp",Inputs!$B$35>0),(INT(Inputs!$B$35/IF(Inputs!$B$4="pvp",15,MAX(0.1,Skills!D9-IF(Skills!E9=TRUE,Inputs!$B$31,0))))+1),0) | S9: =IFERROR(O9/N9,0)
A10: =Skills!A10 | B10: =Skills!B10 | C10: =Inputs!$B$3>=103 | D10: =IF(Skills!C10=1,60+Inputs!$B$24+Inputs!$B$28,IF(Skills!C10=2,90+Inputs!$B$25+Inputs!$B$28,IF(Skills!C10=3,120+Inputs!$B$26+Inputs!$B$28,MAX(0,(Inputs!$B$3-100)*3)+Inputs!$B$27+Inputs!$B$28))) | E10: =INDEX(FactorTable!$B$2:$Y$301, MATCH(ROUND(MIN(300,MAX(1,D10)),0), FactorTable!$A$2:$A$301,0), Skills!M10+1) | F10: =IF(Skills!N10=TRUE,(Skills!L10/10)*(E10/1000),Skills!L10/10)+Skills!O10 | G10: =Skills!G10*IF(Skills!H10>0,Skills!I10/Skills!H10,1) | H10: =1-(1-Skills!J10/100)^Skills!K10 | I10: 1 | J10: =Summary!$B$50*(F10/100) | K10: =J10*(1+Summary!$B$51/100)*(1+Inputs!$B$14/100)*(1+IF(Inputs!$B$4="pvp",0,(1-Summary!$B$55)*(Inputs!$B$19+Skills!P10+Summary!$B$59)+Summary!$B$55*(Inputs!$B$20+Skills!Q10+Summary!$B$59))/100)*(1+Inputs!$B$15/100)*(5000/(6000+Inputs!$B$7*(1-Inputs!$B$18/100)))*(1+(Inputs!$B$23+Summary!$B$65)/100)*(1+(IF(Skills!A10="HOOK_BOMBER",Inputs!$B$16,Inputs!$B$17))/100)*(Summary!$B$57*I10) | L10: =K10*(MIN(Inputs!$B$21,Inputs!$B$22)/100+Inputs!$B$22/100)/2 | M10: =L10*(1+(Inputs!$B$9+Summary!$B$64)/100) | N10: =L10*(1-MIN((Inputs!$B$8+Summary!$B$58),100)/100)+M10*(MIN((Inputs!$B$8+Summary!$B$58),100)/100) | O10: =IF(C10,H10*N10*IF(AND(Inputs!$B$4<>"pvp",Inputs!$B$35>0),((Skills!G10*((R10-1)*IF(Skills!H10>0,Skills!I10/Skills!H10,1)+IF(Skills!H10>0,MIN(Skills!I10,MAX(0,Inputs!$B$35-((R10-1)*IF(Inputs!$B$4="pvp",15,MAX(0.1,Skills!D10-IF(Skills!E10=TRUE,Inputs!$B$31,0))))))/Skills!H10,1)))/Inputs!$B$35),G10*Q10)*IF(Inputs!$B$4="pvp",1,(1-Summary!$B$55)*(1)+Summary!$B$55*(MIN(Skills!R10,Inputs!$B$37))),0) | P10: =IF(Summary!$B$3=0,0,O10/Summary!$B$3) | Q10: =IFERROR(1/IF(Inputs!$B$4="pvp",15,MAX(0.1,Skills!D10-IF(Skills!E10=TRUE,Inputs!$B$31,0))),0) | R10: =IF(AND(Inputs!$B$4<>"pvp",Inputs!$B$35>0),(INT(Inputs!$B$35/IF(Inputs!$B$4="pvp",15,MAX(0.1,Skills!D10-IF(Skills!E10=TRUE,Inputs!$B$31,0))))+1),0) | S10: =IFERROR(O10/N10,0)
A11: =Skills!A11 | B11: =Skills!B11 | C11: =Inputs!$B$3>=113 | D11: =IF(Skills!C11=1,60+Inputs!$B$24+Inputs!$B$28,IF(Skills!C11=2,90+Inputs!$B$25+Inputs!$B$28,IF(Skills!C11=3,120+Inputs!$B$26+Inputs!$B$28,MAX(0,(Inputs!$B$3-100)*3)+Inputs!$B$27+Inputs!$B$28))) | E11: =INDEX(FactorTable!$B$2:$Y$301, MATCH(ROUND(MIN(300,MAX(1,D11)),0), FactorTable!$A$2:$A$301,0), Skills!M11+1) | F11: =IF(Skills!N11=TRUE,(Skills!L11/10)*(E11/1000),Skills!L11/10)+Skills!O11 | G11: =Skills!G11*IF(Skills!H11>0,Skills!I11/Skills!H11,1) | H11: =1-(1-Skills!J11/100)^Skills!K11 | I11: 1 | J11: =Summary!$B$50*(F11/100) | K11: =J11*(1+Summary!$B$51/100)*(1+Inputs!$B$14/100)*(1+IF(Inputs!$B$4="pvp",0,(1-Summary!$B$55)*(Inputs!$B$19+Skills!P11+Summary!$B$59)+Summary!$B$55*(Inputs!$B$20+Skills!Q11+Summary!$B$59))/100)*(1+Inputs!$B$15/100)*(5000/(6000+Inputs!$B$7*(1-Inputs!$B$18/100)))*(1+(Inputs!$B$23+Summary!$B$65)/100)*(1+(IF(Skills!A11="HOOK_BOMBER",Inputs!$B$16,Inputs!$B$17))/100)*(Summary!$B$57*I11) | L11: =K11*(MIN(Inputs!$B$21,Inputs!$B$22)/100+Inputs!$B$22/100)/2 | M11: =L11*(1+(Inputs!$B$9+Summary!$B$64)/100) | N11: =L11*(1-MIN((Inputs!$B$8+Summary!$B$58),100)/100)+M11*(MIN((Inputs!$B$8+Summary!$B$58),100)/100) | O11: =IF(C11,H11*N11*IF(AND(Inputs!$B$4<>"pvp",Inputs!$B$35>0),((Skills!G11*((R11-1)*IF(Skills!H11>0,Skills!I11/Skills!H11,1)+IF(Skills!H11>0,MIN(Skills!I11,MAX(0,Inputs!$B$35-((R11-1)*IF(Inputs!$B$4="pvp",15,MAX(0.1,Skills!D11-IF(Skills!E11=TRUE,Inputs!$B$31,0))))))/Skills!H11,1)))/Inputs!$B$35),G11*Q11)*IF(Inputs!$B$4="pvp",1,(1-Summary!$B$55)*(1)+Summary!$B$55*(MIN(Skills!R11,Inputs!$B$37))),0) | P11: =IF(Summary!$B$3=0,0,O11/Summary!$B$3) | Q11: =IFERROR(1/IF(Inputs!$B$4="pvp",15,MAX(0.1,Skills!D11-IF(Skills!E11=TRUE,Inputs!$B$31,0))),0) | R11: =IF(AND(Inputs!$B$4<>"pvp",Inputs!$B$35>0),(INT(Inputs!$B$35/IF(Inputs!$B$4="pvp",15,MAX(0.1,Skills!D11-IF(Skills!E11=TRUE,Inputs!$B$31,0))))+1),0) | S11: =IFERROR(O11/N11,0)
A12: =Skills!A12 | B12: =Skills!B12 | C12: =Inputs!$B$3>=100 | D12: =IF(Skills!C12=1,60+Inputs!$B$24+Inputs!$B$28,IF(Skills!C12=2,90+Inputs!$B$25+Inputs!$B$28,IF(Skills!C12=3,120+Inputs!$B$26+Inputs!$B$28,MAX(0,(Inputs!$B$3-100)*3)+Inputs!$B$27+Inputs!$B$28))) | E12: =INDEX(FactorTable!$B$2:$Y$301, MATCH(ROUND(MIN(300,MAX(1,D12)),0), FactorTable!$A$2:$A$301,0), Skills!M12+1) | F12: =IF(Skills!N12=TRUE,(Skills!L12/10)*(E12/1000),Skills!L12/10)+Skills!O12 | I12: 1
A13: =Skills!A13 | B13: =Skills!B13 | C13: =Inputs!$B$3>=66 | D13: =IF(Skills!C13=1,60+Inputs!$B$24+Inputs!$B$28,IF(Skills!C13=2,90+Inputs!$B$25+Inputs!$B$28,IF(Skills!C13=3,120+Inputs!$B$26+Inputs!$B$28,MAX(0,(Inputs!$B$3-100)*3)+Inputs!$B$27+Inputs!$B$28))) | E13: =INDEX(FactorTable!$B$2:$Y$301, MATCH(ROUND(MIN(300,MAX(1,D13)),0), FactorTable!$A$2:$A$301,0), Skills!M13+1) | F13: =IF(Skills!N13=TRUE,(Skills!L13/10)*(E13/1000),Skills!L13/10)+Skills!O13 | G13: =Skills!G13*IF(Skills!H13>0,Skills!I13/Skills!H13,1) | H13: =1-(1-Skills!J13/100)^Skills!K13 | I13: 1 | O13: 0 | P13: =IF(Summary!$B$3=0,0,O13/Summary!$B$3) | Q13: 0 | R13: 0 | S13: =IFERROR(O13/N13,0)
A14: =Skills!A14 | B14: =Skills!B14 | C14: =Inputs!$B$3>=107 | D14: =IF(Skills!C14=1,60+Inputs!$B$24+Inputs!$B$28,IF(Skills!C14=2,90+Inputs!$B$25+Inputs!$B$28,IF(Skills!C14=3,120+Inputs!$B$26+Inputs!$B$28,MAX(0,(Inputs!$B$3-100)*3)+Inputs!$B$27+Inputs!$B$28))) | E14: =INDEX(FactorTable!$B$2:$Y$301, MATCH(ROUND(MIN(300,MAX(1,D14)),0), FactorTable!$A$2:$A$301,0), Skills!M14+1) | F14: =IF(Skills!N14=TRUE,(Skills!L14/10)*(E14/1000),Skills!L14/10)+Skills!O14 | G14: =Skills!G14*IF(Skills!H14>0,Skills!I14/Skills!H14,1) | H14: =1-(1-Skills!J14/100)^Skills!K14 | I14: 1 | O14: 0 | P14: =IF(Summary!$B$3=0,0,O14/Summary!$B$3) | Q14: 0 | R14: 0 | S14: =IFERROR(O14/N14,0)
A15: =Skills!A15 | B15: =Skills!B15 | C15: =Inputs!$B$3>=115 | D15: =IF(Skills!C15=1,60+Inputs!$B$24+Inputs!$B$28,IF(Skills!C15=2,90+Inputs!$B$25+Inputs!$B$28,IF(Skills!C15=3,120+Inputs!$B$26+Inputs!$B$28,MAX(0,(Inputs!$B$3-100)*3)+Inputs!$B$27+Inputs!$B$28))) | E15: =INDEX(FactorTable!$B$2:$Y$301, MATCH(ROUND(MIN(300,MAX(1,D15)),0), FactorTable!$A$2:$A$301,0), Skills!M15+1) | F15: =IF(Skills!N15=TRUE,(Skills!L15/10)*(E15/1000),Skills!L15/10)+Skills!O15 | G15: =Skills!G15*IF(Skills!H15>0,Skills!I15/Skills!H15,1) | H15: =1-(1-Skills!J15/100)^Skills!K15 | I15: 1 | O15: 0 | P15: =IF(Summary!$B$3=0,0,O15/Summary!$B$3) | Q15: 0 | R15: 0 | S15: =IFERROR(O15/N15,0)
A16: =Skills!A16 | B16: =Skills!B16 | C16: =Inputs!$B$3>=15 | D16: =IF(Skills!C16=1,60+Inputs!$B$24+Inputs!$B$28,IF(Skills!C16=2,90+Inputs!$B$25+Inputs!$B$28,IF(Skills!C16=3,120+Inputs!$B$26+Inputs!$B$28,MAX(0,(Inputs!$B$3-100)*3)+Inputs!$B$27+Inputs!$B$28))) | E16: =INDEX(FactorTable!$B$2:$Y$301, MATCH(ROUND(MIN(300,MAX(1,D16)),0), FactorTable!$A$2:$A$301,0), Skills!M16+1) | F16: =IF(Skills!N16=TRUE,(Skills!L16/10)*(E16/1000),Skills!L16/10)+Skills!O16 | G16: =Skills!G16*IF(Skills!H16>0,Skills!I16/Skills!H16,1) | H16: =1-(1-Skills!J16/100)^Skills!K16 | I16: 1 | O16: 0 | P16: =IF(Summary!$B$3=0,0,O16/Summary!$B$3) | Q16: 0 | R16: 0 | S16: =IFERROR(O16/N16,0)
A17: =Skills!A17 | B17: =Skills!B17 | C17: =Inputs!$B$3>=10 | D17: =IF(Skills!C17=1,60+Inputs!$B$24+Inputs!$B$28,IF(Skills!C17=2,90+Inputs!$B$25+Inputs!$B$28,IF(Skills!C17=3,120+Inputs!$B$26+Inputs!$B$28,MAX(0,(Inputs!$B$3-100)*3)+Inputs!$B$27+Inputs!$B$28))) | E17: =INDEX(FactorTable!$B$2:$Y$301, MATCH(ROUND(MIN(300,MAX(1,D17)),0), FactorTable!$A$2:$A$301,0), Skills!M17+1) | F17: =IF(Skills!N17=TRUE,(Skills!L17/10)*(E17/1000),Skills!L17/10)+Skills!O17 | G17: =Skills!G17*IF(Skills!H17>0,Skills!I17/Skills!H17,1) | H17: =1-(1-Skills!J17/100)^Skills!K17 | I17: 1 | O17: 0 | P17: =IF(Summary!$B$3=0,0,O17/Summary!$B$3) | Q17: 0 | R17: 0 | S17: =IFERROR(O17/N17,0)
A18: =Skills!A18 | B18: =Skills!B18 | C18: =Inputs!$B$3>=33 | D18: =IF(Skills!C18=1,60+Inputs!$B$24+Inputs!$B$28,IF(Skills!C18=2,90+Inputs!$B$25+Inputs!$B$28,IF(Skills!C18=3,120+Inputs!$B$26+Inputs!$B$28,MAX(0,(Inputs!$B$3-100)*3)+Inputs!$B$27+Inputs!$B$28))) | E18: =INDEX(FactorTable!$B$2:$Y$301, MATCH(ROUND(MIN(300,MAX(1,D18)),0), FactorTable!$A$2:$A$301,0), Skills!M18+1) | F18: =IF(Skills!N18=TRUE,(Skills!L18/10)*(E18/1000),Skills!L18/10)+Skills!O18 | G18: =Skills!G18*IF(Skills!H18>0,Skills!I18/Skills!H18,1) | H18: =1-(1-Skills!J18/100)^Skills!K18 | I18: 1 | O18: 0 | P18: =IF(Summary!$B$3=0,0,O18/Summary!$B$3) | Q18: 0 | R18: 0 | S18: =IFERROR(O18/N18,0)
A19: =Skills!A19 | B19: =Skills!B19 | C19: =Inputs!$B$3>=40 | D19: =IF(Skills!C19=1,60+Inputs!$B$24+Inputs!$B$28,IF(Skills!C19=2,90+Inputs!$B$25+Inputs!$B$28,IF(Skills!C19=3,120+Inputs!$B$26+Inputs!$B$28,MAX(0,(Inputs!$B$3-100)*3)+Inputs!$B$27+Inputs!$B$28))) | E19: =INDEX(FactorTable!$B$2:$Y$301, MATCH(ROUND(MIN(300,MAX(1,D19)),0), FactorTable!$A$2:$A$301,0), Skills!M19+1) | F19: =IF(Skills!N19=TRUE,(Skills!L19/10)*(E19/1000),Skills!L19/10)+Skills!O19 | G19: =Skills!G19*IF(Skills!H19>0,Skills!I19/Skills!H19,1) | H19: =1-(1-Skills!J19/100)^Skills!K19 | I19: 1 | O19: 0 | P19: =IF(Summary!$B$3=0,0,O19/Summary!$B$3) | Q19: 0 | R19: 0 | S19: =IFERROR(O19/N19,0)
A20: =Skills!A20 | B20: =Skills!B20 | C20: =Inputs!$B$3>=43 | D20: =IF(Skills!C20=1,60+Inputs!$B$24+Inputs!$B$28,IF(Skills!C20=2,90+Inputs!$B$25+Inputs!$B$28,IF(Skills!C20=3,120+Inputs!$B$26+Inputs!$B$28,MAX(0,(Inputs!$B$3-100)*3)+Inputs!$B$27+Inputs!$B$28))) | E20: =INDEX(FactorTable!$B$2:$Y$301, MATCH(ROUND(MIN(300,MAX(1,D20)),0), FactorTable!$A$2:$A$301,0), Skills!M20+1) | F20: =IF(Skills!N20=TRUE,(Skills!L20/10)*(E20/1000),Skills!L20/10)+Skills!O20 | G20: =Skills!G20*IF(Skills!H20>0,Skills!I20/Skills!H20,1) | H20: =1-(1-Skills!J20/100)^Skills!K20 | I20: 1 | O20: 0 | P20: =IF(Summary!$B$3=0,0,O20/Summary!$B$3) | Q20: 0 | R20: 0 | S20: =IFERROR(O20/N20,0)
A21: =Skills!A21 | B21: =Skills!B21 | C21: =Inputs!$B$3>=38 | D21: =IF(Skills!C21=1,60+Inputs!$B$24+Inputs!$B$28,IF(Skills!C21=2,90+Inputs!$B$25+Inputs!$B$28,IF(Skills!C21=3,120+Inputs!$B$26+Inputs!$B$28,MAX(0,(Inputs!$B$3-100)*3)+Inputs!$B$27+Inputs!$B$28))) | E21: =INDEX(FactorTable!$B$2:$Y$301, MATCH(ROUND(MIN(300,MAX(1,D21)),0), FactorTable!$A$2:$A$301,0), Skills!M21+1) | F21: =IF(Skills!N21=TRUE,(Skills!L21/10)*(E21/1000),Skills!L21/10)+Skills!O21 | G21: =Skills!G21*IF(Skills!H21>0,Skills!I21/Skills!H21,1) | H21: =1-(1-Skills!J21/100)^Skills!K21 | I21: 1 | O21: 0 | P21: =IF(Summary!$B$3=0,0,O21/Summary!$B$3) | Q21: 0 | R21: 0 | S21: =IFERROR(O21/N21,0)
A22: =Skills!A22 | B22: =Skills!B22 | C22: =Inputs!$B$3>=75 | D22: =IF(Skills!C22=1,60+Inputs!$B$24+Inputs!$B$28,IF(Skills!C22=2,90+Inputs!$B$25+Inputs!$B$28,IF(Skills!C22=3,120+Inputs!$B$26+Inputs!$B$28,MAX(0,(Inputs!$B$3-100)*3)+Inputs!$B$27+Inputs!$B$28))) | E22: =INDEX(FactorTable!$B$2:$Y$301, MATCH(ROUND(MIN(300,MAX(1,D22)),0), FactorTable!$A$2:$A$301,0), Skills!M22+1) | F22: =IF(Skills!N22=TRUE,(Skills!L22/10)*(E22/1000),Skills!L22/10)+Skills!O22 | G22: =Skills!G22*IF(Skills!H22>0,Skills!I22/Skills!H22,1) | H22: =1-(1-Skills!J22/100)^Skills!K22 | I22: 1 | O22: 0 | P22: =IF(Summary!$B$3=0,0,O22/Summary!$B$3) | Q22: 0 | R22: 0 | S22: =IFERROR(O22/N22,0)

Sheet Summary
A1: Buccaneer — DPS Summary
A3: TOTAL DPS | B3: =SUM(Calc!O2:O22)
A5: Per-Skill DPS Breakdown
A6: Skill | B6: DPS | C6: % of Total
A7: =Calc!B2 | B7: =Calc!O2 | C7: =Calc!P2*100
A8: =Calc!B3 | B8: =Calc!O3 | C8: =Calc!P3*100
A9: =Calc!B4 | B9: =Calc!O4 | C9: =Calc!P4*100
A10: =Calc!B6 | B10: =Calc!O6 | C10: =Calc!P6*100
A11: =Calc!B7 | B11: =Calc!O7 | C11: =Calc!P7*100
A12: =Calc!B8 | B12: =Calc!O8 | C12: =Calc!P8*100
A13: =Calc!B9 | B13: =Calc!O9 | C13: =Calc!P9*100
A14: =Calc!B10 | B14: =Calc!O10 | C14: =Calc!P10*100
A15: =Calc!B11 | B15: =Calc!O11 | C15: =Calc!P11*100
A16: Marginal DPS & Stat Value (see Sensitivity for full detail)
A18: Stat | B18: DPS per +1 | C18: Units per +1% DPS
A19: =Sensitivity!A5 | B19: =Sensitivity!H5 | C19: =Sensitivity!B5
A20: =Sensitivity!A6 | B20: =Sensitivity!H6 | C20: =Sensitivity!B6
A21: =Sensitivity!A7 | B21: =Sensitivity!H7 | C21: =Sensitivity!B7
A22: =Sensitivity!A8 | B22: =Sensitivity!H8 | C22: =Sensitivity!B8
A23: =Sensitivity!A9 | B23: =Sensitivity!H9 | C23: =Sensitivity!B9
A24: =Sensitivity!A10 | B24: =Sensitivity!H10 | C24: =Sensitivity!B10
A25: =Sensitivity!A11 | B25: =Sensitivity!H11 | C25: =Sensitivity!B11
A26: =Sensitivity!A12 | B26: =Sensitivity!H12 | C26: =Sensitivity!B12
A27: =Sensitivity!A13 | B27: =Sensitivity!H13 | C27: =Sensitivity!B13
A28: =Sensitivity!A14 | B28: =Sensitivity!H14 | C28: =Sensitivity!B14
A29: =Sensitivity!A15 | B29: =Sensitivity!H15 | C29: =Sensitivity!B15
A30: =Sensitivity!A16 | B30: =Sensitivity!H16 | C30: =Sensitivity!B16
... A44: =Sensitivity!A30 | B44: =Sensitivity!H30 | C44: =Sensitivity!B30
A49: Derived Values (read-only, computed from Inputs)
A50: ATTACK (= Flat ATTACK x (1+ATTACK%/100)) | B50: =Inputs!$B$5*(1+Inputs!$B$6/100)
A51: STAT_DAMAGE % (= 1% of total STR + 0.25% of DEX) | B51: =(Inputs!$B$11*(1+Inputs!$B$12/100))*0.01+Inputs!$B$13*0.0025
A52: Basic Attack (Hook Bomber) Input Level (4th job formula) | B52: =MAX(0,(Inputs!$B$3-100)*3)+Inputs!$B$27+Inputs!$B$28
A53: Basic Attack Factor (factorIndex 21, universal 4th-job basic attack) | B53: =INDEX(FactorTable!$B$2:$Y$301, MATCH(ROUND(MIN(300,MAX(1,Summary!$B$52)),0), FactorTable!$A$2:$A$301,0), 22)
A54: SKILL_COEFFICIENT — Hook Bomber base coefficient % (before bonuses) | B54: =290*Summary!$B$53/1000
A55: Normal-Monster Weight (= 0 for boss, 1 for normal, Breakthrough Normal Weight % for breakthrough, 0 for pvp) | B55: =IF(Inputs!$B$4="normal",1,IF(Inputs!$B$4="breakthrough",Inputs!$B$36/100,0))
A57: Attack%% Bucket Multiplier (Roll of the Dice's dice component only) | B57: =1+(((Calc!C13=TRUE)*Calc!F13))/100
A58: Global Crit Rate Bonus % (unused — no live Crit-Rate-buff source exists) | B58: 0
A59: Global Monster Damage-Taken Bonus % (unused — no live source exists in this kit) | B59: 0
A60: Attack Speed Buff Bonus % (unused — Buccaneer has no Nimble-Feet-style live AS buff) | B60: 0
A61: Actions Per Second | B61: =1+MIN(150,150*(1-(1-Inputs!$B$10/150)*(1-B60/150)))/100
...

Sheet Sensitivity
A1: Marginal DPS per +1 (percentage point / skill level / flat point)
A2: Attack Speed and Def Pen combine their +1 via the diminishing-returns formula (new = (1-(1-old/factor)*(1-1/factor))*factor), not a flat add.
A4: Stat | B4: Units per +1% DPS | C4: Type | D4: Current Value | E4: New Value | F4: Baseline Total DPS | G4: New Total DPS | H4: DPS Gain | I4: % Gain
A5: Flat STR | B5: =IFERROR(1/(I5-100),"n/a") | C5: flat | D5: =Inputs!$B$11 | E5: =(Inputs!$B$11+1) | F5: =Summary!$B$3 | G5: =B66 | H5: =G5-F5 | I5: =IF(F5=0,0,G5/F5*100)
A6: STR % | B6: =IFERROR(1/(I6-100),"n/a") | C6: pct | D6: =Inputs!$B$12 | E6: =(Inputs!$B$12+1) | F6: =Summary!$B$3 | G6: =B102 | H6: =G6-F6 | I6: =IF(F6=0,0,G6/F6*100)
A7: DEX | B7: =IFERROR(1/(I7-100),"n/a") | C7: flat | D7: =Inputs!$B$13 | E7: =(Inputs!$B$13+1) | F7: =Summary!$B$3 | G7: =B138 | H7: =G7-F7 | I7: =IF(F7=0,0,G7/F7*100)
A8: DAMAGE % | B8: =IFERROR(1/(I8-100),"n/a") | C8: pct | D8: =Inputs!$B$14 | E8: =(Inputs!$B$14+1) | F8: =Summary!$B$3 | G8: =B174 | H8: =G8-F8 | I8: =IF(F8=0,0,G8/F8*100)
A9: DAMAGE_AMP % | B9: =IFERROR(1/(I9-100),"n/a") | C9: pct | D9: =Inputs!$B$15 | E9: =(Inputs!$B$15+1) | F9: =Summary!$B$3 | G9: =B210 | H9: =G9-F9 | I9: =IF(F9=0,0,G9/F9*100)
A10: BOSS_DAMAGE % | B10: =IFERROR(1/(I10-100),"n/a") | C10: pct | D10: =Inputs!$B$19 | E10: =(Inputs!$B$19+1) | F10: =Summary!$B$3 | G10: =B246 | H10: =G10-F10 | I10: =IF(F10=0,0,G10/F10*100)
A11: NORMAL_DAMAGE % | B11: =IFERROR(1/(I11-100),"n/a") | C11: pct | D11: =Inputs!$B$20 | E11: =(Inputs!$B$20+1) | F11: =Summary!$B$3 | G11: =B282 | H11: =G11-F11 | I11: =IF(F11=0,0,G11/F11*100)
A12: FINAL_DAMAGE % (multiplicative source) | B12: =IFERROR(1/(I12-100),"n/a") | C12: mult | D12: =Inputs!$B$23 | E12: =((((1+Inputs!$B$23/100)*(1.01))-1)*100) | F12: =Summary!$B$3 | G12: =B318 | H12: =G12-F12 | I12: =IF(F12=0,0,G12/F12*100)
A13: MIN_DAMAGE % | B13: =IFERROR(1/(I13-100),"n/a") | C13: pct | D13: =Inputs!$B$21 | E13: =(Inputs!$B$21+1) | F13: =Summary!$B$3 | G13: =B354 | H13: =G13-F13 | I13: =IF(F13=0,0,G13/F13*100)
A14: MAX_DAMAGE % | B14: =IFERROR(1/(I14-100),"n/a") | C14: pct | D14: =Inputs!$B$22 | E14: =(Inputs!$B$22+1) | F14: =Summary!$B$3 | G14: =B390 | H14: =G14-F14 | I14: =IF(F14=0,0,G14/F14*100)
A15: CRIT_RATE % | B15: =IFERROR(1/(I15-100),"n/a") | C15: pct | D15: =Inputs!$B$8 | E15: =(Inputs!$B$8+1) | F15: =Summary!$B$3 | G15: =B426 | H15: =G15-F15 | I15: =IF(F15=0,0,G15/F15*100)
A16: CRIT_DAMAGE % | B16: =IFERROR(1/(I16-100),"n/a") | C16: pct | D16: =Inputs!$B$9 | E16: =(Inputs!$B$9+1) | F16: =Summary!$B$3 | G16: =B462 | H16: =G16-F16 | I16: =IF(F16=0,0,G16/F16*100)
A17: ATTACK_SPEED % (diminishing returns, factor 150) | B17: =IFERROR(1/(I17-100),"n/a") | C17: dr150 | D17: =Inputs!$B$10 | E17: =((1-(1-Inputs!$B$10/150)*(1-1/150))*150) | F17: =Summary!$B$3 | G17: =B498 | H17: =G17-F17 | I17: =IF(F17=0,0,G17/F17*100)
A18: DEF_PEN % (diminishing returns, factor 100) | B18: =IFERROR(1/(I18-100),"n/a") | C18: dr100 | D18: =Inputs!$B$18 | E18: =((1-(1-Inputs!$B$18/100)*(1-1/100))*100) | F18: =Summary!$B$3 | G18: =B534 | H18: =G18-F18 | I18: =IF(F18=0,0,G18/F18*100)
A19: BASIC_ATTACK_DAMAGE % | B19: =IFERROR(1/(I19-100),"n/a") | C19: pct | D19: =Inputs!$B$16 | E19: =(Inputs!$B$16+1) | F19: =Summary!$B$3 | G19: =B570 | H19: =G19-F19 | I19: =IF(F19=0,0,G19/F19*100)
A20: SKILL_DAMAGE % | B20: =IFERROR(1/(I20-100),"n/a") | C20: pct | D20: =Inputs!$B$17 | E20: =(Inputs!$B$17+1) | F20: =Summary!$B$3 | G20: =B606 | H20: =G20-F20 | I20: =IF(F20=0,0,G20/F20*100)
A21: Skill Level Bonus — 1st Job | B21: =IFERROR(1/(I21-100),"n/a") | C21: level | D21: =Inputs!$B$24 | E21: =(Inputs!$B$24+1) | F21: =Summary!$B$3 | G21: =B642 | H21: =G21-F21 | I21: =IF(F21=0,0,G21/F21*100)
A22: Skill Level Bonus — 2nd Job | B22: =IFERROR(1/(I22-100),"n/a") | C22: level | D22: =Inputs!$B$25 | E22: =(Inputs!$B$25+1) | F22: =Summary!$B$3 | G22: =B678 | H22: =G22-F22 | I22: =IF(F22=0,0,G22/F22*100)
A23: Skill Level Bonus — 3rd Job | B23: =IFERROR(1/(I23-100),"n/a") | C23: level | D23: =Inputs!$B$26 | E23: =(Inputs!$B$26+1) | F23: =Summary!$B$3 | G23: =B714 | H23: =G23-F23 | I23: =IF(F23=0,0,G23/F23*100)
A24: Skill Level Bonus — 4th Job | B24: =IFERROR(1/(I24-100),"n/a") | C24: level | D24: =Inputs!$B$27 | E24: =(Inputs!$B$27+1) | F24: =Summary!$B$3 | G24: =B750 | H24: =G24-F24 | I24: =IF(F24=0,0,G24/F24*100)
A25: Skill Level Bonus — All Skills | B25: =IFERROR(1/(I25-100),"n/a") | C25: level | D25: =Inputs!$B$28 | E25: =(Inputs!$B$28+1) | F25: =Summary!$B$3 | G25: =B786 | H25: =G25-F25 | I25: =IF(F25=0,0,G25/F25*100)
A26: Flat ATTACK | B26: =IFERROR(1/(I26-100),"n/a") | C26: flat | D26: =Inputs!$B$5 | E26: =(Inputs!$B$5+1) | F26: =Summary!$B$3 | G26: =B822 | H26: =G26-F26 | I26: =IF(F26=0,0,G26/F26*100)
A27: ATTACK % | B27: =IFERROR(1/(I27-100),"n/a") | C27: pct | D27: =Inputs!$B$6 | E27: =(Inputs!$B$6+1) | F27: =Summary!$B$3 | G27: =B858 | H27: =G27-F27 | I27: =IF(F27=0,0,G27/F27*100)
