Workbook

Sheet README
A1: Corsair — DPS Calculator: How to Use This Workbook
A3: How to use this workbook
A4: Only edit the yellow-highlighted cells on the Inputs sheet — every other sheet is computed from those values and will be overwritten if you rebuild the workbook.
A5: Summary shows Total DPS, a Per-Skill DPS Breakdown (damage-dealing skills only — buffs/passives that never deal their own damage are omitted), and a Marginal DPS & Stat Value table showing the DPS gained per +1 of each stat.
A6: Sensitivity has the full detail behind that marginal-value table — one self-contained block per stat, showing exactly how bumping that stat by +1 changes every downstream number.
A7: CubeData/PotentialCubes model your current gear's Potential Cube lines and drive cube-reroll expected-value decisions. For the full standalone Potential Cube EV calculator (exact optimal-stopping math, works from this workbook alone), see tools/potential_cubes_ev.py in the project repo.
A9: Design decisions & assumptions
A10: CRITICAL: Corsair has ZERO individual wiki pages AND no Mastery page at all — worse than any other class built in this project. Every scaling skill's (baseDamage, factorIndex) is a FLAGGED ASSUMPTION from its own level-1 value; every mastery bonus below is a FLAGGED ASSUMPTION mapped from Buccaneer's own real mastery table by skill-slot role, per direct user decision. This entire workbook's accuracy ceiling is lower than every sibling class — treat every number as a documented estimate, not verified data.
A11: Shadow Heart, Quick Motion (AS component only), Agile Guns, Gun Mastery, Physical Training, Infinity Blast, Fullmetal Jacket, Cross Cut Blast, and Quickdraw's own flat +25% Basic Attack Damage component are always-on passives assumed to already be reflected in your own Inputs stat entries — only their Sensitivity marginal delta is modeled live, matching this project's established convention.
A12: Eight-Legs Easton (basic attack) reuses the universal 4th-job-basic-attack constant (baseDamage 2900, factorIndex 21) confirmed identical across every class in this project. Its own Mastery chain is mapped from Buccaneer's own Hook Bomber chain (same universal pattern).
A13: Nautilus Strike and Roll of the Dice are both CONFIRMED SHARED verbatim with Buccaneer (byte-identical wiki descriptions) — reuse Buccaneer's exact resolved tuples directly, not re-derived.
A14: Scurvy Summons / All Aboard (crew summons) and Broadside's burst+sustained split use the standard generic ActiveWindow/ICD tick machinery already used for every summon/turret skill in this project (Bowmaster's Phoenix, FP-Mage's Ifrit) — no bespoke mechanics needed.
... A20: Not modeled (out of scope): all forms of crowd control (Blackboot Bill's stun), Accuracy, Evasion, Defense, movement speed, and Companion Summoning Time.

Sheet Inputs
A1: Corsair — DPS Calculator Inputs
A3: Character Level | B3: 200
A4: Monster Type ("boss", "normal", "breakthrough", or "pvp") | B4: boss
A5: Flat ATTACK | B5: 10000
A6: ATTACK % | B6: 0
A7: Monster Defense (flat, post-x100/x10 scaling) | B7: 0
A8: CRIT_RATE % | B8: 0
A9: CRIT_DAMAGE % | B9: 0
A10: ATTACK_SPEED % (base, excludes Weapon Acceleration) | B10: 0
A11: Flat DEX | B11: 0
A12: DEX % | B12: 0
A13: STR | B13: 0
A14: DAMAGE % | B14: 0
A15: DAMAGE_AMP % | B15: 0
A16: BASIC_ATTACK_DAMAGE % | B16: 0
... A28: Skill Level Bonus — All Skills | B28: 0
A30: Additional Bonuses
A31: Skill Cooldown Decrease (seconds, only skills/buffs the character actively casts) | B31: 0
A32: Basic Attack Target Increase (flat, adds to the 6-target normal-monster base) | B32: 1
A33: Buff Duration Increase % | B33: 0
A34: Companion Summoning Time Increase % (companions not modeled — always 0 DPS impact) | B34: 0
A35: Fixed Fight Duration (seconds, boss or normal — leave 0 for steady-state DPS; ignored for pvp) | B35: 0
A36: Chapter Breakthrough: Normal-Monster Weight % (only used when Monster Type = breakthrough) | B36: 60
A37: Max Enemies Actually In Range (normal monsters only; default 999 = uncapped) | B37: 999

Sheet FactorTable
A1: Level | B1: F0 | C1: F1 | D1: F2 | E1: F3 | F1: F4 | G1: F5 | H1: F6 | I1: F7 | J1: F8 | K1: F9 | L1: F10 | M1: F11 | N1: F12 | O1: F13 | P1: F14 | Q1: F15 | R1: F16 | S1: F17 | T1: F18 | U1: F19 | V1: F20 | W1: F21 | X1: F22 | Y1: F23
A2: 1 | B2: 0 | C2: 1000 | D2: 1000 | E2: 1000 | F2: 1000 | G2: 1000 | H2: 1000 | I2: 1000 | J2: 1000 | K2: 1000 | L2: 1000 | M2: 1000 | N2: 1000 | O2: 1000 | P2: 1000 | Q2: 1000 | R2: 1000 | S2: 1000 | T2: 1000 | U2: 1000 | V2: 1000 | W2: 1000 | X2: 1000 | Y2: 1000
A3: 2 | B3: 0 | C3: 1015 | D3: 1020 | E3: 1030 | F3: 1040 | G3: 1050 | H3: 1060 | I3: 1070 | J3: 1020 | K3: 1020 | L3: 1020 | M3: 1000 | N3: 1010 | O3: 1020 | P3: 1030 | Q3: 1040 | R3: 1050 | S3: 1060 | T3: 1070 | U3: 1080 | V3: 1010 | W3: 1008 | X3: 1006 | Y3: 1100
A4: 3 | B4: 0 | C4: 1031 | D4: 1041 | E4: 1061 | F4: 1082 | G4: 1103 | H4: 1124 | I4: 1145 | J4: 1030 | K4: 1041 | L4: 1030 | M4: 1000 | N4: 1015 | O4: 1030 | P4: 1045 | Q4: 1060 | R4: 1075 | S4: 1090 | T4: 1105 | U4: 1120 | V4: 1020 | W4: 1012 | X4: 1009 | Y4: 1150
A5: 4 | B5: 0 | C5: 1047 | D5: 1062 | E5: 1093 | F5: 1126 | G5: 1159 | H5: 1192 | I5: 1226 | J5: 1040 | K5: 1062 | L5: 1040 | M5: 1000 | N5: 1020 | O5: 1040 | P5: 1060 | Q5: 1080 | R5: 1100 | S5: 1120 | T5: 1140 | U5: 1160 | V5: 1030 | W5: 1016 | X5: 1012 | Y5: 1200
A6: 5 | B6: 0 | C6: 1063 | D6: 1084 | E6: 1126 | F6: 1172 | G6: 1217 | H6: 1264 | I6: 1312 | J6: 1050 | K6: 1084 | L6: 1050 | M6: 1000 | N6: 1025 | O6: 1050 | P6: 1075 | Q6: 1100 | R6: 1125 | S6: 1150 | T6: 1175 | U6: 1200 | V6: 1040 | W6: 1020 | X6: 1015 | Y6: 1250
A7: 6 | B7: 0 | C7: 1079 | D7: 1106 | E7: 1160 | F7: 1219 | G7: 1278 | H7: 1340 | I7: 1404 | J7: 1060 | K7: 1106 | L7: 1060 | M7: 1000 | N7: 1030 | O7: 1060 | P7: 1090 | Q7: 1120 | R7: 1150 | S7: 1180 | T7: 1210 | U7: 1240 | V7: 1050 | W7: 1024 | X7: 1018 | Y7: 1300
A8: 7 | B8: 0 | C8: 1096 | D8: 1129 | E8: 1195 | F8: 1268 | G8: 1342 | H8: 1421 | I8: 1503 | J8: 1070 | K8: 1129 | L8: 1070 | M8: 1000 | N8: 1035 | O8: 1070 | P8: 1105 | Q8: 1140 | R8: 1175 | S8: 1210 | T8: 1245 | U8: 1280 | V8: 1060 | W8: 1028 | X8: 1021 | Y8: 1350
A9: 8 | B9: 0 | C9: 1113 | D9: 1152 | E9: 1231 | F9: 1319 | G9: 1410 | H9: 1507 | I9: 1609 | J9: 1080 | K9: 1152 | L9: 1080 | M9: 1000 | N9: 1040 | O9: 1080 | P9: 1120 | Q9: 1160 | R9: 1200 | S9: 1240 | T9: 1280 | U9: 1320 | V9: 1070 | W9: 1032 | X9: 1024 | Y9: 1400
A10: 9 | B10: 0 | C10: 1130 | D10: 1176 | E10: 1268 | F10: 1372 | G10: 1481 | H10: 1598 | I10: 1722 | J10: 1090 | K10: 1176 | L10: 1090 | M10: 1000 | N10: 1045 | O10: 1090 | P10: 1135 | Q10: 1180 | R10: 1225 | S10: 1270 | T10: 1315 | U10: 1360 | V10: 1080 | W10: 1036 | X10: 1027 | Y10: 1450
A11: 10 | B11: 0 | C11: 1147 | D11: 1200 | E11: 1307 | F11: 1427 | G11: 1556 | H11: 1694 | I11: 1843 | J11: 1100 | K11: 1200 | L11: 1100 | M11: 1000 | N11: 1050 | O11: 1100 | P11: 1150 | Q11: 1200 | R11: 1250 | S11: 1300 | T11: 1350 | U11: 1400 | V11: 1090 | W11: 1040 | X11: 1030 | Y11: 1500
A12: 11 | B12: 0 | C12: 1165 | D12: 1224 | E12: 1347 | F12: 1485 | G12: 1634 | H12: 1796 | I12: 1973 | J12: 1110 | K12: 1224 | L12: 1110 | M12: 1000 | N12: 1055 | O12: 1110 | P12: 1165 | Q12: 1220 | R12: 1275 | S12: 1330 | T12: 1385 | U12: 1440 | V12: 1100 | W12: 1044 | X12: 1033 | Y12: 1550
A13: 12 | B13: 0 | C13: 1183 | D13: 1249 | E13: 1388 | F13: 1545 | G13: 1716 | H13: 1904 | I13: 2112 | J13: 1120 | K13: 1249 | L13: 1120 | M13: 1000 | N13: 1060 | O13: 1120 | P13: 1180 | Q13: 1240 | R13: 1300 | S13: 1360 | T13: 1420 | U13: 1480 | V13: 1110 | W13: 1048 | X13: 1036 | Y13: 1600
... A301: 300 | B301: 0 | C301: 88573 | D301: 381637 | E301: 6991522 | F301: 125363453 | G301: 2185120762 | H301: 37157073039 | I301: 614631863830 | J301: 2000 | K301: 53326 | L301: 2500 | M301: 1100 | N301: 2500 | O301: 4000 | P301: 5500 | Q301: 7000 | R301: 8500 | S301: 10000 | T301: 11500 | U301: 13000 | V301: 7558 | W301: 2200 | X301: 1900 | Y301: 8800

Sheet Skills
A1: Key | B1: Name | C1: JobStep | D1: Cooldown(s) | E1: CostsActionSlot | F1: ActionsPerCast | G1: HitsPerCast | H1: ICD(s) | I1: ActiveWindow(s) | J1: ProcChance% | K1: RollsPerCast | L1: BaseDamage(tenths%) | M1: FactorIndex | N1: ScalesWithLevel | O1: SkillMasteryBonus% | P1: MasteryBossDamage% | Q1: MasteryNormalDamage% | R1: NormalMonsterTargets | S1: BuffTargetStat | T1: BuffDuration(s) | U1: MapleHeroBase(tenths%) | V1: MapleHeroFactorIndex | W1: Note
A2: EIGHT_LEGS_EASTON | B2: Eight-Legs Easton | C2: 4 | E2: FALSE | F2: 1 | G2: =IF(Inputs!$B$3>=136,6,5) | H2: 0 | I2: 0 | J2: 100 | K2: 1 | L2: 2900 | M2: 21 | N2: TRUE | O2: =SUMPRODUCT((Inputs!$B$3>={102,106,116,120,128,132})*{10,1,1,1,1,1}) | P2: =SUMPRODUCT((Inputs!$B$3>={111,124})*{10,10}) | Q2: 0 | R2: =6+Inputs!$B$32 | T2: 0 | W2: 4th-job basic-attack effect (supersedes Double Shot/Rapid Blast/Blunderbuster, confirmed identical wiki wording — 290% damage to 6 target(s) in front 5 time(s) — to every other class's own 4th-job basic attack). factorIndex 21, baseDamage 2900 tenths%. HitsPerCast=5, bumping to 6 once the ASSUMED Mastery Lv.136 tier unlocks (mapped from Buccaneer's own Hook Bomber - Strike slot — Corsair has no Mastery page at all to confirm this independently). Real Damage mastery chain (102/106/116/120/128/132, DELTAS) and Boss Monster Damage chain (111/124, +10% each) mapped directly from Buccaneer's own Hook Bomber chain — this is the same universal 4th-job-basic-attack mastery pattern confirmed across every class in this project, so this specific mapping is high-confidence despite the overall lack of Corsair mastery data.
A3: SWIFT_FIRE | B3: Swift Fire | C3: 2 | D3: 18 | E3: TRUE | F3: 1 | G3: 3 | H3: 0 | I3: 0 | J3: 100 | K3: 1 | L3: 1800 | M3: 12 | N3: TRUE | O3: =SUMPRODUCT((Inputs!$B$3>={39})*{50}) | P3: 0 | Q3: 0 | R3: 8 | T3: 0 | U3: 200 | V3: 23 | W3: FLAGGED ASSUMPTION (no individual wiki page exists, no cooldown stated — 18s assumed by convention matching similarly-shaped 2nd-job burst skills elsewhere): 'Fires three bullets consecutively at the target to deal 180% damage each.' factorIndex 12, baseDamage 1800 tenths%. PATCHED: single-target -> up to 8 enemies ahead (targets field reflects this). Mastery mapped from Buccaneer's own Sea Serpent Burst - Damage @39 (+50%) slot — no exact 1:1 analog exists since Corsair has no mastery data at all, but both are the class's own 2nd-job attack-proc-shaped skill, so this role-mapping is a reasonable assumption. Maple Hero target — see MAPLE_HERO_RATIOS (biggest share, 4x Siege Bomber's own).
A4: SCURVY_SUMMONS | B4: Scurvy Summons | C4: 2 | D4: 20 | E4: TRUE | F4: 1 | G4: 2 | H4: 1.5 | I4: 20 | J4: 100 | K4: 1 | L4: 950 | M4: 12 | N4: TRUE | O4: 0 | P4: 0 | Q4: 0 | R4: 3 | T4: 0 | W4: FLAGGED ASSUMPTION (no individual wiki page exists, cooldown assumed = its own 20s duration, recast-on-expiry, same convention as every other summon/turret skill in this project): 'Summons the Dual Pistol Crew of the Nautilus for 20 sec. The Dual Pistol Crew deals 95% damage to the target 2 time(s) every 3 sec.' factorIndex 12, baseDamage 950 tenths%. PATCHED: tick interval 3s->1.5s (baked into ICD(s)), crew now hits up to 3 nearby targets instead of single-target (targets field reflects this). Standard ActiveWindow/ICD tick machinery (EffectiveHits = 2*(20/1.5) per cast) — no bespoke mechanics needed, unlike Buccaneer's own resource-economy skills. No clean Buccaneer mastery-slot analog exists for this specific crew-summon mechanic — left unmodeled (SkillMasteryBonus%=0) rather than forcing a poor mapping. Ahoy Mateys target — see AHOY_MATEYS_RATIOS (biggest share, ratio 1.0).
A5: ALL_ABOARD | B5: All Aboard | C5: 2 | D5: 20 | E5: FALSE | F5: 1 | G5: 3 | H5: 2 | I5: 20 | J5: 100 | K5: 1 | L5: 1100 | M5: 12 | N5: TRUE | O5: 0 | P5: 0 | Q5: 0 | R5: 8 | T5: 0 | W5: FLAGGED ASSUMPTION (no individual wiki page exists): 'Summons the Sharpshooter Crew upon using Scurvy Summons. The Sharpshooter Crew fires bullets every 4 sec to deal 190% damage to 3 target(s) near the main target 3 time(s).' Triggered BY Scurvy Summons — shares its own Cooldown(s)/duration values directly (CostsActionSlot=False so it doesn't double-count the action economy), same 'rides the parent skill's cast timing' pattern as Buccaneer's own Sea Serpent's Rage riding Octopunch. factorIndex 12, baseDamage 1100 tenths%. PATCHED: tick interval 4s->2s (baked into ICD(s)), damage 190%->110%, targets 3->8. No clean Buccaneer mastery-slot analog — left unmodeled. Ahoy Mateys target — see AHOY_MATEYS_RATIOS (0.4x Scurvy Summons' own share).
A6: BLACKBOOT_BILL | B6: Blackboot Bill | C6: 3 | D6: 20 | E6: TRUE | F6: 1 | G6: 4 | H6: 0 | I6: 0 | J6: 100 | K6: 1 | L6: 1700 | M6: 12 | N6: TRUE | O6: =SUMPRODUCT((Inputs!$B$3>={73})*{80}) | P6: 0 | Q6: 0 | R6: 9 | T6: 0 | U6: 400 | V6: 23 | W6: FLAGGED ASSUMPTION (no individual wiki page exists, no cooldown stated — 20s assumed by convention matching Buccaneer's own similarly-shaped Corkscrew Blow): 'Fires a giant bullet to deal 170% damage to 6 target(s) in front 4 time(s) and stun them for 2 sec' (stun not modeled). factorIndex 12, baseDamage 1700 tenths%. PATCHED: targets 6->9. Mastery mapped from Buccaneer's own Corkscrew Blow - Damage @73 (+80%) slot — both are the class's own 3rd-job unique burst skill. Maple Hero target — see MAPLE_HERO_RATIOS (2x Siege Bomber's own share).
A7: SIEGE_BOMBER | B7: Siege Bomber | C7: 3 | D7: 30 | E7: TRUE | F7: 1 | G7: 1 | H7: 1.5 | I7: 30 | J7: 100 | K7: 1 | L7: 1900 | M7: 12 | N7: TRUE | O7: 0 | P7: 0 | Q7: 0 | R7: 6 | T7: 0 | U7: 100 | V7: 23 | W7: FLAGGED ASSUMPTION (no individual wiki page exists, cooldown assumed = its own 30s duration, recast-on-expiry): 'Installs a fixed cannon for 30 sec to deal 290% damage to 4 target(s) near the main target every 2.5 sec.' factorIndex 12, baseDamage 1900 tenths%. PATCHED: tick interval 2.5s->1.5s (baked into ICD(s)), damage 290%->190%, targets 4->6. Standard ActiveWindow/ICD turret machinery, same as Bowmaster's own Arrow Platter. No clean Buccaneer mastery-slot analog — left unmodeled. Maple Hero target — see MAPLE_HERO_RATIOS (smallest share, ratio 1.0).
A8: BRAIN_SCRAMBLER | B8: Brain Scrambler | C8: 4 | D8: 15 | E8: TRUE | F8: 1 | G8: 2 | H8: 0 | I8: 0 | J8: 100 | K8: 1 | L8: 29000 | M8: 12 | N8: TRUE | O8: =SUMPRODUCT((Inputs!$B$3>={108})*{50}) | P8: 0 | Q8: 0 | R8: 1 | T8: 0 | W8: FLAGGED ASSUMPTION (no individual wiki page exists, no cooldown stated — 15s assumed by convention matching Buccaneer's own similarly-shaped 4th-job burst skill Octopunch): 'Hits the target's head to deal 2900% damage 2 time(s).' factorIndex 12, baseDamage 29000 tenths%, single target. Mastery mapped from Buccaneer's own Octopunch - Damage @108 (+50%) slot — both are the class's own 4th-job single-target burst skill. Also feeds Majestic Presence's own combined trigger rate — see MAJESTIC_PRESENCE's own Note.
A9: NAUTILUS_STRIKE | B9: Nautilus Strike | C9: 4 | D9: 45 | E9: TRUE | F9: 1 | G9: 5 | H9: 0 | I9: 0 | J9: 100 | K9: 1 | L9: 19500 | M9: 12 | N9: TRUE | O9: =SUMPRODUCT((Inputs!$B$3>={126})*{50}) | P9: 0 | Q9: 0 | R9: 15 | T9: 0 | W9: CONFIRMED SHARED VERBATIM WITH BUCCANEER (byte-identical wiki description on both classes' overview pages: 'Orders the Nautilus to attack to deal 1950% damage to 15 nearby target(s) 5 time(s).') — reuses Buccaneer's exact FLAGGED-ASSUMPTION (19500, 12) tuple directly, not re-derived. Cooldown (45s) also reused from Buccaneer's own assumption. Mastery mapped from Buccaneer's own Nautilus Strike - Damage @126 (+50%) slot — since this is the SAME shared skill, this mapping is higher-confidence than most other role-mapped masteries in this workbook.
A10: NAUTILUS_FINAL_ATTACK | B10: Nautilus Strike - Final Attack | C10: 4 | D10: 1 | E10: FALSE | F10: 1 | G10: 1 | H10: 0 | I10: 0 | J10: 30 | K10: 1 | L10: 8500 | M10: 21 | N10: TRUE | O10: 0 | P10: 0 | Q10: 0 | R10: 1 | T10: 0 | W10: CONFIRMED SHARED VERBATIM WITH BUCCANEER — same Mastery Lv.113 proc mechanic, same patch note applies identically to both classes: '[Nautilus Strike in Slot] When attacking, deals 850% additional damage' — PATCHED: trigger chance 15%->30%, 'cooldown set to 1s' (both baked in directly: ProcChance%=30, Cooldown(s)=1). Reuses Buccaneer's exact row shape/tuple directly. Triggers off basic attacks generically (CostsActionSlot=False), factorIndex 21, baseDamage 8500 tenths%.
A11: RAPID_FIRE | B11: Rapid Fire | C11: 4 | D11: 17 | E11: TRUE | F11: 1 | G11: 7 | H11: 0 | I11: 0 | J11: 100 | K11: 1 | L11: 18000 | M11: 12 | N11: TRUE | O11: 0 | P11: 0 | Q11: 0 | R11: 9 | T11: 0 | W11: FLAGGED ASSUMPTION (no individual wiki page exists, but cooldown IS explicitly stated in the patch notes — see below): 'Fires bullets at a very high speed 7 time(s) to deal 1350% damage each.' factorIndex 12, baseDamage 18000 tenths% (already reflects the patch). PATCHED: single-target -> up to 9 enemies (targets field), damage 1350%->1800% (curve rescaled 1800/1350=1.333x before applying), cooldown 21s->17s (Cooldown(s) already reflects the patched value directly, unlike every other assumed cooldown in this workbook — this one has an actual documented number). No clean Buccaneer mastery-slot analog — left unmodeled. Also feeds Majestic Presence's own combined trigger rate.
A12: BROADSIDE_BURST | B12: Broadside (initial burst) | C12: 4 | D12: 30 | E12: TRUE | F12: 1 | G12: 2 | H12: 0 | I12: 0 | J12: 100 | K12: 1 | L12: 50000 | M12: 12 | N12: TRUE | O12: =SUMPRODUCT((Inputs!$B$3>={122})*{100}) | P12: 0 | Q12: 0 | R12: 10 | T12: 0 | W12: FLAGGED ASSUMPTION (no individual wiki page exists, cooldown assumed = its own 30s sustained-phase duration, recast-on-expiry): 'Summons the Nautilus's Battleship. The Battleship arrives behind 3 sec later and deals 3800% damage to 5 nearby target(s) 2 time(s).' (the 3s arrival delay is not modeled — folded into a same-cast instant hit, same simplification tier as every other 'delayed burst' skill in this project). factorIndex 12, baseDamage 50000 tenths% (already reflects the patch). PATCHED: damage 3800%->5000%, targets 5->10. This row pays the real Cooldown(s)/action-slot cost; see BROADSIDE_SUSTAINED for the follow-up turret phase, which rides this row's own cast timing. Mastery mapped from Buccaneer's own Sea Serpent's Rage - Damage @122 (+100%) slot — both are the class's own 4th-job summon-triggered burst effect.
A13: BROADSIDE_SUSTAINED | B13: Broadside (sustained turret) | C13: 4 | D13: 30 | E13: FALSE | F13: 1 | G13: 1 | H13: 2 | I13: 30 | J13: 100 | K13: 1 | L13: 33000 | M13: 12 | N13: TRUE | O13: 0 | P13: 0 | Q13: 0 | R13: 5 | T13: 0 | W13: FLAGGED ASSUMPTION (no individual wiki page exists, target count assumed = the burst phase's own PRE-patch value of 5, since the Aug 13 patch notes only cover the initial burst numbers, not this sustained phase — its patch status is genuinely unstated, not necessarily unchanged): 'Afterward it stays for 30 sec and deals 3300% damage to target(s) in front of the Battleship every 2 sec.' factorIndex 12, baseDamage 33000 tenths%. Shares BROADSIDE_BURST's own Cooldown(s) value (same cast timing, CostsActionSlot=False so it doesn't double-count the action economy) — same 'rides the parent's cast timing' pattern as ALL_ABOARD riding SCURVY_SUMMONS.
A14: MAJESTIC_PRESENCE | B14: Majestic Presence | C14: 4 | E14: FALSE | F14: 1 | G14: 1 | H14: 0 | I14: 0 | J14: 25 | K14: 1 | L14: 18000 | M14: 12 | N14: TRUE | O14: 0 | P14: 0 | Q14: 0 | R14: 6 | T14: 0 | W14: FLAGGED ASSUMPTION (no individual wiki page exists): 'When attacking with Basic Attacks Brain Scrambler or Rapid Fire deals 1800% additional damage with a 25% chance.' PATCHED: single-target -> up to 6 enemies near target (targets field). factorIndex 12, baseDamage 18000 tenths%. Procs off THREE independent sources (Basic Attack + Brain Scrambler + Rapid Fire) — has no Cooldown(s) of its own at all (CostsActionSlot=False); its own combined trigger rate is built directly in build_calc_sheet/build_stat_block as Summary!$B$R_BAPS (basic attack rate) + Brain Scrambler's own HitRate(perSec) + Rapid Fire's own HitRate(perSec), extending Marksman's own Bolt Surplus dual-trigger pattern to three sources instead of two. No clean Buccaneer mastery-slot analog — left unmodeled.
A15: MAPLE_HERO_HELPER | B15: Maple Hero (helper) | C15: 4 | E15: FALSE | F15: 1 | G15: 1 | H15: 0 | I15: 0 | J15: 100 | K15: 1 | L15: 200 | M15: 23 | N15: TRUE | O15: 0 | P15: 0 | Q15: 0 | R15: 0 | T15: 0 | W15: Shared ratio-feeder row (see MAPLE_HERO_RATIOS) for Siege Bomber/Blackboot Bill/Swift Fire's own Final Damage chains — mirrors every other class's own Maple Hero mechanism. UNLIKE Buccaneer's own truncated entry, Corsair's level-1 anchor values ARE real/confirmed: 'Siege Bomber 20%, Blackboot Bill 40%, Swift Fire 80%.' FLAGGED ASSUMPTION: factorIndex 23 (the universal Maple Hero growth-curve convention confirmed on every other class), baseDamage 200 tenths% anchored to the confirmed level-1 value (20%). No individual Maple_Hero_(Corsair) page exists to verify the real growth curve. No independent DPS row of its own (Calc columns J-N blank/0, only D/E/F computed, read directly by each target row's own K-column formula).
A16: AHOY_MATEYS_HELPER | B16: Ahoy Mateys (helper) | C16: 4 | E16: FALSE | F16: 1 | G16: 1 | H16: 0 | I16: 0 | J16: 100 | K16: 1 | L16: 2500 | M16: 22 | N16: TRUE | O16: 0 | P16: 0 | Q16: 0 | R16: 0 | T16: 0 | W16: Shared ratio-feeder row (see AHOY_MATEYS_RATIOS) for Scurvy Summons/All Aboard's own Final Damage chains — a SEPARATE, independent helper from Maple Hero (Ahoy Mateys is its own skill, not literally 'Maple Hero'), same 'no independent DPS row' mechanism. FLAGGED ASSUMPTION: factorIndex 22 (generic buff-growth convention, not tied to Maple Hero's own special factorIndex 23 since this is a genuinely different skill), baseDamage 2500 tenths% anchored to the confirmed level-1 value (250%, Scurvy Summons' own share). No individual wiki page exists for this skill at all — even its unlock level is a bare position-in-list assumption.
A17: ROLL_OF_THE_DICE_DICE | B17: Roll of the Dice (dice component) | C17: 3 | E17: FALSE | F17: 1 | G17: 1 | H17: 0 | I17: 0 | J17: 100 | K17: 1 | L17: 25 | M17: 0 | N17: FALSE | O17: 0 | P17: 0 | Q17: 0 | R17: 0 | S17: ATTACK | T17: 0 | W17: CONFIRMED SHARED VERBATIM WITH BUCCANEER (byte-identical wiki description, discovered during this build — not called out by the original research report): 'Increases Attack by 20%. Rolls a six-sided die every 7 sec to increase Attack by 0-5% in proportion to the number on the die for 5 sec. A number that has appeared once does not appear again for 30 sec.' Reuses Buccaneer's exact treatment: this row models ONLY the random dice component, approximated at its average roll (2.5%, the midpoint of 0-5%) treated as an always-active flat bonus once unlocked. The flat, unconditional '+20% Attack' base effect is Magic-Critical-pattern (assumed already reflected in your own Inputs!ATTACK_PCT, see PASSIVE_DELTA_SLOT). factorIndex 0 (non-scaling placeholder), baseDamage 25 tenths%.
A18: JOLLY_ROGER_FD | B18: Jolly Roger | C18: 4 | E18: FALSE | F18: 1 | G18: 1 | H18: 0 | I18: 0 | J18: 100 | K18: 1 | L18: 150 | M18: 22 | N18: TRUE | O18: 0 | P18: 0 | Q18: 0 | R18: 0 | S18: FINAL_DAMAGE | T18: 0 | W18: FLAGGED ASSUMPTION (no individual wiki page exists, no cooldown stated — modeled as always-active steady-state once unlocked, same tier as Buccaneer's own Crossbones/Time Leap): 'Increases Final Damage by 18% for 18 sec but decreases Evasion by 5' (Evasion not modeled). PATCHED: Final Damage 18%->15% (a nerf — baseDamage already reflects this). factorIndex 22, baseDamage 150 tenths%. Corsair's ONLY live (non-Magic-Critical) Final Damage source — feeds R_FD_BONUS directly.
A19: SHADOW_HEART | B19: Shadow Heart | C19: 1 | E19: FALSE | F19: 1 | G19: 1 | H19: 0 | I19: 0 | J19: 100 | K19: 1 | L19: 50 | M19: 22 | N19: TRUE | O19: 0 | P19: 0 | Q19: 0 | R19: 0 | S19: CRIT_RATE | T19: 0 | W19: Magic Critical pattern — already baked into Inputs!CRIT_RATE%; feeds the 1st-Job Skill Level Bonus delta. FLAGGED ASSUMPTION (no individual wiki page exists, though byte-identical wording to Buccaneer's own Shadow Heart): 'Increases Critical Rate by 5%.' factorIndex 22, baseDamage 50 tenths%.
A20: QUICK_MOTION | B20: Quick Motion | C20: 1 | E20: FALSE | F20: 1 | G20: 1 | H20: 0 | I20: 0 | J20: 100 | K20: 1 | L20: 60 | M20: 22 | N20: TRUE | O20: 0 | P20: 0 | Q20: 0 | R20: 0 | S20: ATTACK_SPEED | T20: 0 | W20: Magic Critical pattern — already baked into Inputs!ATTACK_SPEED%; feeds the 1st-Job Skill Level Bonus delta. FLAGGED ASSUMPTION (no individual wiki page exists, though byte-identical wording to Buccaneer's own Quick Motion): 'Increases Attack Speed by 6% and Speed by 8%' (Speed not modeled). Like Buccaneer, Corsair has NO Nimble-Feet-style live AS buff — Quick Motion is a flat passive. factorIndex 22, baseDamage 60 tenths%.
A21: AGILE_GUNS | B21: Agile Guns | C21: 2 | E21: FALSE | F21: 1 | G21: 1 | H21: 0 | I21: 0 | J21: 100 | K21: 1 | L21: 50 | M21: 22 | N21: TRUE | O21: =SUMPRODUCT((Inputs!$B$3>={44})*{7}) | P21: 0 | Q21: 0 | R21: 0 | S21: ATTACK_SPEED | T21: 0 | W21: Magic Critical pattern — already baked into Inputs!ATTACK_SPEED%; feeds the 2nd-Job Skill Level Bonus delta. FLAGGED ASSUMPTION (no individual wiki page exists): 'Increases Attack Speed by 5%.' factorIndex 22, baseDamage 50 tenths%. Mastery mapped from Buccaneer's own Agile Knuckles - Speed @44 (+7) slot — both are the class's own AS passive in the same kit-slot role.
A22: GUN_MASTERY | B22: Gun Mastery | C22: 2 | E22: FALSE | F22: 1 | G22: 1 | H22: 0 | I22: 0 | J22: 100 | K22: 1 | L22: 150 | M22: 22 | N22: TRUE | O22: 0 | P22: 0 | Q22: 0 | R22: 0 | S22: MIN_DAMAGE | T22: 0 | W22: Magic Critical pattern — already baked into Inputs!MIN_DAMAGE%; feeds the 2nd-Job Skill Level Bonus delta. FLAGGED ASSUMPTION (no individual wiki page exists): 'Increases Min Damage Multiplier by 15%.' factorIndex 22, baseDamage 150 tenths% — matches Buccaneer's own Knuckle Mastery exactly (same kit-slot role, no mastery bonus in either class).
A23: PHYSICAL_TRAINING | B23: Physical Training | C23: 2 | E23: FALSE | F23: 1 | G23: 1 | H23: 0 | I23: 0 | J23: 100 | K23: 1 | L23: 100 | M23: 22 | N23: TRUE | O23: 0 | P23: 0 | Q23: 0 | R23: 0 | S23: BASIC_ATTACK_DAMAGE | T23: 0 | W23: Magic Critical pattern — already baked into Inputs!BASIC_ATTACK_DAMAGE%; feeds the 2nd-Job Skill Level Bonus delta. FLAGGED ASSUMPTION (no individual wiki page exists, though byte-identical wording to every other class's own Physical Training): 'Increases Basic Attack Damage by 10%.' factorIndex 22, baseDamage 100 tenths%.
A24: INFINITY_BLAST_ATK | B24: Infinity Blast | C24: 2 | E24: FALSE | F24: 1 | G24: 1 | H24: 0 | I24: 0 | J24: 100 | K24: 1 | L24: 120 | M24: 22 | N24: TRUE | O24: 0 | P24: 0 | Q24: 0 | R24: 0 | S24: ATTACK | T24: 0 | W24: Magic Critical pattern — already baked into Inputs!ATTACK_PCT (folds into the attack_mult delta bucket, same slot as Buccaneer's own Dark Clarity). FLAGGED ASSUMPTION (no individual wiki page exists): 'Increases Attack by 10%.' PATCHED: 10%->12% (baseDamage already reflects this). factorIndex 22, baseDamage 120 tenths%.
A25: FULLMETAL_JACKET_CD | B25: Fullmetal Jacket | C25: 3 | E25: FALSE | F25: 1 | G25: 1 | H25: 0 | I25: 0 | J25: 100 | K25: 1 | L25: 100 | M25: 22 | N25: TRUE | O25: 0 | P25: 0 | Q25: 0 | R25: 0 | S25: CRIT_DAMAGE | T25: 0 | W25: Magic Critical pattern — already baked into Inputs!CRIT_DAMAGE%; feeds the 3rd-Job Skill Level Bonus delta. FLAGGED ASSUMPTION (no individual wiki page exists): 'Increases Critical Damage by 10%.' factorIndex 22, baseDamage 100 tenths%.
A26: CROSS_CUT_BLAST_FD | B26: Cross Cut Blast | C26: 3 | E26: FALSE | F26: 1 | G26: 1 | H26: 0 | I26: 0 | J26: 100 | K26: 1 | L26: 120 | M26: 22 | N26: TRUE | O26: 0 | P26: 0 | Q26: 0 | R26: 0 | S26: FINAL_DAMAGE | T26: 0 | W26: Magic Critical pattern — already baked into Inputs!FINAL_DAMAGE%; feeds the 3rd-Job Skill Level Bonus delta. FLAGGED ASSUMPTION (no individual wiki page exists): 'Increases Final Damage by 10%.' PATCHED: 10%->12% (baseDamage already reflects this). factorIndex 22, baseDamage 120 tenths%.
A27: QUICKDRAW_BAD | B27: Quickdraw | C27: 4 | E27: FALSE | F27: 1 | G27: 1 | H27: 0 | I27: 0 | J27: 100 | K27: 1 | L27: 250 | M27: 22 | N27: TRUE | O27: 0 | P27: 0 | Q27: 0 | R27: 0 | S27: BASIC_ATTACK_DAMAGE | T27: 0 | W27: Magic Critical pattern — already baked into Inputs!BASIC_ATTACK_DAMAGE%; feeds the 4th-Job Skill Level Bonus delta. FLAGGED ASSUMPTION (no individual wiki page exists): only the flat, unconditional 'Increases Basic Attack Damage by 25%' component is modeled here. factorIndex 22, baseDamage 250 tenths%. NOT modeled (out of scope): its own 'every 3rd Eight-Legs Easton cast doubles the damage and reduces Brain Scrambler/Rapid Fire cooldown by 1.5s' proc — no mechanic exists in this project for one skill's cast count to modify another's cooldown, and stacking that on top of an already-assumed kit was judged out of scope for this session.

Sheet Calc
A1: Key | B1: Name | C1: Unlocked | D1: InputLevel | E1: Factor | F1: CoefficientPercent | G1: EffectiveHits | H1: ProcProbability | I1: MapleHeroMultiplier | J1: BaseDamage | K1: BaseHitDamage | L1: NonCritAvg | M1: CritAvg | N1: ExpectedDamage(perHit) | O1: DPS | P1: % of Total | Q1: InvCooldown | R1: CastsInFight | S1: HitRate(perSec)
A2: =Skills!A2 | B2: =Skills!B2 | C2: =Inputs!$B$3>=100 | F2: =Summary!$B$54+Skills!O2 | G2: =Skills!G2*IF(Skills!H2>0,Skills!I2/Skills!H2,1) | H2: =1-(1-Skills!J2/100)^Skills!K2 | I2: 1 | J2: =Summary!$B$50*(F2/100) | K2: =J2*(1+Summary!$B$51/100)*(1+Inputs!$B$14/100)*(1+IF(Inputs!$B$4="pvp",0,(1-Summary!$B$55)*(Inputs!$B$19+Skills!P2+Summary!$B$59)+Summary!$B$55*(Inputs!$B$20+Skills!Q2+Summary!$B$59))/100)*(1+Inputs!$B$15/100)*(5000/(6000+Inputs!$B$7*(1-Inputs!$B$18/100)))*(1+(Inputs!$B$23+Summary!$B$65)/100)*(1+(IF(Skills!A2="EIGHT_LEGS_EASTON",Inputs!$B$16,Inputs!$B$17))/100)*(Summary!$B$57*I2) | L2: =K2*(MIN(Inputs!$B$21,Inputs!$B$22)/100+Inputs!$B$22/100)/2 | M2: =L2*(1+(Inputs!$B$9+Summary!$B$64)/100) | N2: =L2*(1-MIN((Inputs!$B$8+Summary!$B$58),100)/100)+M2*(MIN((Inputs!$B$8+Summary!$B$58),100)/100) | O2: =IF(C2,Skills!G2*N2*Summary!$B$63*IF(Inputs!$B$4="pvp",1,(1-Summary!$B$55)*(1)+Summary!$B$55*(MIN(Skills!R2,Inputs!$B$37))),0) | P2: =IF(Summary!$B$3=0,0,O2/Summary!$B$3) | Q2: 0 | R2: 0 | S2: =IFERROR(O2/N2,0)
A3: =Skills!A3 | B3: =Skills!B3 | C3: =Inputs!$B$3>=35 | D3: =IF(Skills!C3=1,60+Inputs!$B$24+Inputs!$B$28,IF(Skills!C3=2,90+Inputs!$B$25+Inputs!$B$28,IF(Skills!C3=3,120+Inputs!$B$26+Inputs!$B$28,MAX(0,(Inputs!$B$3-100)*3)+Inputs!$B$27+Inputs!$B$28))) | E3: =INDEX(FactorTable!$B$2:$Y$301, MATCH(ROUND(MIN(300,MAX(1,D3)),0), FactorTable!$A$2:$A$301,0), Skills!M3+1) | F3: =IF(Skills!N3=TRUE,(Skills!L3/10)*(E3/1000),Skills!L3/10)+Skills!O3 | G3: =Skills!G3*IF(Skills!H3>0,Skills!I3/Skills!H3,1) | H3: =1-(1-Skills!J3/100)^Skills!K3 | I3: 1 | J3: =Summary!$B$50*(F3/100) | K3: =J3*(1+Summary!$B$51/100)*(1+Inputs!$B$14/100)*(1+IF(Inputs!$B$4="pvp",0,(1-Summary!$B$55)*(Inputs!$B$19+Skills!P3+Summary!$B$59)+Summary!$B$55*(Inputs!$B$20+Skills!Q3+Summary!$B$59))/100)*(1+Inputs!$B$15/100)*(5000/(6000+Inputs!$B$7*(1-Inputs!$B$18/100)))*(1+(Inputs!$B$23+Summary!$B$65)/100)*(1+4.0*IF(C15=TRUE,F15,0)/100)*(1+(IF(Skills!A3="EIGHT_LEGS_EASTON",Inputs!$B$16,Inputs!$B$17))/100)*(Summary!$B$57*I3) | L3: =K3*(MIN(Inputs!$B$21,Inputs!$B$22)/100+Inputs!$B$22/100)/2 | M3: =L3*(1+(Inputs!$B$9+Summary!$B$64)/100) | N3: =L3*(1-MIN((Inputs!$B$8+Summary!$B$58),100)/100)+M3*(MIN((Inputs!$B$8+Summary!$B$58),100)/100) | O3: =IF(C3,H3*N3*IF(AND(Inputs!$B$4<>"pvp",Inputs!$B$35>0),((Skills!G3*((R3-1)*IF(Skills!H3>0,Skills!I3/Skills!H3,1)+IF(Skills!H3>0,MIN(Skills!I3,MAX(0,Inputs!$B$35-((R3-1)*IF(Inputs!$B$4="pvp",15,MAX(0.1,Skills!D3-IF(Skills!E3=TRUE,Inputs!$B$31,0))))))/Skills!H3,1)))/Inputs!$B$35),G3*Q3)*IF(Inputs!$B$4="pvp",1,(1-Summary!$B$55)*(1)+Summary!$B$55*(MIN(Skills!R3,Inputs!$B$37))),0) | P3: =IF(Summary!$B$3=0,0,O3/Summary!$B$3) | Q3: =IFERROR(1/IF(Inputs!$B$4="pvp",15,MAX(0.1,Skills!D3-IF(Skills!E3=TRUE,Inputs!$B$31,0))),0) | R3: =IF(AND(Inputs!$B$4<>"pvp",Inputs!$B$35>0),(INT(Inputs!$B$35/IF(Inputs!$B$4="pvp",15,MAX(0.1,Skills!D3-IF(Skills!E3=TRUE,Inputs!$B$31,0))))+1),0) | S3: =IFERROR(O3/N3,0)
A4: =Skills!A4 | B4: =Skills!B4 | C4: =Inputs!$B$3>=40 | D4: =IF(Skills!C4=1,60+Inputs!$B$24+Inputs!$B$28,IF(Skills!C4=2,90+Inputs!$B$25+Inputs!$B$28,IF(Skills!C4=3,120+Inputs!$B$26+Inputs!$B$28,MAX(0,(Inputs!$B$3-100)*3)+Inputs!$B$27+Inputs!$B$28))) | E4: =INDEX(FactorTable!$B$2:$Y$301, MATCH(ROUND(MIN(300,MAX(1,D4)),0), FactorTable!$A$2:$A$301,0), Skills!M4+1) | F4: =IF(Skills!N4=TRUE,(Skills!L4/10)*(E4/1000),Skills!L4/10)+Skills!O4 | G4: =Skills!G4*IF(Skills!H4>0,Skills!I4/Skills!H4,1) | H4: =1-(1-Skills!J4/100)^Skills!K4 | I4: 1 | J4: =Summary!$B$50*(F4/100) | K4: =J4*(1+Summary!$B$51/100)*(1+Inputs!$B$14/100)*(1+IF(Inputs!$B$4="pvp",0,(1-Summary!$B$55)*(Inputs!$B$19+Skills!P4+Summary!$B$59)+Summary!$B$55*(Inputs!$B$20+Skills!Q4+Summary!$B$59))/100)*(1+Inputs!$B$15/100)*(5000/(6000+Inputs!$B$7*(1-Inputs!$B$18/100)))*(1+(Inputs!$B$23+Summary!$B$65)/100)*(1+1.0*IF(C16=TRUE,F16,0)/100)*(1+(IF(Skills!A4="EIGHT_LEGS_EASTON",Inputs!$B$16,Inputs!$B$17))/100)*(Summary!$B$57*I4) | L4: =K4*(MIN(Inputs!$B$21,Inputs!$B$22)/100+Inputs!$B$22/100)/2 | M4: =L4*(1+(Inputs!$B$9+Summary!$B$64)/100) | N4: =L4*(1-MIN((Inputs!$B$8+Summary!$B$58),100)/100)+M4*(MIN((Inputs!$B$8+Summary!$B$58),100)/100) | O4: =IF(C4,H4*N4*IF(AND(Inputs!$B$4<>"pvp",Inputs!$B$35>0),((Skills!G4*((R4-1)*IF(Skills!H4>0,Skills!I4/Skills!H4,1)+IF(Skills!H4>0,MIN(Skills!I4,MAX(0,Inputs!$B$35-((R4-1)*IF(Inputs!$B$4="pvp",15,MAX(0.1,Skills!D4-IF(Skills!E4=TRUE,Inputs!$B$31,0))))))/Skills!H4,1)))/Inputs!$B$35),G4*Q4)*IF(Inputs!$B$4="pvp",1,(1-Summary!$B$55)*(1)+Summary!$B$55*(MIN(Skills!R4,Inputs!$B$37))),0) | P4: =IF(Summary!$B$3=0,0,O4/Summary!$B$3) | Q4: =IFERROR(1/IF(Inputs!$B$4="pvp",15,MAX(0.1,Skills!D4-IF(Skills!E4=TRUE,Inputs!$B$31,0))),0) | R4: =IF(AND(Inputs!$B$4<>"pvp",Inputs!$B$35>0),(INT(Inputs!$B$35/IF(Inputs!$B$4="pvp",15,MAX(0.1,Skills!D4-IF(Skills!E4=TRUE,Inputs!$B$31,0))))+1),0) | S4: =IFERROR(O4/N4,0)
A5: =Skills!A5 | B5: =Skills!B5 | C5: =Inputs!$B$3>=45 | D5: =IF(Skills!C5=1,60+Inputs!$B$24+Inputs!$B$28,IF(Skills!C5=2,90+Inputs!$B$25+Inputs!$B$28,IF(Skills!C5=3,120+Inputs!$B$26+Inputs!$B$28,MAX(0,(Inputs!$B$3-100)*3)+Inputs!$B$27+Inputs!$B$28))) | E5: =INDEX(FactorTable!$B$2:$Y$301, MATCH(ROUND(MIN(300,MAX(1,D5)),0), FactorTable!$A$2:$A$301,0), Skills!M5+1) | F5: =IF(Skills!N5=TRUE,(Skills!L5/10)*(E5/1000),Skills!L5/10)+Skills!O5 | G5: =Skills!G5*IF(Skills!H5>0,Skills!I5/Skills!H5,1) | H5: =1-(1-Skills!J5/100)^Skills!K5 | I5: 1 | J5: =Summary!$B$50*(F5/100) | K5: =J5*(1+Summary!$B$51/100)*(1+Inputs!$B$14/100)*(1+IF(Inputs!$B$4="pvp",0,(1-Summary!$B$55)*(Inputs!$B$19+Skills!P5+Summary!$B$59)+Summary!$B$55*(Inputs!$B$20+Skills!Q5+Summary!$B$59))/100)*(1+Inputs!$B$15/100)*(5000/(6000+Inputs!$B$7*(1-Inputs!$B$18/100)))*(1+(Inputs!$B$23+Summary!$B$65)/100)*(1+0.4*IF(C16=TRUE,F16,0)/100)*(1+(IF(Skills!A5="EIGHT_LEGS_EASTON",Inputs!$B$16,Inputs!$B$17))/100)*(Summary!$B$57*I5) | L5: =K5*(MIN(Inputs!$B$21,Inputs!$B$22)/100+Inputs!$B$22/100)/2 | M5: =L5*(1+(Inputs!$B$9+Summary!$B$64)/100) | N5: =L5*(1-MIN((Inputs!$B$8+Summary!$B$58),100)/100)+M5*(MIN((Inputs!$B$8+Summary!$B$58),100)/100) | O5: =IF(C5,H5*N5*IF(AND(Inputs!$B$4<>"pvp",Inputs!$B$35>0),((Skills!G5*((R5-1)*IF(Skills!H5>0,Skills!I5/Skills!H5,1)+IF(Skills!H5>0,MIN(Skills!I5,MAX(0,Inputs!$B$35-((R5-1)*IF(Inputs!$B$4="pvp",15,MAX(0.1,Skills!D5-IF(Skills!E5=TRUE,Inputs!$B$31,0))))))/Skills!H5,1)))/Inputs!$B$35),G5*Q5)*IF(Inputs!$B$4="pvp",1,(1-Summary!$B$55)*(1)+Summary!$B$55*(MIN(Skills!R5,Inputs!$B$37))),0) | P5: =IF(Summary!$B$3=0,0,O5/Summary!$B$3) | Q5: =IFERROR(1/IF(Inputs!$B$4="pvp",15,MAX(0.1,Skills!D5-IF(Skills!E5=TRUE,Inputs!$B$31,0))),0) | R5: =IF(AND(Inputs!$B$4<>"pvp",Inputs!$B$35>0),(INT(Inputs!$B$35/IF(Inputs!$B$4="pvp",15,MAX(0.1,Skills!D5-IF(Skills!E5=TRUE,Inputs!$B$31,0))))+1),0) | S5: =IFERROR(O5/N5,0)
A6: =Skills!A6 | B6: =Skills!B6 | C6: =Inputs!$B$3>=63 | D6: =IF(Skills!C6=1,60+Inputs!$B$24+Inputs!$B$28,IF(Skills!C6=2,90+Inputs!$B$25+Inputs!$B$28,IF(Skills!C6=3,120+Inputs!$B$26+Inputs!$B$28,MAX(0,(Inputs!$B$3-100)*3)+Inputs!$B$27+Inputs!$B$28))) | E6: =INDEX(FactorTable!$B$2:$Y$301, MATCH(ROUND(MIN(300,MAX(1,D6)),0), FactorTable!$A$2:$A$301,0), Skills!M6+1) | F6: =IF(Skills!N6=TRUE,(Skills!L6/10)*(E6/1000),Skills!L6/10)+Skills!O6 | G6: =Skills!G6*IF(Skills!H6>0,Skills!I6/Skills!H6,1) | H6: =1-(1-Skills!J6/100)^Skills!K6 | I6: 1 | J6: =Summary!$B$50*(F6/100) | K6: =J6*(1+Summary!$B$51/100)*(1+Inputs!$B$14/100)*(1+IF(Inputs!$B$4="pvp",0,(1-Summary!$B$55)*(Inputs!$B$19+Skills!P6+Summary!$B$59)+Summary!$B$55*(Inputs!$B$20+Skills!Q6+Summary!$B$59))/100)*(1+Inputs!$B$15/100)*(5000/(6000+Inputs!$B$7*(1-Inputs!$B$18/100)))*(1+(Inputs!$B$23+Summary!$B$65)/100)*(1+2.0*IF(C15=TRUE,F15,0)/100)*(1+(IF(Skills!A6="EIGHT_LEGS_EASTON",Inputs!$B$16,Inputs!$B$17))/100)*(Summary!$B$57*I6) | L6: =K6*(MIN(Inputs!$B$21,Inputs!$B$22)/100+Inputs!$B$22/100)/2 | M6: =L6*(1+(Inputs!$B$9+Summary!$B$64)/100) | N6: =L6*(1-MIN((Inputs!$B$8+Summary!$B$58),100)/100)+M6*(MIN((Inputs!$B$8+Summary!$B$58),100)/100) | O6: =IF(C6,H6*N6*IF(AND(Inputs!$B$4<>"pvp",Inputs!$B$35>0),((Skills!G6*((R6-1)*IF(Skills!H6>0,Skills!I6/Skills!H6,1)+IF(Skills!H6>0,MIN(Skills!I6,MAX(0,Inputs!$B$35-((R6-1)*IF(Inputs!$B$4="pvp",15,MAX(0.1,Skills!D6-IF(Skills!E6=TRUE,Inputs!$B$31,0))))))/Skills!H6,1)))/Inputs!$B$35),G6*Q6)*IF(Inputs!$B$4="pvp",1,(1-Summary!$B$55)*(1)+Summary!$B$55*(MIN(Skills!R6,Inputs!$B$37))),0) | P6: =IF(Summary!$B$3=0,0,O6/Summary!$B$3) | Q6: =IFERROR(1/IF(Inputs!$B$4="pvp",15,MAX(0.1,Skills!D6-IF(Skills!E6=TRUE,Inputs!$B$31,0))),0) | R6: =IF(AND(Inputs!$B$4<>"pvp",Inputs!$B$35>0),(INT(Inputs!$B$35/IF(Inputs!$B$4="pvp",15,MAX(0.1,Skills!D6-IF(Skills!E6=TRUE,Inputs!$B$31,0))))+1),0) | S6: =IFERROR(O6/N6,0)
A7: =Skills!A7 | B7: =Skills!B7 | C7: =Inputs!$B$3>=66 | D7: =IF(Skills!C7=1,60+Inputs!$B$24+Inputs!$B$28,IF(Skills!C7=2,90+Inputs!$B$25+Inputs!$B$28,IF(Skills!C7=3,120+Inputs!$B$26+Inputs!$B$28,MAX(0,(Inputs!$B$3-100)*3)+Inputs!$B$27+Inputs!$B$28))) | E7: =INDEX(FactorTable!$B$2:$Y$301, MATCH(ROUND(MIN(300,MAX(1,D7)),0), FactorTable!$A$2:$A$301,0), Skills!M7+1) | F7: =IF(Skills!N7=TRUE,(Skills!L7/10)*(E7/1000),Skills!L7/10)+Skills!O7 | G7: =Skills!G7*IF(Skills!H7>0,Skills!I7/Skills!H7,1) | H7: =1-(1-Skills!J7/100)^Skills!K7 | I7: 1 | J7: =Summary!$B$50*(F7/100) | K7: =J7*(1+Summary!$B$51/100)*(1+Inputs!$B$14/100)*(1+IF(Inputs!$B$4="pvp",0,(1-Summary!$B$55)*(Inputs!$B$19+Skills!P7+Summary!$B$59)+Summary!$B$55*(Inputs!$B$20+Skills!Q7+Summary!$B$59))/100)*(1+Inputs!$B$15/100)*(5000/(6000+Inputs!$B$7*(1-Inputs!$B$18/100)))*(1+(Inputs!$B$23+Summary!$B$65)/100)*(1+1.0*IF(C15=TRUE,F15,0)/100)*(1+(IF(Skills!A7="EIGHT_LEGS_EASTON",Inputs!$B$16,Inputs!$B$17))/100)*(Summary!$B$57*I7) | L7: =K7*(MIN(Inputs!$B$21,Inputs!$B$22)/100+Inputs!$B$22/100)/2 | M7: =L7*(1+(Inputs!$B$9+Summary!$B$64)/100) | N7: =L7*(1-MIN((Inputs!$B$8+Summary!$B$58),100)/100)+M7*(MIN((Inputs!$B$8+Summary!$B$58),100)/100) | O7: =IF(C7,H7*N7*IF(AND(Inputs!$B$4<>"pvp",Inputs!$B$35>0),((Skills!G7*((R7-1)*IF(Skills!H7>0,Skills!I7/Skills!H7,1)+IF(Skills!H7>0,MIN(Skills!I7,MAX(0,Inputs!$B$35-((R7-1)*IF(Inputs!$B$4="pvp",15,MAX(0.1,Skills!D7-IF(Skills!E7=TRUE,Inputs!$B$31,0))))))/Skills!H7,1)))/Inputs!$B$35),G7*Q7)*IF(Inputs!$B$4="pvp",1,(1-Summary!$B$55)*(1)+Summary!$B$55*(MIN(Skills!R7,Inputs!$B$37))),0) | P7: =IF(Summary!$B$3=0,0,O7/Summary!$B$3) | Q7: =IFERROR(1/IF(Inputs!$B$4="pvp",15,MAX(0.1,Skills!D7-IF(Skills!E7=TRUE,Inputs!$B$31,0))),0) | R7: =IF(AND(Inputs!$B$4<>"pvp",Inputs!$B$35>0),(INT(Inputs!$B$35/IF(Inputs!$B$4="pvp",15,MAX(0.1,Skills!D7-IF(Skills!E7=TRUE,Inputs!$B$31,0))))+1),0) | S7: =IFERROR(O7/N7,0)
A8: =Skills!A8 | B8: =Skills!B8 | C8: =Inputs!$B$3>=100 | D8: =IF(Skills!C8=1,60+Inputs!$B$24+Inputs!$B$28,IF(Skills!C8=2,90+Inputs!$B$25+Inputs!$B$28,IF(Skills!C8=3,120+Inputs!$B$26+Inputs!$B$28,MAX(0,(Inputs!$B$3-100)*3)+Inputs!$B$27+Inputs!$B$28))) | E8: =INDEX(FactorTable!$B$2:$Y$301, MATCH(ROUND(MIN(300,MAX(1,D8)),0), FactorTable!$A$2:$A$301,0), Skills!M8+1) | F8: =IF(Skills!N8=TRUE,(Skills!L8/10)*(E8/1000),Skills!L8/10)+Skills!O8 | G8: =Skills!G8*IF(Skills!H8>0,Skills!I8/Skills!H8,1) | H8: =1-(1-Skills!J8/100)^Skills!K8 | I8: 1 | J8: =Summary!$B$50*(F8/100) | K8: =J8*(1+Summary!$B$51/100)*(1+Inputs!$B$14/100)*(1+IF(Inputs!$B$4="pvp",0,(1-Summary!$B$55)*(Inputs!$B$19+Skills!P8+Summary!$B$59)+Summary!$B$55*(Inputs!$B$20+Skills!Q8+Summary!$B$59))/100)*(1+Inputs!$B$15/100)*(5000/(6000+Inputs!$B$7*(1-Inputs!$B$18/100)))*(1+(Inputs!$B$23+Summary!$B$65)/100)*(1+(IF(Skills!A8="EIGHT_LEGS_EASTON",Inputs!$B$16,Inputs!$B$17))/100)*(Summary!$B$57*I8) | L8: =K8*(MIN(Inputs!$B$21,Inputs!$B$22)/100+Inputs!$B$22/100)/2 | M8: =L8*(1+(Inputs!$B$9+Summary!$B$64)/100) | N8: =L8*(1-MIN((Inputs!$B$8+Summary!$B$58),100)/100)+M8*(MIN((Inputs!$B$8+Summary!$B$58),100)/100) | O8: =IF(C8,H8*N8*IF(AND(Inputs!$B$4<>"pvp",Inputs!$B$35>0),((Skills!G8*((R8-1)*IF(Skills!H8>0,Skills!I8/Skills!H8,1)+IF(Skills!H8>0,MIN(Skills!I8,MAX(0,Inputs!$B$35-((R8-1)*IF(Inputs!$B$4="pvp",15,MAX(0.1,Skills!D8-IF(Skills!E8=TRUE,Inputs!$B$31,0))))))/Skills!H8,1)))/Inputs!$B$35),G8*Q8)*IF(Inputs!$B$4="pvp",1,(1-Summary!$B$55)*(1)+Summary!$B$55*(MIN(Skills!R8,Inputs!$B$37))),0) | P8: =IF(Summary!$B$3=0,0,O8/Summary!$B$3) | Q8: =IFERROR(1/IF(Inputs!$B$4="pvp",15,MAX(0.1,Skills!D8-IF(Skills!E8=TRUE,Inputs!$B$31,0))),0) | R8: =IF(AND(Inputs!$B$4<>"pvp",Inputs!$B$35>0),(INT(Inputs!$B$35/IF(Inputs!$B$4="pvp",15,MAX(0.1,Skills!D8-IF(Skills!E8=TRUE,Inputs!$B$31,0))))+1),0) | S8: =IFERROR(O8/N8,0)
A9: =Skills!A9 | B9: =Skills!B9 | C9: =Inputs!$B$3>=103 | D9: =IF(Skills!C9=1,60+Inputs!$B$24+Inputs!$B$28,IF(Skills!C9=2,90+Inputs!$B$25+Inputs!$B$28,IF(Skills!C9=3,120+Inputs!$B$26+Inputs!$B$28,MAX(0,(Inputs!$B$3-100)*3)+Inputs!$B$27+Inputs!$B$28))) | E9: =INDEX(FactorTable!$B$2:$Y$301, MATCH(ROUND(MIN(300,MAX(1,D9)),0), FactorTable!$A$2:$A$301,0), Skills!M9+1) | F9: =IF(Skills!N9=TRUE,(Skills!L9/10)*(E9/1000),Skills!L9/10)+Skills!O9 | G9: =Skills!G9*IF(Skills!H9>0,Skills!I9/Skills!H9,1) | H9: =1-(1-Skills!J9/100)^Skills!K9 | I9: 1 | J9: =Summary!$B$50*(F9/100) | K9: =J9*(1+Summary!$B$51/100)*(1+Inputs!$B$14/100)*(1+IF(Inputs!$B$4="pvp",0,(1-Summary!$B$55)*(Inputs!$B$19+Skills!P9+Summary!$B$59)+Summary!$B$55*(Inputs!$B$20+Skills!Q9+Summary!$B$59))/100)*(1+Inputs!$B$15/100)*(5000/(6000+Inputs!$B$7*(1-Inputs!$B$18/100)))*(1+(Inputs!$B$23+Summary!$B$65)/100)*(1+(IF(Skills!A9="EIGHT_LEGS_EASTON",Inputs!$B$16,Inputs!$B$17))/100)*(Summary!$B$57*I9) | L9: =K9*(MIN(Inputs!$B$21,Inputs!$B$22)/100+Inputs!$B$22/100)/2 | M9: =L9*(1+(Inputs!$B$9+Summary!$B$64)/100) | N9: =L9*(1-MIN((Inputs!$B$8+Summary!$B$58),100)/100)+M9*(MIN((Inputs!$B$8+Summary!$B$58),100)/100) | O9: =IF(C9,H9*N9*IF(AND(Inputs!$B$4<>"pvp",Inputs!$B$35>0),((Skills!G9*((R9-1)*IF(Skills!H9>0,Skills!I9/Skills!H9,1)+IF(Skills!H9>0,MIN(Skills!I9,MAX(0,Inputs!$B$35-((R9-1)*IF(Inputs!$B$4="pvp",15,MAX(0.1,Skills!D9-IF(Skills!E9=TRUE,Inputs!$B$31,0))))))/Skills!H9,1)))/Inputs!$B$35),G9*Q9)*IF(Inputs!$B$4="pvp",1,(1-Summary!$B$55)*(1)+Summary!$B$55*(MIN(Skills!R9,Inputs!$B$37))),0) | P9: =IF(Summary!$B$3=0,0,O9/Summary!$B$3) | Q9: =IFERROR(1/IF(Inputs!$B$4="pvp",15,MAX(0.1,Skills!D9-IF(Skills!E9=TRUE,Inputs!$B$31,0))),0) | R9: =IF(AND(Inputs!$B$4<>"pvp",Inputs!$B$35>0),(INT(Inputs!$B$35/IF(Inputs!$B$4="pvp",15,MAX(0.1,Skills!D9-IF(Skills!E9=TRUE,Inputs!$B$31,0))))+1),0) | S9: =IFERROR(O9/N9,0)
A10: =Skills!A10 | B10: =Skills!B10 | C10: =Inputs!$B$3>=113 | D10: =IF(Skills!C10=1,60+Inputs!$B$24+Inputs!$B$28,IF(Skills!C10=2,90+Inputs!$B$25+Inputs!$B$28,IF(Skills!C10=3,120+Inputs!$B$26+Inputs!$B$28,MAX(0,(Inputs!$B$3-100)*3)+Inputs!$B$27+Inputs!$B$28))) | E10: =INDEX(FactorTable!$B$2:$Y$301, MATCH(ROUND(MIN(300,MAX(1,D10)),0), FactorTable!$A$2:$A$301,0), Skills!M10+1) | F10: =IF(Skills!N10=TRUE,(Skills!L10/10)*(E10/1000),Skills!L10/10)+Skills!O10 | G10: =Skills!G10*IF(Skills!H10>0,Skills!I10/Skills!H10,1) | H10: =1-(1-Skills!J10/100)^Skills!K10 | I10: 1 | J10: =Summary!$B$50*(F10/100) | K10: =J10*(1+Summary!$B$51/100)*(1+Inputs!$B$14/100)*(1+IF(Inputs!$B$4="pvp",0,(1-Summary!$B$55)*(Inputs!$B$19+Skills!P10+Summary!$B$59)+Summary!$B$55*(Inputs!$B$20+Skills!Q10+Summary!$B$59))/100)*(1+Inputs!$B$15/100)*(5000/(6000+Inputs!$B$7*(1-Inputs!$B$18/100)))*(1+(Inputs!$B$23+Summary!$B$65)/100)*(1+(IF(Skills!A10="EIGHT_LEGS_EASTON",Inputs!$B$16,Inputs!$B$17))/100)*(Summary!$B$57*I10) | L10: =K10*(MIN(Inputs!$B$21,Inputs!$B$22)/100+Inputs!$B$22/100)/2 | M10: =L10*(1+(Inputs!$B$9+Summary!$B$64)/100) | N10: =L10*(1-MIN((Inputs!$B$8+Summary!$B$58),100)/100)+M10*(MIN((Inputs!$B$8+Summary!$B$58),100)/100) | O10: =IF(C10,H10*N10*IF(AND(Inputs!$B$4<>"pvp",Inputs!$B$35>0),((Skills!G10*((R10-1)*IF(Skills!H10>0,Skills!I10/Skills!H10,1)+IF(Skills!H10>0,MIN(Skills!I10,MAX(0,Inputs!$B$35-((R10-1)*IF(Inputs!$B$4="pvp",15,MAX(0.1,Skills!D10-IF(Skills!E10=TRUE,Inputs!$B$31,0))))))/Skills!H10,1)))/Inputs!$B$35),G10*Q10)*IF(Inputs!$B$4="pvp",1,(1-Summary!$B$55)*(1)+Summary!$B$55*(MIN(Skills!R10,Inputs!$B$37))),0) | P10: =IF(Summary!$B$3=0,0,O10/Summary!$B$3) | Q10: =IFERROR(1/IF(Inputs!$B$4="pvp",15,MAX(0.1,Skills!D10-IF(Skills!E10=TRUE,Inputs!$B$31,0))),0) | R10: =IF(AND(Inputs!$B$4<>"pvp",Inputs!$B$35>0),(INT(Inputs!$B$35/IF(Inputs!$B$4="pvp",15,MAX(0.1,Skills!D10-IF(Skills!E10=TRUE,Inputs!$B$31,0))))+1),0) | S10: =IFERROR(O10/N10,0)
A11: =Skills!A11 | B11: =Skills!B11 | C11: =Inputs!$B$3>=107 | D11: =IF(Skills!C11=1,60+Inputs!$B$24+Inputs!$B$28,IF(Skills!C11=2,90+Inputs!$B$25+Inputs!$B$28,IF(Skills!C11=3,120+Inputs!$B$26+Inputs!$B$28,MAX(0,(Inputs!$B$3-100)*3)+Inputs!$B$27+Inputs!$B$28))) | E11: =INDEX(FactorTable!$B$2:$Y$301, MATCH(ROUND(MIN(300,MAX(1,D11)),0), FactorTable!$A$2:$A$301,0), Skills!M11+1) | F11: =IF(Skills!N11=TRUE,(Skills!L11/10)*(E11/1000),Skills!L11/10)+Skills!O11 | G11: =Skills!G11*IF(Skills!H11>0,Skills!I11/Skills!H11,1) | H11: =1-(1-Skills!J11/100)^Skills!K11 | I11: 1 | J11: =Summary!$B$50*(F11/100) | K11: =J11*(1+Summary!$B$51/100)*(1+Inputs!$B$14/100)*(1+IF(Inputs!$B$4="pvp",0,(1-Summary!$B$55)*(Inputs!$B$19+Skills!P11+Summary!$B$59)+Summary!$B$55*(Inputs!$B$20+Skills!Q11+Summary!$B$59))/100)*(1+Inputs!$B$15/100)*(5000/(6000+Inputs!$B$7*(1-Inputs!$B$18/100)))*(1+(Inputs!$B$23+Summary!$B$65)/100)*(1+(IF(Skills!A11="EIGHT_LEGS_EASTON",Inputs!$B$16,Inputs!$B$17))/100)*(Summary!$B$57*I11) | L11: =K11*(MIN(Inputs!$B$21,Inputs!$B$22)/100+Inputs!$B$22/100)/2 | M11: =L11*(1+(Inputs!$B$9+Summary!$B$64)/100) | N11: =L11*(1-MIN((Inputs!$B$8+Summary!$B$58),100)/100)+M11*(MIN((Inputs!$B$8+Summary!$B$58),100)/100) | O11: =IF(C11,H11*N11*IF(AND(Inputs!$B$4<>"pvp",Inputs!$B$35>0),((Skills!G11*((R11-1)*IF(Skills!H11>0,Skills!I11/Skills!H11,1)+IF(Skills!H11>0,MIN(Skills!I11,MAX(0,Inputs!$B$35-((R11-1)*IF(Inputs!$B$4="pvp",15,MAX(0.1,Skills!D11-IF(Skills!E11=TRUE,Inputs!$B$31,0))))))/Skills!H11,1)))/Inputs!$B$35),G11*Q11)*IF(Inputs!$B$4="pvp",1,(1-Summary!$B$55)*(1)+Summary!$B$55*(MIN(Skills!R11,Inputs!$B$37))),0) | P11: =IF(Summary!$B$3=0,0,O11/Summary!$B$3) | Q11: =IFERROR(1/IF(Inputs!$B$4="pvp",15,MAX(0.1,Skills!D11-IF(Skills!E11=TRUE,Inputs!$B$31,0))),0) | R11: =IF(AND(Inputs!$B$4<>"pvp",Inputs!$B$35>0),(INT(Inputs!$B$35/IF(Inputs!$B$4="pvp",15,MAX(0.1,Skills!D11-IF(Skills!E11=TRUE,Inputs!$B$31,0))))+1),0) | S11: =IFERROR(O11/N11,0)
A12: =Skills!A12 | B12: =Skills!B12 | C12: =Inputs!$B$3>=110 | D12: =IF(Skills!C12=1,60+Inputs!$B$24+Inputs!$B$28,IF(Skills!C12=2,90+Inputs!$B$25+Inputs!$B$28,IF(Skills!C12=3,120+Inputs!$B$26+Inputs!$B$28,MAX(0,(Inputs!$B$3-100)*3)+Inputs!$B$27+Inputs!$B$28))) | E12: =INDEX(FactorTable!$B$2:$Y$301, MATCH(ROUND(MIN(300,MAX(1,D12)),0), FactorTable!$A$2:$A$301,0), Skills!M12+1) | F12: =IF(Skills!N12=TRUE,(Skills!L12/10)*(E12/1000),Skills!L12/10)+Skills!O12 | G12: =Skills!G12*IF(Skills!H12>0,Skills!I12/Skills!H12,1) | H12: =1-(1-Skills!J12/100)^Skills!K12 | I12: 1 | J12: =Summary!$B$50*(F12/100) | K12: =J12*(1+Summary!$B$51/100)*(1+Inputs!$B$14/100)*(1+IF(Inputs!$B$4="pvp",0,(1-Summary!$B$55)*(Inputs!$B$19+Skills!P12+Summary!$B$59)+Summary!$B$55*(Inputs!$B$20+Skills!Q12+Summary!$B$59))/100)*(1+Inputs!$B$15/100)*(5000/(6000+Inputs!$B$7*(1-Inputs!$B$18/100)))*(1+(Inputs!$B$23+Summary!$B$65)/100)*(1+(IF(Skills!A12="EIGHT_LEGS_EASTON",Inputs!$B$16,Inputs!$B$17))/100)*(Summary!$B$57*I12) | L12: =K12*(MIN(Inputs!$B$21,Inputs!$B$22)/100+Inputs!$B$22/100)/2 | M12: =L12*(1+(Inputs!$B$9+Summary!$B$64)/100) | N12: =L12*(1-MIN((Inputs!$B$8+Summary!$B$58),100)/100)+M12*(MIN((Inputs!$B$8+Summary!$B$58),100)/100) | O12: =IF(C12,H12*N12*IF(AND(Inputs!$B$4<>"pvp",Inputs!$B$35>0),((Skills!G12*((R12-1)*IF(Skills!H12>0,Skills!I12/Skills!H12,1)+IF(Skills!H12>0,MIN(Skills!I12,MAX(0,Inputs!$B$35-((R12-1)*IF(Inputs!$B$4="pvp",15,MAX(0.1,Skills!D12-IF(Skills!E12=TRUE,Inputs!$B$31,0))))))/Skills!H12,1)))/Inputs!$B$35),G12*Q12)*IF(Inputs!$B$4="pvp",1,(1-Summary!$B$55)*(1)+Summary!$B$55*(MIN(Skills!R12,Inputs!$B$37))),0) | P12: =IF(Summary!$B$3=0,0,O12/Summary!$B$3) | Q12: =IFERROR(1/IF(Inputs!$B$4="pvp",15,MAX(0.1,Skills!D12-IF(Skills!E12=TRUE,Inputs!$B$31,0))),0) | R12: =IF(AND(Inputs!$B$4<>"pvp",Inputs!$B$35>0),(INT(Inputs!$B$35/IF(Inputs!$B$4="pvp",15,MAX(0.1,Skills!D12-IF(Skills!E12=TRUE,Inputs!$B$31,0))))+1),0) | S12: =IFERROR(O12/N12,0)
A13: =Skills!A13 | B13: =Skills!B13 | C13: =Inputs!$B$3>=110 | D13: =IF(Skills!C13=1,60+Inputs!$B$24+Inputs!$B$28,IF(Skills!C13=2,90+Inputs!$B$25+Inputs!$B$28,IF(Skills!C13=3,120+Inputs!$B$26+Inputs!$B$28,MAX(0,(Inputs!$B$3-100)*3)+Inputs!$B$27+Inputs!$B$28))) | E13: =INDEX(FactorTable!$B$2:$Y$301, MATCH(ROUND(MIN(300,MAX(1,D13)),0), FactorTable!$A$2:$A$301,0), Skills!M13+1) | F13: =IF(Skills!N13=TRUE,(Skills!L13/10)*(E13/1000),Skills!L13/10)+Skills!O13 | G13: =Skills!G13*IF(Skills!H13>0,Skills!I13/Skills!H13,1) | H13: =1-(1-Skills!J13/100)^Skills!K13 | I13: 1 | J13: =Summary!$B$50*(F13/100) | K13: =J13*(1+Summary!$B$51/100)*(1+Inputs!$B$14/100)*(1+IF(Inputs!$B$4="pvp",0,(1-Summary!$B$55)*(Inputs!$B$19+Skills!P13+Summary!$B$59)+Summary!$B$55*(Inputs!$B$20+Skills!Q13+Summary!$B$59))/100)*(1+Inputs!$B$15/100)*(5000/(6000+Inputs!$B$7*(1-Inputs!$B$18/100)))*(1+(Inputs!$B$23+Summary!$B$65)/100)*(1+(IF(Skills!A13="EIGHT_LEGS_EASTON",Inputs!$B$16,Inputs!$B$17))/100)*(Summary!$B$57*I13) | L13: =K13*(MIN(Inputs!$B$21,Inputs!$B$22)/100+Inputs!$B$22/100)/2 | M13: =L13*(1+(Inputs!$B$9+Summary!$B$64)/100) | N13: =L13*(1-MIN((Inputs!$B$8+Summary!$B$58),100)/100)+M13*(MIN((Inputs!$B$8+Summary!$B$58),100)/100) | O13: =IF(C13,H13*N13*IF(AND(Inputs!$B$4<>"pvp",Inputs!$B$35>0),((Skills!G13*((R13-1)*IF(Skills!H13>0,Skills!I13/Skills!H13,1)+IF(Skills!H13>0,MIN(Skills!I13,MAX(0,Inputs!$B$35-((R13-1)*IF(Inputs!$B$4="pvp",15,MAX(0.1,Skills!D13-IF(Skills!E13=TRUE,Inputs!$B$31,0))))))/Skills!H13,1)))/Inputs!$B$35),G13*Q13)*IF(Inputs!$B$4="pvp",1,(1-Summary!$B$55)*(1)+Summary!$B$55*(MIN(Skills!R13,Inputs!$B$37))),0) | P13: =IF(Summary!$B$3=0,0,O13/Summary!$B$3) | Q13: =IFERROR(1/IF(Inputs!$B$4="pvp",15,MAX(0.1,Skills!D13-IF(Skills!E13=TRUE,Inputs!$B$31,0))),0) | R13: =IF(AND(Inputs!$B$4<>"pvp",Inputs!$B$35>0),(INT(Inputs!$B$35/IF(Inputs!$B$4="pvp",15,MAX(0.1,Skills!D13-IF(Skills!E13=TRUE,Inputs!$B$31,0))))+1),0) | S13: =IFERROR(O13/N13,0)
A14: =Skills!A14 | B14: =Skills!B14 | C14: =Inputs!$B$3>=125 | D14: =IF(Skills!C14=1,60+Inputs!$B$24+Inputs!$B$28,IF(Skills!C14=2,90+Inputs!$B$25+Inputs!$B$28,IF(Skills!C14=3,120+Inputs!$B$26+Inputs!$B$28,MAX(0,(Inputs!$B$3-100)*3)+Inputs!$B$27+Inputs!$B$28))) | E14: =INDEX(FactorTable!$B$2:$Y$301, MATCH(ROUND(MIN(300,MAX(1,D14)),0), FactorTable!$A$2:$A$301,0), Skills!M14+1) | F14: =IF(Skills!N14=TRUE,(Skills!L14/10)*(E14/1000),Skills!L14/10)+Skills!O14 | G14: =Skills!G14*IF(Skills!H14>0,Skills!I14/Skills!H14,1) | H14: =1-(1-Skills!J14/100)^Skills!K14 | I14: 1 | J14: =Summary!$B$50*(F14/100) | K14: =J14*(1+Summary!$B$51/100)*(1+Inputs!$B$14/100)*(1+IF(Inputs!$B$4="pvp",0,(1-Summary!$B$55)*(Inputs!$B$19+Skills!P14+Summary!$B$59)+Summary!$B$55*(Inputs!$B$20+Skills!Q14+Summary!$B$59))/100)*(1+Inputs!$B$15/100)*(5000/(6000+Inputs!$B$7*(1-Inputs!$B$18/100)))*(1+(Inputs!$B$23+Summary!$B$65)/100)*(1+(IF(Skills!A14="EIGHT_LEGS_EASTON",Inputs!$B$16,Inputs!$B$17))/100)*(Summary!$B$57*I14) | L14: =K14*(MIN(Inputs!$B$21,Inputs!$B$22)/100+Inputs!$B$22/100)/2 | M14: =L14*(1+(Inputs!$B$9+Summary!$B$64)/100) | N14: =L14*(1-MIN((Inputs!$B$8+Summary!$B$58),100)/100)+M14*(MIN((Inputs!$B$8+Summary!$B$58),100)/100) | O14: =IF(C14,H14*N14*(Summary!$B$63+IF(AND(Inputs!$B$4<>"pvp",Inputs!$B$35>0),((Skills!G8*((R8-1)*IF(Skills!H8>0,Skills!I8/Skills!H8,1)+IF(Skills!H8>0,MIN(Skills!I8,MAX(0,Inputs!$B$35-((R8-1)*IF(Inputs!$B$4="pvp",15,MAX(0.1,Skills!D8-IF(Skills!E8=TRUE,Inputs!$B$31,0))))))/Skills!H8,1)))/Inputs!$B$35),G8*Q8)+IF(AND(Inputs!$B$4<>"pvp",Inputs!$B$35>0),((Skills!G11*((R11-1)*IF(Skills!H11>0,Skills!I11/Skills!H11,1)+IF(Skills!H11>0,MIN(Skills!I11,MAX(0,Inputs!$B$35-((R11-1)*IF(Inputs!$B$4="pvp",15,MAX(0.1,Skills!D11-IF(Skills!E11=TRUE,Inputs!$B$31,0))))))/Skills!H11,1)))/Inputs!$B$35),G11*Q11))*IF(Inputs!$B$4="pvp",1,(1-Summary!$B$55)*(1)+Summary!$B$55*(MIN(Skills!R14,Inputs!$B$37))),0) | P14: =IF(Summary!$B$3=0,0,O14/Summary!$B$3) | Q14: 0 | R14: 0 | S14: =IFERROR(O14/N14,0)
A15: =Skills!A15 | B15: =Skills!B15 | C15: =Inputs!$B$3>=100 | D15: =IF(Skills!C15=1,60+Inputs!$B$24+Inputs!$B$28,IF(Skills!C15=2,90+Inputs!$B$25+Inputs!$B$28,IF(Skills!C15=3,120+Inputs!$B$26+Inputs!$B$28,MAX(0,(Inputs!$B$3-100)*3)+Inputs!$B$27+Inputs!$B$28))) | E15: =INDEX(FactorTable!$B$2:$Y$301, MATCH(ROUND(MIN(300,MAX(1,D15)),0), FactorTable!$A$2:$A$301,0), Skills!M15+1) | F15: =IF(Skills!N15=TRUE,(Skills!L15/10)*(E15/1000),Skills!L15/10)+Skills!O15 | I15: 1
A16: =Skills!A16 | B16: =Skills!B16 | C16: =Inputs!$B$3>=120 | D16: =IF(Skills!C16=1,60+Inputs!$B$24+Inputs!$B$28,IF(Skills!C16=2,90+Inputs!$B$25+Inputs!$B$28,IF(Skills!C16=3,120+Inputs!$B$26+Inputs!$B$28,MAX(0,(Inputs!$B$3-100)*3)+Inputs!$B$27+Inputs!$B$28))) | E16: =INDEX(FactorTable!$B$2:$Y$301, MATCH(ROUND(MIN(300,MAX(1,D16)),0), FactorTable!$A$2:$A$301,0), Skills!M16+1) | F16: =IF(Skills!N16=TRUE,(Skills!L16/10)*(E16/1000),Skills!L16/10)+Skills!O16 | I16: 1
A17: =Skills!A17 | B17: =Skills!B17 | C17: =Inputs!$B$3>=66 | D17: =IF(Skills!C17=1,60+Inputs!$B$24+Inputs!$B$28,IF(Skills!C17=2,90+Inputs!$B$25+Inputs!$B$28,IF(Skills!C17=3,120+Inputs!$B$26+Inputs!$B$28,MAX(0,(Inputs!$B$3-100)*3)+Inputs!$B$27+Inputs!$B$28))) | E17: =INDEX(FactorTable!$B$2:$Y$301, MATCH(ROUND(MIN(300,MAX(1,D17)),0), FactorTable!$A$2:$A$301,0), Skills!M17+1) | F17: =IF(Skills!N17=TRUE,(Skills!L17/10)*(E17/1000),Skills!L17/10)+Skills!O17 | G17: =Skills!G17*IF(Skills!H17>0,Skills!I17/Skills!H17,1) | H17: =1-(1-Skills!J17/100)^Skills!K17 | I17: 1 | O17: 0 | P17: =IF(Summary!$B$3=0,0,O17/Summary!$B$3) | Q17: 0 | R17: 0 | S17: =IFERROR(O17/N17,0)
A18: =Skills!A18 | B18: =Skills!B18 | C18: =Inputs!$B$3>=115 | D18: =IF(Skills!C18=1,60+Inputs!$B$24+Inputs!$B$28,IF(Skills!C18=2,90+Inputs!$B$25+Inputs!$B$28,IF(Skills!C18=3,120+Inputs!$B$26+Inputs!$B$28,MAX(0,(Inputs!$B$3-100)*3)+Inputs!$B$27+Inputs!$B$28))) | E18: =INDEX(FactorTable!$B$2:$Y$301, MATCH(ROUND(MIN(300,MAX(1,D18)),0), FactorTable!$A$2:$A$301,0), Skills!M18+1) | F18: =IF(Skills!N18=TRUE,(Skills!L18/10)*(E18/1000),Skills!L18/10)+Skills!O18 | G18: =Skills!G18*IF(Skills!H18>0,Skills!I18/Skills!H18,1) | H18: =1-(1-Skills!J18/100)^Skills!K18 | I18: 1 | O18: 0 | P18: =IF(Summary!$B$3=0,0,O18/Summary!$B$3) | Q18: 0 | R18: 0 | S18: =IFERROR(O18/N18,0)
A19: =Skills!A19 | B19: =Skills!B19 | C19: =Inputs!$B$3>=15 | D19: =IF(Skills!C19=1,60+Inputs!$B$24+Inputs!$B$28,IF(Skills!C19=2,90+Inputs!$B$25+Inputs!$B$28,IF(Skills!C19=3,120+Inputs!$B$26+Inputs!$B$28,MAX(0,(Inputs!$B$3-100)*3)+Inputs!$B$27+Inputs!$B$28))) | E19: =INDEX(FactorTable!$B$2:$Y$301, MATCH(ROUND(MIN(300,MAX(1,D19)),0), FactorTable!$A$2:$A$301,0), Skills!M19+1) | F19: =IF(Skills!N19=TRUE,(Skills!L19/10)*(E19/1000),Skills!L19/10)+Skills!O19 | G19: =Skills!G19*IF(Skills!H19>0,Skills!I19/Skills!H19,1) | H19: =1-(1-Skills!J19/100)^Skills!K19 | I19: 1 | O19: 0 | P19: =IF(Summary!$B$3=0,0,O19/Summary!$B$3) | Q19: 0 | R19: 0 | S19: =IFERROR(O19/N19,0)
A20: =Skills!A20 | B20: =Skills!B20 | C20: =Inputs!$B$3>=10 | D20: =IF(Skills!C20=1,60+Inputs!$B$24+Inputs!$B$28,IF(Skills!C20=2,90+Inputs!$B$25+Inputs!$B$28,IF(Skills!C20=3,120+Inputs!$B$26+Inputs!$B$28,MAX(0,(Inputs!$B$3-100)*3)+Inputs!$B$27+Inputs!$B$28))) | E20: =INDEX(FactorTable!$B$2:$Y$301, MATCH(ROUND(MIN(300,MAX(1,D20)),0), FactorTable!$A$2:$A$301,0), Skills!M20+1) | F20: =IF(Skills!N20=TRUE,(Skills!L20/10)*(E20/1000),Skills!L20/10)+Skills!O20 | G20: =Skills!G20*IF(Skills!H20>0,Skills!I20/Skills!H20,1) | H20: =1-(1-Skills!J20/100)^Skills!K20 | I20: 1 | O20: 0 | P20: =IF(Summary!$B$3=0,0,O20/Summary!$B$3) | Q20: 0 | R20: 0 | S20: =IFERROR(O20/N20,0)
A21: =Skills!A21 | B21: =Skills!B21 | C21: =Inputs!$B$3>=33 | D21: =IF(Skills!C21=1,60+Inputs!$B$24+Inputs!$B$28,IF(Skills!C21=2,90+Inputs!$B$25+Inputs!$B$28,IF(Skills!C21=3,120+Inputs!$B$26+Inputs!$B$28,MAX(0,(Inputs!$B$3-100)*3)+Inputs!$B$27+Inputs!$B$28))) | E21: =INDEX(FactorTable!$B$2:$Y$301, MATCH(ROUND(MIN(300,MAX(1,D21)),0), FactorTable!$A$2:$A$301,0), Skills!M21+1) | F21: =IF(Skills!N21=TRUE,(Skills!L21/10)*(E21/1000),Skills!L21/10)+Skills!O21 | G21: =Skills!G21*IF(Skills!H21>0,Skills!I21/Skills!H21,1) | H21: =1-(1-Skills!J21/100)^Skills!K21 | I21: 1 | O21: 0 | P21: =IF(Summary!$B$3=0,0,O21/Summary!$B$3) | Q21: 0 | R21: 0 | S21: =IFERROR(O21/N21,0)
A22: =Skills!A22 | B22: =Skills!B22 | C22: =Inputs!$B$3>=43 | D22: =IF(Skills!C22=1,60+Inputs!$B$24+Inputs!$B$28,IF(Skills!C22=2,90+Inputs!$B$25+Inputs!$B$28,IF(Skills!C22=3,120+Inputs!$B$26+Inputs!$B$28,MAX(0,(Inputs!$B$3-100)*3)+Inputs!$B$27+Inputs!$B$28))) | E22: =INDEX(FactorTable!$B$2:$Y$301, MATCH(ROUND(MIN(300,MAX(1,D22)),0), FactorTable!$A$2:$A$301,0), Skills!M22+1) | F22: =IF(Skills!N22=TRUE,(Skills!L22/10)*(E22/1000),Skills!L22/10)+Skills!O22 | G22: =Skills!G22*IF(Skills!H22>0,Skills!I22/Skills!H22,1) | H22: =1-(1-Skills!J22/100)^Skills!K22 | I22: 1 | O22: 0 | P22: =IF(Summary!$B$3=0,0,O22/Summary!$B$3) | Q22: 0 | R22: 0 | S22: =IFERROR(O22/N22,0)
A23: =Skills!A23 | B23: =Skills!B23 | C23: =Inputs!$B$3>=38 | D23: =IF(Skills!C23=1,60+Inputs!$B$24+Inputs!$B$28,IF(Skills!C23=2,90+Inputs!$B$25+Inputs!$B$28,IF(Skills!C23=3,120+Inputs!$B$26+Inputs!$B$28,MAX(0,(Inputs!$B$3-100)*3)+Inputs!$B$27+Inputs!$B$28))) | E23: =INDEX(FactorTable!$B$2:$Y$301, MATCH(ROUND(MIN(300,MAX(1,D23)),0), FactorTable!$A$2:$A$301,0), Skills!M23+1) | F23: =IF(Skills!N23=TRUE,(Skills!L23/10)*(E23/1000),Skills!L23/10)+Skills!O23 | G23: =Skills!G23*IF(Skills!H23>0,Skills!I23/Skills!H23,1) | H23: =1-(1-Skills!J23/100)^Skills!K23 | I23: 1 | O23: 0 | P23: =IF(Summary!$B$3=0,0,O23/Summary!$B$3) | Q23: 0 | R23: 0 | S23: =IFERROR(O23/N23,0)
A24: =Skills!A24 | B24: =Skills!B24 | C24: =Inputs!$B$3>=40 | D24: =IF(Skills!C24=1,60+Inputs!$B$24+Inputs!$B$28,IF(Skills!C24=2,90+Inputs!$B$25+Inputs!$B$28,IF(Skills!C24=3,120+Inputs!$B$26+Inputs!$B$28,MAX(0,(Inputs!$B$3-100)*3)+Inputs!$B$27+Inputs!$B$28))) | E24: =INDEX(FactorTable!$B$2:$Y$301, MATCH(ROUND(MIN(300,MAX(1,D24)),0), FactorTable!$A$2:$A$301,0), Skills!M24+1) | F24: =IF(Skills!N24=TRUE,(Skills!L24/10)*(E24/1000),Skills!L24/10)+Skills!O24 | G24: =Skills!G24*IF(Skills!H24>0,Skills!I24/Skills!H24,1) | H24: =1-(1-Skills!J24/100)^Skills!K24 | I24: 1 | O24: 0 | P24: =IF(Summary!$B$3=0,0,O24/Summary!$B$3) | Q24: 0 | R24: 0 | S24: =IFERROR(O24/N24,0)
