Workbook

Sheet README
A1: Dark Knight — DPS Calculator: How to Use This Workbook
A3: How to use this workbook
A4: Only edit the yellow-highlighted cells on the Inputs sheet — every other sheet is computed from those values and will be overwritten if you rebuild the workbook.
A5: Summary shows Total DPS, a Per-Skill DPS Breakdown (damage-dealing skills only — buffs/passives that never deal their own damage are omitted), and a Marginal DPS & Stat Value table showing the DPS gained per +1 of each stat.
A6: Sensitivity has the full detail behind that marginal-value table — one self-contained block per stat, showing exactly how bumping that stat by +1 changes every downstream number.
A7: CubeData/PotentialCubes model your current gear's Potential Cube lines and drive cube-reroll expected-value decisions. For the full standalone Potential Cube EV calculator (exact optimal-stopping math, works from this workbook alone), see tools/potential_cubes_ev.py in the project repo.
A9: Design decisions & assumptions
A10: Weapon Acceleration, Weapon Mastery, Barricade Mastery, Power Stance's own Final Damage component, and Final Pact's own Final Damage component are always-on passives assumed to already be reflected in your own Inputs stat entries — only their Sensitivity marginal delta is modeled live, matching this project's established convention. Iron Wall (STR from Defense) and Warrior-Mastery-equivalent flat-stat passives have zero DPS-relevant mechanic and get no row at all (no Defense-tracking mechanic exists anywhere in this project). Dark Knight has NO Physical Training or Endure skill at all (confirmed absent from its own skill list, despite both being present on Hero's).
A11: Evil Eye and Dark Resonance both drive the Global Monster Damage-Taken Bonus% bucket (the mechanism Hero's own Scaring Sword pioneered) — Evil Eye's own +15%->19.2% applies to all monster types (duty-cycle averaged, always-on while summoned, no proc-chance gate), Dark Resonance's patch-added +20% applies boss-only (monster_blend_expr-gated), both summed into the same bucket.
A12: Evil Eye Shock, Evil Eye of Dominant, Hex of the Evil Eye, and Revenge of the Evil Eye all nominally require Evil Eye to be summoned first — this precondition is NOT modeled as a live gate (they're treated as always-castable once individually unlocked), a documented simplification consistent with this project not tracking buff-precondition chains elsewhere either.
A13: Evil Eye of Dominant is modeled as a background DoT tied to Evil Eye's own cast cycle (Cooldown=30s/ActiveWindow=20s matching Evil Eye's own duration, ICD=1s) — same pattern as FP-Mage's own Poison Mist fog DoT tied to its parent skill.
A14: Lord of Darkness is split into two rows (Crit Rate half, Crit Damage half) since this schema's BuffTargetStat column only holds one stat per row — same reason Hero's own Enrage is split. Both modeled as ProcChance% x duty-cycle uptime (Scaring-Sword-style simplification), not an exact per-attack RNG state machine. Its own HP-recovery component is not modeled.
... A20: Not modeled (out of scope): all forms of crowd control (Evil Eye Shock stun), Accuracy, Evasion, Defense, Max HP/MP recovery, movement speed, and Companion Summoning Time.

Sheet Inputs
A1: Dark Knight — DPS Calculator Inputs
A3: Character Level | B3: 200
A4: Monster Type ("boss", "normal", "breakthrough", or "pvp") | B4: boss
A5: Flat ATTACK | B5: 10000
A6: ATTACK % | B6: 0
A7: Monster Defense (flat, post-x100/x10 scaling) | B7: 0
A8: CRIT_RATE % | B8: 0
A9: CRIT_DAMAGE % | B9: 0
A10: ATTACK_SPEED % (base, excludes Weapon Acceleration) | B10: 0
A11: Flat STR | B11: 0
A12: STR % | B12: 0
A13: DEX | B13: 0
A14: DAMAGE % | B14: 0
A15: DAMAGE_AMP % | B15: 0
A16: BASIC_ATTACK_DAMAGE % | B16: 0
... A28: Skill Level Bonus — All Skills | B28: 0
A30: Additional Bonuses
A31: Skill Cooldown Decrease (seconds, only skills/buffs the character actively casts) | B31: 0
A32: Basic Attack Target Increase (flat, adds to the 6-target normal-monster base) | B32: 1
A33: Buff Duration Increase % | B33: 0
A34: Companion Summoning Time Increase % (companions not modeled — always 0 DPS impact) | B34: 0
A35: Fixed Fight Duration (seconds, boss or normal — leave 0 for steady-state DPS; ignored for pvp) | B35: 0
A36: Chapter Breakthrough: Normal-Monster Weight % (only used when Monster Type = breakthrough) | B36: 60
A37: Max Enemies Actually In Range (normal monsters only; default 999 = uncapped) | B37: 999

Sheet FactorTable
A1: Level | B1: F0 | C1: F1 | D1: F2 | E1: F3 | F1: F4 | G1: F5 | H1: F6 | I1: F7 | J1: F8 | K1: F9 | L1: F10 | M1: F11 | N1: F12 | O1: F13 | P1: F14 | Q1: F15 | R1: F16 | S1: F17 | T1: F18 | U1: F19 | V1: F20 | W1: F21 | X1: F22 | Y1: F23
A2: 1 | B2: 0 | C2: 1000 | D2: 1000 | E2: 1000 | F2: 1000 | G2: 1000 | H2: 1000 | I2: 1000 | J2: 1000 | K2: 1000 | L2: 1000 | M2: 1000 | N2: 1000 | O2: 1000 | P2: 1000 | Q2: 1000 | R2: 1000 | S2: 1000 | T2: 1000 | U2: 1000 | V2: 1000 | W2: 1000 | X2: 1000 | Y2: 1000
A3: 2 | B3: 0 | C3: 1015 | D3: 1020 | E3: 1030 | F3: 1040 | G3: 1050 | H3: 1060 | I3: 1070 | J3: 1020 | K3: 1020 | L3: 1020 | M3: 1000 | N3: 1010 | O3: 1020 | P3: 1030 | Q3: 1040 | R3: 1050 | S3: 1060 | T3: 1070 | U3: 1080 | V3: 1010 | W3: 1008 | X3: 1006 | Y3: 1100
A4: 3 | B4: 0 | C4: 1031 | D4: 1041 | E4: 1061 | F4: 1082 | G4: 1103 | H4: 1124 | I4: 1145 | J4: 1030 | K4: 1041 | L4: 1030 | M4: 1000 | N4: 1015 | O4: 1030 | P4: 1045 | Q4: 1060 | R4: 1075 | S4: 1090 | T4: 1105 | U4: 1120 | V4: 1020 | W4: 1012 | X4: 1009 | Y4: 1150
A5: 4 | B5: 0 | C5: 1047 | D5: 1062 | E5: 1093 | F5: 1126 | G5: 1159 | H5: 1192 | I5: 1226 | J5: 1040 | K5: 1062 | L5: 1040 | M5: 1000 | N5: 1020 | O5: 1040 | P5: 1060 | Q5: 1080 | R5: 1100 | S5: 1120 | T5: 1140 | U5: 1160 | V5: 1030 | W5: 1016 | X5: 1012 | Y5: 1200
A6: 5 | B6: 0 | C6: 1063 | D6: 1084 | E6: 1126 | F6: 1172 | G6: 1217 | H6: 1264 | I6: 1312 | J6: 1050 | K6: 1084 | L6: 1050 | M6: 1000 | N6: 1025 | O6: 1050 | P6: 1075 | Q6: 1100 | R6: 1125 | S6: 1150 | T6: 1175 | U6: 1200 | V6: 1040 | W6: 1020 | X6: 1015 | Y6: 1250
A7: 6 | B7: 0 | C7: 1079 | D7: 1106 | E7: 1160 | F7: 1219 | G7: 1278 | H7: 1340 | I7: 1404 | J7: 1060 | K7: 1106 | L7: 1060 | M7: 1000 | N7: 1030 | O7: 1060 | P7: 1090 | Q7: 1120 | R7: 1150 | S7: 1180 | T7: 1210 | U7: 1240 | V7: 1050 | W7: 1024 | X7: 1018 | Y7: 1300
A8: 7 | B8: 0 | C8: 1096 | D8: 1129 | E8: 1195 | F8: 1268 | G8: 1342 | H8: 1421 | I8: 1503 | J8: 1070 | K8: 1129 | L8: 1070 | M8: 1000 | N8: 1035 | O8: 1070 | P8: 1105 | Q8: 1140 | R8: 1175 | S8: 1210 | T8: 1245 | U8: 1280 | V8: 1060 | W8: 1028 | X8: 1021 | Y8: 1350
A9: 8 | B9: 0 | C9: 1113 | D9: 1152 | E9: 1231 | F9: 1319 | G9: 1410 | H9: 1507 | I9: 1609 | J9: 1080 | K9: 1152 | L9: 1080 | M9: 1000 | N9: 1040 | O9: 1080 | P9: 1120 | Q9: 1160 | R9: 1200 | S9: 1240 | T9: 1280 | U9: 1320 | V9: 1070 | W9: 1032 | X9: 1024 | Y9: 1400
A10: 9 | B10: 0 | C10: 1130 | D10: 1176 | E10: 1268 | F10: 1372 | G10: 1481 | H10: 1598 | I10: 1722 | J10: 1090 | K10: 1176 | L10: 1090 | M10: 1000 | N10: 1045 | O10: 1090 | P10: 1135 | Q10: 1180 | R10: 1225 | S10: 1270 | T10: 1315 | U10: 1360 | V10: 1080 | W10: 1036 | X10: 1027 | Y10: 1450
A11: 10 | B11: 0 | C11: 1147 | D11: 1200 | E11: 1307 | F11: 1427 | G11: 1556 | H11: 1694 | I11: 1843 | J11: 1100 | K11: 1200 | L11: 1100 | M11: 1000 | N11: 1050 | O11: 1100 | P11: 1150 | Q11: 1200 | R11: 1250 | S11: 1300 | T11: 1350 | U11: 1400 | V11: 1090 | W11: 1040 | X11: 1030 | Y11: 1500
A12: 11 | B12: 0 | C12: 1165 | D12: 1224 | E12: 1347 | F12: 1485 | G12: 1634 | H12: 1796 | I12: 1973 | J12: 1110 | K12: 1224 | L12: 1110 | M12: 1000 | N12: 1055 | O12: 1110 | P12: 1165 | Q12: 1220 | R12: 1275 | S12: 1330 | T12: 1385 | U12: 1440 | V12: 1100 | W12: 1044 | X12: 1033 | Y12: 1550
A13: 12 | B13: 0 | C13: 1183 | D13: 1249 | E13: 1388 | F13: 1545 | G13: 1716 | H13: 1904 | I13: 2112 | J13: 1120 | K13: 1249 | L13: 1120 | M13: 1000 | N13: 1060 | O13: 1120 | P13: 1180 | Q13: 1240 | R13: 1300 | S13: 1360 | T13: 1420 | U13: 1480 | V13: 1110 | W13: 1048 | X13: 1036 | Y13: 1600
... A301: 300 | B301: 0 | C301: 88573 | D301: 381637 | E301: 6991522 | F301: 125363453 | G301: 2185120762 | H301: 37157073039 | I301: 614631863830 | J301: 2000 | K301: 53326 | L301: 2500 | M301: 1100 | N301: 2500 | O301: 4000 | P301: 5500 | Q301: 7000 | R301: 8500 | S301: 10000 | T301: 11500 | U301: 13000 | V301: 7558 | W301: 2200 | X301: 1900 | Y301: 8800

Sheet Skills
A1: Key | B1: Name | C1: JobStep | D1: Cooldown(s) | E1: CostsActionSlot | F1: ActionsPerCast | G1: HitsPerCast | H1: ICD(s) | I1: ActiveWindow(s) | J1: ProcChance% | K1: RollsPerCast | L1: BaseDamage(tenths%) | M1: FactorIndex | N1: ScalesWithLevel | O1: SkillMasteryBonus% | P1: MasteryBossDamage% | Q1: MasteryNormalDamage% | R1: NormalMonsterTargets | S1: BuffTargetStat | T1: BuffDuration(s) | U1: MapleHeroBase(tenths%) | V1: MapleHeroFactorIndex | W1: Note
A2: DARK_IMPALE | B2: Dark Impale | C2: 4 | E2: FALSE | F2: 1 | G2: =IF(Inputs!$B$3>=136,6,5) | H2: 0 | I2: 0 | J2: 100 | K2: 1 | L2: 2900 | M2: 21 | N2: TRUE | O2: =Calc!F3*IF(Calc!C3=TRUE,1,0)/100*(1+Calc!F4*IF(Calc!C4=TRUE,1,0)/100)*25+SUMPRODUCT((Inputs!$B$3>={102,106,116,120,128,132})*{10,1,1,1,1,1}) | P2: =SUMPRODUCT((Inputs!$B$3>={111,124})*{10,10}) | Q2: 0 | R2: =6+Inputs!$B$32 | T2: 0 | W2: 4th-job basic-attack effect (supersedes Slash Blast/Spear Sweep/La Mancha Spear, confirmed identical wiki wording — 290% damage to 6 target(s) in front 5 time(s) — to every other class's own 4th-job basic attack). factorIndex 21, baseDamage 2900 tenths%. HitsPerCast=5, bumping to 6 once Mastery Lv.136 'Dark Impale - Strike' unlocks (same level as Hero's own equivalent, confirmed independently from Dark Knight/Mastery). SkillMasteryBonus% is Final Attack + Advanced Final Attack's own combined steady-state contribution (same folding mechanism as Hero's own Raging Blow) PLUS the real Dark Impale - Damage mastery chain (102/106/116/120/128/132, cumulative +10/11/12/13/14/15% — summed as DELTAS, not the raw displayed values). MasteryBossDamage% is the real 2-tier Dark Impale - Boss Monster Damage chain (111/124, +10% each, +20% total).
A3: FINAL_ATTACK_HELPER | B3: Final Attack (helper) | C3: 2 | E3: FALSE | F3: 1 | G3: 1 | H3: 0 | I3: 0 | J3: 100 | K3: 1 | L3: 350 | M3: 21 | N3: TRUE | O3: 0 | P3: 0 | Q3: 0 | R3: 0 | T3: 0 | W3: Helper row only — feeds Dark Impale's own coefficient. 25% chance, 35%->49% additional damage (levels 1-100), factorIndex 21/baseDamage 350 tenths% — resolves to the IDENTICAL tuple Hero's/Bowmaster's own Final Attack helper uses, confirming this is genuinely the same cross-tree shared skill. Unlike Hero, Dark Knight's own Mastery table has NO 'Final Attack - Damage' tier at all (confirmed absent) — SkillMasteryBonus% stays 0 here.
A4: ADVANCED_FINAL_ATTACK_HELPER | B4: Advanced Final Attack (helper) | C4: 4 | E4: FALSE | F4: 1 | G4: 1 | H4: 0 | I4: 0 | J4: 100 | K4: 1 | L4: 5000 | M4: 21 | N4: TRUE | O4: =SUMPRODUCT((Inputs!$B$3>={113})*{50}) | P4: 0 | Q4: 0 | R4: 0 | T4: 0 | W4: Helper row only — feeds Dark Impale's own coefficient (Final Attack's own Final Damage bonus). +500%->900% FD (levels 1-200), factorIndex 21/baseDamage 5000 tenths% — resolves to the IDENTICAL tuple Hero's/Bowmaster's own Advanced Final Attack helper uses. Mastery Lv.113 'Advanced Final Attack - Enhance' +50% (real SkillMasteryBonus%, same level as Hero's own).
A5: MAGIC_CRASH | B5: Magic Crash | C5: 4 | D5: 28 | E5: TRUE | F5: 1 | G5: 1 | H5: 0 | I5: 0 | J5: 100 | K5: 1 | L5: 48000 | M5: 12 | N5: TRUE | O5: =SUMPRODUCT((Inputs!$B$3>={126})*{15}) | P5: =SUMPRODUCT((Inputs!$B$3>={126})*{15}) | Q5: =SUMPRODUCT((Inputs!$B$3>={126})*{15}) | R5: =5+IF(Inputs!$B$3>=100,4,0) | T5: 0 | W5: Summons a rock at the target's location, removing 1 buff and dealing 4800%->9600% damage to 5 nearby target(s), 1 time. factorIndex 12, baseDamage 48000 tenths% — resolves to the IDENTICAL tuple Hero's own Magic Crash uses (shared verbatim, single wiki page, /w/Magic_Crash). PATCHED: targets 5->9 (effect range +50% not modeled, no such mechanic exists). Mastery Lv.126 'Magic Crash - Weaken' (+15% damage taken to struck targets) baked into SkillMasteryBonus%/MasteryBossDamage%/MasteryNormalDamage% alike (a real mastery Hero's own build happened to miss on its own Magic Crash row — not fixed there, out of scope for this fork).
A6: GUNGNIRS_DESCENT | B6: Gungnir's Descent | C6: 4 | D6: 13 | E6: TRUE | F6: 1 | G6: =IF(Inputs!$B$3>=134,6,2) | H6: 0 | I6: 0 | J6: 100 | K6: 1 | L6: =IF(Inputs!$B$3>=134,9000,18000) | M6: 12 | N6: TRUE | O6: 0 | P6: 0 | Q6: 0 | R6: 1 | T6: 0 | W6: Throws a mythical spear at the target to deal 1800%->3600% damage, 2 times. factorIndex 12, baseDamage 18000 tenths%, 13s cooldown. Single-target (NormalMonsterTargets=1). Mastery Lv.134 'Gungnir's Descent - Strike' ('base damage -50%, +4 strike count') is modeled directly as a level-gated rebalance of this row's own BaseDamage (18000->9000 tenths%) and HitsPerCast (2->6) once Lv.134 unlocks — net +50% total damage (6*0.5 vs 2*1.0), same 'flip two fields at a level threshold' pattern already used elsewhere in this project for Strike-mastery hit-count bumps, just applied to both BaseDamage and HitsPerCast simultaneously instead of HitsPerCast alone. An earlier version of this row left this mastery completely unmodeled, documented as an under-estimate at high level — fixed.
A7: EVIL_EYE_SHOCK | B7: Evil Eye Shock | C7: 2 | D7: 18 | E7: TRUE | F7: 1 | G7: 6 | H7: 0 | I7: 0 | J7: 100 | K7: 1 | L7: 700 | M7: 12 | N7: TRUE | O7: =SUMPRODUCT((Inputs!$B$3>={44})*{50})+IF(Inputs!$B$3>=75,Calc!F8*IF(Calc!C8=TRUE,1,0),0) | P7: 0 | Q7: 0 | R7: =6+IF(Inputs!$B$3>=75,3,0) | T7: 0 | U7: 400 | V7: 23 | W7: [Must Summon Evil Eye — precondition not modeled as a live gate, treated as always-castable once unlocked] The Evil Eye attacks 6 (then 9 once Lv.75's Evil Eye Shock Enhancement unlocks) nearby target(s), dealing 70%->105% damage (levels 1-100, 2nd-job capped), 6 times, 18s cooldown, stun 1.5s not modeled. factorIndex 12, baseDamage 700 tenths%. Mastery Lv.44 'Evil Eye Shock - Damage' +50% real. Evil Eye Shock Enhancement's own +100%->127% Final Damage curve is folded directly into this row's own SkillMasteryBonus% as an additive coefficient bonus (a documented approximation — true Final Damage multiplies after the crit/defense pipeline, this applies it pre-pipeline instead — same simplification tier as folding Final Attack's own proc into a basic attack's coefficient elsewhere in this project). Maple Hero target (0.75x share) — see MAPLE_HERO_RATIOS.
A8: EVIL_EYE_SHOCK_ENH | B8: Evil Eye Shock Enhancement (helper) | C8: 3 | E8: FALSE | F8: 1 | G8: 1 | H8: 0 | I8: 0 | J8: 100 | K8: 1 | L8: 1000 | M8: 22 | N8: TRUE | O8: 0 | P8: 0 | Q8: 0 | R8: 0 | T8: 0 | W8: Helper row only (no independent O-column DPS) — feeds Evil Eye Shock's own K-column extra Final Damage term (target-count bump baked directly into EVIL_EYE_SHOCK's own NormalMonsterTargets formula instead). 'Target count changes to 9, Final Damage +100%->127%' (levels 1-100, own curve). factorIndex 22, baseDamage 1000 tenths%.
A9: EVIL_EYE_OF_DOMINANT | B9: Evil Eye of Dominant | C9: 3 | D9: 30 | E9: FALSE | F9: 1 | G9: 1 | H9: 1 | I9: 20 | J9: 100 | K9: 1 | L9: 600 | M9: 21 | N9: TRUE | O9: =SUMPRODUCT((Inputs!$B$3>={78})*{50}) | P9: 0 | Q9: 0 | R9: =6+IF(Inputs!$B$3>=94,3,0) | T9: 0 | U9: 400 | V9: 23 | W9: [Must Summon Evil Eye] Background DoT tied to Evil Eye's own cast cycle (CostsActionSlot=False, Cooldown=30s/ActiveWindow=20s matching Evil Eye's own duration, ICD=1s — EffectiveHits = ActiveWindow/ICD = 20 ticks/cast, same FP-Mage Poison-Mist-DoT-tied-to-a-parent-skill pattern): 'deals 60%->84% continuous damage to 6 nearby targets every 1 sec' (levels 1-200). factorIndex 21, baseDamage 600 tenths%. Mastery Lv.78 'Evil Eye of Dominant - Damage' +50% and Lv.94 'Evil Eye of Dominant - Target' +3 (6->9) both real. Maple Hero target (1x share, biggest) — see MAPLE_HERO_RATIOS.
A10: REVENGE_OF_THE_EVIL_EYE | B10: Revenge of the Evil Eye | C10: 4 | D10: 5 | E10: FALSE | F10: 1 | G10: 2 | H10: 0 | I10: 0 | J10: 100 | K10: 1 | L10: 8500 | M10: 12 | N10: TRUE | O10: =SUMPRODUCT((Inputs!$B$3>={122})*{50})+IF(Inputs!$B$3>=138,220*(Calc!E10/1000),0) | P10: 0 | Q10: 0 | R10: 1 | T10: 0 | W10: [Must Summon Evil Eye] Self-triggered proc-shaped row (Cooldown=5s, CostsActionSlot=False — same treatment as Marksman's own Bolt Surplus): 'engraves a vengeful brand dealing 850%->1700% additional damage, 2 times' (levels 1-200). factorIndex 12, baseDamage 8500 tenths%. Mastery Lv.122 'Revenge of the Evil Eye - Damage' +50% real. Mastery Lv.138 'Spectral Shadows' is a raw unevaluated wikitext formula on the live wiki page ({{#expr:2200*(1+x*0.005)}}%) — resolved via the same curve-matching method already used for Marksman's own Snipe-Empowered mastery this session (sample the formula at several levels treating x=character level, match against the 24-column factor table): resolves cleanly to factorIndex 12/baseDamage 2200 tenths% (0.44% max deviation) — since it shares the SAME factorIndex as this row's own base curve, it reuses this row's own Calc!E factor lookup directly rather than needing a separate FactorTable lookup (same trick as Snipe's own Empowered mastery).
A11: MAPLE_HERO_HELPER | B11: Maple Hero (helper) | C11: 4 | E11: FALSE | F11: 1 | G11: 1 | H11: 0 | I11: 0 | J11: 100 | K11: 1 | L11: 400 | M11: 23 | N11: TRUE | O11: 0 | P11: 0 | Q11: 0 | R11: 0 | T11: 0 | W11: Shared ratio-feeder row (see MAPLE_HERO_RATIOS) for Evil Eye of Dominant/Rush/Evil Eye Shock's own Final Damage chains — mirrors Hero/Shadower/Bowmaster's own Maple Hero mechanism. Confirmed via idle.maplestorywiki.net/w/Maple_Hero_(Dark_Knight) (full level 1-200 curve, resolves cleanly to factorIndex 23/baseDamage 400 tenths%, 0% residual, same '80%-growth-reduction after Lv.120' kink already confirmed on Hero/Bowmaster's own Maple Hero curves). No independent DPS row of its own (Calc columns J-N blank/0, only D/E/F computed, read directly by each target row's own K-column formula).
A12: RUSH | B12: Rush | C12: 3 | D12: 22 | E12: TRUE | F12: 1 | G12: 1 | H12: 0 | I12: 0 | J12: 100 | K12: 1 | L12: 6000 | M12: 12 | N12: TRUE | O12: 0 | P12: 0 | Q12: 0 | R12: 12 | T12: 0 | U12: 300 | V12: 23 | W12: Charges to the front to deal 600%->1200% damage to 12 target(s) (stun 2.5s not modeled). factorIndex 12, baseDamage 6000 tenths%, 22s cooldown — resolves to the IDENTICAL tuple Hero's own Rush uses (shared verbatim, confirmed identical wiki page). Not patched (Mastery Lv.68/90 own damage/cooldown tiers not separately modeled here, same treatment as Hero's own Rush row — kept consistent for this genuinely shared skill). Maple Hero target (0.75x share) — see MAPLE_HERO_RATIOS.
A13: HEX_OF_THE_EVIL_EYE | B13: Hex of the Evil Eye | C13: 3 | D13: 30 | E13: FALSE | F13: 1 | G13: 1 | H13: 0 | I13: 0 | J13: 100 | K13: 1 | L13: 150 | M13: 22 | N13: TRUE | O13: =SUMPRODUCT((Inputs!$B$3>={98})*{50}) | P13: 0 | Q13: 0 | R13: 0 | S13: ATTACK | T13: 20 | W13: [Must Summon Evil Eye] Self-inclusive ally buff (matches Hero's own Spirit Blade / Bishop's own 'allied players' precedent), tied to Evil Eye's own duty cycle (Cooldown=30s/BuffDuration=20s matching Evil Eye's own): '+15%->18.6% Attack to allied players for the summoning duration' (levels 1-100, 3rd-job capped). factorIndex 22, baseDamage 150 tenths%. Mastery Lv.98 'Hex of the Evil Eye - Attack' +50% additionally, real. Lv.82's own '+20 Accuracy to allies' not modeled (no Accuracy mechanic exists).
A14: DARK_RESONANCE | B14: Dark Resonance | C14: 4 | D14: 32 | E14: TRUE | F14: 1 | G14: 1 | H14: 0 | I14: 0 | J14: 100 | K14: 1 | L14: 300 | M14: 21 | N14: TRUE | O14: 0 | P14: 0 | Q14: 0 | R14: 0 | S14: ATTACK | T14: =IF(Inputs!$B$3>=130,20*1.4,20) | W14: 'Unlocks the power of pure darkness to increase Attack by 30%->44.4% for 20s' (levels 1-200). factorIndex 21, baseDamage 300 tenths% (curve rescaled 300/240=1.25x from the pre-patch 8%-at-Lv1 baseline... actually: PATCHED level-1 Attack 30%->still 30% per the patch notes, own cooldown 35->32s — this row models the CURRENT/patched Attack% curve directly since the wiki's own level-1 value (30%) already matched the patch notes' stated Attack% exactly, only cooldown/boss-bonus needed patching). PATCHED: cooldown 35->32s (baked into Cooldown(s)), new '+20% boss monster damage while active' clause added — folded into the Global Monster Damage-Taken Bonus% bucket (boss-only via monster_blend_expr), duty-cycle averaged by this row's own uptime, alongside Evil Eye's own contribution (see Summary sheet). Mastery Lv.130 'Dark Resonance - Persistence' +40% duration (real, BuffDuration becomes 20*1.4=28s once unlocked).
A15: CROSS_OVER_CHAINS | B15: Cross Over Chains | C15: 3 | D15: 30 | E15: TRUE | F15: 1 | G15: 1 | H15: 0 | I15: 0 | J15: 100 | K15: 1 | L15: 150 | M15: 21 | N15: TRUE | O15: =SUMPRODUCT((Inputs!$B$3>={73})*{100}) | P15: 0 | Q15: 0 | R15: 0 | S15: ATTACK | T15: 15 | W15: 'Increases Attack by 15%->18.6% for 15 sec (levels 1-60, own curve). If current HP is 50% or lower, the Attack increase effect disappears and damage taken is decreased by 10%->12% instead' — modeled assuming steady-state HP>50% (Attack% component only; the HP<=50% swap-to-defensive branch not modeled, matches this project's general non-modeling of the character's own damage-taken). factorIndex 21, baseDamage 150 tenths%, 30s cooldown. Mastery Lv.73 'Cross Over Chains - Attack' +100% additionally (real, taken literally as +100 percentage points per this project's established additive-mastery convention).
A16: HYPER_BODY | B16: Hyper Body | C16: 2 | D16: 30 | E16: TRUE | F16: 1 | G16: 1 | H16: 0 | I16: 0 | J16: 100 | K16: 1 | L16: 120 | M16: 21 | N16: TRUE | O16: =SUMPRODUCT((Inputs!$B$3>={49})*{50}) | P16: 0 | Q16: 0 | R16: 0 | S16: ATTACK | T16: 15 | W16: 'Increases Attack by 12%->16.8% for 15 sec (levels 1-100, 2nd-job capped), and the Defense of allied players by 15%->21%' (Defense-of-allies component not modeled — no Defense mechanic exists). factorIndex 21, baseDamage 120 tenths%, 30s cooldown. Mastery Lv.49 'Hyper Body - Persistence' +50% duration (real, applied as a SkillMasteryBonus%-style percentage addition since this schema has no separate duration-mastery mechanism — treated as a documented approximation).
A17: EVIL_EYE | B17: Evil Eye | C17: 2 | D17: 30 | E17: TRUE | F17: 1 | G17: 1 | H17: 0 | I17: 0 | J17: 100 | K17: 1 | L17: 150 | M17: 21 | N17: TRUE | O17: =SUMPRODUCT((Inputs!$B$3>={39})*{10}) | P17: 0 | Q17: 0 | R17: 0 | S17: MONSTER_DMG | T17: 20 | W17: 'Summons Evil Eye. Evil Eye follows you for 20 sec and increases the damage taken by 6 nearby target(s) by 15%->19.2%' (levels 1-100, 2nd-job capped) — drives the Global Monster Damage-Taken Bonus% bucket (Hero's own Scaring-Sword-pioneered mechanism), duty-cycle averaged, no proc-chance gate (always-on while summoned, unlike Scaring Sword's proc). factorIndex 21, baseDamage 150 tenths%, 30s cooldown. Mastery Lv.39 'Evil Eye - Damage Taken' +10 percentage points, real, flat add once unlocked.
A18: LORD_OF_DARKNESS_CRITRATE | B18: Lord of Darkness (Crit Rate half) | C18: 3 | D18: 3 | E18: FALSE | F18: 1 | G18: 1 | H18: 0 | I18: 0 | J18: 30 | K18: 1 | L18: 100 | M18: 22 | N18: TRUE | O18: 0 | P18: 0 | Q18: 0 | R18: 0 | S18: CRIT_RATE | T18: 8 | W18: On-attack proc (30% chance, own internal cooldown) granting +Crit Rate/+Crit Damage for a duration (HP-recovery component not modeled) — split into two rows since this schema's BuffTargetStat column only holds one stat per row (same reason as Hero's own Enrage split). Modeled as ProcChance% x duty-cycle uptime (Scaring-Sword-style simplification), not an exact per-attack RNG state machine. PATCHED: duration 5->8s (baked into BuffDuration(s)), Crit Rate 8%->10% (curve rescaled 10/8=1.25x, giving the 100 stored here vs. the pre-patch curve's own 80), cooldown 2->3s (baked into Cooldown(s)).
A19: LORD_OF_DARKNESS_CRITDMG | B19: Lord of Darkness (Crit Damage half) | C19: 3 | D19: 3 | E19: FALSE | F19: 1 | G19: 1 | H19: 0 | I19: 0 | J19: 30 | K19: 1 | L19: 400 | M19: 22 | N19: TRUE | O19: 0 | P19: 0 | Q19: 0 | R19: 0 | S19: CRIT_DAMAGE | T19: 8 | W19: Crit Damage half of Lord of Darkness — same proc-chance/cooldown/duration as LORD_OF_DARKNESS_CRITRATE. PATCHED: Crit Damage 30%->40% (curve rescaled 40/30=1.3333x, giving the 400 stored here vs. the pre-patch curve's own 300).
A20: NIMBLE_FEET | B20: Nimble Feet | C20: 1 | D20: 60 | E20: TRUE | F20: 1 | G20: 1 | H20: 0 | I20: 0 | J20: 100 | K20: 1 | L20: 150 | M20: 0 | N20: FALSE | O20: 0 | P20: 0 | Q20: 0 | R20: 1 | S20: ATTACK_SPEED | T20: 15 | W20: Shared cross-tree verbatim w/ every class in this project (byte-identical wiki wording — '+15% Attack Speed, +10% Speed for 15 sec'). Flat +15% Attack Speed / +10% Speed for 15s, 60s cooldown, non-scaling. FactorIndex unused placeholder.
A21: WEAPON_ACCELERATION | B21: Weapon Acceleration | C21: 2 | E21: FALSE | F21: 1 | G21: 1 | H21: 0 | I21: 0 | J21: 100 | K21: 1 | L21: 50 | M21: 22 | N21: TRUE | O21: 0 | P21: 0 | Q21: 0 | R21: 0 | S21: ATTACK_SPEED | T21: 0 | W21: Magic Critical pattern — already baked into Inputs!ATTACK_SPEED%; feeds the 2nd-Job Skill Level Bonus delta. Reuses Hero's/Bowmaster's own tuple directly (shared-value-different-key, byte-identical wiki wording — '+5% Attack Speed'). factorIndex 22, baseDamage 50 tenths% (5%->6.5%, levels 1-100).
A22: WEAPON_MASTERY | B22: Weapon Mastery | C22: 2 | E22: FALSE | F22: 1 | G22: 1 | H22: 0 | I22: 0 | J22: 100 | K22: 1 | L22: 150 | M22: 22 | N22: TRUE | O22: 0 | P22: 0 | Q22: 0 | R22: 0 | S22: MIN_DAMAGE | T22: 0 | W22: Magic Critical pattern — already baked into Inputs!MIN_DAMAGE%; feeds the 2nd-Job Skill Level Bonus delta. factorIndex 22, baseDamage 150 tenths% (15%->19.5%, levels 1-100).
A23: BARRICADE_SKILL_DMG | B23: Barricade Mastery (Skill Damage) | C23: 4 | E23: FALSE | F23: 1 | G23: 1 | H23: 0 | I23: 0 | J23: 100 | K23: 1 | L23: 150 | M23: 22 | N23: TRUE | O23: 0 | P23: 0 | Q23: 0 | R23: 0 | S23: SKILL_DAMAGE | T23: 0 | W23: Magic Critical pattern — already baked into Inputs!SKILL_DAMAGE%; feeds the 4th-Job Skill Level Bonus delta (Skill Damage side). Same slot as Hero's own Combat Mastery, just renamed. factorIndex 22, baseDamage 150 tenths% (15%->21.3% at Lv140, own curve).
A24: BARRICADE_MAXDMG | B24: Barricade Mastery (Max Damage Multiplier) | C24: 4 | E24: FALSE | F24: 1 | G24: 1 | H24: 0 | I24: 0 | J24: 100 | K24: 1 | L24: 200 | M24: 22 | N24: TRUE | O24: 0 | P24: 0 | Q24: 0 | R24: 0 | S24: MAX_DAMAGE | T24: 0 | W24: Same skill as Barricade Mastery (Skill Damage) above, +20%->27.8% Max Damage Multiplier (at Lv140, own curve). Magic Critical pattern — already baked into Inputs!MAX_DAMAGE%; feeds the 4th-Job Skill Level Bonus delta (Max Damage Multiplier side). factorIndex 22, baseDamage 200 tenths%.
A25: POWER_STANCE_FD | B25: Power Stance (Final Damage) | C25: 4 | E25: FALSE | F25: 1 | G25: 1 | H25: 0 | I25: 0 | J25: 100 | K25: 1 | L25: 150 | M25: 22 | N25: TRUE | O25: 0 | P25: 0 | Q25: 0 | R25: 0 | S25: FINAL_DAMAGE | T25: 0 | W25: Own damage-taken-reduction component (5%->8%) not modeled (no such mechanic exists). Byte-identical wiki wording to Hero's own Power Stance — reuses that tuple directly. Magic Critical pattern — already baked into Inputs!FINAL_DAMAGE%; feeds the 4th-Job Skill Level Bonus delta. factorIndex 22, baseDamage 150 tenths% (15%->24%, levels 1-200).
A26: FINAL_PACT | B26: Final Pact | C26: 4 | E26: FALSE | F26: 1 | G26: 1 | H26: 0 | I26: 0 | J26: 100 | K26: 1 | L26: 100 | M26: 22 | N26: TRUE | O26: =SUMPRODUCT((Inputs!$B$3>={118})*{100}) | P26: 0 | Q26: 0 | R26: 0 | S26: FINAL_DAMAGE | T26: 0 | W26: 'Increases Final Damage by 10%->13% (levels 1-200, own curve). When HP falls below 1%, the Final Damage increase disappears and you become immune to damage for 2 sec (once per battle, prevents death)' — death-prevention mechanic not modeled. Magic Critical pattern — already baked into Inputs!FINAL_DAMAGE%; feeds the 4th-Job Skill Level Bonus delta (Sensitivity-only, same as every other Magic-Critical-pattern row). factorIndex 22, baseDamage 100 tenths%. Mastery Lv.118 'Final Pact - Recovery' +100% Final Damage boost (real, +100 percentage points, Sensitivity-delta only since the whole row is a passive assumed reflected in Inputs).

Sheet Calc
A1: Key | B1: Name | C1: Unlocked | D1: InputLevel | E1: Factor | F1: CoefficientPercent | G1: EffectiveHits | H1: ProcProbability | I1: MapleHeroMultiplier | J1: BaseDamage | K1: BaseHitDamage | L1: NonCritAvg | M1: CritAvg | N1: ExpectedDamage(perHit) | O1: DPS | P1: % of Total | Q1: InvCooldown | R1: CastsInFight | S1: HitRate(perSec)
A2: =Skills!A2 | B2: =Skills!B2 | C2: =Inputs!$B$3>=100 | F2: =Summary!$B$54+Skills!O2 | G2: =Skills!G2*IF(Skills!H2>0,Skills!I2/Skills!H2,1) | H2: =1-(1-Skills!J2/100)^Skills!K2 | I2: 1 | J2: =Summary!$B$50*(F2/100) | K2: =J2*(1+Summary!$B$51/100)*(1+Inputs!$B$14/100)*(1+IF(Inputs!$B$4="pvp",0,(1-Summary!$B$55)*(Inputs!$B$19+Skills!P2+Summary!$B$59)+Summary!$B$55*(Inputs!$B$20+Skills!Q2+Summary!$B$59))/100)*(1+Inputs!$B$15/100)*(5000/(6000+Inputs!$B$7*(1-Inputs!$B$18/100)))*(1+(Inputs!$B$23+Summary!$B$65)/100)*(1+(IF(Skills!A2="DARK_IMPALE",Inputs!$B$16,Inputs!$B$17))/100)*(Summary!$B$57*I2) | L2: =K2*(MIN(Inputs!$B$21,Inputs!$B$22)/100+Inputs!$B$22/100)/2 | M2: =L2*(1+(Inputs!$B$9+Summary!$B$64)/100) | N2: =L2*(1-MIN((Inputs!$B$8+Summary!$B$58),100)/100)+M2*(MIN((Inputs!$B$8+Summary!$B$58),100)/100) | O2: =IF(C2,Skills!G2*N2*Summary!$B$63*IF(Inputs!$B$4="pvp",1,(1-Summary!$B$55)*(1)+Summary!$B$55*(MIN(Skills!R2,Inputs!$B$37))),0) | P2: =IF(Summary!$B$3=0,0,O2/Summary!$B$3) | Q2: 0 | R2: 0 | S2: =IFERROR(O2/N2,0)
A3: =Skills!A3 | B3: =Skills!B3 | C3: =Inputs!$B$3>=50 | D3: =IF(Skills!C3=1,60+Inputs!$B$24+Inputs!$B$28,IF(Skills!C3=2,90+Inputs!$B$25+Inputs!$B$28,IF(Skills!C3=3,120+Inputs!$B$26+Inputs!$B$28,MAX(0,(Inputs!$B$3-100)*3)+Inputs!$B$27+Inputs!$B$28))) | E3: =INDEX(FactorTable!$B$2:$Y$301, MATCH(ROUND(MIN(300,MAX(1,D3)),0), FactorTable!$A$2:$A$301,0), Skills!M3+1) | F3: =IF(Skills!N3=TRUE,(Skills!L3/10)*(E3/1000),Skills!L3/10)+Skills!O3 | I3: 1
A4: =Skills!A4 | B4: =Skills!B4 | C4: =Inputs!$B$3>=105 | D4: =IF(Skills!C4=1,60+Inputs!$B$24+Inputs!$B$28,IF(Skills!C4=2,90+Inputs!$B$25+Inputs!$B$28,IF(Skills!C4=3,120+Inputs!$B$26+Inputs!$B$28,MAX(0,(Inputs!$B$3-100)*3)+Inputs!$B$27+Inputs!$B$28))) | E4: =INDEX(FactorTable!$B$2:$Y$301, MATCH(ROUND(MIN(300,MAX(1,D4)),0), FactorTable!$A$2:$A$301,0), Skills!M4+1) | F4: =IF(Skills!N4=TRUE,(Skills!L4/10)*(E4/1000),Skills!L4/10)+Skills!O4 | I4: 1
A5: =Skills!A5 | B5: =Skills!B5 | C5: =Inputs!$B$3>=117 | D5: =IF(Skills!C5=1,60+Inputs!$B$24+Inputs!$B$28,IF(Skills!C5=2,90+Inputs!$B$25+Inputs!$B$28,IF(Skills!C5=3,120+Inputs!$B$26+Inputs!$B$28,MAX(0,(Inputs!$B$3-100)*3)+Inputs!$B$27+Inputs!$B$28))) | E5: =INDEX(FactorTable!$B$2:$Y$301, MATCH(ROUND(MIN(300,MAX(1,D5)),0), FactorTable!$A$2:$A$301,0), Skills!M5+1) | F5: =IF(Skills!N5=TRUE,(Skills!L5/10)*(E5/1000),Skills!L5/10)+Skills!O5 | G5: =Skills!G5*IF(Skills!H5>0,Skills!I5/Skills!H5,1) | H5: =1-(1-Skills!J5/100)^Skills!K5 | I5: 1 | J5: =Summary!$B$50*(F5/100) | K5: =J5*(1+Summary!$B$51/100)*(1+Inputs!$B$14/100)*(1+IF(Inputs!$B$4="pvp",0,(1-Summary!$B$55)*(Inputs!$B$19+Skills!P5+Summary!$B$59)+Summary!$B$55*(Inputs!$B$20+Skills!Q5+Summary!$B$59))/100)*(1+Inputs!$B$15/100)*(5000/(6000+Inputs!$B$7*(1-Inputs!$B$18/100)))*(1+(Inputs!$B$23+Summary!$B$65)/100)*(1+(IF(Skills!A5="DARK_IMPALE",Inputs!$B$16,Inputs!$B$17))/100)*(Summary!$B$57*I5) | L5: =K5*(MIN(Inputs!$B$21,Inputs!$B$22)/100+Inputs!$B$22/100)/2 | M5: =L5*(1+(Inputs!$B$9+Summary!$B$64)/100) | N5: =L5*(1-MIN((Inputs!$B$8+Summary!$B$58),100)/100)+M5*(MIN((Inputs!$B$8+Summary!$B$58),100)/100) | O5: =IF(C5,H5*N5*IF(AND(Inputs!$B$4<>"pvp",Inputs!$B$35>0),((Skills!G5*((R5-1)*IF(Skills!H5>0,Skills!I5/Skills!H5,1)+IF(Skills!H5>0,MIN(Skills!I5,MAX(0,Inputs!$B$35-((R5-1)*IF(Inputs!$B$4="pvp",15,MAX(0.1,Skills!D5-IF(Skills!E5=TRUE,Inputs!$B$31,0))))))/Skills!H5,1)))/Inputs!$B$35),G5*Q5)*IF(Inputs!$B$4="pvp",1,(1-Summary!$B$55)*(1)+Summary!$B$55*(MIN(Skills!R5,Inputs!$B$37))),0) | P5: =IF(Summary!$B$3=0,0,O5/Summary!$B$3) | Q5: =IFERROR(1/IF(Inputs!$B$4="pvp",15,MAX(0.1,Skills!D5-IF(Skills!E5=TRUE,Inputs!$B$31,0))),0) | R5: =IF(AND(Inputs!$B$4<>"pvp",Inputs!$B$35>0),(INT(Inputs!$B$35/IF(Inputs!$B$4="pvp",15,MAX(0.1,Skills!D5-IF(Skills!E5=TRUE,Inputs!$B$31,0))))+1),0) | S5: =IFERROR(O5/N5,0)
A6: =Skills!A6 | B6: =Skills!B6 | C6: =Inputs!$B$3>=103 | D6: =IF(Skills!C6=1,60+Inputs!$B$24+Inputs!$B$28,IF(Skills!C6=2,90+Inputs!$B$25+Inputs!$B$28,IF(Skills!C6=3,120+Inputs!$B$26+Inputs!$B$28,MAX(0,(Inputs!$B$3-100)*3)+Inputs!$B$27+Inputs!$B$28))) | E6: =INDEX(FactorTable!$B$2:$Y$301, MATCH(ROUND(MIN(300,MAX(1,D6)),0), FactorTable!$A$2:$A$301,0), Skills!M6+1) | F6: =IF(Skills!N6=TRUE,(Skills!L6/10)*(E6/1000),Skills!L6/10)+Skills!O6 | G6: =Skills!G6*IF(Skills!H6>0,Skills!I6/Skills!H6,1) | H6: =1-(1-Skills!J6/100)^Skills!K6 | I6: 1 | J6: =Summary!$B$50*(F6/100) | K6: =J6*(1+Summary!$B$51/100)*(1+Inputs!$B$14/100)*(1+IF(Inputs!$B$4="pvp",0,(1-Summary!$B$55)*(Inputs!$B$19+Skills!P6+Summary!$B$59)+Summary!$B$55*(Inputs!$B$20+Skills!Q6+Summary!$B$59))/100)*(1+Inputs!$B$15/100)*(5000/(6000+Inputs!$B$7*(1-Inputs!$B$18/100)))*(1+(Inputs!$B$23+Summary!$B$65)/100)*(1+(IF(Skills!A6="DARK_IMPALE",Inputs!$B$16,Inputs!$B$17))/100)*(Summary!$B$57*I6) | L6: =K6*(MIN(Inputs!$B$21,Inputs!$B$22)/100+Inputs!$B$22/100)/2 | M6: =L6*(1+(Inputs!$B$9+Summary!$B$64)/100) | N6: =L6*(1-MIN((Inputs!$B$8+Summary!$B$58),100)/100)+M6*(MIN((Inputs!$B$8+Summary!$B$58),100)/100) | O6: =IF(C6,H6*N6*IF(AND(Inputs!$B$4<>"pvp",Inputs!$B$35>0),((Skills!G6*((R6-1)*IF(Skills!H6>0,Skills!I6/Skills!H6,1)+IF(Skills!H6>0,MIN(Skills!I6,MAX(0,Inputs!$B$35-((R6-1)*IF(Inputs!$B$4="pvp",15,MAX(0.1,Skills!D6-IF(Skills!E6=TRUE,Inputs!$B$31,0))))))/Skills!H6,1)))/Inputs!$B$35),G6*Q6)*IF(Inputs!$B$4="pvp",1,(1-Summary!$B$55)*(1)+Summary!$B$55*(MIN(Skills!R6,Inputs!$B$37))),0) | P6: =IF(Summary!$B$3=0,0,O6/Summary!$B$3) | Q6: =IFERROR(1/IF(Inputs!$B$4="pvp",15,MAX(0.1,Skills!D6-IF(Skills!E6=TRUE,Inputs!$B$31,0))),0) | R6: =IF(AND(Inputs!$B$4<>"pvp",Inputs!$B$35>0),(INT(Inputs!$B$35/IF(Inputs!$B$4="pvp",15,MAX(0.1,Skills!D6-IF(Skills!E6=TRUE,Inputs!$B$31,0))))+1),0) | S6: =IFERROR(O6/N6,0)
A7: =Skills!A7 | B7: =Skills!B7 | C7: =Inputs!$B$3>=40 | D7: =IF(Skills!C7=1,60+Inputs!$B$24+Inputs!$B$28,IF(Skills!C7=2,90+Inputs!$B$25+Inputs!$B$28,IF(Skills!C7=3,120+Inputs!$B$26+Inputs!$B$28,MAX(0,(Inputs!$B$3-100)*3)+Inputs!$B$27+Inputs!$B$28))) | E7: =INDEX(FactorTable!$B$2:$Y$301, MATCH(ROUND(MIN(300,MAX(1,D7)),0), FactorTable!$A$2:$A$301,0), Skills!M7+1) | F7: =IF(Skills!N7=TRUE,(Skills!L7/10)*(E7/1000),Skills!L7/10)+Skills!O7 | G7: =Skills!G7*IF(Skills!H7>0,Skills!I7/Skills!H7,1) | H7: =1-(1-Skills!J7/100)^Skills!K7 | I7: 1 | J7: =Summary!$B$50*(F7/100) | K7: =J7*(1+Summary!$B$51/100)*(1+Inputs!$B$14/100)*(1+IF(Inputs!$B$4="pvp",0,(1-Summary!$B$55)*(Inputs!$B$19+Skills!P7+Summary!$B$59)+Summary!$B$55*(Inputs!$B$20+Skills!Q7+Summary!$B$59))/100)*(1+Inputs!$B$15/100)*(5000/(6000+Inputs!$B$7*(1-Inputs!$B$18/100)))*(1+(Inputs!$B$23+Summary!$B$65)/100)*(1+0.75*IF(C11=TRUE,F11,0)/100)*(1+(IF(Skills!A7="DARK_IMPALE",Inputs!$B$16,Inputs!$B$17))/100)*(Summary!$B$57*I7) | L7: =K7*(MIN(Inputs!$B$21,Inputs!$B$22)/100+Inputs!$B$22/100)/2 | M7: =L7*(1+(Inputs!$B$9+Summary!$B$64)/100) | N7: =L7*(1-MIN((Inputs!$B$8+Summary!$B$58),100)/100)+M7*(MIN((Inputs!$B$8+Summary!$B$58),100)/100) | O7: =IF(C7,H7*N7*IF(AND(Inputs!$B$4<>"pvp",Inputs!$B$35>0),((Skills!G7*((R7-1)*IF(Skills!H7>0,Skills!I7/Skills!H7,1)+IF(Skills!H7>0,MIN(Skills!I7,MAX(0,Inputs!$B$35-((R7-1)*IF(Inputs!$B$4="pvp",15,MAX(0.1,Skills!D7-IF(Skills!E7=TRUE,Inputs!$B$31,0))))))/Skills!H7,1)))/Inputs!$B$35),G7*Q7)*IF(Inputs!$B$4="pvp",1,(1-Summary!$B$55)*(1)+Summary!$B$55*(MIN(Skills!R7,Inputs!$B$37))),0) | P7: =IF(Summary!$B$3=0,0,O7/Summary!$B$3) | Q7: =IFERROR(1/IF(Inputs!$B$4="pvp",15,MAX(0.1,Skills!D7-IF(Skills!E7=TRUE,Inputs!$B$31,0))),0) | R7: =IF(AND(Inputs!$B$4<>"pvp",Inputs!$B$35>0),(INT(Inputs!$B$35/IF(Inputs!$B$4="pvp",15,MAX(0.1,Skills!D7-IF(Skills!E7=TRUE,Inputs!$B$31,0))))+1),0) | S7: =IFERROR(O7/N7,0)
A8: =Skills!A8 | B8: =Skills!B8 | C8: =Inputs!$B$3>=75 | D8: =IF(Skills!C8=1,60+Inputs!$B$24+Inputs!$B$28,IF(Skills!C8=2,90+Inputs!$B$25+Inputs!$B$28,IF(Skills!C8=3,120+Inputs!$B$26+Inputs!$B$28,MAX(0,(Inputs!$B$3-100)*3)+Inputs!$B$27+Inputs!$B$28))) | E8: =INDEX(FactorTable!$B$2:$Y$301, MATCH(ROUND(MIN(300,MAX(1,D8)),0), FactorTable!$A$2:$A$301,0), Skills!M8+1) | F8: =IF(Skills!N8=TRUE,(Skills!L8/10)*(E8/1000),Skills!L8/10)+Skills!O8 | I8: 1
A9: =Skills!A9 | B9: =Skills!B9 | C9: =Inputs!$B$3>=60 | D9: =IF(Skills!C9=1,60+Inputs!$B$24+Inputs!$B$28,IF(Skills!C9=2,90+Inputs!$B$25+Inputs!$B$28,IF(Skills!C9=3,120+Inputs!$B$26+Inputs!$B$28,MAX(0,(Inputs!$B$3-100)*3)+Inputs!$B$27+Inputs!$B$28))) | E9: =INDEX(FactorTable!$B$2:$Y$301, MATCH(ROUND(MIN(300,MAX(1,D9)),0), FactorTable!$A$2:$A$301,0), Skills!M9+1) | F9: =IF(Skills!N9=TRUE,(Skills!L9/10)*(E9/1000),Skills!L9/10)+Skills!O9 | G9: =Skills!G9*IF(Skills!H9>0,Skills!I9/Skills!H9,1) | H9: =1-(1-Skills!J9/100)^Skills!K9 | I9: 1 | J9: =Summary!$B$50*(F9/100) | K9: =J9*(1+Summary!$B$51/100)*(1+Inputs!$B$14/100)*(1+IF(Inputs!$B$4="pvp",0,(1-Summary!$B$55)*(Inputs!$B$19+Skills!P9+Summary!$B$59)+Summary!$B$55*(Inputs!$B$20+Skills!Q9+Summary!$B$59))/100)*(1+Inputs!$B$15/100)*(5000/(6000+Inputs!$B$7*(1-Inputs!$B$18/100)))*(1+(Inputs!$B$23+Summary!$B$65)/100)*(1+1.0*IF(C11=TRUE,F11,0)/100)*(1+(IF(Skills!A9="DARK_IMPALE",Inputs!$B$16,Inputs!$B$17))/100)*(Summary!$B$57*I9) | L9: =K9*(MIN(Inputs!$B$21,Inputs!$B$22)/100+Inputs!$B$22/100)/2 | M9: =L9*(1+(Inputs!$B$9+Summary!$B$64)/100) | N9: =L9*(1-MIN((Inputs!$B$8+Summary!$B$58),100)/100)+M9*(MIN((Inputs!$B$8+Summary!$B$58),100)/100) | O9: =IF(C9,H9*N9*IF(AND(Inputs!$B$4<>"pvp",Inputs!$B$35>0),((Skills!G9*((R9-1)*IF(Skills!H9>0,Skills!I9/Skills!H9,1)+IF(Skills!H9>0,MIN(Skills!I9,MAX(0,Inputs!$B$35-((R9-1)*IF(Inputs!$B$4="pvp",15,MAX(0.1,Skills!D9-IF(Skills!E9=TRUE,Inputs!$B$31,0))))))/Skills!H9,1)))/Inputs!$B$35),G9*Q9)*IF(Inputs!$B$4="pvp",1,(1-Summary!$B$55)*(1)+Summary!$B$55*(MIN(Skills!R9,Inputs!$B$37))),0) | P9: =IF(Summary!$B$3=0,0,O9/Summary!$B$3) | Q9: =IFERROR(1/IF(Inputs!$B$4="pvp",15,MAX(0.1,Skills!D9-IF(Skills!E9=TRUE,Inputs!$B$31,0))),0) | R9: =IF(AND(Inputs!$B$4<>"pvp",Inputs!$B$35>0),(INT(Inputs!$B$35/IF(Inputs!$B$4="pvp",15,MAX(0.1,Skills!D9-IF(Skills!E9=TRUE,Inputs!$B$31,0))))+1),0) | S9: =IFERROR(O9/N9,0)
A10: =Skills!A10 | B10: =Skills!B10 | C10: =Inputs!$B$3>=110 | D10: =IF(Skills!C10=1,60+Inputs!$B$24+Inputs!$B$28,IF(Skills!C10=2,90+Inputs!$B$25+Inputs!$B$28,IF(Skills!C10=3,120+Inputs!$B$26+Inputs!$B$28,MAX(0,(Inputs!$B$3-100)*3)+Inputs!$B$27+Inputs!$B$28))) | E10: =INDEX(FactorTable!$B$2:$Y$301, MATCH(ROUND(MIN(300,MAX(1,D10)),0), FactorTable!$A$2:$A$301,0), Skills!M10+1) | F10: =IF(Skills!N10=TRUE,(Skills!L10/10)*(E10/1000),Skills!L10/10)+Skills!O10 | G10: =Skills!G10*IF(Skills!H10>0,Skills!I10/Skills!H10,1) | H10: =1-(1-Skills!J10/100)^Skills!K10 | I10: 1 | J10: =Summary!$B$50*(F10/100) | K10: =J10*(1+Summary!$B$51/100)*(1+Inputs!$B$14/100)*(1+IF(Inputs!$B$4="pvp",0,(1-Summary!$B$55)*(Inputs!$B$19+Skills!P10+Summary!$B$59)+Summary!$B$55*(Inputs!$B$20+Skills!Q10+Summary!$B$59))/100)*(1+Inputs!$B$15/100)*(5000/(6000+Inputs!$B$7*(1-Inputs!$B$18/100)))*(1+(Inputs!$B$23+Summary!$B$65)/100)*(1+(IF(Skills!A10="DARK_IMPALE",Inputs!$B$16,Inputs!$B$17))/100)*(Summary!$B$57*I10) | L10: =K10*(MIN(Inputs!$B$21,Inputs!$B$22)/100+Inputs!$B$22/100)/2 | M10: =L10*(1+(Inputs!$B$9+Summary!$B$64)/100) | N10: =L10*(1-MIN((Inputs!$B$8+Summary!$B$58),100)/100)+M10*(MIN((Inputs!$B$8+Summary!$B$58),100)/100) | O10: =IF(C10,H10*N10*IF(AND(Inputs!$B$4<>"pvp",Inputs!$B$35>0),((Skills!G10*((R10-1)*IF(Skills!H10>0,Skills!I10/Skills!H10,1)+IF(Skills!H10>0,MIN(Skills!I10,MAX(0,Inputs!$B$35-((R10-1)*IF(Inputs!$B$4="pvp",15,MAX(0.1,Skills!D10-IF(Skills!E10=TRUE,Inputs!$B$31,0))))))/Skills!H10,1)))/Inputs!$B$35),G10*Q10)*IF(Inputs!$B$4="pvp",1,(1-Summary!$B$55)*(1)+Summary!$B$55*(MIN(Skills!R10,Inputs!$B$37))),0) | P10: =IF(Summary!$B$3=0,0,O10/Summary!$B$3) | Q10: =IFERROR(1/IF(Inputs!$B$4="pvp",15,MAX(0.1,Skills!D10-IF(Skills!E10=TRUE,Inputs!$B$31,0))),0) | R10: =IF(AND(Inputs!$B$4<>"pvp",Inputs!$B$35>0),(INT(Inputs!$B$35/IF(Inputs!$B$4="pvp",15,MAX(0.1,Skills!D10-IF(Skills!E10=TRUE,Inputs!$B$31,0))))+1),0) | S10: =IFERROR(O10/N10,0)
A11: =Skills!A11 | B11: =Skills!B11 | C11: =Inputs!$B$3>=100 | D11: =IF(Skills!C11=1,60+Inputs!$B$24+Inputs!$B$28,IF(Skills!C11=2,90+Inputs!$B$25+Inputs!$B$28,IF(Skills!C11=3,120+Inputs!$B$26+Inputs!$B$28,MAX(0,(Inputs!$B$3-100)*3)+Inputs!$B$27+Inputs!$B$28))) | E11: =INDEX(FactorTable!$B$2:$Y$301, MATCH(ROUND(MIN(300,MAX(1,D11)),0), FactorTable!$A$2:$A$301,0), Skills!M11+1) | F11: =IF(Skills!N11=TRUE,(Skills!L11/10)*(E11/1000),Skills!L11/10)+Skills!O11 | I11: 1
A12: =Skills!A12 | B12: =Skills!B12 | C12: =Inputs!$B$3>=63 | D12: =IF(Skills!C12=1,60+Inputs!$B$24+Inputs!$B$28,IF(Skills!C12=2,90+Inputs!$B$25+Inputs!$B$28,IF(Skills!C12=3,120+Inputs!$B$26+Inputs!$B$28,MAX(0,(Inputs!$B$3-100)*3)+Inputs!$B$27+Inputs!$B$28))) | E12: =INDEX(FactorTable!$B$2:$Y$301, MATCH(ROUND(MIN(300,MAX(1,D12)),0), FactorTable!$A$2:$A$301,0), Skills!M12+1) | F12: =IF(Skills!N12=TRUE,(Skills!L12/10)*(E12/1000),Skills!L12/10)+Skills!O12 | G12: =Skills!G12*IF(Skills!H12>0,Skills!I12/Skills!H12,1) | H12: =1-(1-Skills!J12/100)^Skills!K12 | I12: 1 | J12: =Summary!$B$50*(F12/100) | K12: =J12*(1+Summary!$B$51/100)*(1+Inputs!$B$14/100)*(1+IF(Inputs!$B$4="pvp",0,(1-Summary!$B$55)*(Inputs!$B$19+Skills!P12+Summary!$B$59)+Summary!$B$55*(Inputs!$B$20+Skills!Q12+Summary!$B$59))/100)*(1+Inputs!$B$15/100)*(5000/(6000+Inputs!$B$7*(1-Inputs!$B$18/100)))*(1+(Inputs!$B$23+Summary!$B$65)/100)*(1+0.75*IF(C11=TRUE,F11,0)/100)*(1+(IF(Skills!A12="DARK_IMPALE",Inputs!$B$16,Inputs!$B$17))/100)*(Summary!$B$57*I12) | L12: =K12*(MIN(Inputs!$B$21,Inputs!$B$22)/100+Inputs!$B$22/100)/2 | M12: =L12*(1+(Inputs!$B$9+Summary!$B$64)/100) | N12: =L12*(1-MIN((Inputs!$B$8+Summary!$B$58),100)/100)+M12*(MIN((Inputs!$B$8+Summary!$B$58),100)/100) | O12: =IF(C12,H12*N12*IF(AND(Inputs!$B$4<>"pvp",Inputs!$B$35>0),((Skills!G12*((R12-1)*IF(Skills!H12>0,Skills!I12/Skills!H12,1)+IF(Skills!H12>0,MIN(Skills!I12,MAX(0,Inputs!$B$35-((R12-1)*IF(Inputs!$B$4="pvp",15,MAX(0.1,Skills!D12-IF(Skills!E12=TRUE,Inputs!$B$31,0))))))/Skills!H12,1)))/Inputs!$B$35),G12*Q12)*IF(Inputs!$B$4="pvp",1,(1-Summary!$B$55)*(1)+Summary!$B$55*(MIN(Skills!R12,Inputs!$B$37))),0) | P12: =IF(Summary!$B$3=0,0,O12/Summary!$B$3) | Q12: =IFERROR(1/IF(Inputs!$B$4="pvp",15,MAX(0.1,Skills!D12-IF(Skills!E12=TRUE,Inputs!$B$31,0))),0) | R12: =IF(AND(Inputs!$B$4<>"pvp",Inputs!$B$35>0),(INT(Inputs!$B$35/IF(Inputs!$B$4="pvp",15,MAX(0.1,Skills!D12-IF(Skills!E12=TRUE,Inputs!$B$31,0))))+1),0) | S12: =IFERROR(O12/N12,0)
A13: =Skills!A13 | B13: =Skills!B13 | C13: =Inputs!$B$3>=69 | D13: =IF(Skills!C13=1,60+Inputs!$B$24+Inputs!$B$28,IF(Skills!C13=2,90+Inputs!$B$25+Inputs!$B$28,IF(Skills!C13=3,120+Inputs!$B$26+Inputs!$B$28,MAX(0,(Inputs!$B$3-100)*3)+Inputs!$B$27+Inputs!$B$28))) | E13: =INDEX(FactorTable!$B$2:$Y$301, MATCH(ROUND(MIN(300,MAX(1,D13)),0), FactorTable!$A$2:$A$301,0), Skills!M13+1) | F13: =IF(Skills!N13=TRUE,(Skills!L13/10)*(E13/1000),Skills!L13/10)+Skills!O13 | G13: =Skills!G13*IF(Skills!H13>0,Skills!I13/Skills!H13,1) | H13: =1-(1-Skills!J13/100)^Skills!K13 | I13: 1 | O13: 0 | P13: =IF(Summary!$B$3=0,0,O13/Summary!$B$3) | Q13: =IFERROR(1/IF(Inputs!$B$4="pvp",15,MAX(0.1,Skills!D13-IF(Skills!E13=TRUE,Inputs!$B$31,0))),0) | R13: =IF(AND(Inputs!$B$4<>"pvp",Inputs!$B$35>0),(INT(Inputs!$B$35/IF(Inputs!$B$4="pvp",15,MAX(0.1,Skills!D13-IF(Skills!E13=TRUE,Inputs!$B$31,0))))+1),0) | S13: =IFERROR(O13/N13,0)
A14: =Skills!A14 | B14: =Skills!B14 | C14: =Inputs!$B$3>=115 | D14: =IF(Skills!C14=1,60+Inputs!$B$24+Inputs!$B$28,IF(Skills!C14=2,90+Inputs!$B$25+Inputs!$B$28,IF(Skills!C14=3,120+Inputs!$B$26+Inputs!$B$28,MAX(0,(Inputs!$B$3-100)*3)+Inputs!$B$27+Inputs!$B$28))) | E14: =INDEX(FactorTable!$B$2:$Y$301, MATCH(ROUND(MIN(300,MAX(1,D14)),0), FactorTable!$A$2:$A$301,0), Skills!M14+1) | F14: =IF(Skills!N14=TRUE,(Skills!L14/10)*(E14/1000),Skills!L14/10)+Skills!O14 | G14: =Skills!G14*IF(Skills!H14>0,Skills!I14/Skills!H14,1) | H14: =1-(1-Skills!J14/100)^Skills!K14 | I14: 1 | O14: 0 | P14: =IF(Summary!$B$3=0,0,O14/Summary!$B$3) | Q14: =IFERROR(1/IF(Inputs!$B$4="pvp",15,MAX(0.1,Skills!D14-IF(Skills!E14=TRUE,Inputs!$B$31,0))),0) | R14: =IF(AND(Inputs!$B$4<>"pvp",Inputs!$B$35>0),(INT(Inputs!$B$35/IF(Inputs!$B$4="pvp",15,MAX(0.1,Skills!D14-IF(Skills!E14=TRUE,Inputs!$B$31,0))))+1),0) | S14: =IFERROR(O14/N14,0)
A15: =Skills!A15 | B15: =Skills!B15 | C15: =Inputs!$B$3>=66 | D15: =IF(Skills!C15=1,60+Inputs!$B$24+Inputs!$B$28,IF(Skills!C15=2,90+Inputs!$B$25+Inputs!$B$28,IF(Skills!C15=3,120+Inputs!$B$26+Inputs!$B$28,MAX(0,(Inputs!$B$3-100)*3)+Inputs!$B$27+Inputs!$B$28))) | E15: =INDEX(FactorTable!$B$2:$Y$301, MATCH(ROUND(MIN(300,MAX(1,D15)),0), FactorTable!$A$2:$A$301,0), Skills!M15+1) | F15: =IF(Skills!N15=TRUE,(Skills!L15/10)*(E15/1000),Skills!L15/10)+Skills!O15 | G15: =Skills!G15*IF(Skills!H15>0,Skills!I15/Skills!H15,1) | H15: =1-(1-Skills!J15/100)^Skills!K15 | I15: 1 | O15: 0 | P15: =IF(Summary!$B$3=0,0,O15/Summary!$B$3) | Q15: =IFERROR(1/IF(Inputs!$B$4="pvp",15,MAX(0.1,Skills!D15-IF(Skills!E15=TRUE,Inputs!$B$31,0))),0) | R15: =IF(AND(Inputs!$B$4<>"pvp",Inputs!$B$35>0),(INT(Inputs!$B$35/IF(Inputs!$B$4="pvp",15,MAX(0.1,Skills!D15-IF(Skills!E15=TRUE,Inputs!$B$31,0))))+1),0) | S15: =IFERROR(O15/N15,0)
A16: =Skills!A16 | B16: =Skills!B16 | C16: =Inputs!$B$3>=45 | D16: =IF(Skills!C16=1,60+Inputs!$B$24+Inputs!$B$28,IF(Skills!C16=2,90+Inputs!$B$25+Inputs!$B$28,IF(Skills!C16=3,120+Inputs!$B$26+Inputs!$B$28,MAX(0,(Inputs!$B$3-100)*3)+Inputs!$B$27+Inputs!$B$28))) | E16: =INDEX(FactorTable!$B$2:$Y$301, MATCH(ROUND(MIN(300,MAX(1,D16)),0), FactorTable!$A$2:$A$301,0), Skills!M16+1) | F16: =IF(Skills!N16=TRUE,(Skills!L16/10)*(E16/1000),Skills!L16/10)+Skills!O16 | G16: =Skills!G16*IF(Skills!H16>0,Skills!I16/Skills!H16,1) | H16: =1-(1-Skills!J16/100)^Skills!K16 | I16: 1 | O16: 0 | P16: =IF(Summary!$B$3=0,0,O16/Summary!$B$3) | Q16: =IFERROR(1/IF(Inputs!$B$4="pvp",15,MAX(0.1,Skills!D16-IF(Skills!E16=TRUE,Inputs!$B$31,0))),0) | R16: =IF(AND(Inputs!$B$4<>"pvp",Inputs!$B$35>0),(INT(Inputs!$B$35/IF(Inputs!$B$4="pvp",15,MAX(0.1,Skills!D16-IF(Skills!E16=TRUE,Inputs!$B$31,0))))+1),0) | S16: =IFERROR(O16/N16,0)
A17: =Skills!A17 | B17: =Skills!B17 | C17: =Inputs!$B$3>=35 | D17: =IF(Skills!C17=1,60+Inputs!$B$24+Inputs!$B$28,IF(Skills!C17=2,90+Inputs!$B$25+Inputs!$B$28,IF(Skills!C17=3,120+Inputs!$B$26+Inputs!$B$28,MAX(0,(Inputs!$B$3-100)*3)+Inputs!$B$27+Inputs!$B$28))) | E17: =INDEX(FactorTable!$B$2:$Y$301, MATCH(ROUND(MIN(300,MAX(1,D17)),0), FactorTable!$A$2:$A$301,0), Skills!M17+1) | F17: =IF(Skills!N17=TRUE,(Skills!L17/10)*(E17/1000),Skills!L17/10)+Skills!O17 | G17: =Skills!G17*IF(Skills!H17>0,Skills!I17/Skills!H17,1) | H17: =1-(1-Skills!J17/100)^Skills!K17 | I17: 1 | O17: 0 | P17: =IF(Summary!$B$3=0,0,O17/Summary!$B$3) | Q17: =IFERROR(1/IF(Inputs!$B$4="pvp",15,MAX(0.1,Skills!D17-IF(Skills!E17=TRUE,Inputs!$B$31,0))),0) | R17: =IF(AND(Inputs!$B$4<>"pvp",Inputs!$B$35>0),(INT(Inputs!$B$35/IF(Inputs!$B$4="pvp",15,MAX(0.1,Skills!D17-IF(Skills!E17=TRUE,Inputs!$B$31,0))))+1),0) | S17: =IFERROR(O17/N17,0)
A18: =Skills!A18 | B18: =Skills!B18 | C18: =Inputs!$B$3>=72 | D18: =IF(Skills!C18=1,60+Inputs!$B$24+Inputs!$B$28,IF(Skills!C18=2,90+Inputs!$B$25+Inputs!$B$28,IF(Skills!C18=3,120+Inputs!$B$26+Inputs!$B$28,MAX(0,(Inputs!$B$3-100)*3)+Inputs!$B$27+Inputs!$B$28))) | E18: =INDEX(FactorTable!$B$2:$Y$301, MATCH(ROUND(MIN(300,MAX(1,D18)),0), FactorTable!$A$2:$A$301,0), Skills!M18+1) | F18: =IF(Skills!N18=TRUE,(Skills!L18/10)*(E18/1000),Skills!L18/10)+Skills!O18 | G18: =Skills!G18*IF(Skills!H18>0,Skills!I18/Skills!H18,1) | H18: =1-(1-Skills!J18/100)^Skills!K18 | I18: 1 | O18: 0 | P18: =IF(Summary!$B$3=0,0,O18/Summary!$B$3) | Q18: =IFERROR(1/IF(Inputs!$B$4="pvp",15,MAX(0.1,Skills!D18-IF(Skills!E18=TRUE,Inputs!$B$31,0))),0) | R18: =IF(AND(Inputs!$B$4<>"pvp",Inputs!$B$35>0),(INT(Inputs!$B$35/IF(Inputs!$B$4="pvp",15,MAX(0.1,Skills!D18-IF(Skills!E18=TRUE,Inputs!$B$31,0))))+1),0) | S18: =IFERROR(O18/N18,0)
A19: =Skills!A19 | B19: =Skills!B19 | C19: =Inputs!$B$3>=72 | D19: =IF(Skills!C19=1,60+Inputs!$B$24+Inputs!$B$28,IF(Skills!C19=2,90+Inputs!$B$25+Inputs!$B$28,IF(Skills!C19=3,120+Inputs!$B$26+Inputs!$B$28,MAX(0,(Inputs!$B$3-100)*3)+Inputs!$B$27+Inputs!$B$28))) | E19: =INDEX(FactorTable!$B$2:$Y$301, MATCH(ROUND(MIN(300,MAX(1,D19)),0), FactorTable!$A$2:$A$301,0), Skills!M19+1) | F19: =IF(Skills!N19=TRUE,(Skills!L19/10)*(E19/1000),Skills!L19/10)+Skills!O19 | G19: =Skills!G19*IF(Skills!H19>0,Skills!I19/Skills!H19,1) | H19: =1-(1-Skills!J19/100)^Skills!K19 | I19: 1 | O19: 0 | P19: =IF(Summary!$B$3=0,0,O19/Summary!$B$3) | Q19: =IFERROR(1/IF(Inputs!$B$4="pvp",15,MAX(0.1,Skills!D19-IF(Skills!E19=TRUE,Inputs!$B$31,0))),0) | R19: =IF(AND(Inputs!$B$4<>"pvp",Inputs!$B$35>0),(INT(Inputs!$B$35/IF(Inputs!$B$4="pvp",15,MAX(0.1,Skills!D19-IF(Skills!E19=TRUE,Inputs!$B$31,0))))+1),0) | S19: =IFERROR(O19/N19,0)
A20: =Skills!A20 | B20: =Skills!B20 | C20: =TRUE | D20: =IF(Skills!C20=1,60+Inputs!$B$24+Inputs!$B$28,IF(Skills!C20=2,90+Inputs!$B$25+Inputs!$B$28,IF(Skills!C20=3,120+Inputs!$B$26+Inputs!$B$28,MAX(0,(Inputs!$B$3-100)*3)+Inputs!$B$27+Inputs!$B$28))) | E20: =INDEX(FactorTable!$B$2:$Y$301, MATCH(ROUND(MIN(300,MAX(1,D20)),0), FactorTable!$A$2:$A$301,0), Skills!M20+1) | F20: =IF(Skills!N20=TRUE,(Skills!L20/10)*(E20/1000),Skills!L20/10)+Skills!O20 | G20: =Skills!G20*IF(Skills!H20>0,Skills!I20/Skills!H20,1) | H20: =1-(1-Skills!J20/100)^Skills!K20 | I20: 1 | O20: 0 | P20: =IF(Summary!$B$3=0,0,O20/Summary!$B$3) | Q20: =IFERROR(1/IF(Inputs!$B$4="pvp",15,MAX(0.1,Skills!D20-IF(Skills!E20=TRUE,Inputs!$B$31,0))),0) | R20: =IF(AND(Inputs!$B$4<>"pvp",Inputs!$B$35>0),(INT(Inputs!$B$35/IF(Inputs!$B$4="pvp",15,MAX(0.1,Skills!D20-IF(Skills!E20=TRUE,Inputs!$B$31,0))))+1),0) | S20: =IFERROR(O20/N20,0)
A21: =Skills!A21 | B21: =Skills!B21 | C21: =Inputs!$B$3>=33 | D21: =IF(Skills!C21=1,60+Inputs!$B$24+Inputs!$B$28,IF(Skills!C21=2,90+Inputs!$B$25+Inputs!$B$28,IF(Skills!C21=3,120+Inputs!$B$26+Inputs!$B$28,MAX(0,(Inputs!$B$3-100)*3)+Inputs!$B$27+Inputs!$B$28))) | E21: =INDEX(FactorTable!$B$2:$Y$301, MATCH(ROUND(MIN(300,MAX(1,D21)),0), FactorTable!$A$2:$A$301,0), Skills!M21+1) | F21: =IF(Skills!N21=TRUE,(Skills!L21/10)*(E21/1000),Skills!L21/10)+Skills!O21 | G21: =Skills!G21*IF(Skills!H21>0,Skills!I21/Skills!H21,1) | H21: =1-(1-Skills!J21/100)^Skills!K21 | I21: 1 | O21: 0 | P21: =IF(Summary!$B$3=0,0,O21/Summary!$B$3) | Q21: 0 | R21: 0 | S21: =IFERROR(O21/N21,0)
A22: =Skills!A22 | B22: =Skills!B22 | C22: =Inputs!$B$3>=43 | D22: =IF(Skills!C22=1,60+Inputs!$B$24+Inputs!$B$28,IF(Skills!C22=2,90+Inputs!$B$25+Inputs!$B$28,IF(Skills!C22=3,120+Inputs!$B$26+Inputs!$B$28,MAX(0,(Inputs!$B$3-100)*3)+Inputs!$B$27+Inputs!$B$28))) | E22: =INDEX(FactorTable!$B$2:$Y$301, MATCH(ROUND(MIN(300,MAX(1,D22)),0), FactorTable!$A$2:$A$301,0), Skills!M22+1) | F22: =IF(Skills!N22=TRUE,(Skills!L22/10)*(E22/1000),Skills!L22/10)+Skills!O22 | G22: =Skills!G22*IF(Skills!H22>0,Skills!I22/Skills!H22,1) | H22: =1-(1-Skills!J22/100)^Skills!K22 | I22: 1 | O22: 0 | P22: =IF(Summary!$B$3=0,0,O22/Summary!$B$3) | Q22: 0 | R22: 0 | S22: =IFERROR(O22/N22,0)
A23: =Skills!A23 | B23: =Skills!B23 | C23: =Inputs!$B$3>=120 | D23: =IF(Skills!C23=1,60+Inputs!$B$24+Inputs!$B$28,IF(Skills!C23=2,90+Inputs!$B$25+Inputs!$B$28,IF(Skills!C23=3,120+Inputs!$B$26+Inputs!$B$28,MAX(0,(Inputs!$B$3-100)*3)+Inputs!$B$27+Inputs!$B$28))) | E23: =INDEX(FactorTable!$B$2:$Y$301, MATCH(ROUND(MIN(300,MAX(1,D23)),0), FactorTable!$A$2:$A$301,0), Skills!M23+1) | F23: =IF(Skills!N23=TRUE,(Skills!L23/10)*(E23/1000),Skills!L23/10)+Skills!O23 | G23: =Skills!G23*IF(Skills!H23>0,Skills!I23/Skills!H23,1) | H23: =1-(1-Skills!J23/100)^Skills!K23 | I23: 1 | O23: 0 | P23: =IF(Summary!$B$3=0,0,O23/Summary!$B$3) | Q23: 0 | R23: 0 | S23: =IFERROR(O23/N23,0)
A24: =Skills!A24 | B24: =Skills!B24 | C24: =Inputs!$B$3>=120 | D24: =IF(Skills!C24=1,60+Inputs!$B$24+Inputs!$B$28,IF(Skills!C24=2,90+Inputs!$B$25+Inputs!$B$28,IF(Skills!C24=3,120+Inputs!$B$26+Inputs!$B$28,MAX(0,(Inputs!$B$3-100)*3)+Inputs!$B$27+Inputs!$B$28))) | E24: =INDEX(FactorTable!$B$2:$Y$301, MATCH(ROUND(MIN(300,MAX(1,D24)),0), FactorTable!$A$2:$A$301,0), Skills!M24+1) | F24: =IF(Skills!N24=TRUE,(Skills!L24/10)*(E24/1000),Skills!L24/10)+Skills!O24 | G24: =Skills!G24*IF(Skills!H24>0,Skills!I24/Skills!H24,1) | H24: =1-(1-Skills!J24/100)^Skills!K24 | I24: 1 | O24: 0 | P24: =IF(Summary!$B$3=0,0,O24/Summary!$B$3) | Q24: 0 | R24: 0 | S24: =IFERROR(O24/N24,0)
A25: =Skills!A25 | B25: =Skills!B25 | C25: =Inputs!$B$3>=125 | D25: =IF(Skills!C25=1,60+Inputs!$B$24+Inputs!$B$28,IF(Skills!C25=2,90+Inputs!$B$25+Inputs!$B$28,IF(Skills!C25=3,120+Inputs!$B$26+Inputs!$B$28,MAX(0,(Inputs!$B$3-100)*3)+Inputs!$B$27+Inputs!$B$28))) | E25: =INDEX(FactorTable!$B$2:$Y$301, MATCH(ROUND(MIN(300,MAX(1,D25)),0), FactorTable!$A$2:$A$301,0), Skills!M25+1) | F25: =IF(Skills!N25=TRUE,(Skills!L25/10)*(E25/1000),Skills!L25/10)+Skills!O25 | G25: =Skills!G25*IF(Skills!H25>0,Skills!I25/Skills!H25,1) | H25: =1-(1-Skills!J25/100)^Skills!K25 | I25: 1 | O25: 0 | P25: =IF(Summary!$B$3=0,0,O25/Summary!$B$3) | Q25: 0 | R25: 0 | S25: =IFERROR(O25/N25,0)
A26: =Skills!A26 | B26: =Skills!B26 | C26: =Inputs!$B$3>=107 | D26: =IF(Skills!C26=1,60+Inputs!$B$24+Inputs!$B$28,IF(Skills!C26=2,90+Inputs!$B$25+Inputs!$B$28,IF(Skills!C26=3,120+Inputs!$B$26+Inputs!$B$28,MAX(0,(Inputs!$B$3-100)*3)+Inputs!$B$27+Inputs!$B$28))) | E26: =INDEX(FactorTable!$B$2:$Y$301, MATCH(ROUND(MIN(300,MAX(1,D26)),0), FactorTable!$A$2:$A$301,0), Skills!M26+1) | F26: =IF(Skills!N26=TRUE,(Skills!L26/10)*(E26/1000),Skills!L26/10)+Skills!O26 | G26: =Skills!G26*IF(Skills!H26>0,Skills!I26/Skills!H26,1) | H26: =1-(1-Skills!J26/100)^Skills!K26 | I26: 1 | O26: 0 | P26: =IF(Summary!$B$3=0,0,O26/Summary!$B$3) | Q26: 0 | R26: 0 | S26: =IFERROR(O26/N26,0)

Sheet Summary
A1: Dark Knight — DPS Summary
A3: TOTAL DPS | B3: =SUM(Calc!O2:O26)
A5: Per-Skill DPS Breakdown
A6: Skill | B6: DPS | C6: % of Total
A7: =Calc!B2 | B7: =Calc!O2 | C7: =Calc!P2*100
A8: =Calc!B5 | B8: =Calc!O5 | C8: =Calc!P5*100
A9: =Calc!B6 | B9: =Calc!O6 | C9: =Calc!P6*100
A10: =Calc!B7 | B10: =Calc!O7 | C10: =Calc!P7*100
A11: =Calc!B9 | B11: =Calc!O9 | C11: =Calc!P9*100
A12: =Calc!B10 | B12: =Calc!O10 | C12: =Calc!P10*100
A13: =Calc!B12 | B13: =Calc!O12 | C13: =Calc!P12*100
A14: Marginal DPS & Stat Value (see Sensitivity for full detail)
A16: Stat | B16: DPS per +1 | C16: Units per +1% DPS
A17: =Sensitivity!A5 | B17: =Sensitivity!H5 | C17: =Sensitivity!B5
A18: =Sensitivity!A6 | B18: =Sensitivity!H6 | C18: =Sensitivity!B6
A19: =Sensitivity!A7 | B19: =Sensitivity!H7 | C19: =Sensitivity!B7
A20: =Sensitivity!A8 | B20: =Sensitivity!H8 | C20: =Sensitivity!B8
A21: =Sensitivity!A9 | B21: =Sensitivity!H9 | C21: =Sensitivity!B9
A22: =Sensitivity!A10 | B22: =Sensitivity!H10 | C22: =Sensitivity!B10
A23: =Sensitivity!A11 | B23: =Sensitivity!H11 | C23: =Sensitivity!B11
A24: =Sensitivity!A12 | B24: =Sensitivity!H12 | C24: =Sensitivity!B12
A25: =Sensitivity!A13 | B25: =Sensitivity!H13 | C25: =Sensitivity!B13
A26: =Sensitivity!A14 | B26: =Sensitivity!H14 | C26: =Sensitivity!B14
A27: =Sensitivity!A15 | B27: =Sensitivity!H15 | C27: =Sensitivity!B15
A28: =Sensitivity!A16 | B28: =Sensitivity!H16 | C28: =Sensitivity!B16
... A42: =Sensitivity!A30 | B42: =Sensitivity!H30 | C42: =Sensitivity!B30
A49: Derived Values (read-only, computed from Inputs)
A50: ATTACK (= Flat ATTACK x (1+ATTACK%/100)) | B50: =Inputs!$B$5*(1+Inputs!$B$6/100)
A51: STAT_DAMAGE % (= 1% of total STR + 0.25% of DEX) | B51: =(Inputs!$B$11*(1+Inputs!$B$12/100))*0.01+Inputs!$B$13*0.0025
A52: Basic Attack (Dark Impale) Input Level (4th job formula) | B52: =MAX(0,(Inputs!$B$3-100)*3)+Inputs!$B$27+Inputs!$B$28
A53: Basic Attack Factor (factorIndex 21, universal 4th-job basic attack) | B53: =INDEX(FactorTable!$B$2:$Y$301, MATCH(ROUND(MIN(300,MAX(1,Summary!$B$52)),0), FactorTable!$A$2:$A$301,0), 22)
A54: SKILL_COEFFICIENT — Dark Impale base coefficient % (before bonuses) | B54: =290*Summary!$B$53/1000
A55: Normal-Monster Weight (= 0 for boss, 1 for normal, Breakthrough Normal Weight % for breakthrough, 0 for pvp) | B55: =IF(Inputs!$B$4="normal",1,IF(Inputs!$B$4="breakthrough",Inputs!$B$36/100,0))
A57: Attack%% Bucket Multiplier (Hex of the Evil Eye + Dark Resonance + Cross Over Chains + Hyper Body, summed additively) | B57: =1+(((Calc!C13=TRUE)*Calc!F13*IF(AND(Inputs!$B$4<>"pvp",Inputs!$B$35>0),(((Calc!R13-1)*(Skills!T13*(1+Inputs!$B$33/100))+MIN((Skills!T13*(1+Inputs!$B$33/100)),MAX(0,Inputs!$B$35-((Calc!R13-1)*Skills!D13))))/Inputs!$B$35),IF(Inputs!$B$4="pvp",MIN((Skills!T13*(1+Inputs!$B$33/100)),15)/15,(Skills!T13*(1+Inputs!$B$33/100))/Skills!D13)))+((Calc!C14=TRUE)*Calc!F14*IF(AND(Inputs!$B$4<>"pvp",Inputs!$B$35>0),(((Calc!R14-1)*(Skills!T14*(1+Inputs!$B$33/100))+MIN((Skills!T14*(1+Inputs!$B$33/100)),MAX(0,Inputs!$B$35-((Calc!R14-1)*Skills!D14))))/Inputs!$B$35),IF(Inputs!$B$4="pvp",MIN((Skills!T14*(1+Inputs!$B$33/100)),15)/15,(Skills!T14*(1+Inputs!$B$33/100))/Skills!D14)))+((Calc!C15=TRUE)*Calc!F15*IF(AND(Inputs!$B$4<>"pvp",Inputs!$B$35>0),(((Calc!R15-1)*(Skills!T15*(1+Inputs!$B$33/100))+MIN((Skills!T15*(1+Inputs!$B$33/100)),MAX(0,Inputs!$B$35-((Calc!R15-1)*Skills!D15))))/Inputs!$B$35),IF(Inputs!$B$4="pvp",MIN((Skills!T15*(1+Inputs!$B$33/100)),15)/15,(Skills!T15*(1+Inputs!$B$33/100))/Skills!D15)))+((Calc!C16=TRUE)*Calc!F16*IF(AND(Inputs!$B$4<>"pvp",Inputs!$B$35>0),(((Calc!R16-1)*(Skills!T16*(1+Inputs!$B$33/100))+MIN((Skills!T16*(1+Inputs!$B$33/100)),MAX(0,Inputs!$B$35-((Calc!R16-1)*Skills!D16))))/Inputs!$B$35),IF(Inputs!$B$4="pvp",MIN((Skills!T16*(1+Inputs!$B$33/100)),15)/15,(Skills!T16*(1+Inputs!$B$33/100))/Skills!D16))))/100
A58: Global Crit Rate Bonus % (Lord of Darkness, proc-chance x duty-cycle) | B58: =((Calc!C18=TRUE)*Calc!F18*(Skills!J18/100)*IF(AND(Inputs!$B$4<>"pvp",Inputs!$B$35>0),(((Calc!R18-1)*(Skills!T18*(1+Inputs!$B$33/100))+MIN((Skills!T18*(1+Inputs!$B$33/100)),MAX(0,Inputs!$B$35-((Calc!R18-1)*Skills!D18))))/Inputs!$B$35),IF(Inputs!$B$4="pvp",MIN((Skills!T18*(1+Inputs!$B$33/100)),15)/15,(Skills!T18*(1+Inputs!$B$33/100))/Skills!D18)))
A59: Global Monster Damage-Taken Bonus % (Evil Eye, all types + Dark Resonance, boss-only) | B59: =((Calc!C17=TRUE)*Calc!F17*IF(AND(Inputs!$B$4<>"pvp",Inputs!$B$35>0),(((Calc!R17-1)*(Skills!T17*(1+Inputs!$B$33/100))+MIN((Skills!T17*(1+Inputs!$B$33/100)),MAX(0,Inputs!$B$35-((Calc!R17-1)*Skills!D17))))/Inputs!$B$35),IF(Inputs!$B$4="pvp",MIN((Skills!T17*(1+Inputs!$B$33/100)),15)/15,(Skills!T17*(1+Inputs!$B$33/100))/Skills!D17)))+((Calc!C14=TRUE)*IF(Inputs!$B$4="pvp",20,(1-Summary!$B$55)*(20)+Summary!$B$55*(0))*IF(AND(Inputs!$B$4<>"pvp",Inputs!$B$35>0),(((Calc!R14-1)*(Skills!T14*(1+Inputs!$B$33/100))+MIN((Skills!T14*(1+Inputs!$B$33/100)),MAX(0,Inputs!$B$35-((Calc!R14-1)*Skills!D14))))/Inputs!$B$35),IF(Inputs!$B$4="pvp",MIN((Skills!T14*(1+Inputs!$B$33/100)),15)/15,(Skills!T14*(1+Inputs!$B$33/100))/Skills!D14)))
A60: Attack Speed Buff Bonus % (Nimble Feet, duty-cycle averaged) | B60: =((Calc!C20=TRUE)*Calc!F20*IF(AND(Inputs!$B$4<>"pvp",Inputs!$B$35>0),(((Calc!R20-1)*(Skills!T20*(1+Inputs!$B$33/100))+MIN((Skills!T20*(1+Inputs!$B$33/100)),MAX(0,Inputs!$B$35-((Calc!R20-1)*Skills!D20))))/Inputs!$B$35),IF(Inputs!$B$4="pvp",MIN((Skills!T20*(1+Inputs!$B$33/100)),15)/15,(Skills!T20*(1+Inputs!$B$33/100))/Skills!D20)))
A61: Actions Per Second | B61: =1+MIN(150,150*(1-(1-Inputs!$B$10/150)*(1-B60/150)))/100
