Workbook

Sheet README
A1: Fire/Poison Arch Mage — DPS Calculator: How to Use This Workbook
A3: How to use this workbook
A4: Only edit the yellow-highlighted cells on the Inputs sheet — every other sheet is computed from those values and will be overwritten if you rebuild the workbook.
A5: Summary shows Total DPS, a Per-Skill DPS Breakdown (damage-dealing skills only — buffs/passives that never deal their own damage are omitted), and a Marginal DPS & Stat Value table showing the DPS gained per +1 of each stat.
A6: Sensitivity has the full detail behind that marginal-value table — one self-contained block per stat, showing exactly how bumping that stat by +1 changes every downstream number.
A7: CubeData/PotentialCubes model your current gear's Potential Cube lines and drive cube-reroll expected-value decisions. For the full standalone Potential Cube EV calculator (exact optimal-stopping math, works from this workbook alone), see tools/potential_cubes_ev.py in the project repo.
A9: Design decisions & assumptions
A10: Poison/DoT skills (Poison Breath, Poison Mist, Creeping Toxin, Ignite) and Burning Magic/Elemental Decrease assume the target is permanently afflicted at steady state, not an exact on/off timer.
A11: Crit Rate pushed above 100% (e.g. by cube potential lines) automatically redirects its stat-value to Crit Damage's own per-unit DPS value on the PotentialCubes sheet, since excess Crit Rate cannot do anything past 100%.
A12: Buffs (Meditation, Magic Guard, Infinity, Nimble Feet) are modeled at steady-state duty-cycle average uptime, not as an exact moment-to-moment state machine.
A13: Meteor Proc's trigger rate is the combined cast rate of every attack that can trigger it (including Basic Attack), averaged rather than simulated hit-by-hit.
A14: Ifrit is a summon skill (own cooldown/duration/DoT-tick mechanism), not part of the game's separate Companion roster system — its damage is modeled as a real DPS source like any other skill.
... A16: Not modeled (out of scope): crowd control, Accuracy/Evasion/Defense reduction, movement speed, the character's own Defense stat, and Companion Summoning Time (the Companion roster system, unrelated to Ifrit).

Sheet Inputs
A1: Fire/Poison Arch Mage — DPS Calculator Inputs
A3: Character Level | B3: 114
A4: Monster Type ("boss", "normal", "breakthrough", or "pvp") | B4: breakthrough
A5: Flat ATTACK | B5: 901891
A6: ATTACK % | B6: 27600.8
A7: Monster Defense (flat, post-x100/x10 scaling) | B7: 3500
A8: CRIT_RATE % | B8: 107
A9: CRIT_DAMAGE % | B9: 319.1
A10: ATTACK_SPEED % (base, excludes Nimble Feet) | B10: 61.5
A11: Flat INT | B11: 58007
A12: INT % | B12: 229.4
A13: LUK | B13: 708
A14: DAMAGE % | B14: 929
A15: DAMAGE_AMP % | B15: 66.8
A16: BASIC_ATTACK_DAMAGE % | B16: 45.6
... A28: Skill Level Bonus — All Skills | B28: 55
A30: Additional Bonuses
A31: Skill Cooldown Decrease (seconds, only skills/buffs the character actively casts) | B31: 0
A32: Basic Attack Target Increase (flat, adds to the 6-target normal-monster base) | B32: 6
A33: Buff Duration Increase % | B33: 0
A34: Companion Summoning Time Increase % (companions not modeled — always 0 DPS impact) | B34: 0
A35: Fixed Fight Duration (seconds, boss or normal — leave 0 for steady-state DPS; ignored for pvp, which already uses its own fixed 15s model) | B35: 0
A36: Chapter Breakthrough: Normal-Monster Weight % (only used when Monster Type = breakthrough; rest of the weight is boss) | B36: 60
A37: Max Enemies Actually In Range (normal monsters only — caps each skill's theoretical AoE target count; default 999 = uncapped) | B37: 999

Sheet FactorTable
A1: Level | B1: F0 | C1: F1 | D1: F2 | E1: F3 | F1: F4 | G1: F5 | H1: F6 | I1: F7 | J1: F8 | K1: F9 | L1: F10 | M1: F11 | N1: F12 | O1: F13 | P1: F14 | Q1: F15 | R1: F16 | S1: F17 | T1: F18 | U1: F19 | V1: F20 | W1: F21 | X1: F22 | Y1: F23
A2: 1 | B2: 0 | C2: 1000 | D2: 1000 | E2: 1000 | F2: 1000 | G2: 1000 | H2: 1000 | I2: 1000 | J2: 1000 | K2: 1000 | L2: 1000 | M2: 1000 | N2: 1000 | O2: 1000 | P2: 1000 | Q2: 1000 | R2: 1000 | S2: 1000 | T2: 1000 | U2: 1000 | V2: 1000 | W2: 1000 | X2: 1000 | Y2: 1000
A3: 2 | B3: 0 | C3: 1015 | D3: 1020 | E3: 1030 | F3: 1040 | G3: 1050 | H3: 1060 | I3: 1070 | J3: 1020 | K3: 1020 | L3: 1020 | M3: 1000 | N3: 1010 | O3: 1020 | P3: 1030 | Q3: 1040 | R3: 1050 | S3: 1060 | T3: 1070 | U3: 1080 | V3: 1010 | W3: 1008 | X3: 1006 | Y3: 1100
A4: 3 | B4: 0 | C4: 1031 | D4: 1041 | E4: 1061 | F4: 1082 | G4: 1103 | H4: 1124 | I4: 1145 | J4: 1030 | K4: 1041 | L4: 1030 | M4: 1000 | N4: 1015 | O4: 1030 | P4: 1045 | Q4: 1060 | R4: 1075 | S4: 1090 | T4: 1105 | U4: 1120 | V4: 1020 | W4: 1012 | X4: 1009 | Y4: 1150
A5: 4 | B5: 0 | C5: 1047 | D5: 1062 | E5: 1093 | F5: 1126 | G5: 1159 | H5: 1192 | I5: 1226 | J5: 1040 | K5: 1062 | L5: 1040 | M5: 1000 | N5: 1020 | O5: 1040 | P5: 1060 | Q5: 1080 | R5: 1100 | S5: 1120 | T5: 1140 | U5: 1160 | V5: 1030 | W5: 1016 | X5: 1012 | Y5: 1200
A6: 5 | B6: 0 | C6: 1063 | D6: 1084 | E6: 1126 | F6: 1172 | G6: 1217 | H6: 1264 | I6: 1312 | J6: 1050 | K6: 1084 | L6: 1050 | M6: 1000 | N6: 1025 | O6: 1050 | P6: 1075 | Q6: 1100 | R6: 1125 | S6: 1150 | T6: 1175 | U6: 1200 | V6: 1040 | W6: 1020 | X6: 1015 | Y6: 1250
A7: 6 | B7: 0 | C7: 1079 | D7: 1106 | E7: 1160 | F7: 1219 | G7: 1278 | H7: 1340 | I7: 1404 | J7: 1060 | K7: 1106 | L7: 1060 | M7: 1000 | N7: 1030 | O7: 1060 | P7: 1090 | Q7: 1120 | R7: 1150 | S7: 1180 | T7: 1210 | U7: 1240 | V7: 1050 | W7: 1024 | X7: 1018 | Y7: 1300
A8: 7 | B8: 0 | C8: 1096 | D8: 1129 | E8: 1195 | F8: 1268 | G8: 1342 | H8: 1421 | I8: 1503 | J8: 1070 | K8: 1129 | L8: 1070 | M8: 1000 | N8: 1035 | O8: 1070 | P8: 1105 | Q8: 1140 | R8: 1175 | S8: 1210 | T8: 1245 | U8: 1280 | V8: 1060 | W8: 1028 | X8: 1021 | Y8: 1350
A9: 8 | B9: 0 | C9: 1113 | D9: 1152 | E9: 1231 | F9: 1319 | G9: 1410 | H9: 1507 | I9: 1609 | J9: 1080 | K9: 1152 | L9: 1080 | M9: 1000 | N9: 1040 | O9: 1080 | P9: 1120 | Q9: 1160 | R9: 1200 | S9: 1240 | T9: 1280 | U9: 1320 | V9: 1070 | W9: 1032 | X9: 1024 | Y9: 1400
A10: 9 | B10: 0 | C10: 1130 | D10: 1176 | E10: 1268 | F10: 1372 | G10: 1481 | H10: 1598 | I10: 1722 | J10: 1090 | K10: 1176 | L10: 1090 | M10: 1000 | N10: 1045 | O10: 1090 | P10: 1135 | Q10: 1180 | R10: 1225 | S10: 1270 | T10: 1315 | U10: 1360 | V10: 1080 | W10: 1036 | X10: 1027 | Y10: 1450
A11: 10 | B11: 0 | C11: 1147 | D11: 1200 | E11: 1307 | F11: 1427 | G11: 1556 | H11: 1694 | I11: 1843 | J11: 1100 | K11: 1200 | L11: 1100 | M11: 1000 | N11: 1050 | O11: 1100 | P11: 1150 | Q11: 1200 | R11: 1250 | S11: 1300 | T11: 1350 | U11: 1400 | V11: 1090 | W11: 1040 | X11: 1030 | Y11: 1500
A12: 11 | B12: 0 | C12: 1165 | D12: 1224 | E12: 1347 | F12: 1485 | G12: 1634 | H12: 1796 | I12: 1973 | J12: 1110 | K12: 1224 | L12: 1110 | M12: 1000 | N12: 1055 | O12: 1110 | P12: 1165 | Q12: 1220 | R12: 1275 | S12: 1330 | T12: 1385 | U12: 1440 | V12: 1100 | W12: 1044 | X12: 1033 | Y12: 1550
A13: 12 | B13: 0 | C13: 1183 | D13: 1249 | E13: 1388 | F13: 1545 | G13: 1716 | H13: 1904 | I13: 2112 | J13: 1120 | K13: 1249 | L13: 1120 | M13: 1000 | N13: 1060 | O13: 1120 | P13: 1180 | Q13: 1240 | R13: 1300 | S13: 1360 | T13: 1420 | U13: 1480 | V13: 1110 | W13: 1048 | X13: 1036 | Y13: 1600
... A301: 300 | B301: 0 | C301: 88573 | D301: 381637 | E301: 6991522 | F301: 125363453 | G301: 2185120762 | H301: 37157073039 | I301: 614631863830 | J301: 2000 | K301: 53326 | L301: 2500 | M301: 1100 | N301: 2500 | O301: 4000 | P301: 5500 | Q301: 7000 | R301: 8500 | S301: 10000 | T301: 11500 | U301: 13000 | V301: 7558 | W301: 2200 | X301: 1900 | Y301: 8800

Sheet Skills
A1: Key | B1: Name | C1: JobStep | D1: Element | E1: Cooldown(s) | F1: CostsActionSlot | G1: HitsPerCast | H1: ICD(s) | I1: ActiveWindow(s) | J1: ProcChance% | K1: RollsPerCast | L1: BaseDamage(tenths%) | M1: FactorIndex | N1: ScalesWithLevel | O1: SkillMasteryBonus% | P1: MasteryBossDamage% | Q1: MasteryNormalDamage% | R1: NormalMonsterTargets | S1: BuffTargetStat | T1: BuffDuration(s) | U1: TriggersElementalDecrease | V1: TriggersMeteorProc | W1: MeteorProcTriggersPerCast | X1: MapleHeroBase(tenths%) | Y1: MapleHeroFactorIndex | Z1: Stacks | AA1: Note
A2: BASIC_ATTACK | B2: Basic Attack | C2: 4 | D2: Fire | F2: FALSE | G2: 5 | H2: 0 | I2: 0 | J2: 100 | K2: 1 | N2: TRUE | O2: =SUMPRODUCT((Inputs!$B$3>={102,106,116,120,128,132})*{10,11,12,13,14,15}) -> 21 | P2: =SUMPRODUCT((Inputs!$B$3>={111,124})*{10,10}) -> 10 | Q2: 0 | R2: =6+Inputs!$B$32+IF(Inputs!$B$3>=136,1,0) -> 12 | T2: 0 | U2: FALSE | V2: FALSE | W2: 1 | AA2: 5 lines of damage per attack cycle — 5 independent full-damage hits (HitsPerCast=5), each using the same expected-damage-per-hit; no cooldown, DPS uses Basic Attacks/sec from the action-economy block. Basic Attack Mastery (level-gated sum: +10@102, +11@106, +12@116, +13@120, +14@128, +15@132 — 75% total once every tier is unlocked) and Boss Mastery (level-gated sum: +10@111, +10@124 — 20% total) are just this row's SkillMasteryBonus%/MasteryBossDamage% — same mechanism as every other skill, no separate Inputs-sheet fields. Basic Attack's own cast rate (Summary!Basic Attacks Per Second) is always added into the Meteor Proc trigger rate directly, so it does not need TriggersMeteorProc=TRUE here. Hits 6+Basic Attack Target Increase targets vs normal monsters (confirmed by the user), +1 more once Flame Sweep Strike Count is unlocked at level 136.
A3: IGNITE | B3: Ignite | C3: 2 | E3: 1 | F3: FALSE | G3: 3 | H3: 0 | I3: 0 | J3: 100 | K3: 1 | L3: 130 | M3: 21 | N3: TRUE | O3: 100 | P3: 0 | Q3: 0 | R3: 3 | T3: 0 | U3: FALSE | V3: FALSE | W3: 1 | X3: 500 | Y3: 23 | AA3: 3 walls of fire assumed permanently maintained (max instances). +250% vs Normal Monster not modeled. Skill Mastery: +100% added directly to the coefficient%. Hits 3 targets vs normal monsters.
A4: POISON_BREATH | B4: Poison Breath | C4: 2 | D4: Poison | E4: 18 | F4: TRUE | G4: 3 | H4: 0 | I4: 0 | J4: 100 | K4: 1 | L4: 2000 | M4: 12 | N4: TRUE | O4: 70 | P4: 0 | Q4: 0 | R4: 6 | T4: 0 | U4: TRUE | V4: TRUE | W4: 1 | X4: 800 | Y4: 23 | AA4: Skill Mastery: +70% added directly to the coefficient%. Hits 6 targets vs normal monsters.
A5: ELEMENTAL_DRAIN | B5: Elemental Drain | C5: 2 | E5: 1 | F5: FALSE | G5: 5 | H5: 0 | I5: 0 | J5: 100 | K5: 1 | L5: 120 | M5: 21 | N5: TRUE | O5: 0 | P5: 0 | Q5: 0 | R5: 1 | T5: 0 | U5: FALSE | V5: FALSE | W5: 1 | X5: 1500 | Y5: 23 | AA5: Poison assumed permanently at 5 stacks (max instances).
A6: MEDITATION | B6: Meditation | C6: 2 | E6: 30 | F6: TRUE | G6: 1 | H6: 0 | I6: 0 | J6: 100 | K6: 1 | L6: 200 | M6: 22 | N6: TRUE | O6: 0 | P6: 0 | Q6: 0 | R6: 1 | S6: ATTACK | T6: 19.5 | U6: FALSE | V6: FALSE | W6: 1 | AA6: Buff — averaged Attack% = BaseDamage/10 * Factor/1000 * Duration/Cooldown.
A7: POISON_MIST_BURST | B7: Poison Mist (burst) | C7: 3 | D7: Poison | E7: 24.5 | F7: TRUE | G7: 3 | H7: 0 | I7: 0 | J7: 100 | K7: 1 | L7: 1600 | M7: 12 | N7: TRUE | O7: 50 | P7: 0 | Q7: 0 | R7: 10 | T7: 0 | U7: TRUE | V7: TRUE | W7: 1 | X7: 100 | Y7: 23 | AA7: Skill Mastery: +50% added directly to the coefficient%. (Does not apply to the fog DoT — see that row.) Hits 10 targets vs normal monsters.
A8: POISON_MIST_DOT | B8: Poison Mist (fog DoT) | C8: 3 | D8: Poison | E8: 24.5 | F8: FALSE | G8: 1 | H8: =IF(Inputs!$B$3>=104,0.4,0.8) -> 0.4 | I8: 20 | J8: 100 | K8: 1 | L8: 700 | M8: 12 | N8: TRUE | O8: 0 | P8: 0 | Q8: 0 | R8: 10 | T8: 0 | U8: FALSE | V8: FALSE | W8: 1 | X8: 100 | Y8: 23 | AA8: EffectiveHits = 1 * (ActiveWindow/ICD) = duration/tick-interval ticks per cast. Skill Mastery's +50% damage bonus does NOT apply to the fog DoT, only the burst — SkillMasteryBonus% intentionally left at 0 here. Hits 10 targets vs normal monsters, same as the burst. Tick interval is 0.8s below level 104, 0.4s once the level-104 mastery is unlocked.
A9: MIST_ERUPTION | B9: Mist Eruption | C9: 4 | E9: =Skills!E7 -> 24.5 | F9: FALSE | G9: =IF(Inputs!$B$4="pvp",0,(1-Summary!$B$56)*(1)+Summary!$B$56*(IF(Inputs!$B$3>=108,4,3))) -> 2.8 | H9: 0 | I9: 0 | J9: 100 | K9: 1 | L9: 30000 | M9: 12 | N9: TRUE | O9: =IF(Inputs!$B$3>=122,100,0) -> 0 | P9: 0 | Q9: 0 | R9: 10 | T9: 0 | U9: FALSE | V9: FALSE | W9: 1 | AA9: A skill of its own — only related to Poison Mist in that it's triggered while the fog is active, so it fires at the same rate as Poison Mist's own cast (Cooldown mirrors Skills!Poison Mist (burst) row's Cooldown live). Vs boss: 1 explosion per Poison Mist cast (when the fog expires, since bosses don't die mid-fog). Vs normal monster: 3 explosions per cast (base), +1 (4 total) once the level-108 mastery is unlocked, hitting 10 targets each. Vs Chapter Breakthrough: weighted average of the boss and normal counts by Inputs!normal_weight_frac. Vs PvP: 0 — it only triggers when the fog naturally expires at the end of its full duration, which never happens within the 15s PvP fight (confirmed by the user). Not affected by Poison Mist's Skill Mastery or Maple Hero bonus (confirmed by the user) — it's jobStep 4, using its own 4th-job skill level, same factorIndex 12. Its own SkillMasteryBonus% is the level-122 mastery (+100% damage), unrelated to Poison Mist's.
A10: CREEPING_TOXIN | B10: Creeping Toxin | C10: 3 | D10: Poison | E10: 27 | F10: TRUE | G10: 2 | H10: 2 | I10: 15 | J10: 100 | K10: 1 | L10: 1200 | M10: 12 | N10: TRUE | O10: 50 | P10: 0 | Q10: 100 | R10: 1 | T10: 0 | U10: TRUE | V10: FALSE | W10: 1 | X10: 100 | Y10: 23 | AA10: Assumes a qualifying Fire-element hit is always available within the 2s ICD window. Skill Mastery: +50% added directly to the coefficient%, plus +100% Normal Monster Damage mastery. Deliberately excluded from Meteor Proc's trigger set (confirmed by the user).
A11: BURNING_MAGIC | B11: Burning Magic | C11: 3 | F11: FALSE | G11: 1 | H11: 0 | I11: 0 | J11: 100 | K11: 1 | L11: 50 | M11: 0 | N11: FALSE | O11: 0 | P11: 0 | Q11: 0 | R11: 1 | T11: 0 | U11: FALSE | V11: FALSE | W11: 1 | Z11: 5 | AA11: Global always-on multiplier: 1 + (BaseDamage/10 * Stacks)/100. Does not scale with level.
A12: ELEMENTAL_DECREASE | B12: Elemental Decrease | C12: 3 | F12: FALSE | G12: 1 | H12: 0 | I12: 0 | J12: 50 | K12: 1 | L12: 120 | M12: 22 | N12: TRUE | O12: 0 | P12: 0 | Q12: 0 | R12: 1 | T12: 7 | U12: FALSE | V12: FALSE | W12: 1 | AA12: Modeled as always-on (flat multiplier, like Burning Magic): at 50% chance per qualifying hit and a 7s duration, it gets reapplied well before it expires, so uptime is treated as 100% (confirmed by the user). ProcChance%/BuffDuration(s) are the real skill values for reference only — they no longer feed the Summary-sheet formula.
A13: METEOR_SHOWER_BURST | B13: Meteor Shower (burst) | C13: 4 | D13: Fire | E13: 33 | F13: TRUE | G13: 9 | H13: 0 | I13: 0 | J13: 100 | K13: 1 | L13: 6000 | M13: 12 | N13: TRUE | O13: =IF(Inputs!$B$3>=134,50,0) -> 0 | P13: 0 | Q13: 0 | R13: 7 | T13: 0 | U13: TRUE | V13: TRUE | W13: 3 | AA13: 3 meteorites x 3 hits collapsed into one 9-hit burst. Hits 7 targets vs normal monsters. MeteorProcTriggersPerCast=3 (not 1) — each of the 3 meteors is an independent Meteor Proc trigger opportunity even though all 3 land from a single cast (confirmed by the user). Skill Mastery: +50% damage once the level-134 mastery is unlocked.
A14: METEOR_PROC | B14: Meteor Proc (30% on-hit, 1s ICD) | C14: 4 | D14: Fire | F14: FALSE | G14: 1 | H14: 1 | I14: 0 | J14: 30 | K14: 1 | L14: 9500 | M14: 21 | N14: TRUE | O14: 0 | P14: 0 | Q14: 0 | R14: 1 | T14: 0 | U14: FALSE | V14: FALSE | W14: 1 | AA14: A skill of its own, NOT tied to Meteor Shower specifically — every cast of Basic Attack, Poison Breath, Poison Mist (burst), Meteor Shower, or Flame Haze (burst) has an independent 30% chance to trigger this meteor drop, gated by a 1s internal cooldown (ICD(s) column) after each trigger. Steady-state proc rate = (Chance% * R) / (1 + ICD * Chance% * R), where R is the combined cast rate of those qualifying attacks (Summary!B66) — NOT the simple EffectiveHits*ProcProbability/Cooldown pattern every other row uses, since this proc has no cooldown of its own to divide by. Creeping Toxin deliberately excluded from the trigger set. 4th job only.
A15: FLAME_HAZE_BURST | B15: Flame Haze (burst) | C15: 4 | D15: Fire | E15: 25 | F15: TRUE | G15: 3 | H15: 0 | I15: 0 | J15: 100 | K15: 1 | L15: 12000 | M15: 12 | N15: TRUE | O15: 0 | P15: 0 | Q15: 0 | R15: 10 | T15: 0 | U15: TRUE | V15: TRUE | W15: 1 | AA15: Hits 10 targets vs normal monsters.
A16: FLAME_HAZE_DOT | B16: Flame Haze (burn DoT) | C16: 4 | D16: Fire | E16: 25 | F16: FALSE | G16: 1 | H16: 0.5 | I16: =IF(Inputs!$B$4="pvp",10,(1-Summary!$B$56)*(20)+Summary!$B$56*(10)) -> 14 | J16: 100 | K16: 1 | L16: 1500 | M16: 12 | N16: TRUE | O16: 0 | P16: 0 | Q16: 0 | R16: 10 | T16: 0 | U16: FALSE | V16: FALSE | W16: 1 | AA16: Burn duration is 20s vs boss, 10s vs normal monsters and PvP (confirmed by the user); Chapter Breakthrough blends the two by Inputs!normal_weight_frac. Hits 10 targets vs normal monsters, same as the burst.
A17: MAGIC_GUARD | B17: Magic Guard | C17: 1 | E17: 21 | F17: TRUE | G17: 1 | H17: 0 | I17: 0 | J17: 100 | K17: 1 | L17: 120 | M17: 21 | N17: TRUE | O17: 0 | P17: 0 | Q17: 0 | R17: 1 | S17: ATTACK | T17: 15 | U17: FALSE | V17: FALSE | W17: 1 | AA17: Buff — only the Attack component is modeled (Defense component doesn't affect own damage).
A18: NIMBLE_FEET | B18: Nimble Feet | C18: 1 | E18: 60 | F18: TRUE | G18: 1 | H18: 0 | I18: 0 | J18: 100 | K18: 1 | L18: 150 | M18: 0 | N18: FALSE | O18: 0 | P18: 0 | Q18: 0 | R18: 1 | S18: ATTACK_SPEED | T18: 15 | U18: FALSE | V18: FALSE | W18: 1 | AA18: Buff — flat +15% Attack Speed, does not scale with level (FactorIndex is an unused placeholder here, same as Burning Magic). Averaged into effective Attack Speed before the 150% cap.
A19: INFINITY | B19: Infinity | C19: 4 | E19: 30 | F19: TRUE | G19: 1 | H19: 0 | I19: 0 | J19: 100 | K19: 1 | L19: 216.67 | M19: 21 | N19: TRUE | O19: 0 | P19: 0 | Q19: 0 | R19: 1 | S19: FINAL_DAMAGE | T19: 15 | U19: FALSE | V19: FALSE | W19: 1 | AA19: Ramps +15%->+25% Final Damage over 10s of its 15s duration; time-averaged while active = 21.6667% at factor 1000, now scaled by FactorTable[level][21]/1000 like Magic Guard/Meditation.
A20: MAGIC_CRITICAL_RATE | B20: Magic Critical (Crit Rate) | C20: 3 | F20: FALSE | G20: 1 | H20: 0 | I20: 0 | J20: 100 | K20: 1 | L20: 80 | M20: 22 | N20: TRUE | O20: 0 | P20: 0 | Q20: 0 | R20: 1 | S20: CRIT_RATE | T20: 0 | U20: FALSE | V20: FALSE | W20: 1 | AA20: Passive, always on (3rd job) — no cooldown/duration, not a damage row (Calc columns J-O stay blank/0). Its current contribution is already baked into Inputs!CRIT_RATE% by the user, so this row's own Calc!F value is NOT added to the baseline calculation — it's only used by the Sensitivity sheet to compute the marginal delta (this row's F at the swept level minus this row's F at the current level) when 'Skill Level Bonus — 3rd Job' is the stat being tested.
A21: MAGIC_CRITICAL_DAMAGE | B21: Magic Critical (Crit Damage) | C21: 3 | F21: FALSE | G21: 1 | H21: 0 | I21: 0 | J21: 100 | K21: 1 | L21: 120 | M21: 22 | N21: TRUE | O21: 0 | P21: 0 | Q21: 0 | R21: 1 | S21: CRIT_DAMAGE | T21: 0 | U21: FALSE | V21: FALSE | W21: 1 | AA21: Same mechanism as Magic Critical (Crit Rate) above, targeting CRIT_DAMAGE% instead.
A22: SPELL_MASTERY | B22: Spell Mastery | C22: 2 | F22: FALSE | G22: 1 | H22: 0 | I22: 0 | J22: 100 | K22: 1 | L22: 150 | M22: 22 | N22: TRUE | O22: 0 | P22: 0 | Q22: 0 | R22: 1 | S22: MIN_DAMAGE | T22: 0 | U22: FALSE | V22: FALSE | W22: 1 | AA22: Passive, always on (2nd job) — no cooldown/duration, not a damage row. Its current contribution is already baked into Inputs!MIN_DAMAGE% by the user; this row's Calc!F is only used by the Sensitivity sheet to compute the marginal delta when 'Skill Level Bonus — 2nd Job' is swept.
A23: ELEMENT_AMPLIFICATION | B23: Element Amplification | C23: 4 | F23: FALSE | G23: 1 | H23: 0 | I23: 0 | J23: 100 | K23: 1 | L23: 150 | M23: 22 | N23: TRUE | O23: 0 | P23: 0 | Q23: 0 | R23: 1 | S23: FINAL_DAMAGE | T23: 0 | U23: FALSE | V23: FALSE | W23: 1 | AA23: Passive, always on (4th job) — no cooldown/duration, not a damage row. Unlike the two rows above, this one is NOT reflected anywhere in Inputs, so its current-level value (Calc!F23) is added directly into every hit's Final Damage term in both the main Calc sheet and every Sensitivity block — combined MULTIPLICATIVELY with Inputs!FINAL_DAMAGE% (Final Damage sources always stack as (1+a/100)*(1+b/100), never as (1+(a+b)/100)).
A24: IFRIT | B24: Ifrit | C24: 4 | D24: Fire | E24: 80 | F24: TRUE | G24: 1 | H24: 4 | I24: =IF(Inputs!$B$3>=138,40,30) -> 30 | J24: 100 | K24: 1 | L24: 35000 | M24: 12 | N24: TRUE | O24: 0 | P24: 0 | Q24: 0 | R24: =IF(Inputs!$B$3>=138,6,3) -> 3 | T24: 0 | U24: FALSE | V24: FALSE | W24: 1 | AA24: Summon, 80s cooldown. EffectiveHits = HitsPerCast*(ActiveWindow/ICD) — same mechanism as Poison Mist's fog DoT/Flame Haze's burn DoT, no new Calc-sheet machinery needed: attacks every 4s (ICD) for its 30s duration (ActiveWindow), hitting 3 targets vs normal monsters, for the whole 80s cast cycle (Cooldown/InvCooldown). Duration -> 40s and targets -> 6 once the level-138 mastery is unlocked. Deliberately excluded from Meteor Proc's trigger set (confirmed by the user) — it only counts as a trigger source for the level-126 Flame Haze burn-proc mastery (see build_calc_sheet) and for Fervent Drain (via DAMAGE_ROW_KEYS, same as every other non-Basic-Attack skill). Gains a level-130 mastery multiplier (1+20%*Flame Haze burn stacks) — see flame_haze_total_stacks_expr.
A25: BUFF_MASTERY | B25: Buff Mastery | C25: 4 | F25: FALSE | G25: 1 | H25: 0 | I25: 0 | J25: 100 | K25: 1 | L25: 100 | M25: 22 | N25: TRUE | O25: 0 | P25: 0 | Q25: 0 | R25: 1 | T25: 0 | U25: FALSE | V25: FALSE | W25: 1 | AA25: Passive, always on (4th job, unlocked level 117) — no cooldown/duration, not a damage row. Not reflected anywhere in Inputs, so its current value (Calc!F) is added directly into every uptime_fraction_expr call's Buff Duration Increase % term, in both the main Calc sheet and every Sensitivity block (see bdi_with_buff_mastery_expr) — +10% base.
A26: ARCANE_AIM | B26: Arcane Aim | C26: 4 | F26: FALSE | G26: 1 | H26: 0 | I26: 0 | J26: 100 | K26: 1 | L26: 30 | M26: 22 | N26: TRUE | O26: 0 | P26: 0 | Q26: 0 | R26: 1 | T26: 0 | U26: FALSE | V26: FALSE | W26: 1 | AA26: Passive, always on (4th job, unlocked level 120) — no cooldown/duration, not a damage row. 25% chance per attack for +3% Final Damage for 10s, stacking up to 5 times; modeled as always at max 5 stacks (confirmed by the user, same precedent as Burning Magic/Elemental Decrease always-on). Combined MULTIPLICATIVELY into the Final Damage chain as (1+Calc!F/100)^5, alongside Element Amplification — stacks are multiplicative with each other, not additive (1.03^5, not 1+5*0.03).
A27: FERVENT_DRAIN | B27: Fervent Drain | C27: 4 | F27: FALSE | G27: 1 | H27: 0 | I27: 0 | J27: 100 | K27: 1 | L27: 40 | M27: 22 | N27: TRUE | O27: 0 | P27: 0 | Q27: 0 | R27: 1 | T27: 0 | U27: FALSE | V27: FALSE | W27: 1 | AA27: Passive, always on (4th job, unlocked level 125) — no cooldown/duration, not a damage row. +4% fire/poison skill damage per Poison stack on target; reuses Elemental Drain's permanently-5-stacks assumption, so its effective contribution is Calc!F*5. Added additively inside the skill_damage term of the hit-damage formula — confirmed by the user to boost skill damage only, NOT Basic Attack (Flame Sweep), even though it does cover both fire- and poison-element skills otherwise. Structurally excluded from Basic Attack's own term, not just numerically zero.
A28: FLAME_HAZE_FOG | B28: Flame Haze (poison fog DoT) | C28: 4 | D28: Poison | E28: =Skills!E15 -> 25 | F28: FALSE | G28: 1 | H28: =IF(Inputs!$B$3>=104,0.4,0.8) -> 0.4 | I28: 20 | J28: 100 | K28: 1 | L28: 700 | M28: 12 | N28: TRUE | O28: 0 | P28: 0 | Q28: 0 | R28: 10 | T28: 0 | U28: FALSE | V28: FALSE | W28: 1 | AA28: Unlocked level 118: Flame Haze creates a second, fully independent poisonous fog that triggers Poison Mist's DoT mechanic too — same damage/duration/ICD-mastery-gate math as POISON_MIST_DOT, tied to Flame Haze (burst)'s own live Cooldown cell (same live-cross-reference pattern MIST_ERUPTION uses for POISON_MIST_BURST). Independent of the existing Poison Mist fog — both can be active at the same time (confirmed by the user). No Maple Hero bonus (MapleHeroBase blank), matching its jobStep-4 sibling FLAME_HAZE_DOT rather than the jobStep-3 POISON_MIST_DOT.

Sheet Calc
A1: Key | B1: Name | C1: Unlocked | D1: InputLevel | E1: Factor | F1: CoefficientPercent | G1: EffectiveHits | H1: ProcProbability | I1: MapleHeroMultiplier | J1: BaseDamage | K1: BaseHitDamage | L1: NonCritAvg | M1: CritAvg | N1: ExpectedDamage(perHit) | O1: DPS | P1: % of Total | Q1: InvCooldown | R1: CastsInFight | Z1: Maple Hero helper (jobStep4, factorIndex23)
A2: =Skills!A2 -> BASIC_ATTACK | B2: =Skills!B2 -> Basic Attack | C2: =TRUE -> TRUE | F2: =Summary!$B$55+Skills!O2 -> 510.52 | G2: =Skills!G2*IF(Skills!H2>0,Skills!I2/Skills!H2,1) -> 5 | H2: =1-(1-Skills!J2/100)^Skills!K2 -> 1 | I2: =IF(Skills!X2<>"",1+(Skills!X2/10)*($Z$3/1000)/100,1) -> 1 | J2: =Summary!$B$51*(F2/100) -> 1.2754373e+09 | K2: =J2*(1+Summary!$B$52/100)*(1+Inputs!$B$14/100)*(1+IF(Inputs!$B$4="pvp",0,(1-Summary!$B$56)*(Inputs!$B$19+Skills!P2)+Summary!$B$56*(Inputs!$B$20+Skills!Q2))/100)*(1+Inputs!$B$15/100)*(5000/(6000+Inputs!$B$7*(1-Inputs!$B$18/100)))*(1+Inputs!$B$23/100)*(1+F23/100)*(1+IF(Inputs!$B$3>=120,F26,0)/100)^5*(1+(IF(Skills!A2="BASIC_ATTACK",Inputs!$B$16,Inputs!$B$17+IF(Inputs!$B$3>=125,F27*5,0)))/100)*(Summary!$B$58*Summary!$B$59*Summary!$B$60*I2) -> 6.9609526e+12 | L2: =K2*(MIN(Inputs!$B$21,Inputs!$B$22)/100+Inputs!$B$22/100)/2 -> 1.8791091e+13 | M2: =L2*(1+Inputs!$B$9/100) -> 7.8753464e+13 | N2: =L2*(1-MIN(Inputs!$B$8,100)/100)+M2*(MIN(Inputs!$B$8,100)/100) -> 7.8753464e+13 | O2: =Skills!G2*N2*Summary!$B$64*IF(Inputs!$B$4="pvp",1,(1-Summary!$B$56)*(1)+Summary!$B$56*(MIN(Skills!R2,Inputs!$B$37))) -> 3.897785e+15 | P2: =IF(Summary!$B$3=0,0,O2/Summary!$B$3) -> 0.46738363 | Q2: =IFERROR(1/IF(Inputs!$B$4="pvp",15,MAX(0.1,Skills!E2-IF(Skills!F2=TRUE,Inputs!$B$31,0))),0) -> 10 | R2: 0 | Z2: =MAX(0,(Inputs!$B$3-100)*3)+Inputs!$B$27+Inputs!$B$28 -> 172
A3: =Skills!A3 -> IGNITE | B3: =Skills!B3 -> Ignite | C3: =TRUE -> TRUE | D3: =IF(Skills!C3=1,60+Inputs!$B$24+Inputs!$B$28,IF(Skills!C3=2,90+Inputs!$B$25+Inputs!$B$28,IF(Skills!C3=3,120+Inputs!$B$26+Inputs!$B$28,MAX(0,(Inputs!$B$3-100)*3)+Inputs!$B$27+Inputs!$B$28))) -> 164 | E3: =INDEX(FactorTable!$B$2:$Y$301, MATCH(ROUND(MIN(300,MAX(1,D3)),0), FactorTable!$A$2:$A$301,0), Skills!M3+1) -> 1656 | F3: =IF(Skills!N3=TRUE,(Skills!L3/10)*(E3/1000),Skills!L3/10)+Skills!O3 -> 121.528 | G3: =Skills!G3*IF(Skills!H3>0,Skills!I3/Skills!H3,1) -> 3 | H3: =1-(1-Skills!J3/100)^Skills!K3 -> 1 | I3: =IF(Skills!X3<>"",1+(Skills!X3/10)*($Z$3/1000)/100,1) -> 4.76 | J3: =Summary!$B$51*(F3/100) -> 3.0361464e+08 | K3: =J3*(1+Summary!$B$52/100)*(1+Inputs!$B$14/100)*(1+IF(Inputs!$B$4="pvp",0,(1-Summary!$B$56)*(Inputs!$B$19+Skills!P3)+Summary!$B$56*(Inputs!$B$20+Skills!Q3))/100)*(1+Inputs!$B$15/100)*(5000/(6000+Inputs!$B$7*(1-Inputs!$B$18/100)))*(1+Inputs!$B$23/100)*(1+F23/100)*(1+IF(Inputs!$B$3>=120,F26,0)/100)^5*(1+(IF(Skills!A3="BASIC_ATTACK",Inputs!$B$16,Inputs!$B$17+IF(Inputs!$B$3>=125,F27*5,0)))/100)*(Summary!$B$58*Summary!$B$59*Summary!$B$60*I3) -> 1.0995012e+13 | L3: =K3*(MIN(Inputs!$B$21,Inputs!$B$22)/100+Inputs!$B$22/100)/2 -> 2.9681035e+13 | M3: =L3*(1+Inputs!$B$9/100) -> 1.2439322e+14 | N3: =L3*(1-MIN(Inputs!$B$8,100)/100)+M3*(MIN(Inputs!$B$8,100)/100) -> 1.2439322e+14 | O3: =IF(C3,H3*N3*IF(AND(Inputs!$B$4<>"pvp",Inputs!$B$35>0),((Skills!G3*((R3-1)*IF(Skills!H3>0,Skills!I3/Skills!H3,1)+IF(Skills!H3>0,MIN(Skills!I3,MAX(0,Inputs!$B$35-((R3-1)*IF(Inputs!$B$4="pvp",15,MAX(0.1,Skills!E3-IF(Skills!F3=TRUE,Inputs!$B$31,0))))))/Skills!H3,1)))/Inputs!$B$35),G3*Q3)*IF(Inputs!$B$4="pvp",1,(1-Summary!$B$56)*(1)+Summary!$B$56*(MIN(Skills!R3,Inputs!$B$37))),0) -> 8.2099524e+14 | P3: =IF(Summary!$B$3=0,0,O3/Summary!$B$3) -> 0.098445587 | Q3: =IFERROR(1/IF(Inputs!$B$4="pvp",15,MAX(0.1,Skills!E3-IF(Skills!F3=TRUE,Inputs!$B$31,0))),0) -> 1 | R3: =IF(AND(Inputs!$B$4<>"pvp",Inputs!$B$35>0),(INT(Inputs!$B$35/IF(Inputs!$B$4="pvp",15,MAX(0.1,Skills!E3-IF(Skills!F3=TRUE,Inputs!$B$31,0))))+1),0) -> 0 | Z3: =INDEX(FactorTable!$B$2:$Y$301, MATCH(ROUND(MIN(300,MAX(1,Z2)),0), FactorTable!$A$2:$A$301,0), 24) -> 7520
A4: =Skills!A4 -> POISON_BREATH | B4: =Skills!B4 -> Poison Breath | C4: =TRUE -> TRUE | D4: =IF(Skills!C4=1,60+Inputs!$B$24+Inputs!$B$28,IF(Skills!C4=2,90+Inputs!$B$25+Inputs!$B$28,IF(Skills!C4=3,120+Inputs!$B$26+Inputs!$B$28,MAX(0,(Inputs!$B$3-100)*3)+Inputs!$B$27+Inputs!$B$28))) -> 164 | E4: =INDEX(FactorTable!$B$2:$Y$301, MATCH(ROUND(MIN(300,MAX(1,D4)),0), FactorTable!$A$2:$A$301,0), Skills!M4+1) -> 1820 | F4: =IF(Skills!N4=TRUE,(Skills!L4/10)*(E4/1000),Skills!L4/10)+Skills!O4 -> 434 | G4: =Skills!G4*IF(Skills!H4>0,Skills!I4/Skills!H4,1) -> 3 | H4: =1-(1-Skills!J4/100)^Skills!K4 -> 1 | I4: =IF(Skills!X4<>"",1+(Skills!X4/10)*($Z$3/1000)/100,1) -> 7.016 | J4: =Summary!$B$51*(F4/100) -> 1.0842666e+09 | K4: =J4*(1+Summary!$B$52/100)*(1+Inputs!$B$14/100)*(1+IF(Inputs!$B$4="pvp",0,(1-Summary!$B$56)*(Inputs!$B$19+Skills!P4)+Summary!$B$56*(Inputs!$B$20+Skills!Q4))/100)*(1+Inputs!$B$15/100)*(5000/(6000+Inputs!$B$7*(1-Inputs!$B$18/100)))*(1+Inputs!$B$23/100)*(1+F23/100)*(1+IF(Inputs!$B$3>=120,F26,0)/100)^5*(1+(IF(Skills!A4="BASIC_ATTACK",Inputs!$B$16,Inputs!$B$17+IF(Inputs!$B$3>=125,F27*5,0)))/100)*(Summary!$B$58*Summary!$B$59*Summary!$B$60*I4) -> 5.7875095e+13 | L4: =K4*(MIN(Inputs!$B$21,Inputs!$B$22)/100+Inputs!$B$22/100)/2 -> 1.5623382e+14 | M4: =L4*(1+Inputs!$B$9/100) -> 6.5477593e+14 | N4: =L4*(1-MIN(Inputs!$B$8,100)/100)+M4*(MIN(Inputs!$B$8,100)/100) -> 6.5477593e+14 | O4: =IF(C4,H4*N4*IF(AND(Inputs!$B$4<>"pvp",Inputs!$B$35>0),((Skills!G4*((R4-1)*IF(Skills!H4>0,Skills!I4/Skills!H4,1)+IF(Skills!H4>0,MIN(Skills!I4,MAX(0,Inputs!$B$35-((R4-1)*IF(Inputs!$B$4="pvp",15,MAX(0.1,Skills!E4-IF(Skills!F4=TRUE,Inputs!$B$31,0))))))/Skills!H4,1)))/Inputs!$B$35),G4*Q4)*IF(Inputs!$B$4="pvp",1,(1-Summary!$B$56)*(1)+Summary!$B$56*(MIN(Skills!R4,Inputs!$B$37))),0) -> 4.3651729e+14 | P4: =IF(Summary!$B$3=0,0,O4/Summary!$B$3) -> 0.052342814 | Q4: =IFERROR(1/IF(Inputs!$B$4="pvp",15,MAX(0.1,Skills!E4-IF(Skills!F4=TRUE,Inputs!$B$31,0))),0) -> 0.055555556 | R4: =IF(AND(Inputs!$B$4<>"pvp",Inputs!$B$35>0),(INT(Inputs!$B$35/IF(Inputs!$B$4="pvp",15,MAX(0.1,Skills!E4-IF(Skills!F4=TRUE,Inputs!$B$31,0))))+1),0) -> 0
A5: =Skills!A5 -> ELEMENTAL_DRAIN | B5: =Skills!B5 -> Elemental Drain | C5: =TRUE -> TRUE | D5: =IF(Skills!C5=1,60+Inputs!$B$24+Inputs!$B$28,IF(Skills!C5=2,90+Inputs!$B$25+Inputs!$B$28,IF(Skills!C5=3,120+Inputs!$B$26+Inputs!$B$28,MAX(0,(Inputs!$B$3-100)*3)+Inputs!$B$27+Inputs!$B$28))) -> 164 | E5: =INDEX(FactorTable!$B$2:$Y$301, MATCH(ROUND(MIN(300,MAX(1,D5)),0), FactorTable!$A$2:$A$301,0), Skills!M5+1) -> 1656 | F5: =IF(Skills!N5=TRUE,(Skills!L5/10)*(E5/1000),Skills!L5/10)+Skills!O5 -> 19.872 | G5: =Skills!G5*IF(Skills!H5>0,Skills!I5/Skills!H5,1) -> 5 | H5: =1-(1-Skills!J5/100)^Skills!K5 -> 1 | I5: =IF(Skills!X5<>"",1+(Skills!X5/10)*($Z$3/1000)/100,1) -> 12.28 | J5: =Summary!$B$51*(F5/100) -> 49646421 | K5: =J5*(1+Summary!$B$52/100)*(1+Inputs!$B$14/100)*(1+IF(Inputs!$B$4="pvp",0,(1-Summary!$B$56)*(Inputs!$B$19+Skills!P5)+Summary!$B$56*(Inputs!$B$20+Skills!Q5))/100)*(1+Inputs!$B$15/100)*(5000/(6000+Inputs!$B$7*(1-Inputs!$B$18/100)))*(1+Inputs!$B$23/100)*(1+F23/100)*(1+IF(Inputs!$B$3>=120,F26,0)/100)^5*(1+(IF(Skills!A5="BASIC_ATTACK",Inputs!$B$16,Inputs!$B$17+IF(Inputs!$B$3>=125,F27*5,0)))/100)*(Summary!$B$58*Summary!$B$59*Summary!$B$60*I5) -> 4.6382307e+12 | L5: =K5*(MIN(Inputs!$B$21,Inputs!$B$22)/100+Inputs!$B$22/100)/2 -> 1.2520904e+13 | M5: =L5*(1+Inputs!$B$9/100) -> 5.2475108e+13 | N5: =L5*(1-MIN(Inputs!$B$8,100)/100)+M5*(MIN(Inputs!$B$8,100)/100) -> 5.2475108e+13 | O5: =IF(C5,H5*N5*IF(AND(Inputs!$B$4<>"pvp",Inputs!$B$35>0),((Skills!G5*((R5-1)*IF(Skills!H5>0,Skills!I5/Skills!H5,1)+IF(Skills!H5>0,MIN(Skills!I5,MAX(0,Inputs!$B$35-((R5-1)*IF(Inputs!$B$4="pvp",15,MAX(0.1,Skills!E5-IF(Skills!F5=TRUE,Inputs!$B$31,0))))))/Skills!H5,1)))/Inputs!$B$35),G5*Q5)*IF(Inputs!$B$4="pvp",1,(1-Summary!$B$56)*(1)+Summary!$B$56*(MIN(Skills!R5,Inputs!$B$37))),0) -> 2.6237554e+14 | P5: =IF(Summary!$B$3=0,0,O5/Summary!$B$3) -> 0.031461467 | Q5: =IFERROR(1/IF(Inputs!$B$4="pvp",15,MAX(0.1,Skills!E5-IF(Skills!F5=TRUE,Inputs!$B$31,0))),0) -> 1 | R5: =IF(AND(Inputs!$B$4<>"pvp",Inputs!$B$35>0),(INT(Inputs!$B$35/IF(Inputs!$B$4="pvp",15,MAX(0.1,Skills!E5-IF(Skills!F5=TRUE,Inputs!$B$31,0))))+1),0) -> 0
A6: =Skills!A6 -> MEDITATION | B6: =Skills!B6 -> Meditation | C6: =TRUE -> TRUE | D6: =IF(Skills!C6=1,60+Inputs!$B$24+Inputs!$B$28,IF(Skills!C6=2,90+Inputs!$B$25+Inputs!$B$28,IF(Skills!C6=3,120+Inputs!$B$26+Inputs!$B$28,MAX(0,(Inputs!$B$3-100)*3)+Inputs!$B$27+Inputs!$B$28))) -> 164 | E6: =INDEX(FactorTable!$B$2:$Y$301, MATCH(ROUND(MIN(300,MAX(1,D6)),0), FactorTable!$A$2:$A$301,0), Skills!M6+1) -> 1492 | F6: =IF(Skills!N6=TRUE,(Skills!L6/10)*(E6/1000),Skills!L6/10)+Skills!O6 -> 29.84 | G6: =Skills!G6*IF(Skills!H6>0,Skills!I6/Skills!H6,1) -> 1 | H6: =1-(1-Skills!J6/100)^Skills!K6 -> 1 | I6: =IF(Skills!X6<>"",1+(Skills!X6/10)*($Z$3/1000)/100,1) -> 1 | O6: 0 | P6: =IF(Summary!$B$3=0,0,O6/Summary!$B$3) -> 0 | Q6: =IFERROR(1/IF(Inputs!$B$4="pvp",15,MAX(0.1,Skills!E6-IF(Skills!F6=TRUE,Inputs!$B$31,0))),0) -> 0.033333333 | R6: =IF(AND(Inputs!$B$4<>"pvp",Inputs!$B$35>0),(INT(Inputs!$B$35/IF(Inputs!$B$4="pvp",15,MAX(0.1,Skills!E6-IF(Skills!F6=TRUE,Inputs!$B$31,0))))+1),0) -> 0
A7: =Skills!A7 -> POISON_MIST_BURST | B7: =Skills!B7 -> Poison Mist (burst) | C7: =TRUE -> TRUE | D7: =IF(Skills!C7=1,60+Inputs!$B$24+Inputs!$B$28,IF(Skills!C7=2,90+Inputs!$B$25+Inputs!$B$28,IF(Skills!C7=3,120+Inputs!$B$26+Inputs!$B$28,MAX(0,(Inputs!$B$3-100)*3)+Inputs!$B$27+Inputs!$B$28))) -> 184 | E7: =INDEX(FactorTable!$B$2:$Y$301, MATCH(ROUND(MIN(300,MAX(1,D7)),0), FactorTable!$A$2:$A$301,0), Skills!M7+1) -> 1920 | F7: =IF(Skills!N7=TRUE,(Skills!L7/10)*(E7/1000),Skills!L7/10)+Skills!O7 -> 357.2 | G7: =Skills!G7*IF(Skills!H7>0,Skills!I7/Skills!H7,1) -> 3 | H7: =1-(1-Skills!J7/100)^Skills!K7 -> 1 | I7: =IF(Skills!X7<>"",1+(Skills!X7/10)*($Z$3/1000)/100,1) -> 1.752 | J7: =Summary!$B$51*(F7/100) -> 8.9239641e+08 | K7: =J7*(1+Summary!$B$52/100)*(1+Inputs!$B$14/100)*(1+IF(Inputs!$B$4="pvp",0,(1-Summary!$B$56)*(Inputs!$B$19+Skills!P7)+Summary!$B$56*(Inputs!$B$20+Skills!Q7))/100)*(1+Inputs!$B$15/100)*(5000/(6000+Inputs!$B$7*(1-Inputs!$B$18/100)))*(1+Inputs!$B$23/100)*(1+F23/100)*(1+IF(Inputs!$B$3>=120,F26,0)/100)^5*(1+(IF(Skills!A7="BASIC_ATTACK",Inputs!$B$16,Inputs!$B$17+IF(Inputs!$B$3>=125,F27*5,0)))/100)*(Summary!$B$58*Summary!$B$59*Summary!$B$60*I7) -> 1.1894822e+13 | L7: =K7*(MIN(Inputs!$B$21,Inputs!$B$22)/100+Inputs!$B$22/100)/2 -> 3.2110073e+13 | M7: =L7*(1+Inputs!$B$9/100) -> 1.3457331e+14 | N7: =L7*(1-MIN(Inputs!$B$8,100)/100)+M7*(MIN(Inputs!$B$8,100)/100) -> 1.3457331e+14 | O7: =IF(C7,H7*N7*IF(AND(Inputs!$B$4<>"pvp",Inputs!$B$35>0),((Skills!G7*((R7-1)*IF(Skills!H7>0,Skills!I7/Skills!H7,1)+IF(Skills!H7>0,MIN(Skills!I7,MAX(0,Inputs!$B$35-((R7-1)*IF(Inputs!$B$4="pvp",15,MAX(0.1,Skills!E7-IF(Skills!F7=TRUE,Inputs!$B$31,0))))))/Skills!H7,1)))/Inputs!$B$35),G7*Q7)*IF(Inputs!$B$4="pvp",1,(1-Summary!$B$56)*(1)+Summary!$B$56*(MIN(Skills!R7,Inputs!$B$37))),0) -> 1.0546154e+14 | P7: =IF(Summary!$B$3=0,0,O7/Summary!$B$3) -> 0.012645899 | Q7: =IFERROR(1/IF(Inputs!$B$4="pvp",15,MAX(0.1,Skills!E7-IF(Skills!F7=TRUE,Inputs!$B$31,0))),0) -> 0.040816327 | R7: =IF(AND(Inputs!$B$4<>"pvp",Inputs!$B$35>0),(INT(Inputs!$B$35/IF(Inputs!$B$4="pvp",15,MAX(0.1,Skills!E7-IF(Skills!F7=TRUE,Inputs!$B$31,0))))+1),0) -> 0
A8: =Skills!A8 -> POISON_MIST_DOT | B8: =Skills!B8 -> Poison Mist (fog DoT) | C8: =TRUE -> TRUE | D8: =IF(Skills!C8=1,60+Inputs!$B$24+Inputs!$B$28,IF(Skills!C8=2,90+Inputs!$B$25+Inputs!$B$28,IF(Skills!C8=3,120+Inputs!$B$26+Inputs!$B$28,MAX(0,(Inputs!$B$3-100)*3)+Inputs!$B$27+Inputs!$B$28))) -> 184 | E8: =INDEX(FactorTable!$B$2:$Y$301, MATCH(ROUND(MIN(300,MAX(1,D8)),0), FactorTable!$A$2:$A$301,0), Skills!M8+1) -> 1920 | F8: =IF(Skills!N8=TRUE,(Skills!L8/10)*(E8/1000),Skills!L8/10)+Skills!O8 -> 134.4 | G8: =Skills!G8*IF(Skills!H8>0,Skills!I8/Skills!H8,1) -> 50 | H8: =1-(1-Skills!J8/100)^Skills!K8 -> 1 | I8: =IF(Skills!X8<>"",1+(Skills!X8/10)*($Z$3/1000)/100,1) -> 1.752 | J8: =Summary!$B$51*(F8/100) -> 3.3577289e+08 | K8: =J8*(1+Summary!$B$52/100)*(1+Inputs!$B$14/100)*(1+IF(Inputs!$B$4="pvp",0,(1-Summary!$B$56)*(Inputs!$B$19+Skills!P8)+Summary!$B$56*(Inputs!$B$20+Skills!Q8))/100)*(1+Inputs!$B$15/100)*(5000/(6000+Inputs!$B$7*(1-Inputs!$B$18/100)))*(1+Inputs!$B$23/100)*(1+F23/100)*(1+IF(Inputs!$B$3>=120,F26,0)/100)^5*(1+(IF(Skills!A8="BASIC_ATTACK",Inputs!$B$16,Inputs!$B$17+IF(Inputs!$B$3>=125,F27*5,0)))/100)*(Summary!$B$58*Summary!$B$59*Summary!$B$60*I8) -> 4.4755434e+12 | L8: =K8*(MIN(Inputs!$B$21,Inputs!$B$22)/100+Inputs!$B$22/100)/2 -> 1.2081729e+13 | M8: =L8*(1+Inputs!$B$9/100) -> 5.0634528e+13 | N8: =L8*(1-MIN(Inputs!$B$8,100)/100)+M8*(MIN(Inputs!$B$8,100)/100) -> 5.0634528e+13 | O8: =IF(C8,H8*N8*IF(AND(Inputs!$B$4<>"pvp",Inputs!$B$35>0),((Skills!G8*((R8-1)*IF(Skills!H8>0,Skills!I8/Skills!H8,1)+IF(Skills!H8>0,MIN(Skills!I8,MAX(0,Inputs!$B$35-((R8-1)*IF(Inputs!$B$4="pvp",15,MAX(0.1,Skills!E8-IF(Skills!F8=TRUE,Inputs!$B$31,0))))))/Skills!H8,1)))/Inputs!$B$35),G8*Q8)*IF(Inputs!$B$4="pvp",1,(1-Summary!$B$56)*(1)+Summary!$B$56*(MIN(Skills!R8,Inputs!$B$37))),0) -> 6.6134894e+14 | P8: =IF(Summary!$B$3=0,0,O8/Summary!$B$3) -> 0.07930239 | Q8: =IFERROR(1/IF(Inputs!$B$4="pvp",15,MAX(0.1,Skills!E8-IF(Skills!F8=TRUE,Inputs!$B$31,0))),0) -> 0.040816327 | R8: =IF(AND(Inputs!$B$4<>"pvp",Inputs!$B$35>0),(INT(Inputs!$B$35/IF(Inputs!$B$4="pvp",15,MAX(0.1,Skills!E8-IF(Skills!F8=TRUE,Inputs!$B$31,0))))+1),0) -> 0
A9: =Skills!A9 -> MIST_ERUPTION | B9: =Skills!B9 -> Mist Eruption | C9: =Inputs!$B$3>=103 -> TRUE | D9: =IF(Skills!C9=1,60+Inputs!$B$24+Inputs!$B$28,IF(Skills!C9=2,90+Inputs!$B$25+Inputs!$B$28,IF(Skills!C9=3,120+Inputs!$B$26+Inputs!$B$28,MAX(0,(Inputs!$B$3-100)*3)+Inputs!$B$27+Inputs!$B$28))) -> 172 | E9: =INDEX(FactorTable!$B$2:$Y$301, MATCH(ROUND(MIN(300,MAX(1,D9)),0), FactorTable!$A$2:$A$301,0), Skills!M9+1) -> 1860 | F9: =IF(Skills!N9=TRUE,(Skills!L9/10)*(E9/1000),Skills!L9/10)+Skills!O9 -> 5580 | G9: =Skills!G9*IF(Skills!H9>0,Skills!I9/Skills!H9,1) -> 2.8 | H9: =1-(1-Skills!J9/100)^Skills!K9 -> 1 | I9: =IF(Skills!X9<>"",1+(Skills!X9/10)*($Z$3/1000)/100,1) -> 1 | J9: =Summary!$B$51*(F9/100) -> 1.3940571e+10 | K9: =J9*(1+Summary!$B$52/100)*(1+Inputs!$B$14/100)*(1+IF(Inputs!$B$4="pvp",0,(1-Summary!$B$56)*(Inputs!$B$19+Skills!P9)+Summary!$B$56*(Inputs!$B$20+Skills!Q9))/100)*(1+Inputs!$B$15/100)*(5000/(6000+Inputs!$B$7*(1-Inputs!$B$18/100)))*(1+Inputs!$B$23/100)*(1+F23/100)*(1+IF(Inputs!$B$3>=120,F26,0)/100)^5*(1+(IF(Skills!A9="BASIC_ATTACK",Inputs!$B$16,Inputs!$B$17+IF(Inputs!$B$3>=125,F27*5,0)))/100)*(Summary!$B$58*Summary!$B$59*Summary!$B$60*I9) -> 1.0605877e+14 | L9: =K9*(MIN(Inputs!$B$21,Inputs!$B$22)/100+Inputs!$B$22/100)/2 -> 2.8630566e+14 | M9: =L9*(1+Inputs!$B$9/100) -> 1.199907e+15 | N9: =L9*(1-MIN(Inputs!$B$8,100)/100)+M9*(MIN(Inputs!$B$8,100)/100) -> 1.199907e+15 | O9: =IF(C9,H9*N9*IF(AND(Inputs!$B$4<>"pvp",Inputs!$B$35>0),((Skills!G9*((R9-1)*IF(Skills!H9>0,Skills!I9/Skills!H9,1)+IF(Skills!H9>0,MIN(Skills!I9,MAX(0,Inputs!$B$35-((R9-1)*IF(Inputs!$B$4="pvp",15,MAX(0.1,Skills!E9-IF(Skills!F7=TRUE,Inputs!$B$31,0))))))/Skills!H9,1)))/Inputs!$B$35),G9*Q9)*IF(Inputs!$B$4="pvp",1,(1-Summary!$B$56)*(1)+Summary!$B$56*(MIN(Skills!R9,Inputs!$B$37))),0) -> 8.7764628e+14 | P9: =IF(Summary!$B$3=0,0,O9/Summary!$B$3) -> 0.10523862 | Q9: =IFERROR(1/IF(Inputs!$B$4="pvp",15,MAX(0.1,Skills!E9-IF(Skills!F7=TRUE,Inputs!$B$31,0))),0) -> 0.040816327 | R9: =IF(AND(Inputs!$B$4<>"pvp",Inputs!$B$35>0),(INT(Inputs!$B$35/IF(Inputs!$B$4="pvp",15,MAX(0.1,Skills!E9-IF(Skills!F7=TRUE,Inputs!$B$31,0))))+1),0) -> 0
A10: =Skills!A10 -> CREEPING_TOXIN | B10: =Skills!B10 -> Creeping Toxin | C10: =TRUE -> TRUE | D10: =IF(Skills!C10=1,60+Inputs!$B$24+Inputs!$B$28,IF(Skills!C10=2,90+Inputs!$B$25+Inputs!$B$28,IF(Skills!C10=3,120+Inputs!$B$26+Inputs!$B$28,MAX(0,(Inputs!$B$3-100)*3)+Inputs!$B$27+Inputs!$B$28))) -> 184 | E10: =INDEX(FactorTable!$B$2:$Y$301, MATCH(ROUND(MIN(300,MAX(1,D10)),0), FactorTable!$A$2:$A$301,0), Skills!M10+1) -> 1920 | F10: =IF(Skills!N10=TRUE,(Skills!L10/10)*(E10/1000),Skills!L10/10)+Skills!O10 -> 280.4 | G10: =Skills!G10*IF(Skills!H10>0,Skills!I10/Skills!H10,1) -> 15 | H10: =1-(1-Skills!J10/100)^Skills!K10 -> 1 | I10: =IF(Skills!X10<>"",1+(Skills!X10/10)*($Z$3/1000)/100,1) -> 1.752 | J10: =Summary!$B$51*(F10/100) -> 7.0052619e+08 | K10: =J10*(1+Summary!$B$52/100)*(1+Inputs!$B$14/100)*(1+IF(Inputs!$B$4="pvp",0,(1-Summary!$B$56)*(Inputs!$B$19+Skills!P10)+Summary!$B$56*(Inputs!$B$20+Skills!Q10))/100)*(1+Inputs!$B$15/100)*(5000/(6000+Inputs!$B$7*(1-Inputs!$B$18/100)))*(1+Inputs!$B$23/100)*(1+F23/100)*(1+IF(Inputs!$B$3>=120,F26,0)/100)^5*(1+(IF(Skills!A10="BASIC_ATTACK",Inputs!$B$16,Inputs!$B$17+IF(Inputs!$B$3>=125,F27*5,0)))/100)*(Summary!$B$58*Summary!$B$59*Summary!$B$60*I10) -> 1.1018768e+13 | L10: =K10*(MIN(Inputs!$B$21,Inputs!$B$22)/100+Inputs!$B$22/100)/2 -> 2.9745164e+13 | M10: =L10*(1+Inputs!$B$9/100) -> 1.2466198e+14 | N10: =L10*(1-MIN(Inputs!$B$8,100)/100)+M10*(MIN(Inputs!$B$8,100)/100) -> 1.2466198e+14 | O10: =IF(C10,H10*N10*IF(AND(Inputs!$B$4<>"pvp",Inputs!$B$35>0),((Skills!G10*((R10-1)*IF(Skills!H10>0,Skills!I10/Skills!H10,1)+IF(Skills!H10>0,MIN(Skills!I10,MAX(0,Inputs!$B$35-((R10-1)*IF(Inputs!$B$4="pvp",15,MAX(0.1,Skills!E10-IF(Skills!F10=TRUE,Inputs!$B$31,0))))))/Skills!H10,1)))/Inputs!$B$35),G10*Q10)*IF(Inputs!$B$4="pvp",1,(1-Summary!$B$56)*(1)+Summary!$B$56*(MIN(Skills!R10,Inputs!$B$37))),0) -> 6.9256656e+13 | P10: =IF(Summary!$B$3=0,0,O10/Summary!$B$3) -> 0.0083045697 | Q10: =IFERROR(1/IF(Inputs!$B$4="pvp",15,MAX(0.1,Skills!E10-IF(Skills!F10=TRUE,Inputs!$B$31,0))),0) -> 0.037037037 | R10: =IF(AND(Inputs!$B$4<>"pvp",Inputs!$B$35>0),(INT(Inputs!$B$35/IF(Inputs!$B$4="pvp",15,MAX(0.1,Skills!E10-IF(Skills!F10=TRUE,Inputs!$B$31,0))))+1),0) -> 0
A11: =Skills!A11 -> BURNING_MAGIC | B11: =Skills!B11 -> Burning Magic | C11: =TRUE -> TRUE | D11: =IF(Skills!C11=1,60+Inputs!$B$24+Inputs!$B$28,IF(Skills!C11=2,90+Inputs!$B$25+Inputs!$B$28,IF(Skills!C11=3,120+Inputs!$B$26+Inputs!$B$28,MAX(0,(Inputs!$B$3-100)*3)+Inputs!$B$27+Inputs!$B$28))) -> 184 | E11: =INDEX(FactorTable!$B$2:$Y$301, MATCH(ROUND(MIN(300,MAX(1,D11)),0), FactorTable!$A$2:$A$301,0), Skills!M11+1) -> 0 | F11: =IF(Skills!N11=TRUE,(Skills!L11/10)*(E11/1000),Skills!L11/10)+Skills!O11 -> 5 | G11: =Skills!G11*IF(Skills!H11>0,Skills!I11/Skills!H11,1) -> 1 | H11: =1-(1-Skills!J11/100)^Skills!K11 -> 1 | I11: =IF(Skills!X11<>"",1+(Skills!X11/10)*($Z$3/1000)/100,1) -> 1 | O11: 0 | P11: =IF(Summary!$B$3=0,0,O11/Summary!$B$3) -> 0 | Q11: =IFERROR(1/IF(Inputs!$B$4="pvp",15,MAX(0.1,Skills!E11-IF(Skills!F11=TRUE,Inputs!$B$31,0))),0) -> 10 | R11: 0
A12: =Skills!A12 -> ELEMENTAL_DECREASE | B12: =Skills!B12 -> Elemental Decrease | C12: =TRUE -> TRUE | D12: =IF(Skills!C12=1,60+Inputs!$B$24+Inputs!$B$28,IF(Skills!C12=2,90+Inputs!$B$25+Inputs!$B$28,IF(Skills!C12=3,120+Inputs!$B$26+Inputs!$B$28,MAX(0,(Inputs!$B$3-100)*3)+Inputs!$B$27+Inputs!$B$28))) -> 184 | E12: =INDEX(FactorTable!$B$2:$Y$301, MATCH(ROUND(MIN(300,MAX(1,D12)),0), FactorTable!$A$2:$A$301,0), Skills!M12+1) -> 1552 | F12: =IF(Skills!N12=TRUE,(Skills!L12/10)*(E12/1000),Skills!L12/10)+Skills!O12 -> 18.624 | G12: =Skills!G12*IF(Skills!H12>0,Skills!I12/Skills!H12,1) -> 1 | H12: =1-(1-Skills!J12/100)^Skills!K12 -> 0.5 | I12: =IF(Skills!X12<>"",1+(Skills!X12/10)*($Z$3/1000)/100,1) -> 1 | O12: 0 | P12: =IF(Summary!$B$3=0,0,O12/Summary!$B$3) -> 0 | Q12: =IFERROR(1/IF(Inputs!$B$4="pvp",15,MAX(0.1,Skills!E12-IF(Skills!F12=TRUE,Inputs!$B$31,0))),0) -> 10 | R12: 0
A13: =Skills!A13 -> METEOR_SHOWER_BURST | B13: =Skills!B13 -> Meteor Shower (burst) | C13: =Inputs!$B$3>=105 -> TRUE | D13: =IF(Skills!C13=1,60+Inputs!$B$24+Inputs!$B$28,IF(Skills!C13=2,90+Inputs!$B$25+Inputs!$B$28,IF(Skills!C13=3,120+Inputs!$B$26+Inputs!$B$28,MAX(0,(Inputs!$B$3-100)*3)+Inputs!$B$27+Inputs!$B$28))) -> 172 | E13: =INDEX(FactorTable!$B$2:$Y$301, MATCH(ROUND(MIN(300,MAX(1,D13)),0), FactorTable!$A$2:$A$301,0), Skills!M13+1) -> 1860 | F13: =IF(Skills!N13=TRUE,(Skills!L13/10)*(E13/1000),Skills!L13/10)+Skills!O13 -> 1116 | G13: =Skills!G13*IF(Skills!H13>0,Skills!I13/Skills!H13,1) -> 9 | H13: =1-(1-Skills!J13/100)^Skills!K13 -> 1 | I13: =IF(Skills!X13<>"",1+(Skills!X13/10)*($Z$3/1000)/100,1) -> 1 | J13: =Summary!$B$51*(F13/100) -> 2.7881142e+09 | K13: =J13*(1+Summary!$B$52/100)*(1+Inputs!$B$14/100)*(1+IF(Inputs!$B$4="pvp",0,(1-Summary!$B$56)*(Inputs!$B$19+Skills!P13)+Summary!$B$56*(Inputs!$B$20+Skills!Q13))/100)*(1+Inputs!$B$15/100)*(5000/(6000+Inputs!$B$7*(1-Inputs!$B$18/100)))*(1+Inputs!$B$23/100)*(1+F23/100)*(1+IF(Inputs!$B$3>=120,F26,0)/100)^5*(1+(IF(Skills!A13="BASIC_ATTACK",Inputs!$B$16,Inputs!$B$17+IF(Inputs!$B$3>=125,F27*5,0)))/100)*(Summary!$B$58*Summary!$B$59*Summary!$B$60*I13) -> 2.1211755e+13 | L13: =K13*(MIN(Inputs!$B$21,Inputs!$B$22)/100+Inputs!$B$22/100)/2 -> 5.7261132e+13 | M13: =L13*(1+Inputs!$B$9/100) -> 2.3998141e+14 | N13: =L13*(1-MIN(Inputs!$B$8,100)/100)+M13*(MIN(Inputs!$B$8,100)/100) -> 2.3998141e+14 | O13: =IF(C13,H13*N13*IF(AND(Inputs!$B$4<>"pvp",Inputs!$B$35>0),((Skills!G13*((R13-1)*IF(Skills!H13>0,Skills!I13/Skills!H13,1)+IF(Skills!H13>0,MIN(Skills!I13,MAX(0,Inputs!$B$35-((R13-1)*IF(Inputs!$B$4="pvp",15,MAX(0.1,Skills!E13-IF(Skills!F13=TRUE,Inputs!$B$31,0))))))/Skills!H13,1)))/Inputs!$B$35),G13*Q13)*IF(Inputs!$B$4="pvp",1,(1-Summary!$B$56)*(1)+Summary!$B$56*(MIN(Skills!R13,Inputs!$B$37))),0) -> 3.0106758e+14 | P13: =IF(Summary!$B$3=0,0,O13/Summary!$B$3) -> 0.036101031 | Q13: =IFERROR(1/IF(Inputs!$B$4="pvp",15,MAX(0.1,Skills!E13-IF(Skills!F13=TRUE,Inputs!$B$31,0))),0) -> 0.03030303 | R13: =IF(AND(Inputs!$B$4<>"pvp",Inputs!$B$35>0),(INT(Inputs!$B$35/IF(Inputs!$B$4="pvp",15,MAX(0.1,Skills!E13-IF(Skills!F13=TRUE,Inputs!$B$31,0))))+1),0) -> 0
A14: =Skills!A14 -> METEOR_PROC | B14: =Skills!B14 -> Meteor Proc (30% on-hit, 1s ICD) | C14: =Inputs!$B$3>=113 -> TRUE | D14: =IF(Skills!C14=1,60+Inputs!$B$24+Inputs!$B$28,IF(Skills!C14=2,90+Inputs!$B$25+Inputs!$B$28,IF(Skills!C14=3,120+Inputs!$B$26+Inputs!$B$28,MAX(0,(Inputs!$B$3-100)*3)+Inputs!$B$27+Inputs!$B$28))) -> 172 | E14: =INDEX(FactorTable!$B$2:$Y$301, MATCH(ROUND(MIN(300,MAX(1,D14)),0), FactorTable!$A$2:$A$301,0), Skills!M14+1) -> 1688 | F14: =IF(Skills!N14=TRUE,(Skills!L14/10)*(E14/1000),Skills!L14/10)+Skills!O14 -> 1603.6 | G14: =Skills!G14*IF(Skills!H14>0,Skills!I14/Skills!H14,1) -> 0 | H14: =1-(1-Skills!J14/100)^Skills!K14 -> 0.3 | I14: =IF(Skills!X14<>"",1+(Skills!X14/10)*($Z$3/1000)/100,1) -> 1 | J14: =Summary!$B$51*(F14/100) -> 4.0062903e+09 | K14: =J14*(1+Summary!$B$52/100)*(1+Inputs!$B$14/100)*(1+IF(Inputs!$B$4="pvp",0,(1-Summary!$B$56)*(Inputs!$B$19+Skills!P14)+Summary!$B$56*(Inputs!$B$20+Skills!Q14))/100)*(1+Inputs!$B$15/100)*(5000/(6000+Inputs!$B$7*(1-Inputs!$B$18/100)))*(1+Inputs!$B$23/100)*(1+F23/100)*(1+IF(Inputs!$B$3>=120,F26,0)/100)^5*(1+(IF(Skills!A14="BASIC_ATTACK",Inputs!$B$16,Inputs!$B$17+IF(Inputs!$B$3>=125,F27*5,0)))/100)*(Summary!$B$58*Summary!$B$59*Summary!$B$60*I14) -> 3.0479543e+13 | L14: =K14*(MIN(Inputs!$B$21,Inputs!$B$22)/100+Inputs!$B$22/100)/2 -> 8.2279527e+13 | M14: =L14*(1+Inputs!$B$9/100) -> 3.448335e+14 | N14: =L14*(1-MIN(Inputs!$B$8,100)/100)+M14*(MIN(Inputs!$B$8,100)/100) -> 3.448335e+14 | O14: =IF(C14,(H14*Summary!$B$66)/(1+Skills!H14*H14*Summary!$B$66)*N14*IF(Inputs!$B$4="pvp",1,(1-Summary!$B$56)*(1)+Summary!$B$56*(MIN(Skills!R14,Inputs!$B$37))),0) -> 1.0847173e+14 | P14: =IF(Summary!$B$3=0,0,O14/Summary!$B$3) -> 0.013006852 | Q14: =IFERROR(1/IF(Inputs!$B$4="pvp",15,MAX(0.1,Skills!E14-IF(Skills!F14=TRUE,Inputs!$B$31,0))),0) -> 10 | R14: 0
A15: =Skills!A15 -> FLAME_HAZE_BURST | B15: =Skills!B15 -> Flame Haze (burst) | C15: =Inputs!$B$3>=107 -> TRUE | D15: =IF(Skills!C15=1,60+Inputs!$B$24+Inputs!$B$28,IF(Skills!C15=2,90+Inputs!$B$25+Inputs!$B$28,IF(Skills!C15=3,120+Inputs!$B$26+Inputs!$B$28,MAX(0,(Inputs!$B$3-100)*3)+Inputs!$B$27+Inputs!$B$28))) -> 172 | E15: =INDEX(FactorTable!$B$2:$Y$301, MATCH(ROUND(MIN(300,MAX(1,D15)),0), FactorTable!$A$2:$A$301,0), Skills!M15+1) -> 1860 | F15: =IF(Skills!N15=TRUE,(Skills!L15/10)*(E15/1000),Skills!L15/10)+Skills!O15 -> 2232 | G15: =Skills!G15*IF(Skills!H15>0,Skills!I15/Skills!H15,1) -> 3 | H15: =1-(1-Skills!J15/100)^Skills!K15 -> 1 | I15: =IF(Skills!X15<>"",1+(Skills!X15/10)*($Z$3/1000)/100,1) -> 1 | J15: =Summary!$B$51*(F15/100) -> 5.5762284e+09 | K15: =J15*(1+Summary!$B$52/100)*(1+Inputs!$B$14/100)*(1+IF(Inputs!$B$4="pvp",0,(1-Summary!$B$56)*(Inputs!$B$19+Skills!P15)+Summary!$B$56*(Inputs!$B$20+Skills!Q15))/100)*(1+Inputs!$B$15/100)*(5000/(6000+Inputs!$B$7*(1-Inputs!$B$18/100)))*(1+Inputs!$B$23/100)*(1+F23/100)*(1+IF(Inputs!$B$3>=120,F26,0)/100)^5*(1+(IF(Skills!A15="BASIC_ATTACK",Inputs!$B$16,Inputs!$B$17+IF(Inputs!$B$3>=125,F27*5,0)))/100)*(Summary!$B$58*Summary!$B$59*Summary!$B$60*I15) -> 4.242351e+13 | L15: =K15*(MIN(Inputs!$B$21,Inputs!$B$22)/100+Inputs!$B$22/100)/2 -> 1.1452226e+14 | M15: =L15*(1+Inputs!$B$9/100) -> 4.7996281e+14 | N15: =L15*(1-MIN(Inputs!$B$8,100)/100)+M15*(MIN(Inputs!$B$8,100)/100) -> 4.7996281e+14 | O15: =IF(C15,H15*N15*IF(AND(Inputs!$B$4<>"pvp",Inputs!$B$35>0),((Skills!G15*((R15-1)*IF(Skills!H15>0,Skills!I15/Skills!H15,1)+IF(Skills!H15>0,MIN(Skills!I15,MAX(0,Inputs!$B$35-((R15-1)*IF(Inputs!$B$4="pvp",15,MAX(0.1,Skills!E15-IF(Skills!F15=TRUE,Inputs!$B$31,0))))))/Skills!H15,1)))/Inputs!$B$35),G15*Q15)*IF(Inputs!$B$4="pvp",1,(1-Summary!$B$56)*(1)+Summary!$B$56*(MIN(Skills!R15,Inputs!$B$37))),0) -> 3.6861144e+14 | P15: =IF(Summary!$B$3=0,0,O15/Summary!$B$3) -> 0.044200219 | Q15: =IFERROR(1/IF(Inputs!$B$4="pvp",15,MAX(0.1,Skills!E15-IF(Skills!F15=TRUE,Inputs!$B$31,0))),0) -> 0.04 | R15: =IF(AND(Inputs!$B$4<>"pvp",Inputs!$B$35>0),(INT(Inputs!$B$35/IF(Inputs!$B$4="pvp",15,MAX(0.1,Skills!E15-IF(Skills!F15=TRUE,Inputs!$B$31,0))))+1),0) -> 0
A16: =Skills!A16 -> FLAME_HAZE_DOT | B16: =Skills!B16 -> Flame Haze (burn DoT) | C16: =Inputs!$B$3>=107 -> TRUE | D16: =IF(Skills!C16=1,60+Inputs!$B$24+Inputs!$B$28,IF(Skills!C16=2,90+Inputs!$B$25+Inputs!$B$28,IF(Skills!C16=3,120+Inputs!$B$26+Inputs!$B$28,MAX(0,(Inputs!$B$3-100)*3)+Inputs!$B$27+Inputs!$B$28))) -> 172 | E16: =INDEX(FactorTable!$B$2:$Y$301, MATCH(ROUND(MIN(300,MAX(1,D16)),0), FactorTable!$A$2:$A$301,0), Skills!M16+1) -> 1860 | F16: =IF(Skills!N16=TRUE,(Skills!L16/10)*(E16/1000),Skills!L16/10)+Skills!O16 -> 279 | G16: =Skills!G16*IF(Skills!H16>0,Skills!I16/Skills!H16,1) -> 28 | H16: =1-(1-Skills!J16/100)^Skills!K16 -> 1 | I16: =IF(Skills!X16<>"",1+(Skills!X16/10)*($Z$3/1000)/100,1) -> 1 | J16: =Summary!$B$51*(F16/100) -> 6.9702855e+08 | K16: =J16*(1+Summary!$B$52/100)*(1+Inputs!$B$14/100)*(1+IF(Inputs!$B$4="pvp",0,(1-Summary!$B$56)*(Inputs!$B$19+Skills!P16)+Summary!$B$56*(Inputs!$B$20+Skills!Q16))/100)*(1+Inputs!$B$15/100)*(5000/(6000+Inputs!$B$7*(1-Inputs!$B$18/100)))*(1+Inputs!$B$23/100)*(1+F23/100)*(1+IF(Inputs!$B$3>=120,F26,0)/100)^5*(1+(IF(Skills!A16="BASIC_ATTACK",Inputs!$B$16,Inputs!$B$17+IF(Inputs!$B$3>=125,F27*5,0)))/100)*(Summary!$B$58*Summary!$B$59*Summary!$B$60*I16) -> 5.3029387e+12 | L16: =K16*(MIN(Inputs!$B$21,Inputs!$B$22)/100+Inputs!$B$22/100)/2 -> 1.4315283e+13 | M16: =L16*(1+Inputs!$B$9/100) -> 5.9995351e+13 | N16: =L16*(1-MIN(Inputs!$B$8,100)/100)+M16*(MIN(Inputs!$B$8,100)/100) -> 5.9995351e+13 | O16: =IF(C16,H16*N16*IF(AND(Inputs!$B$4<>"pvp",Inputs!$B$35>0),((Skills!G16*((R16-1)*IF(Skills!H16>0,Skills!I16/Skills!H16,1)+IF(Skills!H16>0,MIN(Skills!I16,MAX(0,Inputs!$B$35-((R16-1)*IF(Inputs!$B$4="pvp",15,MAX(0.1,Skills!E16-IF(Skills!F16=TRUE,Inputs!$B$31,0))))))/Skills!H16,1)))/Inputs!$B$35),G16*Q16)*(1+IF(Inputs!$B$3>=126,0.05*(Summary!$B$64+Q13+(H14*Summary!$B$66)/(1+Skills!H14*H14*Summary!$B$66)+Q24),0)*Skills!E15)*IF(Inputs!$B$4="pvp",1,(1-Summary!$B$56)*(1)+Summary!$B$56*(MIN(Skills!R16,Inputs!$B$37))),0) -> 4.3004668e+14 | P16: =IF(Summary!$B$3=0,0,O16/Summary!$B$3) -> 0.051566923 | Q16: =IFERROR(1/IF(Inputs!$B$4="pvp",15,MAX(0.1,Skills!E16-IF(Skills!F16=TRUE,Inputs!$B$31,0))),0) -> 0.04 | R16: =IF(AND(Inputs!$B$4<>"pvp",Inputs!$B$35>0),(INT(Inputs!$B$35/IF(Inputs!$B$4="pvp",15,MAX(0.1,Skills!E16-IF(Skills!F16=TRUE,Inputs!$B$31,0))))+1),0) -> 0
A17: =Skills!A17 -> MAGIC_GUARD | B17: =Skills!B17 -> Magic Guard | C17: =TRUE -> TRUE | D17: =IF(Skills!C17=1,60+Inputs!$B$24+Inputs!$B$28,IF(Skills!C17=2,90+Inputs!$B$25+Inputs!$B$28,IF(Skills!C17=3,120+Inputs!$B$26+Inputs!$B$28,MAX(0,(Inputs!$B$3-100)*3)+Inputs!$B$27+Inputs!$B$28))) -> 115 | E17: =INDEX(FactorTable!$B$2:$Y$301, MATCH(ROUND(MIN(300,MAX(1,D17)),0), FactorTable!$A$2:$A$301,0), Skills!M17+1) -> 1460 | F17: =IF(Skills!N17=TRUE,(Skills!L17/10)*(E17/1000),Skills!L17/10)+Skills!O17 -> 17.52 | G17: =Skills!G17*IF(Skills!H17>0,Skills!I17/Skills!H17,1) -> 1 | H17: =1-(1-Skills!J17/100)^Skills!K17 -> 1 | I17: =IF(Skills!X17<>"",1+(Skills!X17/10)*($Z$3/1000)/100,1) -> 1 | O17: 0 | P17: =IF(Summary!$B$3=0,0,O17/Summary!$B$3) -> 0 | Q17: =IFERROR(1/IF(Inputs!$B$4="pvp",15,MAX(0.1,Skills!E17-IF(Skills!F17=TRUE,Inputs!$B$31,0))),0) -> 0.047619048 | R17: =IF(AND(Inputs!$B$4<>"pvp",Inputs!$B$35>0),(INT(Inputs!$B$35/IF(Inputs!$B$4="pvp",15,MAX(0.1,Skills!E17-IF(Skills!F17=TRUE,Inputs!$B$31,0))))+1),0) -> 0
A18: =Skills!A18 -> NIMBLE_FEET | B18: =Skills!B18 -> Nimble Feet | C18: =TRUE -> TRUE | D18: =IF(Skills!C18=1,60+Inputs!$B$24+Inputs!$B$28,IF(Skills!C18=2,90+Inputs!$B$25+Inputs!$B$28,IF(Skills!C18=3,120+Inputs!$B$26+Inputs!$B$28,MAX(0,(Inputs!$B$3-100)*3)+Inputs!$B$27+Inputs!$B$28))) -> 115 | E18: =INDEX(FactorTable!$B$2:$Y$301, MATCH(ROUND(MIN(300,MAX(1,D18)),0), FactorTable!$A$2:$A$301,0), Skills!M18+1) -> 0 | F18: =IF(Skills!N18=TRUE,(Skills!L18/10)*(E18/1000),Skills!L18/10)+Skills!O18 -> 15 | G18: =Skills!G18*IF(Skills!H18>0,Skills!I18/Skills!H18,1) -> 1 | H18: =1-(1-Skills!J18/100)^Skills!K18 -> 1 | I18: =IF(Skills!X18<>"",1+(Skills!X18/10)*($Z$3/1000)/100,1) -> 1 | O18: 0 | P18: =IF(Summary!$B$3=0,0,O18/Summary!$B$3) -> 0 | Q18: =IFERROR(1/IF(Inputs!$B$4="pvp",15,MAX(0.1,Skills!E18-IF(Skills!F18=TRUE,Inputs!$B$31,0))),0) -> 0.016666667 | R18: =IF(AND(Inputs!$B$4<>"pvp",Inputs!$B$35>0),(INT(Inputs!$B$35/IF(Inputs!$B$4="pvp",15,MAX(0.1,Skills!E18-IF(Skills!F18=TRUE,Inputs!$B$31,0))))+1),0) -> 0
A19: =Skills!A19 -> INFINITY | B19: =Skills!B19 -> Infinity | C19: =Inputs!$B$3>=110 -> TRUE | D19: =IF(Skills!C19=1,60+Inputs!$B$24+Inputs!$B$28,IF(Skills!C19=2,90+Inputs!$B$25+Inputs!$B$28,IF(Skills!C19=3,120+Inputs!$B$26+Inputs!$B$28,MAX(0,(Inputs!$B$3-100)*3)+Inputs!$B$27+Inputs!$B$28))) -> 172 | E19: =INDEX(FactorTable!$B$2:$Y$301, MATCH(ROUND(MIN(300,MAX(1,D19)),0), FactorTable!$A$2:$A$301,0), Skills!M19+1) -> 1688 | F19: =IF(Skills!N19=TRUE,(Skills!L19/10)*(E19/1000),Skills!L19/10)+Skills!O19 -> 36.573896 | G19: =Skills!G19*IF(Skills!H19>0,Skills!I19/Skills!H19,1) -> 1 | H19: =1-(1-Skills!J19/100)^Skills!K19 -> 1 | I19: =IF(Skills!X19<>"",1+(Skills!X19/10)*($Z$3/1000)/100,1) -> 1 | O19: 0 | P19: =IF(Summary!$B$3=0,0,O19/Summary!$B$3) -> 0 | Q19: =IFERROR(1/IF(Inputs!$B$4="pvp",15,MAX(0.1,Skills!E19-IF(Skills!F19=TRUE,Inputs!$B$31,0))),0) -> 0.033333333 | R19: =IF(AND(Inputs!$B$4<>"pvp",Inputs!$B$35>0),(INT(Inputs!$B$35/IF(Inputs!$B$4="pvp",15,MAX(0.1,Skills!E19-IF(Skills!F19=TRUE,Inputs!$B$31,0))))+1),0) -> 0
A20: =Skills!A20 -> MAGIC_CRITICAL_RATE | B20: =Skills!B20 -> Magic Critical (Crit Rate) | C20: =TRUE -> TRUE | D20: =IF(Skills!C20=1,60+Inputs!$B$24+Inputs!$B$28,IF(Skills!C20=2,90+Inputs!$B$25+Inputs!$B$28,IF(Skills!C20=3,120+Inputs!$B$26+Inputs!$B$28,MAX(0,(Inputs!$B$3-100)*3)+Inputs!$B$27+Inputs!$B$28))) -> 184 | E20: =INDEX(FactorTable!$B$2:$Y$301, MATCH(ROUND(MIN(300,MAX(1,D20)),0), FactorTable!$A$2:$A$301,0), Skills!M20+1) -> 1552 | F20: =IF(Skills!N20=TRUE,(Skills!L20/10)*(E20/1000),Skills!L20/10)+Skills!O20 -> 12.416 | G20: =Skills!G20*IF(Skills!H20>0,Skills!I20/Skills!H20,1) -> 1 | H20: =1-(1-Skills!J20/100)^Skills!K20 -> 1 | I20: =IF(Skills!X20<>"",1+(Skills!X20/10)*($Z$3/1000)/100,1) -> 1 | O20: 0 | P20: =IF(Summary!$B$3=0,0,O20/Summary!$B$3) -> 0 | Q20: =IFERROR(1/IF(Inputs!$B$4="pvp",15,MAX(0.1,Skills!E20-IF(Skills!F20=TRUE,Inputs!$B$31,0))),0) -> 10 | R20: 0
A21: =Skills!A21 -> MAGIC_CRITICAL_DAMAGE | B21: =Skills!B21 -> Magic Critical (Crit Damage) | C21: =TRUE -> TRUE | D21: =IF(Skills!C21=1,60+Inputs!$B$24+Inputs!$B$28,IF(Skills!C21=2,90+Inputs!$B$25+Inputs!$B$28,IF(Skills!C21=3,120+Inputs!$B$26+Inputs!$B$28,MAX(0,(Inputs!$B$3-100)*3)+Inputs!$B$27+Inputs!$B$28))) -> 184 | E21: =INDEX(FactorTable!$B$2:$Y$301, MATCH(ROUND(MIN(300,MAX(1,D21)),0), FactorTable!$A$2:$A$301,0), Skills!M21+1) -> 1552 | F21: =IF(Skills!N21=TRUE,(Skills!L21/10)*(E21/1000),Skills!L21/10)+Skills!O21 -> 18.624 | G21: =Skills!G21*IF(Skills!H21>0,Skills!I21/Skills!H21,1) -> 1 | H21: =1-(1-Skills!J21/100)^Skills!K21 -> 1 | I21: =IF(Skills!X21<>"",1+(Skills!X21/10)*($Z$3/1000)/100,1) -> 1 | O21: 0 | P21: =IF(Summary!$B$3=0,0,O21/Summary!$B$3) -> 0 | Q21: =IFERROR(1/IF(Inputs!$B$4="pvp",15,MAX(0.1,Skills!E21-IF(Skills!F21=TRUE,Inputs!$B$31,0))),0) -> 10 | R21: 0
A22: =Skills!A22 -> SPELL_MASTERY | B22: =Skills!B22 -> Spell Mastery | C22: =TRUE -> TRUE | D22: =IF(Skills!C22=1,60+Inputs!$B$24+Inputs!$B$28,IF(Skills!C22=2,90+Inputs!$B$25+Inputs!$B$28,IF(Skills!C22=3,120+Inputs!$B$26+Inputs!$B$28,MAX(0,(Inputs!$B$3-100)*3)+Inputs!$B$27+Inputs!$B$28))) -> 164 | E22: =INDEX(FactorTable!$B$2:$Y$301, MATCH(ROUND(MIN(300,MAX(1,D22)),0), FactorTable!$A$2:$A$301,0), Skills!M22+1) -> 1492 | F22: =IF(Skills!N22=TRUE,(Skills!L22/10)*(E22/1000),Skills!L22/10)+Skills!O22 -> 22.38 | G22: =Skills!G22*IF(Skills!H22>0,Skills!I22/Skills!H22,1) -> 1 | H22: =1-(1-Skills!J22/100)^Skills!K22 -> 1 | I22: =IF(Skills!X22<>"",1+(Skills!X22/10)*($Z$3/1000)/100,1) -> 1 | O22: 0 | P22: =IF(Summary!$B$3=0,0,O22/Summary!$B$3) -> 0 | Q22: =IFERROR(1/IF(Inputs!$B$4="pvp",15,MAX(0.1,Skills!E22-IF(Skills!F22=TRUE,Inputs!$B$31,0))),0) -> 10 | R22: 0
A23: =Skills!A23 -> ELEMENT_AMPLIFICATION | B23: =Skills!B23 -> Element Amplification | C23: =TRUE -> TRUE | D23: =IF(Skills!C23=1,60+Inputs!$B$24+Inputs!$B$28,IF(Skills!C23=2,90+Inputs!$B$25+Inputs!$B$28,IF(Skills!C23=3,120+Inputs!$B$26+Inputs!$B$28,MAX(0,(Inputs!$B$3-100)*3)+Inputs!$B$27+Inputs!$B$28))) -> 172 | E23: =INDEX(FactorTable!$B$2:$Y$301, MATCH(ROUND(MIN(300,MAX(1,D23)),0), FactorTable!$A$2:$A$301,0), Skills!M23+1) -> 1516 | F23: =IF(Skills!N23=TRUE,(Skills!L23/10)*(E23/1000),Skills!L23/10)+Skills!O23 -> 22.74 | G23: =Skills!G23*IF(Skills!H23>0,Skills!I23/Skills!H23,1) -> 1 | H23: =1-(1-Skills!J23/100)^Skills!K23 -> 1 | I23: =IF(Skills!X23<>"",1+(Skills!X23/10)*($Z$3/1000)/100,1) -> 1 | O23: 0 | P23: =IF(Summary!$B$3=0,0,O23/Summary!$B$3) -> 0 | Q23: =IFERROR(1/IF(Inputs!$B$4="pvp",15,MAX(0.1,Skills!E23-IF(Skills!F23=TRUE,Inputs!$B$31,0))),0) -> 10 | R23: 0
