Workbook

Sheet README
A1: Arch Mage (Ice/Lightning) — DPS Calculator: How to Use This Workbook
A3: How to use this workbook
A4: Only edit the yellow-highlighted cells on the Inputs sheet — every other sheet is computed from those values and will be overwritten if you rebuild the workbook.
A5: Summary shows Total DPS, a Per-Skill DPS Breakdown (damage-dealing skills only — buffs/passives that never deal their own damage are omitted), and a Marginal DPS & Stat Value table showing the DPS gained per +1 of each stat.
A6: Sensitivity has the full detail behind that marginal-value table — one self-contained block per stat, showing exactly how bumping that stat by +1 changes every downstream number.
A7: CubeData/PotentialCubes model your current gear's Potential Cube lines and drive cube-reroll expected-value decisions. For the full standalone Potential Cube EV calculator (exact optimal-stopping math, works from this workbook alone), see tools/potential_cubes_ev.py in the project repo.
A9: Design decisions & assumptions
A10: Freezing Breath's Weaken debuff and Elemental Reset's own Damage Taken bonus assume the target is permanently afflicted at steady state, not an exact on/off timer.
A11: Crit Rate pushed above 100% (e.g. by cube potential lines) automatically redirects its stat-value to Crit Damage's own per-unit DPS value on the PotentialCubes sheet, since excess Crit Rate cannot do anything past 100%.
A12: Buffs (Magic Guard, Meditation, Infinity) are modeled at steady-state duty-cycle average uptime, not as an exact moment-to-moment state machine.
A13: Monster Type blends Boss/Normal Monster Damage% by the Chapter Breakthrough weight %; PvP forces a fixed 15-second window regardless of the Fixed Fight Duration input.
A14: Not modeled (out of scope): crowd control, Accuracy/Evasion/Defense reduction, movement speed, the character's own Defense stat, and Companion Summoning Time.

Sheet Inputs
A1: Arch Mage (Ice/Lightning) — DPS Calculator Inputs
A3: Character Level | B3: 200
A4: Monster Type ("boss", "normal", "breakthrough", or "pvp") | B4: boss
A5: Flat ATTACK | B5: 10000
A6: ATTACK % | B6: 0
A7: Monster Defense (flat, post-x100/x10 scaling) | B7: 0
A8: CRIT_RATE % | B8: 0
A9: CRIT_DAMAGE % | B9: 0
A10: ATTACK_SPEED % (base, excludes Nimble Feet/MP Eater) | B10: 0
A11: Flat INT | B11: 0
A12: INT % | B12: 0
A13: LUK | B13: 0
A14: DAMAGE % | B14: 0
A15: DAMAGE_AMP % | B15: 0
A16: BASIC_ATTACK_DAMAGE % | B16: 0
... A28: Skill Level Bonus — All Skills | B28: 0
A30: Additional Bonuses
A31: Skill Cooldown Decrease (seconds, only skills/buffs the character actively casts) | B31: 0
A32: Basic Attack Target Increase (flat, adds to the 6-target normal-monster base) | B32: 1
A33: Buff Duration Increase % | B33: 0
A34: Companion Summoning Time Increase % (companions not modeled — always 0 DPS impact) | B34: 0
A35: Fixed Fight Duration (seconds, boss or normal — leave 0 for steady-state DPS; ignored for pvp) | B35: 0
A36: Chapter Breakthrough: Normal-Monster Weight % (only used when Monster Type = breakthrough) | B36: 60
A37: Max Enemies Actually In Range (normal monsters only; default 999 = uncapped) | B37: 999

Sheet FactorTable
A1: Level | B1: F0 | C1: F1 | D1: F2 | E1: F3 | F1: F4 | G1: F5 | H1: F6 | I1: F7 | J1: F8 | K1: F9 | L1: F10 | M1: F11 | N1: F12 | O1: F13 | P1: F14 | Q1: F15 | R1: F16 | S1: F17 | T1: F18 | U1: F19 | V1: F20 | W1: F21 | X1: F22 | Y1: F23
A2: 1 | B2: 0 | C2: 1000 | D2: 1000 | E2: 1000 | F2: 1000 | G2: 1000 | H2: 1000 | I2: 1000 | J2: 1000 | K2: 1000 | L2: 1000 | M2: 1000 | N2: 1000 | O2: 1000 | P2: 1000 | Q2: 1000 | R2: 1000 | S2: 1000 | T2: 1000 | U2: 1000 | V2: 1000 | W2: 1000 | X2: 1000 | Y2: 1000
A3: 2 | B3: 0 | C3: 1015 | D3: 1020 | E3: 1030 | F3: 1040 | G3: 1050 | H3: 1060 | I3: 1070 | J3: 1020 | K3: 1020 | L3: 1020 | M3: 1000 | N3: 1010 | O3: 1020 | P3: 1030 | Q3: 1040 | R3: 1050 | S3: 1060 | T3: 1070 | U3: 1080 | V3: 1010 | W3: 1008 | X3: 1006 | Y3: 1100
A4: 3 | B4: 0 | C4: 1031 | D4: 1041 | E4: 1061 | F4: 1082 | G4: 1103 | H4: 1124 | I4: 1145 | J4: 1030 | K4: 1041 | L4: 1030 | M4: 1000 | N4: 1015 | O4: 1030 | P4: 1045 | Q4: 1060 | R4: 1075 | S4: 1090 | T4: 1105 | U4: 1120 | V4: 1020 | W4: 1012 | X4: 1009 | Y4: 1150
A5: 4 | B5: 0 | C5: 1047 | D5: 1062 | E5: 1093 | F5: 1126 | G5: 1159 | H5: 1192 | I5: 1226 | J5: 1040 | K5: 1062 | L5: 1040 | M5: 1000 | N5: 1020 | O5: 1040 | P5: 1060 | Q5: 1080 | R5: 1100 | S5: 1120 | T5: 1140 | U5: 1160 | V5: 1030 | W5: 1016 | X5: 1012 | Y5: 1200
A6: 5 | B6: 0 | C6: 1063 | D6: 1084 | E6: 1126 | F6: 1172 | G6: 1217 | H6: 1264 | I6: 1312 | J6: 1050 | K6: 1084 | L6: 1050 | M6: 1000 | N6: 1025 | O6: 1050 | P6: 1075 | Q6: 1100 | R6: 1125 | S6: 1150 | T6: 1175 | U6: 1200 | V6: 1040 | W6: 1020 | X6: 1015 | Y6: 1250
A7: 6 | B7: 0 | C7: 1079 | D7: 1106 | E7: 1160 | F7: 1219 | G7: 1278 | H7: 1340 | I7: 1404 | J7: 1060 | K7: 1106 | L7: 1060 | M7: 1000 | N7: 1030 | O7: 1060 | P7: 1090 | Q7: 1120 | R7: 1150 | S7: 1180 | T7: 1210 | U7: 1240 | V7: 1050 | W7: 1024 | X7: 1018 | Y7: 1300
A8: 7 | B8: 0 | C8: 1096 | D8: 1129 | E8: 1195 | F8: 1268 | G8: 1342 | H8: 1421 | I8: 1503 | J8: 1070 | K8: 1129 | L8: 1070 | M8: 1000 | N8: 1035 | O8: 1070 | P8: 1105 | Q8: 1140 | R8: 1175 | S8: 1210 | T8: 1245 | U8: 1280 | V8: 1060 | W8: 1028 | X8: 1021 | Y8: 1350
A9: 8 | B9: 0 | C9: 1113 | D9: 1152 | E9: 1231 | F9: 1319 | G9: 1410 | H9: 1507 | I9: 1609 | J9: 1080 | K9: 1152 | L9: 1080 | M9: 1000 | N9: 1040 | O9: 1080 | P9: 1120 | Q9: 1160 | R9: 1200 | S9: 1240 | T9: 1280 | U9: 1320 | V9: 1070 | W9: 1032 | X9: 1024 | Y9: 1400
A10: 9 | B10: 0 | C10: 1130 | D10: 1176 | E10: 1268 | F10: 1372 | G10: 1481 | H10: 1598 | I10: 1722 | J10: 1090 | K10: 1176 | L10: 1090 | M10: 1000 | N10: 1045 | O10: 1090 | P10: 1135 | Q10: 1180 | R10: 1225 | S10: 1270 | T10: 1315 | U10: 1360 | V10: 1080 | W10: 1036 | X10: 1027 | Y10: 1450
A11: 10 | B11: 0 | C11: 1147 | D11: 1200 | E11: 1307 | F11: 1427 | G11: 1556 | H11: 1694 | I11: 1843 | J11: 1100 | K11: 1200 | L11: 1100 | M11: 1000 | N11: 1050 | O11: 1100 | P11: 1150 | Q11: 1200 | R11: 1250 | S11: 1300 | T11: 1350 | U11: 1400 | V11: 1090 | W11: 1040 | X11: 1030 | Y11: 1500
A12: 11 | B12: 0 | C12: 1165 | D12: 1224 | E12: 1347 | F12: 1485 | G12: 1634 | H12: 1796 | I12: 1973 | J12: 1110 | K12: 1224 | L12: 1110 | M12: 1000 | N12: 1055 | O12: 1110 | P12: 1165 | Q12: 1220 | R12: 1275 | S12: 1330 | T12: 1385 | U12: 1440 | V12: 1100 | W12: 1044 | X12: 1033 | Y12: 1550
A13: 12 | B13: 0 | C13: 1183 | D13: 1249 | E13: 1388 | F13: 1545 | G13: 1716 | H13: 1904 | I13: 2112 | J13: 1120 | K13: 1249 | L13: 1120 | M13: 1000 | N13: 1060 | O13: 1120 | P13: 1180 | Q13: 1240 | R13: 1300 | S13: 1360 | T13: 1420 | U13: 1480 | V13: 1110 | W13: 1048 | X13: 1036 | Y13: 1600
... A301: 300 | B301: 0 | C301: 88573 | D301: 381637 | E301: 6991522 | F301: 125363453 | G301: 2185120762 | H301: 37157073039 | I301: 614631863830 | J301: 2000 | K301: 53326 | L301: 2500 | M301: 1100 | N301: 2500 | O301: 4000 | P301: 5500 | Q301: 7000 | R301: 8500 | S301: 10000 | T301: 11500 | U301: 13000 | V301: 7558 | W301: 2200 | X301: 1900 | Y301: 8800

Sheet Skills
A1: Key | B1: Name | C1: JobStep | D1: Cooldown(s) | E1: CostsActionSlot | F1: HitsPerCast | G1: ICD(s) | H1: ActiveWindow(s) | I1: ProcChance% | J1: RollsPerCast | K1: BaseDamage(tenths%) | L1: FactorIndex | M1: ScalesWithLevel | N1: SkillMasteryBonus% | O1: MasteryBossDamage% | P1: MasteryNormalDamage% | Q1: NormalMonsterTargets | R1: BuffTargetStat | S1: BuffDuration(s) | T1: MapleHeroBase(tenths%) | U1: MapleHeroFactorIndex | V1: Stacks | W1: Note
A2: CHAIN_LIGHTNING | B2: Chain Lightning | C2: 4 | E2: FALSE | F2: =IF(Inputs!$B$3>=136,6,5) | G2: 0 | H2: 0 | I2: 100 | J2: 1 | M2: TRUE | N2: =SUMPRODUCT((Inputs!$B$3>={102,106,116,120,128,132})*{10,1,1,1,1,1}) | O2: =SUMPRODUCT((Inputs!$B$3>={111,124})*{10,10}) | P2: 0 | Q2: =6+Inputs!$B$32 | S2: 0 | W2: 4th-job basic-attack effect (supersedes Energy Bolt/Cold Beam/Ice Strike, out of scope per the project's job-tier-is-gone convention). Wiki: 290%->522% (levels 1-200) to 6 target(s) 5 time(s) — factorIndex 21, baseDamage 2900 tenths%, matching Inputs!skill_coefficient (=290*basic_factor/1000) exactly, so this row's own coefficient is just that Inputs value + SkillMasteryBonus% (same mechanism as FP-Mage/Night Lord's own Basic Attack/Showdown rows). SkillMasteryBonus% is the 6-tier 'Chain Lightning - Damage' mastery chain (102/106/116/120/128/132), cumulative totals 10%->15% per the game's own tooltip convention, so level_gated_sum uses DELTA increments (10, then +1 five times). MasteryBossDamage% is the 2-tier 'Chain Lightning - Boss Monster Damage' chain (111/124), each independently +10%, totaling +20%. HitsPerCast 5->6 once the level-136 'Strike' mastery unlocks.
A3: MAGIC_GUARD | B3: Magic Guard | C3: 1 | D3: =IF(Inputs!$B$3>=21,30*0.7,30) | E3: TRUE | F3: 1 | G3: 0 | H3: 0 | I3: 100 | J3: 1 | K3: 120 | L3: 21 | M3: TRUE | N3: 0 | O3: 0 | P3: 0 | Q3: 1 | R3: ATTACK | S3: 15 | W3: Self-buff, +12%->16.8% Attack (levels 1-100), 15s duration/30s cooldown (Mastery Lv.21 'Magic Guard - Reuse' -30% cooldown -> 21s, baked directly into the Cooldown(s) formula). factorIndex 21, baseDamage 120 tenths%. Shared w/ FP-Mage.
A4: MEDITATION | B4: Meditation | C4: 2 | D4: 30 | E4: TRUE | F4: 1 | G4: 0 | H4: 0 | I4: 100 | J4: 1 | K4: 200 | L4: 21 | M4: TRUE | N4: 0 | O4: 0 | P4: 0 | Q4: 1 | R4: ATTACK | S4: =IF(Inputs!$B$3>=44,15*1.3,15) | W4: Self-buff, +20%->28% Attack (levels 1-100), 15s duration (Mastery Lv.44 'Meditation - Persistence' +30% duration -> 19.5s, baked directly into the BuffDuration(s) formula), 30s cooldown. factorIndex 21, baseDamage 200 tenths%. Shared w/ FP-Mage.
A5: THUNDER_BOLT | B5: Thunder Bolt | C5: 2 | D5: 18 | E5: TRUE | F5: 3 | G5: 0 | H5: 0 | I5: 100 | J5: 1 | K5: 1800 | L5: 12 | M5: TRUE | N5: =SUMPRODUCT((Inputs!$B$3>={39})*{70}) | O5: 0 | P5: 0 | Q5: 8 | S5: 0 | T5: 1000 | U5: 23 | W5: Wiki: 180%->270% (levels 1-100) to 8 target(s) 3 time(s), cooldown 18s. factorIndex 12, baseDamage 1800 tenths%. Mastery Lv.39 'Thunder Bolt - Damage' +70% (single-tier, real SkillMasteryBonus%). Maple Hero (Ice/Lightning) target: 100%->780% (levels 1-200), factorIndex 23, baseDamage 1000 tenths% (jointly reverse-engineered with Glacier Wall's and Thunder Sphere's own Maple Hero curves, confirmed same factorIndex).
A6: GLACIER_WALL | B6: Glacier Wall | C6: 3 | D6: =IF(Inputs!$B$3>=90,22*0.7,22) | E6: TRUE | F6: 3 | G6: 0 | H6: 0 | I6: 100 | J6: 1 | K6: 2900 | L6: 12 | M6: TRUE | N6: =SUMPRODUCT((Inputs!$B$3>={68})*{80}) | O6: 0 | P6: 0 | Q6: 8 | S6: 0 | T6: 300 | U6: 23 | W6: Wiki: 290%->580% (levels 1-200) to 8 target(s) 3 time(s), freezing them for 2s (freeze not modeled — no CC mechanic anywhere in this calculator), cooldown 22s. factorIndex 12, baseDamage 2900 tenths%. Mastery Lv.68 'Glacier Wall - Damage' +80% (real SkillMasteryBonus%), Lv.90 'Glacier Wall - Reuse' -30% cooldown -> 15.4s (baked into the Cooldown(s) formula). Maple Hero target: 30%->234% (levels 1-200), factorIndex 23, baseDamage 300 tenths%.
A7: THUNDER_SPHERE | B7: Thunder Sphere | C7: 3 | D7: =IF(Inputs!$B$3>=78,30*0.7,30) | E7: TRUE | F7: 3 | G7: =IF(Inputs!$B$3>=104,2*0.7,2) | H7: 10 | I7: 100 | J7: 1 | K7: 1000 | L7: 12 | M7: TRUE | N7: =SUMPRODUCT((Inputs!$B$3>={73})*{50}) | O7: 0 | P7: =150+SUMPRODUCT((Inputs!$B$3>={94})*{100}) | Q7: 6 | S7: 0 | T7: 200 | U7: 23 | W7: Wiki: 100%->200% (levels 1-200) to 6 target(s) 3 time(s) every 2s, for a 10s duration, cooldown 30s. factorIndex 12, baseDamage 1000 tenths%. Skill-intrinsic (unconditional, NOT mastery-gated) +150% Normal Monster Damage baked directly into this row's own MasteryNormalDamage% field, PLUS Mastery Lv.94's +100%p on top (so the field itself is '150 + level_gated_sum'). Mastery Lv.73 'Thunder Sphere - Damage' +50% (real SkillMasteryBonus%), Lv.78 'Thunder Sphere - Reuse' -30% cooldown -> 21s, Lv.104 'Thunder Sphere - Strike Interval' -30% tick interval (2s->1.4s, baked into the ICD(s) formula). Maple Hero target: 20%->200% (levels 1-200), factorIndex 23, baseDamage 200 tenths%.
A8: FREEZING_BREATH | B8: Freezing Breath | C8: 4 | D8: 40 | E8: TRUE | F8: 1 | G8: 0.5 | H8: 5 | I8: 100 | J8: 1 | K8: 8000 | L8: 12 | M8: TRUE | N8: =SUMPRODUCT((Inputs!$B$3>={108})*{50}) | O8: 0 | P8: 0 | Q8: 10 | S8: 0 | W8: Wiki: 800%->1600% (levels 1-200) to 10 target(s) every 0.5s for a 5s duration, cooldown 45s (patched -> 40s, Aug 13 2026 patch note — the wiki page itself is stale). factorIndex 12, baseDamage 8000 tenths%. EffectiveHits = 1*(5/0.5) = 10 ticks per cast. Mastery Lv.108 'Freezing Breath - Damage' +50% (real SkillMasteryBonus%). Mastery Lv.118 'Freezing Breath - Weaken' (+15% Damage Taken debuff, 30s) is NOT part of this row — it's a separate global Summary-sheet duty-cycle-averaged monster-damage bonus (see build_summary_sheet, mirrors Night Lord's Venom Lv.82/Frailty Curse Debuff precedent), added in a later build stage.
A9: BLIZZARD | B9: Blizzard | C9: 4 | D9: 33 | E9: TRUE | F9: 3 | G9: 0 | H9: 0 | I9: 100 | J9: 1 | K9: 6000 | L9: 12 | M9: TRUE | N9: =SUMPRODUCT((Inputs!$B$3>={130})*{40}) | O9: 0 | P9: 0 | Q9: 7 | S9: 0 | W9: Wiki: 600%->1200% (levels 1-200) to 5 target(s) 3 time(s) (patched targets 5->7, Aug 13 2026 patch note — the wiki page is stale), cooldown 33s. factorIndex 12, baseDamage 6000 tenths%. Mastery Lv.130 (corrected name/description pairing — wiki mismatch resolved via content-matching, see the plan) 'Blizzard - Damage' +40% flat (real SkillMasteryBonus%). Mastery Lv.113 'Blizzard - Final Attack' is its own separate proc row, see BLIZZARD_FINAL_ATTACK below, not part of this row's own fields.
A10: BLIZZARD_FINAL_ATTACK | B10: Blizzard - Final Attack (Mastery Lv.113) | C10: 4 | D10: =Skills!D9 | E10: FALSE | F10: 1 | G10: 0 | H10: 0 | I10: 30 | J10: 3 | K10: 9500 | L10: 21 | M10: TRUE | N10: 0 | O10: 0 | P10: 0 | Q10: 1 | S10: 0 | W10: Standalone proc row, mirrors FP-Mage's own METEOR_PROC row structure but simpler: procs only off Blizzard's own casts (per the wiki's own '[Blizzard in Slot] When attacking, deals...' phrasing — self-contained, not a multi-skill trigger set), so it shares Blizzard's own live Cooldown(s) cell directly instead of needing an external combined-cast-rate formula. Wiki formula ({#expr:750*(1+x*0.004)}%, patched base 750->950%, chance 20%->30%): reverse-engineered as factorIndex 21, baseDamage 9500 tenths% (950%, already the patched value). RollsPerCast=3 (Blizzard's own 3 hits, each an independent 30% roll -> ProcProbability = 1-(1-0.3)^3 = 65.7% chance per Blizzard cast), ICD(s)=0 (already capped to at most one proc per Blizzard cast via HitsPerCast=1, no further ICD needed). Single-target (NormalMonsterTargets=1), matching FP-Mage's own Meteor Proc precedent for an 'additional damage on a hit' style proc, absent any wiki text specifying a target count of its own.
A11: FROZEN_ORB | B11: Frozen Orb | C11: 4 | D11: 23 | E11: TRUE | F11: 1 | G11: =IF(Inputs!$B$3>=134,0.5*0.5,0.5) | H11: 6 | I11: 100 | J11: 1 | K11: 9000 | L11: 12 | M11: TRUE | N11: =SUMPRODUCT((Inputs!$B$3>={122})*{50}) | O11: 0 | P11: 0 | Q11: 10 | S11: 0 | W11: Wiki: 900%->1800% (levels 1-200) to 10 target(s) every 0.5s for a 5s duration (patched -> 6s, Aug 13 2026 patch note), cooldown 23s. factorIndex 12, baseDamage 9000 tenths%. 'If there is 1 target near the orb, the damage is halved' — a single-target (boss) halving mechanic implemented ONLY in this row's own Calc!O (DPS) formula in a later build stage (x0.5 when monster_type=boss, x1 otherwise), not a Skills-sheet field. Mastery Lv.122 'Frozen Orb - Damage' +50% (real SkillMasteryBonus%), Lv.134 (corrected name/description pairing) 'Frozen Orb - Strike Interval' -50% tick interval (0.5s->0.25s, baked into the ICD(s) formula).
A12: ELQUINES | B12: Elquines | C12: 4 | D12: 80 | E12: TRUE | F12: 1 | G12: =IF(Inputs!$B$3>=126,4*0.8,4) | H12: 30 | I12: 100 | J12: 1 | K12: 35000 | L12: 12 | M12: TRUE | N12: =SUMPRODUCT((Inputs!$B$3>={138})*{50}) | O12: 0 | P12: 0 | Q12: =IF(Inputs!$B$3>=138,6,3) | S12: 0 | W12: Summon, wiki: 3500%->7000% (levels 1-200) to 3 target(s) every 4s for a 30s duration, cooldown 80s. factorIndex 12, baseDamage 35000 tenths%. Mastery Lv.126 (corrected name/description pairing, user-confirmed 20% not the wiki's typo'd 0.2%) 'Elquines - Strike Interval' -20% attack interval (4s->3.2s, baked into the ICD(s) formula), Lv.138 'Elquines - Damage & Target' +50% damage (real SkillMasteryBonus%) AND +3 max targets (3->6, baked into the NormalMonsterTargets formula).
A13: MP_EATER_MP_BOOST | B13: MP Eater - MP Boost (Mastery Lv.49) | C13: 2 | E13: FALSE | F13: 1 | G13: 0 | H13: 0 | I13: 100 | J13: 1 | K13: 70 | L13: 0 | M13: FALSE | N13: 0 | O13: 0 | P13: 0 | Q13: 1 | S13: 0 | W13: Mastery-only row (MP Eater's own base MP-recovery mechanic is not modeled — MP isn't tracked anywhere in this calculator). Flat +7% Attack Speed once unlocked (level 49, see UNLOCK_LEVEL's own note on the 47-vs-49 discrepancy), ignoring the MP>=50% condition per the user's always-on decision (same treatment as Element Amplification). This IS a real, always-on contributor (NOT baked into Inputs, unlike the Magic-Critical-pattern rows below) — folds into the Attack Speed diminishing-returns stack in Summary once unlocked, with no uptime averaging (it's a permanent passive, not a timed buff — BuffTargetStat deliberately left blank so the generic buff-uptime machinery doesn't try to average it; Summary reads this row's Calc!F and Calc!C directly instead). FactorIndex is an unused placeholder (ScalesWithLevel=False), same convention as Nimble Feet's own non-scaling row in FP-Mage/Night Lord.
A14: ELEMENTAL_RESET | B14: Elemental Reset | C14: 3 | E14: FALSE | F14: 1 | G14: 0 | H14: 0 | I14: =IF(Inputs!$B$3>=82,50,25) | J14: 1 | K14: 120 | L14: 22 | M14: TRUE | N14: 0 | O14: 0 | P14: 0 | Q14: 1 | S14: 7 | W14: User-confirmed: this is the patch note's 'Elemental Decrease' entry (patched base chance 20%->25%, base Damage Taken 10%->12% — the wiki's own 10%->16% curve rescaled by the patch's 12/10=1.2x factor, giving the reverse-engineered factorIndex 22/baseDamage 120 used here, which already reflects the patched 12%->19.2% curve). Mastery Lv.82 'Elemental Reset - Chance' doubles the PATCHED chance (25%->50%, NOT the stale wiki 20%->40%). Modeled always-on (100% uptime), same precedent as FP-Mage's own Elemental Decrease — ProcChance%/BuffDuration(s) here are reference-only, they do not feed the Summary formula (which instead just adds Calc!F/100 as an unconditional multiplier).
A15: ELEMENT_AMPLIFICATION | B15: Element Amplification | C15: 3 | E15: FALSE | F15: 1 | G15: 0 | H15: 0 | I15: 100 | J15: 1 | K15: 150 | L15: 22 | M15: TRUE | N15: 0 | O15: 0 | P15: 0 | Q15: 1 | R15: FINAL_DAMAGE | S15: 0 | W15: Wiki: +15%->24% Final Damage (levels 1-200), unconditional (ignore the MP>=50% condition and MP-cost increase per the user's decision, matching FP-Mage's own established treatment of this exact shared-kit passive). factorIndex 22, baseDamage 150 tenths%. Not reflected anywhere in Inputs — added directly into the Final Damage chain (multiplied in, same as Arcane Aim/Element Amplification are combined in FP-Mage) in a later build stage.
A16: INFINITY | B16: Infinity | C16: 4 | D16: 30 | E16: TRUE | F16: 1 | G16: 0 | H16: 0 | I16: 100 | J16: 1 | K16: 150 | L16: 21 | M16: TRUE | N16: 0 | O16: 0 | P16: 0 | Q16: 1 | R16: FINAL_DAMAGE | S16: 15 | W16: Wiki: base +15%->27% Final Damage for 15s, ADDITIONALLY +1%->1.8% per second, stacking up to 10 times (levels 1-200), cooldown 30s. Both curves reverse-engineered independently: base factorIndex 21/baseDamage 150 tenths%, increment factorIndex 21/baseDamage 10 tenths% — the increment is EXACTLY base/15 at every sampled level (zero residual error), confirming the ramp is a fixed fraction of the base, not an independently-scaled curve. Time-averaged stacks over the 15s window = (0+1+...+9+10*5)/15 = 6.3333, so the time-averaged total = base*(1+6.3333/15) = base*64/45 exactly. This row's own Calc!F needs a BESPOKE formula in build_calc_sheet (base_pct * 64/45, using the single factorIndex-21 lookup for 'base_pct') instead of the generic F-column formula every other row uses — flagged here so the Calc-sheet build stage doesn't miss it.
A17: MAGIC_ACCELERATION | B17: Magic Acceleration | C17: 2 | E17: FALSE | F17: 1 | G17: 0 | H17: 0 | I17: 100 | J17: 1 | K17: 50 | L17: 22 | M17: TRUE | N17: 0 | O17: 0 | P17: 0 | Q17: 1 | R17: ATTACK_SPEED | S17: 0 | W17: Permanent passive, +5%->6.5% Attack Speed (levels 1-100) — Magic Critical pattern, already baked into Inputs!ATTACK_SPEED%; this row only feeds the 2nd-Job Skill Level Bonus Sensitivity delta. factorIndex 22, baseDamage 50 tenths%.
A18: SPELL_MASTERY | B18: Spell Mastery | C18: 2 | E18: FALSE | F18: 1 | G18: 0 | H18: 0 | I18: 100 | J18: 1 | K18: 150 | L18: 22 | M18: TRUE | N18: 0 | O18: 0 | P18: 0 | Q18: 1 | R18: MIN_DAMAGE | S18: 0 | W18: Permanent passive, +15%->19.5% Min Damage Multiplier (levels 1-100) — Magic Critical pattern, already baked into Inputs!MIN_DAMAGE%; feeds the 2nd-Job Skill Level Bonus delta. factorIndex 22, baseDamage 150 tenths%.
A19: HIGH_WISDOM | B19: High Wisdom | C19: 2 | E19: FALSE | F19: 1 | G19: 0 | H19: 0 | I19: 100 | J19: 1 | K19: 80 | L19: 22 | M19: TRUE | N19: 0 | O19: 0 | P19: 0 | Q19: 1 | R19: CRIT_RATE | S19: 0 | W19: Permanent passive, +8%->10.4% Critical Rate (levels 1-100) — Magic Critical pattern, already baked into Inputs!CRIT_RATE% (jointly with Magic Critical (Crit Rate) below, both are separate skills contributing to the same Inputs field); feeds the 2nd-Job Skill Level Bonus delta. factorIndex 22, baseDamage 80 tenths%.
A20: MAGIC_CRITICAL_RATE | B20: Magic Critical (Crit Rate) | C20: 3 | E20: FALSE | F20: 1 | G20: 0 | H20: 0 | I20: 100 | J20: 1 | K20: 80 | L20: 22 | M20: TRUE | N20: 0 | O20: 0 | P20: 0 | Q20: 1 | R20: CRIT_RATE | S20: 0 | W20: Permanent passive, +8%->12.8% Critical Rate (levels 1-200) — Magic Critical pattern, already baked into Inputs!CRIT_RATE%; feeds the 3rd-Job Skill Level Bonus delta. factorIndex 22, baseDamage 80 tenths%.
A21: MAGIC_CRITICAL_DAMAGE | B21: Magic Critical (Crit Damage) | C21: 3 | E21: FALSE | F21: 1 | G21: 0 | H21: 0 | I21: 100 | J21: 1 | K21: 120 | L21: 22 | M21: TRUE | N21: 0 | O21: 0 | P21: 0 | Q21: 1 | R21: CRIT_DAMAGE | S21: 0 | W21: Same skill as Magic Critical (Crit Rate) above, +12%->19.2% Critical Damage (levels 1-200) — Magic Critical pattern, already baked into Inputs!CRIT_DAMAGE%; feeds the 3rd-Job Skill Level Bonus delta. factorIndex 22, baseDamage 120 tenths%.
A22: BUFF_MASTERY | B22: Buff Mastery | C22: 4 | E22: FALSE | F22: 1 | G22: 0 | H22: 0 | I22: 100 | J22: 1 | K22: 100 | L22: 22 | M22: TRUE | N22: 0 | O22: 0 | P22: 0 | Q22: 1 | S22: 0 | W22: Permanent passive (unlocked level 117), +10%->16% Buff Duration (levels 1-200) — not reflected anywhere in Inputs, so its current value (Calc!F) is added directly into every uptime_fraction_expr call's Buff Duration Increase % term (see bdi_with_buff_mastery_expr, already defined above). factorIndex 22, baseDamage 100 tenths%. Shared w/ FP-Mage.
A23: ARCANE_AIM | B23: Arcane Aim | C23: 4 | E23: FALSE | F23: 1 | G23: 0 | H23: 0 | I23: 100 | J23: 1 | K23: 30 | L23: 22 | M23: TRUE | N23: 0 | O23: 0 | P23: 0 | Q23: 1 | S23: 0 | W23: Permanent passive (unlocked level 120), 25% chance per attack for +3%->4.8% Final Damage (levels 1-200) for 10s, stacking up to 5 times — modeled as always at max 5 stacks (same always-on-proc-stack precedent as Elemental Reset/FP-Mage's own Arcane Aim). Combined MULTIPLICATIVELY into the Final Damage chain as (1+Calc!F/100)^5 in a later build stage. factorIndex 22, baseDamage 30 tenths%. Shared w/ FP-Mage.

Sheet Calc
A1: Key | B1: Name | C1: Unlocked | D1: InputLevel | E1: Factor | F1: CoefficientPercent | G1: EffectiveHits | H1: ProcProbability | I1: MapleHeroMultiplier | J1: BaseDamage | K1: BaseHitDamage | L1: NonCritAvg | M1: CritAvg | N1: ExpectedDamage(perHit) | O1: DPS | P1: % of Total | Q1: InvCooldown | R1: CastsInFight | Z1: Maple Hero helper (jobStep4, factorIndex23)
A2: =Skills!A2 | B2: =Skills!B2 | C2: =Inputs!$B$3>=100 | F2: =Summary!$B$50+Skills!N2 | G2: =Skills!F2*IF(Skills!G2>0,Skills!H2/Skills!G2,1) | H2: =1-(1-Skills!I2/100)^Skills!J2 | I2: =IF(Skills!T2<>"",1+(Skills!T2/10)*($Z$3/1000)/100,1) | J2: =Summary!$B$46*(F2/100) | K2: =J2*(1+Summary!$B$47/100)*(1+(Inputs!$B$14+Summary!$B$55)/100)*(1+IF(Inputs!$B$4="pvp",0,(1-Summary!$B$51)*(Inputs!$B$19+Skills!O2+Summary!$B$54)+Summary!$B$51*(Inputs!$B$20+Skills!P2+Summary!$B$54))/100)*(1+Inputs!$B$15/100)*(5000/(6000+Inputs!$B$7*(1-Inputs!$B$18/100)))*(1+Inputs!$B$23/100)*(1+IF(C15=TRUE,F15,0)/100)*(1+IF(C23=TRUE,F23,0)/100)^5*(1+(IF(Skills!A2="CHAIN_LIGHTNING",Inputs!$B$16,Inputs!$B$17))/100)*(Summary!$B$53*I2) | L2: =K2*(MIN(Inputs!$B$21,Inputs!$B$22)/100+Inputs!$B$22/100)/2 | M2: =L2*(1+Inputs!$B$9/100) | N2: =L2*(1-MIN(Inputs!$B$8,100)/100)+M2*(MIN(Inputs!$B$8,100)/100) | O2: =IF(C2,Skills!F2*N2*Summary!$B$59*IF(Inputs!$B$4="pvp",1,(1-Summary!$B$51)*(1)+Summary!$B$51*(MIN(Skills!Q2,Inputs!$B$37))),0) | P2: =IF(Summary!$B$3=0,0,O2/Summary!$B$3) | Q2: =IFERROR(1/IF(Inputs!$B$4="pvp",15,MAX(0.1,Skills!D2-IF(Skills!E2=TRUE,Inputs!$B$31,0))),0) | R2: 0 | Z2: =MAX(0,(Inputs!$B$3-100)*3)+Inputs!$B$27+Inputs!$B$28
A3: =Skills!A3 | B3: =Skills!B3 | C3: =Inputs!$B$3>=15 | D3: =IF(Skills!C3=1,60+Inputs!$B$24+Inputs!$B$28,IF(Skills!C3=2,90+Inputs!$B$25+Inputs!$B$28,IF(Skills!C3=3,120+Inputs!$B$26+Inputs!$B$28,MAX(0,(Inputs!$B$3-100)*3)+Inputs!$B$27+Inputs!$B$28))) | E3: =INDEX(FactorTable!$B$2:$Y$301, MATCH(ROUND(MIN(300,MAX(1,D3)),0), FactorTable!$A$2:$A$301,0), Skills!L3+1) | F3: =IF(Skills!M3=TRUE,(Skills!K3/10)*(E3/1000),Skills!K3/10)+Skills!N3 | G3: =Skills!F3*IF(Skills!G3>0,Skills!H3/Skills!G3,1) | H3: =1-(1-Skills!I3/100)^Skills!J3 | I3: =IF(Skills!T3<>"",1+(Skills!T3/10)*($Z$3/1000)/100,1) | O3: 0 | P3: =IF(Summary!$B$3=0,0,O3/Summary!$B$3) | Q3: =IFERROR(1/IF(Inputs!$B$4="pvp",15,MAX(0.1,Skills!D3-IF(Skills!E3=TRUE,Inputs!$B$31,0))),0) | R3: =IF(AND(Inputs!$B$4<>"pvp",Inputs!$B$35>0),(INT(Inputs!$B$35/IF(Inputs!$B$4="pvp",15,MAX(0.1,Skills!D3-IF(Skills!E3=TRUE,Inputs!$B$31,0))))+1),0) | Z3: =INDEX(FactorTable!$B$2:$Y$301, MATCH(ROUND(MIN(300,MAX(1,Z2)),0), FactorTable!$A$2:$A$301,0), 24)
A4: =Skills!A4 | B4: =Skills!B4 | C4: =Inputs!$B$3>=40 | D4: =IF(Skills!C4=1,60+Inputs!$B$24+Inputs!$B$28,IF(Skills!C4=2,90+Inputs!$B$25+Inputs!$B$28,IF(Skills!C4=3,120+Inputs!$B$26+Inputs!$B$28,MAX(0,(Inputs!$B$3-100)*3)+Inputs!$B$27+Inputs!$B$28))) | E4: =INDEX(FactorTable!$B$2:$Y$301, MATCH(ROUND(MIN(300,MAX(1,D4)),0), FactorTable!$A$2:$A$301,0), Skills!L4+1) | F4: =IF(Skills!M4=TRUE,(Skills!K4/10)*(E4/1000),Skills!K4/10)+Skills!N4 | G4: =Skills!F4*IF(Skills!G4>0,Skills!H4/Skills!G4,1) | H4: =1-(1-Skills!I4/100)^Skills!J4 | I4: =IF(Skills!T4<>"",1+(Skills!T4/10)*($Z$3/1000)/100,1) | O4: 0 | P4: =IF(Summary!$B$3=0,0,O4/Summary!$B$3) | Q4: =IFERROR(1/IF(Inputs!$B$4="pvp",15,MAX(0.1,Skills!D4-IF(Skills!E4=TRUE,Inputs!$B$31,0))),0) | R4: =IF(AND(Inputs!$B$4<>"pvp",Inputs!$B$35>0),(INT(Inputs!$B$35/IF(Inputs!$B$4="pvp",15,MAX(0.1,Skills!D4-IF(Skills!E4=TRUE,Inputs!$B$31,0))))+1),0)
A5: =Skills!A5 | B5: =Skills!B5 | C5: =Inputs!$B$3>=38 | D5: =IF(Skills!C5=1,60+Inputs!$B$24+Inputs!$B$28,IF(Skills!C5=2,90+Inputs!$B$25+Inputs!$B$28,IF(Skills!C5=3,120+Inputs!$B$26+Inputs!$B$28,MAX(0,(Inputs!$B$3-100)*3)+Inputs!$B$27+Inputs!$B$28))) | E5: =INDEX(FactorTable!$B$2:$Y$301, MATCH(ROUND(MIN(300,MAX(1,D5)),0), FactorTable!$A$2:$A$301,0), Skills!L5+1) | F5: =IF(Skills!M5=TRUE,(Skills!K5/10)*(E5/1000),Skills!K5/10)+Skills!N5 | G5: =Skills!F5*IF(Skills!G5>0,Skills!H5/Skills!G5,1) | H5: =1-(1-Skills!I5/100)^Skills!J5 | I5: =IF(Skills!T5<>"",1+(Skills!T5/10)*($Z$3/1000)/100,1) | J5: =Summary!$B$46*(F5/100) | K5: =J5*(1+Summary!$B$47/100)*(1+(Inputs!$B$14+Summary!$B$55)/100)*(1+IF(Inputs!$B$4="pvp",0,(1-Summary!$B$51)*(Inputs!$B$19+Skills!O5+Summary!$B$54)+Summary!$B$51*(Inputs!$B$20+Skills!P5+Summary!$B$54))/100)*(1+Inputs!$B$15/100)*(5000/(6000+Inputs!$B$7*(1-Inputs!$B$18/100)))*(1+Inputs!$B$23/100)*(1+IF(C15=TRUE,F15,0)/100)*(1+IF(C23=TRUE,F23,0)/100)^5*(1+(IF(Skills!A5="CHAIN_LIGHTNING",Inputs!$B$16,Inputs!$B$17))/100)*(Summary!$B$53*I5) | L5: =K5*(MIN(Inputs!$B$21,Inputs!$B$22)/100+Inputs!$B$22/100)/2 | M5: =L5*(1+Inputs!$B$9/100) | N5: =L5*(1-MIN(Inputs!$B$8,100)/100)+M5*(MIN(Inputs!$B$8,100)/100) | O5: =IF(C5,H5*N5*IF(AND(Inputs!$B$4<>"pvp",Inputs!$B$35>0),((Skills!F5*((R5-1)*IF(Skills!G5>0,Skills!H5/Skills!G5,1)+IF(Skills!G5>0,MIN(Skills!H5,MAX(0,Inputs!$B$35-((R5-1)*IF(Inputs!$B$4="pvp",15,MAX(0.1,Skills!D5-IF(Skills!E5=TRUE,Inputs!$B$31,0))))))/Skills!G5,1)))/Inputs!$B$35),G5*Q5)*IF(Inputs!$B$4="pvp",1,(1-Summary!$B$51)*(1)+Summary!$B$51*(MIN(Skills!Q5,Inputs!$B$37))),0) | P5: =IF(Summary!$B$3=0,0,O5/Summary!$B$3) | Q5: =IFERROR(1/IF(Inputs!$B$4="pvp",15,MAX(0.1,Skills!D5-IF(Skills!E5=TRUE,Inputs!$B$31,0))),0) | R5: =IF(AND(Inputs!$B$4<>"pvp",Inputs!$B$35>0),(INT(Inputs!$B$35/IF(Inputs!$B$4="pvp",15,MAX(0.1,Skills!D5-IF(Skills!E5=TRUE,Inputs!$B$31,0))))+1),0)
A6: =Skills!A6 | B6: =Skills!B6 | C6: =Inputs!$B$3>=63 | D6: =IF(Skills!C6=1,60+Inputs!$B$24+Inputs!$B$28,IF(Skills!C6=2,90+Inputs!$B$25+Inputs!$B$28,IF(Skills!C6=3,120+Inputs!$B$26+Inputs!$B$28,MAX(0,(Inputs!$B$3-100)*3)+Inputs!$B$27+Inputs!$B$28))) | E6: =INDEX(FactorTable!$B$2:$Y$301, MATCH(ROUND(MIN(300,MAX(1,D6)),0), FactorTable!$A$2:$A$301,0), Skills!L6+1) | F6: =IF(Skills!M6=TRUE,(Skills!K6/10)*(E6/1000),Skills!K6/10)+Skills!N6 | G6: =Skills!F6*IF(Skills!G6>0,Skills!H6/Skills!G6,1) | H6: =1-(1-Skills!I6/100)^Skills!J6 | I6: =IF(Skills!T6<>"",1+(Skills!T6/10)*($Z$3/1000)/100,1) | J6: =Summary!$B$46*(F6/100) | K6: =J6*(1+Summary!$B$47/100)*(1+(Inputs!$B$14+Summary!$B$55)/100)*(1+IF(Inputs!$B$4="pvp",0,(1-Summary!$B$51)*(Inputs!$B$19+Skills!O6+Summary!$B$54)+Summary!$B$51*(Inputs!$B$20+Skills!P6+Summary!$B$54))/100)*(1+Inputs!$B$15/100)*(5000/(6000+Inputs!$B$7*(1-Inputs!$B$18/100)))*(1+Inputs!$B$23/100)*(1+IF(C15=TRUE,F15,0)/100)*(1+IF(C23=TRUE,F23,0)/100)^5*(1+(IF(Skills!A6="CHAIN_LIGHTNING",Inputs!$B$16,Inputs!$B$17))/100)*(Summary!$B$53*I6) | L6: =K6*(MIN(Inputs!$B$21,Inputs!$B$22)/100+Inputs!$B$22/100)/2 | M6: =L6*(1+Inputs!$B$9/100) | N6: =L6*(1-MIN(Inputs!$B$8,100)/100)+M6*(MIN(Inputs!$B$8,100)/100) | O6: =IF(C6,H6*N6*IF(AND(Inputs!$B$4<>"pvp",Inputs!$B$35>0),((Skills!F6*((R6-1)*IF(Skills!G6>0,Skills!H6/Skills!G6,1)+IF(Skills!G6>0,MIN(Skills!H6,MAX(0,Inputs!$B$35-((R6-1)*IF(Inputs!$B$4="pvp",15,MAX(0.1,Skills!D6-IF(Skills!E6=TRUE,Inputs!$B$31,0))))))/Skills!G6,1)))/Inputs!$B$35),G6*Q6)*IF(Inputs!$B$4="pvp",1,(1-Summary!$B$51)*(1)+Summary!$B$51*(MIN(Skills!Q6,Inputs!$B$37))),0) | P6: =IF(Summary!$B$3=0,0,O6/Summary!$B$3) | Q6: =IFERROR(1/IF(Inputs!$B$4="pvp",15,MAX(0.1,Skills!D6-IF(Skills!E6=TRUE,Inputs!$B$31,0))),0) | R6: =IF(AND(Inputs!$B$4<>"pvp",Inputs!$B$35>0),(INT(Inputs!$B$35/IF(Inputs!$B$4="pvp",15,MAX(0.1,Skills!D6-IF(Skills!E6=TRUE,Inputs!$B$31,0))))+1),0)
A7: =Skills!A7 | B7: =Skills!B7 | C7: =Inputs!$B$3>=69 | D7: =IF(Skills!C7=1,60+Inputs!$B$24+Inputs!$B$28,IF(Skills!C7=2,90+Inputs!$B$25+Inputs!$B$28,IF(Skills!C7=3,120+Inputs!$B$26+Inputs!$B$28,MAX(0,(Inputs!$B$3-100)*3)+Inputs!$B$27+Inputs!$B$28))) | E7: =INDEX(FactorTable!$B$2:$Y$301, MATCH(ROUND(MIN(300,MAX(1,D7)),0), FactorTable!$A$2:$A$301,0), Skills!L7+1) | F7: =IF(Skills!M7=TRUE,(Skills!K7/10)*(E7/1000),Skills!K7/10)+Skills!N7 | G7: =Skills!F7*IF(Skills!G7>0,Skills!H7/Skills!G7,1) | H7: =1-(1-Skills!I7/100)^Skills!J7 | I7: =IF(Skills!T7<>"",1+(Skills!T7/10)*($Z$3/1000)/100,1) | J7: =Summary!$B$46*(F7/100) | K7: =J7*(1+Summary!$B$47/100)*(1+(Inputs!$B$14+Summary!$B$55)/100)*(1+IF(Inputs!$B$4="pvp",0,(1-Summary!$B$51)*(Inputs!$B$19+Skills!O7+Summary!$B$54)+Summary!$B$51*(Inputs!$B$20+Skills!P7+Summary!$B$54))/100)*(1+Inputs!$B$15/100)*(5000/(6000+Inputs!$B$7*(1-Inputs!$B$18/100)))*(1+Inputs!$B$23/100)*(1+IF(C15=TRUE,F15,0)/100)*(1+IF(C23=TRUE,F23,0)/100)^5*(1+(IF(Skills!A7="CHAIN_LIGHTNING",Inputs!$B$16,Inputs!$B$17))/100)*(Summary!$B$53*I7) | L7: =K7*(MIN(Inputs!$B$21,Inputs!$B$22)/100+Inputs!$B$22/100)/2 | M7: =L7*(1+Inputs!$B$9/100) | N7: =L7*(1-MIN(Inputs!$B$8,100)/100)+M7*(MIN(Inputs!$B$8,100)/100) | O7: =IF(C7,H7*N7*IF(AND(Inputs!$B$4<>"pvp",Inputs!$B$35>0),((Skills!F7*((R7-1)*IF(Skills!G7>0,Skills!H7/Skills!G7,1)+IF(Skills!G7>0,MIN(Skills!H7,MAX(0,Inputs!$B$35-((R7-1)*IF(Inputs!$B$4="pvp",15,MAX(0.1,Skills!D7-IF(Skills!E7=TRUE,Inputs!$B$31,0))))))/Skills!G7,1)))/Inputs!$B$35),G7*Q7)*IF(Inputs!$B$4="pvp",1,(1-Summary!$B$51)*(1)+Summary!$B$51*(MIN(Skills!Q7,Inputs!$B$37))),0) | P7: =IF(Summary!$B$3=0,0,O7/Summary!$B$3) | Q7: =IFERROR(1/IF(Inputs!$B$4="pvp",15,MAX(0.1,Skills!D7-IF(Skills!E7=TRUE,Inputs!$B$31,0))),0) | R7: =IF(AND(Inputs!$B$4<>"pvp",Inputs!$B$35>0),(INT(Inputs!$B$35/IF(Inputs!$B$4="pvp",15,MAX(0.1,Skills!D7-IF(Skills!E7=TRUE,Inputs!$B$31,0))))+1),0)
A8: =Skills!A8 | B8: =Skills!B8 | C8: =Inputs!$B$3>=103 | D8: =IF(Skills!C8=1,60+Inputs!$B$24+Inputs!$B$28,IF(Skills!C8=2,90+Inputs!$B$25+Inputs!$B$28,IF(Skills!C8=3,120+Inputs!$B$26+Inputs!$B$28,MAX(0,(Inputs!$B$3-100)*3)+Inputs!$B$27+Inputs!$B$28))) | E8: =INDEX(FactorTable!$B$2:$Y$301, MATCH(ROUND(MIN(300,MAX(1,D8)),0), FactorTable!$A$2:$A$301,0), Skills!L8+1) | F8: =IF(Skills!M8=TRUE,(Skills!K8/10)*(E8/1000),Skills!K8/10)+Skills!N8 | G8: =Skills!F8*IF(Skills!G8>0,Skills!H8/Skills!G8,1) | H8: =1-(1-Skills!I8/100)^Skills!J8 | I8: =IF(Skills!T8<>"",1+(Skills!T8/10)*($Z$3/1000)/100,1) | J8: =Summary!$B$46*(F8/100) | K8: =J8*(1+Summary!$B$47/100)*(1+(Inputs!$B$14+Summary!$B$55)/100)*(1+IF(Inputs!$B$4="pvp",0,(1-Summary!$B$51)*(Inputs!$B$19+Skills!O8+Summary!$B$54)+Summary!$B$51*(Inputs!$B$20+Skills!P8+Summary!$B$54))/100)*(1+Inputs!$B$15/100)*(5000/(6000+Inputs!$B$7*(1-Inputs!$B$18/100)))*(1+Inputs!$B$23/100)*(1+IF(C15=TRUE,F15,0)/100)*(1+IF(C23=TRUE,F23,0)/100)^5*(1+(IF(Skills!A8="CHAIN_LIGHTNING",Inputs!$B$16,Inputs!$B$17))/100)*(Summary!$B$53*I8) | L8: =K8*(MIN(Inputs!$B$21,Inputs!$B$22)/100+Inputs!$B$22/100)/2 | M8: =L8*(1+Inputs!$B$9/100) | N8: =L8*(1-MIN(Inputs!$B$8,100)/100)+M8*(MIN(Inputs!$B$8,100)/100) | O8: =IF(C8,H8*N8*IF(AND(Inputs!$B$4<>"pvp",Inputs!$B$35>0),((Skills!F8*((R8-1)*IF(Skills!G8>0,Skills!H8/Skills!G8,1)+IF(Skills!G8>0,MIN(Skills!H8,MAX(0,Inputs!$B$35-((R8-1)*IF(Inputs!$B$4="pvp",15,MAX(0.1,Skills!D8-IF(Skills!E8=TRUE,Inputs!$B$31,0))))))/Skills!G8,1)))/Inputs!$B$35),G8*Q8)*IF(Inputs!$B$4="pvp",1,(1-Summary!$B$51)*(1)+Summary!$B$51*(MIN(Skills!Q8,Inputs!$B$37))),0) | P8: =IF(Summary!$B$3=0,0,O8/Summary!$B$3) | Q8: =IFERROR(1/IF(Inputs!$B$4="pvp",15,MAX(0.1,Skills!D8-IF(Skills!E8=TRUE,Inputs!$B$31,0))),0) | R8: =IF(AND(Inputs!$B$4<>"pvp",Inputs!$B$35>0),(INT(Inputs!$B$35/IF(Inputs!$B$4="pvp",15,MAX(0.1,Skills!D8-IF(Skills!E8=TRUE,Inputs!$B$31,0))))+1),0)
A9: =Skills!A9 | B9: =Skills!B9 | C9: =Inputs!$B$3>=105 | D9: =IF(Skills!C9=1,60+Inputs!$B$24+Inputs!$B$28,IF(Skills!C9=2,90+Inputs!$B$25+Inputs!$B$28,IF(Skills!C9=3,120+Inputs!$B$26+Inputs!$B$28,MAX(0,(Inputs!$B$3-100)*3)+Inputs!$B$27+Inputs!$B$28))) | E9: =INDEX(FactorTable!$B$2:$Y$301, MATCH(ROUND(MIN(300,MAX(1,D9)),0), FactorTable!$A$2:$A$301,0), Skills!L9+1) | F9: =IF(Skills!M9=TRUE,(Skills!K9/10)*(E9/1000),Skills!K9/10)+Skills!N9 | G9: =Skills!F9*IF(Skills!G9>0,Skills!H9/Skills!G9,1) | H9: =1-(1-Skills!I9/100)^Skills!J9 | I9: =IF(Skills!T9<>"",1+(Skills!T9/10)*($Z$3/1000)/100,1) | J9: =Summary!$B$46*(F9/100) | K9: =J9*(1+Summary!$B$47/100)*(1+(Inputs!$B$14+Summary!$B$55)/100)*(1+IF(Inputs!$B$4="pvp",0,(1-Summary!$B$51)*(Inputs!$B$19+Skills!O9+Summary!$B$54)+Summary!$B$51*(Inputs!$B$20+Skills!P9+Summary!$B$54))/100)*(1+Inputs!$B$15/100)*(5000/(6000+Inputs!$B$7*(1-Inputs!$B$18/100)))*(1+Inputs!$B$23/100)*(1+IF(C15=TRUE,F15,0)/100)*(1+IF(C23=TRUE,F23,0)/100)^5*(1+(IF(Skills!A9="CHAIN_LIGHTNING",Inputs!$B$16,Inputs!$B$17))/100)*(Summary!$B$53*I9) | L9: =K9*(MIN(Inputs!$B$21,Inputs!$B$22)/100+Inputs!$B$22/100)/2 | M9: =L9*(1+Inputs!$B$9/100) | N9: =L9*(1-MIN(Inputs!$B$8,100)/100)+M9*(MIN(Inputs!$B$8,100)/100) | O9: =IF(C9,H9*N9*IF(AND(Inputs!$B$4<>"pvp",Inputs!$B$35>0),((Skills!F9*((R9-1)*IF(Skills!G9>0,Skills!H9/Skills!G9,1)+IF(Skills!G9>0,MIN(Skills!H9,MAX(0,Inputs!$B$35-((R9-1)*IF(Inputs!$B$4="pvp",15,MAX(0.1,Skills!D9-IF(Skills!E9=TRUE,Inputs!$B$31,0))))))/Skills!G9,1)))/Inputs!$B$35),G9*Q9)*IF(Inputs!$B$4="pvp",1,(1-Summary!$B$51)*(1)+Summary!$B$51*(MIN(Skills!Q9,Inputs!$B$37))),0) | P9: =IF(Summary!$B$3=0,0,O9/Summary!$B$3) | Q9: =IFERROR(1/IF(Inputs!$B$4="pvp",15,MAX(0.1,Skills!D9-IF(Skills!E9=TRUE,Inputs!$B$31,0))),0) | R9: =IF(AND(Inputs!$B$4<>"pvp",Inputs!$B$35>0),(INT(Inputs!$B$35/IF(Inputs!$B$4="pvp",15,MAX(0.1,Skills!D9-IF(Skills!E9=TRUE,Inputs!$B$31,0))))+1),0)
A10: =Skills!A10 | B10: =Skills!B10 | C10: =Inputs!$B$3>=113 | D10: =IF(Skills!C10=1,60+Inputs!$B$24+Inputs!$B$28,IF(Skills!C10=2,90+Inputs!$B$25+Inputs!$B$28,IF(Skills!C10=3,120+Inputs!$B$26+Inputs!$B$28,MAX(0,(Inputs!$B$3-100)*3)+Inputs!$B$27+Inputs!$B$28))) | E10: =INDEX(FactorTable!$B$2:$Y$301, MATCH(ROUND(MIN(300,MAX(1,D10)),0), FactorTable!$A$2:$A$301,0), Skills!L10+1) | F10: =IF(Skills!M10=TRUE,(Skills!K10/10)*(E10/1000),Skills!K10/10)+Skills!N10 | G10: =Skills!F10*IF(Skills!G10>0,Skills!H10/Skills!G10,1) | H10: =1-(1-Skills!I10/100)^Skills!J10 | I10: =IF(Skills!T10<>"",1+(Skills!T10/10)*($Z$3/1000)/100,1) | J10: =Summary!$B$46*(F10/100) | K10: =J10*(1+Summary!$B$47/100)*(1+(Inputs!$B$14+Summary!$B$55)/100)*(1+IF(Inputs!$B$4="pvp",0,(1-Summary!$B$51)*(Inputs!$B$19+Skills!O10+Summary!$B$54)+Summary!$B$51*(Inputs!$B$20+Skills!P10+Summary!$B$54))/100)*(1+Inputs!$B$15/100)*(5000/(6000+Inputs!$B$7*(1-Inputs!$B$18/100)))*(1+Inputs!$B$23/100)*(1+IF(C15=TRUE,F15,0)/100)*(1+IF(C23=TRUE,F23,0)/100)^5*(1+(IF(Skills!A10="CHAIN_LIGHTNING",Inputs!$B$16,Inputs!$B$17))/100)*(Summary!$B$53*I10) | L10: =K10*(MIN(Inputs!$B$21,Inputs!$B$22)/100+Inputs!$B$22/100)/2 | M10: =L10*(1+Inputs!$B$9/100) | N10: =L10*(1-MIN(Inputs!$B$8,100)/100)+M10*(MIN(Inputs!$B$8,100)/100) | O10: =IF(C10,H10*N10*IF(AND(Inputs!$B$4<>"pvp",Inputs!$B$35>0),((Skills!F10*((R10-1)*IF(Skills!G10>0,Skills!H10/Skills!G10,1)+IF(Skills!G10>0,MIN(Skills!H10,MAX(0,Inputs!$B$35-((R10-1)*IF(Inputs!$B$4="pvp",15,MAX(0.1,Skills!D10-IF(Skills!E9=TRUE,Inputs!$B$31,0))))))/Skills!G10,1)))/Inputs!$B$35),G10*Q10)*IF(Inputs!$B$4="pvp",1,(1-Summary!$B$51)*(1)+Summary!$B$51*(MIN(Skills!Q10,Inputs!$B$37))),0) | P10: =IF(Summary!$B$3=0,0,O10/Summary!$B$3) | Q10: =IFERROR(1/IF(Inputs!$B$4="pvp",15,MAX(0.1,Skills!D10-IF(Skills!E9=TRUE,Inputs!$B$31,0))),0) | R10: =IF(AND(Inputs!$B$4<>"pvp",Inputs!$B$35>0),(INT(Inputs!$B$35/IF(Inputs!$B$4="pvp",15,MAX(0.1,Skills!D10-IF(Skills!E9=TRUE,Inputs!$B$31,0))))+1),0)
A11: =Skills!A11 | B11: =Skills!B11 | C11: =Inputs!$B$3>=107 | D11: =IF(Skills!C11=1,60+Inputs!$B$24+Inputs!$B$28,IF(Skills!C11=2,90+Inputs!$B$25+Inputs!$B$28,IF(Skills!C11=3,120+Inputs!$B$26+Inputs!$B$28,MAX(0,(Inputs!$B$3-100)*3)+Inputs!$B$27+Inputs!$B$28))) | E11: =INDEX(FactorTable!$B$2:$Y$301, MATCH(ROUND(MIN(300,MAX(1,D11)),0), FactorTable!$A$2:$A$301,0), Skills!L11+1) | F11: =IF(Skills!M11=TRUE,(Skills!K11/10)*(E11/1000),Skills!K11/10)+Skills!N11 | G11: =Skills!F11*IF(Skills!G11>0,Skills!H11/Skills!G11,1) | H11: =1-(1-Skills!I11/100)^Skills!J11 | I11: =IF(Skills!T11<>"",1+(Skills!T11/10)*($Z$3/1000)/100,1) | J11: =Summary!$B$46*(F11/100) | K11: =J11*(1+Summary!$B$47/100)*(1+(Inputs!$B$14+Summary!$B$55)/100)*(1+IF(Inputs!$B$4="pvp",0,(1-Summary!$B$51)*(Inputs!$B$19+Skills!O11+Summary!$B$54)+Summary!$B$51*(Inputs!$B$20+Skills!P11+Summary!$B$54))/100)*(1+Inputs!$B$15/100)*(5000/(6000+Inputs!$B$7*(1-Inputs!$B$18/100)))*(1+Inputs!$B$23/100)*(1+IF(C15=TRUE,F15,0)/100)*(1+IF(C23=TRUE,F23,0)/100)^5*(1+(IF(Skills!A11="CHAIN_LIGHTNING",Inputs!$B$16,Inputs!$B$17))/100)*(Summary!$B$53*I11) | L11: =K11*(MIN(Inputs!$B$21,Inputs!$B$22)/100+Inputs!$B$22/100)/2 | M11: =L11*(1+Inputs!$B$9/100) | N11: =L11*(1-MIN(Inputs!$B$8,100)/100)+M11*(MIN(Inputs!$B$8,100)/100) | O11: =IF(C11,H11*N11*IF(AND(Inputs!$B$4<>"pvp",Inputs!$B$35>0),((Skills!F11*((R11-1)*IF(Skills!G11>0,Skills!H11/Skills!G11,1)+IF(Skills!G11>0,MIN(Skills!H11,MAX(0,Inputs!$B$35-((R11-1)*IF(Inputs!$B$4="pvp",15,MAX(0.1,Skills!D11-IF(Skills!E11=TRUE,Inputs!$B$31,0))))))/Skills!G11,1)))/Inputs!$B$35),G11*Q11)*IF(Inputs!$B$4="pvp",0.5,(1-Summary!$B$51)*0.5+Summary!$B$51*1)*IF(Inputs!$B$4="pvp",1,(1-Summary!$B$51)*(1)+Summary!$B$51*(MIN(Skills!Q11,Inputs!$B$37))),0) | P11: =IF(Summary!$B$3=0,0,O11/Summary!$B$3) | Q11: =IFERROR(1/IF(Inputs!$B$4="pvp",15,MAX(0.1,Skills!D11-IF(Skills!E11=TRUE,Inputs!$B$31,0))),0) | R11: =IF(AND(Inputs!$B$4<>"pvp",Inputs!$B$35>0),(INT(Inputs!$B$35/IF(Inputs!$B$4="pvp",15,MAX(0.1,Skills!D11-IF(Skills!E11=TRUE,Inputs!$B$31,0))))+1),0)
A12: =Skills!A12 | B12: =Skills!B12 | C12: =Inputs!$B$3>=115 | D12: =IF(Skills!C12=1,60+Inputs!$B$24+Inputs!$B$28,IF(Skills!C12=2,90+Inputs!$B$25+Inputs!$B$28,IF(Skills!C12=3,120+Inputs!$B$26+Inputs!$B$28,MAX(0,(Inputs!$B$3-100)*3)+Inputs!$B$27+Inputs!$B$28))) | E12: =INDEX(FactorTable!$B$2:$Y$301, MATCH(ROUND(MIN(300,MAX(1,D12)),0), FactorTable!$A$2:$A$301,0), Skills!L12+1) | F12: =IF(Skills!M12=TRUE,(Skills!K12/10)*(E12/1000),Skills!K12/10)+Skills!N12 | G12: =Skills!F12*IF(Skills!G12>0,Skills!H12/Skills!G12,1) | H12: =1-(1-Skills!I12/100)^Skills!J12 | I12: =IF(Skills!T12<>"",1+(Skills!T12/10)*($Z$3/1000)/100,1) | J12: =Summary!$B$46*(F12/100) | K12: =J12*(1+Summary!$B$47/100)*(1+(Inputs!$B$14+Summary!$B$55)/100)*(1+IF(Inputs!$B$4="pvp",0,(1-Summary!$B$51)*(Inputs!$B$19+Skills!O12+Summary!$B$54)+Summary!$B$51*(Inputs!$B$20+Skills!P12+Summary!$B$54))/100)*(1+Inputs!$B$15/100)*(5000/(6000+Inputs!$B$7*(1-Inputs!$B$18/100)))*(1+Inputs!$B$23/100)*(1+IF(C15=TRUE,F15,0)/100)*(1+IF(C23=TRUE,F23,0)/100)^5*(1+(IF(Skills!A12="CHAIN_LIGHTNING",Inputs!$B$16,Inputs!$B$17))/100)*(Summary!$B$53*I12) | L12: =K12*(MIN(Inputs!$B$21,Inputs!$B$22)/100+Inputs!$B$22/100)/2 | M12: =L12*(1+Inputs!$B$9/100) | N12: =L12*(1-MIN(Inputs!$B$8,100)/100)+M12*(MIN(Inputs!$B$8,100)/100) | O12: =IF(C12,H12*N12*IF(AND(Inputs!$B$4<>"pvp",Inputs!$B$35>0),((Skills!F12*((R12-1)*IF(Skills!G12>0,Skills!H12/Skills!G12,1)+IF(Skills!G12>0,MIN(Skills!H12,MAX(0,Inputs!$B$35-((R12-1)*IF(Inputs!$B$4="pvp",15,MAX(0.1,Skills!D12-IF(Skills!E12=TRUE,Inputs!$B$31,0))))))/Skills!G12,1)))/Inputs!$B$35),G12*Q12)*IF(Inputs!$B$4="pvp",1,(1-Summary!$B$51)*(1)+Summary!$B$51*(MIN(Skills!Q12,Inputs!$B$37))),0) | P12: =IF(Summary!$B$3=0,0,O12/Summary!$B$3) | Q12: =IFERROR(1/IF(Inputs!$B$4="pvp",15,MAX(0.1,Skills!D12-IF(Skills!E12=TRUE,Inputs!$B$31,0))),0) | R12: =IF(AND(Inputs!$B$4<>"pvp",Inputs!$B$35>0),(INT(Inputs!$B$35/IF(Inputs!$B$4="pvp",15,MAX(0.1,Skills!D12-IF(Skills!E12=TRUE,Inputs!$B$31,0))))+1),0)
A13: =Skills!A13 | B13: =Skills!B13 | C13: =Inputs!$B$3>=49 | D13: =IF(Skills!C13=1,60+Inputs!$B$24+Inputs!$B$28,IF(Skills!C13=2,90+Inputs!$B$25+Inputs!$B$28,IF(Skills!C13=3,120+Inputs!$B$26+Inputs!$B$28,MAX(0,(Inputs!$B$3-100)*3)+Inputs!$B$27+Inputs!$B$28))) | E13: =INDEX(FactorTable!$B$2:$Y$301, MATCH(ROUND(MIN(300,MAX(1,D13)),0), FactorTable!$A$2:$A$301,0), Skills!L13+1) | F13: =IF(Skills!M13=TRUE,(Skills!K13/10)*(E13/1000),Skills!K13/10)+Skills!N13 | G13: =Skills!F13*IF(Skills!G13>0,Skills!H13/Skills!G13,1) | H13: =1-(1-Skills!I13/100)^Skills!J13 | I13: =IF(Skills!T13<>"",1+(Skills!T13/10)*($Z$3/1000)/100,1) | O13: 0 | P13: =IF(Summary!$B$3=0,0,O13/Summary!$B$3) | Q13: =IFERROR(1/IF(Inputs!$B$4="pvp",15,MAX(0.1,Skills!D13-IF(Skills!E13=TRUE,Inputs!$B$31,0))),0) | R13: 0
A14: =Skills!A14 | B14: =Skills!B14 | C14: =Inputs!$B$3>=72 | D14: =IF(Skills!C14=1,60+Inputs!$B$24+Inputs!$B$28,IF(Skills!C14=2,90+Inputs!$B$25+Inputs!$B$28,IF(Skills!C14=3,120+Inputs!$B$26+Inputs!$B$28,MAX(0,(Inputs!$B$3-100)*3)+Inputs!$B$27+Inputs!$B$28))) | E14: =INDEX(FactorTable!$B$2:$Y$301, MATCH(ROUND(MIN(300,MAX(1,D14)),0), FactorTable!$A$2:$A$301,0), Skills!L14+1) | F14: =IF(Skills!M14=TRUE,(Skills!K14/10)*(E14/1000),Skills!K14/10)+Skills!N14 | G14: =Skills!F14*IF(Skills!G14>0,Skills!H14/Skills!G14,1) | H14: =1-(1-Skills!I14/100)^Skills!J14 | I14: =IF(Skills!T14<>"",1+(Skills!T14/10)*($Z$3/1000)/100,1) | O14: 0 | P14: =IF(Summary!$B$3=0,0,O14/Summary!$B$3) | Q14: =IFERROR(1/IF(Inputs!$B$4="pvp",15,MAX(0.1,Skills!D14-IF(Skills!E14=TRUE,Inputs!$B$31,0))),0) | R14: 0
A15: =Skills!A15 | B15: =Skills!B15 | C15: =Inputs!$B$3>=75 | D15: =IF(Skills!C15=1,60+Inputs!$B$24+Inputs!$B$28,IF(Skills!C15=2,90+Inputs!$B$25+Inputs!$B$28,IF(Skills!C15=3,120+Inputs!$B$26+Inputs!$B$28,MAX(0,(Inputs!$B$3-100)*3)+Inputs!$B$27+Inputs!$B$28))) | E15: =INDEX(FactorTable!$B$2:$Y$301, MATCH(ROUND(MIN(300,MAX(1,D15)),0), FactorTable!$A$2:$A$301,0), Skills!L15+1) | F15: =IF(Skills!M15=TRUE,(Skills!K15/10)*(E15/1000),Skills!K15/10)+Skills!N15 | G15: =Skills!F15*IF(Skills!G15>0,Skills!H15/Skills!G15,1) | H15: =1-(1-Skills!I15/100)^Skills!J15 | I15: =IF(Skills!T15<>"",1+(Skills!T15/10)*($Z$3/1000)/100,1) | O15: 0 | P15: =IF(Summary!$B$3=0,0,O15/Summary!$B$3) | Q15: =IFERROR(1/IF(Inputs!$B$4="pvp",15,MAX(0.1,Skills!D15-IF(Skills!E15=TRUE,Inputs!$B$31,0))),0) | R15: 0
A16: =Skills!A16 | B16: =Skills!B16 | C16: =Inputs!$B$3>=110 | D16: =IF(Skills!C16=1,60+Inputs!$B$24+Inputs!$B$28,IF(Skills!C16=2,90+Inputs!$B$25+Inputs!$B$28,IF(Skills!C16=3,120+Inputs!$B$26+Inputs!$B$28,MAX(0,(Inputs!$B$3-100)*3)+Inputs!$B$27+Inputs!$B$28))) | E16: =INDEX(FactorTable!$B$2:$Y$301, MATCH(ROUND(MIN(300,MAX(1,D16)),0), FactorTable!$A$2:$A$301,0), Skills!L16+1) | F16: =(Skills!K16/10)*(E16/1000)*64/45+Skills!N16 | G16: =Skills!F16*IF(Skills!G16>0,Skills!H16/Skills!G16,1) | H16: =1-(1-Skills!I16/100)^Skills!J16 | I16: =IF(Skills!T16<>"",1+(Skills!T16/10)*($Z$3/1000)/100,1) | O16: 0 | P16: =IF(Summary!$B$3=0,0,O16/Summary!$B$3) | Q16: =IFERROR(1/IF(Inputs!$B$4="pvp",15,MAX(0.1,Skills!D16-IF(Skills!E16=TRUE,Inputs!$B$31,0))),0) | R16: =IF(AND(Inputs!$B$4<>"pvp",Inputs!$B$35>0),(INT(Inputs!$B$35/IF(Inputs!$B$4="pvp",15,MAX(0.1,Skills!D16-IF(Skills!E16=TRUE,Inputs!$B$31,0))))+1),0)
A17: =Skills!A17 | B17: =Skills!B17 | C17: =Inputs!$B$3>=33 | D17: =IF(Skills!C17=1,60+Inputs!$B$24+Inputs!$B$28,IF(Skills!C17=2,90+Inputs!$B$25+Inputs!$B$28,IF(Skills!C17=3,120+Inputs!$B$26+Inputs!$B$28,MAX(0,(Inputs!$B$3-100)*3)+Inputs!$B$27+Inputs!$B$28))) | E17: =INDEX(FactorTable!$B$2:$Y$301, MATCH(ROUND(MIN(300,MAX(1,D17)),0), FactorTable!$A$2:$A$301,0), Skills!L17+1) | F17: =IF(Skills!M17=TRUE,(Skills!K17/10)*(E17/1000),Skills!K17/10)+Skills!N17 | G17: =Skills!F17*IF(Skills!G17>0,Skills!H17/Skills!G17,1) | H17: =1-(1-Skills!I17/100)^Skills!J17 | I17: =IF(Skills!T17<>"",1+(Skills!T17/10)*($Z$3/1000)/100,1) | O17: 0 | P17: =IF(Summary!$B$3=0,0,O17/Summary!$B$3) | Q17: =IFERROR(1/IF(Inputs!$B$4="pvp",15,MAX(0.1,Skills!D17-IF(Skills!E17=TRUE,Inputs!$B$31,0))),0) | R17: 0
A18: =Skills!A18 | B18: =Skills!B18 | C18: =Inputs!$B$3>=43 | D18: =IF(Skills!C18=1,60+Inputs!$B$24+Inputs!$B$28,IF(Skills!C18=2,90+Inputs!$B$25+Inputs!$B$28,IF(Skills!C18=3,120+Inputs!$B$26+Inputs!$B$28,MAX(0,(Inputs!$B$3-100)*3)+Inputs!$B$27+Inputs!$B$28))) | E18: =INDEX(FactorTable!$B$2:$Y$301, MATCH(ROUND(MIN(300,MAX(1,D18)),0), FactorTable!$A$2:$A$301,0), Skills!L18+1) | F18: =IF(Skills!M18=TRUE,(Skills!K18/10)*(E18/1000),Skills!K18/10)+Skills!N18 | G18: =Skills!F18*IF(Skills!G18>0,Skills!H18/Skills!G18,1) | H18: =1-(1-Skills!I18/100)^Skills!J18 | I18: =IF(Skills!T18<>"",1+(Skills!T18/10)*($Z$3/1000)/100,1) | O18: 0 | P18: =IF(Summary!$B$3=0,0,O18/Summary!$B$3) | Q18: =IFERROR(1/IF(Inputs!$B$4="pvp",15,MAX(0.1,Skills!D18-IF(Skills!E18=TRUE,Inputs!$B$31,0))),0) | R18: 0
A19: =Skills!A19 | B19: =Skills!B19 | C19: =Inputs!$B$3>=50 | D19: =IF(Skills!C19=1,60+Inputs!$B$24+Inputs!$B$28,IF(Skills!C19=2,90+Inputs!$B$25+Inputs!$B$28,IF(Skills!C19=3,120+Inputs!$B$26+Inputs!$B$28,MAX(0,(Inputs!$B$3-100)*3)+Inputs!$B$27+Inputs!$B$28))) | E19: =INDEX(FactorTable!$B$2:$Y$301, MATCH(ROUND(MIN(300,MAX(1,D19)),0), FactorTable!$A$2:$A$301,0), Skills!L19+1) | F19: =IF(Skills!M19=TRUE,(Skills!K19/10)*(E19/1000),Skills!K19/10)+Skills!N19 | G19: =Skills!F19*IF(Skills!G19>0,Skills!H19/Skills!G19,1) | H19: =1-(1-Skills!I19/100)^Skills!J19 | I19: =IF(Skills!T19<>"",1+(Skills!T19/10)*($Z$3/1000)/100,1) | O19: 0 | P19: =IF(Summary!$B$3=0,0,O19/Summary!$B$3) | Q19: =IFERROR(1/IF(Inputs!$B$4="pvp",15,MAX(0.1,Skills!D19-IF(Skills!E19=TRUE,Inputs!$B$31,0))),0) | R19: 0
A20: =Skills!A20 | B20: =Skills!B20 | C20: =Inputs!$B$3>=74 | D20: =IF(Skills!C20=1,60+Inputs!$B$24+Inputs!$B$28,IF(Skills!C20=2,90+Inputs!$B$25+Inputs!$B$28,IF(Skills!C20=3,120+Inputs!$B$26+Inputs!$B$28,MAX(0,(Inputs!$B$3-100)*3)+Inputs!$B$27+Inputs!$B$28))) | E20: =INDEX(FactorTable!$B$2:$Y$301, MATCH(ROUND(MIN(300,MAX(1,D20)),0), FactorTable!$A$2:$A$301,0), Skills!L20+1) | F20: =IF(Skills!M20=TRUE,(Skills!K20/10)*(E20/1000),Skills!K20/10)+Skills!N20 | G20: =Skills!F20*IF(Skills!G20>0,Skills!H20/Skills!G20,1) | H20: =1-(1-Skills!I20/100)^Skills!J20 | I20: =IF(Skills!T20<>"",1+(Skills!T20/10)*($Z$3/1000)/100,1) | O20: 0 | P20: =IF(Summary!$B$3=0,0,O20/Summary!$B$3) | Q20: =IFERROR(1/IF(Inputs!$B$4="pvp",15,MAX(0.1,Skills!D20-IF(Skills!E20=TRUE,Inputs!$B$31,0))),0) | R20: 0
A21: =Skills!A21 | B21: =Skills!B21 | C21: =Inputs!$B$3>=74 | D21: =IF(Skills!C21=1,60+Inputs!$B$24+Inputs!$B$28,IF(Skills!C21=2,90+Inputs!$B$25+Inputs!$B$28,IF(Skills!C21=3,120+Inputs!$B$26+Inputs!$B$28,MAX(0,(Inputs!$B$3-100)*3)+Inputs!$B$27+Inputs!$B$28))) | E21: =INDEX(FactorTable!$B$2:$Y$301, MATCH(ROUND(MIN(300,MAX(1,D21)),0), FactorTable!$A$2:$A$301,0), Skills!L21+1) | F21: =IF(Skills!M21=TRUE,(Skills!K21/10)*(E21/1000),Skills!K21/10)+Skills!N21 | G21: =Skills!F21*IF(Skills!G21>0,Skills!H21/Skills!G21,1) | H21: =1-(1-Skills!I21/100)^Skills!J21 | I21: =IF(Skills!T21<>"",1+(Skills!T21/10)*($Z$3/1000)/100,1) | O21: 0 | P21: =IF(Summary!$B$3=0,0,O21/Summary!$B$3) | Q21: =IFERROR(1/IF(Inputs!$B$4="pvp",15,MAX(0.1,Skills!D21-IF(Skills!E21=TRUE,Inputs!$B$31,0))),0) | R21: 0
A22: =Skills!A22 | B22: =Skills!B22 | C22: =Inputs!$B$3>=117 | D22: =IF(Skills!C22=1,60+Inputs!$B$24+Inputs!$B$28,IF(Skills!C22=2,90+Inputs!$B$25+Inputs!$B$28,IF(Skills!C22=3,120+Inputs!$B$26+Inputs!$B$28,MAX(0,(Inputs!$B$3-100)*3)+Inputs!$B$27+Inputs!$B$28))) | E22: =INDEX(FactorTable!$B$2:$Y$301, MATCH(ROUND(MIN(300,MAX(1,D22)),0), FactorTable!$A$2:$A$301,0), Skills!L22+1) | F22: =IF(Skills!M22=TRUE,(Skills!K22/10)*(E22/1000),Skills!K22/10)+Skills!N22 | G22: =Skills!F22*IF(Skills!G22>0,Skills!H22/Skills!G22,1) | H22: =1-(1-Skills!I22/100)^Skills!J22 | I22: =IF(Skills!T22<>"",1+(Skills!T22/10)*($Z$3/1000)/100,1) | O22: 0 | P22: =IF(Summary!$B$3=0,0,O22/Summary!$B$3) | Q22: =IFERROR(1/IF(Inputs!$B$4="pvp",15,MAX(0.1,Skills!D22-IF(Skills!E22=TRUE,Inputs!$B$31,0))),0) | R22: 0
A23: =Skills!A23 | B23: =Skills!B23 | C23: =Inputs!$B$3>=120 | D23: =IF(Skills!C23=1,60+Inputs!$B$24+Inputs!$B$28,IF(Skills!C23=2,90+Inputs!$B$25+Inputs!$B$28,IF(Skills!C23=3,120+Inputs!$B$26+Inputs!$B$28,MAX(0,(Inputs!$B$3-100)*3)+Inputs!$B$27+Inputs!$B$28))) | E23: =INDEX(FactorTable!$B$2:$Y$301, MATCH(ROUND(MIN(300,MAX(1,D23)),0), FactorTable!$A$2:$A$301,0), Skills!L23+1) | F23: =IF(Skills!M23=TRUE,(Skills!K23/10)*(E23/1000),Skills!K23/10)+Skills!N23 | G23: =Skills!F23*IF(Skills!G23>0,Skills!H23/Skills!G23,1) | H23: =1-(1-Skills!I23/100)^Skills!J23 | I23: =IF(Skills!T23<>"",1+(Skills!T23/10)*($Z$3/1000)/100,1) | O23: 0 | P23: =IF(Summary!$B$3=0,0,O23/Summary!$B$3) | Q23: =IFERROR(1/IF(Inputs!$B$4="pvp",15,MAX(0.1,Skills!D23-IF(Skills!E23=TRUE,Inputs!$B$31,0))),0) | R23: 0

Sheet Summary
A1: Arch Mage (Ice/Lightning) — DPS Summary
A3: TOTAL DPS | B3: =SUM(Calc!O2:O23)
A5: Per-Skill DPS Breakdown
A6: Skill | B6: DPS | C6: % of Total
A7: =Calc!B2 | B7: =Calc!O2 | C7: =Calc!P2*100
A8: =Calc!B5 | B8: =Calc!O5 | C8: =Calc!P5*100
A9: =Calc!B6 | B9: =Calc!O6 | C9: =Calc!P6*100
A10: =Calc!B7 | B10: =Calc!O7 | C10: =Calc!P7*100
A11: =Calc!B8 | B11: =Calc!O8 | C11: =Calc!P8*100
A12: =Calc!B9 | B12: =Calc!O9 | C12: =Calc!P9*100
A13: =Calc!B10 | B13: =Calc!O10 | C13: =Calc!P10*100
A14: =Calc!B11 | B14: =Calc!O11 | C14: =Calc!P11*100
A15: =Calc!B12 | B15: =Calc!O12 | C15: =Calc!P12*100
A16: Marginal DPS & Stat Value (see Sensitivity for full detail)
A18: Stat | B18: DPS per +1 | C18: Units per +1% DPS
A19: =Sensitivity!A5 | B19: =Sensitivity!H5 | C19: =Sensitivity!B5
A20: =Sensitivity!A6 | B20: =Sensitivity!H6 | C20: =Sensitivity!B6
A21: =Sensitivity!A7 | B21: =Sensitivity!H7 | C21: =Sensitivity!B7
A22: =Sensitivity!A8 | B22: =Sensitivity!H8 | C22: =Sensitivity!B8
A23: =Sensitivity!A9 | B23: =Sensitivity!H9 | C23: =Sensitivity!B9
A24: =Sensitivity!A10 | B24: =Sensitivity!H10 | C24: =Sensitivity!B10
A25: =Sensitivity!A11 | B25: =Sensitivity!H11 | C25: =Sensitivity!B11
A26: =Sensitivity!A12 | B26: =Sensitivity!H12 | C26: =Sensitivity!B12
A27: =Sensitivity!A13 | B27: =Sensitivity!H13 | C27: =Sensitivity!B13
A28: =Sensitivity!A14 | B28: =Sensitivity!H14 | C28: =Sensitivity!B14
A29: =Sensitivity!A15 | B29: =Sensitivity!H15 | C29: =Sensitivity!B15
A30: =Sensitivity!A16 | B30: =Sensitivity!H16 | C30: =Sensitivity!B16
... A43: =Sensitivity!A29 | B43: =Sensitivity!H29 | C43: =Sensitivity!B29
A45: Derived Values (read-only, computed from Inputs)
A46: ATTACK (= Flat ATTACK x (1+ATTACK%/100)) | B46: =Inputs!$B$5*(1+Inputs!$B$6/100)
A47: STAT_DAMAGE % (= 1% of total INT + 0.25% of LUK) | B47: =(Inputs!$B$11*(1+Inputs!$B$12/100))*0.01+Inputs!$B$13*0.0025
A48: Basic Attack (Chain Lightning) Input Level (4th job formula) | B48: =MAX(0,(Inputs!$B$3-100)*3)+Inputs!$B$27+Inputs!$B$28
A49: Basic Attack Factor (factorIndex 21, from Chain Lightning reverse-engineering) | B49: =INDEX(FactorTable!$B$2:$Y$301, MATCH(ROUND(MIN(300,MAX(1,Summary!$B$48)),0), FactorTable!$A$2:$A$301,0), 22)
A50: SKILL_COEFFICIENT — Chain Lightning base coefficient % (before Skill Mastery) | B50: =290*Summary!$B$49/1000
A51: Normal-Monster Weight (= 0 for boss, 1 for normal, Breakthrough Normal Weight % for breakthrough, 0 for pvp) | B51: =IF(Inputs!$B$4="normal",1,IF(Inputs!$B$4="breakthrough",Inputs!$B$36/100,0))
A53: Average Buff Multiplier (Magic Guard + Meditation, summed; then Infinity) | B53: =(1+(IF(Calc!C3=TRUE,Calc!F3*IF(AND(Inputs!$B$4<>"pvp",Inputs!$B$35>0),(((Calc!R3-1)*(Skills!S3*(1+(Inputs!$B$33+IF(Inputs!$B$3>=117,Calc!F22,0))/100))+MIN((Skills!S3*(1+(Inputs!$B$33+IF(Inputs!$B$3>=117,Calc!F22,0))/100)),MAX(0,Inputs!$B$35-((Calc!R3-1)*Skills!D3))))/Inputs!$B$35),IF(Inputs!$B$4="pvp",MIN((Skills!S3*(1+(Inputs!$B$33+IF(Inputs!$B$3>=117,Calc!F22,0))/100)),15)/15,(Skills!S3*(1+(Inputs!$B$33+IF(Inputs!$B$3>=117,Calc!F22,0))/100))/Skills!D3)),0)+IF(Calc!C4=TRUE,Calc!F4*IF(AND(Inputs!$B$4<>"pvp",Inputs!$B$35>0),(((Calc!R4-1)*(Skills!S4*(1+(Inputs!$B$33+IF(Inputs!$B$3>=117,Calc!F22,0))/100))+MIN((Skills!S4*(1+(Inputs!$B$33+IF(Inputs!$B$3>=117,Calc!F22,0))/100)),MAX(0,Inputs!$B$35-((Calc!R4-1)*Skills!D4))))/Inputs!$B$35),IF(Inputs!$B$4="pvp",MIN((Skills!S4*(1+(Inputs!$B$33+IF(Inputs!$B$3>=117,Calc!F22,0))/100)),15)/15,(Skills!S4*(1+(Inputs!$B$33+IF(Inputs!$B$3>=117,Calc!F22,0))/100))/Skills!D4)),0))/100)*IF(Calc!C16=TRUE,(1+Calc!F16*IF(AND(Inputs!$B$4<>"pvp",Inputs!$B$35>0),(((Calc!R16-1)*(Skills!S16*(1+(Inputs!$B$33+IF(Inputs!$B$3>=117,Calc!F22,0))/100))+MIN((Skills!S16*(1+(Inputs!$B$33+IF(Inputs!$B$3>=117,Calc!F22,0))/100)),MAX(0,Inputs!$B$35-((Calc!R16-1)*Skills!D16))))/Inputs!$B$35),IF(Inputs!$B$4="pvp",MIN((Skills!S16*(1+(Inputs!$B$33+IF(Inputs!$B$3>=117,Calc!F22,0))/100)),15)/15,(Skills!S16*(1+(Inputs!$B$33+IF(Inputs!$B$3>=117,Calc!F22,0))/100))/Skills!D16))/100),1)
A54: Monster Damage Taken Bonus % (Freezing Breath - Weaken + Elemental Reset, summed) | B54: =IF(Inputs!$B$3>=118,15*IF(Inputs!$B$4="pvp",MIN((30*(1+(Inputs!$B$33+IF(Inputs!$B$3>=117,Calc!F22,0))/100)),15)/15,(30*(1+(Inputs!$B$33+IF(Inputs!$B$3>=117,Calc!F22,0))/100))/Skills!D8),0)+IF(Calc!C14=TRUE,Calc!F14,0)
A55: Damage % Bonus (Frozen Break + Frost Clutch, flat) | B55: =IF(Inputs!$B$3>=66,15,0)+IF(Inputs!$B$3>=98,10,0)+IF(Inputs!$B$3>=125,20,0)
A56: Attack Speed Bonus % (MP Eater - MP Boost, always-on once unlocked) | B56: =IF(Calc!C13=TRUE,Calc!F13,0)
A57: Actions Per Second (Attack Speed combined via diminishing-returns stack, factor 150, then capped) | B57: =1+MIN(150,150*(1-(1-Inputs!$B$10/150)*(1-B56/150)))/100
...

Sheet Sensitivity
A1: Marginal DPS per +1 (percentage point / skill level / flat point)
A2: Attack Speed and Def Pen combine their +1 via the diminishing-returns formula (new = (1-(1-old/factor)*(1-1/factor))*factor), not a flat add.
A4: Stat | B4: Units per +1% DPS | C4: Type | D4: Current Value | E4: New Value | F4: Baseline Total DPS | G4: New Total DPS | H4: DPS Gain | I4: % Gain
A5: Flat INT | B5: =IFERROR(1/(I5-100),"n/a") | C5: flat | D5: =Inputs!$B$11 | E5: =(Inputs!$B$11+1) | F5: =Summary!$B$3 | G5: =B66 | H5: =G5-F5 | I5: =IF(F5=0,0,G5/F5*100)
A6: INT % | B6: =IFERROR(1/(I6-100),"n/a") | C6: pct | D6: =Inputs!$B$12 | E6: =(Inputs!$B$12+1) | F6: =Summary!$B$3 | G6: =B103 | H6: =G6-F6 | I6: =IF(F6=0,0,G6/F6*100)
A7: DAMAGE % | B7: =IFERROR(1/(I7-100),"n/a") | C7: pct | D7: =Inputs!$B$14 | E7: =(Inputs!$B$14+1) | F7: =Summary!$B$3 | G7: =B140 | H7: =G7-F7 | I7: =IF(F7=0,0,G7/F7*100)
A8: DAMAGE_AMP % | B8: =IFERROR(1/(I8-100),"n/a") | C8: pct | D8: =Inputs!$B$15 | E8: =(Inputs!$B$15+1) | F8: =Summary!$B$3 | G8: =B177 | H8: =G8-F8 | I8: =IF(F8=0,0,G8/F8*100)
A9: BOSS_DAMAGE % | B9: =IFERROR(1/(I9-100),"n/a") | C9: pct | D9: =Inputs!$B$19 | E9: =(Inputs!$B$19+1) | F9: =Summary!$B$3 | G9: =B214 | H9: =G9-F9 | I9: =IF(F9=0,0,G9/F9*100)
A10: NORMAL_DAMAGE % | B10: =IFERROR(1/(I10-100),"n/a") | C10: pct | D10: =Inputs!$B$20 | E10: =(Inputs!$B$20+1) | F10: =Summary!$B$3 | G10: =B251 | H10: =G10-F10 | I10: =IF(F10=0,0,G10/F10*100)
A11: FINAL_DAMAGE % (multiplicative source) | B11: =IFERROR(1/(I11-100),"n/a") | C11: mult | D11: =Inputs!$B$23 | E11: =((((1+Inputs!$B$23/100)*(1.01))-1)*100) | F11: =Summary!$B$3 | G11: =B288 | H11: =G11-F11 | I11: =IF(F11=0,0,G11/F11*100)
A12: MIN_DAMAGE % | B12: =IFERROR(1/(I12-100),"n/a") | C12: pct | D12: =Inputs!$B$21 | E12: =(Inputs!$B$21+1) | F12: =Summary!$B$3 | G12: =B325 | H12: =G12-F12 | I12: =IF(F12=0,0,G12/F12*100)
A13: MAX_DAMAGE % | B13: =IFERROR(1/(I13-100),"n/a") | C13: pct | D13: =Inputs!$B$22 | E13: =(Inputs!$B$22+1) | F13: =Summary!$B$3 | G13: =B362 | H13: =G13-F13 | I13: =IF(F13=0,0,G13/F13*100)
A14: CRIT_RATE % | B14: =IFERROR(1/(I14-100),"n/a") | C14: pct | D14: =Inputs!$B$8 | E14: =(Inputs!$B$8+1) | F14: =Summary!$B$3 | G14: =B399 | H14: =G14-F14 | I14: =IF(F14=0,0,G14/F14*100)
A15: CRIT_DAMAGE % | B15: =IFERROR(1/(I15-100),"n/a") | C15: pct | D15: =Inputs!$B$9 | E15: =(Inputs!$B$9+1) | F15: =Summary!$B$3 | G15: =B436 | H15: =G15-F15 | I15: =IF(F15=0,0,G15/F15*100)
A16: ATTACK_SPEED % (diminishing returns, factor 150) | B16: =IFERROR(1/(I16-100),"n/a") | C16: dr150 | D16: =Inputs!$B$10 | E16: =((1-(1-Inputs!$B$10/150)*(1-1/150))*150) | F16: =Summary!$B$3 | G16: =B473 | H16: =G16-F16 | I16: =IF(F16=0,0,G16/F16*100)
A17: DEF_PEN % (diminishing returns, factor 100) | B17: =IFERROR(1/(I17-100),"n/a") | C17: dr100 | D17: =Inputs!$B$18 | E17: =((1-(1-Inputs!$B$18/100)*(1-1/100))*100) | F17: =Summary!$B$3 | G17: =B510 | H17: =G17-F17 | I17: =IF(F17=0,0,G17/F17*100)
A18: BASIC_ATTACK_DAMAGE % | B18: =IFERROR(1/(I18-100),"n/a") | C18: pct | D18: =Inputs!$B$16 | E18: =(Inputs!$B$16+1) | F18: =Summary!$B$3 | G18: =B547 | H18: =G18-F18 | I18: =IF(F18=0,0,G18/F18*100)
A19: SKILL_DAMAGE % | B19: =IFERROR(1/(I19-100),"n/a") | C19: pct | D19: =Inputs!$B$17 | E19: =(Inputs!$B$17+1) | F19: =Summary!$B$3 | G19: =B584 | H19: =G19-F19 | I19: =IF(F19=0,0,G19/F19*100)
A20: Skill Level Bonus — 1st Job | B20: =IFERROR(1/(I20-100),"n/a") | C20: level | D20: =Inputs!$B$24 | E20: =(Inputs!$B$24+1) | F20: =Summary!$B$3 | G20: =B621 | H20: =G20-F20 | I20: =IF(F20=0,0,G20/F20*100)
