Workbook

Sheet README
A1: Marksman — DPS Calculator: How to Use This Workbook
A3: How to use this workbook
A4: Only edit the yellow-highlighted cells on the Inputs sheet — every other sheet is computed from those values and will be overwritten if you rebuild the workbook.
A5: Summary shows Total DPS, a Per-Skill DPS Breakdown (damage-dealing skills only — buffs/passives that never deal their own damage are omitted), and a Marginal DPS & Stat Value table showing the DPS gained per +1 of each stat.
A6: Sensitivity has the full detail behind that marginal-value table — one self-contained block per stat, showing exactly how bumping that stat by +1 changes every downstream number.
A7: CubeData/PotentialCubes model your current gear's Potential Cube lines and drive cube-reroll expected-value decisions. For the full standalone Potential Cube EV calculator (exact optimal-stopping math, works from this workbook alone), see tools/potential_cubes_ev.py in the project repo.
A9: Design decisions & assumptions
A10: Critical Shot, Archer Mastery, Bow Acceleration, Physical Training, Bow Mastery, Extreme Archery/Reckless Hunt: Bow's own Final Damage component, Armor Break, Bow Expert, and Soul Arrow: Bow's own DEX/Attack bonuses are always-on passives assumed to already be reflected in your own Inputs stat entries — only their Sensitivity marginal delta (what changes if their mastery level differs from what you assumed) is modeled live, matching this project's established convention (see build_shadower_workbook.py's own README). Soul Arrow: Bow's flat DEX bonus specifically has NO Sensitivity delta row (no percentage-bucket exists for a flat sub-stat bonus in this template) — just assume your own Inputs!Flat DEX already includes it.
A11: Concentration ("Focused Fury" in the Aug 13 patch notes — same skill, wiki and Nexon's own English patch notes use different names) and Mortal Blow are both modeled at steady-state maximum stacks/uptime once unlocked, not as exact stack-timer/hit-counter state machines — the same simplification tier as every other accumulating-stack mechanic in this project.
A12: Arrow Platter's per-level damage curve is confirmed via idle.maplestorywiki.net/w/Quiver_Flow (the skill's real curve lives under an old/alternate page name — its current-name page, .../w/Arrow_Platter, is a wiki content bug rendering Wind Arrow II's data instead). Its real cooldown (40s, not 60s) came from that same page's infobox.
A13: Quiver Cartridge's Attack-Speed-scaled tick rate uses the English wiki wording ('up to 0.4 times based on Attack Speed') over the Korean text's disagreeing 'up to 2x', per user direction — tick multiplier = 1+0.4*(TotalAS%/150), same 150%-AS cap as Actions Per Second. Flash Mirage's own Attack-Speed-scaled activation-chance text is separately still too vague/self-contradictory (English vs. Korean disagree) to model precisely — it uses a flat, non-AS-scaled proc rate instead, flagged as a simplification.
A14: Final Attack: Bow + Advanced Final Attack are folded into Empowered Piercing Arrow's own coefficient as a steady-state average addition, not modeled as an independent damage pipeline with its own separate Final Damage chain.
... A17: Not modeled (out of scope): all forms of crowd control, Accuracy, Evasion, Defense reduction/penetration debuffs on the character's own Defense stat, movement speed, Illusion Step's own Evasion/damage-taken-reduction phase, and Companion Summoning Time.

Sheet Inputs
A1: Marksman — DPS Calculator Inputs
A3: Character Level | B3: 200
A4: Monster Type ("boss", "normal", "breakthrough", or "pvp") | B4: boss
A5: Flat ATTACK | B5: 10000
A6: ATTACK % | B6: 0
A7: Monster Defense (flat, post-x100/x10 scaling) | B7: 0
A8: CRIT_RATE % | B8: 0
A9: CRIT_DAMAGE % | B9: 0
A10: ATTACK_SPEED % (base, excludes Archer Mastery/Bow Acceleration) | B10: 0
A11: Flat DEX (include Soul Arrow: Bow's own bonus if unlocked) | B11: 0
A12: DEX % | B12: 0
A13: STR | B13: 0
A14: DAMAGE % | B14: 0
A15: DAMAGE_AMP % | B15: 0
A16: BASIC_ATTACK_DAMAGE % | B16: 0
... A28: Skill Level Bonus — All Skills | B28: 0
A30: Additional Bonuses
A31: Skill Cooldown Decrease (seconds, only skills/buffs the character actively casts) | B31: 0
A32: Basic Attack Target Increase (flat, adds to the 6-target normal-monster base) | B32: 1
A33: Buff Duration Increase % | B33: 0
A34: Companion Summoning Time Increase % (companions not modeled — always 0 DPS impact) | B34: 0
A35: Fixed Fight Duration (seconds, boss or normal — leave 0 for steady-state DPS; ignored for pvp) | B35: 0
A36: Chapter Breakthrough: Normal-Monster Weight % (only used when Monster Type = breakthrough) | B36: 60
A37: Max Enemies Actually In Range (normal monsters only; default 999 = uncapped) | B37: 999

Sheet FactorTable
A1: Level | B1: F0 | C1: F1 | D1: F2 | E1: F3 | F1: F4 | G1: F5 | H1: F6 | I1: F7 | J1: F8 | K1: F9 | L1: F10 | M1: F11 | N1: F12 | O1: F13 | P1: F14 | Q1: F15 | R1: F16 | S1: F17 | T1: F18 | U1: F19 | V1: F20 | W1: F21 | X1: F22 | Y1: F23
A2: 1 | B2: 0 | C2: 1000 | D2: 1000 | E2: 1000 | F2: 1000 | G2: 1000 | H2: 1000 | I2: 1000 | J2: 1000 | K2: 1000 | L2: 1000 | M2: 1000 | N2: 1000 | O2: 1000 | P2: 1000 | Q2: 1000 | R2: 1000 | S2: 1000 | T2: 1000 | U2: 1000 | V2: 1000 | W2: 1000 | X2: 1000 | Y2: 1000
A3: 2 | B3: 0 | C3: 1015 | D3: 1020 | E3: 1030 | F3: 1040 | G3: 1050 | H3: 1060 | I3: 1070 | J3: 1020 | K3: 1020 | L3: 1020 | M3: 1000 | N3: 1010 | O3: 1020 | P3: 1030 | Q3: 1040 | R3: 1050 | S3: 1060 | T3: 1070 | U3: 1080 | V3: 1010 | W3: 1008 | X3: 1006 | Y3: 1100
A4: 3 | B4: 0 | C4: 1031 | D4: 1041 | E4: 1061 | F4: 1082 | G4: 1103 | H4: 1124 | I4: 1145 | J4: 1030 | K4: 1041 | L4: 1030 | M4: 1000 | N4: 1015 | O4: 1030 | P4: 1045 | Q4: 1060 | R4: 1075 | S4: 1090 | T4: 1105 | U4: 1120 | V4: 1020 | W4: 1012 | X4: 1009 | Y4: 1150
A5: 4 | B5: 0 | C5: 1047 | D5: 1062 | E5: 1093 | F5: 1126 | G5: 1159 | H5: 1192 | I5: 1226 | J5: 1040 | K5: 1062 | L5: 1040 | M5: 1000 | N5: 1020 | O5: 1040 | P5: 1060 | Q5: 1080 | R5: 1100 | S5: 1120 | T5: 1140 | U5: 1160 | V5: 1030 | W5: 1016 | X5: 1012 | Y5: 1200
A6: 5 | B6: 0 | C6: 1063 | D6: 1084 | E6: 1126 | F6: 1172 | G6: 1217 | H6: 1264 | I6: 1312 | J6: 1050 | K6: 1084 | L6: 1050 | M6: 1000 | N6: 1025 | O6: 1050 | P6: 1075 | Q6: 1100 | R6: 1125 | S6: 1150 | T6: 1175 | U6: 1200 | V6: 1040 | W6: 1020 | X6: 1015 | Y6: 1250
A7: 6 | B7: 0 | C7: 1079 | D7: 1106 | E7: 1160 | F7: 1219 | G7: 1278 | H7: 1340 | I7: 1404 | J7: 1060 | K7: 1106 | L7: 1060 | M7: 1000 | N7: 1030 | O7: 1060 | P7: 1090 | Q7: 1120 | R7: 1150 | S7: 1180 | T7: 1210 | U7: 1240 | V7: 1050 | W7: 1024 | X7: 1018 | Y7: 1300
A8: 7 | B8: 0 | C8: 1096 | D8: 1129 | E8: 1195 | F8: 1268 | G8: 1342 | H8: 1421 | I8: 1503 | J8: 1070 | K8: 1129 | L8: 1070 | M8: 1000 | N8: 1035 | O8: 1070 | P8: 1105 | Q8: 1140 | R8: 1175 | S8: 1210 | T8: 1245 | U8: 1280 | V8: 1060 | W8: 1028 | X8: 1021 | Y8: 1350
A9: 8 | B9: 0 | C9: 1113 | D9: 1152 | E9: 1231 | F9: 1319 | G9: 1410 | H9: 1507 | I9: 1609 | J9: 1080 | K9: 1152 | L9: 1080 | M9: 1000 | N9: 1040 | O9: 1080 | P9: 1120 | Q9: 1160 | R9: 1200 | S9: 1240 | T9: 1280 | U9: 1320 | V9: 1070 | W9: 1032 | X9: 1024 | Y9: 1400
A10: 9 | B10: 0 | C10: 1130 | D10: 1176 | E10: 1268 | F10: 1372 | G10: 1481 | H10: 1598 | I10: 1722 | J10: 1090 | K10: 1176 | L10: 1090 | M10: 1000 | N10: 1045 | O10: 1090 | P10: 1135 | Q10: 1180 | R10: 1225 | S10: 1270 | T10: 1315 | U10: 1360 | V10: 1080 | W10: 1036 | X10: 1027 | Y10: 1450
A11: 10 | B11: 0 | C11: 1147 | D11: 1200 | E11: 1307 | F11: 1427 | G11: 1556 | H11: 1694 | I11: 1843 | J11: 1100 | K11: 1200 | L11: 1100 | M11: 1000 | N11: 1050 | O11: 1100 | P11: 1150 | Q11: 1200 | R11: 1250 | S11: 1300 | T11: 1350 | U11: 1400 | V11: 1090 | W11: 1040 | X11: 1030 | Y11: 1500
A12: 11 | B12: 0 | C12: 1165 | D12: 1224 | E12: 1347 | F12: 1485 | G12: 1634 | H12: 1796 | I12: 1973 | J12: 1110 | K12: 1224 | L12: 1110 | M12: 1000 | N12: 1055 | O12: 1110 | P12: 1165 | Q12: 1220 | R12: 1275 | S12: 1330 | T12: 1385 | U12: 1440 | V12: 1100 | W12: 1044 | X12: 1033 | Y12: 1550
A13: 12 | B13: 0 | C13: 1183 | D13: 1249 | E13: 1388 | F13: 1545 | G13: 1716 | H13: 1904 | I13: 2112 | J13: 1120 | K13: 1249 | L13: 1120 | M13: 1000 | N13: 1060 | O13: 1120 | P13: 1180 | Q13: 1240 | R13: 1300 | S13: 1360 | T13: 1420 | U13: 1480 | V13: 1110 | W13: 1048 | X13: 1036 | Y13: 1600
... A301: 300 | B301: 0 | C301: 88573 | D301: 381637 | E301: 6991522 | F301: 125363453 | G301: 2185120762 | H301: 37157073039 | I301: 614631863830 | J301: 2000 | K301: 53326 | L301: 2500 | M301: 1100 | N301: 2500 | O301: 4000 | P301: 5500 | Q301: 7000 | R301: 8500 | S301: 10000 | T301: 11500 | U301: 13000 | V301: 7558 | W301: 2200 | X301: 1900 | Y301: 8800

Sheet Skills
A1: Key | B1: Name | C1: JobStep | D1: Cooldown(s) | E1: CostsActionSlot | F1: ActionsPerCast | G1: HitsPerCast | H1: ICD(s) | I1: ActiveWindow(s) | J1: ProcChance% | K1: RollsPerCast | L1: BaseDamage(tenths%) | M1: FactorIndex | N1: ScalesWithLevel | O1: SkillMasteryBonus% | P1: MasteryBossDamage% | Q1: MasteryNormalDamage% | R1: NormalMonsterTargets | S1: BuffTargetStat | T1: BuffDuration(s) | U1: TriggersBoltSurplus | V1: MapleHeroBase(tenths%) | W1: MapleHeroFactorIndex | X1: Note
A2: EMPOWERED_PIERCING_ARROW | B2: Empowered Piercing Arrow | C2: 4 | E2: FALSE | F2: 1 | G2: =IF(Inputs!$B$3>=134,6,5) | H2: 0 | I2: 0 | J2: 100 | K2: 1 | L2: 2900 | M2: 21 | N2: TRUE | O2: =Calc!F3*IF(Calc!C3=TRUE,1,0)/100*(1+Calc!F4*IF(Calc!C4=TRUE,1,0)/100)*25+SUMPRODUCT((Inputs!$B$3>={98,104,113,118,126,130})*{10,1,1,1,1,1}) | P2: =SUMPRODUCT((Inputs!$B$3>={108,122})*{10,10}) | Q2: 0 | R2: =6+Inputs!$B$32 | T2: 0 | U2: TRUE | X2: 4th-job basic-attack effect (supersedes Piercing Arrow/Piercing Arrow II/Arrow Blow, confirmed identical wiki wording — 290% damage to 6 target(s) in front 5 time(s) — to every other class's own 4th-job basic attack, including Bowmaster's own Arrow Stream). factorIndex 21, baseDamage 2900 tenths%. HitsPerCast = 5 (the wiki's own 'time(s)' figure), bumping to 6 once Mastery Lv.134 'Empowered Piercing Arrow - Strike' unlocks (confirmed via Marksman/Mastery this session — same pattern/level as Bowmaster's own Arrow Stream and Night Lord's own Showdown). SkillMasteryBonus% combines Final Attack: Crossbow + Advanced Final Attack's own steady-state contribution (ProcChance x AdditionalDamage% x (1+AdvancedFD%/100) x 25, the x25 converting Final Attack's own attack-triggered percentage into an equivalent addition to Empowered Piercing Arrow's per-hit coefficient at its own 5-hit-per-cast rate) PLUS the real level-gated Damage mastery chain (98/104/113/118/126/130, cumulative +10/11/12/13/14/15% per the wiki's own tooltip display — level_gated_sum uses DELTA increments (10, then +1 five times) to reproduce that cumulative curve, not the raw displayed percentages summed directly, same convention as Night Lord's own Showdown mastery and Bowmaster's own Arrow Stream mastery; an earlier version of this row summed the raw displayed values directly, giving a wrong 75% total instead of the correct 15% — caught and fixed during this session's own cross-check against Night Lord's established precedent). MasteryBossDamage% is the real Boss Monster Damage mastery sum (+10/10% at Lv.108/122, 20% total). TriggersBoltSurplus=TRUE — this row's own HitRate(perSec) feeds Bolt Surplus's combined dual-trigger rate.
A3: FINAL_ATTACK_CROSSBOW_HELPER | B3: Final Attack: Crossbow (helper) | C3: 2 | E3: FALSE | F3: 1 | G3: 1 | H3: 0 | I3: 0 | J3: 100 | K3: 1 | L3: 350 | M3: 21 | N3: TRUE | O3: =SUMPRODUCT((Inputs!$B$3>={52})*{50}) | P3: 0 | Q3: 0 | R3: 0 | T3: 0 | U3: FALSE | X3: Helper row only (no independent O-column DPS) — feeds Empowered Piercing Arrow's own coefficient. 25% chance, 35%->49% additional damage (levels 1-100), shared-value-different-key w/ Bowmaster's own Final Attack: Bow (confirmed identical curve via its own individual page). factorIndex 21, baseDamage 350 tenths%. Mastery Lv.52 'Final Attack - Damage' +50% (real SkillMasteryBonus%, confirmed via Marksman/Mastery this session — a bonus Bowmaster's own equivalent helper row may also be missing, not checked this session). Not otherwise patched (Aug 13 2026 patch notes make no mention of this skill).
A4: ADVANCED_FINAL_ATTACK_HELPER | B4: Advanced Final Attack (helper) | C4: 4 | E4: FALSE | F4: 1 | G4: 1 | H4: 0 | I4: 0 | J4: 100 | K4: 1 | L4: 5000 | M4: 21 | N4: TRUE | O4: =SUMPRODUCT((Inputs!$B$3>={111})*{50}) | P4: 0 | Q4: 0 | R4: 0 | T4: 0 | U4: FALSE | X4: Helper row only — feeds Empowered Piercing Arrow's own coefficient (Final Attack's own Final Damage bonus). +500%->900% FD (levels 1-200), shared verbatim w/ Bowmaster (confirmed identical curve via its own individual page). factorIndex 21, baseDamage 5000 tenths%. Mastery Lv.111 'Advanced Final Attack - Enhance' +50% (real SkillMasteryBonus%, confirmed via Marksman/Mastery this session — Bowmaster's own equivalent helper row is missing this bonus, flagged for the coordinator, not fixed here).
A5: COVERING_FIRE | B5: Covering Fire | C5: 1 | D5: 19 | E5: TRUE | F5: 1 | G5: 3 | H5: 0 | I5: 0 | J5: 100 | K5: 1 | L5: 2500 | M5: 12 | N5: TRUE | O5: =SUMPRODUCT((Inputs!$B$3>={39})*{50}) | P5: 0 | Q5: 0 | R5: 1 | T5: 0 | U5: FALSE | V5: 250 | W5: 0 | X5: Shared verbatim w/ Bowmaster (identical name AND numbers both classes, confirmed via its own Marksman-side page 'Retreat_Shot' this session, and via the patch notes' own shared 'Covering Fire' entry). 250%->375% damage x3 hits (levels 1-100), 19s cooldown. factorIndex 12, baseDamage 2500 tenths%. Mastery Lv.39 'Covering Fire - Damage' +50% (real SkillMasteryBonus%). Patched: skill use range +~20% (not modeled). Maple Hero target — see MAPLE_HERO_RATIOS (biggest share, 4x Bolt Burst's own share).
A6: BOLT_BURST | B6: Bolt Burst | C6: 3 | D6: 21 | E6: TRUE | F6: 1 | G6: 3 | H6: 0 | I6: 0 | J6: 100 | K6: 1 | L6: 4500 | M6: 12 | N6: TRUE | O6: =SUMPRODUCT((Inputs!$B$3>={66})*{50}) | P6: 0 | Q6: 0 | R6: 10 | T6: 0 | U6: FALSE | V6: 250 | W6: 0 | X6: Real page name is 'Bolt Flash' (confirmed via the Marksman/Skills overview page's own <a href> link — same 'display name differs from page slug' pattern as Bowmaster's own Arrow Platter/Quiver Flow, though this page itself is NOT bugged, its content matches its own infobox/description correctly). 'Shoots arrows in multiple directions to deal 450% damage to 10 nearby target(s) 3 time(s)', 21s cooldown. PATCHED: base damage 380%->450% (curve rescaled 450/380=1.1842x before reverse-engineering — factorIndex 12, baseDamage 4500 tenths% already reflects the patched value), attack range +~15% (not modeled). Mastery Lv.66 'Bolt Burst - Damage' +50% (real SkillMasteryBonus%). Maple Hero target — see MAPLE_HERO_RATIOS.
A7: FROSTPREY | B7: Frostprey | C7: 3 | D7: =IF(Inputs!$B$3>=102,60*0.6,60) | E7: TRUE | F7: 1 | G7: 1 | H7: 1.5 | I7: 30 | J7: 100 | K7: 1 | L7: 3000 | M7: 12 | N7: TRUE | O7: =SUMPRODUCT((Inputs!$B$3>={80})*{50}) | P7: 0 | Q7: =IF(Inputs!$B$3>=92,100,0) | R7: =3+IF(Inputs!$B$3>=76,2,0) | T7: 0 | U7: FALSE | V7: 250 | W7: 0 | X7: Real page name is 'Freezer' (confirmed via the Marksman/Skills overview page's own href link — same page-name-differs-from-display-name pattern as Bowmaster's own Arrow Platter/Quiver Flow). Summons Frostprey, attacks nearby targets on a periodic tick (EffectiveHits = HitsPerCast x (ActiveWindow/ICD), same mechanism as FP-Mage/ILM's own summon rows and Bowmaster's own Phoenix). PATCHED: hit interval 3s->1.5s (baked into ICD(s) directly, confirmed via the PDF as belonging to Frostprey itself, not Bolt Burst — resolves the prior session's own Frostprey/Bolt Burst pairing ambiguity), damage 600%->300% (curve rescaled 300/600=0.5x before reverse-engineering — factorIndex 12, baseDamage 3000 tenths% already reflects the patched value), freeze chance 20%->10% (CC, not modeled), duration 20s->30s (target detection range +~25% not modeled). Cooldown 60s, Mastery Lv.102 'Frostprey - Reuse' -50%->-40% per the patch (this session's own live wiki fetch confirms the mastery sits at level 102, not the PDF section header's stated 'Lv.104' — same judgment call Bowmaster's own build already made for its analogous Phoenix - Reuse mastery, trusting the wiki's level-threshold table over the PDF's own row-label level). Mastery Lv.76 'Frostprey - Target' +2 targets (base 3, wiki-confirmed — NOT the same +3 Bowmaster's own Phoenix gets at its own Lv.76 slot, a genuine per-class difference despite the shared level number), Lv.80 'Frostprey - Damage' +50% (real SkillMasteryBonus%), Lv.92 'Frostprey - Normal Monster Damage' +100%p (own MasteryNormalDamage%, scoped to this row only — not the global bucket). Maple Hero target — see MAPLE_HERO_RATIOS.
A8: MAPLE_HERO_HELPER | B8: Maple Hero (helper) | C8: 4 | E8: FALSE | F8: 1 | G8: 1 | H8: 0 | I8: 0 | J8: 100 | K8: 1 | L8: 250 | M8: 23 | N8: TRUE | O8: 0 | P8: 0 | Q8: 0 | R8: 0 | T8: 0 | U8: FALSE | X8: Shared ratio-feeder row (see MAPLE_HERO_RATIOS) for Bolt Burst/Frostprey/Covering Fire's own Final Damage chains — mirrors Shadower's own MAPLE_HERO_SHADOWER mechanism and Bowmaster's own MAPLE_HERO_HELPER. Confirmed this session via idle.maplestorywiki.net/w/Maple_Hero_(Marksman): uses the EXACT SAME numbers as Maple Hero (Bowmaster) at every level (not just the same ratio-shape), so this row's own (baseDamage, factorIndex) tuple is reused verbatim (factorIndex 23/baseDamage 250 tenths%, 0% residual). No independent DPS row of its own (Calc columns J-N blank/0, only D/E/F computed, read directly by each target row's own K-column formula — same 'no independent row' pattern as Shadower's own Maple Hero).
A9: SNIPE | B9: Snipe | C9: 4 | D9: 12 | E9: TRUE | F9: 1 | G9: 1 | H9: 0 | I9: 0 | J9: 100 | K9: 1 | L9: 38000 | M9: 12 | N9: TRUE | O9: =SUMPRODUCT((Inputs!$B$3>={106})*{50})+IF(Inputs!$B$3>=134,570*(Calc!E9/1000),0) | P9: 0 | Q9: 0 | R9: 1 | T9: 0 | U9: TRUE | X9: Single-target big hit: 'Aims at the target's vital point to deal 3800% damage', 12s cooldown (own wiki infobox), not patched. factorIndex 12, baseDamage 38000 tenths% (3800%->7600%, levels 1-200). Mastery Lv.106 'Snipe - Damage' +50% (real SkillMasteryBonus%). Mastery Lv.134 'Snipe - Empowered' (confirmed by user, not the wiki's own raw table order which mis-parsed as 132 due to this entry's unusually multi-part description cell): 'Leaves a mark on targets damaged by Snipe. When attacking marked targets with Snipe, deals {#expr:5700*(1+x*0.005)}% damage (Damage increases with Snipe skill level)' — resolves cleanly (0.44% max deviation) to the SAME factorIndex 12 as Snipe's own base curve, baseDamage 5700 tenths%, so it reuses Snipe's own Calc!E factor-lookup cell directly rather than needing a separate FactorTable lookup. Modeled at the same steady-state-always-active convention as Concentration/Mortal Blow, per user direction ('it's the same rate as the Snipe skill') — the mark persists across the single-target rotation this project already assumes, so every steady-state Snipe cast after unlock also deals this additive bonus. TriggersBoltSurplus=TRUE — this row's own HitRate(perSec) feeds Bolt Surplus's combined dual-trigger rate alongside Empowered Piercing Arrow.
A10: BOLT_SURPLUS | B10: Bolt Surplus | C10: 4 | E10: FALSE | F10: 1 | G10: =2+IF(Inputs!$B$3>=136,1,0) | H10: 0 | I10: 0 | J10: 15 | K10: 1 | L10: 6500 | M10: 21 | N10: TRUE | O10: =SUMPRODUCT((Inputs!$B$3>={120})*{50}) | P10: 0 | Q10: 0 | R10: =3+IF(Inputs!$B$3>=136,2,0) | T10: 0 | U10: FALSE | X10: Dual-trigger proc: 'When attacking with Empowered Piercing Arrow and Snipe, an extra explosion occurs with a 15% [chance] to deal 650% damage to 3 nearby target(s) 2 time(s)', own wiki infobox lists 'Cooldown: 0.1 sec' (functionally non-restrictive vs. its own 15% proc gate — modeled with NO Cooldown(s) field at all, like Shadower's own Toxic Venom, since its O-column DPS bypasses the normal per-row cooldown/rate machinery entirely). Combined trigger rate = the summed per-second hit rate of every row flagged TriggersBoltSurplus=TRUE (Empowered Piercing Arrow + Snipe) — same SUMPRODUCT-over-a-boolean-column mechanism as Shadower's own TriggersToxicVenom, applied here to exactly two specific trigger sources instead of every damage row. Not patched. factorIndex 21, baseDamage 6500 tenths% (650%->1170%, levels 1-200). Mastery Lv.120 'Bolt Surplus - Damage' +50% (real SkillMasteryBonus%), Lv.136 'Bolt Surplus - Strike & Target' +1 strike/+2 targets (HitsPerCast 2->3, NormalMonsterTargets 3->5, both live level-gated once Lv.136 hits).
A11: ARROW_ILLUSION | B11: Arrow Illusion | C11: 4 | D11: 45 | E11: TRUE | F11: 1 | G11: 1 | H11: 1.5 | I11: 25 | J11: 100 | K11: 1 | L11: 12000 | M11: 12 | N11: TRUE | O11: =SUMPRODUCT((Inputs!$B$3>={128})*{50}) | P11: 0 | Q11: 0 | R11: 10 | T11: 0 | U11: FALSE | X11: Channeled turret: 'Summons an illusionary arrow...binds nearby targets for 3 sec (CC, not modeled), and attacks 10 nearby target(s) every 3 sec for 25 sec to deal 2400% damage', 45s cooldown (own wiki infobox), same EffectiveHits tick mechanism as Frostprey/Bowmaster's own Phoenix. PATCHED: hit interval 3s->1.5s (baked into ICD(s)), damage 2400%->1200% (curve rescaled 1200/2400=0.5x before reverse-engineering — factorIndex 12, baseDamage 12000 tenths% already reflects the patched value), added 'max 1 placement at a time' (self-uptime cap already implicit in this project's single-instance summon treatment, no code change needed). Mastery Lv.128 'Arrow Illusion - Damage' +50% (real SkillMasteryBonus%; the same mastery tier also adds a bind-on-expiry CC effect, not modeled).
A12: BLINK_BOLT | B12: Blink Bolt | C12: 3 | E12: FALSE | F12: 1 | G12: 1 | H12: 0 | I12: 0 | J12: 100 | K12: 1 | L12: 250 | M12: 22 | N12: TRUE | O12: 0 | P12: 0 | Q12: 0 | R12: 0 | S12: ATTACK | T12: 0 | U12: FALSE | X12: 'Creates a special mark for 30 sec. While the mark lasts, increases Attack by 25%->40% (levels 1-200). When you use this skill again, you move to the mark's location and the mark disappears.' Own wiki infobox confirms Cooldown=10s (matches the prior session's own direct confirmation) — but the skill's own description is a TOGGLE (recast consumes/teleports the mark, ending the buff), not a typical refresh-on-recast buff like Nimble Feet. FLAGGED modeling caveat: this row is modeled as an unconditional always-on Attack% contribution (no duty-cycle/uptime computation at all, same treatment as Marksmanship's own unconditional half) per this session's directive to use the plan's own stated assumption ('since duration(30s) > cooldown(10s), effectively a permanent buff at full uptime') rather than modeling the toggle mechanic's real alternating on/off behavior in auto-combat, which could plausibly yield a lower ~50% uptime instead — a human should revisit this if real gameplay data suggests otherwise. Not patched. factorIndex 22, baseDamage 250 tenths%. Teleport-movement component out of scope.
A13: MARKSMANSHIP_BASE | B13: Marksmanship (unconditional half) | C13: 3 | E13: FALSE | F13: 1 | G13: 1 | H13: 0 | I13: 0 | J13: 100 | K13: 1 | L13: 100 | M13: 22 | N13: TRUE | O13: 0 | P13: 0 | Q13: 0 | R13: 0 | S13: ATTACK | T13: 0 | U13: FALSE | X13: PATCHED: 'Base Attack +10%, additional +10% when 1 target' replaces the old flat '+20% at 1 target only' wording — modeled as two separate rows (this unconditional half + MARKSMANSHIP_COND's conditional half), summed additively into the same Attack% bucket as Illusion Step (Verification item 6 — these must never multiply against each other). Half of the wiki's own pre-patch curve (10%->16%, levels 1-200), assumed symmetric 50/50 split at every level (the patch note only confirms the level-1 split, 10/10) — factorIndex 22, baseDamage 100 tenths%. Shared verbatim w/ Bowmaster (identical name, wording, and numbers confirmed both classes via the patch notes' own shared 'Marksmanship' entry, and via this session's own live fetch of Marksman's own Marksmanship page).
A14: MARKSMANSHIP_COND | B14: Marksmanship (conditional half, 1 target) | C14: 3 | E14: FALSE | F14: 1 | G14: 1 | H14: 0 | I14: 0 | J14: 100 | K14: 1 | L14: 100 | M14: 22 | N14: TRUE | O14: 0 | P14: 0 | Q14: 0 | R14: 0 | S14: ATTACK_COND_1TARGET | T14: 0 | U14: FALSE | X14: Conditional half of Marksmanship's own patched Attack% bonus — blended via the same monster_blend_expr helper already used for Boss/Normal Monster Damage% (boss/pvp -> full value, normal -> 0, breakthrough -> weighted), applied to the Attack% bucket instead. Same curve/tuple as MARKSMANSHIP_BASE (factorIndex 22, baseDamage 100 tenths%).
A15: ILLUSION_STEP | B15: Illusion Step | C15: 4 | D15: 24 | E15: FALSE | F15: 1 | G15: 1 | H15: 0 | I15: 0 | J15: 100 | K15: 1 | L15: 140 | M15: 22 | N15: TRUE | O15: 0 | P15: 0 | Q15: 0 | R15: 0 | S15: ATTACK | T15: 15 | U15: FALSE | X15: Cycling passive: Attack+14%->22.4% for 15s, then swaps to Evasion+15->24/damage taken -10%->16% for 9s (not modeled — those components have no mechanic anywhere in this calculator). Modeled as a duty-cycled buff (Cooldown(s)=24 = full 15+9s cycle length, BuffDuration(s)=15 = the Attack-active portion, giving a 0.625 duty-cycle uptime) — same buff_uptime machinery as every other timed buff in this project. factorIndex 22, baseDamage 140 tenths%. Not patched. Shared verbatim w/ Bowmaster (confirmed via this session's own live fetch of Marksman's own Illusion Step page).
A16: SHARP_EYES | B16: Sharp Eyes | C16: 4 | D16: 35 | E16: TRUE | F16: 1 | G16: 1 | H16: 0 | I16: 0 | J16: 100 | K16: 1 | L16: 400 | M16: 21 | N16: TRUE | O16: 0 | P16: 0 | Q16: 0 | R16: 0 | S16: CRIT_DAMAGE | T16: 18 | U16: FALSE | X16: Self-inclusive ally buff (matches Bishop's own 'allied players' precedent) — flat +20% Crit Rate (non-scaling, not represented in this row's own BaseDamage/FactorIndex; added directly as a hardcoded 20 in the Crit-Rate-bonus accumulator formula in build_summary_sheet) + scaling Crit Damage +40%->72% (levels 1-200, this row's own curve — factorIndex 21, baseDamage 400 tenths%) for 18s, cooldown 35s. Not patched. Shared verbatim w/ Bowmaster (confirmed via this session's own live fetch of Marksman's own Sharp Eyes page).
A17: MORTAL_BLOW | B17: Mortal Blow | C17: 3 | E17: FALSE | F17: 1 | G17: 1 | H17: 0 | I17: 0 | J17: 100 | K17: 1 | L17: 120 | M17: 22 | N17: TRUE | O17: 0 | P17: 0 | Q17: 0 | R17: 0 | S17: FINAL_DAMAGE | T17: 0 | U17: FALSE | X17: Upon attacking a target directly 40 times, +10%->16%(pre-patch curve) FD for 5s. Modeled at steady state (assumed always active once unlocked), not an exact hit-counter/timer state machine — same simplification tier every other steady-state buff in this project uses. PATCHED: base 10%->12% (curve rescaled 12/10=1.2x before reverse-engineering — factorIndex 22, baseDamage 120 tenths% already reflects the patched value). Shared verbatim w/ Bowmaster (confirmed via this session's own live fetch of Marksman's own Mortal Blow page).
A18: NIMBLE_FEET | B18: Nimble Feet | C18: 1 | D18: 60 | E18: TRUE | F18: 1 | G18: 1 | H18: 0 | I18: 0 | J18: 100 | K18: 1 | L18: 150 | M18: 0 | N18: FALSE | O18: 0 | P18: 0 | Q18: 0 | R18: 1 | S18: ATTACK_SPEED | T18: 15 | U18: FALSE | X18: Shared cross-tree verbatim w/ Night Lord/Shadower/FP-Mage/Bowmaster (byte-identical wiki wording — '+15% Attack Speed, +10% Speed for 15 sec'). Flat +15% Attack Speed / +10% Speed for 15s, 60s cooldown, non-scaling. FactorIndex unused placeholder.
A19: CRITICAL_SHOT | B19: Critical Shot | C19: 1 | E19: FALSE | F19: 1 | G19: 1 | H19: 0 | I19: 0 | J19: 100 | K19: 1 | L19: 50 | M19: 22 | N19: TRUE | O19: 0 | P19: 0 | Q19: 0 | R19: 0 | S19: CRIT_RATE | T19: 0 | U19: FALSE | X19: Magic Critical pattern — already baked into Inputs!CRIT_RATE%; feeds the 1st-Job Skill Level Bonus delta. factorIndex 22, baseDamage 50 tenths% (5%->6.5%, levels 1-100). Shared verbatim w/ Bowmaster (byte-identical wiki wording, confirmed both classes).
A20: ARCHER_MASTERY | B20: Archer Mastery (Attack Speed) | C20: 1 | E20: FALSE | F20: 1 | G20: 1 | H20: 0 | I20: 0 | J20: 100 | K20: 1 | L20: 50 | M20: 22 | N20: TRUE | O20: 0 | P20: 0 | Q20: 0 | R20: 0 | S20: ATTACK_SPEED | T20: 0 | U20: FALSE | X20: Magic Critical pattern — already baked into Inputs!ATTACK_SPEED%; feeds the 1st-Job Skill Level Bonus delta. factorIndex 22, baseDamage 50 tenths% (5%->6.5%, levels 1-100). Own Speed component not modeled. Shared verbatim w/ Bowmaster (byte-identical wiki wording).
A21: CROSSBOW_ACCELERATION | B21: Crossbow Acceleration | C21: 2 | E21: FALSE | F21: 1 | G21: 1 | H21: 0 | I21: 0 | J21: 100 | K21: 1 | L21: 50 | M21: 22 | N21: TRUE | O21: 0 | P21: 0 | Q21: 0 | R21: 0 | S21: ATTACK_SPEED | T21: 0 | U21: FALSE | X21: Real page name is 'Crossbow_Acceleration' (not 'Agile_Crossbows', despite that being the skill's own display name on the Marksman/Skills overview page — confirmed via the overview page's own href link). Magic Critical pattern — already baked into Inputs!ATTACK_SPEED%; feeds the 2nd-Job Skill Level Bonus delta. factorIndex 22, baseDamage 50 tenths% (5%->6.5%, levels 1-100). Shared-value-different-key w/ Bowmaster's own Bow Acceleration (confirmed identical curve via its own individual page).
A22: PHYSICAL_TRAINING | B22: Physical Training | C22: 2 | E22: FALSE | F22: 1 | G22: 1 | H22: 0 | I22: 0 | J22: 100 | K22: 1 | L22: 100 | M22: 22 | N22: TRUE | O22: 0 | P22: 0 | Q22: 0 | R22: 0 | S22: BASIC_ATTACK_DAMAGE | T22: 0 | U22: FALSE | X22: Magic Critical pattern — already baked into Inputs!BASIC_ATTACK_DAMAGE%; feeds the 2nd-Job Skill Level Bonus delta. factorIndex 22, baseDamage 100 tenths% (10%->13%, levels 1-100). Shared verbatim w/ Bowmaster (byte-identical wiki wording, confirmed both classes).
A23: CROSSBOW_MASTERY | B23: Crossbow Mastery | C23: 2 | E23: FALSE | F23: 1 | G23: 1 | H23: 0 | I23: 0 | J23: 100 | K23: 1 | L23: 150 | M23: 22 | N23: TRUE | O23: 0 | P23: 0 | Q23: 0 | R23: 0 | S23: MIN_DAMAGE | T23: 0 | U23: FALSE | X23: Magic Critical pattern — already baked into Inputs!MIN_DAMAGE%; feeds the 2nd-Job Skill Level Bonus delta. factorIndex 22, baseDamage 150 tenths% (15%->19.5%, levels 1-100). Shared-value-different-key w/ Bowmaster's own Bow Mastery (confirmed identical curve via its own individual page).
A24: RECKLESS_HUNT_CROSSBOW | B24: Extreme Archery / Reckless Hunt: Crossbow | C24: 3 | E24: FALSE | F24: 1 | G24: 1 | H24: 0 | I24: 0 | J24: 100 | K24: 1 | L24: 150 | M24: 22 | N24: TRUE | O24: 0 | P24: 0 | Q24: 0 | R24: 0 | S24: FINAL_DAMAGE | T24: 0 | U24: FALSE | X24: Own Final Damage component only (Defense reduction not modeled — no Defense mechanic exists anywhere in this calculator). Magic Critical pattern — already baked into Inputs!FINAL_DAMAGE%; feeds the 3rd-Job Skill Level Bonus delta. factorIndex 22, baseDamage 150 tenths% (15%->24%, levels 1-200). PATCHED name: wiki still shows 'Extreme Archery: Crossbow', Aug 13 patch notes confirm current name 'Reckless Hunt: Crossbow' (-10%->-5% Defense, not modeled either way; FD component itself unpatched). Shared-value-different-key w/ Bowmaster's own Reckless Hunt: Bow (confirmed identical curve via its own individual page).
A25: LAST_MAN_STANDING_FD | B25: Last Man Standing (base FD) | C25: 4 | E25: FALSE | F25: 1 | G25: 1 | H25: 0 | I25: 0 | J25: 100 | K25: 1 | L25: 150 | M25: 22 | N25: TRUE | O25: 0 | P25: 0 | Q25: 0 | R25: 0 | S25: FINAL_DAMAGE | T25: 0 | U25: FALSE | X25: Marksman's own 4th-job Final-Damage passive slot (NOT shared with Bowmaster's Armor Break — a genuinely different mechanic per the plan). 'Increases Final Damage by 15%->24% (levels 1-200). If there is 1 enemy, additionally increased by 5%->8.9%.' This row models the unconditional base-FD half; see LAST_MAN_STANDING_COND for the conditional 1-enemy half. Magic Critical pattern — already baked into Inputs!FINAL_DAMAGE%; feeds the 4th-Job Skill Level Bonus delta. factorIndex 22, baseDamage 150 tenths%. Not patched.
A26: LAST_MAN_STANDING_COND | B26: Last Man Standing (1-enemy conditional FD) | C26: 4 | E26: FALSE | F26: 1 | G26: 1 | H26: 0 | I26: 0 | J26: 100 | K26: 1 | L26: 50 | M26: 22 | N26: TRUE | O26: 0 | P26: 0 | Q26: 0 | R26: 0 | S26: FINAL_DAMAGE | T26: 0 | U26: FALSE | X26: Conditional +5%->6.9%(levels 1-140, own confirmed curve range) Final Damage half of Last Man Standing, active only at 1 target (boss or pvp — confirmed by user). Modeled as a LIVE row, same monster_blend_expr mechanism as Marksmanship's own conditional Attack% half (full value at boss/pvp, zero at normal, weighted at breakthrough), folded additively into R_MORTAL_BLOW_BONUS's own Final Damage bucket alongside Mortal Blow — an earlier version of this row assumed Final Damage had no per-monster-type blend mechanism and left it flat/baked into Inputs, which was wrong; the same blend mechanism Attack% already uses applies here too, just added as another multiplicative-chain contributor instead of an Attack%-bucket one. factorIndex 22, baseDamage 50 tenths%.
A27: CROSSBOW_EXPERT_SKILL | B27: Crossbow Expert (Skill Damage) | C27: 4 | E27: FALSE | F27: 1 | G27: 1 | H27: 0 | I27: 0 | J27: 100 | K27: 1 | L27: 150 | M27: 22 | N27: TRUE | O27: 0 | P27: 0 | Q27: 0 | R27: 0 | S27: SKILL_DAMAGE | T27: 0 | U27: FALSE | X27: Magic Critical pattern — already baked into Inputs!SKILL_DAMAGE%; feeds the 4th-Job Skill Level Bonus delta (Skill Damage side). factorIndex 22, baseDamage 150 tenths% (15%->24%, levels 1-200). Not patched. Shared-value-different-key w/ Bowmaster's own Bow Expert (confirmed identical curve via its own individual page).
A28: CROSSBOW_EXPERT_MAXDMG | B28: Crossbow Expert (Max Damage Multiplier) | C28: 4 | E28: FALSE | F28: 1 | G28: 1 | H28: 0 | I28: 0 | J28: 100 | K28: 1 | L28: 200 | M28: 22 | N28: TRUE | O28: 0 | P28: 0 | Q28: 0 | R28: 0 | S28: MAX_DAMAGE | T28: 0 | U28: FALSE | X28: Same skill as Crossbow Expert (Skill Damage) above, +20%->32% Max Damage Multiplier. Magic Critical pattern — already baked into Inputs!MAX_DAMAGE%; feeds the 4th-Job Skill Level Bonus delta (Max Damage Multiplier side). factorIndex 22, baseDamage 200 tenths%.
A29: SOUL_ARROW_CROSSBOW_ATK | B29: Soul Arrow: Crossbow (Attack%) | C29: 2 | E29: FALSE | F29: 1 | G29: 1 | H29: 0 | I29: 0 | J29: 100 | K29: 1 | L29: 120 | M29: 22 | N29: TRUE | O29: 0 | P29: 0 | Q29: 0 | R29: 0 | S29: ATTACK | T29: 0 | U29: FALSE | X29: Genuinely different mechanic from Bowmaster's own Soul Arrow: Bow (flat Attack%, no AS-scaling, no DEX bonus at all — per the plan's own NOT-shared list). Own scaling curve confirmed via its individual page (10%->13% pre-patch), PATCHED 10%->12% at level 1 (curve rescaled 12/10=1.2x before reverse-engineering — factorIndex 22, baseDamage 120 tenths% already reflects the patched value). Magic Critical pattern — already baked into Inputs!ATTACK_PCT (folds into the attack_mult delta bucket, same slot as Shadower's own Channel Karma); feeds the 2nd-Job Skill Level Bonus delta.

Sheet Calc
A1: Key | B1: Name | C1: Unlocked | D1: InputLevel | E1: Factor | F1: CoefficientPercent | G1: EffectiveHits | H1: ProcProbability | I1: MapleHeroMultiplier | J1: BaseDamage | K1: BaseHitDamage | L1: NonCritAvg | M1: CritAvg | N1: ExpectedDamage(perHit) | O1: DPS | P1: % of Total | Q1: InvCooldown | R1: CastsInFight | S1: HitRate(perSec)
A2: =Skills!A2 | B2: =Skills!B2 | C2: =Inputs!$B$3>=100 | F2: =Summary!$B$54+Skills!O2 | G2: =Skills!G2*IF(Skills!H2>0,Skills!I2/Skills!H2,1) | H2: =1-(1-Skills!J2/100)^Skills!K2 | I2: 1 | J2: =Summary!$B$50*(F2/100) | K2: =J2*(1+Summary!$B$51/100)*(1+Inputs!$B$14/100)*(1+IF(Inputs!$B$4="pvp",0,(1-Summary!$B$55)*(Inputs!$B$19+Skills!P2+Summary!$B$59)+Summary!$B$55*(Inputs!$B$20+Skills!Q2+Summary!$B$59))/100)*(1+Inputs!$B$15/100)*(5000/(6000+Inputs!$B$7*(1-Inputs!$B$18/100)))*(1+(Inputs!$B$23+Summary!$B$65)/100)*(1+(IF(Skills!A2="EMPOWERED_PIERCING_ARROW",Inputs!$B$16,Inputs!$B$17))/100)*(Summary!$B$57*I2) | L2: =K2*(MIN(Inputs!$B$21,Inputs!$B$22)/100+Inputs!$B$22/100)/2 | M2: =L2*(1+(Inputs!$B$9+Summary!$B$64)/100) | N2: =L2*(1-MIN((Inputs!$B$8+Summary!$B$58),100)/100)+M2*(MIN((Inputs!$B$8+Summary!$B$58),100)/100) | O2: =IF(C2,Skills!G2*N2*Summary!$B$63*IF(Inputs!$B$4="pvp",1,(1-Summary!$B$55)*(1)+Summary!$B$55*(MIN(Skills!R2,Inputs!$B$37))),0) | P2: =IF(Summary!$B$3=0,0,O2/Summary!$B$3) | Q2: 0 | R2: 0 | S2: =IFERROR(O2/N2,0)
A3: =Skills!A3 | B3: =Skills!B3 | C3: =Inputs!$B$3>=50 | D3: =IF(Skills!C3=1,60+Inputs!$B$24+Inputs!$B$28,IF(Skills!C3=2,90+Inputs!$B$25+Inputs!$B$28,IF(Skills!C3=3,120+Inputs!$B$26+Inputs!$B$28,MAX(0,(Inputs!$B$3-100)*3)+Inputs!$B$27+Inputs!$B$28))) | E3: =INDEX(FactorTable!$B$2:$Y$301, MATCH(ROUND(MIN(300,MAX(1,D3)),0), FactorTable!$A$2:$A$301,0), Skills!M3+1) | F3: =IF(Skills!N3=TRUE,(Skills!L3/10)*(E3/1000),Skills!L3/10)+Skills!O3 | I3: 1
A4: =Skills!A4 | B4: =Skills!B4 | C4: =Inputs!$B$3>=105 | D4: =IF(Skills!C4=1,60+Inputs!$B$24+Inputs!$B$28,IF(Skills!C4=2,90+Inputs!$B$25+Inputs!$B$28,IF(Skills!C4=3,120+Inputs!$B$26+Inputs!$B$28,MAX(0,(Inputs!$B$3-100)*3)+Inputs!$B$27+Inputs!$B$28))) | E4: =INDEX(FactorTable!$B$2:$Y$301, MATCH(ROUND(MIN(300,MAX(1,D4)),0), FactorTable!$A$2:$A$301,0), Skills!M4+1) | F4: =IF(Skills!N4=TRUE,(Skills!L4/10)*(E4/1000),Skills!L4/10)+Skills!O4 | I4: 1
A5: =Skills!A5 | B5: =Skills!B5 | C5: =Inputs!$B$3>=35 | D5: =IF(Skills!C5=1,60+Inputs!$B$24+Inputs!$B$28,IF(Skills!C5=2,90+Inputs!$B$25+Inputs!$B$28,IF(Skills!C5=3,120+Inputs!$B$26+Inputs!$B$28,MAX(0,(Inputs!$B$3-100)*3)+Inputs!$B$27+Inputs!$B$28))) | E5: =INDEX(FactorTable!$B$2:$Y$301, MATCH(ROUND(MIN(300,MAX(1,D5)),0), FactorTable!$A$2:$A$301,0), Skills!M5+1) | F5: =IF(Skills!N5=TRUE,(Skills!L5/10)*(E5/1000),Skills!L5/10)+Skills!O5 | G5: =Skills!G5*IF(Skills!H5>0,Skills!I5/Skills!H5,1) | H5: =1-(1-Skills!J5/100)^Skills!K5 | I5: 1 | J5: =Summary!$B$50*(F5/100) | K5: =J5*(1+Summary!$B$51/100)*(1+Inputs!$B$14/100)*(1+IF(Inputs!$B$4="pvp",0,(1-Summary!$B$55)*(Inputs!$B$19+Skills!P5+Summary!$B$59)+Summary!$B$55*(Inputs!$B$20+Skills!Q5+Summary!$B$59))/100)*(1+Inputs!$B$15/100)*(5000/(6000+Inputs!$B$7*(1-Inputs!$B$18/100)))*(1+(Inputs!$B$23+Summary!$B$65)/100)*(1+4.0*IF(C8=TRUE,F8,0)/100)*(1+(IF(Skills!A5="EMPOWERED_PIERCING_ARROW",Inputs!$B$16,Inputs!$B$17))/100)*(Summary!$B$57*I5) | L5: =K5*(MIN(Inputs!$B$21,Inputs!$B$22)/100+Inputs!$B$22/100)/2 | M5: =L5*(1+(Inputs!$B$9+Summary!$B$64)/100) | N5: =L5*(1-MIN((Inputs!$B$8+Summary!$B$58),100)/100)+M5*(MIN((Inputs!$B$8+Summary!$B$58),100)/100) | O5: =IF(C5,H5*N5*IF(AND(Inputs!$B$4<>"pvp",Inputs!$B$35>0),((Skills!G5*((R5-1)*IF(Skills!H5>0,Skills!I5/Skills!H5,1)+IF(Skills!H5>0,MIN(Skills!I5,MAX(0,Inputs!$B$35-((R5-1)*IF(Inputs!$B$4="pvp",15,MAX(0.1,Skills!D5-IF(Skills!E5=TRUE,Inputs!$B$31,0))))))/Skills!H5,1)))/Inputs!$B$35),G5*Q5)*IF(Inputs!$B$4="pvp",1,(1-Summary!$B$55)*(1)+Summary!$B$55*(MIN(Skills!R5,Inputs!$B$37))),0) | P5: =IF(Summary!$B$3=0,0,O5/Summary!$B$3) | Q5: =IFERROR(1/IF(Inputs!$B$4="pvp",15,MAX(0.1,Skills!D5-IF(Skills!E5=TRUE,Inputs!$B$31,0))),0) | R5: =IF(AND(Inputs!$B$4<>"pvp",Inputs!$B$35>0),(INT(Inputs!$B$35/IF(Inputs!$B$4="pvp",15,MAX(0.1,Skills!D5-IF(Skills!E5=TRUE,Inputs!$B$31,0))))+1),0) | S5: =IFERROR(O5/N5,0)
A6: =Skills!A6 | B6: =Skills!B6 | C6: =Inputs!$B$3>=63 | D6: =IF(Skills!C6=1,60+Inputs!$B$24+Inputs!$B$28,IF(Skills!C6=2,90+Inputs!$B$25+Inputs!$B$28,IF(Skills!C6=3,120+Inputs!$B$26+Inputs!$B$28,MAX(0,(Inputs!$B$3-100)*3)+Inputs!$B$27+Inputs!$B$28))) | E6: =INDEX(FactorTable!$B$2:$Y$301, MATCH(ROUND(MIN(300,MAX(1,D6)),0), FactorTable!$A$2:$A$301,0), Skills!M6+1) | F6: =IF(Skills!N6=TRUE,(Skills!L6/10)*(E6/1000),Skills!L6/10)+Skills!O6 | G6: =Skills!G6*IF(Skills!H6>0,Skills!I6/Skills!H6,1) | H6: =1-(1-Skills!J6/100)^Skills!K6 | I6: 1 | J6: =Summary!$B$50*(F6/100) | K6: =J6*(1+Summary!$B$51/100)*(1+Inputs!$B$14/100)*(1+IF(Inputs!$B$4="pvp",0,(1-Summary!$B$55)*(Inputs!$B$19+Skills!P6+Summary!$B$59)+Summary!$B$55*(Inputs!$B$20+Skills!Q6+Summary!$B$59))/100)*(1+Inputs!$B$15/100)*(5000/(6000+Inputs!$B$7*(1-Inputs!$B$18/100)))*(1+(Inputs!$B$23+Summary!$B$65)/100)*(1+1.0*IF(C8=TRUE,F8,0)/100)*(1+(IF(Skills!A6="EMPOWERED_PIERCING_ARROW",Inputs!$B$16,Inputs!$B$17))/100)*(Summary!$B$57*I6) | L6: =K6*(MIN(Inputs!$B$21,Inputs!$B$22)/100+Inputs!$B$22/100)/2 | M6: =L6*(1+(Inputs!$B$9+Summary!$B$64)/100) | N6: =L6*(1-MIN((Inputs!$B$8+Summary!$B$58),100)/100)+M6*(MIN((Inputs!$B$8+Summary!$B$58),100)/100) | O6: =IF(C6,H6*N6*IF(AND(Inputs!$B$4<>"pvp",Inputs!$B$35>0),((Skills!G6*((R6-1)*IF(Skills!H6>0,Skills!I6/Skills!H6,1)+IF(Skills!H6>0,MIN(Skills!I6,MAX(0,Inputs!$B$35-((R6-1)*IF(Inputs!$B$4="pvp",15,MAX(0.1,Skills!D6-IF(Skills!E6=TRUE,Inputs!$B$31,0))))))/Skills!H6,1)))/Inputs!$B$35),G6*Q6)*IF(Inputs!$B$4="pvp",1,(1-Summary!$B$55)*(1)+Summary!$B$55*(MIN(Skills!R6,Inputs!$B$37))),0) | P6: =IF(Summary!$B$3=0,0,O6/Summary!$B$3) | Q6: =IFERROR(1/IF(Inputs!$B$4="pvp",15,MAX(0.1,Skills!D6-IF(Skills!E6=TRUE,Inputs!$B$31,0))),0) | R6: =IF(AND(Inputs!$B$4<>"pvp",Inputs!$B$35>0),(INT(Inputs!$B$35/IF(Inputs!$B$4="pvp",15,MAX(0.1,Skills!D6-IF(Skills!E6=TRUE,Inputs!$B$31,0))))+1),0) | S6: =IFERROR(O6/N6,0)
A7: =Skills!A7 | B7: =Skills!B7 | C7: =Inputs!$B$3>=69 | D7: =IF(Skills!C7=1,60+Inputs!$B$24+Inputs!$B$28,IF(Skills!C7=2,90+Inputs!$B$25+Inputs!$B$28,IF(Skills!C7=3,120+Inputs!$B$26+Inputs!$B$28,MAX(0,(Inputs!$B$3-100)*3)+Inputs!$B$27+Inputs!$B$28))) | E7: =INDEX(FactorTable!$B$2:$Y$301, MATCH(ROUND(MIN(300,MAX(1,D7)),0), FactorTable!$A$2:$A$301,0), Skills!M7+1) | F7: =IF(Skills!N7=TRUE,(Skills!L7/10)*(E7/1000),Skills!L7/10)+Skills!O7 | G7: =Skills!G7*IF(Skills!H7>0,Skills!I7/Skills!H7,1) | H7: =1-(1-Skills!J7/100)^Skills!K7 | I7: 1 | J7: =Summary!$B$50*(F7/100) | K7: =J7*(1+Summary!$B$51/100)*(1+Inputs!$B$14/100)*(1+IF(Inputs!$B$4="pvp",0,(1-Summary!$B$55)*(Inputs!$B$19+Skills!P7+Summary!$B$59)+Summary!$B$55*(Inputs!$B$20+Skills!Q7+Summary!$B$59))/100)*(1+Inputs!$B$15/100)*(5000/(6000+Inputs!$B$7*(1-Inputs!$B$18/100)))*(1+(Inputs!$B$23+Summary!$B$65)/100)*(1+1.2*IF(C8=TRUE,F8,0)/100)*(1+(IF(Skills!A7="EMPOWERED_PIERCING_ARROW",Inputs!$B$16,Inputs!$B$17))/100)*(Summary!$B$57*I7) | L7: =K7*(MIN(Inputs!$B$21,Inputs!$B$22)/100+Inputs!$B$22/100)/2 | M7: =L7*(1+(Inputs!$B$9+Summary!$B$64)/100) | N7: =L7*(1-MIN((Inputs!$B$8+Summary!$B$58),100)/100)+M7*(MIN((Inputs!$B$8+Summary!$B$58),100)/100) | O7: =IF(C7,H7*N7*IF(AND(Inputs!$B$4<>"pvp",Inputs!$B$35>0),((Skills!G7*((R7-1)*IF(Skills!H7>0,Skills!I7/Skills!H7,1)+IF(Skills!H7>0,MIN(Skills!I7,MAX(0,Inputs!$B$35-((R7-1)*IF(Inputs!$B$4="pvp",15,MAX(0.1,Skills!D7-IF(Skills!E7=TRUE,Inputs!$B$31,0))))))/Skills!H7,1)))/Inputs!$B$35),G7*Q7)*IF(Inputs!$B$4="pvp",1,(1-Summary!$B$55)*(1)+Summary!$B$55*(MIN(Skills!R7,Inputs!$B$37))),0) | P7: =IF(Summary!$B$3=0,0,O7/Summary!$B$3) | Q7: =IFERROR(1/IF(Inputs!$B$4="pvp",15,MAX(0.1,Skills!D7-IF(Skills!E7=TRUE,Inputs!$B$31,0))),0) | R7: =IF(AND(Inputs!$B$4<>"pvp",Inputs!$B$35>0),(INT(Inputs!$B$35/IF(Inputs!$B$4="pvp",15,MAX(0.1,Skills!D7-IF(Skills!E7=TRUE,Inputs!$B$31,0))))+1),0) | S7: =IFERROR(O7/N7,0)
A8: =Skills!A8 | B8: =Skills!B8 | C8: =Inputs!$B$3>=100 | D8: =IF(Skills!C8=1,60+Inputs!$B$24+Inputs!$B$28,IF(Skills!C8=2,90+Inputs!$B$25+Inputs!$B$28,IF(Skills!C8=3,120+Inputs!$B$26+Inputs!$B$28,MAX(0,(Inputs!$B$3-100)*3)+Inputs!$B$27+Inputs!$B$28))) | E8: =INDEX(FactorTable!$B$2:$Y$301, MATCH(ROUND(MIN(300,MAX(1,D8)),0), FactorTable!$A$2:$A$301,0), Skills!M8+1) | F8: =IF(Skills!N8=TRUE,(Skills!L8/10)*(E8/1000),Skills!L8/10)+Skills!O8 | I8: 1
A9: =Skills!A9 | B9: =Skills!B9 | C9: =Inputs!$B$3>=103 | D9: =IF(Skills!C9=1,60+Inputs!$B$24+Inputs!$B$28,IF(Skills!C9=2,90+Inputs!$B$25+Inputs!$B$28,IF(Skills!C9=3,120+Inputs!$B$26+Inputs!$B$28,MAX(0,(Inputs!$B$3-100)*3)+Inputs!$B$27+Inputs!$B$28))) | E9: =INDEX(FactorTable!$B$2:$Y$301, MATCH(ROUND(MIN(300,MAX(1,D9)),0), FactorTable!$A$2:$A$301,0), Skills!M9+1) | F9: =IF(Skills!N9=TRUE,(Skills!L9/10)*(E9/1000),Skills!L9/10)+Skills!O9 | G9: =Skills!G9*IF(Skills!H9>0,Skills!I9/Skills!H9,1) | H9: =1-(1-Skills!J9/100)^Skills!K9 | I9: 1 | J9: =Summary!$B$50*(F9/100) | K9: =J9*(1+Summary!$B$51/100)*(1+Inputs!$B$14/100)*(1+IF(Inputs!$B$4="pvp",0,(1-Summary!$B$55)*(Inputs!$B$19+Skills!P9+Summary!$B$59)+Summary!$B$55*(Inputs!$B$20+Skills!Q9+Summary!$B$59))/100)*(1+Inputs!$B$15/100)*(5000/(6000+Inputs!$B$7*(1-Inputs!$B$18/100)))*(1+(Inputs!$B$23+Summary!$B$65)/100)*(1+(IF(Skills!A9="EMPOWERED_PIERCING_ARROW",Inputs!$B$16,Inputs!$B$17))/100)*(Summary!$B$57*I9) | L9: =K9*(MIN(Inputs!$B$21,Inputs!$B$22)/100+Inputs!$B$22/100)/2 | M9: =L9*(1+(Inputs!$B$9+Summary!$B$64)/100) | N9: =L9*(1-MIN((Inputs!$B$8+Summary!$B$58),100)/100)+M9*(MIN((Inputs!$B$8+Summary!$B$58),100)/100) | O9: =IF(C9,H9*N9*IF(AND(Inputs!$B$4<>"pvp",Inputs!$B$35>0),((Skills!G9*((R9-1)*IF(Skills!H9>0,Skills!I9/Skills!H9,1)+IF(Skills!H9>0,MIN(Skills!I9,MAX(0,Inputs!$B$35-((R9-1)*IF(Inputs!$B$4="pvp",15,MAX(0.1,Skills!D9-IF(Skills!E9=TRUE,Inputs!$B$31,0))))))/Skills!H9,1)))/Inputs!$B$35),G9*Q9)*IF(Inputs!$B$4="pvp",1,(1-Summary!$B$55)*(1)+Summary!$B$55*(MIN(Skills!R9,Inputs!$B$37))),0) | P9: =IF(Summary!$B$3=0,0,O9/Summary!$B$3) | Q9: =IFERROR(1/IF(Inputs!$B$4="pvp",15,MAX(0.1,Skills!D9-IF(Skills!E9=TRUE,Inputs!$B$31,0))),0) | R9: =IF(AND(Inputs!$B$4<>"pvp",Inputs!$B$35>0),(INT(Inputs!$B$35/IF(Inputs!$B$4="pvp",15,MAX(0.1,Skills!D9-IF(Skills!E9=TRUE,Inputs!$B$31,0))))+1),0) | S9: =IFERROR(O9/N9,0)
A10: =Skills!A10 | B10: =Skills!B10 | C10: =Inputs!$B$3>=107 | D10: =IF(Skills!C10=1,60+Inputs!$B$24+Inputs!$B$28,IF(Skills!C10=2,90+Inputs!$B$25+Inputs!$B$28,IF(Skills!C10=3,120+Inputs!$B$26+Inputs!$B$28,MAX(0,(Inputs!$B$3-100)*3)+Inputs!$B$27+Inputs!$B$28))) | E10: =INDEX(FactorTable!$B$2:$Y$301, MATCH(ROUND(MIN(300,MAX(1,D10)),0), FactorTable!$A$2:$A$301,0), Skills!M10+1) | F10: =IF(Skills!N10=TRUE,(Skills!L10/10)*(E10/1000),Skills!L10/10)+Skills!O10 | G10: =Skills!G10*IF(Skills!H10>0,Skills!I10/Skills!H10,1) | H10: =1-(1-Skills!J10/100)^Skills!K10 | I10: 1 | J10: =Summary!$B$50*(F10/100) | K10: =J10*(1+Summary!$B$51/100)*(1+Inputs!$B$14/100)*(1+IF(Inputs!$B$4="pvp",0,(1-Summary!$B$55)*(Inputs!$B$19+Skills!P10+Summary!$B$59)+Summary!$B$55*(Inputs!$B$20+Skills!Q10+Summary!$B$59))/100)*(1+Inputs!$B$15/100)*(5000/(6000+Inputs!$B$7*(1-Inputs!$B$18/100)))*(1+(Inputs!$B$23+Summary!$B$65)/100)*(1+(IF(Skills!A10="EMPOWERED_PIERCING_ARROW",Inputs!$B$16,Inputs!$B$17))/100)*(Summary!$B$57*I10) | L10: =K10*(MIN(Inputs!$B$21,Inputs!$B$22)/100+Inputs!$B$22/100)/2 | M10: =L10*(1+(Inputs!$B$9+Summary!$B$64)/100) | N10: =L10*(1-MIN((Inputs!$B$8+Summary!$B$58),100)/100)+M10*(MIN((Inputs!$B$8+Summary!$B$58),100)/100) | O10: =IF(C10,0.15*SUMPRODUCT((Skills!U2:U29=TRUE)*(Calc!C2:C29=TRUE)*Calc!S2:S29)*Skills!G10*N10*IF(Inputs!$B$4="pvp",1,(1-Summary!$B$55)*(1)+Summary!$B$55*(MIN(Skills!R10,Inputs!$B$37))),0) | P10: =IF(Summary!$B$3=0,0,O10/Summary!$B$3) | Q10: 0 | R10: 0 | S10: 0
A11: =Skills!A11 | B11: =Skills!B11 | C11: =Inputs!$B$3>=110 | D11: =IF(Skills!C11=1,60+Inputs!$B$24+Inputs!$B$28,IF(Skills!C11=2,90+Inputs!$B$25+Inputs!$B$28,IF(Skills!C11=3,120+Inputs!$B$26+Inputs!$B$28,MAX(0,(Inputs!$B$3-100)*3)+Inputs!$B$27+Inputs!$B$28))) | E11: =INDEX(FactorTable!$B$2:$Y$301, MATCH(ROUND(MIN(300,MAX(1,D11)),0), FactorTable!$A$2:$A$301,0), Skills!M11+1) | F11: =IF(Skills!N11=TRUE,(Skills!L11/10)*(E11/1000),Skills!L11/10)+Skills!O11 | G11: =Skills!G11*IF(Skills!H11>0,Skills!I11/Skills!H11,1) | H11: =1-(1-Skills!J11/100)^Skills!K11 | I11: 1 | J11: =Summary!$B$50*(F11/100) | K11: =J11*(1+Summary!$B$51/100)*(1+Inputs!$B$14/100)*(1+IF(Inputs!$B$4="pvp",0,(1-Summary!$B$55)*(Inputs!$B$19+Skills!P11+Summary!$B$59)+Summary!$B$55*(Inputs!$B$20+Skills!Q11+Summary!$B$59))/100)*(1+Inputs!$B$15/100)*(5000/(6000+Inputs!$B$7*(1-Inputs!$B$18/100)))*(1+(Inputs!$B$23+Summary!$B$65)/100)*(1+(IF(Skills!A11="EMPOWERED_PIERCING_ARROW",Inputs!$B$16,Inputs!$B$17))/100)*(Summary!$B$57*I11) | L11: =K11*(MIN(Inputs!$B$21,Inputs!$B$22)/100+Inputs!$B$22/100)/2 | M11: =L11*(1+(Inputs!$B$9+Summary!$B$64)/100) | N11: =L11*(1-MIN((Inputs!$B$8+Summary!$B$58),100)/100)+M11*(MIN((Inputs!$B$8+Summary!$B$58),100)/100) | O11: =IF(C11,H11*N11*IF(AND(Inputs!$B$4<>"pvp",Inputs!$B$35>0),((Skills!G11*((R11-1)*IF(Skills!H11>0,Skills!I11/Skills!H11,1)+IF(Skills!H11>0,MIN(Skills!I11,MAX(0,Inputs!$B$35-((R11-1)*IF(Inputs!$B$4="pvp",15,MAX(0.1,Skills!D11-IF(Skills!E11=TRUE,Inputs!$B$31,0))))))/Skills!H11,1)))/Inputs!$B$35),G11*Q11)*IF(Inputs!$B$4="pvp",1,(1-Summary!$B$55)*(1)+Summary!$B$55*(MIN(Skills!R11,Inputs!$B$37))),0) | P11: =IF(Summary!$B$3=0,0,O11/Summary!$B$3) | Q11: =IFERROR(1/IF(Inputs!$B$4="pvp",15,MAX(0.1,Skills!D11-IF(Skills!E11=TRUE,Inputs!$B$31,0))),0) | R11: =IF(AND(Inputs!$B$4<>"pvp",Inputs!$B$35>0),(INT(Inputs!$B$35/IF(Inputs!$B$4="pvp",15,MAX(0.1,Skills!D11-IF(Skills!E11=TRUE,Inputs!$B$31,0))))+1),0) | S11: =IFERROR(O11/N11,0)
A12: =Skills!A12 | B12: =Skills!B12 | C12: =Inputs!$B$3>=60 | D12: =IF(Skills!C12=1,60+Inputs!$B$24+Inputs!$B$28,IF(Skills!C12=2,90+Inputs!$B$25+Inputs!$B$28,IF(Skills!C12=3,120+Inputs!$B$26+Inputs!$B$28,MAX(0,(Inputs!$B$3-100)*3)+Inputs!$B$27+Inputs!$B$28))) | E12: =INDEX(FactorTable!$B$2:$Y$301, MATCH(ROUND(MIN(300,MAX(1,D12)),0), FactorTable!$A$2:$A$301,0), Skills!M12+1) | F12: =IF(Skills!N12=TRUE,(Skills!L12/10)*(E12/1000),Skills!L12/10)+Skills!O12 | G12: =Skills!G12*IF(Skills!H12>0,Skills!I12/Skills!H12,1) | H12: =1-(1-Skills!J12/100)^Skills!K12 | I12: 1 | O12: 0 | P12: =IF(Summary!$B$3=0,0,O12/Summary!$B$3) | Q12: 0 | R12: 0 | S12: =IFERROR(O12/N12,0)
A13: =Skills!A13 | B13: =Skills!B13 | C13: =Inputs!$B$3>=74 | D13: =IF(Skills!C13=1,60+Inputs!$B$24+Inputs!$B$28,IF(Skills!C13=2,90+Inputs!$B$25+Inputs!$B$28,IF(Skills!C13=3,120+Inputs!$B$26+Inputs!$B$28,MAX(0,(Inputs!$B$3-100)*3)+Inputs!$B$27+Inputs!$B$28))) | E13: =INDEX(FactorTable!$B$2:$Y$301, MATCH(ROUND(MIN(300,MAX(1,D13)),0), FactorTable!$A$2:$A$301,0), Skills!M13+1) | F13: =IF(Skills!N13=TRUE,(Skills!L13/10)*(E13/1000),Skills!L13/10)+Skills!O13 | G13: =Skills!G13*IF(Skills!H13>0,Skills!I13/Skills!H13,1) | H13: =1-(1-Skills!J13/100)^Skills!K13 | I13: 1 | O13: 0 | P13: =IF(Summary!$B$3=0,0,O13/Summary!$B$3) | Q13: 0 | R13: 0 | S13: =IFERROR(O13/N13,0)
A14: =Skills!A14 | B14: =Skills!B14 | C14: =Inputs!$B$3>=74 | D14: =IF(Skills!C14=1,60+Inputs!$B$24+Inputs!$B$28,IF(Skills!C14=2,90+Inputs!$B$25+Inputs!$B$28,IF(Skills!C14=3,120+Inputs!$B$26+Inputs!$B$28,MAX(0,(Inputs!$B$3-100)*3)+Inputs!$B$27+Inputs!$B$28))) | E14: =INDEX(FactorTable!$B$2:$Y$301, MATCH(ROUND(MIN(300,MAX(1,D14)),0), FactorTable!$A$2:$A$301,0), Skills!M14+1) | F14: =IF(Skills!N14=TRUE,(Skills!L14/10)*(E14/1000),Skills!L14/10)+Skills!O14 | G14: =Skills!G14*IF(Skills!H14>0,Skills!I14/Skills!H14,1) | H14: =1-(1-Skills!J14/100)^Skills!K14 | I14: 1 | O14: 0 | P14: =IF(Summary!$B$3=0,0,O14/Summary!$B$3) | Q14: 0 | R14: 0 | S14: =IFERROR(O14/N14,0)
A15: =Skills!A15 | B15: =Skills!B15 | C15: =Inputs!$B$3>=117 | D15: =IF(Skills!C15=1,60+Inputs!$B$24+Inputs!$B$28,IF(Skills!C15=2,90+Inputs!$B$25+Inputs!$B$28,IF(Skills!C15=3,120+Inputs!$B$26+Inputs!$B$28,MAX(0,(Inputs!$B$3-100)*3)+Inputs!$B$27+Inputs!$B$28))) | E15: =INDEX(FactorTable!$B$2:$Y$301, MATCH(ROUND(MIN(300,MAX(1,D15)),0), FactorTable!$A$2:$A$301,0), Skills!M15+1) | F15: =IF(Skills!N15=TRUE,(Skills!L15/10)*(E15/1000),Skills!L15/10)+Skills!O15 | G15: =Skills!G15*IF(Skills!H15>0,Skills!I15/Skills!H15,1) | H15: =1-(1-Skills!J15/100)^Skills!K15 | I15: 1 | O15: 0 | P15: =IF(Summary!$B$3=0,0,O15/Summary!$B$3) | Q15: =IFERROR(1/IF(Inputs!$B$4="pvp",15,MAX(0.1,Skills!D15-IF(Skills!E15=TRUE,Inputs!$B$31,0))),0) | R15: =IF(AND(Inputs!$B$4<>"pvp",Inputs!$B$35>0),(INT(Inputs!$B$35/IF(Inputs!$B$4="pvp",15,MAX(0.1,Skills!D15-IF(Skills!E15=TRUE,Inputs!$B$31,0))))+1),0) | S15: =IFERROR(O15/N15,0)
A16: =Skills!A16 | B16: =Skills!B16 | C16: =Inputs!$B$3>=115 | D16: =IF(Skills!C16=1,60+Inputs!$B$24+Inputs!$B$28,IF(Skills!C16=2,90+Inputs!$B$25+Inputs!$B$28,IF(Skills!C16=3,120+Inputs!$B$26+Inputs!$B$28,MAX(0,(Inputs!$B$3-100)*3)+Inputs!$B$27+Inputs!$B$28))) | E16: =INDEX(FactorTable!$B$2:$Y$301, MATCH(ROUND(MIN(300,MAX(1,D16)),0), FactorTable!$A$2:$A$301,0), Skills!M16+1) | F16: =IF(Skills!N16=TRUE,(Skills!L16/10)*(E16/1000),Skills!L16/10)+Skills!O16 | G16: =Skills!G16*IF(Skills!H16>0,Skills!I16/Skills!H16,1) | H16: =1-(1-Skills!J16/100)^Skills!K16 | I16: 1 | O16: 0 | P16: =IF(Summary!$B$3=0,0,O16/Summary!$B$3) | Q16: =IFERROR(1/IF(Inputs!$B$4="pvp",15,MAX(0.1,Skills!D16-IF(Skills!E16=TRUE,Inputs!$B$31,0))),0) | R16: =IF(AND(Inputs!$B$4<>"pvp",Inputs!$B$35>0),(INT(Inputs!$B$35/IF(Inputs!$B$4="pvp",15,MAX(0.1,Skills!D16-IF(Skills!E16=TRUE,Inputs!$B$31,0))))+1),0) | S16: =IFERROR(O16/N16,0)
A17: =Skills!A17 | B17: =Skills!B17 | C17: =Inputs!$B$3>=72 | D17: =IF(Skills!C17=1,60+Inputs!$B$24+Inputs!$B$28,IF(Skills!C17=2,90+Inputs!$B$25+Inputs!$B$28,IF(Skills!C17=3,120+Inputs!$B$26+Inputs!$B$28,MAX(0,(Inputs!$B$3-100)*3)+Inputs!$B$27+Inputs!$B$28))) | E17: =INDEX(FactorTable!$B$2:$Y$301, MATCH(ROUND(MIN(300,MAX(1,D17)),0), FactorTable!$A$2:$A$301,0), Skills!M17+1) | F17: =IF(Skills!N17=TRUE,(Skills!L17/10)*(E17/1000),Skills!L17/10)+Skills!O17 | G17: =Skills!G17*IF(Skills!H17>0,Skills!I17/Skills!H17,1) | H17: =1-(1-Skills!J17/100)^Skills!K17 | I17: 1 | O17: 0 | P17: =IF(Summary!$B$3=0,0,O17/Summary!$B$3) | Q17: 0 | R17: 0 | S17: =IFERROR(O17/N17,0)
A18: =Skills!A18 | B18: =Skills!B18 | C18: =TRUE | D18: =IF(Skills!C18=1,60+Inputs!$B$24+Inputs!$B$28,IF(Skills!C18=2,90+Inputs!$B$25+Inputs!$B$28,IF(Skills!C18=3,120+Inputs!$B$26+Inputs!$B$28,MAX(0,(Inputs!$B$3-100)*3)+Inputs!$B$27+Inputs!$B$28))) | E18: =INDEX(FactorTable!$B$2:$Y$301, MATCH(ROUND(MIN(300,MAX(1,D18)),0), FactorTable!$A$2:$A$301,0), Skills!M18+1) | F18: =IF(Skills!N18=TRUE,(Skills!L18/10)*(E18/1000),Skills!L18/10)+Skills!O18 | G18: =Skills!G18*IF(Skills!H18>0,Skills!I18/Skills!H18,1) | H18: =1-(1-Skills!J18/100)^Skills!K18 | I18: 1 | O18: 0 | P18: =IF(Summary!$B$3=0,0,O18/Summary!$B$3) | Q18: =IFERROR(1/IF(Inputs!$B$4="pvp",15,MAX(0.1,Skills!D18-IF(Skills!E18=TRUE,Inputs!$B$31,0))),0) | R18: =IF(AND(Inputs!$B$4<>"pvp",Inputs!$B$35>0),(INT(Inputs!$B$35/IF(Inputs!$B$4="pvp",15,MAX(0.1,Skills!D18-IF(Skills!E18=TRUE,Inputs!$B$31,0))))+1),0) | S18: =IFERROR(O18/N18,0)
A19: =Skills!A19 | B19: =Skills!B19 | C19: =Inputs!$B$3>=15 | D19: =IF(Skills!C19=1,60+Inputs!$B$24+Inputs!$B$28,IF(Skills!C19=2,90+Inputs!$B$25+Inputs!$B$28,IF(Skills!C19=3,120+Inputs!$B$26+Inputs!$B$28,MAX(0,(Inputs!$B$3-100)*3)+Inputs!$B$27+Inputs!$B$28))) | E19: =INDEX(FactorTable!$B$2:$Y$301, MATCH(ROUND(MIN(300,MAX(1,D19)),0), FactorTable!$A$2:$A$301,0), Skills!M19+1) | F19: =IF(Skills!N19=TRUE,(Skills!L19/10)*(E19/1000),Skills!L19/10)+Skills!O19 | G19: =Skills!G19*IF(Skills!H19>0,Skills!I19/Skills!H19,1) | H19: =1-(1-Skills!J19/100)^Skills!K19 | I19: 1 | O19: 0 | P19: =IF(Summary!$B$3=0,0,O19/Summary!$B$3) | Q19: 0 | R19: 0 | S19: =IFERROR(O19/N19,0)
A20: =Skills!A20 | B20: =Skills!B20 | C20: =Inputs!$B$3>=10 | D20: =IF(Skills!C20=1,60+Inputs!$B$24+Inputs!$B$28,IF(Skills!C20=2,90+Inputs!$B$25+Inputs!$B$28,IF(Skills!C20=3,120+Inputs!$B$26+Inputs!$B$28,MAX(0,(Inputs!$B$3-100)*3)+Inputs!$B$27+Inputs!$B$28))) | E20: =INDEX(FactorTable!$B$2:$Y$301, MATCH(ROUND(MIN(300,MAX(1,D20)),0), FactorTable!$A$2:$A$301,0), Skills!M20+1) | F20: =IF(Skills!N20=TRUE,(Skills!L20/10)*(E20/1000),Skills!L20/10)+Skills!O20 | G20: =Skills!G20*IF(Skills!H20>0,Skills!I20/Skills!H20,1) | H20: =1-(1-Skills!J20/100)^Skills!K20 | I20: 1 | O20: 0 | P20: =IF(Summary!$B$3=0,0,O20/Summary!$B$3) | Q20: 0 | R20: 0 | S20: =IFERROR(O20/N20,0)
A21: =Skills!A21 | B21: =Skills!B21 | C21: =Inputs!$B$3>=33 | D21: =IF(Skills!C21=1,60+Inputs!$B$24+Inputs!$B$28,IF(Skills!C21=2,90+Inputs!$B$25+Inputs!$B$28,IF(Skills!C21=3,120+Inputs!$B$26+Inputs!$B$28,MAX(0,(Inputs!$B$3-100)*3)+Inputs!$B$27+Inputs!$B$28))) | E21: =INDEX(FactorTable!$B$2:$Y$301, MATCH(ROUND(MIN(300,MAX(1,D21)),0), FactorTable!$A$2:$A$301,0), Skills!M21+1) | F21: =IF(Skills!N21=TRUE,(Skills!L21/10)*(E21/1000),Skills!L21/10)+Skills!O21 | G21: =Skills!G21*IF(Skills!H21>0,Skills!I21/Skills!H21,1) | H21: =1-(1-Skills!J21/100)^Skills!K21 | I21: 1 | O21: 0 | P21: =IF(Summary!$B$3=0,0,O21/Summary!$B$3) | Q21: 0 | R21: 0 | S21: =IFERROR(O21/N21,0)
A22: =Skills!A22 | B22: =Skills!B22 | C22: =Inputs!$B$3>=38 | D22: =IF(Skills!C22=1,60+Inputs!$B$24+Inputs!$B$28,IF(Skills!C22=2,90+Inputs!$B$25+Inputs!$B$28,IF(Skills!C22=3,120+Inputs!$B$26+Inputs!$B$28,MAX(0,(Inputs!$B$3-100)*3)+Inputs!$B$27+Inputs!$B$28))) | E22: =INDEX(FactorTable!$B$2:$Y$301, MATCH(ROUND(MIN(300,MAX(1,D22)),0), FactorTable!$A$2:$A$301,0), Skills!M22+1) | F22: =IF(Skills!N22=TRUE,(Skills!L22/10)*(E22/1000),Skills!L22/10)+Skills!O22 | G22: =Skills!G22*IF(Skills!H22>0,Skills!I22/Skills!H22,1) | H22: =1-(1-Skills!J22/100)^Skills!K22 | I22: 1 | O22: 0 | P22: =IF(Summary!$B$3=0,0,O22/Summary!$B$3) | Q22: 0 | R22: 0 | S22: =IFERROR(O22/N22,0)
A23: =Skills!A23 | B23: =Skills!B23 | C23: =Inputs!$B$3>=43 | D23: =IF(Skills!C23=1,60+Inputs!$B$24+Inputs!$B$28,IF(Skills!C23=2,90+Inputs!$B$25+Inputs!$B$28,IF(Skills!C23=3,120+Inputs!$B$26+Inputs!$B$28,MAX(0,(Inputs!$B$3-100)*3)+Inputs!$B$27+Inputs!$B$28))) | E23: =INDEX(FactorTable!$B$2:$Y$301, MATCH(ROUND(MIN(300,MAX(1,D23)),0), FactorTable!$A$2:$A$301,0), Skills!M23+1) | F23: =IF(Skills!N23=TRUE,(Skills!L23/10)*(E23/1000),Skills!L23/10)+Skills!O23 | G23: =Skills!G23*IF(Skills!H23>0,Skills!I23/Skills!H23,1) | H23: =1-(1-Skills!J23/100)^Skills!K23 | I23: 1 | O23: 0 | P23: =IF(Summary!$B$3=0,0,O23/Summary!$B$3) | Q23: 0 | R23: 0 | S23: =IFERROR(O23/N23,0)
A24: =Skills!A24 | B24: =Skills!B24 | C24: =Inputs!$B$3>=75 | D24: =IF(Skills!C24=1,60+Inputs!$B$24+Inputs!$B$28,IF(Skills!C24=2,90+Inputs!$B$25+Inputs!$B$28,IF(Skills!C24=3,120+Inputs!$B$26+Inputs!$B$28,MAX(0,(Inputs!$B$3-100)*3)+Inputs!$B$27+Inputs!$B$28))) | E24: =INDEX(FactorTable!$B$2:$Y$301, MATCH(ROUND(MIN(300,MAX(1,D24)),0), FactorTable!$A$2:$A$301,0), Skills!M24+1) | F24: =IF(Skills!N24=TRUE,(Skills!L24/10)*(E24/1000),Skills!L24/10)+Skills!O24 | G24: =Skills!G24*IF(Skills!H24>0,Skills!I24/Skills!H24,1) | H24: =1-(1-Skills!J24/100)^Skills!K24 | I24: 1 | O24: 0 | P24: =IF(Summary!$B$3=0,0,O24/Summary!$B$3) | Q24: 0 | R24: 0 | S24: =IFERROR(O24/N24,0)
A25: =Skills!A25 | B25: =Skills!B25 | C25: =Inputs!$B$3>=125 | D25: =IF(Skills!C25=1,60+Inputs!$B$24+Inputs!$B$28,IF(Skills!C25=2,90+Inputs!$B$25+Inputs!$B$28,IF(Skills!C25=3,120+Inputs!$B$26+Inputs!$B$28,MAX(0,(Inputs!$B$3-100)*3)+Inputs!$B$27+Inputs!$B$28))) | E25: =INDEX(FactorTable!$B$2:$Y$301, MATCH(ROUND(MIN(300,MAX(1,D25)),0), FactorTable!$A$2:$A$301,0), Skills!M25+1) | F25: =IF(Skills!N25=TRUE,(Skills!L25/10)*(E25/1000),Skills!L25/10)+Skills!O25 | G25: =Skills!G25*IF(Skills!H25>0,Skills!I25/Skills!H25,1) | H25: =1-(1-Skills!J25/100)^Skills!K25 | I25: 1 | O25: 0 | P25: =IF(Summary!$B$3=0,0,O25/Summary!$B$3) | Q25: 0 | R25: 0 | S25: =IFERROR(O25/N25,0)
A26: =Skills!A26 | B26: =Skills!B26 | C26: =Inputs!$B$3>=125 | D26: =IF(Skills!C26=1,60+Inputs!$B$24+Inputs!$B$28,IF(Skills!C26=2,90+Inputs!$B$25+Inputs!$B$28,IF(Skills!C26=3,120+Inputs!$B$26+Inputs!$B$28,MAX(0,(Inputs!$B$3-100)*3)+Inputs!$B$27+Inputs!$B$28))) | E26: =INDEX(FactorTable!$B$2:$Y$301, MATCH(ROUND(MIN(300,MAX(1,D26)),0), FactorTable!$A$2:$A$301,0), Skills!M26+1) | F26: =IF(Skills!N26=TRUE,(Skills!L26/10)*(E26/1000),Skills!L26/10)+Skills!O26 | G26: =Skills!G26*IF(Skills!H26>0,Skills!I26/Skills!H26,1) | H26: =1-(1-Skills!J26/100)^Skills!K26 | I26: 1 | O26: 0 | P26: =IF(Summary!$B$3=0,0,O26/Summary!$B$3) | Q26: 0 | R26: 0 | S26: =IFERROR(O26/N26,0)
A27: =Skills!A27 | B27: =Skills!B27 | C27: =Inputs!$B$3>=120 | D27: =IF(Skills!C27=1,60+Inputs!$B$24+Inputs!$B$28,IF(Skills!C27=2,90+Inputs!$B$25+Inputs!$B$28,IF(Skills!C27=3,120+Inputs!$B$26+Inputs!$B$28,MAX(0,(Inputs!$B$3-100)*3)+Inputs!$B$27+Inputs!$B$28))) | E27: =INDEX(FactorTable!$B$2:$Y$301, MATCH(ROUND(MIN(300,MAX(1,D27)),0), FactorTable!$A$2:$A$301,0), Skills!M27+1) | F27: =IF(Skills!N27=TRUE,(Skills!L27/10)*(E27/1000),Skills!L27/10)+Skills!O27 | G27: =Skills!G27*IF(Skills!H27>0,Skills!I27/Skills!H27,1) | H27: =1-(1-Skills!J27/100)^Skills!K27 | I27: 1 | O27: 0 | P27: =IF(Summary!$B$3=0,0,O27/Summary!$B$3) | Q27: 0 | R27: 0 | S27: =IFERROR(O27/N27,0)
