Workbook

Sheet README
A1: Shadower — DPS Calculator: How to Use This Workbook
A3: How to use this workbook
A4: Only edit the yellow-highlighted cells on the Inputs sheet — every other sheet is computed from those values and will be overwritten if you rebuild the workbook.
A5: Summary shows Total DPS, a Per-Skill DPS Breakdown (damage-dealing skills only — buffs/passives that never deal their own damage are omitted), and a Marginal DPS & Stat Value table showing the DPS gained per +1 of each stat.
A6: Sensitivity has the full detail behind that marginal-value table — one self-contained block per stat, showing exactly how bumping that stat by +1 changes every downstream number.
A7: CubeData/PotentialCubes model your current gear's Potential Cube lines and drive cube-reroll expected-value decisions. For the full standalone Potential Cube EV calculator (exact optimal-stopping math, works from this workbook alone), see tools/potential_cubes_ev.py in the project repo.
A9: Design decisions & assumptions
A10: Venom/Toxic Venom assume the target is permanently afflicted with Venom's poison at steady state, not an exact on/off timer — matches every other DoT-uptime assumption in this project.
A11: Crit Rate pushed above 100% (e.g. by cube potential lines) automatically redirects its stat-value to Crit Damage's own per-unit DPS value on the PotentialCubes sheet, since excess Crit Rate cannot do anything past 100%.
A12: Buffs and stacking resources (Dark Sight Attack, Into Darkness, Smokescreen, Meso Explosion/Blood Money stacks) are modeled at steady-state duty-cycle average uptime, not as an exact moment-to-moment state machine.
A13: Assassinate's finishing blow is modeled as landing on average every 2nd cast (a flat 50% average multiplier), and Mastery Lv.108 Murderous Intent's finisher-doubling is a steady-state average multiplier based on relative cast rates, not an exact alternating state machine.
A14: Channel Karma, Shadow Shifter's own Attack buff, Dagger Mastery, Critical Edge, Physical Training, Dagger Expert, and Shadower Instinct are always-on passives assumed to already be reflected in your own Inputs stat entries — only their Sensitivity marginal delta (what changes if their mastery level differs from what you assumed) is modeled live.
... A16: Not modeled (out of scope): all forms of crowd control (Phase Dash/Dark Sight/Assassinate stuns), Accuracy/Evasion/Defense reduction (Smokescreen, Steal, Assassinate), movement speed (Nimble Feet, Haste), the character's own Defense stat (Shield Mastery), and Companion Summoning Time.

Sheet Inputs
A1: Shadower — DPS Calculator Inputs
A3: Character Level | B3: 200
A4: Monster Type ("boss", "normal", "breakthrough", or "pvp") | B4: boss
A5: Flat ATTACK | B5: 10000
A6: ATTACK % | B6: 0
A7: Monster Defense (flat, post-x100/x10 scaling) | B7: 0
A8: CRIT_RATE % | B8: 0
A9: CRIT_DAMAGE % | B9: 0
A10: ATTACK_SPEED % (base, excludes Nimble Feet/Agile Daggers) | B10: 0
A11: Flat LUK | B11: 0
A12: LUK % | B12: 0
A13: DEX | B13: 0
A14: DAMAGE % | B14: 0
A15: DAMAGE_AMP % | B15: 0
A16: BASIC_ATTACK_DAMAGE % | B16: 0
... A28: Skill Level Bonus — All Skills | B28: 0
A30: Additional Bonuses
A31: Skill Cooldown Decrease (seconds, only skills/buffs the character actively casts) | B31: 0
A32: Basic Attack Target Increase (flat, adds to the 6-target normal-monster base) | B32: 1
A33: Buff Duration Increase % | B33: 0
A34: Companion Summoning Time Increase % (companions not modeled — always 0 DPS impact) | B34: 0
A35: Fixed Fight Duration (seconds, boss or normal — leave 0 for steady-state DPS; ignored for pvp) | B35: 0
A36: Chapter Breakthrough: Normal-Monster Weight % (only used when Monster Type = breakthrough) | B36: 60
A37: Max Enemies Actually In Range (normal monsters only; default 999 = uncapped) | B37: 999
A38: Incoming Hit Rate (hits/sec taken — user-estimated, feeds Shadow Shifter's counterattack only) | B38: 1

Sheet FactorTable
A1: Level | B1: F0 | C1: F1 | D1: F2 | E1: F3 | F1: F4 | G1: F5 | H1: F6 | I1: F7 | J1: F8 | K1: F9 | L1: F10 | M1: F11 | N1: F12 | O1: F13 | P1: F14 | Q1: F15 | R1: F16 | S1: F17 | T1: F18 | U1: F19 | V1: F20 | W1: F21 | X1: F22 | Y1: F23
A2: 1 | B2: 0 | C2: 1000 | D2: 1000 | E2: 1000 | F2: 1000 | G2: 1000 | H2: 1000 | I2: 1000 | J2: 1000 | K2: 1000 | L2: 1000 | M2: 1000 | N2: 1000 | O2: 1000 | P2: 1000 | Q2: 1000 | R2: 1000 | S2: 1000 | T2: 1000 | U2: 1000 | V2: 1000 | W2: 1000 | X2: 1000 | Y2: 1000
A3: 2 | B3: 0 | C3: 1015 | D3: 1020 | E3: 1030 | F3: 1040 | G3: 1050 | H3: 1060 | I3: 1070 | J3: 1020 | K3: 1020 | L3: 1020 | M3: 1000 | N3: 1010 | O3: 1020 | P3: 1030 | Q3: 1040 | R3: 1050 | S3: 1060 | T3: 1070 | U3: 1080 | V3: 1010 | W3: 1008 | X3: 1006 | Y3: 1100
A4: 3 | B4: 0 | C4: 1031 | D4: 1041 | E4: 1061 | F4: 1082 | G4: 1103 | H4: 1124 | I4: 1145 | J4: 1030 | K4: 1041 | L4: 1030 | M4: 1000 | N4: 1015 | O4: 1030 | P4: 1045 | Q4: 1060 | R4: 1075 | S4: 1090 | T4: 1105 | U4: 1120 | V4: 1020 | W4: 1012 | X4: 1009 | Y4: 1150
A5: 4 | B5: 0 | C5: 1047 | D5: 1062 | E5: 1093 | F5: 1126 | G5: 1159 | H5: 1192 | I5: 1226 | J5: 1040 | K5: 1062 | L5: 1040 | M5: 1000 | N5: 1020 | O5: 1040 | P5: 1060 | Q5: 1080 | R5: 1100 | S5: 1120 | T5: 1140 | U5: 1160 | V5: 1030 | W5: 1016 | X5: 1012 | Y5: 1200
A6: 5 | B6: 0 | C6: 1063 | D6: 1084 | E6: 1126 | F6: 1172 | G6: 1217 | H6: 1264 | I6: 1312 | J6: 1050 | K6: 1084 | L6: 1050 | M6: 1000 | N6: 1025 | O6: 1050 | P6: 1075 | Q6: 1100 | R6: 1125 | S6: 1150 | T6: 1175 | U6: 1200 | V6: 1040 | W6: 1020 | X6: 1015 | Y6: 1250
A7: 6 | B7: 0 | C7: 1079 | D7: 1106 | E7: 1160 | F7: 1219 | G7: 1278 | H7: 1340 | I7: 1404 | J7: 1060 | K7: 1106 | L7: 1060 | M7: 1000 | N7: 1030 | O7: 1060 | P7: 1090 | Q7: 1120 | R7: 1150 | S7: 1180 | T7: 1210 | U7: 1240 | V7: 1050 | W7: 1024 | X7: 1018 | Y7: 1300
A8: 7 | B8: 0 | C8: 1096 | D8: 1129 | E8: 1195 | F8: 1268 | G8: 1342 | H8: 1421 | I8: 1503 | J8: 1070 | K8: 1129 | L8: 1070 | M8: 1000 | N8: 1035 | O8: 1070 | P8: 1105 | Q8: 1140 | R8: 1175 | S8: 1210 | T8: 1245 | U8: 1280 | V8: 1060 | W8: 1028 | X8: 1021 | Y8: 1350
A9: 8 | B9: 0 | C9: 1113 | D9: 1152 | E9: 1231 | F9: 1319 | G9: 1410 | H9: 1507 | I9: 1609 | J9: 1080 | K9: 1152 | L9: 1080 | M9: 1000 | N9: 1040 | O9: 1080 | P9: 1120 | Q9: 1160 | R9: 1200 | S9: 1240 | T9: 1280 | U9: 1320 | V9: 1070 | W9: 1032 | X9: 1024 | Y9: 1400
A10: 9 | B10: 0 | C10: 1130 | D10: 1176 | E10: 1268 | F10: 1372 | G10: 1481 | H10: 1598 | I10: 1722 | J10: 1090 | K10: 1176 | L10: 1090 | M10: 1000 | N10: 1045 | O10: 1090 | P10: 1135 | Q10: 1180 | R10: 1225 | S10: 1270 | T10: 1315 | U10: 1360 | V10: 1080 | W10: 1036 | X10: 1027 | Y10: 1450
A11: 10 | B11: 0 | C11: 1147 | D11: 1200 | E11: 1307 | F11: 1427 | G11: 1556 | H11: 1694 | I11: 1843 | J11: 1100 | K11: 1200 | L11: 1100 | M11: 1000 | N11: 1050 | O11: 1100 | P11: 1150 | Q11: 1200 | R11: 1250 | S11: 1300 | T11: 1350 | U11: 1400 | V11: 1090 | W11: 1040 | X11: 1030 | Y11: 1500
A12: 11 | B12: 0 | C12: 1165 | D12: 1224 | E12: 1347 | F12: 1485 | G12: 1634 | H12: 1796 | I12: 1973 | J12: 1110 | K12: 1224 | L12: 1110 | M12: 1000 | N12: 1055 | O12: 1110 | P12: 1165 | Q12: 1220 | R12: 1275 | S12: 1330 | T12: 1385 | U12: 1440 | V12: 1100 | W12: 1044 | X12: 1033 | Y12: 1550
A13: 12 | B13: 0 | C13: 1183 | D13: 1249 | E13: 1388 | F13: 1545 | G13: 1716 | H13: 1904 | I13: 2112 | J13: 1120 | K13: 1249 | L13: 1120 | M13: 1000 | N13: 1060 | O13: 1120 | P13: 1180 | Q13: 1240 | R13: 1300 | S13: 1360 | T13: 1420 | U13: 1480 | V13: 1110 | W13: 1048 | X13: 1036 | Y13: 1600
... A301: 300 | B301: 0 | C301: 88573 | D301: 381637 | E301: 6991522 | F301: 125363453 | G301: 2185120762 | H301: 37157073039 | I301: 614631863830 | J301: 2000 | K301: 53326 | L301: 2500 | M301: 1100 | N301: 2500 | O301: 4000 | P301: 5500 | Q301: 7000 | R301: 8500 | S301: 10000 | T301: 11500 | U301: 13000 | V301: 7558 | W301: 2200 | X301: 1900 | Y301: 8800

Sheet Skills
A1: Key | B1: Name | C1: JobStep | D1: Cooldown(s) | E1: CostsActionSlot | F1: ActionsPerCast | G1: HitsPerCast | H1: ICD(s) | I1: ActiveWindow(s) | J1: ProcChance% | K1: RollsPerCast | L1: BaseDamage(tenths%) | M1: FactorIndex | N1: ScalesWithLevel | O1: SkillMasteryBonus% | P1: MasteryBossDamage% | Q1: MasteryNormalDamage% | R1: MasteryFinalDamage% | S1: MasteryMaxDamage% | T1: MasteryMinDamage% | U1: MasteryCooldownPct | V1: MasteryTargetIncrease | W1: NormalMonsterTargets | X1: BuffTargetStat | Y1: BuffDuration(s) | Z1: TriggersToxicVenom | AA1: MapleHeroBase(tenths%) | AB1: MapleHeroFactorIndex | AC1: Stacks | AD1: Note
A2: CRUEL_STAB | B2: Cruel Stab | C2: 4 | E2: FALSE | F2: 1 | G2: =IF(Inputs!$B$3>=136,6,5) | H2: 0 | I2: 0 | J2: 100 | K2: 1 | N2: TRUE | O2: =SUMPRODUCT((Inputs!$B$3>={102,106,116,120,128,132})*{10,1,1,1,1,1}) | P2: =SUMPRODUCT((Inputs!$B$3>={111,124})*{10,10}) | Q2: 0 | R2: 0 | S2: 0 | T2: 0 | U2: 0 | V2: 0 | W2: =6+Inputs!$B$32 | Y2: 0 | Z2: TRUE | AD2: 4th-job basic-attack effect (supersedes Double Stab/Savage Blow/Midnight Carnival). HIGH-CONFIDENCE REUSE of the universal 4th-job basic-attack constant confirmed identical across every class built so far (Showdown/Chain Lightning/Big Bang/Cruel Stab all share this exact wiki-documented 290%->522% curve) — factorIndex 21, baseDamage 2900 tenths%, matching Inputs!skill_coefficient exactly. SkillMasteryBonus% is the 6-tier 'Cruel Stab - Damage' mastery chain (102-132, cumulative totals 10%->15%, DELTA increments). MasteryBossDamage% is the 2-tier 'Cruel Stab - Boss Monster Damage' chain (111/124, +20% total). HitsPerCast 5->6 once the level-136 'Strike' mastery unlocks. Triggers Toxic Venom.
A3: STEAL | B3: Steal (self Attack%) | C3: 2 | E3: FALSE | F3: 1 | G3: 1 | H3: 0 | I3: 0 | J3: 100 | K3: 1 | L3: 50 | M3: 22 | N3: TRUE | O3: 0 | P3: 0 | Q3: 0 | R3: 0 | S3: 0 | T3: 0 | U3: 0 | V3: 0 | W3: 1 | X3: ATTACK | Y3: 0 | Z3: FALSE | AD3: Own self-Attack-buff component only (target-debuff component out of scope — not the caster's own damage). 5%->6.5% Attack per stack (levels 1-100), stacks up to 3 — modeled at steady-state max stacks (mirrors Elemental Drain's always-max-stacks convention), so this row's own contribution is 3x its own F-value, always-on once unlocked (no uptime averaging — see build_summary_sheet). factorIndex 22, baseDamage 50 tenths%. Mastery Lv.39 '+5%p activation chance' (10%->15%) has zero DPS effect under the always-max-stacks assumption (same no-op tier as Bishop's own Elemental-Reset-chance-doubling mastery). Mastery Lv.54 '+50% Attack reduction on target' is a target-debuff, out of scope.
A4: MESO_EXPLOSION | B4: Meso Explosion | C4: 3 | D4: 11 | E4: TRUE | F4: 1 | G4: 3 | H4: 0 | I4: 0 | J4: 100 | K4: 1 | L4: 2700 | M4: 12 | N4: TRUE | O4: =SUMPRODUCT((Inputs!$B$3>={90})*{100}) | P4: 0 | Q4: 0 | R4: 0 | S4: 0 | T4: 0 | U4: 0 | V4: 0 | Y4: 0 | Z4: TRUE | AD4: Resource-gated activated skill: 50% chance per attack to generate a Meso stack (max 10); own cast (this row's own 11s cooldown) deals damage to (stack count) targets. Modeled at steady state: average stack count at cast time = MIN(10, 0.5*attack_rate*cooldown), computed as a bespoke NormalMonsterTargets-equivalent formula in build_calc_sheet (left blank here, NOT a Skills-sheet literal, since it depends on the live Summary attack-rate cell) — same 'assume steady accumulation' simplification tier as Frost stacks/Elemental Drain elsewhere. factorIndex 12, baseDamage 2700 tenths% (270% level-1). SkillMasteryBonus% is Mastery Lv.90 'Meso Explosion damage +100%' (content-based — the wiki mislabels this row 'Meso Explosion - Strike', ignore the label, the description is unambiguous). Triggers Toxic Venom.
A5: PHASE_DASH | B5: Phase Dash | C5: 3 | D5: 23 | E5: TRUE | F5: 1 | G5: 2 | H5: 0 | I5: 0 | J5: 100 | K5: 1 | L5: 4500 | M5: 12 | N5: TRUE | O5: =SUMPRODUCT((Inputs!$B$3>={73})*{80}) | P5: 0 | Q5: 0 | R5: 0 | S5: 0 | T5: 0 | U5: 0 | V5: 0 | W5: 9 | Y5: 0 | Z5: TRUE | AD5: 450%->... to 7 target(s) (patched Aug 13 2026 -> 9, confirmed no tick/interval mechanic exists on this skill's own wiki page to change, despite an initially-mis-paired patch-note line — see the plan's Context section), 2 hits, cooldown 23s, stun not modeled. factorIndex 12, baseDamage 4500 tenths%. Mastery Lv.73 'Phase Dash - Damage' +80% (real SkillMasteryBonus%). Triggers Toxic Venom.
A6: DARK_FLARE | B6: Dark Flare | C6: 3 | D6: =IF(Inputs!$B$3>=92,45*0.7,45) | E6: TRUE | F6: 1 | G6: =IF(Inputs!$B$3>=76,3,2) | H6: =IF(Inputs!$B$3>=104,2*0.75,2) | I6: 20 | J6: 100 | K6: 1 | L6: 3300 | M6: 12 | N6: TRUE | O6: 0 | P6: 0 | Q6: 0 | R6: 0 | S6: 0 | T6: 0 | U6: =IF(Inputs!$B$3>=92,30,0) | V6: 0 | W6: 8 | Y6: 0 | Z6: TRUE | AD6: Shared verbatim w/ Night Lord (identical wiki wording AND identical patch corrections: hit interval 5s->2s, targets 5->8, damage 400%->330%). factorIndex 12, baseDamage 3300 tenths%. Mastery Lv.104 (Shadower's own 'Dark Flare - Strike Interval', -25%, matches Night Lord's own mastery of the same name exactly) baked into the ICD(s) formula; Lv.92 -30% cooldown baked into Cooldown(s). Maple Hero (Shadower) target — see MAPLE_HERO_SHADOWER_RATIOS, NOT the generic MapleHeroBase mechanism (unlike Night Lord's own copy of this row, which uses the generic 'additional damage%' mechanism instead — the two classes' Maple Hero effects are structurally different even though the base skill is identical). Triggers Toxic Venom.
A7: SHADOW_PARTNER | B7: Shadow Partner | C7: 3 | E7: FALSE | F7: 1 | G7: 1 | H7: 0 | I7: 0 | J7: 25 | K7: 1 | L7: 840 | M7: 21 | N7: TRUE | O7: =SUMPRODUCT((Inputs!$B$3>={68})*{100}) | P7: 0 | Q7: 0 | R7: 0 | S7: 0 | T7: 0 | U7: 0 | V7: 0 | W7: 1 | Y7: 0 | Z7: FALSE | AD7: Shared verbatim w/ Night Lord. Hybrid row: Calc columns D-I computed like a normal damage row but Calc!O forced to 0 — not an independent hit; Summary reads this row's Calc!F directly and folds into the shared extra_mult chain. factorIndex 21, baseDamage 840 tenths%. ProcChance% is the real 25% proc rate. SkillMasteryBonus% is Mastery Lv.68 'Shadow Partner - Damage' +100%. Maple Hero (Shadower) target — see MAPLE_HERO_SHADOWER_RATIOS (structurally different from Night Lord's own copy, same caveat as Dark Flare above).
A8: VENOM | B8: Venom | C8: 3 | D8: 1 | E8: FALSE | F8: 1 | G8: 1 | H8: 0 | I8: 0 | J8: 100 | K8: 1 | L8: 450 | M8: 21 | N8: TRUE | O8: 0 | P8: 0 | Q8: 0 | R8: 0 | S8: 0 | T8: 0 | U8: 0 | V8: 0 | W8: 1 | Y8: 0 | Z8: FALSE | AD8: Shared verbatim w/ Night Lord (patched poison chance 30%->50%, modeled always-active at steady state — matches Night Lord's own treatment exactly, including the Cooldown=1 'always-on tick' trick). factorIndex 21, baseDamage 450 tenths% (45%->81%, levels 1-200) — reverse-engineered fresh this session and confirmed to resolve to the EXACT same tuple Night Lord already uses, cross-validating the shared-skill-reuse premise. Mastery Lv.82 Weaken (+15%p Damage Taken while poisoned, patched from 12% — matches Night Lord's own Venom - Weaken mastery exactly, confirmed via the patch note despite the wiki mastery table mislabeling this row 'Meso Explosion - Damage') is a GLOBAL always-on monster-damage-taken bonus, not a per-row Mastery column — see build_summary_sheet. Maple Hero (Shadower) target — see MAPLE_HERO_SHADOWER_RATIOS (structurally different from Night Lord's own copy, same caveat as Dark Flare above).
A9: TOXIC_VENOM | B9: Toxic Venom | C9: 4 | E9: FALSE | F9: 1 | G9: 1 | H9: 0 | I9: 0 | J9: 20 | K9: 1 | L9: 6000 | M9: 21 | N9: TRUE | O9: =SUMPRODUCT((Inputs!$B$3>={130})*{100}) | P9: 0 | Q9: 0 | R9: 0 | S9: 0 | T9: 0 | U9: 0 | V9: 0 | W9: 1 | Y9: 0 | Z9: FALSE | AD9: Shared verbatim w/ Night Lord. No ICD — every attack against a (permanently poisoned) target independently rolls the 20% chance. Trigger rate = the combined per-second hit rate of every row with TriggersToxicVenom=TRUE. factorIndex 21, baseDamage 6000 tenths% (600%->1080%, levels 1-200). SkillMasteryBonus% is Mastery Lv.130 'Toxic Venom - Damage' +100% (Shadower's own tier — same mastery name/effect as Night Lord's own Lv.128 tier, just at a different level in this class's own mastery table).
A10: INTO_DARKNESS | B10: Into Darkness | C10: 3 | D10: 40 | E10: TRUE | F10: 1 | G10: 1 | H10: 0 | I10: 0 | J10: 100 | K10: 1 | L10: 200 | M10: 21 | N10: TRUE | O10: 0 | P10: 0 | Q10: 0 | R10: 0 | S10: 0 | T10: 0 | U10: 0 | V10: 0 | W10: 1 | X10: FINAL_DAMAGE | Y10: 13 | Z10: FALSE | AD10: FLAGGED (full curve exists, but a genuinely new skill with no cross-class precedent to sanity-check against): +20%->28% Final Damage for 13s, cooldown 40s. Basic-attack-damage immunity component (defensive) not modeled. factorIndex 21, baseDamage 200 tenths%.
A11: ASSASSINATE | B11: Assassinate | C11: 4 | D11: 13 | E11: TRUE | F11: 1 | G11: 2 | H11: 0 | I11: 0 | J11: 100 | K11: 1 | L11: 14000 | M11: 21 | N11: TRUE | O11: 0 | P11: 0 | Q11: 0 | R11: 0 | S11: 0 | T11: 0 | U11: 0 | V11: 0 | W11: 1 | Y11: 0 | Z11: TRUE | AD11: 2-part damage structure: base 1400%->1680%(lvl50, curve continues) x2 hits (factorIndex 21, baseDamage 14000 tenths%), PLUS a periodic finishing blow (+3000%->3750%(lvl50) additional damage, factorIndex 12, baseDamage 30000 tenths% — see FINISHER constants below) landing on average every 2nd cast (modeled as a flat 50% average multiplier, not an exact odd/even cast counter). This row needs a BESPOKE Calc!F formula (two independent FactorTable lookups combined additively, the finisher term halved for its average-every-2nd-cast frequency) — see build_calc_sheet. Mastery Lv.108 'Murderous Intent' doubles the NEXT finishing blow after a Blood Money attack — modeled as a steady-state average multiplier on the finisher term (probability = MIN(1, Blood-Money's own cast rate / Assassinate's own finisher rate)), not an exact alternating-state machine. Mastery Lv.134 'Assassinate - Damage' +50% (real, applies to the base-hit term only, matching the wiki's own 'Assassinate damage' wording which doesn't call out the finisher specifically). Curve confidence note: the patch's own qualitative text ('base hit damage now increases more significantly with skill level') has no numeric override — using the wiki's own current curve as the best available data. Triggers Toxic Venom (a genuine independent attack, unlike Venom/Shadow Partner/Shadow Shifter's own deliberate exclusions).
A12: SUDDEN_RAID_BURST | B12: Sudden Raid (burst) | C12: 4 | D12: 19 | E12: TRUE | F12: 1 | G12: 3 | H12: 0 | I12: 0 | J12: 100 | K12: 1 | L12: 14000 | M12: 12 | N12: TRUE | O12: =SUMPRODUCT((Inputs!$B$3>={126})*{50}) | P12: 0 | Q12: 0 | R12: 0 | S12: 0 | T12: 0 | U12: 0 | V12: 0 | W12: 8 | Y12: 0 | Z12: TRUE | AD12: Shared verbatim w/ Night Lord. factorIndex 12, baseDamage 14000 tenths% (1400%->2800%, levels 1-200). Mastery Lv.126 'Sudden Raid - Damage' +50% (Shadower's own tier, at a different level than Night Lord's own Lv.124 tier for the same mastery name — each class's mastery TABLE assigns its own level to a shared base skill's mastery, confirmed not an error). Does not apply to the DoT row below.
A13: SUDDEN_RAID_DOT | B13: Sudden Raid (DoT) | C13: 4 | D13: =Skills!D12 | E13: FALSE | F13: 1 | G13: 1 | H13: 1 | I13: 5 | J13: 100 | K13: 1 | L13: 3600 | M13: 12 | N13: TRUE | O13: 0 | P13: 0 | Q13: 0 | R13: 0 | S13: 0 | T13: 0 | U13: 0 | V13: 0 | W13: 8 | Y13: 0 | Z13: TRUE | AD13: Shared verbatim w/ Night Lord. Shares Sudden Raid (burst)'s live Cooldown(s) cell. factorIndex 12, baseDamage 3600 tenths% (360%->720%, levels 1-200), 5s window / 1s ICD = 5 EffectiveHits per cast.
A14: BLOOD_MONEY | B14: Blood Money | C14: 4 | D14: =Skills!D4 | E14: FALSE | F14: 1 | G14: 3 | H14: 0 | I14: 0 | J14: 100 | K14: 1 | L14: 36000 | M14: 12 | N14: TRUE | O14: =SUMPRODUCT((Inputs!$B$3>={122,138})*{50,50}) | P14: 0 | Q14: 0 | R14: 0 | S14: 0 | T14: 0 | U14: 0 | V14: =IF(Inputs!$B$3>=138,3,IF(Inputs!$B$3>=122,2,1)) | Y14: 0 | Z14: TRUE | AD14: PATCHED (Aug 13 2026): base damage 2800%->3600% (curve rescaled 1.2857x before reverse-engineering — factorIndex 12, baseDamage 36000 tenths% already reflects the patched value), single-target +5%/stack bonus REMOVED. Triggers alongside Meso Explosion's own cast (shares its live Cooldown(s) cell, no independent cooldown) — 50% chance PER meso-generation-roll to also create a Blood Money stack (max 5), modeled at steady state: MIN(5, 0.25*attack_rate*11) (0.5 meso-chance x 0.5 blood-money-chance), a bespoke NormalMonsterTargets-equivalent formula in build_calc_sheet (left blank here, same treatment as Meso Explosion's own targets formula). MasteryTargetIncrease field repurposed here as the stack-to-targets MULTIPLIER (1x pre-122, 2x at 122, 3x at 138 — both Lv.122 and Lv.138 masteries renamed 'Damage & Target' by the patch, see the plan's Context section for the full before/after reconciliation). SkillMasteryBonus% is the combined +50%(122)+50%(138) = +100% total once both unlock. Triggers Toxic Venom.
A15: SMOKESCREEN | B15: Smokescreen | C15: 4 | D15: 45 | E15: TRUE | F15: 1 | G15: 1 | H15: 0 | I15: 0 | J15: 100 | K15: 1 | L15: 130 | M15: 22 | N15: TRUE | O15: 0 | P15: 0 | Q15: 0 | R15: 0 | S15: 0 | T15: 0 | U15: 0 | V15: 0 | W15: 1 | X15: FINAL_DAMAGE | Y15: 20 | Z15: FALSE | AD15: Enemy-debuff components (Accuracy/Evasion/Defense reduction) and ally-damage-taken-reduction not modeled (no such mechanics exist anywhere in this calculator). Self Final Damage component only: +13%->14.9%(lvl50, curve continues) for 20s, cooldown 45s. factorIndex 22, baseDamage 130 tenths% — confirmed via exact-floor curve matching (the naive mean-based resolver initially suggested 129, off by one due to this being a small-magnitude curve, same class of rounding issue flagged in this project's own memory notes for FP-Mage — resolved by checking which integer base reproduces every sampled level's value exactly under floor-to-1-decimal rounding, not just within a loose tolerance). Mastery Lv.113 'Smokescreen - Critical': -10% enemy Critical Resistance in range (not modeled) + allies' Critical Damage +30% (self-inclusive, feeds a Crit-Damage-bonus accumulator in build_summary_sheet, duty-cycle-averaged off this row's own uptime).
A16: SHADOW_SHIFTER | B16: Shadow Shifter (counterattack) | C16: 4 | E16: FALSE | F16: 1 | G16: 1 | H16: 0 | I16: 0 | J16: 100 | K16: 1 | L16: 25000 | M16: 21 | N16: TRUE | O16: 0 | P16: 0 | Q16: 0 | R16: 0 | S16: 0 | T16: 0 | U16: 0 | V16: 0 | W16: 1 | Y16: 0 | Z16: FALSE | AD16: Shared verbatim w/ Night Lord. Counterattack DPS = Inputs!incoming_hit_rate * 20% * ExpectedDamage(counterHit) — bespoke O-column branch, no Cooldown(s)/rate machinery of its own. factorIndex 21, baseDamage 25000 tenths% (2500%->4500%, levels 1-200).
A17: SHADOW_SHIFTER_SELF_ATK | B17: Shadow Shifter (self Attack%) | C17: 4 | E17: FALSE | F17: 1 | G17: 1 | H17: 0 | I17: 0 | J17: 100 | K17: 1 | L17: 100 | M17: 22 | N17: TRUE | O17: 0 | P17: 0 | Q17: 0 | R17: 0 | S17: 0 | T17: 0 | U17: 0 | V17: 0 | W17: 1 | X17: ATTACK | Y17: 0 | Z17: FALSE | AD17: Shared verbatim w/ Night Lord. Passive-mult delta-tracking row (10%->16% self Attack) — assumed already baked into Inputs!ATTACK_PCT (Magic Critical pattern). factorIndex 22, baseDamage 100 tenths%.
A18: MAPLE_HERO_SHADOWER | B18: Maple Hero | C18: 4 | E18: FALSE | F18: 1 | G18: 1 | H18: 0 | I18: 0 | J18: 100 | K18: 1 | L18: 150 | M18: 23 | N18: TRUE | O18: 0 | P18: 0 | Q18: 0 | R18: 0 | S18: 0 | T18: 0 | U18: 0 | V18: 0 | W18: 1 | Y18: 0 | Z18: FALSE | AD18: Shared curve feeding Dark Flare/Venom/Shadow Partner/Phase Dash's own Final Damage chains (see MAPLE_HERO_SHADOWER_RATIOS) — confirmed via reverse-engineering that all 4 target values scale proportionally across the full level range (factorIndex 23, baseDamage 150 tenths%, representing Dark Flare's own 1x share; Venom/Shadow Partner are 3.3333x, Phase Dash is 2.6667x). No independent DPS row of its own (Calc columns J-N stay blank/0, same 'no independent row' pattern as Night Lord's own Night Lord's Mark) — only D/E/F are computed, read directly by each target row's own K-column formula.
A19: NIMBLE_FEET | B19: Nimble Feet | C19: 1 | D19: 60 | E19: TRUE | F19: 1 | G19: 1 | H19: 0 | I19: 0 | J19: 100 | K19: 1 | L19: 150 | M19: 0 | N19: FALSE | O19: 0 | P19: 0 | Q19: 0 | R19: 0 | S19: 0 | T19: 0 | U19: 0 | V19: 0 | W19: 1 | X19: ATTACK_SPEED | Y19: 15 | Z19: FALSE | AD19: Shared verbatim w/ Night Lord/FP-Mage. Flat +15% Attack Speed / +10% Speed for 15s, 60s cooldown, non-scaling. FactorIndex unused placeholder.
A20: DARK_SIGHT_CRIT | B20: Dark Sight (Crit Rate) | C20: 1 | D20: 25 | E20: FALSE | F20: 1 | G20: 1 | H20: 0 | I20: 0 | J20: 100 | K20: 1 | L20: 60 | M20: 21 | N20: TRUE | O20: 0 | P20: 0 | Q20: 0 | R20: 0 | S20: 0 | T20: 0 | U20: 0 | V20: 0 | W20: 1 | X20: CRIT_RATE | Y20: =IF(Inputs!$B$3>=24,12,8) | Z20: FALSE | AD20: Shared verbatim w/ Night Lord (identical wording). Two-stage activation grants +6%->8.4% Crit Rate for 8s (->12s once Mastery Lv.24 'Dark Sight - Persistence' unlocks). factorIndex 21, baseDamage 60 tenths%. Passenger row (CostsActionSlot=False).
A21: DARK_SIGHT_ATK | B21: Dark Sight (Attack) | C21: 1 | D21: 25 | E21: TRUE | F21: 2 | G21: 1 | H21: 0 | I21: 0 | J21: 100 | K21: 1 | L21: 100 | M21: 21 | N21: TRUE | O21: 0 | P21: 0 | Q21: 0 | R21: 0 | S21: 0 | T21: 0 | U21: 0 | V21: 0 | W21: 1 | X21: ATTACK | Y21: =IF(Inputs!$B$3>=24,12,8) | Z21: FALSE | AD21: Shared verbatim w/ Night Lord. Same 2-stage activation, +10%->14% Attack for 8s (->12s at Mastery Lv.24). factorIndex 21, baseDamage 100 tenths%. ActionsPerCast=2.
A22: AGILE_DAGGERS | B22: Agile Daggers | C22: 2 | E22: FALSE | F22: 1 | G22: 1 | H22: 0 | I22: 0 | J22: 100 | K22: 1 | L22: 50 | M22: 22 | N22: TRUE | O22: 0 | P22: 0 | Q22: 0 | R22: 0 | S22: 0 | T22: 0 | U22: 0 | V22: 0 | W22: 1 | X22: ATTACK_SPEED | Y22: 0 | Z22: FALSE | AD22: HIGH-CONFIDENCE REUSE (no individual wiki page exists for this specific skill, but its level-1 text '+5% Attack Speed' is word-for-word identical to Night Lord's own Agile Claws): reuses that exact factorIndex 22/baseDamage 50 tenths% pair. Magic Critical pattern — already baked into Inputs!ATTACK_SPEED%; feeds the 2nd-Job Skill Level Bonus Sensitivity delta only.
A23: CHANNEL_KARMA | B23: Channel Karma (self Attack%) | C23: 2 | E23: FALSE | F23: 1 | G23: 1 | H23: 0 | I23: 0 | J23: 100 | K23: 1 | L23: 80 | M23: 22 | N23: TRUE | O23: 0 | P23: 0 | Q23: 0 | R23: 0 | S23: 0 | T23: 0 | U23: 0 | V23: 0 | W23: 1 | X23: ATTACK | Y23: 0 | Z23: FALSE | AD23: FLAGGED ASSUMPTION (no individual wiki page exists): factorIndex 22 (convention), baseDamage 80 tenths% (8% level-1 Attack component). Critical Resistance component not modeled (no such mechanic exists). Magic Critical pattern — already baked into Inputs!ATTACK_PCT; feeds the 2nd-Job Skill Level Bonus delta only.
A24: DAGGER_MASTERY | B24: Dagger Mastery | C24: 2 | E24: FALSE | F24: 1 | G24: 1 | H24: 0 | I24: 0 | J24: 100 | K24: 1 | L24: 150 | M24: 22 | N24: TRUE | O24: 0 | P24: 0 | Q24: 0 | R24: 0 | S24: 0 | T24: 0 | U24: 0 | V24: 0 | W24: 1 | X24: MIN_DAMAGE | Y24: 0 | Z24: FALSE | AD24: Magic Critical pattern — already baked into Inputs!MIN_DAMAGE%; feeds the 2nd-Job Skill Level Bonus delta. factorIndex 22, baseDamage 150 tenths%.
A25: CRITICAL_EDGE_RATE | B25: Critical Edge (Crit Rate) | C25: 2 | E25: FALSE | F25: 1 | G25: 1 | H25: 0 | I25: 0 | J25: 100 | K25: 1 | L25: 60 | M25: 22 | N25: TRUE | O25: 0 | P25: 0 | Q25: 0 | R25: 0 | S25: 0 | T25: 0 | U25: 0 | V25: 0 | W25: 1 | X25: CRIT_RATE | Y25: 0 | Z25: FALSE | AD25: Magic Critical pattern — already baked into Inputs!CRIT_RATE%; feeds the 2nd-Job Skill Level Bonus delta. factorIndex 22, baseDamage 60 tenths%.
A26: CRITICAL_EDGE_DMG | B26: Critical Edge (Crit Damage) | C26: 2 | E26: FALSE | F26: 1 | G26: 1 | H26: 0 | I26: 0 | J26: 100 | K26: 1 | L26: 100 | M26: 22 | N26: TRUE | O26: 0 | P26: 0 | Q26: 0 | R26: 0 | S26: 0 | T26: 0 | U26: 0 | V26: 0 | W26: 1 | X26: CRIT_DAMAGE | Y26: 0 | Z26: FALSE | AD26: Same skill as Critical Edge (Crit Rate) above. Magic Critical pattern — already baked into Inputs!CRIT_DAMAGE%; feeds the 2nd-Job Skill Level Bonus delta. factorIndex 22, baseDamage 100 tenths%.
A27: PHYSICAL_TRAINING | B27: Physical Training | C27: 2 | E27: FALSE | F27: 1 | G27: 1 | H27: 0 | I27: 0 | J27: 100 | K27: 1 | L27: 100 | M27: 22 | N27: TRUE | O27: 0 | P27: 0 | Q27: 0 | R27: 0 | S27: 0 | T27: 0 | U27: 0 | V27: 0 | W27: 1 | X27: BASIC_ATTACK_DAMAGE | Y27: 0 | Z27: FALSE | AD27: Magic Critical pattern — already baked into Inputs!BASIC_ATTACK_DAMAGE%; feeds the 2nd-Job Skill Level Bonus delta. factorIndex 22, baseDamage 100 tenths%.
A28: DAGGER_EXPERT_SKILL | B28: Dagger Expert (Skill Damage) | C28: 4 | E28: FALSE | F28: 1 | G28: 1 | H28: 0 | I28: 0 | J28: 100 | K28: 1 | L28: 150 | M28: 22 | N28: TRUE | O28: 0 | P28: 0 | Q28: 0 | R28: 0 | S28: 0 | T28: 0 | U28: 0 | V28: 0 | W28: 1 | X28: SKILL_DAMAGE | Y28: 0 | Z28: FALSE | AD28: Magic Critical pattern — already baked into Inputs!SKILL_DAMAGE%; feeds the 4th-Job Skill Level Bonus delta (Skill Damage side). factorIndex 22, baseDamage 150 tenths%.
A29: DAGGER_EXPERT_MAXDMG | B29: Dagger Expert (Max Damage Multiplier) | C29: 4 | E29: FALSE | F29: 1 | G29: 1 | H29: 0 | I29: 0 | J29: 100 | K29: 1 | L29: 200 | M29: 22 | N29: TRUE | O29: 0 | P29: 0 | Q29: 0 | R29: 0 | S29: 0 | T29: 0 | U29: 0 | V29: 0 | W29: 1 | X29: MAX_DAMAGE | Y29: 0 | Z29: FALSE | AD29: Same skill as Dagger Expert (Skill Damage) above, +20%->23% Max Damage Multiplier. Magic Critical pattern — already baked into Inputs!MAX_DAMAGE%; feeds the 4th-Job Skill Level Bonus delta (Max Damage Multiplier side). factorIndex 22, baseDamage 200 tenths%.
A30: SHADOWER_INSTINCT | B30: Shadower Instinct | C30: 4 | E30: FALSE | F30: 1 | G30: 1 | H30: 0 | I30: 0 | J30: 100 | K30: 1 | L30: 200 | M30: 22 | N30: TRUE | O30: 0 | P30: 0 | Q30: 0 | R30: 0 | S30: 0 | T30: 0 | U30: 0 | V30: 0 | W30: 1 | X30: FINAL_DAMAGE | Y30: 0 | Z30: FALSE | AD30: Magic Critical pattern — already baked into Inputs!FINAL_DAMAGE%; feeds the 4th-Job Skill Level Bonus delta. factorIndex 22, baseDamage 200 tenths%.

Sheet Calc
A1: Key | B1: Name | C1: Unlocked | D1: InputLevel | E1: Factor | F1: CoefficientPercent | G1: EffectiveHits | H1: ProcProbability | I1: MapleHeroMultiplier | J1: BaseDamage | K1: BaseHitDamage | L1: NonCritAvg | M1: CritAvg | N1: ExpectedDamage(perHit) | O1: DPS | P1: % of Total | Q1: InvCooldown | R1: CastsInFight | S1: HitRate(perSec) | U1: Maple Hero (Shadower) helper — unused (see MAPLE_HERO_SHADOWER row's own Note)
A2: =Skills!A2 | B2: =Skills!B2 | C2: =Inputs!$B$3>=100 | F2: =Summary!$B$54+Skills!O2 | G2: =Skills!G2*IF(Skills!H2>0,Skills!I2/Skills!H2,1) | H2: =1-(1-Skills!J2/100)^Skills!K2 | I2: 1 | J2: =Summary!$B$50*(F2/100) | K2: =J2*(1+Summary!$B$51/100)*(1+Inputs!$B$14/100)*(1+IF(Inputs!$B$4="pvp",0,(1-Summary!$B$55)*(Inputs!$B$19+Skills!P2+Summary!$B$59)+Summary!$B$55*(Inputs!$B$20+Skills!Q2+Summary!$B$59))/100)*(1+Inputs!$B$15/100)*(5000/(6000+Inputs!$B$7*(1-Inputs!$B$18/100)))*(1+Inputs!$B$23/100)*(1+(IF(Skills!A2="CRUEL_STAB",Inputs!$B$16,Inputs!$B$17))/100)*(Summary!$B$57*Summary!$B$60*I2) | L2: =K2*(MIN(Inputs!$B$21,Inputs!$B$22)/100+Inputs!$B$22/100)/2 | M2: =L2*(1+(Inputs!$B$9+Summary!$B$65)/100) | N2: =L2*(1-MIN((Inputs!$B$8+Summary!$B$58),100)/100)+M2*(MIN((Inputs!$B$8+Summary!$B$58),100)/100) | O2: =IF(C2,Skills!G2*N2*Summary!$B$64*IF(Inputs!$B$4="pvp",1,(1-Summary!$B$55)*(1)+Summary!$B$55*(MIN(Skills!W2,Inputs!$B$37))),0) | P2: =IF(Summary!$B$3=0,0,O2/Summary!$B$3) | Q2: 0 | R2: 0 | S2: =IFERROR(O2/N2,0)
A3: =Skills!A3 | B3: =Skills!B3 | C3: =Inputs!$B$3>=35 | D3: =IF(Skills!C3=1,60+Inputs!$B$24+Inputs!$B$28,IF(Skills!C3=2,90+Inputs!$B$25+Inputs!$B$28,IF(Skills!C3=3,120+Inputs!$B$26+Inputs!$B$28,MAX(0,(Inputs!$B$3-100)*3)+Inputs!$B$27+Inputs!$B$28))) | E3: =INDEX(FactorTable!$B$2:$Y$301, MATCH(ROUND(MIN(300,MAX(1,D3)),0), FactorTable!$A$2:$A$301,0), Skills!M3+1) | F3: =IF(Skills!N3=TRUE,(Skills!L3/10)*(E3/1000),Skills!L3/10)+Skills!O3 | G3: =Skills!G3*IF(Skills!H3>0,Skills!I3/Skills!H3,1) | H3: =1-(1-Skills!J3/100)^Skills!K3 | I3: 1 | O3: 0 | P3: =IF(Summary!$B$3=0,0,O3/Summary!$B$3) | Q3: 0 | R3: 0 | S3: =IFERROR(O3/N3,0)
A4: =Skills!A4 | B4: =Skills!B4 | C4: =Inputs!$B$3>=66 | D4: =IF(Skills!C4=1,60+Inputs!$B$24+Inputs!$B$28,IF(Skills!C4=2,90+Inputs!$B$25+Inputs!$B$28,IF(Skills!C4=3,120+Inputs!$B$26+Inputs!$B$28,MAX(0,(Inputs!$B$3-100)*3)+Inputs!$B$27+Inputs!$B$28))) | E4: =INDEX(FactorTable!$B$2:$Y$301, MATCH(ROUND(MIN(300,MAX(1,D4)),0), FactorTable!$A$2:$A$301,0), Skills!M4+1) | F4: =IF(Skills!N4=TRUE,(Skills!L4/10)*(E4/1000),Skills!L4/10)+Skills!O4 | G4: =Skills!G4*IF(Skills!H4>0,Skills!I4/Skills!H4,1) | H4: =1-(1-Skills!J4/100)^Skills!K4 | I4: 1 | J4: =Summary!$B$50*(F4/100) | K4: =J4*(1+Summary!$B$51/100)*(1+Inputs!$B$14/100)*(1+IF(Inputs!$B$4="pvp",0,(1-Summary!$B$55)*(Inputs!$B$19+Skills!P4+Summary!$B$59)+Summary!$B$55*(Inputs!$B$20+Skills!Q4+Summary!$B$59))/100)*(1+Inputs!$B$15/100)*(5000/(6000+Inputs!$B$7*(1-Inputs!$B$18/100)))*(1+Inputs!$B$23/100)*(1+(IF(Skills!A4="CRUEL_STAB",Inputs!$B$16,Inputs!$B$17))/100)*(Summary!$B$57*Summary!$B$60*I4) | L4: =K4*(MIN(Inputs!$B$21,Inputs!$B$22)/100+Inputs!$B$22/100)/2 | M4: =L4*(1+(Inputs!$B$9+Summary!$B$65)/100) | N4: =L4*(1-MIN((Inputs!$B$8+Summary!$B$58),100)/100)+M4*(MIN((Inputs!$B$8+Summary!$B$58),100)/100) | O4: =IF(C4,H4*N4*IF(AND(Inputs!$B$4<>"pvp",Inputs!$B$35>0),((Skills!G4*((R4-1)*IF(Skills!H4>0,Skills!I4/Skills!H4,1)+IF(Skills!H4>0,MIN(Skills!I4,MAX(0,Inputs!$B$35-((R4-1)*IF(Inputs!$B$4="pvp",15,MAX(0.1,Skills!D4-IF(Skills!E4=TRUE,Inputs!$B$31,0))))))/Skills!H4,1)))/Inputs!$B$35),G4*Q4)*IF(Inputs!$B$4="pvp",1,(1-Summary!$B$55)*(1)+Summary!$B$55*(MIN(MIN(10,0.5*Summary!$B$62*Skills!D4),Inputs!$B$37))),0) | P4: =IF(Summary!$B$3=0,0,O4/Summary!$B$3) | Q4: =IFERROR(1/IF(Inputs!$B$4="pvp",15,MAX(0.1,Skills!D4-IF(Skills!E4=TRUE,Inputs!$B$31,0))),0) | R4: =IF(AND(Inputs!$B$4<>"pvp",Inputs!$B$35>0),(INT(Inputs!$B$35/IF(Inputs!$B$4="pvp",15,MAX(0.1,Skills!D4-IF(Skills!E4=TRUE,Inputs!$B$31,0))))+1),0) | S4: =IFERROR(O4/N4,0)
A5: =Skills!A5 | B5: =Skills!B5 | C5: =Inputs!$B$3>=63 | D5: =IF(Skills!C5=1,60+Inputs!$B$24+Inputs!$B$28,IF(Skills!C5=2,90+Inputs!$B$25+Inputs!$B$28,IF(Skills!C5=3,120+Inputs!$B$26+Inputs!$B$28,MAX(0,(Inputs!$B$3-100)*3)+Inputs!$B$27+Inputs!$B$28))) | E5: =INDEX(FactorTable!$B$2:$Y$301, MATCH(ROUND(MIN(300,MAX(1,D5)),0), FactorTable!$A$2:$A$301,0), Skills!M5+1) | F5: =IF(Skills!N5=TRUE,(Skills!L5/10)*(E5/1000),Skills!L5/10)+Skills!O5 | G5: =Skills!G5*IF(Skills!H5>0,Skills!I5/Skills!H5,1) | H5: =1-(1-Skills!J5/100)^Skills!K5 | I5: 1 | J5: =Summary!$B$50*(F5/100) | K5: =J5*(1+Summary!$B$51/100)*(1+Inputs!$B$14/100)*(1+IF(Inputs!$B$4="pvp",0,(1-Summary!$B$55)*(Inputs!$B$19+Skills!P5+Summary!$B$59)+Summary!$B$55*(Inputs!$B$20+Skills!Q5+Summary!$B$59))/100)*(1+Inputs!$B$15/100)*(5000/(6000+Inputs!$B$7*(1-Inputs!$B$18/100)))*(1+Inputs!$B$23/100)*(1+2.6666666666666665*IF(C18=TRUE,F18,0)/100)*(1+(IF(Skills!A5="CRUEL_STAB",Inputs!$B$16,Inputs!$B$17))/100)*(Summary!$B$57*Summary!$B$60*I5) | L5: =K5*(MIN(Inputs!$B$21,Inputs!$B$22)/100+Inputs!$B$22/100)/2 | M5: =L5*(1+(Inputs!$B$9+Summary!$B$65)/100) | N5: =L5*(1-MIN((Inputs!$B$8+Summary!$B$58),100)/100)+M5*(MIN((Inputs!$B$8+Summary!$B$58),100)/100) | O5: =IF(C5,H5*N5*IF(AND(Inputs!$B$4<>"pvp",Inputs!$B$35>0),((Skills!G5*((R5-1)*IF(Skills!H5>0,Skills!I5/Skills!H5,1)+IF(Skills!H5>0,MIN(Skills!I5,MAX(0,Inputs!$B$35-((R5-1)*IF(Inputs!$B$4="pvp",15,MAX(0.1,Skills!D5-IF(Skills!E5=TRUE,Inputs!$B$31,0))))))/Skills!H5,1)))/Inputs!$B$35),G5*Q5)*IF(Inputs!$B$4="pvp",1,(1-Summary!$B$55)*(1)+Summary!$B$55*(MIN(Skills!W5,Inputs!$B$37))),0) | P5: =IF(Summary!$B$3=0,0,O5/Summary!$B$3) | Q5: =IFERROR(1/IF(Inputs!$B$4="pvp",15,MAX(0.1,Skills!D5-IF(Skills!E5=TRUE,Inputs!$B$31,0))),0) | R5: =IF(AND(Inputs!$B$4<>"pvp",Inputs!$B$35>0),(INT(Inputs!$B$35/IF(Inputs!$B$4="pvp",15,MAX(0.1,Skills!D5-IF(Skills!E5=TRUE,Inputs!$B$31,0))))+1),0) | S5: =IFERROR(O5/N5,0)
A6: =Skills!A6 | B6: =Skills!B6 | C6: =Inputs!$B$3>=69 | D6: =IF(Skills!C6=1,60+Inputs!$B$24+Inputs!$B$28,IF(Skills!C6=2,90+Inputs!$B$25+Inputs!$B$28,IF(Skills!C6=3,120+Inputs!$B$26+Inputs!$B$28,MAX(0,(Inputs!$B$3-100)*3)+Inputs!$B$27+Inputs!$B$28))) | E6: =INDEX(FactorTable!$B$2:$Y$301, MATCH(ROUND(MIN(300,MAX(1,D6)),0), FactorTable!$A$2:$A$301,0), Skills!M6+1) | F6: =IF(Skills!N6=TRUE,(Skills!L6/10)*(E6/1000),Skills!L6/10)+Skills!O6 | G6: =Skills!G6*IF(Skills!H6>0,Skills!I6/Skills!H6,1) | H6: =1-(1-Skills!J6/100)^Skills!K6 | I6: 1 | J6: =Summary!$B$50*(F6/100) | K6: =J6*(1+Summary!$B$51/100)*(1+Inputs!$B$14/100)*(1+IF(Inputs!$B$4="pvp",0,(1-Summary!$B$55)*(Inputs!$B$19+Skills!P6+Summary!$B$59)+Summary!$B$55*(Inputs!$B$20+Skills!Q6+Summary!$B$59))/100)*(1+Inputs!$B$15/100)*(5000/(6000+Inputs!$B$7*(1-Inputs!$B$18/100)))*(1+Inputs!$B$23/100)*(1+1.0*IF(C18=TRUE,F18,0)/100)*(1+(IF(Skills!A6="CRUEL_STAB",Inputs!$B$16,Inputs!$B$17))/100)*(Summary!$B$57*Summary!$B$60*I6) | L6: =K6*(MIN(Inputs!$B$21,Inputs!$B$22)/100+Inputs!$B$22/100)/2 | M6: =L6*(1+(Inputs!$B$9+Summary!$B$65)/100) | N6: =L6*(1-MIN((Inputs!$B$8+Summary!$B$58),100)/100)+M6*(MIN((Inputs!$B$8+Summary!$B$58),100)/100) | O6: =IF(C6,H6*N6*IF(AND(Inputs!$B$4<>"pvp",Inputs!$B$35>0),((Skills!G6*((R6-1)*IF(Skills!H6>0,Skills!I6/Skills!H6,1)+IF(Skills!H6>0,MIN(Skills!I6,MAX(0,Inputs!$B$35-((R6-1)*IF(Inputs!$B$4="pvp",15,MAX(0.1,Skills!D6-IF(Skills!E6=TRUE,Inputs!$B$31,0))))))/Skills!H6,1)))/Inputs!$B$35),G6*Q6)*IF(Inputs!$B$4="pvp",1,(1-Summary!$B$55)*(1)+Summary!$B$55*(MIN(Skills!W6,Inputs!$B$37))),0) | P6: =IF(Summary!$B$3=0,0,O6/Summary!$B$3) | Q6: =IFERROR(1/IF(Inputs!$B$4="pvp",15,MAX(0.1,Skills!D6-IF(Skills!E6=TRUE,Inputs!$B$31,0))),0) | R6: =IF(AND(Inputs!$B$4<>"pvp",Inputs!$B$35>0),(INT(Inputs!$B$35/IF(Inputs!$B$4="pvp",15,MAX(0.1,Skills!D6-IF(Skills!E6=TRUE,Inputs!$B$31,0))))+1),0) | S6: =IFERROR(O6/N6,0)
A7: =Skills!A7 | B7: =Skills!B7 | C7: =Inputs!$B$3>=60 | D7: =IF(Skills!C7=1,60+Inputs!$B$24+Inputs!$B$28,IF(Skills!C7=2,90+Inputs!$B$25+Inputs!$B$28,IF(Skills!C7=3,120+Inputs!$B$26+Inputs!$B$28,MAX(0,(Inputs!$B$3-100)*3)+Inputs!$B$27+Inputs!$B$28))) | E7: =INDEX(FactorTable!$B$2:$Y$301, MATCH(ROUND(MIN(300,MAX(1,D7)),0), FactorTable!$A$2:$A$301,0), Skills!M7+1) | F7: =IF(Skills!N7=TRUE,(Skills!L7/10)*(E7/1000),Skills!L7/10)+Skills!O7 | G7: =Skills!G7*IF(Skills!H7>0,Skills!I7/Skills!H7,1) | H7: =1-(1-Skills!J7/100)^Skills!K7 | I7: 1 | O7: 0 | P7: =IF(Summary!$B$3=0,0,O7/Summary!$B$3) | Q7: 0 | R7: 0 | S7: =IFERROR(O7/N7,0)
A8: =Skills!A8 | B8: =Skills!B8 | C8: =Inputs!$B$3>=72 | D8: =IF(Skills!C8=1,60+Inputs!$B$24+Inputs!$B$28,IF(Skills!C8=2,90+Inputs!$B$25+Inputs!$B$28,IF(Skills!C8=3,120+Inputs!$B$26+Inputs!$B$28,MAX(0,(Inputs!$B$3-100)*3)+Inputs!$B$27+Inputs!$B$28))) | E8: =INDEX(FactorTable!$B$2:$Y$301, MATCH(ROUND(MIN(300,MAX(1,D8)),0), FactorTable!$A$2:$A$301,0), Skills!M8+1) | F8: =IF(Skills!N8=TRUE,(Skills!L8/10)*(E8/1000),Skills!L8/10)+Skills!O8 | G8: =Skills!G8*IF(Skills!H8>0,Skills!I8/Skills!H8,1) | H8: =1-(1-Skills!J8/100)^Skills!K8 | I8: 1 | J8: =Summary!$B$50*(F8/100) | K8: =J8*(1+Summary!$B$51/100)*(1+Inputs!$B$14/100)*(1+IF(Inputs!$B$4="pvp",0,(1-Summary!$B$55)*(Inputs!$B$19+Skills!P8+Summary!$B$59)+Summary!$B$55*(Inputs!$B$20+Skills!Q8+Summary!$B$59))/100)*(1+Inputs!$B$15/100)*(5000/(6000+Inputs!$B$7*(1-Inputs!$B$18/100)))*(1+Inputs!$B$23/100)*(1+3.3333333333333335*IF(C18=TRUE,F18,0)/100)*(1+(IF(Skills!A8="CRUEL_STAB",Inputs!$B$16,Inputs!$B$17))/100)*(Summary!$B$57*Summary!$B$60*I8) | L8: =K8*(MIN(Inputs!$B$21,Inputs!$B$22)/100+Inputs!$B$22/100)/2 | M8: =L8*(1+(Inputs!$B$9+Summary!$B$65)/100) | N8: =L8*(1-MIN((Inputs!$B$8+Summary!$B$58),100)/100)+M8*(MIN((Inputs!$B$8+Summary!$B$58),100)/100) | O8: =IF(C8,H8*N8*IF(AND(Inputs!$B$4<>"pvp",Inputs!$B$35>0),((Skills!G8*((R8-1)*IF(Skills!H8>0,Skills!I8/Skills!H8,1)+IF(Skills!H8>0,MIN(Skills!I8,MAX(0,Inputs!$B$35-((R8-1)*IF(Inputs!$B$4="pvp",15,MAX(0.1,Skills!D8-IF(Skills!E8=TRUE,Inputs!$B$31,0))))))/Skills!H8,1)))/Inputs!$B$35),G8*Q8)*IF(Inputs!$B$4="pvp",1,(1-Summary!$B$55)*(1)+Summary!$B$55*(MIN(Skills!W8,Inputs!$B$37))),0) | P8: =IF(Summary!$B$3=0,0,O8/Summary!$B$3) | Q8: =IFERROR(1/IF(Inputs!$B$4="pvp",15,MAX(0.1,Skills!D8-IF(Skills!E8=TRUE,Inputs!$B$31,0))),0) | R8: =IF(AND(Inputs!$B$4<>"pvp",Inputs!$B$35>0),(INT(Inputs!$B$35/IF(Inputs!$B$4="pvp",15,MAX(0.1,Skills!D8-IF(Skills!E8=TRUE,Inputs!$B$31,0))))+1),0) | S8: =IFERROR(O8/N8,0)
A9: =Skills!A9 | B9: =Skills!B9 | C9: =Inputs!$B$3>=117 | D9: =IF(Skills!C9=1,60+Inputs!$B$24+Inputs!$B$28,IF(Skills!C9=2,90+Inputs!$B$25+Inputs!$B$28,IF(Skills!C9=3,120+Inputs!$B$26+Inputs!$B$28,MAX(0,(Inputs!$B$3-100)*3)+Inputs!$B$27+Inputs!$B$28))) | E9: =INDEX(FactorTable!$B$2:$Y$301, MATCH(ROUND(MIN(300,MAX(1,D9)),0), FactorTable!$A$2:$A$301,0), Skills!M9+1) | F9: =IF(Skills!N9=TRUE,(Skills!L9/10)*(E9/1000),Skills!L9/10)+Skills!O9 | G9: =Skills!G9*IF(Skills!H9>0,Skills!I9/Skills!H9,1) | H9: =1-(1-Skills!J9/100)^Skills!K9 | I9: 1 | J9: =Summary!$B$50*(F9/100) | K9: =J9*(1+Summary!$B$51/100)*(1+Inputs!$B$14/100)*(1+IF(Inputs!$B$4="pvp",0,(1-Summary!$B$55)*(Inputs!$B$19+Skills!P9+Summary!$B$59)+Summary!$B$55*(Inputs!$B$20+Skills!Q9+Summary!$B$59))/100)*(1+Inputs!$B$15/100)*(5000/(6000+Inputs!$B$7*(1-Inputs!$B$18/100)))*(1+Inputs!$B$23/100)*(1+(IF(Skills!A9="CRUEL_STAB",Inputs!$B$16,Inputs!$B$17))/100)*(Summary!$B$57*Summary!$B$60*I9) | L9: =K9*(MIN(Inputs!$B$21,Inputs!$B$22)/100+Inputs!$B$22/100)/2 | M9: =L9*(1+(Inputs!$B$9+Summary!$B$65)/100) | N9: =L9*(1-MIN((Inputs!$B$8+Summary!$B$58),100)/100)+M9*(MIN((Inputs!$B$8+Summary!$B$58),100)/100) | O9: =IF(C9,0.2*SUMPRODUCT((Skills!Z2:Z30=TRUE)*(C2:C30=TRUE)*S2:S30)*N9,0) | P9: =IF(Summary!$B$3=0,0,O9/Summary!$B$3) | Q9: 0 | R9: 0 | S9: 0
A10: =Skills!A10 | B10: =Skills!B10 | C10: =Inputs!$B$3>=74 | D10: =IF(Skills!C10=1,60+Inputs!$B$24+Inputs!$B$28,IF(Skills!C10=2,90+Inputs!$B$25+Inputs!$B$28,IF(Skills!C10=3,120+Inputs!$B$26+Inputs!$B$28,MAX(0,(Inputs!$B$3-100)*3)+Inputs!$B$27+Inputs!$B$28))) | E10: =INDEX(FactorTable!$B$2:$Y$301, MATCH(ROUND(MIN(300,MAX(1,D10)),0), FactorTable!$A$2:$A$301,0), Skills!M10+1) | F10: =IF(Skills!N10=TRUE,(Skills!L10/10)*(E10/1000),Skills!L10/10)+Skills!O10 | G10: =Skills!G10*IF(Skills!H10>0,Skills!I10/Skills!H10,1) | H10: =1-(1-Skills!J10/100)^Skills!K10 | I10: 1 | O10: 0 | P10: =IF(Summary!$B$3=0,0,O10/Summary!$B$3) | Q10: =IFERROR(1/IF(Inputs!$B$4="pvp",15,MAX(0.1,Skills!D10-IF(Skills!E10=TRUE,Inputs!$B$31,0))),0) | R10: =IF(AND(Inputs!$B$4<>"pvp",Inputs!$B$35>0),(INT(Inputs!$B$35/IF(Inputs!$B$4="pvp",15,MAX(0.1,Skills!D10-IF(Skills!E10=TRUE,Inputs!$B$31,0))))+1),0) | S10: =IFERROR(O10/N10,0)
A11: =Skills!A11 | B11: =Skills!B11 | C11: =Inputs!$B$3>=103 | D11: =IF(Skills!C11=1,60+Inputs!$B$24+Inputs!$B$28,IF(Skills!C11=2,90+Inputs!$B$25+Inputs!$B$28,IF(Skills!C11=3,120+Inputs!$B$26+Inputs!$B$28,MAX(0,(Inputs!$B$3-100)*3)+Inputs!$B$27+Inputs!$B$28))) | E11: =INDEX(FactorTable!$B$2:$Y$301, MATCH(ROUND(MIN(300,MAX(1,D11)),0), FactorTable!$A$2:$A$301,0), Skills!M11+1) | F11: =(Skills!L11/10)*(E11/1000)+IF(Inputs!$B$3>=134,50,0)+0.5*(30000/10)*(INDEX(FactorTable!$B$2:$Y$301, MATCH(ROUND(MIN(300,MAX(1,D11)),0), FactorTable!$A$2:$A$301,0), 13)/1000)*Summary!$B$68 | G11: =Skills!G11*IF(Skills!H11>0,Skills!I11/Skills!H11,1) | H11: =1-(1-Skills!J11/100)^Skills!K11 | I11: 1 | J11: =Summary!$B$50*(F11/100) | K11: =J11*(1+Summary!$B$51/100)*(1+Inputs!$B$14/100)*(1+IF(Inputs!$B$4="pvp",0,(1-Summary!$B$55)*(Inputs!$B$19+Skills!P11+Summary!$B$59)+Summary!$B$55*(Inputs!$B$20+Skills!Q11+Summary!$B$59))/100)*(1+Inputs!$B$15/100)*(5000/(6000+Inputs!$B$7*(1-Inputs!$B$18/100)))*(1+Inputs!$B$23/100)*(1+(IF(Skills!A11="CRUEL_STAB",Inputs!$B$16,Inputs!$B$17))/100)*(Summary!$B$57*Summary!$B$60*I11) | L11: =K11*(MIN(Inputs!$B$21,Inputs!$B$22)/100+Inputs!$B$22/100)/2 | M11: =L11*(1+(Inputs!$B$9+Summary!$B$65)/100) | N11: =L11*(1-MIN((Inputs!$B$8+Summary!$B$58),100)/100)+M11*(MIN((Inputs!$B$8+Summary!$B$58),100)/100) | O11: =IF(C11,H11*N11*IF(AND(Inputs!$B$4<>"pvp",Inputs!$B$35>0),((Skills!G11*((R11-1)*IF(Skills!H11>0,Skills!I11/Skills!H11,1)+IF(Skills!H11>0,MIN(Skills!I11,MAX(0,Inputs!$B$35-((R11-1)*IF(Inputs!$B$4="pvp",15,MAX(0.1,Skills!D11-IF(Skills!E11=TRUE,Inputs!$B$31,0))))))/Skills!H11,1)))/Inputs!$B$35),G11*Q11)*IF(Inputs!$B$4="pvp",1,(1-Summary!$B$55)*(1)+Summary!$B$55*(MIN(Skills!W11,Inputs!$B$37))),0) | P11: =IF(Summary!$B$3=0,0,O11/Summary!$B$3) | Q11: =IFERROR(1/IF(Inputs!$B$4="pvp",15,MAX(0.1,Skills!D11-IF(Skills!E11=TRUE,Inputs!$B$31,0))),0) | R11: =IF(AND(Inputs!$B$4<>"pvp",Inputs!$B$35>0),(INT(Inputs!$B$35/IF(Inputs!$B$4="pvp",15,MAX(0.1,Skills!D11-IF(Skills!E11=TRUE,Inputs!$B$31,0))))+1),0) | S11: =IFERROR(O11/N11,0)
A12: =Skills!A12 | B12: =Skills!B12 | C12: =Inputs!$B$3>=105 | D12: =IF(Skills!C12=1,60+Inputs!$B$24+Inputs!$B$28,IF(Skills!C12=2,90+Inputs!$B$25+Inputs!$B$28,IF(Skills!C12=3,120+Inputs!$B$26+Inputs!$B$28,MAX(0,(Inputs!$B$3-100)*3)+Inputs!$B$27+Inputs!$B$28))) | E12: =INDEX(FactorTable!$B$2:$Y$301, MATCH(ROUND(MIN(300,MAX(1,D12)),0), FactorTable!$A$2:$A$301,0), Skills!M12+1) | F12: =IF(Skills!N12=TRUE,(Skills!L12/10)*(E12/1000),Skills!L12/10)+Skills!O12 | G12: =Skills!G12*IF(Skills!H12>0,Skills!I12/Skills!H12,1) | H12: =1-(1-Skills!J12/100)^Skills!K12 | I12: 1 | J12: =Summary!$B$50*(F12/100) | K12: =J12*(1+Summary!$B$51/100)*(1+Inputs!$B$14/100)*(1+IF(Inputs!$B$4="pvp",0,(1-Summary!$B$55)*(Inputs!$B$19+Skills!P12+Summary!$B$59)+Summary!$B$55*(Inputs!$B$20+Skills!Q12+Summary!$B$59))/100)*(1+Inputs!$B$15/100)*(5000/(6000+Inputs!$B$7*(1-Inputs!$B$18/100)))*(1+Inputs!$B$23/100)*(1+(IF(Skills!A12="CRUEL_STAB",Inputs!$B$16,Inputs!$B$17))/100)*(Summary!$B$57*Summary!$B$60*I12) | L12: =K12*(MIN(Inputs!$B$21,Inputs!$B$22)/100+Inputs!$B$22/100)/2 | M12: =L12*(1+(Inputs!$B$9+Summary!$B$65)/100) | N12: =L12*(1-MIN((Inputs!$B$8+Summary!$B$58),100)/100)+M12*(MIN((Inputs!$B$8+Summary!$B$58),100)/100) | O12: =IF(C12,H12*N12*IF(AND(Inputs!$B$4<>"pvp",Inputs!$B$35>0),((Skills!G12*((R12-1)*IF(Skills!H12>0,Skills!I12/Skills!H12,1)+IF(Skills!H12>0,MIN(Skills!I12,MAX(0,Inputs!$B$35-((R12-1)*IF(Inputs!$B$4="pvp",15,MAX(0.1,Skills!D12-IF(Skills!E12=TRUE,Inputs!$B$31,0))))))/Skills!H12,1)))/Inputs!$B$35),G12*Q12)*IF(Inputs!$B$4="pvp",1,(1-Summary!$B$55)*(1)+Summary!$B$55*(MIN(Skills!W12,Inputs!$B$37))),0) | P12: =IF(Summary!$B$3=0,0,O12/Summary!$B$3) | Q12: =IFERROR(1/IF(Inputs!$B$4="pvp",15,MAX(0.1,Skills!D12-IF(Skills!E12=TRUE,Inputs!$B$31,0))),0) | R12: =IF(AND(Inputs!$B$4<>"pvp",Inputs!$B$35>0),(INT(Inputs!$B$35/IF(Inputs!$B$4="pvp",15,MAX(0.1,Skills!D12-IF(Skills!E12=TRUE,Inputs!$B$31,0))))+1),0) | S12: =IFERROR(O12/N12,0)
A13: =Skills!A13 | B13: =Skills!B13 | C13: =Inputs!$B$3>=105 | D13: =IF(Skills!C13=1,60+Inputs!$B$24+Inputs!$B$28,IF(Skills!C13=2,90+Inputs!$B$25+Inputs!$B$28,IF(Skills!C13=3,120+Inputs!$B$26+Inputs!$B$28,MAX(0,(Inputs!$B$3-100)*3)+Inputs!$B$27+Inputs!$B$28))) | E13: =INDEX(FactorTable!$B$2:$Y$301, MATCH(ROUND(MIN(300,MAX(1,D13)),0), FactorTable!$A$2:$A$301,0), Skills!M13+1) | F13: =IF(Skills!N13=TRUE,(Skills!L13/10)*(E13/1000),Skills!L13/10)+Skills!O13 | G13: =Skills!G13*IF(Skills!H13>0,Skills!I13/Skills!H13,1) | H13: =1-(1-Skills!J13/100)^Skills!K13 | I13: 1 | J13: =Summary!$B$50*(F13/100) | K13: =J13*(1+Summary!$B$51/100)*(1+Inputs!$B$14/100)*(1+IF(Inputs!$B$4="pvp",0,(1-Summary!$B$55)*(Inputs!$B$19+Skills!P13+Summary!$B$59)+Summary!$B$55*(Inputs!$B$20+Skills!Q13+Summary!$B$59))/100)*(1+Inputs!$B$15/100)*(5000/(6000+Inputs!$B$7*(1-Inputs!$B$18/100)))*(1+Inputs!$B$23/100)*(1+(IF(Skills!A13="CRUEL_STAB",Inputs!$B$16,Inputs!$B$17))/100)*(Summary!$B$57*Summary!$B$60*I13) | L13: =K13*(MIN(Inputs!$B$21,Inputs!$B$22)/100+Inputs!$B$22/100)/2 | M13: =L13*(1+(Inputs!$B$9+Summary!$B$65)/100) | N13: =L13*(1-MIN((Inputs!$B$8+Summary!$B$58),100)/100)+M13*(MIN((Inputs!$B$8+Summary!$B$58),100)/100) | O13: =IF(C13,H13*N13*IF(AND(Inputs!$B$4<>"pvp",Inputs!$B$35>0),((Skills!G13*((R13-1)*IF(Skills!H13>0,Skills!I13/Skills!H13,1)+IF(Skills!H13>0,MIN(Skills!I13,MAX(0,Inputs!$B$35-((R13-1)*IF(Inputs!$B$4="pvp",15,MAX(0.1,Skills!D13-IF(Skills!E13=TRUE,Inputs!$B$31,0))))))/Skills!H13,1)))/Inputs!$B$35),G13*Q13)*IF(Inputs!$B$4="pvp",1,(1-Summary!$B$55)*(1)+Summary!$B$55*(MIN(Skills!W13,Inputs!$B$37))),0) | P13: =IF(Summary!$B$3=0,0,O13/Summary!$B$3) | Q13: =IFERROR(1/IF(Inputs!$B$4="pvp",15,MAX(0.1,Skills!D13-IF(Skills!E13=TRUE,Inputs!$B$31,0))),0) | R13: =IF(AND(Inputs!$B$4<>"pvp",Inputs!$B$35>0),(INT(Inputs!$B$35/IF(Inputs!$B$4="pvp",15,MAX(0.1,Skills!D13-IF(Skills!E13=TRUE,Inputs!$B$31,0))))+1),0) | S13: =IFERROR(O13/N13,0)
A14: =Skills!A14 | B14: =Skills!B14 | C14: =Inputs!$B$3>=107 | D14: =IF(Skills!C14=1,60+Inputs!$B$24+Inputs!$B$28,IF(Skills!C14=2,90+Inputs!$B$25+Inputs!$B$28,IF(Skills!C14=3,120+Inputs!$B$26+Inputs!$B$28,MAX(0,(Inputs!$B$3-100)*3)+Inputs!$B$27+Inputs!$B$28))) | E14: =INDEX(FactorTable!$B$2:$Y$301, MATCH(ROUND(MIN(300,MAX(1,D14)),0), FactorTable!$A$2:$A$301,0), Skills!M14+1) | F14: =IF(Skills!N14=TRUE,(Skills!L14/10)*(E14/1000),Skills!L14/10)+Skills!O14 | G14: =Skills!G14*IF(Skills!H14>0,Skills!I14/Skills!H14,1) | H14: =1-(1-Skills!J14/100)^Skills!K14 | I14: 1 | J14: =Summary!$B$50*(F14/100) | K14: =J14*(1+Summary!$B$51/100)*(1+Inputs!$B$14/100)*(1+IF(Inputs!$B$4="pvp",0,(1-Summary!$B$55)*(Inputs!$B$19+Skills!P14+Summary!$B$59)+Summary!$B$55*(Inputs!$B$20+Skills!Q14+Summary!$B$59))/100)*(1+Inputs!$B$15/100)*(5000/(6000+Inputs!$B$7*(1-Inputs!$B$18/100)))*(1+Inputs!$B$23/100)*(1+(IF(Skills!A14="CRUEL_STAB",Inputs!$B$16,Inputs!$B$17))/100)*(Summary!$B$57*Summary!$B$60*I14) | L14: =K14*(MIN(Inputs!$B$21,Inputs!$B$22)/100+Inputs!$B$22/100)/2 | M14: =L14*(1+(Inputs!$B$9+Summary!$B$65)/100) | N14: =L14*(1-MIN((Inputs!$B$8+Summary!$B$58),100)/100)+M14*(MIN((Inputs!$B$8+Summary!$B$58),100)/100) | O14: =IF(C14,H14*N14*IF(AND(Inputs!$B$4<>"pvp",Inputs!$B$35>0),((Skills!G14*((R14-1)*IF(Skills!H14>0,Skills!I14/Skills!H14,1)+IF(Skills!H14>0,MIN(Skills!I14,MAX(0,Inputs!$B$35-((R14-1)*IF(Inputs!$B$4="pvp",15,MAX(0.1,Skills!D14-IF(Skills!E14=TRUE,Inputs!$B$31,0))))))/Skills!H14,1)))/Inputs!$B$35),G14*Q14)*IF(Inputs!$B$4="pvp",1,(1-Summary!$B$55)*(1)+Summary!$B$55*(MIN(MIN(5,0.25*Summary!$B$62*Skills!D4)*Skills!V14,Inputs!$B$37))),0) | P14: =IF(Summary!$B$3=0,0,O14/Summary!$B$3) | Q14: =IFERROR(1/IF(Inputs!$B$4="pvp",15,MAX(0.1,Skills!D14-IF(Skills!E14=TRUE,Inputs!$B$31,0))),0) | R14: =IF(AND(Inputs!$B$4<>"pvp",Inputs!$B$35>0),(INT(Inputs!$B$35/IF(Inputs!$B$4="pvp",15,MAX(0.1,Skills!D14-IF(Skills!E14=TRUE,Inputs!$B$31,0))))+1),0) | S14: =IFERROR(O14/N14,0)
A15: =Skills!A15 | B15: =Skills!B15 | C15: =Inputs!$B$3>=110 | D15: =IF(Skills!C15=1,60+Inputs!$B$24+Inputs!$B$28,IF(Skills!C15=2,90+Inputs!$B$25+Inputs!$B$28,IF(Skills!C15=3,120+Inputs!$B$26+Inputs!$B$28,MAX(0,(Inputs!$B$3-100)*3)+Inputs!$B$27+Inputs!$B$28))) | E15: =INDEX(FactorTable!$B$2:$Y$301, MATCH(ROUND(MIN(300,MAX(1,D15)),0), FactorTable!$A$2:$A$301,0), Skills!M15+1) | F15: =IF(Skills!N15=TRUE,(Skills!L15/10)*(E15/1000),Skills!L15/10)+Skills!O15 | G15: =Skills!G15*IF(Skills!H15>0,Skills!I15/Skills!H15,1) | H15: =1-(1-Skills!J15/100)^Skills!K15 | I15: 1 | O15: 0 | P15: =IF(Summary!$B$3=0,0,O15/Summary!$B$3) | Q15: =IFERROR(1/IF(Inputs!$B$4="pvp",15,MAX(0.1,Skills!D15-IF(Skills!E15=TRUE,Inputs!$B$31,0))),0) | R15: =IF(AND(Inputs!$B$4<>"pvp",Inputs!$B$35>0),(INT(Inputs!$B$35/IF(Inputs!$B$4="pvp",15,MAX(0.1,Skills!D15-IF(Skills!E15=TRUE,Inputs!$B$31,0))))+1),0) | S15: =IFERROR(O15/N15,0)
A16: =Skills!A16 | B16: =Skills!B16 | C16: =Inputs!$B$3>=115 | D16: =IF(Skills!C16=1,60+Inputs!$B$24+Inputs!$B$28,IF(Skills!C16=2,90+Inputs!$B$25+Inputs!$B$28,IF(Skills!C16=3,120+Inputs!$B$26+Inputs!$B$28,MAX(0,(Inputs!$B$3-100)*3)+Inputs!$B$27+Inputs!$B$28))) | E16: =INDEX(FactorTable!$B$2:$Y$301, MATCH(ROUND(MIN(300,MAX(1,D16)),0), FactorTable!$A$2:$A$301,0), Skills!M16+1) | F16: =IF(Skills!N16=TRUE,(Skills!L16/10)*(E16/1000),Skills!L16/10)+Skills!O16 | G16: =Skills!G16*IF(Skills!H16>0,Skills!I16/Skills!H16,1) | H16: =1-(1-Skills!J16/100)^Skills!K16 | I16: 1 | J16: =Summary!$B$50*(F16/100) | K16: =J16*(1+Summary!$B$51/100)*(1+Inputs!$B$14/100)*(1+IF(Inputs!$B$4="pvp",0,(1-Summary!$B$55)*(Inputs!$B$19+Skills!P16+Summary!$B$59)+Summary!$B$55*(Inputs!$B$20+Skills!Q16+Summary!$B$59))/100)*(1+Inputs!$B$15/100)*(5000/(6000+Inputs!$B$7*(1-Inputs!$B$18/100)))*(1+Inputs!$B$23/100)*(1+(IF(Skills!A16="CRUEL_STAB",Inputs!$B$16,Inputs!$B$17))/100)*(Summary!$B$57*Summary!$B$60*I16) | L16: =K16*(MIN(Inputs!$B$21,Inputs!$B$22)/100+Inputs!$B$22/100)/2 | M16: =L16*(1+(Inputs!$B$9+Summary!$B$65)/100) | N16: =L16*(1-MIN((Inputs!$B$8+Summary!$B$58),100)/100)+M16*(MIN((Inputs!$B$8+Summary!$B$58),100)/100) | O16: =IF(C16,Inputs!$B$38*0.2*N16,0) | P16: =IF(Summary!$B$3=0,0,O16/Summary!$B$3) | Q16: 0 | R16: 0 | S16: =IFERROR(O16/N16,0)
A17: =Skills!A17 | B17: =Skills!B17 | C17: =Inputs!$B$3>=115 | D17: =IF(Skills!C17=1,60+Inputs!$B$24+Inputs!$B$28,IF(Skills!C17=2,90+Inputs!$B$25+Inputs!$B$28,IF(Skills!C17=3,120+Inputs!$B$26+Inputs!$B$28,MAX(0,(Inputs!$B$3-100)*3)+Inputs!$B$27+Inputs!$B$28))) | E17: =INDEX(FactorTable!$B$2:$Y$301, MATCH(ROUND(MIN(300,MAX(1,D17)),0), FactorTable!$A$2:$A$301,0), Skills!M17+1) | F17: =IF(Skills!N17=TRUE,(Skills!L17/10)*(E17/1000),Skills!L17/10)+Skills!O17 | G17: =Skills!G17*IF(Skills!H17>0,Skills!I17/Skills!H17,1) | H17: =1-(1-Skills!J17/100)^Skills!K17 | I17: 1 | O17: 0 | P17: =IF(Summary!$B$3=0,0,O17/Summary!$B$3) | Q17: 0 | R17: 0 | S17: =IFERROR(O17/N17,0)
A18: =Skills!A18 | B18: =Skills!B18 | C18: =Inputs!$B$3>=100 | D18: =IF(Skills!C18=1,60+Inputs!$B$24+Inputs!$B$28,IF(Skills!C18=2,90+Inputs!$B$25+Inputs!$B$28,IF(Skills!C18=3,120+Inputs!$B$26+Inputs!$B$28,MAX(0,(Inputs!$B$3-100)*3)+Inputs!$B$27+Inputs!$B$28))) | E18: =INDEX(FactorTable!$B$2:$Y$301, MATCH(ROUND(MIN(300,MAX(1,D18)),0), FactorTable!$A$2:$A$301,0), Skills!M18+1) | F18: =IF(Skills!N18=TRUE,(Skills!L18/10)*(E18/1000),Skills!L18/10)+Skills!O18 | G18: =Skills!G18*IF(Skills!H18>0,Skills!I18/Skills!H18,1) | H18: =1-(1-Skills!J18/100)^Skills!K18 | I18: 1 | O18: 0 | P18: =IF(Summary!$B$3=0,0,O18/Summary!$B$3) | Q18: 0 | R18: 0 | S18: =IFERROR(O18/N18,0)
A19: =Skills!A19 | B19: =Skills!B19 | C19: =TRUE | D19: =IF(Skills!C19=1,60+Inputs!$B$24+Inputs!$B$28,IF(Skills!C19=2,90+Inputs!$B$25+Inputs!$B$28,IF(Skills!C19=3,120+Inputs!$B$26+Inputs!$B$28,MAX(0,(Inputs!$B$3-100)*3)+Inputs!$B$27+Inputs!$B$28))) | E19: =INDEX(FactorTable!$B$2:$Y$301, MATCH(ROUND(MIN(300,MAX(1,D19)),0), FactorTable!$A$2:$A$301,0), Skills!M19+1) | F19: =IF(Skills!N19=TRUE,(Skills!L19/10)*(E19/1000),Skills!L19/10)+Skills!O19 | G19: =Skills!G19*IF(Skills!H19>0,Skills!I19/Skills!H19,1) | H19: =1-(1-Skills!J19/100)^Skills!K19 | I19: 1 | O19: 0 | P19: =IF(Summary!$B$3=0,0,O19/Summary!$B$3) | Q19: =IFERROR(1/IF(Inputs!$B$4="pvp",15,MAX(0.1,Skills!D19-IF(Skills!E19=TRUE,Inputs!$B$31,0))),0) | R19: =IF(AND(Inputs!$B$4<>"pvp",Inputs!$B$35>0),(INT(Inputs!$B$35/IF(Inputs!$B$4="pvp",15,MAX(0.1,Skills!D19-IF(Skills!E19=TRUE,Inputs!$B$31,0))))+1),0) | S19: =IFERROR(O19/N19,0)
A20: =Skills!A20 | B20: =Skills!B20 | C20: =Inputs!$B$3>=15 | D20: =IF(Skills!C20=1,60+Inputs!$B$24+Inputs!$B$28,IF(Skills!C20=2,90+Inputs!$B$25+Inputs!$B$28,IF(Skills!C20=3,120+Inputs!$B$26+Inputs!$B$28,MAX(0,(Inputs!$B$3-100)*3)+Inputs!$B$27+Inputs!$B$28))) | E20: =INDEX(FactorTable!$B$2:$Y$301, MATCH(ROUND(MIN(300,MAX(1,D20)),0), FactorTable!$A$2:$A$301,0), Skills!M20+1) | F20: =IF(Skills!N20=TRUE,(Skills!L20/10)*(E20/1000),Skills!L20/10)+Skills!O20 | G20: =Skills!G20*IF(Skills!H20>0,Skills!I20/Skills!H20,1) | H20: =1-(1-Skills!J20/100)^Skills!K20 | I20: 1 | O20: 0 | P20: =IF(Summary!$B$3=0,0,O20/Summary!$B$3) | Q20: =IFERROR(1/IF(Inputs!$B$4="pvp",15,MAX(0.1,Skills!D20-IF(Skills!E20=TRUE,Inputs!$B$31,0))),0) | R20: =IF(AND(Inputs!$B$4<>"pvp",Inputs!$B$35>0),(INT(Inputs!$B$35/IF(Inputs!$B$4="pvp",15,MAX(0.1,Skills!D20-IF(Skills!E20=TRUE,Inputs!$B$31,0))))+1),0) | S20: =IFERROR(O20/N20,0)
A21: =Skills!A21 | B21: =Skills!B21 | C21: =Inputs!$B$3>=15 | D21: =IF(Skills!C21=1,60+Inputs!$B$24+Inputs!$B$28,IF(Skills!C21=2,90+Inputs!$B$25+Inputs!$B$28,IF(Skills!C21=3,120+Inputs!$B$26+Inputs!$B$28,MAX(0,(Inputs!$B$3-100)*3)+Inputs!$B$27+Inputs!$B$28))) | E21: =INDEX(FactorTable!$B$2:$Y$301, MATCH(ROUND(MIN(300,MAX(1,D21)),0), FactorTable!$A$2:$A$301,0), Skills!M21+1) | F21: =IF(Skills!N21=TRUE,(Skills!L21/10)*(E21/1000),Skills!L21/10)+Skills!O21 | G21: =Skills!G21*IF(Skills!H21>0,Skills!I21/Skills!H21,1) | H21: =1-(1-Skills!J21/100)^Skills!K21 | I21: 1 | O21: 0 | P21: =IF(Summary!$B$3=0,0,O21/Summary!$B$3) | Q21: =IFERROR(1/IF(Inputs!$B$4="pvp",15,MAX(0.1,Skills!D21-IF(Skills!E21=TRUE,Inputs!$B$31,0))),0) | R21: =IF(AND(Inputs!$B$4<>"pvp",Inputs!$B$35>0),(INT(Inputs!$B$35/IF(Inputs!$B$4="pvp",15,MAX(0.1,Skills!D21-IF(Skills!E21=TRUE,Inputs!$B$31,0))))+1),0) | S21: =IFERROR(O21/N21,0)
A22: =Skills!A22 | B22: =Skills!B22 | C22: =Inputs!$B$3>=33 | D22: =IF(Skills!C22=1,60+Inputs!$B$24+Inputs!$B$28,IF(Skills!C22=2,90+Inputs!$B$25+Inputs!$B$28,IF(Skills!C22=3,120+Inputs!$B$26+Inputs!$B$28,MAX(0,(Inputs!$B$3-100)*3)+Inputs!$B$27+Inputs!$B$28))) | E22: =INDEX(FactorTable!$B$2:$Y$301, MATCH(ROUND(MIN(300,MAX(1,D22)),0), FactorTable!$A$2:$A$301,0), Skills!M22+1) | F22: =IF(Skills!N22=TRUE,(Skills!L22/10)*(E22/1000),Skills!L22/10)+Skills!O22 | G22: =Skills!G22*IF(Skills!H22>0,Skills!I22/Skills!H22,1) | H22: =1-(1-Skills!J22/100)^Skills!K22 | I22: 1 | O22: 0 | P22: =IF(Summary!$B$3=0,0,O22/Summary!$B$3) | Q22: 0 | R22: 0 | S22: =IFERROR(O22/N22,0)
A23: =Skills!A23 | B23: =Skills!B23 | C23: =Inputs!$B$3>=40 | D23: =IF(Skills!C23=1,60+Inputs!$B$24+Inputs!$B$28,IF(Skills!C23=2,90+Inputs!$B$25+Inputs!$B$28,IF(Skills!C23=3,120+Inputs!$B$26+Inputs!$B$28,MAX(0,(Inputs!$B$3-100)*3)+Inputs!$B$27+Inputs!$B$28))) | E23: =INDEX(FactorTable!$B$2:$Y$301, MATCH(ROUND(MIN(300,MAX(1,D23)),0), FactorTable!$A$2:$A$301,0), Skills!M23+1) | F23: =IF(Skills!N23=TRUE,(Skills!L23/10)*(E23/1000),Skills!L23/10)+Skills!O23 | G23: =Skills!G23*IF(Skills!H23>0,Skills!I23/Skills!H23,1) | H23: =1-(1-Skills!J23/100)^Skills!K23 | I23: 1 | O23: 0 | P23: =IF(Summary!$B$3=0,0,O23/Summary!$B$3) | Q23: 0 | R23: 0 | S23: =IFERROR(O23/N23,0)
A24: =Skills!A24 | B24: =Skills!B24 | C24: =Inputs!$B$3>=43 | D24: =IF(Skills!C24=1,60+Inputs!$B$24+Inputs!$B$28,IF(Skills!C24=2,90+Inputs!$B$25+Inputs!$B$28,IF(Skills!C24=3,120+Inputs!$B$26+Inputs!$B$28,MAX(0,(Inputs!$B$3-100)*3)+Inputs!$B$27+Inputs!$B$28))) | E24: =INDEX(FactorTable!$B$2:$Y$301, MATCH(ROUND(MIN(300,MAX(1,D24)),0), FactorTable!$A$2:$A$301,0), Skills!M24+1) | F24: =IF(Skills!N24=TRUE,(Skills!L24/10)*(E24/1000),Skills!L24/10)+Skills!O24 | G24: =Skills!G24*IF(Skills!H24>0,Skills!I24/Skills!H24,1) | H24: =1-(1-Skills!J24/100)^Skills!K24 | I24: 1 | O24: 0 | P24: =IF(Summary!$B$3=0,0,O24/Summary!$B$3) | Q24: 0 | R24: 0 | S24: =IFERROR(O24/N24,0)
A25: =Skills!A25 | B25: =Skills!B25 | C25: =Inputs!$B$3>=50 | D25: =IF(Skills!C25=1,60+Inputs!$B$24+Inputs!$B$28,IF(Skills!C25=2,90+Inputs!$B$25+Inputs!$B$28,IF(Skills!C25=3,120+Inputs!$B$26+Inputs!$B$28,MAX(0,(Inputs!$B$3-100)*3)+Inputs!$B$27+Inputs!$B$28))) | E25: =INDEX(FactorTable!$B$2:$Y$301, MATCH(ROUND(MIN(300,MAX(1,D25)),0), FactorTable!$A$2:$A$301,0), Skills!M25+1) | F25: =IF(Skills!N25=TRUE,(Skills!L25/10)*(E25/1000),Skills!L25/10)+Skills!O25 | G25: =Skills!G25*IF(Skills!H25>0,Skills!I25/Skills!H25,1) | H25: =1-(1-Skills!J25/100)^Skills!K25 | I25: 1 | O25: 0 | P25: =IF(Summary!$B$3=0,0,O25/Summary!$B$3) | Q25: 0 | R25: 0 | S25: =IFERROR(O25/N25,0)
