Workbook

Sheet README
A1: Dark Knight — DPS Calculator: How to Use This Workbook
A3: How to use this workbook
A4: Only edit the yellow-highlighted cells on the Inputs sheet — every other sheet is computed from those values and will be overwritten if you rebuild the workbook.
A5: Summary shows Total DPS, a Per-Skill DPS Breakdown (damage-dealing skills only — buffs/passives that never deal their own damage are omitted), and a Marginal DPS & Stat Value table showing the DPS gained per +1 of each stat.
A6: Sensitivity has the full detail behind that marginal-value table — one self-contained block per stat, showing exactly how bumping that stat by +1 changes every downstream number.
A7: CubeData/PotentialCubes model your current gear's Potential Cube lines and drive cube-reroll expected-value decisions. For the full standalone Potential Cube EV calculator (exact optimal-stopping math, works from this workbook alone), see tools/potential_cubes_ev.py in the project repo.
A9: Design decisions & assumptions
A10: Weapon Acceleration, Weapon Mastery, Barricade Mastery, Power Stance's own Final Damage component, and Final Pact's own Final Damage component are always-on passives assumed to already be reflected in your own Inputs stat entries — only their Sensitivity marginal delta is modeled live, matching this project's established convention. Iron Wall (a level-scaling % of your total Defense as STR — 10% at Lv.1, growing with level, once Lv.38 unlocks) IS modeled live — Defense (flat) and Defense % are their own tracked Inputs, feeding STAT_DAMAGE directly, with their own Sensitivity marginal-value rows and PotentialCubes Defense % support. Warrior-Mastery-equivalent flat-stat passives have zero DPS-relevant mechanic and get no row at all. Dark Knight has NO Physical Training or Endure skill at all (confirmed absent from its own skill list, despite both being present on Hero's).
A11: Evil Eye and Dark Resonance both drive the Global Monster Damage-Taken Bonus% bucket (the mechanism Hero's own Scaring Sword pioneered) — Evil Eye's own +15%->19.2% applies to all monster types (duty-cycle averaged, always-on while summoned, no proc-chance gate), Dark Resonance's patch-added +20% applies boss-only (monster_blend_expr-gated), both summed into the same bucket.
A12: Evil Eye Shock, Evil Eye of Dominant, Hex of the Evil Eye, and Revenge of the Evil Eye all nominally require Evil Eye to be summoned first — this precondition is NOT modeled as a live gate (they're treated as always-castable once individually unlocked), a documented simplification consistent with this project not tracking buff-precondition chains elsewhere either.
A13: Evil Eye of Dominant is modeled as a background DoT tied to Evil Eye's own cast cycle (Cooldown=30s/ActiveWindow=20s matching Evil Eye's own duration, ICD=1s) — same pattern as FP-Mage's own Poison Mist fog DoT tied to its parent skill.
A14: Lord of Darkness is split into two rows (Crit Rate half, Crit Damage half) since this schema's BuffTargetStat column only holds one stat per row — same reason Hero's own Enrage is split. Both modeled as ProcChance% x duty-cycle uptime (Scaring-Sword-style simplification), not an exact per-attack RNG state machine. Its own HP-recovery component is not modeled.
... A20: Not modeled (out of scope): all forms of crowd control (Evil Eye Shock stun), Accuracy, Evasion, Defense, Max HP/MP recovery, movement speed, and Companion Summoning Time.

Sheet Inputs
A1: Dark Knight — DPS Calculator Inputs | N1: (none)
C2: Chapter Boss | D2: Breakthrough | E2: PvP | F2: EXP Dungeon | G2: Equipment Dungeon | H2: Weapon Dungeon | I2: Enhancement Dungeon | J2: Hero Dungeon | K2: World Boss | L2: Chapter Hunt | N2: Charm of the Undead
A3: Character Level | B3: 200 | N3: Pig's Ribbon
A4: Content Type | B4: Chapter Boss | N4: Shamaness Marble
A5: Chapter-Stage — 'chapter-substage' (e.g. '28-9') for Breakthrough/Chapter Hunt, just the chapter number for Chapter Boss, or just the stage number for Weapon/Equipment/Enhancement/EXP/Hero Dungeon. Not applicable to World Boss/PvP. | B5: =INDEX($C$5:$L$5,MATCH($B$4,$C$2:$L$2,0)) | C5: 28 | D5: 28-9 | F5: 80 | G5: 80 | H5: 80 | I5: 80 | J5: 80 | L5: 28-9 | N5: The Contract of Darkness
A6: Flat ATTACK | B6: =INDEX($C$6:$L$6,MATCH($B$4,$C$2:$L$2,0)) | C6: 10000 | D6: 10000 | E6: 10000 | F6: 10000 | G6: 10000 | H6: 10000 | I6: 10000 | J6: 10000 | K6: 10000 | L6: 10000 | N6: Rainbow-colored Snail Shell
A7: ATTACK % | B7: =INDEX($C$7:$L$7,MATCH($B$4,$C$2:$L$2,0)) | C7: 0 | D7: 0 | E7: 0 | F7: 0 | G7: 0 | H7: 0 | I7: 0 | J7: 0 | K7: 0 | L7: 0 | N7: Hexagon Necklace
A8: Defense (flat) — your own DEF stat; Iron Wall converts a level-scaling % (10% at Lv.1, growing with level) of it into STR, and PvP assumes the opponent has the same total Defense as you | B8: =INDEX($C$8:$L$8,MATCH($B$4,$C$2:$L$2,0)) | C8: 0 | D8: 0 | E8: 0 | F8: 0 | G8: 0 | H8: 0 | I8: 0 | J8: 0 | K8: 0 | L8: 0 | N8: Arwen's Glass Shoes
A9: Defense % (Iron Wall converts total Defense, incl. this %, into STR, at a level-scaling rate) | B9: =INDEX($C$9:$L$9,MATCH($B$4,$C$2:$L$2,0)) | C9: 0 | D9: 0 | E9: 0 | F9: 0 | G9: 0 | H9: 0 | I9: 0 | J9: 0 | K9: 0 | L9: 0 | N9: Mushmom's Cap
A10: CRIT_RATE % | B10: =INDEX($C$10:$L$10,MATCH($B$4,$C$2:$L$2,0)) | C10: 0 | D10: 0 | E10: 0 | F10: 0 | G10: 0 | H10: 0 | I10: 0 | J10: 0 | K10: 0 | L10: 0 | N10: Clear Spring Water
A11: CRIT_DAMAGE % | B11: =INDEX($C$11:$L$11,MATCH($B$4,$C$2:$L$2,0)) | C11: 0 | D11: 0 | E11: 0 | F11: 0 | G11: 0 | H11: 0 | I11: 0 | J11: 0 | K11: 0 | L11: 0 | N11: Athena Pierce's Old Gloves
A12: ATTACK_SPEED % (base, excludes Weapon Acceleration) | B12: =INDEX($C$12:$L$12,MATCH($B$4,$C$2:$L$2,0)) | C12: 0 | D12: 0 | E12: 0 | F12: 0 | G12: 0 | H12: 0 | I12: 0 | J12: 0 | K12: 0 | L12: 0 | N12: Zakum's Stone Piece
A13: Flat STR | B13: =INDEX($C$13:$L$13,MATCH($B$4,$C$2:$L$2,0)) | C13: 0 | D13: 0 | E13: 0 | F13: 0 | G13: 0 | H13: 0 | I13: 0 | J13: 0 | K13: 0 | L13: 0 | N13: Horntail's Scale
A14: STR % | B14: =INDEX($C$14:$L$14,MATCH($B$4,$C$2:$L$2,0)) | C14: 0 | D14: 0 | E14: 0 | F14: 0 | G14: 0 | H14: 0 | I14: 0 | J14: 0 | K14: 0 | L14: 0 | N14: Pink Bean's Giant Rib
A15: DEX | B15: =INDEX($C$15:$L$15,MATCH($B$4,$C$2:$L$2,0)) | C15: 0 | D15: 0 | E15: 0 | F15: 0 | G15: 0 | H15: 0 | I15: 0 | J15: 0 | K15: 0 | L15: 0 | N15: Chalice
A16: DAMAGE % | B16: =INDEX($C$16:$L$16,MATCH($B$4,$C$2:$L$2,0)) | C16: 0 | D16: 0 | E16: 0 | F16: 0 | G16: 0 | H16: 0 | I16: 0 | J16: 0 | K16: 0 | L16: 0 | N16: Old Music Box
A17: DAMAGE_AMP % | B17: =INDEX($C$17:$L$17,MATCH($B$4,$C$2:$L$2,0)) | C17: 0 | D17: 0 | E17: 0 | F17: 0 | G17: 0 | H17: 0 | I17: 0 | J17: 0 | K17: 0 | L17: 0 | N17: Silver Pendant
A18: BASIC_ATTACK_DAMAGE % | B18: =INDEX($C$18:$L$18,MATCH($B$4,$C$2:$L$2,0)) | C18: 0 | D18: 0 | E18: 0 | F18: 0 | G18: 0 | H18: 0 | I18: 0 | J18: 0 | K18: 0 | L18: 0 | N18: Star Rock
A19: SKILL_DAMAGE % | B19: =INDEX($C$19:$L$19,MATCH($B$4,$C$2:$L$2,0)) | C19: 0 | D19: 0 | E19: 0 | F19: 0 | G19: 0 | H19: 0 | I19: 0 | J19: 0 | K19: 0 | L19: 0 | N19: Book of Ancient
A20: DEF_PEN % | B20: =INDEX($C$20:$L$20,MATCH($B$4,$C$2:$L$2,0)) | C20: 0 | D20: 0 | E20: 0 | F20: 0 | G20: 0 | H20: 0 | I20: 0 | J20: 0 | K20: 0 | L20: 0 | N20: Lunar Dew
A21: BOSS_DAMAGE % | B21: =INDEX($C$21:$L$21,MATCH($B$4,$C$2:$L$2,0)) | C21: 0 | D21: 0 | E21: 0 | F21: 0 | G21: 0 | H21: 0 | I21: 0 | J21: 0 | K21: 0 | L21: 0 | N21: Fire Flower
A22: NORMAL_DAMAGE % | B22: =INDEX($C$22:$L$22,MATCH($B$4,$C$2:$L$2,0)) | C22: 0 | D22: 0 | E22: 0 | F22: 0 | G22: 0 | H22: 0 | I22: 0 | J22: 0 | K22: 0 | L22: 0 | N22: Soul Contract
A23: MIN_DAMAGE % | B23: =INDEX($C$23:$L$23,MATCH($B$4,$C$2:$L$2,0)) | C23: 100 | D23: 100 | E23: 100 | F23: 100 | G23: 100 | H23: 100 | I23: 100 | J23: 100 | K23: 100 | L23: 100 | N23: Lit Lamp
A24: MAX_DAMAGE % | B24: =INDEX($C$24:$L$24,MATCH($B$4,$C$2:$L$2,0)) | C24: 100 | D24: 100 | E24: 100 | F24: 100 | G24: 100 | H24: 100 | I24: 100 | J24: 100 | K24: 100 | L24: 100 | N24: Soul Pouch
A25: FINAL_DAMAGE % (base) | B25: =INDEX($C$25:$L$25,MATCH($B$4,$C$2:$L$2,0)) | C25: 0 | D25: 0 | E25: 0 | F25: 0 | G25: 0 | H25: 0 | I25: 0 | J25: 0 | K25: 0 | L25: 0 | N25: Ancient Text Piece
A26: Skill Level Bonus — 1st Job | B26: =INDEX($C$26:$L$26,MATCH($B$4,$C$2:$L$2,0)) | C26: 0 | D26: 0 | E26: 0 | F26: 0 | G26: 0 | H26: 0 | I26: 0 | J26: 0 | K26: 0 | L26: 0 | N26: Icy Soul Rock
A27: Skill Level Bonus — 2nd Job | B27: =INDEX($C$27:$L$27,MATCH($B$4,$C$2:$L$2,0)) | C27: 0 | D27: 0 | E27: 0 | F27: 0 | G27: 0 | H27: 0 | I27: 0 | J27: 0 | K27: 0 | L27: 0 | N27: Flaming Lava
A28: Skill Level Bonus — 3rd Job | B28: =INDEX($C$28:$L$28,MATCH($B$4,$C$2:$L$2,0)) | C28: 0 | D28: 0 | E28: 0 | F28: 0 | G28: 0 | H28: 0 | I28: 0 | J28: 0 | K28: 0 | L28: 0 | N28: Sayram's Necklace
A29: Skill Level Bonus — 4th Job | B29: =INDEX($C$29:$L$29,MATCH($B$4,$C$2:$L$2,0)) | C29: 0 | D29: 0 | E29: 0 | F29: 0 | G29: 0 | H29: 0 | I29: 0 | J29: 0 | K29: 0 | L29: 0 | N29: Bottle of Emotion
A30: Skill Level Bonus — All Skills | B30: =INDEX($C$30:$L$30,MATCH($B$4,$C$2:$L$2,0)) | C30: 0 | D30: 0 | E30: 0 | F30: 0 | G30: 0 | H30: 0 | I30: 0 | J30: 0 | K30: 0 | L30: 0 | N30: Peach Tree Herb Pouch
N31: Candle
A32: Additional Bonuses | N32: Alliance Badge
A33: Skill Cooldown Decrease (seconds; applies to every cooldown — skills, buffs and passives) | B33: =INDEX($C$33:$L$33,MATCH($B$4,$C$2:$L$2,0)) | C33: 0 | D33: 0 | E33: 0 | F33: 0 | G33: 0 | H33: 0 | I33: 0 | J33: 0 | K33: 0 | L33: 0 | N33: Horn Flute
A34: Basic Attack Target Increase (flat, adds to the 6-target normal-monster base) | B34: =INDEX($C$34:$L$34,MATCH($B$4,$C$2:$L$2,0)) | C34: 1 | D34: 1 | E34: 1 | F34: 1 | G34: 1 | H34: 1 | I34: 1 | J34: 1 | K34: 1 | L34: 1 | N34: Cursed Doll
A35: Buff Duration Increase % | B35: =INDEX($C$35:$L$35,MATCH($B$4,$C$2:$L$2,0)) | C35: 0 | D35: 0 | E35: 0 | F35: 0 | G35: 0 | H35: 0 | I35: 0 | J35: 0 | K35: 0 | L35: 0 | N35: Reindeer's Spear
A36: Companion Summoning Time Increase % (companions not modeled — always 0 DPS impact) | B36: =INDEX($C$36:$L$36,MATCH($B$4,$C$2:$L$2,0)) | C36: 0 | D36: 0 | E36: 0 | F36: 0 | G36: 0 | H36: 0 | I36: 0 | J36: 0 | K36: 0 | L36: 0 | N36: Secret Map
A37: Boss/Normal Emphasis (Breakthrough/Hero Dungeon only) | B37: =INDEX($C$37:$L$37,MATCH($B$4,$C$2:$L$2,0)) | D37: A Little More Normal | J37: A Little More Normal | N37: Ring of Cycles
A38: Max Enemies Actually In Range (normal-monster content only; default 999 = uncapped) | B38: =INDEX($C$38:$L$38,MATCH($B$4,$C$2:$L$2,0)) | D38: 999 | F38: 999 | G38: 999 | J38: 999 | L38: 999
A39: Monster Type (auto-computed from Content Type) — computed, do not edit | B39: =IF(Inputs!$B$4="PvP","pvp",IF(OR(Inputs!$B$4="Breakthrough",Inputs!$B$4="Hero Dungeon"),"breakthrough",IF(OR(Inputs!$B$4="EXP Dungeon",Inputs!$B$4="Equipment Dungeon",Inputs!$B$4="Chapter Hunt"),"normal","boss")))
A40: Chapter (parsed from Chapter-Stage) — computed, do not edit | B40: =IFERROR(IF(ISNUMBER(FIND("-",Inputs!$B$5)),VALUE(LEFT(Inputs!$B$5,FIND("-",Inputs!$B$5)-1)),VALUE(Inputs!$B$5)),28)
...

Sheet FactorTable
A1: Level | B1: F0 | C1: F1 | D1: F2 | E1: F3 | F1: F4 | G1: F5 | H1: F6 | I1: F7 | J1: F8 | K1: F9 | L1: F10 | M1: F11 | N1: F12 | O1: F13 | P1: F14 | Q1: F15 | R1: F16 | S1: F17 | T1: F18 | U1: F19 | V1: F20 | W1: F21 | X1: F22 | Y1: F23
A2: 1 | B2: 0 | C2: 1000 | D2: 1000 | E2: 1000 | F2: 1000 | G2: 1000 | H2: 1000 | I2: 1000 | J2: 1000 | K2: 1000 | L2: 1000 | M2: 1000 | N2: 1000 | O2: 1000 | P2: 1000 | Q2: 1000 | R2: 1000 | S2: 1000 | T2: 1000 | U2: 1000 | V2: 1000 | W2: 1000 | X2: 1000 | Y2: 1000
A3: 2 | B3: 0 | C3: 1015 | D3: 1020 | E3: 1030 | F3: 1040 | G3: 1050 | H3: 1060 | I3: 1070 | J3: 1020 | K3: 1020 | L3: 1020 | M3: 1000 | N3: 1010 | O3: 1020 | P3: 1030 | Q3: 1040 | R3: 1050 | S3: 1060 | T3: 1070 | U3: 1080 | V3: 1010 | W3: 1008 | X3: 1006 | Y3: 1100
A4: 3 | B4: 0 | C4: 1031 | D4: 1041 | E4: 1061 | F4: 1082 | G4: 1103 | H4: 1124 | I4: 1145 | J4: 1030 | K4: 1041 | L4: 1030 | M4: 1000 | N4: 1015 | O4: 1030 | P4: 1045 | Q4: 1060 | R4: 1075 | S4: 1090 | T4: 1105 | U4: 1120 | V4: 1020 | W4: 1012 | X4: 1009 | Y4: 1150
A5: 4 | B5: 0 | C5: 1047 | D5: 1062 | E5: 1093 | F5: 1126 | G5: 1159 | H5: 1192 | I5: 1226 | J5: 1040 | K5: 1062 | L5: 1040 | M5: 1000 | N5: 1020 | O5: 1040 | P5: 1060 | Q5: 1080 | R5: 1100 | S5: 1120 | T5: 1140 | U5: 1160 | V5: 1030 | W5: 1016 | X5: 1012 | Y5: 1200
A6: 5 | B6: 0 | C6: 1063 | D6: 1084 | E6: 1126 | F6: 1172 | G6: 1217 | H6: 1264 | I6: 1312 | J6: 1050 | K6: 1084 | L6: 1050 | M6: 1000 | N6: 1025 | O6: 1050 | P6: 1075 | Q6: 1100 | R6: 1125 | S6: 1150 | T6: 1175 | U6: 1200 | V6: 1040 | W6: 1020 | X6: 1015 | Y6: 1250
A7: 6 | B7: 0 | C7: 1079 | D7: 1106 | E7: 1160 | F7: 1219 | G7: 1278 | H7: 1340 | I7: 1404 | J7: 1060 | K7: 1106 | L7: 1060 | M7: 1000 | N7: 1030 | O7: 1060 | P7: 1090 | Q7: 1120 | R7: 1150 | S7: 1180 | T7: 1210 | U7: 1240 | V7: 1050 | W7: 1024 | X7: 1018 | Y7: 1300
A8: 7 | B8: 0 | C8: 1096 | D8: 1129 | E8: 1195 | F8: 1268 | G8: 1342 | H8: 1421 | I8: 1503 | J8: 1070 | K8: 1129 | L8: 1070 | M8: 1000 | N8: 1035 | O8: 1070 | P8: 1105 | Q8: 1140 | R8: 1175 | S8: 1210 | T8: 1245 | U8: 1280 | V8: 1060 | W8: 1028 | X8: 1021 | Y8: 1350
A9: 8 | B9: 0 | C9: 1113 | D9: 1152 | E9: 1231 | F9: 1319 | G9: 1410 | H9: 1507 | I9: 1609 | J9: 1080 | K9: 1152 | L9: 1080 | M9: 1000 | N9: 1040 | O9: 1080 | P9: 1120 | Q9: 1160 | R9: 1200 | S9: 1240 | T9: 1280 | U9: 1320 | V9: 1070 | W9: 1032 | X9: 1024 | Y9: 1400
A10: 9 | B10: 0 | C10: 1130 | D10: 1176 | E10: 1268 | F10: 1372 | G10: 1481 | H10: 1598 | I10: 1722 | J10: 1090 | K10: 1176 | L10: 1090 | M10: 1000 | N10: 1045 | O10: 1090 | P10: 1135 | Q10: 1180 | R10: 1225 | S10: 1270 | T10: 1315 | U10: 1360 | V10: 1080 | W10: 1036 | X10: 1027 | Y10: 1450
A11: 10 | B11: 0 | C11: 1147 | D11: 1200 | E11: 1307 | F11: 1427 | G11: 1556 | H11: 1694 | I11: 1843 | J11: 1100 | K11: 1200 | L11: 1100 | M11: 1000 | N11: 1050 | O11: 1100 | P11: 1150 | Q11: 1200 | R11: 1250 | S11: 1300 | T11: 1350 | U11: 1400 | V11: 1090 | W11: 1040 | X11: 1030 | Y11: 1500
A12: 11 | B12: 0 | C12: 1165 | D12: 1224 | E12: 1347 | F12: 1485 | G12: 1634 | H12: 1796 | I12: 1973 | J12: 1110 | K12: 1224 | L12: 1110 | M12: 1000 | N12: 1055 | O12: 1110 | P12: 1165 | Q12: 1220 | R12: 1275 | S12: 1330 | T12: 1385 | U12: 1440 | V12: 1100 | W12: 1044 | X12: 1033 | Y12: 1550
A13: 12 | B13: 0 | C13: 1183 | D13: 1249 | E13: 1388 | F13: 1545 | G13: 1716 | H13: 1904 | I13: 2112 | J13: 1120 | K13: 1249 | L13: 1120 | M13: 1000 | N13: 1060 | O13: 1120 | P13: 1180 | Q13: 1240 | R13: 1300 | S13: 1360 | T13: 1420 | U13: 1480 | V13: 1110 | W13: 1048 | X13: 1036 | Y13: 1600
... A301: 300 | B301: 0 | C301: 88573 | D301: 381637 | E301: 6991522 | F301: 125363453 | G301: 2185120762 | H301: 37157073039 | I301: 614631863830 | J301: 2000 | K301: 53326 | L301: 2500 | M301: 1100 | N301: 2500 | O301: 4000 | P301: 5500 | Q301: 7000 | R301: 8500 | S301: 10000 | T301: 11500 | U301: 13000 | V301: 7558 | W301: 2200 | X301: 1900 | Y301: 8800

Sheet Skills
A1: Key | B1: Name | C1: JobStep | D1: Cooldown(s) | E1: CostsActionSlot | F1: ActionsPerCast | G1: HitsPerCast | H1: ICD(s) | I1: ActiveWindow(s) | J1: ProcChance% | K1: RollsPerCast | L1: BaseDamage(tenths%) | M1: FactorIndex | N1: ScalesWithLevel | O1: SkillMasteryBonus% | P1: MasteryBossDamage% | Q1: MasteryNormalDamage% | R1: NormalMonsterTargets | S1: BuffTargetStat | T1: BuffDuration(s) | U1: MapleHeroBase(tenths%) | V1: MapleHeroFactorIndex | W1: Note
A2: DARK_IMPALE | B2: Dark Impale | C2: 4 | E2: FALSE | F2: 1 | G2: =IF(Inputs!$B$3>=136,6,5) | H2: 0 | I2: 0 | J2: 100 | K2: 1 | L2: 2900 | M2: 21 | N2: TRUE | O2: =Calc!F3*IF(Calc!C3=TRUE,1,0)/100*(1+Calc!F4*IF(Calc!C4=TRUE,1,0)/100)*25+SUMPRODUCT((Inputs!$B$3>={102,106,116,120,128,132})*{10,11,12,13,14,15}) | P2: =SUMPRODUCT((Inputs!$B$3>={111,124})*{10,10}) | Q2: 0 | R2: =6+Inputs!$B$34 | T2: 0 | W2: 4th-job basic-attack effect (supersedes Slash Blast/Spear Sweep/La Mancha Spear, confirmed identical wiki wording — 290% damage to 6 target(s) in front 5 time(s) — to every other class's own 4th-job basic attack). factorIndex 21, baseDamage 2900 tenths%. HitsPerCast=5, bumping to 6 once Mastery Lv.136 'Dark Impale - Strike' unlocks (same level as Hero's own equivalent, confirmed independently from Dark Knight/Mastery). SkillMasteryBonus% is Final Attack + Advanced Final Attack's own combined steady-state contribution (same folding mechanism as Hero's own Raging Blow) PLUS the real Dark Impale - Damage mastery chain (102/106/116/120/128/132, cumulative +10/11/12/13/14/15% — summed as DELTAS, not the raw displayed values). MasteryBossDamage% is the real 2-tier Dark Impale - Boss Monster Damage chain (111/124, +10% each, +20% total).
A3: FINAL_ATTACK_HELPER | B3: Final Attack (helper) | C3: 2 | E3: FALSE | F3: 1 | G3: 1 | H3: 0 | I3: 0 | J3: 100 | K3: 1 | L3: 350 | M3: 21 | N3: TRUE | O3: =SUMPRODUCT((Inputs!$B$3>={54})*{50}) | P3: 0 | Q3: 0 | R3: 0 | T3: 0 | W3: AUDIT 2026-10-21: Dark Knight DOES have 'Final Attack - Damage' +50% at Lv54 (wiki Mastery rows + site) - the statement below that the tier is absent was wrong. Helper row only — feeds Dark Impale's own coefficient. 25% chance, 35%->49% additional damage (levels 1-100), factorIndex 21/baseDamage 350 tenths% — resolves to the IDENTICAL tuple Hero's/Bowmaster's own Final Attack helper uses, confirming this is genuinely the same cross-tree shared skill. Unlike Hero, Dark Knight's own Mastery table has NO 'Final Attack - Damage' tier at all (confirmed absent) — SkillMasteryBonus% stays 0 here.
A4: ADVANCED_FINAL_ATTACK_HELPER | B4: Advanced Final Attack (helper) | C4: 4 | E4: FALSE | F4: 1 | G4: 1 | H4: 0 | I4: 0 | J4: 100 | K4: 1 | L4: 5000 | M4: 21 | N4: TRUE | O4: =SUMPRODUCT((Inputs!$B$3>={113})*{50}) | P4: 0 | Q4: 0 | R4: 0 | T4: 0 | W4: Helper row only — feeds Dark Impale's own coefficient (Final Attack's own Final Damage bonus). +500%->900% FD (levels 1-200), factorIndex 21/baseDamage 5000 tenths% — resolves to the IDENTICAL tuple Hero's/Bowmaster's own Advanced Final Attack helper uses. Mastery Lv.113 'Advanced Final Attack - Enhance' +50% (real SkillMasteryBonus%, same level as Hero's own).
A5: MAGIC_CRASH | B5: Magic Crash | C5: 4 | D5: 28 | E5: TRUE | F5: 1 | G5: 1 | H5: 0 | I5: 0 | J5: 100 | K5: 1 | L5: 48000 | M5: 12 | N5: TRUE | O5: 0 | P5: 0 | Q5: 0 | R5: =5+IF(Inputs!$B$3>=100,4,0) | T5: 0 | W5: AUDIT 2026-10-21: Lv126 'Magic Crash - Weaken' is +10% damage taken (site + game table; the wiki said 15%) for 15s on struck targets - now a global duty-cycled Monster-Damage-Taken term (all hits benefit), no longer folded into this row's own buckets. Summons a rock at the target's location, removing 1 buff and dealing 4800%->9600% damage to 5 nearby target(s), 1 time. factorIndex 12, baseDamage 48000 tenths% — resolves to the IDENTICAL tuple Hero's own Magic Crash uses (shared verbatim, single wiki page, /w/Magic_Crash). PATCHED: targets 5->9 (effect range +50% not modeled, no such mechanic exists). Mastery Lv.126 'Magic Crash - Weaken' (+15% damage taken to struck targets) baked into SkillMasteryBonus%/MasteryBossDamage%/MasteryNormalDamage% alike (a real mastery Hero's own build happened to miss on its own Magic Crash row — not fixed there, out of scope for this fork).
A6: GUNGNIRS_DESCENT | B6: Gungnir's Descent | C6: 4 | D6: 13 | E6: TRUE | F6: 1 | G6: =IF(Inputs!$B$3>=134,6,2) | H6: 0 | I6: 0 | J6: 100 | K6: 1 | L6: =IF(Inputs!$B$3>=134,9000,18000) | M6: 12 | N6: TRUE | O6: =SUMPRODUCT((Inputs!$B$3>={108})*{50}) | P6: 0 | Q6: 0 | R6: 1 | T6: 0 | W6: AUDIT 2026-10-21: Mastery Lv108 'Gungnir's Descent - Damage' +50% added (was missing). Throws a mythical spear at the target to deal 1800%->3600% damage, 2 times. factorIndex 12, baseDamage 18000 tenths%, 13s cooldown. Single-target (NormalMonsterTargets=1). Mastery Lv.134 'Gungnir's Descent - Strike' ('base damage -50%, +4 strike count') is modeled directly as a level-gated rebalance of this row's own BaseDamage (18000->9000 tenths%) and HitsPerCast (2->6) once Lv.134 unlocks — net +50% total damage (6*0.5 vs 2*1.0), same 'flip two fields at a level threshold' pattern already used elsewhere in this project for Strike-mastery hit-count bumps, just applied to both BaseDamage and HitsPerCast simultaneously instead of HitsPerCast alone. An earlier version of this row left this mastery completely unmodeled, documented as an under-estimate at high level — fixed.
A7: EVIL_EYE_SHOCK | B7: Evil Eye Shock | C7: 2 | D7: 18 | E7: TRUE | F7: 1 | G7: 6 | H7: 0 | I7: 0 | J7: 100 | K7: 1 | L7: 700 | M7: 12 | N7: TRUE | O7: =SUMPRODUCT((Inputs!$B$3>={44})*{50})+IF(Inputs!$B$3>=75,Calc!F8*IF(Calc!C8=TRUE,1,0),0) | P7: 0 | Q7: 0 | R7: =6+IF(Inputs!$B$3>=75,3,0) | T7: 0 | U7: 400 | V7: 23 | W7: [Must Summon Evil Eye — precondition not modeled as a live gate, treated as always-castable once unlocked] The Evil Eye attacks 6 (then 9 once Lv.75's Evil Eye Shock Enhancement unlocks) nearby target(s), dealing 70%->105% damage (levels 1-100, 2nd-job capped), 6 times, 18s cooldown, stun 1.5s not modeled. factorIndex 12, baseDamage 700 tenths%. Mastery Lv.44 'Evil Eye Shock - Damage' +50% real. Evil Eye Shock Enhancement's own +100%->127% Final Damage curve is folded directly into this row's own SkillMasteryBonus% as an additive coefficient bonus (a documented approximation — true Final Damage multiplies after the crit/defense pipeline, this applies it pre-pipeline instead — same simplification tier as folding Final Attack's own proc into a basic attack's coefficient elsewhere in this project). Maple Hero target (0.75x share) — see MAPLE_HERO_RATIOS.
A8: EVIL_EYE_SHOCK_ENH | B8: Evil Eye Shock Enhancement (helper) | C8: 3 | E8: FALSE | F8: 1 | G8: 1 | H8: 0 | I8: 0 | J8: 100 | K8: 1 | L8: 1000 | M8: 22 | N8: TRUE | O8: 0 | P8: 0 | Q8: 0 | R8: 0 | T8: 0 | W8: Helper row only (no independent O-column DPS) — feeds Evil Eye Shock's own K-column extra Final Damage term (target-count bump baked directly into EVIL_EYE_SHOCK's own NormalMonsterTargets formula instead). 'Target count changes to 9, Final Damage +100%->127%' (levels 1-100, own curve). factorIndex 22, baseDamage 1000 tenths%.
A9: EVIL_EYE_OF_DOMINANT | B9: Evil Eye of Dominant | C9: 3 | D9: =IF(Inputs!$B$3>=104,30*0.7,30) | E9: FALSE | F9: 1 | G9: 1 | H9: 1 | I9: 20 | J9: 100 | K9: 1 | L9: 600 | M9: 21 | N9: TRUE | O9: =SUMPRODUCT((Inputs!$B$3>={78})*{50}) | P9: 0 | Q9: 0 | R9: =6+IF(Inputs!$B$3>=94,3,0) | T9: 0 | U9: 400 | V9: 23 | W9: [Must Summon Evil Eye] Background DoT tied to Evil Eye's own cast cycle (CostsActionSlot=False, Cooldown=30s/ActiveWindow=20s matching Evil Eye's own duration, ICD=1s — EffectiveHits = ActiveWindow/ICD = 20 ticks/cast, same FP-Mage Poison-Mist-DoT-tied-to-a-parent-skill pattern): 'deals 60%->84% continuous damage to 6 nearby targets every 1 sec' (levels 1-200). factorIndex 21, baseDamage 600 tenths%. Mastery Lv.78 'Evil Eye of Dominant - Damage' +50% and Lv.94 'Evil Eye of Dominant - Target' +3 (6->9) both real. Maple Hero target (1x share, biggest) — see MAPLE_HERO_RATIOS.
A10: REVENGE_OF_THE_EVIL_EYE | B10: Revenge of the Evil Eye | C10: 4 | D10: 5 | E10: FALSE | F10: 1 | G10: 2 | H10: 0 | I10: 0 | J10: 100 | K10: 1 | L10: 8500 | M10: 12 | N10: TRUE | O10: =SUMPRODUCT((Inputs!$B$3>={122})*{50})+IF(Inputs!$B$3>=138,2200*(Calc!E10/1000),0) | P10: 0 | Q10: 0 | R10: 1 | T10: 0 | W10: [Must Summon Evil Eye] Self-triggered proc-shaped row (Cooldown=5s, CostsActionSlot=False — same treatment as Marksman's own Bolt Surplus): 'engraves a vengeful brand dealing 850%->1700% additional damage, 2 times' (levels 1-200). factorIndex 12, baseDamage 8500 tenths%. Mastery Lv.122 'Revenge of the Evil Eye - Damage' +50% real. Mastery Lv.138 'Spectral Shadows' is a raw unevaluated wikitext formula on the live wiki page ({{#expr:2200*(1+x*0.005)}}%) — resolved via the same curve-matching method already used for Marksman's own Snipe-Empowered mastery this session (sample the formula at several levels treating x=character level, match against the 24-column factor table): resolves cleanly to factorIndex 12/baseDamage 2200 tenths% (0.44% max deviation) — since it shares the SAME factorIndex as this row's own base curve, it reuses this row's own Calc!E factor lookup directly rather than needing a separate FactorTable lookup (same trick as Snipe's own Empowered mastery).
A11: MAPLE_HERO_HELPER | B11: Maple Hero (helper) | C11: 4 | E11: FALSE | F11: 1 | G11: 1 | H11: 0 | I11: 0 | J11: 100 | K11: 1 | L11: 400 | M11: 23 | N11: TRUE | O11: 0 | P11: 0 | Q11: 0 | R11: 0 | T11: 0 | W11: Shared ratio-feeder row (see MAPLE_HERO_RATIOS) for Evil Eye of Dominant/Rush/Evil Eye Shock's own Final Damage chains — mirrors Hero/Shadower/Bowmaster's own Maple Hero mechanism. Confirmed via idle.maplestorywiki.net/w/Maple_Hero_(Dark_Knight) (full level 1-200 curve, resolves cleanly to factorIndex 23/baseDamage 400 tenths%, 0% residual, same '80%-growth-reduction after Lv.120' kink already confirmed on Hero/Bowmaster's own Maple Hero curves). No independent DPS row of its own (Calc columns J-N blank/0, only D/E/F computed, read directly by each target row's own K-column formula).
A12: RUSH | B12: Rush | C12: 3 | D12: =IF(Inputs!$B$3>=90,22*0.7,22) | E12: TRUE | F12: 1 | G12: 1 | H12: 0 | I12: 0 | J12: 100 | K12: 1 | L12: 6000 | M12: 12 | N12: TRUE | O12: =SUMPRODUCT((Inputs!$B$3>={68})*{80}) | P12: 0 | Q12: 0 | R12: 12 | T12: 0 | U12: 300 | V12: 23 | W12: AUDIT 2026-10-21: previously-missing masteries added: Damage +80% @68, Reuse -30% cooldown @90. Charges to the front to deal 600%->1200% damage to 12 target(s) (stun 2.5s not modeled). factorIndex 12, baseDamage 6000 tenths%, 22s cooldown — resolves to the IDENTICAL tuple Hero's own Rush uses (shared verbatim, confirmed identical wiki page). Not patched (Mastery Lv.68/90 own damage/cooldown tiers not separately modeled here, same treatment as Hero's own Rush row — kept consistent for this genuinely shared skill). Maple Hero target (0.75x share) — see MAPLE_HERO_RATIOS.
A13: HEX_OF_THE_EVIL_EYE | B13: Hex of the Evil Eye | C13: 3 | D13: =IF(Inputs!$B$3>=104,30*0.7,30) | E13: FALSE | F13: 1 | G13: 1 | H13: 0 | I13: 0 | J13: 100 | K13: 1 | L13: 150 | M13: 22 | N13: TRUE | O13: =SUMPRODUCT((Inputs!$B$3>={98})*{50}) | P13: 0 | Q13: 0 | R13: 0 | S13: ATTACK | T13: 20 | W13: [Must Summon Evil Eye] Self-inclusive ally buff (matches Hero's own Spirit Blade / Bishop's own 'allied players' precedent), tied to Evil Eye's own duty cycle (Cooldown=30s/BuffDuration=20s matching Evil Eye's own): '+15%->18.6% Attack to allied players for the summoning duration' (levels 1-100, 3rd-job capped). factorIndex 22, baseDamage 150 tenths%. Mastery Lv.98 'Hex of the Evil Eye - Attack' +50% additionally, real. Lv.82's own '+20 Accuracy to allies' not modeled (no Accuracy mechanic exists).
A14: DARK_RESONANCE | B14: Dark Resonance | C14: 4 | D14: 32 | E14: TRUE | F14: 1 | G14: 1 | H14: 0 | I14: 0 | J14: 100 | K14: 1 | L14: 300 | M14: 21 | N14: TRUE | O14: 0 | P14: 0 | Q14: 0 | R14: 0 | S14: ATTACK | T14: =IF(Inputs!$B$3>=130,20*1.4,20) | W14: 'Unlocks the power of pure darkness to increase Attack by 30%->44.4% for 20s' (levels 1-200). factorIndex 21, baseDamage 300 tenths% (curve rescaled 300/240=1.25x from the pre-patch 8%-at-Lv1 baseline... actually: PATCHED level-1 Attack 30%->still 30% per the patch notes, own cooldown 35->32s — this row models the CURRENT/patched Attack% curve directly since the wiki's own level-1 value (30%) already matched the patch notes' stated Attack% exactly, only cooldown/boss-bonus needed patching). PATCHED: cooldown 35->32s (baked into Cooldown(s)), new '+20% boss monster damage while active' clause added — folded into the Global Monster Damage-Taken Bonus% bucket (boss-only via monster_blend_expr), duty-cycle averaged by this row's own uptime, alongside Evil Eye's own contribution (see Summary sheet). Mastery Lv.130 'Dark Resonance - Persistence' +40% duration (real, BuffDuration becomes 20*1.4=28s once unlocked).
A15: CROSS_OVER_CHAINS | B15: Cross Over Chains | C15: 3 | D15: 30 | E15: TRUE | F15: 1 | G15: 1 | H15: 0 | I15: 0 | J15: 100 | K15: 1 | L15: 150 | M15: 21 | N15: TRUE | O15: =SUMPRODUCT((Inputs!$B$3>={73})*{100}) | P15: 0 | Q15: 0 | R15: 0 | S15: ATTACK | T15: 15 | W15: 'Increases Attack by 15%->18.6% for 15 sec (levels 1-60, own curve). If current HP is 50% or lower, the Attack increase effect disappears and damage taken is decreased by 10%->12% instead' — modeled assuming steady-state HP>50% (Attack% component only; the HP<=50% swap-to-defensive branch not modeled, matches this project's general non-modeling of the character's own damage-taken). factorIndex 21, baseDamage 150 tenths%, 30s cooldown. Mastery Lv.73 'Cross Over Chains - Attack' +100% additionally (real, taken literally as +100 percentage points per this project's established additive-mastery convention).
A16: HYPER_BODY | B16: Hyper Body | C16: 2 | D16: 30 | E16: TRUE | F16: 1 | G16: 1 | H16: 0 | I16: 0 | J16: 100 | K16: 1 | L16: 120 | M16: 21 | N16: TRUE | O16: =SUMPRODUCT((Inputs!$B$3>={49})*{50}) | P16: 0 | Q16: 0 | R16: 0 | S16: ATTACK | T16: 15 | W16: 'Increases Attack by 12%->16.8% for 15 sec (levels 1-100, 2nd-job capped), and the Defense of allied players by 15%->21%' (Defense-of-allies component not modeled — no Defense mechanic exists). factorIndex 21, baseDamage 120 tenths%, 30s cooldown. Mastery Lv.49 'Hyper Body - Persistence' +50% duration (real, applied as a SkillMasteryBonus%-style percentage addition since this schema has no separate duration-mastery mechanism — treated as a documented approximation).
A17: EVIL_EYE | B17: Evil Eye | C17: 2 | D17: =IF(Inputs!$B$3>=104,30*0.7,30) | E17: TRUE | F17: 1 | G17: 1 | H17: 0 | I17: 0 | J17: 100 | K17: 1 | L17: 150 | M17: 21 | N17: TRUE | O17: =SUMPRODUCT((Inputs!$B$3>={39})*{10}) | P17: 0 | Q17: 0 | R17: 0 | S17: MONSTER_DMG | T17: 20 | W17: 'Summons Evil Eye. Evil Eye follows you for 20 sec and increases the damage taken by 6 nearby target(s) by 15%->19.2%' (levels 1-100, 2nd-job capped) — drives the Global Monster Damage-Taken Bonus% bucket (Hero's own Scaring-Sword-pioneered mechanism), duty-cycle averaged, no proc-chance gate (always-on while summoned, unlike Scaring Sword's proc). factorIndex 21, baseDamage 150 tenths%, 30s cooldown. Mastery Lv.39 'Evil Eye - Damage Taken' +10 percentage points, real, flat add once unlocked.
A18: LORD_OF_DARKNESS_CRITRATE | B18: Lord of Darkness (Crit Rate half) | C18: 3 | D18: 3 | E18: FALSE | F18: 1 | G18: 1 | H18: 0 | I18: 0 | J18: 30 | K18: 1 | L18: 100 | M18: 22 | N18: TRUE | O18: 0 | P18: 0 | Q18: 0 | R18: 0 | S18: CRIT_RATE | T18: 8 | W18: On-attack proc (30% chance, own internal cooldown) granting +Crit Rate/+Crit Damage for a duration (HP-recovery component not modeled) — split into two rows since this schema's BuffTargetStat column only holds one stat per row (same reason as Hero's own Enrage split). Modeled as ProcChance% x duty-cycle uptime (Scaring-Sword-style simplification), not an exact per-attack RNG state machine. PATCHED: duration 5->8s (baked into BuffDuration(s)), Crit Rate 8%->10% (curve rescaled 10/8=1.25x, giving the 100 stored here vs. the pre-patch curve's own 80), cooldown 2->3s (baked into Cooldown(s)).
A19: LORD_OF_DARKNESS_CRITDMG | B19: Lord of Darkness (Crit Damage half) | C19: 3 | D19: 3 | E19: FALSE | F19: 1 | G19: 1 | H19: 0 | I19: 0 | J19: 30 | K19: 1 | L19: 400 | M19: 22 | N19: TRUE | O19: 0 | P19: 0 | Q19: 0 | R19: 0 | S19: CRIT_DAMAGE | T19: 8 | W19: Crit Damage half of Lord of Darkness — same proc-chance/cooldown/duration as LORD_OF_DARKNESS_CRITRATE. PATCHED: Crit Damage 30%->40% (curve rescaled 40/30=1.3333x, giving the 400 stored here vs. the pre-patch curve's own 300).
A20: NIMBLE_FEET | B20: Nimble Feet | C20: 1 | D20: 60 | E20: TRUE | F20: 1 | G20: 1 | H20: 0 | I20: 0 | J20: 100 | K20: 1 | L20: 150 | M20: 0 | N20: FALSE | O20: 0 | P20: 0 | Q20: 0 | R20: 1 | S20: ATTACK_SPEED | T20: 15 | W20: Shared cross-tree verbatim w/ every class in this project (byte-identical wiki wording — '+15% Attack Speed, +10% Speed for 15 sec'). Flat +15% Attack Speed / +10% Speed for 15s, 60s cooldown, non-scaling. FactorIndex unused placeholder.
A21: WEAPON_ACCELERATION | B21: Weapon Acceleration | C21: 2 | E21: FALSE | F21: 1 | G21: 1 | H21: 0 | I21: 0 | J21: 100 | K21: 1 | L21: 50 | M21: 22 | N21: TRUE | O21: 0 | P21: 0 | Q21: 0 | R21: 0 | S21: ATTACK_SPEED | T21: 0 | W21: Magic Critical pattern — already baked into Inputs!ATTACK_SPEED%; feeds the 2nd-Job Skill Level Bonus delta. Reuses Hero's/Bowmaster's own tuple directly (shared-value-different-key, byte-identical wiki wording — '+5% Attack Speed'). factorIndex 22, baseDamage 50 tenths% (5%->6.5%, levels 1-100).
A22: WEAPON_MASTERY | B22: Weapon Mastery | C22: 2 | E22: FALSE | F22: 1 | G22: 1 | H22: 0 | I22: 0 | J22: 100 | K22: 1 | L22: 150 | M22: 22 | N22: TRUE | O22: 0 | P22: 0 | Q22: 0 | R22: 0 | S22: MIN_DAMAGE | T22: 0 | W22: Magic Critical pattern — already baked into Inputs!MIN_DAMAGE%; feeds the 2nd-Job Skill Level Bonus delta. factorIndex 22, baseDamage 150 tenths% (15%->19.5%, levels 1-100).
A23: BARRICADE_SKILL_DMG | B23: Barricade Mastery (Skill Damage) | C23: 4 | E23: FALSE | F23: 1 | G23: 1 | H23: 0 | I23: 0 | J23: 100 | K23: 1 | L23: 150 | M23: 22 | N23: TRUE | O23: 0 | P23: 0 | Q23: 0 | R23: 0 | S23: SKILL_DAMAGE | T23: 0 | W23: Magic Critical pattern — already baked into Inputs!SKILL_DAMAGE%; feeds the 4th-Job Skill Level Bonus delta (Skill Damage side). Same slot as Hero's own Combat Mastery, just renamed. factorIndex 22, baseDamage 150 tenths% (15%->21.3% at Lv140, own curve).
A24: BARRICADE_MAXDMG | B24: Barricade Mastery (Max Damage Multiplier) | C24: 4 | E24: FALSE | F24: 1 | G24: 1 | H24: 0 | I24: 0 | J24: 100 | K24: 1 | L24: 200 | M24: 22 | N24: TRUE | O24: 0 | P24: 0 | Q24: 0 | R24: 0 | S24: MAX_DAMAGE | T24: 0 | W24: Same skill as Barricade Mastery (Skill Damage) above, +20%->27.8% Max Damage Multiplier (at Lv140, own curve). Magic Critical pattern — already baked into Inputs!MAX_DAMAGE%; feeds the 4th-Job Skill Level Bonus delta (Max Damage Multiplier side). factorIndex 22, baseDamage 200 tenths%.
A25: POWER_STANCE_FD | B25: Power Stance (Final Damage) | C25: 4 | E25: FALSE | F25: 1 | G25: 1 | H25: 0 | I25: 0 | J25: 100 | K25: 1 | L25: 150 | M25: 22 | N25: TRUE | O25: 0 | P25: 0 | Q25: 0 | R25: 0 | S25: FINAL_DAMAGE | T25: 0 | W25: Own damage-taken-reduction component (5%->8%) not modeled (no such mechanic exists). Byte-identical wiki wording to Hero's own Power Stance — reuses that tuple directly. Magic Critical pattern — already baked into Inputs!FINAL_DAMAGE%; feeds the 4th-Job Skill Level Bonus delta. factorIndex 22, baseDamage 150 tenths% (15%->24%, levels 1-200).
A26: FINAL_PACT | B26: Final Pact | C26: 4 | E26: FALSE | F26: 1 | G26: 1 | H26: 0 | I26: 0 | J26: 100 | K26: 1 | L26: 100 | M26: 22 | N26: TRUE | O26: =SUMPRODUCT((Inputs!$B$3>={118})*{100}) | P26: 0 | Q26: 0 | R26: 0 | S26: FINAL_DAMAGE | T26: 0 | W26: 'Increases Final Damage by 10%->13% (levels 1-200, own curve). When HP falls below 1%, the Final Damage increase disappears and you become immune to damage for 2 sec (once per battle, prevents death)' — death-prevention mechanic not modeled. Magic Critical pattern — already baked into Inputs!FINAL_DAMAGE%; feeds the 4th-Job Skill Level Bonus delta (Sensitivity-only, same as every other Magic-Critical-pattern row). factorIndex 22, baseDamage 100 tenths%. Mastery Lv.118 'Final Pact - Recovery' +100% Final Damage boost (real, +100 percentage points, Sensitivity-delta only since the whole row is a passive assumed reflected in Inputs).

Sheet Artifacts
A1: Dark Knight — Artifacts (Equip Effect)
A3: Book of Ancient — Crit Damage (from Crit Rate, reference only) | B3: =IF(ArtifactsInput!$M$24,CHOOSE(ArtifactsInput!$N$24+1,30,36,42,48,54,60)/100*(Inputs!$B$10+Summary!$B$14+B5+B29),0)
A4: Ring of Cycles — Threshold Crit Rate (excl. self) | B4: =Inputs!$B$10+Summary!$B$14+B29
A5: Ring of Cycles — Crit Rate (if threshold < 100%) | B5: =IF(AND(Inputs!$B$39<>"pvp",Inputs!$B$44=0),1,IF(IF(Inputs!$B$39="pvp",15,Inputs!$B$44)-(Summary!$B$23)<=0,1,MAX(0,IF(Inputs!$B$39="pvp",15,Inputs!$B$44)-MAX(5,Summary!$B$23))/(IF(Inputs!$B$39="pvp",15,Inputs!$B$44)-(Summary!$B$23))))*IF(AND(ArtifactsInput!$M$42,B4<100),CHOOSE(ArtifactsInput!$N$42+1,30,36,42,48,54,60),0)
A6: Ring of Cycles — Skill Damage (if threshold >= 100%) | B6: =IF(AND(Inputs!$B$39<>"pvp",Inputs!$B$44=0),1,IF(IF(Inputs!$B$39="pvp",15,Inputs!$B$44)-(Summary!$B$23)<=0,1,MAX(0,IF(Inputs!$B$39="pvp",15,Inputs!$B$44)-MAX(5,Summary!$B$23))/(IF(Inputs!$B$39="pvp",15,Inputs!$B$44)-(Summary!$B$23))))*IF(AND(ArtifactsInput!$M$42,B4>=100),CHOOSE(ArtifactsInput!$N$42+1,40,48,56,64,72,80),0)
A7: Ring of Cycles — Excess-100% Points (capped at 100) | B7: =IF(AND(ArtifactsInput!$M$42,B4>=100),MIN(100,B4-100),0)
A8: Ring of Cycles — Basic Attack Damage (excess points x per-point) | B8: =IF(AND(Inputs!$B$39<>"pvp",Inputs!$B$44=0),1,IF(IF(Inputs!$B$39="pvp",15,Inputs!$B$44)-(Summary!$B$23)<=0,1,MAX(0,IF(Inputs!$B$39="pvp",15,Inputs!$B$44)-MAX(5,Summary!$B$23))/(IF(Inputs!$B$39="pvp",15,Inputs!$B$44)-(Summary!$B$23))))*B7*CHOOSE(ArtifactsInput!$N$42+1,0.6,0.72,0.84,0.96,1.08,1.2)
A9: Candle — Effective Fight Duration | B9: =IF(Inputs!$B$39="pvp",15,Inputs!$B$44)
A10: Candle — Effective Active (fixed-duration or PvP) | B10: =IF(Inputs!$B$39="pvp",TRUE,AND(Inputs!$B$39<>"pvp",Inputs!$B$44>0))
A11: Candle — Final Damage (100% uptime, patched) | B11: =IF(AND(ArtifactsInput!$M$36,B10),CHOOSE(ArtifactsInput!$N$36+1,8,9.6,11.2,12.8,14.4,16),0)
A12: Candle — Boss Monster Damage (20-40s window / boss-present-time uptime, patched) | B12: =IF(AND(ArtifactsInput!$M$36,B10),MAX(0,MIN(40,B9)-MAX(20,B41))/(B9-B41)*CHOOSE(ArtifactsInput!$N$36+1,30,36,42,48,54,60),0)
A13: Peach Tree Herb Pouch — Proc Rate (per second) | B13: =0.2*Summary!$B$17
A14: Peach Tree Herb Pouch — Uptime (refreshing 5s timer) | B14: =1-EXP(-B13*5)
A15: Peach Tree Herb Pouch — Enemy Damage Taken | B15: =IF(AND(ArtifactsInput!$M$35,Inputs!$B$4<>"Chapter Hunt"),CHOOSE(ArtifactsInput!$N$35+1,15,18,21,24,27,30)*B14,0)
A16: Silver Pendant — Offered Load (rho = lambda x duration) | B16: =0.15*Summary!$B$17*5
A17: Silver Pendant — Erlang Loss Weight (n=0) | B17: =B16^0/1
A18: Silver Pendant — Erlang Loss Weight (n=1) | B18: =B16^1/1
A19: Silver Pendant — Erlang Loss Weight (n=2) | B19: =B16^2/2
A20: Silver Pendant — Erlang Loss Weight (n=3) | B20: =B16^3/6
A21: Silver Pendant — Erlang Loss Weight (n=4) | B21: =B16^4/24
A22: Silver Pendant — Erlang Loss Weight (n=5) | B22: =B16^5/120
A23: Silver Pendant — Average Stacks (Erlang-loss mean) | B23: =(0*B17+1*B18+2*B19+3*B20+4*B21+5*B22)/(B17+B18+B19+B20+B21+B22)
A24: Silver Pendant — Enemy Damage Taken | B24: =IF(AND(ArtifactsInput!$M$22,Inputs!$B$4<>"Chapter Hunt"),CHOOSE(ArtifactsInput!$N$22+1,10,12,14,16,18,20)*B23,0)
A25: Athena Pierce's Old Gloves — Max Damage (from Attack Speed, reference only) | B25: =IF(ArtifactsInput!$M$15,CHOOSE(ArtifactsInput!$N$15+1,25,30,35,40,45,50)/100*Inputs!$B$12,0)
A26: Hexagon Necklace — Average Stacks | B26: =IF(AND(Inputs!$B$39<>"pvp",Inputs!$B$44=0),3,IF(IF(Inputs!$B$39="pvp",15,Inputs!$B$44)<=20,0,IF(IF(Inputs!$B$39="pvp",15,Inputs!$B$44)<=40,(IF(Inputs!$B$39="pvp",15,Inputs!$B$44)-20)/IF(Inputs!$B$39="pvp",15,Inputs!$B$44),IF(IF(Inputs!$B$39="pvp",15,Inputs!$B$44)<=60,(2*IF(Inputs!$B$39="pvp",15,Inputs!$B$44)-60)/IF(Inputs!$B$39="pvp",15,Inputs!$B$44),(3*IF(Inputs!$B$39="pvp",15,Inputs!$B$44)-120)/IF(Inputs!$B$39="pvp",15,Inputs!$B$44)))))
A27: Hexagon Necklace — Damage % | B27: =IF(ArtifactsInput!$M$11,CHOOSE(ArtifactsInput!$N$11+1,15,18,21,24,27,30)*B26,0)
A28: Rainbow-colored Snail Shell — Uptime (0-15s window) | B28: =IF(Inputs!$B$39="pvp",MIN(15,15)/15,IF(AND(Inputs!$B$39<>"pvp",Inputs!$B$44>0),MIN(15,Inputs!$B$44)/Inputs!$B$44,0))
A29: Rainbow-colored Snail Shell — Crit Rate | B29: =IF(ArtifactsInput!$M$10,CHOOSE(ArtifactsInput!$N$10+1,15,18,21,24,27,30)*B28,0)
A30: Rainbow-colored Snail Shell — Crit Damage | B30: =IF(ArtifactsInput!$M$10,CHOOSE(ArtifactsInput!$N$10+1,20,24,28,32,36,40)*B28,0)
A32: TOTAL — Artifact Crit Rate Bonus | B32: =B5+B29
A33: TOTAL — Artifact Crit Damage Bonus | B33: =B30+B47
A34: TOTAL — Artifact Final Damage Bonus (equivalent %, each real source combines MULTIPLICATIVELY — Candle x Flaming Lava x Horn Flute, not summed) | B34: =((1+B11/100)*(1+B46/100)*(1+B55/100)-1)*100
A35: TOTAL — Artifact Boss Monster Damage Bonus | B35: =B12+B60
A36: TOTAL — Artifact Enemy Damage Taken Bonus | B36: =B15+B24
A38: TOTAL — Artifact Damage Bonus (own separate final multiplier, like Magic Guard/Meditation's Average Buff Multiplier — not blended into Inputs!DAMAGE%) | B38: =B27
A39: TOTAL — Artifact Skill Damage Bonus | B39: =B6
A40: TOTAL — Artifact Basic Attack Damage Bonus | B40: =B8
A41: Candle — Boss Appear Time (Breakthrough/Hero Dungeon only) | B41: =IF(Inputs!$B$4="Breakthrough",20,IF(Inputs!$B$4="Hero Dungeon",30,0))
A42: Clear Spring Water — Final Damage (reference only, Growth Dungeon types) | B42: =IF(AND(ArtifactsInput!$M$14,OR(Inputs!$B$4="Weapon Dungeon",Inputs!$B$4="Equipment Dungeon",Inputs!$B$4="Enhancement Dungeon",Inputs!$B$4="EXP Dungeon",Inputs!$B$4="Hero Dungeon")),CHOOSE(ArtifactsInput!$N$14+1,10,12,14,16,18,20),0)
A43: Old Music Box — Attack % (content-type uptime assumption) | B43: =IF(ArtifactsInput!$M$21,CHOOSE(ArtifactsInput!$N$21+1,25,30,35,40,45,50)*(IF(OR(Inputs!$B$4="Chapter Hunt",Inputs!$B$4="Breakthrough",Inputs!$B$4="Weapon Dungeon",Inputs!$B$4="Equipment Dungeon",Inputs!$B$4="Enhancement Dungeon",Inputs!$B$4="EXP Dungeon",Inputs!$B$4="Hero Dungeon"),0,IF(OR(Inputs!$B$4="World Boss",Inputs!$B$4="PvP"),1,IF(Inputs!$B$4="Chapter Boss",60/70,0)))),0)
...

Sheet Calc
A1: Key | B1: Name | C1: Unlocked | D1: InputLevel | E1: Factor | F1: CoefficientPercent | G1: EffectiveHits | H1: ProcProbability | I1: MapleHeroMultiplier | J1: BaseDamage | K1: BaseHitDamage | L1: NonCritAvg | M1: CritAvg | N1: ExpectedDamage(perHit) | O1: DPS | P1: % of Total | Q1: InvCooldown | R1: CastsInFight | S1: HitRate(perSec) | T1: BossOnlyDPS | V1: NormalOnlyDPS
A2: =Skills!A2 | B2: =Skills!B2 | C2: =Inputs!$B$3>=100 | F2: =Summary!$B$10+Skills!O2 | G2: =Skills!G2*IF(Skills!H2>0,INT(IF(Inputs!$B$39="pvp",MIN(Skills!I2,15),Skills!I2)/Skills!H2+0.000000001),1) | H2: =1-(1-Skills!J2/100)^Skills!K2 | I2: 1 | J2: =Summary!$B$6*(F2/100) | K2: =J2*(1+Summary!$B$7/100)*(1+Inputs!$B$16/100)*(1+Inputs!$B$17/100)*(5000/(6000+Inputs!$B$43*(1-Inputs!$B$20/100)))*(1+(Inputs!$B$25+Summary!$B$21)/100)*(1+Artifacts!$B$34/100)*(1+(IF(Skills!A2="DARK_IMPALE",Inputs!$B$18+Artifacts!$B$40,Inputs!$B$19+Artifacts!$B$39))/100)*(Summary!$B$13*(1+Artifacts!$B$38/100)*I2) | L2: =K2*(MIN(Inputs!$B$23,Inputs!$B$24)/100+Inputs!$B$24/100)/2 | M2: =L2*(1+(Inputs!$B$11+Summary!$B$20+Artifacts!$B$33)/100) | N2: =L2*(1-MIN((Inputs!$B$10+Summary!$B$14+Artifacts!$B$32),100)/100)+M2*(MIN((Inputs!$B$10+Summary!$B$14+Artifacts!$B$32),100)/100) | O2: =(1-Summary!$B$11)*T2+Summary!$B$11*V2 | P2: =IF(Summary!$B$3=0,0,O2/Summary!$B$3) | Q2: 0 | R2: 0 | S2: =IFERROR(O2/N2,0) | T2: =IF(C2,(Skills!G2*N2*Summary!$B$19)*IF(Inputs!$B$39="pvp",1,1+(Inputs!$B$21+Skills!P2+Summary!$B$15+Artifacts!$B$35)/100)*((((5000/(6000+Inputs!$B$43*(1-(100*(1-(1-Inputs!$B$20/100)*(1-Artifacts!$B$51/100)^IF(Inputs!$B$39="pvp",1,2)))/100)))/(5000/(6000+Inputs!$B$43*(1-Inputs!$B$20/100))))*((L2*(1-MIN(100,(Inputs!$B$10+Summary!$B$14+Artifacts!$B$32)+Artifacts!$B$69)/100)+M2*(MIN(100,(Inputs!$B$10+Summary!$B$14+Artifacts!$B$32)+Artifacts!$B$69)/100))/(L2*(1-MIN(100,(Inputs!$B$10+Summary!$B$14+Artifacts!$B$32))/100)+M2*(MIN(100,(Inputs!$B$10+Summary!$B$14+Artifacts!$B$32))/100)))*(1+Artifacts!$B$81/100))),0) | V2: =IF(C2,(Skills!G2*N2*Summary!$B$19)*IF(Inputs!$B$39="pvp",1,(1+(Inputs!$B$22+Skills!Q2+Summary!$B$15+Artifacts!$B$80)/100)*(MIN(Skills!R2,Inputs!$B$38)))*((1+Artifacts!$B$53/100)),0)
A3: =Skills!A3 | B3: =Skills!B3 | C3: =Inputs!$B$3>=50 | D3: =IF(Skills!C3=1,60+Inputs!$B$26+Inputs!$B$30,IF(Skills!C3=2,90+Inputs!$B$27+Inputs!$B$30,IF(Skills!C3=3,120+Inputs!$B$28+Inputs!$B$30,MAX(0,(Inputs!$B$3-100)*3)+Inputs!$B$29+Inputs!$B$30))) | E3: =INDEX(FactorTable!$B$2:$Y$301, MATCH(ROUND(MIN(300,MAX(1,D3)),0), FactorTable!$A$2:$A$301,0), Skills!M3+1) | F3: =IF(Skills!N3=TRUE,(Skills!L3/10)*(E3/1000),Skills!L3/10)+Skills!O3 | I3: 1
A4: =Skills!A4 | B4: =Skills!B4 | C4: =Inputs!$B$3>=105 | D4: =IF(Skills!C4=1,60+Inputs!$B$26+Inputs!$B$30,IF(Skills!C4=2,90+Inputs!$B$27+Inputs!$B$30,IF(Skills!C4=3,120+Inputs!$B$28+Inputs!$B$30,MAX(0,(Inputs!$B$3-100)*3)+Inputs!$B$29+Inputs!$B$30))) | E4: =INDEX(FactorTable!$B$2:$Y$301, MATCH(ROUND(MIN(300,MAX(1,D4)),0), FactorTable!$A$2:$A$301,0), Skills!M4+1) | F4: =IF(Skills!N4=TRUE,(Skills!L4/10)*(E4/1000),Skills!L4/10)+Skills!O4 | I4: 1
A5: =Skills!A5 | B5: =Skills!B5 | C5: =Inputs!$B$3>=117 | D5: =IF(Skills!C5=1,60+Inputs!$B$26+Inputs!$B$30,IF(Skills!C5=2,90+Inputs!$B$27+Inputs!$B$30,IF(Skills!C5=3,120+Inputs!$B$28+Inputs!$B$30,MAX(0,(Inputs!$B$3-100)*3)+Inputs!$B$29+Inputs!$B$30))) | E5: =INDEX(FactorTable!$B$2:$Y$301, MATCH(ROUND(MIN(300,MAX(1,D5)),0), FactorTable!$A$2:$A$301,0), Skills!M5+1) | F5: =IF(Skills!N5=TRUE,(Skills!L5/10)*(E5/1000),Skills!L5/10)+Skills!O5 | G5: =Skills!G5*IF(Skills!H5>0,INT(IF(Inputs!$B$39="pvp",MIN(Skills!I5,15),Skills!I5)/Skills!H5+0.000000001),1) | H5: =1-(1-Skills!J5/100)^Skills!K5 | I5: 1 | J5: =Summary!$B$6*(F5/100) | K5: =J5*(1+Summary!$B$7/100)*(1+Inputs!$B$16/100)*(1+Inputs!$B$17/100)*(5000/(6000+Inputs!$B$43*(1-Inputs!$B$20/100)))*(1+(Inputs!$B$25+Summary!$B$21)/100)*(1+Artifacts!$B$34/100)*(1+(IF(Skills!A5="DARK_IMPALE",Inputs!$B$18+Artifacts!$B$40,Inputs!$B$19+Artifacts!$B$39))/100)*(Summary!$B$13*(1+Artifacts!$B$38/100)*I5) | L5: =K5*(MIN(Inputs!$B$23,Inputs!$B$24)/100+Inputs!$B$24/100)/2 | M5: =L5*(1+(Inputs!$B$11+Summary!$B$20+Artifacts!$B$33)/100) | N5: =L5*(1-MIN((Inputs!$B$10+Summary!$B$14+Artifacts!$B$32),100)/100)+M5*(MIN((Inputs!$B$10+Summary!$B$14+Artifacts!$B$32),100)/100) | O5: =(1-Summary!$B$11)*T5+Summary!$B$11*V5 | P5: =IF(Summary!$B$3=0,0,O5/Summary!$B$3) | Q5: =IFERROR(1/IF(Inputs!$B$39="pvp",15,MAX(0.1,Skills!D5-IF(TRUE=TRUE,Inputs!$B$33,0))),0) | R5: =IF(AND(Inputs!$B$39<>"pvp",Inputs!$B$44>0),IF(MAX(0,Inputs!$B$44-Summary!$B$23)<=0,0,(INT(MAX(0,Inputs!$B$44-Summary!$B$23)/IF(Inputs!$B$39="pvp",15,MAX(0.1,Skills!D5-IF(TRUE=TRUE,Inputs!$B$33,0))))+1)),0) | S5: =IFERROR(O5/N5,0) | T5: =IF(C5,(H5*N5*IF(AND(Inputs!$B$39<>"pvp",Inputs!$B$44>0),((Skills!G5*((R5-1)*IF(Skills!H5>0,INT(Skills!I5/Skills!H5+0.000000001),1)+IF(Skills!H5>0,INT(MIN(Skills!I5,MAX(0,MAX(0,Inputs!$B$44-Summary!$B$23)-((R5-1)*IF(Inputs!$B$39="pvp",15,MAX(0.1,Skills!D5-IF(TRUE=TRUE,Inputs!$B$33,0))))))/Skills!H5+0.000000001),1)))/Inputs!$B$44),G5*Q5))*IF(Inputs!$B$39="pvp",1,1+(Inputs!$B$21+Skills!P5+Summary!$B$15+Artifacts!$B$35)/100)*((((5000/(6000+Inputs!$B$43*(1-(100*(1-(1-Inputs!$B$20/100)*(1-Artifacts!$B$51/100)^IF(Inputs!$B$39="pvp",1,2)))/100)))/(5000/(6000+Inputs!$B$43*(1-Inputs!$B$20/100))))*((L5*(1-MIN(100,(Inputs!$B$10+Summary!$B$14+Artifacts!$B$32)+Artifacts!$B$69)/100)+M5*(MIN(100,(Inputs!$B$10+Summary!$B$14+Artifacts!$B$32)+Artifacts!$B$69)/100))/(L5*(1-MIN(100,(Inputs!$B$10+Summary!$B$14+Artifacts!$B$32))/100)+M5*(MIN(100,(Inputs!$B$10+Summary!$B$14+Artifacts!$B$32))/100)))*(1+Artifacts!$B$81/100))),0) | V5: =IF(C5,(H5*N5*IF(AND(Inputs!$B$39<>"pvp",Inputs!$B$44>0),((Skills!G5*((R5-1)*IF(Skills!H5>0,INT(Skills!I5/Skills!H5+0.000000001),1)+IF(Skills!H5>0,INT(MIN(Skills!I5,MAX(0,MAX(0,Inputs!$B$44-Summary!$B$23)-((R5-1)*IF(Inputs!$B$39="pvp",15,MAX(0.1,Skills!D5-IF(TRUE=TRUE,Inputs!$B$33,0))))))/Skills!H5+0.000000001),1)))/Inputs!$B$44),G5*Q5))*IF(Inputs!$B$39="pvp",1,(1+(Inputs!$B$22+Skills!Q5+Summary!$B$15+Artifacts!$B$80)/100)*(MIN(Skills!R5,Inputs!$B$38)))*((1+Artifacts!$B$53/100)),0)
A6: =Skills!A6 | B6: =Skills!B6 | C6: =Inputs!$B$3>=103 | D6: =IF(Skills!C6=1,60+Inputs!$B$26+Inputs!$B$30,IF(Skills!C6=2,90+Inputs!$B$27+Inputs!$B$30,IF(Skills!C6=3,120+Inputs!$B$28+Inputs!$B$30,MAX(0,(Inputs!$B$3-100)*3)+Inputs!$B$29+Inputs!$B$30))) | E6: =INDEX(FactorTable!$B$2:$Y$301, MATCH(ROUND(MIN(300,MAX(1,D6)),0), FactorTable!$A$2:$A$301,0), Skills!M6+1) | F6: =IF(Skills!N6=TRUE,(Skills!L6/10)*(E6/1000),Skills!L6/10)+Skills!O6 | G6: =Skills!G6*IF(Skills!H6>0,INT(IF(Inputs!$B$39="pvp",MIN(Skills!I6,15),Skills!I6)/Skills!H6+0.000000001),1) | H6: =1-(1-Skills!J6/100)^Skills!K6 | I6: 1 | J6: =Summary!$B$6*(F6/100) | K6: =J6*(1+Summary!$B$7/100)*(1+Inputs!$B$16/100)*(1+Inputs!$B$17/100)*(5000/(6000+Inputs!$B$43*(1-Inputs!$B$20/100)))*(1+(Inputs!$B$25+Summary!$B$21)/100)*(1+Artifacts!$B$34/100)*(1+(IF(Skills!A6="DARK_IMPALE",Inputs!$B$18+Artifacts!$B$40,Inputs!$B$19+Artifacts!$B$39))/100)*(Summary!$B$13*(1+Artifacts!$B$38/100)*I6) | L6: =K6*(MIN(Inputs!$B$23,Inputs!$B$24)/100+Inputs!$B$24/100)/2 | M6: =L6*(1+(Inputs!$B$11+Summary!$B$20+Artifacts!$B$33)/100) | N6: =L6*(1-MIN((Inputs!$B$10+Summary!$B$14+Artifacts!$B$32),100)/100)+M6*(MIN((Inputs!$B$10+Summary!$B$14+Artifacts!$B$32),100)/100) | O6: =(1-Summary!$B$11)*T6+Summary!$B$11*V6 | P6: =IF(Summary!$B$3=0,0,O6/Summary!$B$3) | Q6: =IFERROR(1/IF(Inputs!$B$39="pvp",15,MAX(0.1,Skills!D6-IF(TRUE=TRUE,Inputs!$B$33,0))),0) | R6: =IF(AND(Inputs!$B$39<>"pvp",Inputs!$B$44>0),IF(MAX(0,Inputs!$B$44-Summary!$B$23)<=0,0,(INT(MAX(0,Inputs!$B$44-Summary!$B$23)/IF(Inputs!$B$39="pvp",15,MAX(0.1,Skills!D6-IF(TRUE=TRUE,Inputs!$B$33,0))))+1)),0) | S6: =IFERROR(O6/N6,0) | T6: =IF(C6,(H6*N6*IF(AND(Inputs!$B$39<>"pvp",Inputs!$B$44>0),((Skills!G6*((R6-1)*IF(Skills!H6>0,INT(Skills!I6/Skills!H6+0.000000001),1)+IF(Skills!H6>0,INT(MIN(Skills!I6,MAX(0,MAX(0,Inputs!$B$44-Summary!$B$23)-((R6-1)*IF(Inputs!$B$39="pvp",15,MAX(0.1,Skills!D6-IF(TRUE=TRUE,Inputs!$B$33,0))))))/Skills!H6+0.000000001),1)))/Inputs!$B$44),G6*Q6))*IF(Inputs!$B$39="pvp",1,1+(Inputs!$B$21+Skills!P6+Summary!$B$15+Artifacts!$B$35)/100)*((((5000/(6000+Inputs!$B$43*(1-(100*(1-(1-Inputs!$B$20/100)*(1-Artifacts!$B$51/100)^IF(Inputs!$B$39="pvp",1,2)))/100)))/(5000/(6000+Inputs!$B$43*(1-Inputs!$B$20/100))))*((L6*(1-MIN(100,(Inputs!$B$10+Summary!$B$14+Artifacts!$B$32)+Artifacts!$B$69)/100)+M6*(MIN(100,(Inputs!$B$10+Summary!$B$14+Artifacts!$B$32)+Artifacts!$B$69)/100))/(L6*(1-MIN(100,(Inputs!$B$10+Summary!$B$14+Artifacts!$B$32))/100)+M6*(MIN(100,(Inputs!$B$10+Summary!$B$14+Artifacts!$B$32))/100)))*(1+Artifacts!$B$81/100))),0) | V6: =IF(C6,(H6*N6*IF(AND(Inputs!$B$39<>"pvp",Inputs!$B$44>0),((Skills!G6*((R6-1)*IF(Skills!H6>0,INT(Skills!I6/Skills!H6+0.000000001),1)+IF(Skills!H6>0,INT(MIN(Skills!I6,MAX(0,MAX(0,Inputs!$B$44-Summary!$B$23)-((R6-1)*IF(Inputs!$B$39="pvp",15,MAX(0.1,Skills!D6-IF(TRUE=TRUE,Inputs!$B$33,0))))))/Skills!H6+0.000000001),1)))/Inputs!$B$44),G6*Q6))*IF(Inputs!$B$39="pvp",1,(1+(Inputs!$B$22+Skills!Q6+Summary!$B$15+Artifacts!$B$80)/100)*(MIN(Skills!R6,Inputs!$B$38)))*((1+Artifacts!$B$53/100)),0)
A7: =Skills!A7 | B7: =Skills!B7 | C7: =Inputs!$B$3>=40 | D7: =IF(Skills!C7=1,60+Inputs!$B$26+Inputs!$B$30,IF(Skills!C7=2,90+Inputs!$B$27+Inputs!$B$30,IF(Skills!C7=3,120+Inputs!$B$28+Inputs!$B$30,MAX(0,(Inputs!$B$3-100)*3)+Inputs!$B$29+Inputs!$B$30))) | E7: =INDEX(FactorTable!$B$2:$Y$301, MATCH(ROUND(MIN(300,MAX(1,D7)),0), FactorTable!$A$2:$A$301,0), Skills!M7+1) | F7: =IF(Skills!N7=TRUE,(Skills!L7/10)*(E7/1000),Skills!L7/10)+Skills!O7 | G7: =Skills!G7*IF(Skills!H7>0,INT(IF(Inputs!$B$39="pvp",MIN(Skills!I7,15),Skills!I7)/Skills!H7+0.000000001),1) | H7: =1-(1-Skills!J7/100)^Skills!K7 | I7: 1 | J7: =Summary!$B$6*(F7/100) | K7: =J7*(1+Summary!$B$7/100)*(1+Inputs!$B$16/100)*(1+Inputs!$B$17/100)*(5000/(6000+Inputs!$B$43*(1-Inputs!$B$20/100)))*(1+(Inputs!$B$25+Summary!$B$21)/100)*(1+Artifacts!$B$34/100)*(1+0.75*IF(C11=TRUE,F11,0)/100)*(1+(IF(Skills!A7="DARK_IMPALE",Inputs!$B$18+Artifacts!$B$40,Inputs!$B$19+Artifacts!$B$39))/100)*(Summary!$B$13*(1+Artifacts!$B$38/100)*I7) | L7: =K7*(MIN(Inputs!$B$23,Inputs!$B$24)/100+Inputs!$B$24/100)/2 | M7: =L7*(1+(Inputs!$B$11+Summary!$B$20+Artifacts!$B$33)/100) | N7: =L7*(1-MIN((Inputs!$B$10+Summary!$B$14+Artifacts!$B$32),100)/100)+M7*(MIN((Inputs!$B$10+Summary!$B$14+Artifacts!$B$32),100)/100) | O7: =(1-Summary!$B$11)*T7+Summary!$B$11*V7 | P7: =IF(Summary!$B$3=0,0,O7/Summary!$B$3) | Q7: =IFERROR(1/IF(Inputs!$B$39="pvp",15,MAX(0.1,Skills!D7-IF(TRUE=TRUE,Inputs!$B$33,0))),0) | R7: =IF(AND(Inputs!$B$39<>"pvp",Inputs!$B$44>0),IF(MAX(0,Inputs!$B$44-Summary!$B$23)<=0,0,(INT(MAX(0,Inputs!$B$44-Summary!$B$23)/IF(Inputs!$B$39="pvp",15,MAX(0.1,Skills!D7-IF(TRUE=TRUE,Inputs!$B$33,0))))+1)),0) | S7: =IFERROR(O7/N7,0) | T7: =IF(C7,(H7*N7*IF(AND(Inputs!$B$39<>"pvp",Inputs!$B$44>0),((Skills!G7*((R7-1)*IF(Skills!H7>0,INT(Skills!I7/Skills!H7+0.000000001),1)+IF(Skills!H7>0,INT(MIN(Skills!I7,MAX(0,MAX(0,Inputs!$B$44-Summary!$B$23)-((R7-1)*IF(Inputs!$B$39="pvp",15,MAX(0.1,Skills!D7-IF(TRUE=TRUE,Inputs!$B$33,0))))))/Skills!H7+0.000000001),1)))/Inputs!$B$44),G7*Q7))*IF(Inputs!$B$39="pvp",1,1+(Inputs!$B$21+Skills!P7+Summary!$B$15+Artifacts!$B$35)/100)*((((5000/(6000+Inputs!$B$43*(1-(100*(1-(1-Inputs!$B$20/100)*(1-Artifacts!$B$51/100)^IF(Inputs!$B$39="pvp",1,2)))/100)))/(5000/(6000+Inputs!$B$43*(1-Inputs!$B$20/100))))*((L7*(1-MIN(100,(Inputs!$B$10+Summary!$B$14+Artifacts!$B$32)+Artifacts!$B$69)/100)+M7*(MIN(100,(Inputs!$B$10+Summary!$B$14+Artifacts!$B$32)+Artifacts!$B$69)/100))/(L7*(1-MIN(100,(Inputs!$B$10+Summary!$B$14+Artifacts!$B$32))/100)+M7*(MIN(100,(Inputs!$B$10+Summary!$B$14+Artifacts!$B$32))/100)))*(1+Artifacts!$B$81/100))),0) | V7: =IF(C7,(H7*N7*IF(AND(Inputs!$B$39<>"pvp",Inputs!$B$44>0),((Skills!G7*((R7-1)*IF(Skills!H7>0,INT(Skills!I7/Skills!H7+0.000000001),1)+IF(Skills!H7>0,INT(MIN(Skills!I7,MAX(0,MAX(0,Inputs!$B$44-Summary!$B$23)-((R7-1)*IF(Inputs!$B$39="pvp",15,MAX(0.1,Skills!D7-IF(TRUE=TRUE,Inputs!$B$33,0))))))/Skills!H7+0.000000001),1)))/Inputs!$B$44),G7*Q7))*IF(Inputs!$B$39="pvp",1,(1+(Inputs!$B$22+Skills!Q7+Summary!$B$15+Artifacts!$B$80)/100)*(MIN(Skills!R7,Inputs!$B$38)))*((1+Artifacts!$B$53/100)),0)
A8: =Skills!A8 | B8: =Skills!B8 | C8: =Inputs!$B$3>=75 | D8: =IF(Skills!C8=1,60+Inputs!$B$26+Inputs!$B$30,IF(Skills!C8=2,90+Inputs!$B$27+Inputs!$B$30,IF(Skills!C8=3,120+Inputs!$B$28+Inputs!$B$30,MAX(0,(Inputs!$B$3-100)*3)+Inputs!$B$29+Inputs!$B$30))) | E8: =INDEX(FactorTable!$B$2:$Y$301, MATCH(ROUND(MIN(300,MAX(1,D8)),0), FactorTable!$A$2:$A$301,0), Skills!M8+1) | F8: =IF(Skills!N8=TRUE,(Skills!L8/10)*(E8/1000),Skills!L8/10)+Skills!O8 | I8: 1
A9: =Skills!A9 | B9: =Skills!B9 | C9: =Inputs!$B$3>=60 | D9: =IF(Skills!C9=1,60+Inputs!$B$26+Inputs!$B$30,IF(Skills!C9=2,90+Inputs!$B$27+Inputs!$B$30,IF(Skills!C9=3,120+Inputs!$B$28+Inputs!$B$30,MAX(0,(Inputs!$B$3-100)*3)+Inputs!$B$29+Inputs!$B$30))) | E9: =INDEX(FactorTable!$B$2:$Y$301, MATCH(ROUND(MIN(300,MAX(1,D9)),0), FactorTable!$A$2:$A$301,0), Skills!M9+1) | F9: =IF(Skills!N9=TRUE,(Skills!L9/10)*(E9/1000),Skills!L9/10)+Skills!O9 | G9: =Skills!G9*IF(Skills!H9>0,INT(IF(Inputs!$B$39="pvp",MIN(Skills!I9,15),Skills!I9)/Skills!H9+0.000000001),1) | H9: =1-(1-Skills!J9/100)^Skills!K9 | I9: 1 | J9: =Summary!$B$6*(F9/100) | K9: =J9*(1+Summary!$B$7/100)*(1+Inputs!$B$16/100)*(1+Inputs!$B$17/100)*(5000/(6000+Inputs!$B$43*(1-Inputs!$B$20/100)))*(1+(Inputs!$B$25+Summary!$B$21)/100)*(1+Artifacts!$B$34/100)*(1+1.0*IF(C11=TRUE,F11,0)/100)*(1+(IF(Skills!A9="DARK_IMPALE",Inputs!$B$18+Artifacts!$B$40,Inputs!$B$19+Artifacts!$B$39))/100)*(Summary!$B$13*(1+Artifacts!$B$38/100)*I9) | L9: =K9*(MIN(Inputs!$B$23,Inputs!$B$24)/100+Inputs!$B$24/100)/2 | M9: =L9*(1+(Inputs!$B$11+Summary!$B$20+Artifacts!$B$33)/100) | N9: =L9*(1-MIN((Inputs!$B$10+Summary!$B$14+Artifacts!$B$32),100)/100)+M9*(MIN((Inputs!$B$10+Summary!$B$14+Artifacts!$B$32),100)/100) | O9: =(1-Summary!$B$11)*T9+Summary!$B$11*V9 | P9: =IF(Summary!$B$3=0,0,O9/Summary!$B$3) | Q9: =IFERROR(1/IF(Inputs!$B$39="pvp",15,MAX(0.1,Skills!D9-IF(TRUE=TRUE,Inputs!$B$33,0))),0) | R9: =IF(AND(Inputs!$B$39<>"pvp",Inputs!$B$44>0),IF(MAX(0,Inputs!$B$44-Summary!$B$23)<=0,0,(INT(MAX(0,Inputs!$B$44-Summary!$B$23)/IF(Inputs!$B$39="pvp",15,MAX(0.1,Skills!D9-IF(TRUE=TRUE,Inputs!$B$33,0))))+1)),0) | S9: =IFERROR(O9/N9,0) | T9: =IF(C9,(H9*N9*IF(AND(Inputs!$B$39<>"pvp",Inputs!$B$44>0),((Skills!G9*((R9-1)*IF(Skills!H9>0,INT(Skills!I9/Skills!H9+0.000000001),1)+IF(Skills!H9>0,INT(MIN(Skills!I9,MAX(0,MAX(0,Inputs!$B$44-Summary!$B$23)-((R9-1)*IF(Inputs!$B$39="pvp",15,MAX(0.1,Skills!D9-IF(TRUE=TRUE,Inputs!$B$33,0))))))/Skills!H9+0.000000001),1)))/Inputs!$B$44),G9*Q9))*IF(Inputs!$B$39="pvp",1,1+(Inputs!$B$21+Skills!P9+Summary!$B$15+Artifacts!$B$35)/100)*((((5000/(6000+Inputs!$B$43*(1-(100*(1-(1-Inputs!$B$20/100)*(1-Artifacts!$B$51/100)^IF(Inputs!$B$39="pvp",1,2)))/100)))/(5000/(6000+Inputs!$B$43*(1-Inputs!$B$20/100))))*((L9*(1-MIN(100,(Inputs!$B$10+Summary!$B$14+Artifacts!$B$32)+Artifacts!$B$69)/100)+M9*(MIN(100,(Inputs!$B$10+Summary!$B$14+Artifacts!$B$32)+Artifacts!$B$69)/100))/(L9*(1-MIN(100,(Inputs!$B$10+Summary!$B$14+Artifacts!$B$32))/100)+M9*(MIN(100,(Inputs!$B$10+Summary!$B$14+Artifacts!$B$32))/100)))*(1+Artifacts!$B$81/100))),0) | V9: =IF(C9,(H9*N9*IF(AND(Inputs!$B$39<>"pvp",Inputs!$B$44>0),((Skills!G9*((R9-1)*IF(Skills!H9>0,INT(Skills!I9/Skills!H9+0.000000001),1)+IF(Skills!H9>0,INT(MIN(Skills!I9,MAX(0,MAX(0,Inputs!$B$44-Summary!$B$23)-((R9-1)*IF(Inputs!$B$39="pvp",15,MAX(0.1,Skills!D9-IF(TRUE=TRUE,Inputs!$B$33,0))))))/Skills!H9+0.000000001),1)))/Inputs!$B$44),G9*Q9))*IF(Inputs!$B$39="pvp",1,(1+(Inputs!$B$22+Skills!Q9+Summary!$B$15+Artifacts!$B$80)/100)*(MIN(Skills!R9,Inputs!$B$38)))*((1+Artifacts!$B$53/100)),0)
