Workbook

Sheet README
A1: Arch Mage (Ice/Lightning) — DPS Calculator: How to Use This Workbook
A3: How to use this workbook
A4: Only edit the yellow-highlighted cells on the Inputs sheet — every other sheet is computed from those values and will be overwritten if you rebuild the workbook.
A5: Summary shows Total DPS, a Per-Skill DPS Breakdown (damage-dealing skills only — buffs/passives that never deal their own damage are omitted), and a Marginal DPS & Stat Value table showing the DPS gained per +1 of each stat.
A6: Sensitivity has the full detail behind that marginal-value table — one self-contained block per stat, showing exactly how bumping that stat by +1 changes every downstream number.
A7: CubeData/PotentialCubes model your current gear's Potential Cube lines and drive cube-reroll expected-value decisions. For the full standalone Potential Cube EV calculator (exact optimal-stopping math, works from this workbook alone), see tools/potential_cubes_ev.py in the project repo.
A9: Design decisions & assumptions
A10: Freezing Breath's Weaken debuff and Elemental Reset's own Damage Taken bonus assume the target is permanently afflicted at steady state, not an exact on/off timer.
A11: Crit Rate pushed above 100% (e.g. by cube potential lines) automatically redirects its stat-value to Crit Damage's own per-unit DPS value on the PotentialCubes sheet, since excess Crit Rate cannot do anything past 100%.
A12: Buffs (Magic Guard, Meditation, Infinity) are modeled at steady-state duty-cycle average uptime, not as an exact moment-to-moment state machine.
A13: Content Type (Inputs) picks what you're fighting — Chapter Boss/Breakthrough/PvP/EXP Dungeon/Equipment Dungeon/Weapon Dungeon/Enhancement Dungeon/Hero Dungeon/World Boss/Chapter Hunt — and Monster Defense and Fixed Fight Duration are both auto-computed from it (plus Chapter/Stage for the chapter- and dungeon-based types); PvP still forces its own fixed 15-second window and uses your own Defense stat as the opponent's Defense estimate. See README.md's 'Content Type' section for the exact formulas.
A14: Not modeled (out of scope): crowd control, Accuracy/Evasion/Defense reduction, movement speed, the character's own Defense stat, and Companion Summoning Time.

Sheet Inputs
A1: Arch Mage (Ice/Lightning) — DPS Calculator Inputs | N1: (none)
C2: Chapter Boss | D2: Breakthrough | E2: PvP | F2: EXP Dungeon | G2: Equipment Dungeon | H2: Weapon Dungeon | I2: Enhancement Dungeon | J2: Hero Dungeon | K2: World Boss | L2: Chapter Hunt | N2: Charm of the Undead
A3: Character Level | B3: 200 | N3: Pig's Ribbon
A4: Content Type | B4: Chapter Boss | N4: Shamaness Marble
A5: Chapter-Stage — 'chapter-substage' (e.g. '28-9') for Breakthrough/Chapter Hunt, just the chapter number for Chapter Boss, or just the stage number for Weapon/Equipment/Enhancement/EXP/Hero Dungeon. Not applicable to World Boss/PvP. | B5: =INDEX($C$5:$L$5,MATCH($B$4,$C$2:$L$2,0)) | C5: 28 | D5: 28-9 | F5: 80 | G5: 80 | H5: 80 | I5: 80 | J5: 80 | L5: 28-9 | N5: The Contract of Darkness
A6: Flat ATTACK | B6: =INDEX($C$6:$L$6,MATCH($B$4,$C$2:$L$2,0)) | C6: 10000 | D6: 10000 | E6: 10000 | F6: 10000 | G6: 10000 | H6: 10000 | I6: 10000 | J6: 10000 | K6: 10000 | L6: 10000 | N6: Rainbow-colored Snail Shell
A7: ATTACK % | B7: =INDEX($C$7:$L$7,MATCH($B$4,$C$2:$L$2,0)) | C7: 0 | D7: 0 | E7: 0 | F7: 0 | G7: 0 | H7: 0 | I7: 0 | J7: 0 | K7: 0 | L7: 0 | N7: Hexagon Necklace
A8: Defense (your own DEF stat; PvP assumes the opponent has the same Defense as you) | B8: =INDEX($C$8:$L$8,MATCH($B$4,$C$2:$L$2,0)) | C8: 0 | D8: 0 | E8: 0 | F8: 0 | G8: 0 | H8: 0 | I8: 0 | J8: 0 | K8: 0 | L8: 0 | N8: Arwen's Glass Shoes
A9: CRIT_RATE % | B9: =INDEX($C$9:$L$9,MATCH($B$4,$C$2:$L$2,0)) | C9: 0 | D9: 0 | E9: 0 | F9: 0 | G9: 0 | H9: 0 | I9: 0 | J9: 0 | K9: 0 | L9: 0 | N9: Mushmom's Cap
A10: CRIT_DAMAGE % | B10: =INDEX($C$10:$L$10,MATCH($B$4,$C$2:$L$2,0)) | C10: 0 | D10: 0 | E10: 0 | F10: 0 | G10: 0 | H10: 0 | I10: 0 | J10: 0 | K10: 0 | L10: 0 | N10: Clear Spring Water
A11: ATTACK_SPEED % (base, excludes Nimble Feet/MP Eater) | B11: =INDEX($C$11:$L$11,MATCH($B$4,$C$2:$L$2,0)) | C11: 0 | D11: 0 | E11: 0 | F11: 0 | G11: 0 | H11: 0 | I11: 0 | J11: 0 | K11: 0 | L11: 0 | N11: Athena Pierce's Old Gloves
A12: Flat INT | B12: =INDEX($C$12:$L$12,MATCH($B$4,$C$2:$L$2,0)) | C12: 0 | D12: 0 | E12: 0 | F12: 0 | G12: 0 | H12: 0 | I12: 0 | J12: 0 | K12: 0 | L12: 0 | N12: Zakum's Stone Piece
A13: INT % | B13: =INDEX($C$13:$L$13,MATCH($B$4,$C$2:$L$2,0)) | C13: 0 | D13: 0 | E13: 0 | F13: 0 | G13: 0 | H13: 0 | I13: 0 | J13: 0 | K13: 0 | L13: 0 | N13: Horntail's Scale
A14: LUK | B14: =INDEX($C$14:$L$14,MATCH($B$4,$C$2:$L$2,0)) | C14: 0 | D14: 0 | E14: 0 | F14: 0 | G14: 0 | H14: 0 | I14: 0 | J14: 0 | K14: 0 | L14: 0 | N14: Pink Bean's Giant Rib
A15: DAMAGE % | B15: =INDEX($C$15:$L$15,MATCH($B$4,$C$2:$L$2,0)) | C15: 0 | D15: 0 | E15: 0 | F15: 0 | G15: 0 | H15: 0 | I15: 0 | J15: 0 | K15: 0 | L15: 0 | N15: Chalice
A16: DAMAGE_AMP % | B16: =INDEX($C$16:$L$16,MATCH($B$4,$C$2:$L$2,0)) | C16: 0 | D16: 0 | E16: 0 | F16: 0 | G16: 0 | H16: 0 | I16: 0 | J16: 0 | K16: 0 | L16: 0 | N16: Old Music Box
A17: BASIC_ATTACK_DAMAGE % | B17: =INDEX($C$17:$L$17,MATCH($B$4,$C$2:$L$2,0)) | C17: 0 | D17: 0 | E17: 0 | F17: 0 | G17: 0 | H17: 0 | I17: 0 | J17: 0 | K17: 0 | L17: 0 | N17: Silver Pendant
A18: SKILL_DAMAGE % | B18: =INDEX($C$18:$L$18,MATCH($B$4,$C$2:$L$2,0)) | C18: 0 | D18: 0 | E18: 0 | F18: 0 | G18: 0 | H18: 0 | I18: 0 | J18: 0 | K18: 0 | L18: 0 | N18: Star Rock
A19: DEF_PEN % | B19: =INDEX($C$19:$L$19,MATCH($B$4,$C$2:$L$2,0)) | C19: 0 | D19: 0 | E19: 0 | F19: 0 | G19: 0 | H19: 0 | I19: 0 | J19: 0 | K19: 0 | L19: 0 | N19: Book of Ancient
A20: BOSS_DAMAGE % | B20: =INDEX($C$20:$L$20,MATCH($B$4,$C$2:$L$2,0)) | C20: 0 | D20: 0 | E20: 0 | F20: 0 | G20: 0 | H20: 0 | I20: 0 | J20: 0 | K20: 0 | L20: 0 | N20: Lunar Dew
A21: NORMAL_DAMAGE % | B21: =INDEX($C$21:$L$21,MATCH($B$4,$C$2:$L$2,0)) | C21: 0 | D21: 0 | E21: 0 | F21: 0 | G21: 0 | H21: 0 | I21: 0 | J21: 0 | K21: 0 | L21: 0 | N21: Fire Flower
A22: MIN_DAMAGE % | B22: =INDEX($C$22:$L$22,MATCH($B$4,$C$2:$L$2,0)) | C22: 100 | D22: 100 | E22: 100 | F22: 100 | G22: 100 | H22: 100 | I22: 100 | J22: 100 | K22: 100 | L22: 100 | N22: Soul Contract
A23: MAX_DAMAGE % | B23: =INDEX($C$23:$L$23,MATCH($B$4,$C$2:$L$2,0)) | C23: 100 | D23: 100 | E23: 100 | F23: 100 | G23: 100 | H23: 100 | I23: 100 | J23: 100 | K23: 100 | L23: 100 | N23: Lit Lamp
A24: FINAL_DAMAGE % (base, excludes Infinity) | B24: =INDEX($C$24:$L$24,MATCH($B$4,$C$2:$L$2,0)) | C24: 0 | D24: 0 | E24: 0 | F24: 0 | G24: 0 | H24: 0 | I24: 0 | J24: 0 | K24: 0 | L24: 0 | N24: Soul Pouch
A25: Skill Level Bonus — 1st Job | B25: =INDEX($C$25:$L$25,MATCH($B$4,$C$2:$L$2,0)) | C25: 0 | D25: 0 | E25: 0 | F25: 0 | G25: 0 | H25: 0 | I25: 0 | J25: 0 | K25: 0 | L25: 0 | N25: Ancient Text Piece
A26: Skill Level Bonus — 2nd Job | B26: =INDEX($C$26:$L$26,MATCH($B$4,$C$2:$L$2,0)) | C26: 0 | D26: 0 | E26: 0 | F26: 0 | G26: 0 | H26: 0 | I26: 0 | J26: 0 | K26: 0 | L26: 0 | N26: Icy Soul Rock
A27: Skill Level Bonus — 3rd Job | B27: =INDEX($C$27:$L$27,MATCH($B$4,$C$2:$L$2,0)) | C27: 0 | D27: 0 | E27: 0 | F27: 0 | G27: 0 | H27: 0 | I27: 0 | J27: 0 | K27: 0 | L27: 0 | N27: Flaming Lava
A28: Skill Level Bonus — 4th Job | B28: =INDEX($C$28:$L$28,MATCH($B$4,$C$2:$L$2,0)) | C28: 0 | D28: 0 | E28: 0 | F28: 0 | G28: 0 | H28: 0 | I28: 0 | J28: 0 | K28: 0 | L28: 0 | N28: Sayram's Necklace
A29: Skill Level Bonus — All Skills | B29: =INDEX($C$29:$L$29,MATCH($B$4,$C$2:$L$2,0)) | C29: 0 | D29: 0 | E29: 0 | F29: 0 | G29: 0 | H29: 0 | I29: 0 | J29: 0 | K29: 0 | L29: 0 | N29: Bottle of Emotion
N30: Peach Tree Herb Pouch
A31: Additional Bonuses | N31: Candle
A32: Skill Cooldown Decrease (seconds; applies to every cooldown — skills, buffs and passives) | B32: =INDEX($C$32:$L$32,MATCH($B$4,$C$2:$L$2,0)) | C32: 0 | D32: 0 | E32: 0 | F32: 0 | G32: 0 | H32: 0 | I32: 0 | J32: 0 | K32: 0 | L32: 0 | N32: Alliance Badge
A33: Basic Attack Target Increase (flat, adds to the 6-target normal-monster base) | B33: =INDEX($C$33:$L$33,MATCH($B$4,$C$2:$L$2,0)) | C33: 1 | D33: 1 | E33: 1 | F33: 1 | G33: 1 | H33: 1 | I33: 1 | J33: 1 | K33: 1 | L33: 1 | N33: Horn Flute
A34: Buff Duration Increase % | B34: =INDEX($C$34:$L$34,MATCH($B$4,$C$2:$L$2,0)) | C34: 0 | D34: 0 | E34: 0 | F34: 0 | G34: 0 | H34: 0 | I34: 0 | J34: 0 | K34: 0 | L34: 0 | N34: Cursed Doll
A35: Companion Summoning Time Increase % (companions not modeled — always 0 DPS impact) | B35: =INDEX($C$35:$L$35,MATCH($B$4,$C$2:$L$2,0)) | C35: 0 | D35: 0 | E35: 0 | F35: 0 | G35: 0 | H35: 0 | I35: 0 | J35: 0 | K35: 0 | L35: 0 | N35: Reindeer's Spear
A36: Boss/Normal Emphasis (Breakthrough/Hero Dungeon only) | B36: =INDEX($C$36:$L$36,MATCH($B$4,$C$2:$L$2,0)) | D36: A Little More Normal | J36: A Little More Normal | N36: Secret Map
A37: Max Enemies Actually In Range (normal-monster content only; default 999 = uncapped) | B37: =INDEX($C$37:$L$37,MATCH($B$4,$C$2:$L$2,0)) | D37: 999 | F37: 999 | G37: 999 | J37: 999 | L37: 999 | N37: Ring of Cycles
A38: Monster Type (auto-computed from Content Type) — computed, do not edit | B38: =IF(Inputs!$B$4="PvP","pvp",IF(OR(Inputs!$B$4="Breakthrough",Inputs!$B$4="Hero Dungeon"),"breakthrough",IF(OR(Inputs!$B$4="EXP Dungeon",Inputs!$B$4="Equipment Dungeon",Inputs!$B$4="Chapter Hunt"),"normal","boss")))
A39: Chapter (parsed from Chapter-Stage) — computed, do not edit | B39: =IFERROR(IF(ISNUMBER(FIND("-",Inputs!$B$5)),VALUE(LEFT(Inputs!$B$5,FIND("-",Inputs!$B$5)-1)),VALUE(Inputs!$B$5)),28)
A40: Stage (parsed from Chapter-Stage) — computed, do not edit | B40: =IFERROR(IF(ISNUMBER(FIND("-",Inputs!$B$5)),VALUE(MID(Inputs!$B$5,FIND("-",Inputs!$B$5)+1,50)),VALUE(Inputs!$B$5)),9)
...

Sheet FactorTable
A1: Level | B1: F0 | C1: F1 | D1: F2 | E1: F3 | F1: F4 | G1: F5 | H1: F6 | I1: F7 | J1: F8 | K1: F9 | L1: F10 | M1: F11 | N1: F12 | O1: F13 | P1: F14 | Q1: F15 | R1: F16 | S1: F17 | T1: F18 | U1: F19 | V1: F20 | W1: F21 | X1: F22 | Y1: F23
A2: 1 | B2: 0 | C2: 1000 | D2: 1000 | E2: 1000 | F2: 1000 | G2: 1000 | H2: 1000 | I2: 1000 | J2: 1000 | K2: 1000 | L2: 1000 | M2: 1000 | N2: 1000 | O2: 1000 | P2: 1000 | Q2: 1000 | R2: 1000 | S2: 1000 | T2: 1000 | U2: 1000 | V2: 1000 | W2: 1000 | X2: 1000 | Y2: 1000
A3: 2 | B3: 0 | C3: 1015 | D3: 1020 | E3: 1030 | F3: 1040 | G3: 1050 | H3: 1060 | I3: 1070 | J3: 1020 | K3: 1020 | L3: 1020 | M3: 1000 | N3: 1010 | O3: 1020 | P3: 1030 | Q3: 1040 | R3: 1050 | S3: 1060 | T3: 1070 | U3: 1080 | V3: 1010 | W3: 1008 | X3: 1006 | Y3: 1100
A4: 3 | B4: 0 | C4: 1031 | D4: 1041 | E4: 1061 | F4: 1082 | G4: 1103 | H4: 1124 | I4: 1145 | J4: 1030 | K4: 1041 | L4: 1030 | M4: 1000 | N4: 1015 | O4: 1030 | P4: 1045 | Q4: 1060 | R4: 1075 | S4: 1090 | T4: 1105 | U4: 1120 | V4: 1020 | W4: 1012 | X4: 1009 | Y4: 1150
A5: 4 | B5: 0 | C5: 1047 | D5: 1062 | E5: 1093 | F5: 1126 | G5: 1159 | H5: 1192 | I5: 1226 | J5: 1040 | K5: 1062 | L5: 1040 | M5: 1000 | N5: 1020 | O5: 1040 | P5: 1060 | Q5: 1080 | R5: 1100 | S5: 1120 | T5: 1140 | U5: 1160 | V5: 1030 | W5: 1016 | X5: 1012 | Y5: 1200
A6: 5 | B6: 0 | C6: 1063 | D6: 1084 | E6: 1126 | F6: 1172 | G6: 1217 | H6: 1264 | I6: 1312 | J6: 1050 | K6: 1084 | L6: 1050 | M6: 1000 | N6: 1025 | O6: 1050 | P6: 1075 | Q6: 1100 | R6: 1125 | S6: 1150 | T6: 1175 | U6: 1200 | V6: 1040 | W6: 1020 | X6: 1015 | Y6: 1250
A7: 6 | B7: 0 | C7: 1079 | D7: 1106 | E7: 1160 | F7: 1219 | G7: 1278 | H7: 1340 | I7: 1404 | J7: 1060 | K7: 1106 | L7: 1060 | M7: 1000 | N7: 1030 | O7: 1060 | P7: 1090 | Q7: 1120 | R7: 1150 | S7: 1180 | T7: 1210 | U7: 1240 | V7: 1050 | W7: 1024 | X7: 1018 | Y7: 1300
A8: 7 | B8: 0 | C8: 1096 | D8: 1129 | E8: 1195 | F8: 1268 | G8: 1342 | H8: 1421 | I8: 1503 | J8: 1070 | K8: 1129 | L8: 1070 | M8: 1000 | N8: 1035 | O8: 1070 | P8: 1105 | Q8: 1140 | R8: 1175 | S8: 1210 | T8: 1245 | U8: 1280 | V8: 1060 | W8: 1028 | X8: 1021 | Y8: 1350
A9: 8 | B9: 0 | C9: 1113 | D9: 1152 | E9: 1231 | F9: 1319 | G9: 1410 | H9: 1507 | I9: 1609 | J9: 1080 | K9: 1152 | L9: 1080 | M9: 1000 | N9: 1040 | O9: 1080 | P9: 1120 | Q9: 1160 | R9: 1200 | S9: 1240 | T9: 1280 | U9: 1320 | V9: 1070 | W9: 1032 | X9: 1024 | Y9: 1400
A10: 9 | B10: 0 | C10: 1130 | D10: 1176 | E10: 1268 | F10: 1372 | G10: 1481 | H10: 1598 | I10: 1722 | J10: 1090 | K10: 1176 | L10: 1090 | M10: 1000 | N10: 1045 | O10: 1090 | P10: 1135 | Q10: 1180 | R10: 1225 | S10: 1270 | T10: 1315 | U10: 1360 | V10: 1080 | W10: 1036 | X10: 1027 | Y10: 1450
A11: 10 | B11: 0 | C11: 1147 | D11: 1200 | E11: 1307 | F11: 1427 | G11: 1556 | H11: 1694 | I11: 1843 | J11: 1100 | K11: 1200 | L11: 1100 | M11: 1000 | N11: 1050 | O11: 1100 | P11: 1150 | Q11: 1200 | R11: 1250 | S11: 1300 | T11: 1350 | U11: 1400 | V11: 1090 | W11: 1040 | X11: 1030 | Y11: 1500
A12: 11 | B12: 0 | C12: 1165 | D12: 1224 | E12: 1347 | F12: 1485 | G12: 1634 | H12: 1796 | I12: 1973 | J12: 1110 | K12: 1224 | L12: 1110 | M12: 1000 | N12: 1055 | O12: 1110 | P12: 1165 | Q12: 1220 | R12: 1275 | S12: 1330 | T12: 1385 | U12: 1440 | V12: 1100 | W12: 1044 | X12: 1033 | Y12: 1550
A13: 12 | B13: 0 | C13: 1183 | D13: 1249 | E13: 1388 | F13: 1545 | G13: 1716 | H13: 1904 | I13: 2112 | J13: 1120 | K13: 1249 | L13: 1120 | M13: 1000 | N13: 1060 | O13: 1120 | P13: 1180 | Q13: 1240 | R13: 1300 | S13: 1360 | T13: 1420 | U13: 1480 | V13: 1110 | W13: 1048 | X13: 1036 | Y13: 1600
... A301: 300 | B301: 0 | C301: 88573 | D301: 381637 | E301: 6991522 | F301: 125363453 | G301: 2185120762 | H301: 37157073039 | I301: 614631863830 | J301: 2000 | K301: 53326 | L301: 2500 | M301: 1100 | N301: 2500 | O301: 4000 | P301: 5500 | Q301: 7000 | R301: 8500 | S301: 10000 | T301: 11500 | U301: 13000 | V301: 7558 | W301: 2200 | X301: 1900 | Y301: 8800

Sheet Skills
A1: Key | B1: Name | C1: JobStep | D1: Cooldown(s) | E1: CostsActionSlot | F1: HitsPerCast | G1: ICD(s) | H1: ActiveWindow(s) | I1: ProcChance% | J1: RollsPerCast | K1: BaseDamage(tenths%) | L1: FactorIndex | M1: ScalesWithLevel | N1: SkillMasteryBonus% | O1: MasteryBossDamage% | P1: MasteryNormalDamage% | Q1: NormalMonsterTargets | R1: BuffTargetStat | S1: BuffDuration(s) | T1: MapleHeroBase(tenths%) | U1: MapleHeroFactorIndex | V1: Stacks | W1: Note
A2: CHAIN_LIGHTNING | B2: Chain Lightning | C2: 4 | E2: FALSE | F2: =IF(Inputs!$B$3>=136,6,5) | G2: 0 | H2: 0 | I2: 100 | J2: 1 | M2: TRUE | N2: =SUMPRODUCT((Inputs!$B$3>={102,106,116,120,128,132})*{10,11,12,13,14,15}) | O2: =SUMPRODUCT((Inputs!$B$3>={111,124})*{10,10}) | P2: 0 | Q2: =6+Inputs!$B$33 | S2: 0 | W2: 4th-job basic-attack effect (supersedes Energy Bolt/Cold Beam/Ice Strike, out of scope per the project's job-tier-is-gone convention). Wiki: 290%->522% (levels 1-200) to 6 target(s) 5 time(s) — factorIndex 21, baseDamage 2900 tenths%, matching Inputs!skill_coefficient (=290*basic_factor/1000) exactly, so this row's own coefficient is just that Inputs value + SkillMasteryBonus% (same mechanism as FP-Mage/Night Lord's own Basic Attack/Showdown rows). SkillMasteryBonus% is the 6-tier 'Chain Lightning - Damage' mastery chain (102/106/116/120/128/132): every tier is its own add-on (user-confirmed 2026-10-21: +10, +11, +12, +13, +14, +15 = 75% total at max), so level_gated_sum uses the RAW tier values. MasteryBossDamage% is the 2-tier 'Chain Lightning - Boss Monster Damage' chain (111/124), each independently +10%, totaling +20%. HitsPerCast 5->6 once the level-136 'Strike' mastery unlocks.
A3: MAGIC_GUARD | B3: Magic Guard | C3: 1 | D3: =IF(Inputs!$B$3>=21,30*0.7,30) | E3: TRUE | F3: 1 | G3: 0 | H3: 0 | I3: 100 | J3: 1 | K3: 120 | L3: 21 | M3: TRUE | N3: 0 | O3: 0 | P3: 0 | Q3: 1 | R3: ATTACK | S3: 15 | W3: Self-buff, +12%->16.8% Attack (levels 1-100), 15s duration/30s cooldown (Mastery Lv.21 'Magic Guard - Reuse' -30% cooldown -> 21s, baked directly into the Cooldown(s) formula). factorIndex 21, baseDamage 120 tenths%. Shared w/ FP-Mage.
A4: MEDITATION | B4: Meditation | C4: 2 | D4: 30 | E4: TRUE | F4: 1 | G4: 0 | H4: 0 | I4: 100 | J4: 1 | K4: 200 | L4: 21 | M4: TRUE | N4: 0 | O4: 0 | P4: 0 | Q4: 1 | R4: ATTACK | S4: =IF(Inputs!$B$3>=44,15*1.3,15) | W4: Self-buff, +20%->28% Attack (levels 1-100), 15s duration (Mastery Lv.44 'Meditation - Persistence' +30% duration -> 19.5s, baked directly into the BuffDuration(s) formula), 30s cooldown. factorIndex 21, baseDamage 200 tenths%. Shared w/ FP-Mage.
A5: THUNDER_BOLT | B5: Thunder Bolt | C5: 2 | D5: 18 | E5: TRUE | F5: 3 | G5: 0 | H5: 0 | I5: 100 | J5: 1 | K5: 1800 | L5: 12 | M5: TRUE | N5: =SUMPRODUCT((Inputs!$B$3>={39})*{70}) | O5: 0 | P5: 0 | Q5: 8 | S5: 0 | T5: 1000 | U5: 23 | W5: Wiki: 180%->270% (levels 1-100) to 8 target(s) 3 time(s), cooldown 18s. factorIndex 12, baseDamage 1800 tenths%. Mastery Lv.39 'Thunder Bolt - Damage' +70% (single-tier, real SkillMasteryBonus%). Maple Hero (Ice/Lightning) target: 100%->780% (levels 1-200), factorIndex 23, baseDamage 1000 tenths% (jointly reverse-engineered with Glacier Wall's and Thunder Sphere's own Maple Hero curves, confirmed same factorIndex).
A6: GLACIER_WALL | B6: Glacier Wall | C6: 3 | D6: =IF(Inputs!$B$3>=90,22*0.7,22) | E6: TRUE | F6: 3 | G6: 0 | H6: 0 | I6: 100 | J6: 1 | K6: 2900 | L6: 12 | M6: TRUE | N6: =SUMPRODUCT((Inputs!$B$3>={68})*{80}) | O6: 0 | P6: 0 | Q6: 8 | S6: 0 | T6: 300 | U6: 23 | W6: Wiki: 290%->580% (levels 1-200) to 8 target(s) 3 time(s), freezing them for 2s (freeze not modeled — no CC mechanic anywhere in this calculator), cooldown 22s. factorIndex 12, baseDamage 2900 tenths%. Mastery Lv.68 'Glacier Wall - Damage' +80% (real SkillMasteryBonus%), Lv.90 'Glacier Wall - Reuse' -30% cooldown -> 15.4s (baked into the Cooldown(s) formula). Maple Hero target: 30%->234% (levels 1-200), factorIndex 23, baseDamage 300 tenths%.
A7: THUNDER_SPHERE | B7: Thunder Sphere | C7: 3 | D7: =IF(Inputs!$B$3>=78,30*0.7,30) | E7: TRUE | F7: 3 | G7: =IF(Inputs!$B$3>=104,2*0.7,2) | H7: 10 | I7: 100 | J7: 1 | K7: 1000 | L7: 12 | M7: TRUE | N7: =SUMPRODUCT((Inputs!$B$3>={73})*{50}) | O7: 0 | P7: =150+SUMPRODUCT((Inputs!$B$3>={94})*{100}) | Q7: 6 | S7: 0 | T7: 200 | U7: 23 | W7: Wiki: 100%->200% (levels 1-200) to 6 target(s) 3 time(s) every 2s, for a 10s duration, cooldown 30s. factorIndex 12, baseDamage 1000 tenths%. Skill-intrinsic (unconditional, NOT mastery-gated) +150% Normal Monster Damage baked directly into this row's own MasteryNormalDamage% field, PLUS Mastery Lv.94's +100%p on top (so the field itself is '150 + level_gated_sum'). Mastery Lv.73 'Thunder Sphere - Damage' +50% (real SkillMasteryBonus%), Lv.78 'Thunder Sphere - Reuse' -30% cooldown -> 21s, Lv.104 'Thunder Sphere - Strike Interval' -30% tick interval (2s->1.4s, baked into the ICD(s) formula). Maple Hero target: 20%->200% (levels 1-200), factorIndex 23, baseDamage 200 tenths%.
A8: FREEZING_BREATH | B8: Freezing Breath | C8: 4 | D8: 40 | E8: TRUE | F8: 1 | G8: 0.5 | H8: 5 | I8: 100 | J8: 1 | K8: 8000 | L8: 12 | M8: TRUE | N8: =SUMPRODUCT((Inputs!$B$3>={108})*{50}) | O8: 0 | P8: 0 | Q8: 10 | S8: 0 | W8: Wiki: 800%->1600% (levels 1-200) to 10 target(s) every 0.5s for a 5s duration, cooldown 45s (patched -> 40s, Aug 13 2026 patch note — the wiki page itself is stale). factorIndex 12, baseDamage 8000 tenths%. EffectiveHits = 1*(5/0.5) = 10 ticks per cast. Mastery Lv.108 'Freezing Breath - Damage' +50% (real SkillMasteryBonus%). Mastery Lv.118 'Freezing Breath - Weaken' (+15% Damage Taken debuff, 30s) is NOT part of this row — it's a separate global Summary-sheet duty-cycle-averaged monster-damage bonus (see build_summary_sheet, mirrors Night Lord's Venom Lv.82/Frailty Curse Debuff precedent), added in a later build stage.
A9: BLIZZARD | B9: Blizzard | C9: 4 | D9: 33 | E9: TRUE | F9: 3 | G9: 0 | H9: 0 | I9: 100 | J9: 1 | K9: 6000 | L9: 12 | M9: TRUE | N9: =SUMPRODUCT((Inputs!$B$3>={134})*{50}) | O9: 0 | P9: 0 | Q9: 7 | S9: 0 | W9: Wiki: 600%->1200% (levels 1-200) to 5 target(s) 3 time(s) (patched targets 5->7, Aug 13 2026 patch note — the wiki page is stale), cooldown 33s. factorIndex 12, baseDamage 6000 tenths%. Mastery Lv.134 'Blizzard - Damage' +50% (user-confirmed in-game text: 'Blizzard and Blizzard Final Attack damage +50%'; the wiki's Lv.130 '+40%' line was a garbled name/description pairing) — real SkillMasteryBonus%, and the same +50 is applied to the Final Attack row below. Mastery Lv.113 'Blizzard - Final Attack' is its own separate proc row, see BLIZZARD_FINAL_ATTACK below, not part of this row's own fields.
A10: BLIZZARD_FINAL_ATTACK | B10: Blizzard - Final Attack (Mastery Lv.113) | C10: 4 | E10: FALSE | F10: 1 | G10: 1 | H10: 0 | I10: 30 | J10: 1 | K10: 9500 | L10: 21 | M10: TRUE | N10: =SUMPRODUCT((Inputs!$B$3>={134})*{50}) | O10: 0 | P10: 0 | Q10: 1 | S10: 0 | W10: Standalone proc row, same structure as FP-Mage's METEOR_PROC: '[Blizzard in Slot] When attacking, deals ...% additional damage with a 30% chance' + the Aug-13 patch note 'Cooldown set to 1s' => ANY attack can trigger it (30% per attack, 1s ICD), not just Blizzard's own casts (an earlier version modeled Blizzard-only triggers, a large undercount). Steady-state proc rate = (Chance*R)/(1+ICD*Chance*R) where R is the combined cast rate of the triggering attacks (Summary!BLIZZARD_TRIGGER_RATE): Chain Lightning's cast rate + one trigger per cast of Thunder Bolt/Glacier Wall/Freezing Breath/Frozen Orb + 3 per Blizzard cast (its 3 frost spears are independent triggers, same convention as Meteor Shower in FP-Mage). ASSUMPTION (mirrors FP-Mage's user-confirmed trigger set): summons and damage-over-time ticks (Thunder Sphere, Elquines) do not trigger it. This row has NO cooldown of its own (RollsPerCast=1: Chance applies per triggering attack; ICD(s)=1 is the internal cooldown, ActiveWindow=0 so EffectiveHits is unused). Mastery Lv.134 'Blizzard - Damage' also boosts this row by +50 (same SkillMasteryBonus% as Blizzard). Wiki formula ({#expr:750*(1+x*0.004)}%, patched base 750->950%, chance 20%->30%): reverse-engineered as factorIndex 21, baseDamage 9500 tenths% (950%, already the patched value). Single-target (NormalMonsterTargets=1), matching FP-Mage's own Meteor Proc precedent for an 'additional damage on a hit' style proc, absent any wiki text specifying a target count of its own.
A11: FROZEN_ORB | B11: Frozen Orb | C11: 4 | D11: 23 | E11: TRUE | F11: 1 | G11: =IF(Inputs!$B$3>=126,0.5-0.2,0.5) | H11: 6 | I11: 100 | J11: 1 | K11: 9000 | L11: 12 | M11: TRUE | N11: =SUMPRODUCT((Inputs!$B$3>={122})*{50}) | O11: 0 | P11: 0 | Q11: 10 | S11: 0 | W11: Wiki: 900%->1800% (levels 1-200) to 10 target(s) every 0.5s for a 5s duration (patched -> 6s, Aug 13 2026 patch note), cooldown 23s. factorIndex 12, baseDamage 9000 tenths%. 'If there is 1 target near the orb, the damage is halved' — a single-target (boss) halving mechanic implemented ONLY in this row's own Calc!O (DPS) formula in a later build stage (x0.5 when monster_type=boss, x1 otherwise), not a Skills-sheet field. Mastery Lv.122 'Frozen Orb - Damage' +50% (real SkillMasteryBonus%), Lv.126 'Frozen Orb - Strike Interval' -0.2 SEC tick interval (0.5s->0.3s, baked into the ICD(s) formula; user-confirmed in-game text — earlier versions had this as -50% at Lv.134, a garbled wiki pairing).
A12: ELQUINES | B12: Elquines | C12: 4 | D12: 80 | E12: TRUE | F12: 1 | G12: =IF(Inputs!$B$3>=130,4*0.8,4) | H12: 30 | I12: 100 | J12: 1 | K12: 35000 | L12: 12 | M12: TRUE | N12: =SUMPRODUCT((Inputs!$B$3>={138})*{50}) | O12: 0 | P12: 0 | Q12: =IF(Inputs!$B$3>=138,6,3) | S12: 0 | W12: Summon, wiki: 3500%->7000% (levels 1-200) to 3 target(s) every 4s for a 30s duration, cooldown 80s. factorIndex 12, baseDamage 35000 tenths%. Mastery Lv.130 'Elquines - Strike Interval' -20% attack interval (4s->3.2s, baked into the ICD(s) formula; the wiki prints a typo'd '0.2%' on the Lv.126 row, an earlier session recorded the user confirming 20%, and BOTH sources' mastery NAMES put Elquines-Strike Interval at Lv.130 — the level was moved 126->130 on that basis; the exact in-game text is still unverified), Lv.138 'Elquines - Damage & Target' +50% damage (real SkillMasteryBonus%) AND +3 max targets (3->6, baked into the NormalMonsterTargets formula).
A13: MP_EATER_MP_BOOST | B13: MP Eater - MP Boost (Mastery Lv.49) | C13: 2 | E13: FALSE | F13: 1 | G13: 0 | H13: 0 | I13: 100 | J13: 1 | K13: 70 | L13: 0 | M13: FALSE | N13: 0 | O13: 0 | P13: 0 | Q13: 1 | S13: 0 | W13: Mastery-only row (MP Eater's own base MP-recovery mechanic is not modeled — MP isn't tracked anywhere in this calculator). Flat +7% Attack Speed once unlocked (level 49, see UNLOCK_LEVEL's own note on the 47-vs-49 discrepancy), ignoring the MP>=50% condition per the user's always-on decision (same treatment as Element Amplification). This IS a real, always-on contributor (NOT baked into Inputs, unlike the Magic-Critical-pattern rows below) — folds into the Attack Speed diminishing-returns stack in Summary once unlocked, with no uptime averaging (it's a permanent passive, not a timed buff — BuffTargetStat deliberately left blank so the generic buff-uptime machinery doesn't try to average it; Summary reads this row's Calc!F and Calc!C directly instead). FactorIndex is an unused placeholder (ScalesWithLevel=False), same convention as Nimble Feet's own non-scaling row in FP-Mage/Night Lord.
A14: ELEMENTAL_RESET | B14: Elemental Reset | C14: 3 | E14: FALSE | F14: 1 | G14: 0 | H14: 0 | I14: =IF(Inputs!$B$3>=82,50,25) | J14: 1 | K14: 120 | L14: 22 | M14: TRUE | N14: 0 | O14: 0 | P14: 0 | Q14: 1 | S14: 7 | W14: User-confirmed: this is the patch note's 'Elemental Decrease' entry (patched base chance 20%->25%, base Damage Taken 10%->12% — the wiki's own 10%->16% curve rescaled by the patch's 12/10=1.2x factor, giving the reverse-engineered factorIndex 22/baseDamage 120 used here, which already reflects the patched 12%->19.2% curve). Mastery Lv.82 'Elemental Reset - Chance' doubles the PATCHED chance (25%->50%, NOT the stale wiki 20%->40%). Modeled always-on (100% uptime), same precedent as FP-Mage's own Elemental Decrease — ProcChance%/BuffDuration(s) here are reference-only, they do not feed the Summary formula (which instead just adds Calc!F/100 as an unconditional multiplier).
A15: ELEMENT_AMPLIFICATION | B15: Element Amplification | C15: 3 | E15: FALSE | F15: 1 | G15: 0 | H15: 0 | I15: 100 | J15: 1 | K15: 150 | L15: 22 | M15: TRUE | N15: 0 | O15: 0 | P15: 0 | Q15: 1 | R15: FINAL_DAMAGE | S15: 0 | W15: Wiki: +15%->24% Final Damage (levels 1-200), unconditional (ignore the MP>=50% condition and MP-cost increase per the user's decision, matching FP-Mage's own established treatment of this exact shared-kit passive). factorIndex 22, baseDamage 150 tenths%. Not reflected anywhere in Inputs — added directly into the Final Damage chain (multiplied in, same as Arcane Aim/Element Amplification are combined in FP-Mage) in a later build stage.
A16: INFINITY | B16: Infinity | C16: 4 | D16: 30 | E16: TRUE | F16: 1 | G16: 0 | H16: 0 | I16: 100 | J16: 1 | K16: 150 | L16: 21 | M16: TRUE | N16: 0 | O16: 0 | P16: 0 | Q16: 1 | R16: FINAL_DAMAGE | S16: 15 | W16: Wiki: base +15%->27% Final Damage for 15s, ADDITIONALLY +1%->1.8% per second, stacking up to 10 times (levels 1-200), cooldown 30s. Both curves reverse-engineered independently: base factorIndex 21/baseDamage 150 tenths%, increment factorIndex 21/baseDamage 10 tenths% — the increment is EXACTLY base/15 at every sampled level (zero residual error), confirming the ramp is a fixed fraction of the base, not an independently-scaled curve. Time-averaged stacks over the 15s window = (0+1+...+9+10*5)/15 = 6.3333, so the time-averaged total = base*(1+6.3333/15) = base*64/45 exactly. This row's own Calc!F needs a BESPOKE formula in build_calc_sheet (base_pct * 64/45, using the single factorIndex-21 lookup for 'base_pct') instead of the generic F-column formula every other row uses — flagged here so the Calc-sheet build stage doesn't miss it.
A17: MAGIC_ACCELERATION | B17: Magic Acceleration | C17: 2 | E17: FALSE | F17: 1 | G17: 0 | H17: 0 | I17: 100 | J17: 1 | K17: 50 | L17: 22 | M17: TRUE | N17: 0 | O17: 0 | P17: 0 | Q17: 1 | R17: ATTACK_SPEED | S17: 0 | W17: Permanent passive, +5%->6.5% Attack Speed (levels 1-100) — Magic Critical pattern, already baked into Inputs!ATTACK_SPEED%; this row only feeds the 2nd-Job Skill Level Bonus Sensitivity delta. factorIndex 22, baseDamage 50 tenths%.
A18: SPELL_MASTERY | B18: Spell Mastery | C18: 2 | E18: FALSE | F18: 1 | G18: 0 | H18: 0 | I18: 100 | J18: 1 | K18: 150 | L18: 22 | M18: TRUE | N18: 0 | O18: 0 | P18: 0 | Q18: 1 | R18: MIN_DAMAGE | S18: 0 | W18: Permanent passive, +15%->19.5% Min Damage Multiplier (levels 1-100) — Magic Critical pattern, already baked into Inputs!MIN_DAMAGE%; feeds the 2nd-Job Skill Level Bonus delta. factorIndex 22, baseDamage 150 tenths%.
A19: HIGH_WISDOM | B19: High Wisdom | C19: 2 | E19: FALSE | F19: 1 | G19: 0 | H19: 0 | I19: 100 | J19: 1 | K19: 80 | L19: 22 | M19: TRUE | N19: 0 | O19: 0 | P19: 0 | Q19: 1 | R19: CRIT_RATE | S19: 0 | W19: Permanent passive, +8%->10.4% Critical Rate (levels 1-100) — Magic Critical pattern, already baked into Inputs!CRIT_RATE% (jointly with Magic Critical (Crit Rate) below, both are separate skills contributing to the same Inputs field); feeds the 2nd-Job Skill Level Bonus delta. factorIndex 22, baseDamage 80 tenths%.
A20: MAGIC_CRITICAL_RATE | B20: Magic Critical (Crit Rate) | C20: 3 | E20: FALSE | F20: 1 | G20: 0 | H20: 0 | I20: 100 | J20: 1 | K20: 80 | L20: 22 | M20: TRUE | N20: 0 | O20: 0 | P20: 0 | Q20: 1 | R20: CRIT_RATE | S20: 0 | W20: Permanent passive, +8%->12.8% Critical Rate (levels 1-200) — Magic Critical pattern, already baked into Inputs!CRIT_RATE%; feeds the 3rd-Job Skill Level Bonus delta. factorIndex 22, baseDamage 80 tenths%.
A21: MAGIC_CRITICAL_DAMAGE | B21: Magic Critical (Crit Damage) | C21: 3 | E21: FALSE | F21: 1 | G21: 0 | H21: 0 | I21: 100 | J21: 1 | K21: 120 | L21: 22 | M21: TRUE | N21: 0 | O21: 0 | P21: 0 | Q21: 1 | R21: CRIT_DAMAGE | S21: 0 | W21: Same skill as Magic Critical (Crit Rate) above, +12%->19.2% Critical Damage (levels 1-200) — Magic Critical pattern, already baked into Inputs!CRIT_DAMAGE%; feeds the 3rd-Job Skill Level Bonus delta. factorIndex 22, baseDamage 120 tenths%.
A22: BUFF_MASTERY | B22: Buff Mastery | C22: 4 | E22: FALSE | F22: 1 | G22: 0 | H22: 0 | I22: 100 | J22: 1 | K22: 100 | L22: 22 | M22: TRUE | N22: 0 | O22: 0 | P22: 0 | Q22: 1 | S22: 0 | W22: Permanent passive (unlocked level 117), +10%->16% Buff Duration (levels 1-200) — not added on top of Inputs: Inputs!buff_duration_increase_pct already includes it (confirmed by the user). Informational row only. factorIndex 22, baseDamage 100 tenths%. Shared w/ FP-Mage.
A23: ARCANE_AIM | B23: Arcane Aim | C23: 4 | E23: FALSE | F23: 1 | G23: 0 | H23: 0 | I23: 100 | J23: 1 | K23: 30 | L23: 22 | M23: TRUE | N23: 0 | O23: 0 | P23: 0 | Q23: 1 | S23: 0 | W23: Permanent passive (unlocked level 120), 25% chance per attack for +3%->4.8% Final Damage (levels 1-200) for 10s, stacking up to 5 times — modeled as always at max 5 stacks (same always-on-proc-stack precedent as Elemental Reset/FP-Mage's own Arcane Aim). Combined MULTIPLICATIVELY into the Final Damage chain as (1+Calc!F/100)^5 in a later build stage. factorIndex 22, baseDamage 30 tenths%. Shared w/ FP-Mage.
A24: NIMBLE_FEET | B24: Nimble Feet | C24: 1 | D24: 60 | E24: TRUE | F24: 1 | G24: 0 | H24: 0 | I24: 100 | J24: 1 | K24: 150 | L24: 0 | M24: FALSE | N24: 0 | O24: 0 | P24: 0 | Q24: 1 | R24: ATTACK_SPEED | S24: 15 | W24: Universal 1st-Job Explorer skill (identical wording on both idle.maplestorywiki.net and maplestoryidle.info — 'Increases Attack Speed by 15% and Speed by 10% for 15 sec', 60s cooldown, reqLevel 5) — was missing from this workbook entirely (a real gap found by cross-class comparison, not a class-design difference: Bowmaster/Dark Knight/FP-Mage/Hero/Marksman/Night Lord/Paladin/Shadower all already have it). Flat +15% Attack Speed / +10% Speed for 15s, non-scaling. Speed component not modeled (no Speed stat anywhere in this project). FactorIndex unused placeholder.

Sheet Artifacts
A1: Arch Mage (Ice/Lightning) — Artifacts (Equip Effect)
A3: Book of Ancient — Crit Damage (from Crit Rate, reference only) | B3: =IF(ArtifactsInput!$M$24,CHOOSE(ArtifactsInput!$N$24+1,30,36,42,48,54,60)/100*(Inputs!$B$9+B5+B29),0)
A4: Ring of Cycles — Threshold Crit Rate (excl. self) | B4: =Inputs!$B$9+B29
A5: Ring of Cycles — Crit Rate (if threshold < 100%) | B5: =IF(AND(Inputs!$B$38<>"pvp",Inputs!$B$43=0),1,IF(IF(Inputs!$B$38="pvp",15,Inputs!$B$43)-(Summary!$B$21)<=0,1,MAX(0,IF(Inputs!$B$38="pvp",15,Inputs!$B$43)-MAX(5,Summary!$B$21))/(IF(Inputs!$B$38="pvp",15,Inputs!$B$43)-(Summary!$B$21))))*IF(AND(ArtifactsInput!$M$42,B4<100),CHOOSE(ArtifactsInput!$N$42+1,30,36,42,48,54,60),0)
A6: Ring of Cycles — Skill Damage (if threshold >= 100%) | B6: =IF(AND(Inputs!$B$38<>"pvp",Inputs!$B$43=0),1,IF(IF(Inputs!$B$38="pvp",15,Inputs!$B$43)-(Summary!$B$21)<=0,1,MAX(0,IF(Inputs!$B$38="pvp",15,Inputs!$B$43)-MAX(5,Summary!$B$21))/(IF(Inputs!$B$38="pvp",15,Inputs!$B$43)-(Summary!$B$21))))*IF(AND(ArtifactsInput!$M$42,B4>=100),CHOOSE(ArtifactsInput!$N$42+1,40,48,56,64,72,80),0)
A7: Ring of Cycles — Excess-100% Points (capped at 100) | B7: =IF(AND(ArtifactsInput!$M$42,B4>=100),MIN(100,B4-100),0)
A8: Ring of Cycles — Basic Attack Damage (excess points x per-point) | B8: =IF(AND(Inputs!$B$38<>"pvp",Inputs!$B$43=0),1,IF(IF(Inputs!$B$38="pvp",15,Inputs!$B$43)-(Summary!$B$21)<=0,1,MAX(0,IF(Inputs!$B$38="pvp",15,Inputs!$B$43)-MAX(5,Summary!$B$21))/(IF(Inputs!$B$38="pvp",15,Inputs!$B$43)-(Summary!$B$21))))*B7*CHOOSE(ArtifactsInput!$N$42+1,0.6,0.72,0.84,0.96,1.08,1.2)
A9: Candle — Effective Fight Duration | B9: =IF(Inputs!$B$38="pvp",15,Inputs!$B$43)
A10: Candle — Effective Active (fixed-duration or PvP) | B10: =IF(Inputs!$B$38="pvp",TRUE,AND(Inputs!$B$38<>"pvp",Inputs!$B$43>0))
A11: Candle — Final Damage (100% uptime, patched) | B11: =IF(AND(ArtifactsInput!$M$36,B10),CHOOSE(ArtifactsInput!$N$36+1,8,9.6,11.2,12.8,14.4,16),0)
A12: Candle — Boss Monster Damage (20-40s window / boss-present-time uptime, patched) | B12: =IF(AND(ArtifactsInput!$M$36,B10),MAX(0,MIN(40,B9)-MAX(20,B41))/(B9-B41)*CHOOSE(ArtifactsInput!$N$36+1,30,36,42,48,54,60),0)
A13: Peach Tree Herb Pouch — Proc Rate (per second) | B13: =0.2*Summary!$B$17
A14: Peach Tree Herb Pouch — Uptime (refreshing 5s timer) | B14: =1-EXP(-B13*5)
A15: Peach Tree Herb Pouch — Enemy Damage Taken | B15: =IF(AND(ArtifactsInput!$M$35,Inputs!$B$4<>"Chapter Hunt"),CHOOSE(ArtifactsInput!$N$35+1,15,18,21,24,27,30)*B14,0)
A16: Silver Pendant — Offered Load (rho = lambda x duration) | B16: =0.15*Summary!$B$17*5
A17: Silver Pendant — Erlang Loss Weight (n=0) | B17: =B16^0/1
A18: Silver Pendant — Erlang Loss Weight (n=1) | B18: =B16^1/1
A19: Silver Pendant — Erlang Loss Weight (n=2) | B19: =B16^2/2
A20: Silver Pendant — Erlang Loss Weight (n=3) | B20: =B16^3/6
A21: Silver Pendant — Erlang Loss Weight (n=4) | B21: =B16^4/24
A22: Silver Pendant — Erlang Loss Weight (n=5) | B22: =B16^5/120
A23: Silver Pendant — Average Stacks (Erlang-loss mean) | B23: =(0*B17+1*B18+2*B19+3*B20+4*B21+5*B22)/(B17+B18+B19+B20+B21+B22)
A24: Silver Pendant — Enemy Damage Taken | B24: =IF(AND(ArtifactsInput!$M$22,Inputs!$B$4<>"Chapter Hunt"),CHOOSE(ArtifactsInput!$N$22+1,10,12,14,16,18,20)*B23,0)
A25: Athena Pierce's Old Gloves — Max Damage (from Attack Speed, reference only) | B25: =IF(ArtifactsInput!$M$15,CHOOSE(ArtifactsInput!$N$15+1,25,30,35,40,45,50)/100*Inputs!$B$11,0)
A26: Hexagon Necklace — Average Stacks | B26: =IF(AND(Inputs!$B$38<>"pvp",Inputs!$B$43=0),3,IF(IF(Inputs!$B$38="pvp",15,Inputs!$B$43)<=20,0,IF(IF(Inputs!$B$38="pvp",15,Inputs!$B$43)<=40,(IF(Inputs!$B$38="pvp",15,Inputs!$B$43)-20)/IF(Inputs!$B$38="pvp",15,Inputs!$B$43),IF(IF(Inputs!$B$38="pvp",15,Inputs!$B$43)<=60,(2*IF(Inputs!$B$38="pvp",15,Inputs!$B$43)-60)/IF(Inputs!$B$38="pvp",15,Inputs!$B$43),(3*IF(Inputs!$B$38="pvp",15,Inputs!$B$43)-120)/IF(Inputs!$B$38="pvp",15,Inputs!$B$43)))))
A27: Hexagon Necklace — Damage % | B27: =IF(ArtifactsInput!$M$11,CHOOSE(ArtifactsInput!$N$11+1,15,18,21,24,27,30)*B26,0)
A28: Rainbow-colored Snail Shell — Uptime (0-15s window) | B28: =IF(Inputs!$B$38="pvp",MIN(15,15)/15,IF(AND(Inputs!$B$38<>"pvp",Inputs!$B$43>0),MIN(15,Inputs!$B$43)/Inputs!$B$43,0))
A29: Rainbow-colored Snail Shell — Crit Rate | B29: =IF(ArtifactsInput!$M$10,CHOOSE(ArtifactsInput!$N$10+1,15,18,21,24,27,30)*B28,0)
A30: Rainbow-colored Snail Shell — Crit Damage | B30: =IF(ArtifactsInput!$M$10,CHOOSE(ArtifactsInput!$N$10+1,20,24,28,32,36,40)*B28,0)
A32: TOTAL — Artifact Crit Rate Bonus | B32: =B5+B29
A33: TOTAL — Artifact Crit Damage Bonus | B33: =B30+B47
A34: TOTAL — Artifact Final Damage Bonus (equivalent %, each real source combines MULTIPLICATIVELY — Candle x Flaming Lava x Horn Flute, not summed) | B34: =((1+B11/100)*(1+B46/100)*(1+B55/100)-1)*100
A35: TOTAL — Artifact Boss Monster Damage Bonus | B35: =B12+B60
A36: TOTAL — Artifact Enemy Damage Taken Bonus | B36: =B15+B24
A38: TOTAL — Artifact Damage Bonus (own separate final multiplier — not blended into Inputs!DAMAGE%) | B38: =B27
A39: TOTAL — Artifact Skill Damage Bonus | B39: =B6
A40: TOTAL — Artifact Basic Attack Damage Bonus | B40: =B8
A41: Candle — Boss Appear Time (Breakthrough/Hero Dungeon only) | B41: =IF(Inputs!$B$4="Breakthrough",20,IF(Inputs!$B$4="Hero Dungeon",30,0))
A42: Clear Spring Water — Final Damage (reference only, Growth Dungeon types) | B42: =IF(AND(ArtifactsInput!$M$14,OR(Inputs!$B$4="Weapon Dungeon",Inputs!$B$4="Equipment Dungeon",Inputs!$B$4="Enhancement Dungeon",Inputs!$B$4="EXP Dungeon",Inputs!$B$4="Hero Dungeon")),CHOOSE(ArtifactsInput!$N$14+1,10,12,14,16,18,20),0)
A43: Old Music Box — Attack % (content-type uptime assumption) | B43: =IF(ArtifactsInput!$M$21,CHOOSE(ArtifactsInput!$N$21+1,25,30,35,40,45,50)*(IF(OR(Inputs!$B$4="Chapter Hunt",Inputs!$B$4="Breakthrough",Inputs!$B$4="Weapon Dungeon",Inputs!$B$4="Equipment Dungeon",Inputs!$B$4="Enhancement Dungeon",Inputs!$B$4="EXP Dungeon",Inputs!$B$4="Hero Dungeon"),0,IF(OR(Inputs!$B$4="World Boss",Inputs!$B$4="PvP"),1,IF(Inputs!$B$4="Chapter Boss",60/70,0)))),0)
...

Sheet Calc
A1: Key | B1: Name | C1: Unlocked | D1: InputLevel | E1: Factor | F1: CoefficientPercent | G1: EffectiveHits | H1: ProcProbability | I1: MapleHeroMultiplier | J1: BaseDamage | K1: BaseHitDamage | L1: NonCritAvg | M1: CritAvg | N1: ExpectedDamage(perHit) | O1: DPS | P1: % of Total | Q1: InvCooldown | R1: CastsInFight | S1: BossOnlyDPS | U1: NormalOnlyDPS | Z1: Maple Hero helper (jobStep4, factorIndex23)
A2: =Skills!A2 | B2: =Skills!B2 | C2: =Inputs!$B$3>=100 | F2: =Summary!$B$10+Skills!N2 | G2: =Skills!F2*IF(Skills!G2>0,Skills!H2/Skills!G2,1) | H2: =1-(1-Skills!I2/100)^Skills!J2 | I2: =IF(Skills!T2<>"",1+(Skills!T2/10)*($Z$3/1000)/100,1) | J2: =Summary!$B$6*(F2/100) | K2: =J2*(1+Summary!$B$7/100)*(1+(Inputs!$B$15+Summary!$B$15)/100)*(1+Inputs!$B$16/100)*(5000/(6000+Inputs!$B$42*(1-Inputs!$B$19/100)))*(1+Inputs!$B$24/100)*(1+Artifacts!$B$34/100)*(1+IF(C15=TRUE,F15,0)/100)*(1+IF(C23=TRUE,F23,0)/100)^5*(1+(IF(Skills!A2="CHAIN_LIGHTNING",Inputs!$B$17+Artifacts!$B$40,Inputs!$B$18+Artifacts!$B$39))/100)*(Summary!$B$13*(1+Artifacts!$B$38/100)*I2) | L2: =K2*(MIN(Inputs!$B$22,Inputs!$B$23)/100+Inputs!$B$23/100)/2 | M2: =L2*(1+(Inputs!$B$10+Artifacts!$B$33)/100) | N2: =L2*(1-MIN((Inputs!$B$9+Artifacts!$B$32),100)/100)+M2*(MIN((Inputs!$B$9+Artifacts!$B$32),100)/100) | O2: =(1-Summary!$B$11)*S2+Summary!$B$11*U2 | P2: =IF(Summary!$B$3=0,0,O2/Summary!$B$3) | Q2: =IFERROR(1/(IF(Inputs!$B$38="pvp",15,MAX(0.1,Skills!D2-IF(TRUE=TRUE,Inputs!$B$32,0)))*(1-IF(AND(ArtifactsInput!$M$27,Inputs!$B$4="Chapter Hunt"),CHOOSE(ArtifactsInput!$N$27+1,20,24,28,32,36,40),0)/100)),0) | R2: 0 | S2: =IF(C2,(Skills!F2*N2*Summary!$B$19)*IF(Inputs!$B$38="pvp",1,1+(Inputs!$B$20+Skills!O2+Summary!$B$14+Artifacts!$B$35)/100)*((((5000/(6000+Inputs!$B$42*(1-(100*(1-(1-Inputs!$B$19/100)*(1-Artifacts!$B$51/100)^IF(Inputs!$B$38="pvp",1,2)))/100)))/(5000/(6000+Inputs!$B$42*(1-Inputs!$B$19/100))))*((L2*(1-MIN(100,(Inputs!$B$9+Artifacts!$B$32)+Artifacts!$B$69)/100)+M2*(MIN(100,(Inputs!$B$9+Artifacts!$B$32)+Artifacts!$B$69)/100))/(L2*(1-MIN(100,(Inputs!$B$9+Artifacts!$B$32))/100)+M2*(MIN(100,(Inputs!$B$9+Artifacts!$B$32))/100)))*(1+Artifacts!$B$81/100))),0) | U2: =IF(C2,(Skills!F2*N2*Summary!$B$19)*IF(Inputs!$B$38="pvp",1,(1+(Inputs!$B$21+Skills!P2+Summary!$B$14+Artifacts!$B$80)/100)*(MIN(Skills!Q2,Inputs!$B$37)))*((1+Artifacts!$B$53/100)),0) | Z2: =MAX(0,(Inputs!$B$3-100)*3)+Inputs!$B$28+Inputs!$B$29
A3: =Skills!A3 | B3: =Skills!B3 | C3: =Inputs!$B$3>=15 | D3: =IF(Skills!C3=1,60+Inputs!$B$25+Inputs!$B$29,IF(Skills!C3=2,90+Inputs!$B$26+Inputs!$B$29,IF(Skills!C3=3,120+Inputs!$B$27+Inputs!$B$29,MAX(0,(Inputs!$B$3-100)*3)+Inputs!$B$28+Inputs!$B$29))) | E3: =INDEX(FactorTable!$B$2:$Y$301, MATCH(ROUND(MIN(300,MAX(1,D3)),0), FactorTable!$A$2:$A$301,0), Skills!L3+1) | F3: =IF(Skills!M3=TRUE,(Skills!K3/10)*(E3/1000),Skills!K3/10)+Skills!N3 | G3: =Skills!F3*IF(Skills!G3>0,Skills!H3/Skills!G3,1) | H3: =1-(1-Skills!I3/100)^Skills!J3 | I3: =IF(Skills!T3<>"",1+(Skills!T3/10)*($Z$3/1000)/100,1) | O3: =(1-Summary!$B$11)*S3+Summary!$B$11*U3 | P3: =IF(Summary!$B$3=0,0,O3/Summary!$B$3) | Q3: =IFERROR(1/(IF(Inputs!$B$38="pvp",15,MAX(0.1,Skills!D3-IF(TRUE=TRUE,Inputs!$B$32,0)))*(1-IF(AND(ArtifactsInput!$M$27,Inputs!$B$4="Chapter Hunt"),CHOOSE(ArtifactsInput!$N$27+1,20,24,28,32,36,40),0)/100)),0) | R3: =IF(AND(Inputs!$B$38<>"pvp",Inputs!$B$43>0),IF(Inputs!$B$43<=0,0,(INT(Inputs!$B$43/(IF(Inputs!$B$38="pvp",15,MAX(0.1,Skills!D3-IF(TRUE=TRUE,Inputs!$B$32,0)))*(1-IF(AND(ArtifactsInput!$M$27,Inputs!$B$4="Chapter Hunt"),CHOOSE(ArtifactsInput!$N$27+1,20,24,28,32,36,40),0)/100)))+1)),0) | S3: 0 | U3: 0 | Z3: =INDEX(FactorTable!$B$2:$Y$301, MATCH(ROUND(MIN(300,MAX(1,Z2)),0), FactorTable!$A$2:$A$301,0), 24)
A4: =Skills!A4 | B4: =Skills!B4 | C4: =Inputs!$B$3>=40 | D4: =IF(Skills!C4=1,60+Inputs!$B$25+Inputs!$B$29,IF(Skills!C4=2,90+Inputs!$B$26+Inputs!$B$29,IF(Skills!C4=3,120+Inputs!$B$27+Inputs!$B$29,MAX(0,(Inputs!$B$3-100)*3)+Inputs!$B$28+Inputs!$B$29))) | E4: =INDEX(FactorTable!$B$2:$Y$301, MATCH(ROUND(MIN(300,MAX(1,D4)),0), FactorTable!$A$2:$A$301,0), Skills!L4+1) | F4: =IF(Skills!M4=TRUE,(Skills!K4/10)*(E4/1000),Skills!K4/10)+Skills!N4 | G4: =Skills!F4*IF(Skills!G4>0,Skills!H4/Skills!G4,1) | H4: =1-(1-Skills!I4/100)^Skills!J4 | I4: =IF(Skills!T4<>"",1+(Skills!T4/10)*($Z$3/1000)/100,1) | O4: =(1-Summary!$B$11)*S4+Summary!$B$11*U4 | P4: =IF(Summary!$B$3=0,0,O4/Summary!$B$3) | Q4: =IFERROR(1/(IF(Inputs!$B$38="pvp",15,MAX(0.1,Skills!D4-IF(TRUE=TRUE,Inputs!$B$32,0)))*(1-IF(AND(ArtifactsInput!$M$27,Inputs!$B$4="Chapter Hunt"),CHOOSE(ArtifactsInput!$N$27+1,20,24,28,32,36,40),0)/100)),0) | R4: =IF(AND(Inputs!$B$38<>"pvp",Inputs!$B$43>0),IF(Inputs!$B$43<=0,0,(INT(Inputs!$B$43/(IF(Inputs!$B$38="pvp",15,MAX(0.1,Skills!D4-IF(TRUE=TRUE,Inputs!$B$32,0)))*(1-IF(AND(ArtifactsInput!$M$27,Inputs!$B$4="Chapter Hunt"),CHOOSE(ArtifactsInput!$N$27+1,20,24,28,32,36,40),0)/100)))+1)),0) | S4: 0 | U4: 0
A5: =Skills!A5 | B5: =Skills!B5 | C5: =Inputs!$B$3>=38 | D5: =IF(Skills!C5=1,60+Inputs!$B$25+Inputs!$B$29,IF(Skills!C5=2,90+Inputs!$B$26+Inputs!$B$29,IF(Skills!C5=3,120+Inputs!$B$27+Inputs!$B$29,MAX(0,(Inputs!$B$3-100)*3)+Inputs!$B$28+Inputs!$B$29))) | E5: =INDEX(FactorTable!$B$2:$Y$301, MATCH(ROUND(MIN(300,MAX(1,D5)),0), FactorTable!$A$2:$A$301,0), Skills!L5+1) | F5: =IF(Skills!M5=TRUE,(Skills!K5/10)*(E5/1000),Skills!K5/10)+Skills!N5 | G5: =Skills!F5*IF(Skills!G5>0,Skills!H5/Skills!G5,1) | H5: =1-(1-Skills!I5/100)^Skills!J5 | I5: =IF(Skills!T5<>"",1+(Skills!T5/10)*($Z$3/1000)/100,1) | J5: =Summary!$B$6*(F5/100) | K5: =J5*(1+Summary!$B$7/100)*(1+(Inputs!$B$15+Summary!$B$15)/100)*(1+Inputs!$B$16/100)*(5000/(6000+Inputs!$B$42*(1-Inputs!$B$19/100)))*(1+Inputs!$B$24/100)*(1+Artifacts!$B$34/100)*(1+IF(C15=TRUE,F15,0)/100)*(1+IF(C23=TRUE,F23,0)/100)^5*(1+(IF(Skills!A5="CHAIN_LIGHTNING",Inputs!$B$17+Artifacts!$B$40,Inputs!$B$18+Artifacts!$B$39))/100)*(Summary!$B$13*(1+Artifacts!$B$38/100)*I5) | L5: =K5*(MIN(Inputs!$B$22,Inputs!$B$23)/100+Inputs!$B$23/100)/2 | M5: =L5*(1+(Inputs!$B$10+Artifacts!$B$33)/100) | N5: =L5*(1-MIN((Inputs!$B$9+Artifacts!$B$32),100)/100)+M5*(MIN((Inputs!$B$9+Artifacts!$B$32),100)/100) | O5: =(1-Summary!$B$11)*S5+Summary!$B$11*U5 | P5: =IF(Summary!$B$3=0,0,O5/Summary!$B$3) | Q5: =IFERROR(1/(IF(Inputs!$B$38="pvp",15,MAX(0.1,Skills!D5-IF(TRUE=TRUE,Inputs!$B$32,0)))*(1-IF(AND(ArtifactsInput!$M$27,Inputs!$B$4="Chapter Hunt"),CHOOSE(ArtifactsInput!$N$27+1,20,24,28,32,36,40),0)/100)),0) | R5: =IF(AND(Inputs!$B$38<>"pvp",Inputs!$B$43>0),IF(MAX(0,Inputs!$B$43-Summary!$B$21)<=0,0,(INT(MAX(0,Inputs!$B$43-Summary!$B$21)/(IF(Inputs!$B$38="pvp",15,MAX(0.1,Skills!D5-IF(TRUE=TRUE,Inputs!$B$32,0)))*(1-IF(AND(ArtifactsInput!$M$27,Inputs!$B$4="Chapter Hunt"),CHOOSE(ArtifactsInput!$N$27+1,20,24,28,32,36,40),0)/100)))+1)),0) | S5: =IF(C5,(H5*N5*IF(AND(Inputs!$B$38<>"pvp",Inputs!$B$43>0),((Skills!F5*((R5-1)*IF(Skills!G5>0,Skills!H5/Skills!G5,1)+IF(Skills!G5>0,MIN(Skills!H5,MAX(0,MAX(0,Inputs!$B$43-Summary!$B$21)-((R5-1)*(IF(Inputs!$B$38="pvp",15,MAX(0.1,Skills!D5-IF(TRUE=TRUE,Inputs!$B$32,0)))*(1-IF(AND(ArtifactsInput!$M$27,Inputs!$B$4="Chapter Hunt"),CHOOSE(ArtifactsInput!$N$27+1,20,24,28,32,36,40),0)/100)))))/Skills!G5,1)))/Inputs!$B$43),G5*Q5))*IF(Inputs!$B$38="pvp",1,1+(Inputs!$B$20+Skills!O5+Summary!$B$14+Artifacts!$B$35)/100)*((((5000/(6000+Inputs!$B$42*(1-(100*(1-(1-Inputs!$B$19/100)*(1-Artifacts!$B$51/100)^IF(Inputs!$B$38="pvp",1,2)))/100)))/(5000/(6000+Inputs!$B$42*(1-Inputs!$B$19/100))))*((L5*(1-MIN(100,(Inputs!$B$9+Artifacts!$B$32)+Artifacts!$B$69)/100)+M5*(MIN(100,(Inputs!$B$9+Artifacts!$B$32)+Artifacts!$B$69)/100))/(L5*(1-MIN(100,(Inputs!$B$9+Artifacts!$B$32))/100)+M5*(MIN(100,(Inputs!$B$9+Artifacts!$B$32))/100)))*(1+Artifacts!$B$81/100))),0) | U5: =IF(C5,(H5*N5*IF(AND(Inputs!$B$38<>"pvp",Inputs!$B$43>0),((Skills!F5*((R5-1)*IF(Skills!G5>0,Skills!H5/Skills!G5,1)+IF(Skills!G5>0,MIN(Skills!H5,MAX(0,MAX(0,Inputs!$B$43-Summary!$B$21)-((R5-1)*(IF(Inputs!$B$38="pvp",15,MAX(0.1,Skills!D5-IF(TRUE=TRUE,Inputs!$B$32,0)))*(1-IF(AND(ArtifactsInput!$M$27,Inputs!$B$4="Chapter Hunt"),CHOOSE(ArtifactsInput!$N$27+1,20,24,28,32,36,40),0)/100)))))/Skills!G5,1)))/Inputs!$B$43),G5*Q5))*IF(Inputs!$B$38="pvp",1,(1+(Inputs!$B$21+Skills!P5+Summary!$B$14+Artifacts!$B$80)/100)*(MIN(Skills!Q5,Inputs!$B$37)))*((1+Artifacts!$B$53/100)),0)
A6: =Skills!A6 | B6: =Skills!B6 | C6: =Inputs!$B$3>=63 | D6: =IF(Skills!C6=1,60+Inputs!$B$25+Inputs!$B$29,IF(Skills!C6=2,90+Inputs!$B$26+Inputs!$B$29,IF(Skills!C6=3,120+Inputs!$B$27+Inputs!$B$29,MAX(0,(Inputs!$B$3-100)*3)+Inputs!$B$28+Inputs!$B$29))) | E6: =INDEX(FactorTable!$B$2:$Y$301, MATCH(ROUND(MIN(300,MAX(1,D6)),0), FactorTable!$A$2:$A$301,0), Skills!L6+1) | F6: =IF(Skills!M6=TRUE,(Skills!K6/10)*(E6/1000),Skills!K6/10)+Skills!N6 | G6: =Skills!F6*IF(Skills!G6>0,Skills!H6/Skills!G6,1) | H6: =1-(1-Skills!I6/100)^Skills!J6 | I6: =IF(Skills!T6<>"",1+(Skills!T6/10)*($Z$3/1000)/100,1) | J6: =Summary!$B$6*(F6/100) | K6: =J6*(1+Summary!$B$7/100)*(1+(Inputs!$B$15+Summary!$B$15)/100)*(1+Inputs!$B$16/100)*(5000/(6000+Inputs!$B$42*(1-Inputs!$B$19/100)))*(1+Inputs!$B$24/100)*(1+Artifacts!$B$34/100)*(1+IF(C15=TRUE,F15,0)/100)*(1+IF(C23=TRUE,F23,0)/100)^5*(1+(IF(Skills!A6="CHAIN_LIGHTNING",Inputs!$B$17+Artifacts!$B$40,Inputs!$B$18+Artifacts!$B$39))/100)*(Summary!$B$13*(1+Artifacts!$B$38/100)*I6) | L6: =K6*(MIN(Inputs!$B$22,Inputs!$B$23)/100+Inputs!$B$23/100)/2 | M6: =L6*(1+(Inputs!$B$10+Artifacts!$B$33)/100) | N6: =L6*(1-MIN((Inputs!$B$9+Artifacts!$B$32),100)/100)+M6*(MIN((Inputs!$B$9+Artifacts!$B$32),100)/100) | O6: =(1-Summary!$B$11)*S6+Summary!$B$11*U6 | P6: =IF(Summary!$B$3=0,0,O6/Summary!$B$3) | Q6: =IFERROR(1/(IF(Inputs!$B$38="pvp",15,MAX(0.1,Skills!D6-IF(TRUE=TRUE,Inputs!$B$32,0)))*(1-IF(AND(ArtifactsInput!$M$27,Inputs!$B$4="Chapter Hunt"),CHOOSE(ArtifactsInput!$N$27+1,20,24,28,32,36,40),0)/100)),0) | R6: =IF(AND(Inputs!$B$38<>"pvp",Inputs!$B$43>0),IF(MAX(0,Inputs!$B$43-Summary!$B$21)<=0,0,(INT(MAX(0,Inputs!$B$43-Summary!$B$21)/(IF(Inputs!$B$38="pvp",15,MAX(0.1,Skills!D6-IF(TRUE=TRUE,Inputs!$B$32,0)))*(1-IF(AND(ArtifactsInput!$M$27,Inputs!$B$4="Chapter Hunt"),CHOOSE(ArtifactsInput!$N$27+1,20,24,28,32,36,40),0)/100)))+1)),0) | S6: =IF(C6,(H6*N6*IF(AND(Inputs!$B$38<>"pvp",Inputs!$B$43>0),((Skills!F6*((R6-1)*IF(Skills!G6>0,Skills!H6/Skills!G6,1)+IF(Skills!G6>0,MIN(Skills!H6,MAX(0,MAX(0,Inputs!$B$43-Summary!$B$21)-((R6-1)*(IF(Inputs!$B$38="pvp",15,MAX(0.1,Skills!D6-IF(TRUE=TRUE,Inputs!$B$32,0)))*(1-IF(AND(ArtifactsInput!$M$27,Inputs!$B$4="Chapter Hunt"),CHOOSE(ArtifactsInput!$N$27+1,20,24,28,32,36,40),0)/100)))))/Skills!G6,1)))/Inputs!$B$43),G6*Q6))*IF(Inputs!$B$38="pvp",1,1+(Inputs!$B$20+Skills!O6+Summary!$B$14+Artifacts!$B$35)/100)*((((5000/(6000+Inputs!$B$42*(1-(100*(1-(1-Inputs!$B$19/100)*(1-Artifacts!$B$51/100)^IF(Inputs!$B$38="pvp",1,2)))/100)))/(5000/(6000+Inputs!$B$42*(1-Inputs!$B$19/100))))*((L6*(1-MIN(100,(Inputs!$B$9+Artifacts!$B$32)+Artifacts!$B$69)/100)+M6*(MIN(100,(Inputs!$B$9+Artifacts!$B$32)+Artifacts!$B$69)/100))/(L6*(1-MIN(100,(Inputs!$B$9+Artifacts!$B$32))/100)+M6*(MIN(100,(Inputs!$B$9+Artifacts!$B$32))/100)))*(1+Artifacts!$B$81/100))),0) | U6: =IF(C6,(H6*N6*IF(AND(Inputs!$B$38<>"pvp",Inputs!$B$43>0),((Skills!F6*((R6-1)*IF(Skills!G6>0,Skills!H6/Skills!G6,1)+IF(Skills!G6>0,MIN(Skills!H6,MAX(0,MAX(0,Inputs!$B$43-Summary!$B$21)-((R6-1)*(IF(Inputs!$B$38="pvp",15,MAX(0.1,Skills!D6-IF(TRUE=TRUE,Inputs!$B$32,0)))*(1-IF(AND(ArtifactsInput!$M$27,Inputs!$B$4="Chapter Hunt"),CHOOSE(ArtifactsInput!$N$27+1,20,24,28,32,36,40),0)/100)))))/Skills!G6,1)))/Inputs!$B$43),G6*Q6))*IF(Inputs!$B$38="pvp",1,(1+(Inputs!$B$21+Skills!P6+Summary!$B$14+Artifacts!$B$80)/100)*(MIN(Skills!Q6,Inputs!$B$37)))*((1+Artifacts!$B$53/100)),0)
A7: =Skills!A7 | B7: =Skills!B7 | C7: =Inputs!$B$3>=69 | D7: =IF(Skills!C7=1,60+Inputs!$B$25+Inputs!$B$29,IF(Skills!C7=2,90+Inputs!$B$26+Inputs!$B$29,IF(Skills!C7=3,120+Inputs!$B$27+Inputs!$B$29,MAX(0,(Inputs!$B$3-100)*3)+Inputs!$B$28+Inputs!$B$29))) | E7: =INDEX(FactorTable!$B$2:$Y$301, MATCH(ROUND(MIN(300,MAX(1,D7)),0), FactorTable!$A$2:$A$301,0), Skills!L7+1) | F7: =IF(Skills!M7=TRUE,(Skills!K7/10)*(E7/1000),Skills!K7/10)+Skills!N7 | G7: =Skills!F7*IF(Skills!G7>0,Skills!H7/Skills!G7,1) | H7: =1-(1-Skills!I7/100)^Skills!J7 | I7: =IF(Skills!T7<>"",1+(Skills!T7/10)*($Z$3/1000)/100,1) | J7: =Summary!$B$6*(F7/100) | K7: =J7*(1+Summary!$B$7/100)*(1+(Inputs!$B$15+Summary!$B$15)/100)*(1+Inputs!$B$16/100)*(5000/(6000+Inputs!$B$42*(1-Inputs!$B$19/100)))*(1+Inputs!$B$24/100)*(1+Artifacts!$B$34/100)*(1+IF(C15=TRUE,F15,0)/100)*(1+IF(C23=TRUE,F23,0)/100)^5*(1+(IF(Skills!A7="CHAIN_LIGHTNING",Inputs!$B$17+Artifacts!$B$40,Inputs!$B$18+Artifacts!$B$39))/100)*(Summary!$B$13*(1+Artifacts!$B$38/100)*I7) | L7: =K7*(MIN(Inputs!$B$22,Inputs!$B$23)/100+Inputs!$B$23/100)/2 | M7: =L7*(1+(Inputs!$B$10+Artifacts!$B$33)/100) | N7: =L7*(1-MIN((Inputs!$B$9+Artifacts!$B$32),100)/100)+M7*(MIN((Inputs!$B$9+Artifacts!$B$32),100)/100) | O7: =(1-Summary!$B$11)*S7+Summary!$B$11*U7 | P7: =IF(Summary!$B$3=0,0,O7/Summary!$B$3) | Q7: =IFERROR(1/(IF(Inputs!$B$38="pvp",15,MAX(0.1,Skills!D7-IF(TRUE=TRUE,Inputs!$B$32,0)))*(1-IF(AND(ArtifactsInput!$M$27,Inputs!$B$4="Chapter Hunt"),CHOOSE(ArtifactsInput!$N$27+1,20,24,28,32,36,40),0)/100)),0) | R7: =IF(AND(Inputs!$B$38<>"pvp",Inputs!$B$43>0),IF(MAX(0,Inputs!$B$43-Summary!$B$21)<=0,0,(INT(MAX(0,Inputs!$B$43-Summary!$B$21)/(IF(Inputs!$B$38="pvp",15,MAX(0.1,Skills!D7-IF(TRUE=TRUE,Inputs!$B$32,0)))*(1-IF(AND(ArtifactsInput!$M$27,Inputs!$B$4="Chapter Hunt"),CHOOSE(ArtifactsInput!$N$27+1,20,24,28,32,36,40),0)/100)))+1)),0) | S7: =IF(C7,(H7*N7*IF(AND(Inputs!$B$38<>"pvp",Inputs!$B$43>0),((Skills!F7*((R7-1)*IF(Skills!G7>0,Skills!H7/Skills!G7,1)+IF(Skills!G7>0,MIN(Skills!H7,MAX(0,MAX(0,Inputs!$B$43-Summary!$B$21)-((R7-1)*(IF(Inputs!$B$38="pvp",15,MAX(0.1,Skills!D7-IF(TRUE=TRUE,Inputs!$B$32,0)))*(1-IF(AND(ArtifactsInput!$M$27,Inputs!$B$4="Chapter Hunt"),CHOOSE(ArtifactsInput!$N$27+1,20,24,28,32,36,40),0)/100)))))/Skills!G7,1)))/Inputs!$B$43),G7*Q7))*IF(Inputs!$B$38="pvp",1,1+(Inputs!$B$20+Skills!O7+Summary!$B$14+Artifacts!$B$35)/100)*((((5000/(6000+Inputs!$B$42*(1-(100*(1-(1-Inputs!$B$19/100)*(1-Artifacts!$B$51/100)^IF(Inputs!$B$38="pvp",1,2)))/100)))/(5000/(6000+Inputs!$B$42*(1-Inputs!$B$19/100))))*((L7*(1-MIN(100,(Inputs!$B$9+Artifacts!$B$32)+Artifacts!$B$69)/100)+M7*(MIN(100,(Inputs!$B$9+Artifacts!$B$32)+Artifacts!$B$69)/100))/(L7*(1-MIN(100,(Inputs!$B$9+Artifacts!$B$32))/100)+M7*(MIN(100,(Inputs!$B$9+Artifacts!$B$32))/100)))*(1+Artifacts!$B$81/100))),0) | U7: =IF(C7,(H7*N7*IF(AND(Inputs!$B$38<>"pvp",Inputs!$B$43>0),((Skills!F7*((R7-1)*IF(Skills!G7>0,Skills!H7/Skills!G7,1)+IF(Skills!G7>0,MIN(Skills!H7,MAX(0,MAX(0,Inputs!$B$43-Summary!$B$21)-((R7-1)*(IF(Inputs!$B$38="pvp",15,MAX(0.1,Skills!D7-IF(TRUE=TRUE,Inputs!$B$32,0)))*(1-IF(AND(ArtifactsInput!$M$27,Inputs!$B$4="Chapter Hunt"),CHOOSE(ArtifactsInput!$N$27+1,20,24,28,32,36,40),0)/100)))))/Skills!G7,1)))/Inputs!$B$43),G7*Q7))*IF(Inputs!$B$38="pvp",1,(1+(Inputs!$B$21+Skills!P7+Summary!$B$14+Artifacts!$B$80)/100)*(MIN(Skills!Q7,Inputs!$B$37)))*((1+Artifacts!$B$53/100)),0)
A8: =Skills!A8 | B8: =Skills!B8 | C8: =Inputs!$B$3>=103 | D8: =IF(Skills!C8=1,60+Inputs!$B$25+Inputs!$B$29,IF(Skills!C8=2,90+Inputs!$B$26+Inputs!$B$29,IF(Skills!C8=3,120+Inputs!$B$27+Inputs!$B$29,MAX(0,(Inputs!$B$3-100)*3)+Inputs!$B$28+Inputs!$B$29))) | E8: =INDEX(FactorTable!$B$2:$Y$301, MATCH(ROUND(MIN(300,MAX(1,D8)),0), FactorTable!$A$2:$A$301,0), Skills!L8+1) | F8: =IF(Skills!M8=TRUE,(Skills!K8/10)*(E8/1000),Skills!K8/10)+Skills!N8 | G8: =Skills!F8*IF(Skills!G8>0,Skills!H8/Skills!G8,1) | H8: =1-(1-Skills!I8/100)^Skills!J8 | I8: =IF(Skills!T8<>"",1+(Skills!T8/10)*($Z$3/1000)/100,1) | J8: =Summary!$B$6*(F8/100) | K8: =J8*(1+Summary!$B$7/100)*(1+(Inputs!$B$15+Summary!$B$15)/100)*(1+Inputs!$B$16/100)*(5000/(6000+Inputs!$B$42*(1-Inputs!$B$19/100)))*(1+Inputs!$B$24/100)*(1+Artifacts!$B$34/100)*(1+IF(C15=TRUE,F15,0)/100)*(1+IF(C23=TRUE,F23,0)/100)^5*(1+(IF(Skills!A8="CHAIN_LIGHTNING",Inputs!$B$17+Artifacts!$B$40,Inputs!$B$18+Artifacts!$B$39))/100)*(Summary!$B$13*(1+Artifacts!$B$38/100)*I8) | L8: =K8*(MIN(Inputs!$B$22,Inputs!$B$23)/100+Inputs!$B$23/100)/2 | M8: =L8*(1+(Inputs!$B$10+Artifacts!$B$33)/100) | N8: =L8*(1-MIN((Inputs!$B$9+Artifacts!$B$32),100)/100)+M8*(MIN((Inputs!$B$9+Artifacts!$B$32),100)/100) | O8: =(1-Summary!$B$11)*S8+Summary!$B$11*U8 | P8: =IF(Summary!$B$3=0,0,O8/Summary!$B$3) | Q8: =IFERROR(1/(IF(Inputs!$B$38="pvp",15,MAX(0.1,Skills!D8-IF(TRUE=TRUE,Inputs!$B$32,0)))*(1-IF(AND(ArtifactsInput!$M$27,Inputs!$B$4="Chapter Hunt"),CHOOSE(ArtifactsInput!$N$27+1,20,24,28,32,36,40),0)/100)),0) | R8: =IF(AND(Inputs!$B$38<>"pvp",Inputs!$B$43>0),IF(MAX(0,Inputs!$B$43-Summary!$B$21)<=0,0,(INT(MAX(0,Inputs!$B$43-Summary!$B$21)/(IF(Inputs!$B$38="pvp",15,MAX(0.1,Skills!D8-IF(TRUE=TRUE,Inputs!$B$32,0)))*(1-IF(AND(ArtifactsInput!$M$27,Inputs!$B$4="Chapter Hunt"),CHOOSE(ArtifactsInput!$N$27+1,20,24,28,32,36,40),0)/100)))+1)),0) | S8: =IF(C8,(H8*N8*IF(AND(Inputs!$B$38<>"pvp",Inputs!$B$43>0),((Skills!F8*((R8-1)*IF(Skills!G8>0,Skills!H8/Skills!G8,1)+IF(Skills!G8>0,MIN(Skills!H8,MAX(0,MAX(0,Inputs!$B$43-Summary!$B$21)-((R8-1)*(IF(Inputs!$B$38="pvp",15,MAX(0.1,Skills!D8-IF(TRUE=TRUE,Inputs!$B$32,0)))*(1-IF(AND(ArtifactsInput!$M$27,Inputs!$B$4="Chapter Hunt"),CHOOSE(ArtifactsInput!$N$27+1,20,24,28,32,36,40),0)/100)))))/Skills!G8,1)))/Inputs!$B$43),G8*Q8))*IF(Inputs!$B$38="pvp",1,1+(Inputs!$B$20+Skills!O8+Summary!$B$14+Artifacts!$B$35)/100)*((((5000/(6000+Inputs!$B$42*(1-(100*(1-(1-Inputs!$B$19/100)*(1-Artifacts!$B$51/100)^IF(Inputs!$B$38="pvp",1,2)))/100)))/(5000/(6000+Inputs!$B$42*(1-Inputs!$B$19/100))))*((L8*(1-MIN(100,(Inputs!$B$9+Artifacts!$B$32)+Artifacts!$B$69)/100)+M8*(MIN(100,(Inputs!$B$9+Artifacts!$B$32)+Artifacts!$B$69)/100))/(L8*(1-MIN(100,(Inputs!$B$9+Artifacts!$B$32))/100)+M8*(MIN(100,(Inputs!$B$9+Artifacts!$B$32))/100)))*(1+Artifacts!$B$81/100))),0) | U8: =IF(C8,(H8*N8*IF(AND(Inputs!$B$38<>"pvp",Inputs!$B$43>0),((Skills!F8*((R8-1)*IF(Skills!G8>0,Skills!H8/Skills!G8,1)+IF(Skills!G8>0,MIN(Skills!H8,MAX(0,MAX(0,Inputs!$B$43-Summary!$B$21)-((R8-1)*(IF(Inputs!$B$38="pvp",15,MAX(0.1,Skills!D8-IF(TRUE=TRUE,Inputs!$B$32,0)))*(1-IF(AND(ArtifactsInput!$M$27,Inputs!$B$4="Chapter Hunt"),CHOOSE(ArtifactsInput!$N$27+1,20,24,28,32,36,40),0)/100)))))/Skills!G8,1)))/Inputs!$B$43),G8*Q8))*IF(Inputs!$B$38="pvp",1,(1+(Inputs!$B$21+Skills!P8+Summary!$B$14+Artifacts!$B$80)/100)*(MIN(Skills!Q8,Inputs!$B$37)))*((1+Artifacts!$B$53/100)),0)
A9: =Skills!A9 | B9: =Skills!B9 | C9: =Inputs!$B$3>=105 | D9: =IF(Skills!C9=1,60+Inputs!$B$25+Inputs!$B$29,IF(Skills!C9=2,90+Inputs!$B$26+Inputs!$B$29,IF(Skills!C9=3,120+Inputs!$B$27+Inputs!$B$29,MAX(0,(Inputs!$B$3-100)*3)+Inputs!$B$28+Inputs!$B$29))) | E9: =INDEX(FactorTable!$B$2:$Y$301, MATCH(ROUND(MIN(300,MAX(1,D9)),0), FactorTable!$A$2:$A$301,0), Skills!L9+1) | F9: =IF(Skills!M9=TRUE,(Skills!K9/10)*(E9/1000),Skills!K9/10)+Skills!N9 | G9: =Skills!F9*IF(Skills!G9>0,Skills!H9/Skills!G9,1) | H9: =1-(1-Skills!I9/100)^Skills!J9 | I9: =IF(Skills!T9<>"",1+(Skills!T9/10)*($Z$3/1000)/100,1) | J9: =Summary!$B$6*(F9/100) | K9: =J9*(1+Summary!$B$7/100)*(1+(Inputs!$B$15+Summary!$B$15)/100)*(1+Inputs!$B$16/100)*(5000/(6000+Inputs!$B$42*(1-Inputs!$B$19/100)))*(1+Inputs!$B$24/100)*(1+Artifacts!$B$34/100)*(1+IF(C15=TRUE,F15,0)/100)*(1+IF(C23=TRUE,F23,0)/100)^5*(1+(IF(Skills!A9="CHAIN_LIGHTNING",Inputs!$B$17+Artifacts!$B$40,Inputs!$B$18+Artifacts!$B$39))/100)*(Summary!$B$13*(1+Artifacts!$B$38/100)*I9) | L9: =K9*(MIN(Inputs!$B$22,Inputs!$B$23)/100+Inputs!$B$23/100)/2 | M9: =L9*(1+(Inputs!$B$10+Artifacts!$B$33)/100) | N9: =L9*(1-MIN((Inputs!$B$9+Artifacts!$B$32),100)/100)+M9*(MIN((Inputs!$B$9+Artifacts!$B$32),100)/100) | O9: =(1-Summary!$B$11)*S9+Summary!$B$11*U9 | P9: =IF(Summary!$B$3=0,0,O9/Summary!$B$3) | Q9: =IFERROR(1/(IF(Inputs!$B$38="pvp",15,MAX(0.1,Skills!D9-IF(TRUE=TRUE,Inputs!$B$32,0)))*(1-IF(AND(ArtifactsInput!$M$27,Inputs!$B$4="Chapter Hunt"),CHOOSE(ArtifactsInput!$N$27+1,20,24,28,32,36,40),0)/100)),0) | R9: =IF(AND(Inputs!$B$38<>"pvp",Inputs!$B$43>0),IF(MAX(0,Inputs!$B$43-Summary!$B$21)<=0,0,(INT(MAX(0,Inputs!$B$43-Summary!$B$21)/(IF(Inputs!$B$38="pvp",15,MAX(0.1,Skills!D9-IF(TRUE=TRUE,Inputs!$B$32,0)))*(1-IF(AND(ArtifactsInput!$M$27,Inputs!$B$4="Chapter Hunt"),CHOOSE(ArtifactsInput!$N$27+1,20,24,28,32,36,40),0)/100)))+1)),0) | S9: =IF(C9,(H9*N9*IF(AND(Inputs!$B$38<>"pvp",Inputs!$B$43>0),((Skills!F9*((R9-1)*IF(Skills!G9>0,Skills!H9/Skills!G9,1)+IF(Skills!G9>0,MIN(Skills!H9,MAX(0,MAX(0,Inputs!$B$43-Summary!$B$21)-((R9-1)*(IF(Inputs!$B$38="pvp",15,MAX(0.1,Skills!D9-IF(TRUE=TRUE,Inputs!$B$32,0)))*(1-IF(AND(ArtifactsInput!$M$27,Inputs!$B$4="Chapter Hunt"),CHOOSE(ArtifactsInput!$N$27+1,20,24,28,32,36,40),0)/100)))))/Skills!G9,1)))/Inputs!$B$43),G9*Q9))*IF(Inputs!$B$38="pvp",1,1+(Inputs!$B$20+Skills!O9+Summary!$B$14+Artifacts!$B$35)/100)*((((5000/(6000+Inputs!$B$42*(1-(100*(1-(1-Inputs!$B$19/100)*(1-Artifacts!$B$51/100)^IF(Inputs!$B$38="pvp",1,2)))/100)))/(5000/(6000+Inputs!$B$42*(1-Inputs!$B$19/100))))*((L9*(1-MIN(100,(Inputs!$B$9+Artifacts!$B$32)+Artifacts!$B$69)/100)+M9*(MIN(100,(Inputs!$B$9+Artifacts!$B$32)+Artifacts!$B$69)/100))/(L9*(1-MIN(100,(Inputs!$B$9+Artifacts!$B$32))/100)+M9*(MIN(100,(Inputs!$B$9+Artifacts!$B$32))/100)))*(1+Artifacts!$B$81/100))),0) | U9: =IF(C9,(H9*N9*IF(AND(Inputs!$B$38<>"pvp",Inputs!$B$43>0),((Skills!F9*((R9-1)*IF(Skills!G9>0,Skills!H9/Skills!G9,1)+IF(Skills!G9>0,MIN(Skills!H9,MAX(0,MAX(0,Inputs!$B$43-Summary!$B$21)-((R9-1)*(IF(Inputs!$B$38="pvp",15,MAX(0.1,Skills!D9-IF(TRUE=TRUE,Inputs!$B$32,0)))*(1-IF(AND(ArtifactsInput!$M$27,Inputs!$B$4="Chapter Hunt"),CHOOSE(ArtifactsInput!$N$27+1,20,24,28,32,36,40),0)/100)))))/Skills!G9,1)))/Inputs!$B$43),G9*Q9))*IF(Inputs!$B$38="pvp",1,(1+(Inputs!$B$21+Skills!P9+Summary!$B$14+Artifacts!$B$80)/100)*(MIN(Skills!Q9,Inputs!$B$37)))*((1+Artifacts!$B$53/100)),0)
