Workbook

Sheet README
A1: Hero — DPS Calculator: How to Use This Workbook
A3: How to use this workbook
A4: Only edit the yellow-highlighted cells on the Inputs sheet — every other sheet is computed from those values and will be overwritten if you rebuild the workbook.
A5: Summary shows Total DPS, a Per-Skill DPS Breakdown (damage-dealing skills only — buffs/passives that never deal their own damage are omitted), and a Marginal DPS & Stat Value table showing the DPS gained per +1 of each stat.
A6: Sensitivity has the full detail behind that marginal-value table — one self-contained block per stat, showing exactly how bumping that stat by +1 changes every downstream number.
A7: CubeData/PotentialCubes model your current gear's Potential Cube lines and drive cube-reroll expected-value decisions. For the full standalone Potential Cube EV calculator (exact optimal-stopping math, works from this workbook alone), see tools/potential_cubes_ev.py in the project repo.
A9: Design decisions & assumptions
A10: Iron Body's flat +30 STR, Weapon Acceleration, Physical Training, Weapon Mastery, Combat Mastery, and Power Stance's own Final Damage component are always-on passives assumed to already be reflected in your own Inputs stat entries — only their Sensitivity marginal delta is modeled live, matching this project's established convention. Iron Body's flat STR specifically has NO Sensitivity delta row (no percentage-bucket exists for a flat sub-stat bonus in this template) — just assume your own Inputs!STR already includes it. Warrior Mastery (Max HP/Speed) and Power Stance's own damage-reduction component have zero DPS-relevant mechanic and get no row at all.
A11: Hero's Mastery table has a confirmed skill-name swap bug: every row labeled 'Puncture' actually describes an Enhanced Raging Blow effect, and vice versa. Re-attributed by effect description, not label, throughout this workbook.
A12: Puncture is split into two rows (direct hit + wound DoT), same pattern as FP-Mage's own Poison Mist Burst/DoT split. Its wound's own continuously-scaling boss-damage-taken curve (10%->18%) is a live FactorTable lookup (factorIndex 21/baseDamage 100 tenths%, resolved via _reverse_engineer_hero_factors.py), not a flat approximation.
A13: Combo Attack and Combo Synergy (both combo-stack-scaling passives) are modeled at steady-state MAX stacks once unlocked, not as an exact stack-gain/decay state machine — the same simplification tier as Concentration/Mortal Blow elsewhere in this project. Enhanced Raging Blow's own Lv.134 mastery ('combo final damage +50% per excess stack') reuses this same steady-state assumption: 2 excess stacks above the 5 required to use the skill, once Advanced Combo's own 7-stack cap unlocks at Lv.110, giving a flat +100% Final Damage term once Lv.134 is reached.
A14: Scaring Sword is the first skill in this project to actually drive the Global Monster Damage-Taken Bonus% bucket (a placeholder left at 0 in every prior class) — modeled as proc-chance x duty-cycle uptime, feeding every damage row's own monster-damage-taken term.
... A19: Not modeled (out of scope): all forms of crowd control (Rush/Puncture stuns), Accuracy, Evasion, Defense, Max HP/MP recovery, movement speed, and Companion Summoning Time.

Sheet Inputs
A1: Hero — DPS Calculator Inputs | N1: (none)
C2: Chapter Boss | D2: Breakthrough | E2: PvP | F2: EXP Dungeon | G2: Equipment Dungeon | H2: Weapon Dungeon | I2: Enhancement Dungeon | J2: Hero Dungeon | K2: World Boss | L2: Chapter Hunt | N2: Charm of the Undead
A3: Character Level | B3: 200 | N3: Pig's Ribbon
A4: Content Type | B4: Chapter Boss | N4: Shamaness Marble
A5: Chapter-Stage — 'chapter-substage' (e.g. '28-9') for Breakthrough/Chapter Hunt, just the chapter number for Chapter Boss, or just the stage number for Weapon/Equipment/Enhancement/EXP/Hero Dungeon. Not applicable to World Boss/PvP. | B5: =INDEX($C$5:$L$5,MATCH($B$4,$C$2:$L$2,0)) | C5: 28 | D5: 28-9 | F5: 80 | G5: 80 | H5: 80 | I5: 80 | J5: 80 | L5: 28-9 | N5: The Contract of Darkness
A6: Flat ATTACK | B6: =INDEX($C$6:$L$6,MATCH($B$4,$C$2:$L$2,0)) | C6: 10000 | D6: 10000 | E6: 10000 | F6: 10000 | G6: 10000 | H6: 10000 | I6: 10000 | J6: 10000 | K6: 10000 | L6: 10000 | N6: Rainbow-colored Snail Shell
A7: ATTACK % | B7: =INDEX($C$7:$L$7,MATCH($B$4,$C$2:$L$2,0)) | C7: 0 | D7: 0 | E7: 0 | F7: 0 | G7: 0 | H7: 0 | I7: 0 | J7: 0 | K7: 0 | L7: 0 | N7: Hexagon Necklace
A8: Defense (your own DEF stat; PvP assumes the opponent has the same Defense as you) | B8: =INDEX($C$8:$L$8,MATCH($B$4,$C$2:$L$2,0)) | C8: 0 | D8: 0 | E8: 0 | F8: 0 | G8: 0 | H8: 0 | I8: 0 | J8: 0 | K8: 0 | L8: 0 | N8: Arwen's Glass Shoes
A9: CRIT_RATE % | B9: =INDEX($C$9:$L$9,MATCH($B$4,$C$2:$L$2,0)) | C9: 0 | D9: 0 | E9: 0 | F9: 0 | G9: 0 | H9: 0 | I9: 0 | J9: 0 | K9: 0 | L9: 0 | N9: Mushmom's Cap
A10: CRIT_DAMAGE % | B10: =INDEX($C$10:$L$10,MATCH($B$4,$C$2:$L$2,0)) | C10: 0 | D10: 0 | E10: 0 | F10: 0 | G10: 0 | H10: 0 | I10: 0 | J10: 0 | K10: 0 | L10: 0 | N10: Clear Spring Water
A11: ATTACK_SPEED % (base, excludes Weapon Acceleration) | B11: =INDEX($C$11:$L$11,MATCH($B$4,$C$2:$L$2,0)) | C11: 0 | D11: 0 | E11: 0 | F11: 0 | G11: 0 | H11: 0 | I11: 0 | J11: 0 | K11: 0 | L11: 0 | N11: Athena Pierce's Old Gloves
A12: Flat STR (include Iron Body's own +30 if unlocked) | B12: =INDEX($C$12:$L$12,MATCH($B$4,$C$2:$L$2,0)) | C12: 0 | D12: 0 | E12: 0 | F12: 0 | G12: 0 | H12: 0 | I12: 0 | J12: 0 | K12: 0 | L12: 0 | N12: Zakum's Stone Piece
A13: STR % | B13: =INDEX($C$13:$L$13,MATCH($B$4,$C$2:$L$2,0)) | C13: 0 | D13: 0 | E13: 0 | F13: 0 | G13: 0 | H13: 0 | I13: 0 | J13: 0 | K13: 0 | L13: 0 | N13: Horntail's Scale
A14: DEX | B14: =INDEX($C$14:$L$14,MATCH($B$4,$C$2:$L$2,0)) | C14: 0 | D14: 0 | E14: 0 | F14: 0 | G14: 0 | H14: 0 | I14: 0 | J14: 0 | K14: 0 | L14: 0 | N14: Pink Bean's Giant Rib
A15: DAMAGE % | B15: =INDEX($C$15:$L$15,MATCH($B$4,$C$2:$L$2,0)) | C15: 0 | D15: 0 | E15: 0 | F15: 0 | G15: 0 | H15: 0 | I15: 0 | J15: 0 | K15: 0 | L15: 0 | N15: Chalice
A16: DAMAGE_AMP % | B16: =INDEX($C$16:$L$16,MATCH($B$4,$C$2:$L$2,0)) | C16: 0 | D16: 0 | E16: 0 | F16: 0 | G16: 0 | H16: 0 | I16: 0 | J16: 0 | K16: 0 | L16: 0 | N16: Old Music Box
A17: BASIC_ATTACK_DAMAGE % | B17: =INDEX($C$17:$L$17,MATCH($B$4,$C$2:$L$2,0)) | C17: 0 | D17: 0 | E17: 0 | F17: 0 | G17: 0 | H17: 0 | I17: 0 | J17: 0 | K17: 0 | L17: 0 | N17: Silver Pendant
A18: SKILL_DAMAGE % | B18: =INDEX($C$18:$L$18,MATCH($B$4,$C$2:$L$2,0)) | C18: 0 | D18: 0 | E18: 0 | F18: 0 | G18: 0 | H18: 0 | I18: 0 | J18: 0 | K18: 0 | L18: 0 | N18: Star Rock
A19: DEF_PEN % | B19: =INDEX($C$19:$L$19,MATCH($B$4,$C$2:$L$2,0)) | C19: 0 | D19: 0 | E19: 0 | F19: 0 | G19: 0 | H19: 0 | I19: 0 | J19: 0 | K19: 0 | L19: 0 | N19: Book of Ancient
A20: BOSS_DAMAGE % | B20: =INDEX($C$20:$L$20,MATCH($B$4,$C$2:$L$2,0)) | C20: 0 | D20: 0 | E20: 0 | F20: 0 | G20: 0 | H20: 0 | I20: 0 | J20: 0 | K20: 0 | L20: 0 | N20: Lunar Dew
A21: NORMAL_DAMAGE % | B21: =INDEX($C$21:$L$21,MATCH($B$4,$C$2:$L$2,0)) | C21: 0 | D21: 0 | E21: 0 | F21: 0 | G21: 0 | H21: 0 | I21: 0 | J21: 0 | K21: 0 | L21: 0 | N21: Fire Flower
A22: MIN_DAMAGE % | B22: =INDEX($C$22:$L$22,MATCH($B$4,$C$2:$L$2,0)) | C22: 100 | D22: 100 | E22: 100 | F22: 100 | G22: 100 | H22: 100 | I22: 100 | J22: 100 | K22: 100 | L22: 100 | N22: Soul Contract
A23: MAX_DAMAGE % | B23: =INDEX($C$23:$L$23,MATCH($B$4,$C$2:$L$2,0)) | C23: 100 | D23: 100 | E23: 100 | F23: 100 | G23: 100 | H23: 100 | I23: 100 | J23: 100 | K23: 100 | L23: 100 | N23: Lit Lamp
A24: FINAL_DAMAGE % (base) | B24: =INDEX($C$24:$L$24,MATCH($B$4,$C$2:$L$2,0)) | C24: 0 | D24: 0 | E24: 0 | F24: 0 | G24: 0 | H24: 0 | I24: 0 | J24: 0 | K24: 0 | L24: 0 | N24: Soul Pouch
A25: Skill Level Bonus — 1st Job | B25: =INDEX($C$25:$L$25,MATCH($B$4,$C$2:$L$2,0)) | C25: 0 | D25: 0 | E25: 0 | F25: 0 | G25: 0 | H25: 0 | I25: 0 | J25: 0 | K25: 0 | L25: 0 | N25: Ancient Text Piece
A26: Skill Level Bonus — 2nd Job | B26: =INDEX($C$26:$L$26,MATCH($B$4,$C$2:$L$2,0)) | C26: 0 | D26: 0 | E26: 0 | F26: 0 | G26: 0 | H26: 0 | I26: 0 | J26: 0 | K26: 0 | L26: 0 | N26: Icy Soul Rock
A27: Skill Level Bonus — 3rd Job | B27: =INDEX($C$27:$L$27,MATCH($B$4,$C$2:$L$2,0)) | C27: 0 | D27: 0 | E27: 0 | F27: 0 | G27: 0 | H27: 0 | I27: 0 | J27: 0 | K27: 0 | L27: 0 | N27: Flaming Lava
A28: Skill Level Bonus — 4th Job | B28: =INDEX($C$28:$L$28,MATCH($B$4,$C$2:$L$2,0)) | C28: 0 | D28: 0 | E28: 0 | F28: 0 | G28: 0 | H28: 0 | I28: 0 | J28: 0 | K28: 0 | L28: 0 | N28: Sayram's Necklace
A29: Skill Level Bonus — All Skills | B29: =INDEX($C$29:$L$29,MATCH($B$4,$C$2:$L$2,0)) | C29: 0 | D29: 0 | E29: 0 | F29: 0 | G29: 0 | H29: 0 | I29: 0 | J29: 0 | K29: 0 | L29: 0 | N29: Bottle of Emotion
N30: Peach Tree Herb Pouch
A31: Additional Bonuses | N31: Candle
A32: Skill Cooldown Decrease (seconds, only skills/buffs the character actively casts) | B32: =INDEX($C$32:$L$32,MATCH($B$4,$C$2:$L$2,0)) | C32: 0 | D32: 0 | E32: 0 | F32: 0 | G32: 0 | H32: 0 | I32: 0 | J32: 0 | K32: 0 | L32: 0 | N32: Alliance Badge
A33: Basic Attack Target Increase (flat, adds to the 6-target normal-monster base) | B33: =INDEX($C$33:$L$33,MATCH($B$4,$C$2:$L$2,0)) | C33: 1 | D33: 1 | E33: 1 | F33: 1 | G33: 1 | H33: 1 | I33: 1 | J33: 1 | K33: 1 | L33: 1 | N33: Horn Flute
A34: Buff Duration Increase % | B34: =INDEX($C$34:$L$34,MATCH($B$4,$C$2:$L$2,0)) | C34: 0 | D34: 0 | E34: 0 | F34: 0 | G34: 0 | H34: 0 | I34: 0 | J34: 0 | K34: 0 | L34: 0 | N34: Cursed Doll
A35: Companion Summoning Time Increase % (companions not modeled — always 0 DPS impact) | B35: =INDEX($C$35:$L$35,MATCH($B$4,$C$2:$L$2,0)) | C35: 0 | D35: 0 | E35: 0 | F35: 0 | G35: 0 | H35: 0 | I35: 0 | J35: 0 | K35: 0 | L35: 0 | N35: Reindeer's Spear
A36: Boss/Normal Emphasis (Breakthrough/Hero Dungeon only) | B36: =INDEX($C$36:$L$36,MATCH($B$4,$C$2:$L$2,0)) | D36: A Little More Normal | J36: A Little More Normal | N36: Secret Map
A37: Max Enemies Actually In Range (normal-monster content only; default 999 = uncapped) | B37: =INDEX($C$37:$L$37,MATCH($B$4,$C$2:$L$2,0)) | D37: 999 | F37: 999 | G37: 999 | J37: 999 | L37: 999 | N37: Ring of Cycles
A38: Monster Type (auto-computed from Content Type) — computed, do not edit | B38: =IF(Inputs!$B$4="PvP","pvp",IF(OR(Inputs!$B$4="Breakthrough",Inputs!$B$4="Hero Dungeon"),"breakthrough",IF(OR(Inputs!$B$4="EXP Dungeon",Inputs!$B$4="Equipment Dungeon",Inputs!$B$4="Chapter Hunt"),"normal","boss")))
A39: Chapter (parsed from Chapter-Stage) — computed, do not edit | B39: =IFERROR(IF(ISNUMBER(FIND("-",Inputs!$B$5)),VALUE(LEFT(Inputs!$B$5,FIND("-",Inputs!$B$5)-1)),VALUE(Inputs!$B$5)),28)
A40: Stage (parsed from Chapter-Stage) — computed, do not edit | B40: =IFERROR(IF(ISNUMBER(FIND("-",Inputs!$B$5)),VALUE(MID(Inputs!$B$5,FIND("-",Inputs!$B$5)+1,50)),VALUE(Inputs!$B$5)),9)
...

Sheet FactorTable
A1: Level | B1: F0 | C1: F1 | D1: F2 | E1: F3 | F1: F4 | G1: F5 | H1: F6 | I1: F7 | J1: F8 | K1: F9 | L1: F10 | M1: F11 | N1: F12 | O1: F13 | P1: F14 | Q1: F15 | R1: F16 | S1: F17 | T1: F18 | U1: F19 | V1: F20 | W1: F21 | X1: F22 | Y1: F23
A2: 1 | B2: 0 | C2: 1000 | D2: 1000 | E2: 1000 | F2: 1000 | G2: 1000 | H2: 1000 | I2: 1000 | J2: 1000 | K2: 1000 | L2: 1000 | M2: 1000 | N2: 1000 | O2: 1000 | P2: 1000 | Q2: 1000 | R2: 1000 | S2: 1000 | T2: 1000 | U2: 1000 | V2: 1000 | W2: 1000 | X2: 1000 | Y2: 1000
A3: 2 | B3: 0 | C3: 1015 | D3: 1020 | E3: 1030 | F3: 1040 | G3: 1050 | H3: 1060 | I3: 1070 | J3: 1020 | K3: 1020 | L3: 1020 | M3: 1000 | N3: 1010 | O3: 1020 | P3: 1030 | Q3: 1040 | R3: 1050 | S3: 1060 | T3: 1070 | U3: 1080 | V3: 1010 | W3: 1008 | X3: 1006 | Y3: 1100
A4: 3 | B4: 0 | C4: 1031 | D4: 1041 | E4: 1061 | F4: 1082 | G4: 1103 | H4: 1124 | I4: 1145 | J4: 1030 | K4: 1041 | L4: 1030 | M4: 1000 | N4: 1015 | O4: 1030 | P4: 1045 | Q4: 1060 | R4: 1075 | S4: 1090 | T4: 1105 | U4: 1120 | V4: 1020 | W4: 1012 | X4: 1009 | Y4: 1150
A5: 4 | B5: 0 | C5: 1047 | D5: 1062 | E5: 1093 | F5: 1126 | G5: 1159 | H5: 1192 | I5: 1226 | J5: 1040 | K5: 1062 | L5: 1040 | M5: 1000 | N5: 1020 | O5: 1040 | P5: 1060 | Q5: 1080 | R5: 1100 | S5: 1120 | T5: 1140 | U5: 1160 | V5: 1030 | W5: 1016 | X5: 1012 | Y5: 1200
A6: 5 | B6: 0 | C6: 1063 | D6: 1084 | E6: 1126 | F6: 1172 | G6: 1217 | H6: 1264 | I6: 1312 | J6: 1050 | K6: 1084 | L6: 1050 | M6: 1000 | N6: 1025 | O6: 1050 | P6: 1075 | Q6: 1100 | R6: 1125 | S6: 1150 | T6: 1175 | U6: 1200 | V6: 1040 | W6: 1020 | X6: 1015 | Y6: 1250
A7: 6 | B7: 0 | C7: 1079 | D7: 1106 | E7: 1160 | F7: 1219 | G7: 1278 | H7: 1340 | I7: 1404 | J7: 1060 | K7: 1106 | L7: 1060 | M7: 1000 | N7: 1030 | O7: 1060 | P7: 1090 | Q7: 1120 | R7: 1150 | S7: 1180 | T7: 1210 | U7: 1240 | V7: 1050 | W7: 1024 | X7: 1018 | Y7: 1300
A8: 7 | B8: 0 | C8: 1096 | D8: 1129 | E8: 1195 | F8: 1268 | G8: 1342 | H8: 1421 | I8: 1503 | J8: 1070 | K8: 1129 | L8: 1070 | M8: 1000 | N8: 1035 | O8: 1070 | P8: 1105 | Q8: 1140 | R8: 1175 | S8: 1210 | T8: 1245 | U8: 1280 | V8: 1060 | W8: 1028 | X8: 1021 | Y8: 1350
A9: 8 | B9: 0 | C9: 1113 | D9: 1152 | E9: 1231 | F9: 1319 | G9: 1410 | H9: 1507 | I9: 1609 | J9: 1080 | K9: 1152 | L9: 1080 | M9: 1000 | N9: 1040 | O9: 1080 | P9: 1120 | Q9: 1160 | R9: 1200 | S9: 1240 | T9: 1280 | U9: 1320 | V9: 1070 | W9: 1032 | X9: 1024 | Y9: 1400
A10: 9 | B10: 0 | C10: 1130 | D10: 1176 | E10: 1268 | F10: 1372 | G10: 1481 | H10: 1598 | I10: 1722 | J10: 1090 | K10: 1176 | L10: 1090 | M10: 1000 | N10: 1045 | O10: 1090 | P10: 1135 | Q10: 1180 | R10: 1225 | S10: 1270 | T10: 1315 | U10: 1360 | V10: 1080 | W10: 1036 | X10: 1027 | Y10: 1450
A11: 10 | B11: 0 | C11: 1147 | D11: 1200 | E11: 1307 | F11: 1427 | G11: 1556 | H11: 1694 | I11: 1843 | J11: 1100 | K11: 1200 | L11: 1100 | M11: 1000 | N11: 1050 | O11: 1100 | P11: 1150 | Q11: 1200 | R11: 1250 | S11: 1300 | T11: 1350 | U11: 1400 | V11: 1090 | W11: 1040 | X11: 1030 | Y11: 1500
A12: 11 | B12: 0 | C12: 1165 | D12: 1224 | E12: 1347 | F12: 1485 | G12: 1634 | H12: 1796 | I12: 1973 | J12: 1110 | K12: 1224 | L12: 1110 | M12: 1000 | N12: 1055 | O12: 1110 | P12: 1165 | Q12: 1220 | R12: 1275 | S12: 1330 | T12: 1385 | U12: 1440 | V12: 1100 | W12: 1044 | X12: 1033 | Y12: 1550
A13: 12 | B13: 0 | C13: 1183 | D13: 1249 | E13: 1388 | F13: 1545 | G13: 1716 | H13: 1904 | I13: 2112 | J13: 1120 | K13: 1249 | L13: 1120 | M13: 1000 | N13: 1060 | O13: 1120 | P13: 1180 | Q13: 1240 | R13: 1300 | S13: 1360 | T13: 1420 | U13: 1480 | V13: 1110 | W13: 1048 | X13: 1036 | Y13: 1600
... A301: 300 | B301: 0 | C301: 88573 | D301: 381637 | E301: 6991522 | F301: 125363453 | G301: 2185120762 | H301: 37157073039 | I301: 614631863830 | J301: 2000 | K301: 53326 | L301: 2500 | M301: 1100 | N301: 2500 | O301: 4000 | P301: 5500 | Q301: 7000 | R301: 8500 | S301: 10000 | T301: 11500 | U301: 13000 | V301: 7558 | W301: 2200 | X301: 1900 | Y301: 8800

Sheet Skills
A1: Key | B1: Name | C1: JobStep | D1: Cooldown(s) | E1: CostsActionSlot | F1: ActionsPerCast | G1: HitsPerCast | H1: ICD(s) | I1: ActiveWindow(s) | J1: ProcChance% | K1: RollsPerCast | L1: BaseDamage(tenths%) | M1: FactorIndex | N1: ScalesWithLevel | O1: SkillMasteryBonus% | P1: MasteryBossDamage% | Q1: MasteryNormalDamage% | R1: NormalMonsterTargets | S1: BuffTargetStat | T1: BuffDuration(s) | U1: MapleHeroBase(tenths%) | V1: MapleHeroFactorIndex | W1: Note
A2: RAGING_BLOW | B2: Raging Blow | C2: 4 | E2: FALSE | F2: 1 | G2: =IF(Inputs!$B$3>=136,6,5) | H2: 0 | I2: 0 | J2: 100 | K2: 1 | L2: 2900 | M2: 21 | N2: TRUE | O2: =Calc!F3*IF(Calc!C3=TRUE,1,0)/100*(1+Calc!F4*IF(Calc!C4=TRUE,1,0)/100)*25+SUMPRODUCT((Inputs!$B$3>={102,106,116,120,128,132})*{10,1,1,1,1,1}) | P2: =SUMPRODUCT((Inputs!$B$3>={111,124})*{10,10}) | Q2: 0 | R2: =6+Inputs!$B$33 | T2: 0 | W2: 4th-job basic-attack effect (supersedes Slash Blast/Brandish/Intrepid Slash, confirmed identical wiki wording — 290% damage to 6 target(s) in front 5 time(s) — to every other class's own 4th-job basic attack). factorIndex 21, baseDamage 2900 tenths%. HitsPerCast=5, bumping to 6 once Mastery Lv.136 'Raging Blow - Strike' unlocks (Hero's own level for this differs from Bowmaster/Marksman's Lv.134 — confirmed directly from Hero/Mastery). SkillMasteryBonus% is Final Attack + Advanced Final Attack's own combined steady-state contribution (same folding mechanism as Bowmaster's Arrow Stream) PLUS the real Raging Blow - Damage mastery chain (102/106/116/120/128/132, cumulative +10/11/12/13/14/15% — summed as DELTAS, not the raw displayed values). MasteryBossDamage% is the real 2-tier Raging Blow - Boss Monster Damage chain (111/124, +10% each, +20% total).
A3: FINAL_ATTACK_HELPER | B3: Final Attack (helper) | C3: 2 | E3: FALSE | F3: 1 | G3: 1 | H3: 0 | I3: 0 | J3: 100 | K3: 1 | L3: 350 | M3: 21 | N3: TRUE | O3: =SUMPRODUCT((Inputs!$B$3>={54})*{50}) | P3: 0 | Q3: 0 | R3: 0 | T3: 0 | W3: Helper row only — feeds Raging Blow's own coefficient. 25% chance, 35%->49% additional damage (levels 1-100), factorIndex 21/baseDamage 350 tenths% — resolves to the IDENTICAL tuple Bowmaster's own Final Attack: Bow helper uses, confirming this is genuinely the same cross-tree shared skill. Mastery Lv.54 'Final Attack - Damage' +50% (real SkillMasteryBonus%).
A4: ADVANCED_FINAL_ATTACK_HELPER | B4: Advanced Final Attack (helper) | C4: 4 | E4: FALSE | F4: 1 | G4: 1 | H4: 0 | I4: 0 | J4: 100 | K4: 1 | L4: 5000 | M4: 21 | N4: TRUE | O4: =SUMPRODUCT((Inputs!$B$3>={113})*{50}) | P4: 0 | Q4: 0 | R4: 0 | T4: 0 | W4: Helper row only — feeds Raging Blow's own coefficient (Final Attack's own Final Damage bonus). +500%->900% FD (levels 1-200), factorIndex 21/baseDamage 5000 tenths% — resolves to the IDENTICAL tuple Bowmaster's own Advanced Final Attack helper uses. Mastery Lv.113 'Advanced Final Attack - Enhance' +50% (real SkillMasteryBonus%).
A5: PUNCTURE | B5: Puncture | C5: 4 | D5: 17 | E5: TRUE | F5: 1 | G5: 3 | H5: 0 | I5: 0 | J5: 100 | K5: 1 | L5: 9000 | M5: 12 | N5: TRUE | O5: =SUMPRODUCT((Inputs!$B$3>={122})*{50}) | P5: =(100/10)*(INDEX(FactorTable!$B$2:$Y$301,MATCH(ROUND(MIN(300,MAX(1,MAX(0,(Inputs!$B$3-100)*3)+Inputs!$B$28+Inputs!$B$29)),0),FactorTable!$A$2:$A$301,0),22)/1000)+IF(Inputs!$B$3>=138,20,0) | Q5: 0 | R5: =5+IF(Inputs!$B$3>=100,5,0) | T5: 0 | W5: Drives a sword into the target's location: 900%->1800% damage to 5 nearby target(s), 3 times, leaving a 10-sec wound (see PUNCTURE_WOUND for the DoT half). factorIndex 12, baseDamage 9000 tenths%. PATCHED: targets 5->10 (modeled as base 5 +5 once Raging Blow's own Lv.100 unlock, a simplification standing in for 'always 10 once 4th job' since the patch made this unconditional — cooldown 19->17s. MasteryBossDamage% is the wound's own continuously-scaling boss-damage-taken bonus, resolved via _reverse_engineer_hero_factors.py to factorIndex 21/baseDamage 100 tenths% (10%->18% across levels 1-200, 0% residual) — computed live via its own FactorTable lookup at Puncture's own job-step-4 input level (this row's own factorIndex is 12, a different curve shape, so the wound's own 21 lookup can't reuse Calc!E{row} and is inlined here instead), plus the Lv.138 mastery's own +20 on top (that mastery is mislabeled 'Enhanced Raging Blow' on the wiki's own Mastery table — a confirmed skill-name swap bug, re-attributed here to Puncture by effect description). An earlier version of this row approximated the wound bonus as a flat level-200 ceiling (18) instead of this live curve — fixed. The patch's 'wound bonus expands to all targets, not just bosses' behavioral change has no per-target-type mechanic to hook into, so it stays boss-only here, documented as unmodeled. Mastery Lv.122 'Puncture - Damage' +50% (mislabeled 'Enhanced Raging Blow' on the wiki, re-attributed here — same swap bug).
A6: PUNCTURE_WOUND | B6: Puncture (wound DoT) | C6: 4 | D6: 17 | E6: FALSE | F6: 1 | G6: 1 | H6: 1 | I6: 10 | J6: 100 | K6: 1 | L6: 1500 | M6: 12 | N6: TRUE | O6: 0 | P6: 0 | Q6: 0 | R6: =5+IF(Inputs!$B$3>=100,5,0) | T6: 0 | W6: Wound DoT half of Puncture — 150%->300% damage/sec for 10 sec (EffectiveHits = ActiveWindow/ICD = 10 ticks/cast). Shares Puncture's own cooldown/targets (same cast, same patch). factorIndex 12, baseDamage 1500 tenths%. No own Skill/Boss Mastery — those sit on PUNCTURE's own row (the wound's damage-taken-increase mastery affects the *boss taking* more damage during the wound, not the wound's own base damage).
A7: ENHANCED_RAGING_BLOW | B7: Enhanced Raging Blow | C7: 4 | D7: 17 | E7: TRUE | F7: 1 | G7: 6 | H7: 0 | I7: 0 | J7: 100 | K7: 1 | L7: 6105 | M7: 12 | N7: TRUE | O7: =SUMPRODUCT((Inputs!$B$3>={108})*{50}) | P7: 100 | Q7: 0 | R7: =9+IF(Inputs!$B$3>=100,3,0) | T7: 0 | W7: Quickly slashes target(s) in front multiple times: 550%->1100% damage (pre-patch curve), 6 times, usable at combo stack >=5. factorIndex 12, baseDamage 5500 tenths% pre-patch, PATCHED base damage 550%->610% (curve rescaled 610/550=1.1091x, giving the 6105 stored here), targets 9->12, cooldown 19->17s. +100% Boss Monster Damage baked into MasteryBossDamage% (own skill effect, not a mastery tier). Mastery Lv.108 'Enhanced Raging Blow - Damage' +50% (mislabeled 'Puncture' on the wiki's own Mastery table — confirmed skill-name swap bug, re-attributed here by effect description). Mastery Lv.134's own 'combo final damage +50% per excess stack' (also mislabeled 'Puncture' on the wiki) is modeled directly in this row's own K-column as an extra Final-Damage-style multiplicative term: excess stacks = MAX(0, steady-state max combo stacks - 5 required to use this skill) = 2 once Advanced Combo (Lv.110) is unlocked, so the term is a flat +100% FD once Lv.134 is reached (since Lv.134 already implies Lv.110). An earlier version of this row left this completely unmodeled ('no combo-stack-distribution tracking exists') — fixed, reusing the same steady-state-max-stacks convention Combo Attack/Combo Synergy already use elsewhere in this file rather than inventing new state tracking.
A8: MAGIC_CRASH | B8: Magic Crash | C8: 4 | D8: 28 | E8: TRUE | F8: 1 | G8: 1 | H8: 0 | I8: 0 | J8: 100 | K8: 1 | L8: 48000 | M8: 12 | N8: TRUE | O8: 0 | P8: 0 | Q8: 0 | R8: =5+IF(Inputs!$B$3>=100,4,0) | T8: 0 | W8: Summons a rock at the target's location, removing 1 buff and dealing 4800%->9600% damage to 5 nearby target(s), 1 time. factorIndex 12, baseDamage 48000 tenths%. Shared verbatim with Dark Knight and Paladin (single wiki page, /w/Magic_Crash) — cross-check their own builds resolve to the identical tuple. PATCHED: targets 5->9 (effect range +50% not modeled, no such mechanic exists in this project).
A9: BEAM_BLADE | B9: Beam Blade | C9: 3 | D9: 16 | E9: TRUE | F9: 1 | G9: 4 | H9: 0 | I9: 0 | J9: 100 | K9: 1 | L9: 2500 | M9: 12 | N9: TRUE | O9: 0 | P9: 0 | Q9: 0 | R9: 8 | T9: 0 | U9: 200 | V9: 23 | W9: Releases sword energy: 250%->500% damage to 8 target(s) in front, 4 times. factorIndex 12, baseDamage 2500 tenths%, 16s cooldown. Not patched. Maple Hero target (own 1x share) — see MAPLE_HERO_RATIOS.
A10: RUSH | B10: Rush | C10: 3 | D10: 22 | E10: TRUE | F10: 1 | G10: 1 | H10: 0 | I10: 0 | J10: 100 | K10: 1 | L10: 6000 | M10: 12 | N10: TRUE | O10: 0 | P10: 0 | Q10: 0 | R10: 12 | T10: 0 | U10: 300 | V10: 23 | W10: Charges to the front to deal 600%->1200% damage to 12 target(s) (stun 2.5s not modeled). factorIndex 12, baseDamage 6000 tenths%, 22s cooldown. Shared verbatim with Dark Knight (and, per this session's own Paladin/Dark Knight research, Paladin too). Not patched (Mastery Lv.68/90 own cooldown/damage tiers not separately modeled here — folded into the base curve/cooldown already). Maple Hero target (1.5x share) — see MAPLE_HERO_RATIOS.
A11: FLASH_SLASH | B11: Flash Slash | C11: 2 | D11: 16 | E11: TRUE | F11: 1 | G11: 1 | H11: 0 | I11: 0 | J11: 100 | K11: 1 | L11: 3500 | M11: 12 | N11: TRUE | O11: =SUMPRODUCT((Inputs!$B$3>={39})*{50}) | P11: 0 | Q11: 0 | R11: 7 | T11: 0 | U11: 800 | V11: 23 | W11: Deals 350% damage to 7 target(s) in front, scaling '+5%/level' per the wiki page's own prose (the level 1-200 sampled table showed a constant 350% at every sampled level, which was wrongly trusted over the prose as a 'wiki content bug' — per direct user correction, the flat table was itself the error, same failure mode already caught on Bowmaster's Hurricane/Flash Mirage/Soul Arrow: a wiki per-level table reading flat is not reliable evidence a skill is truly non-scaling). factorIndex 12 (burst-damage active-skill convention, matching Close Combat/Puncture/Noble Demand's own curve), baseDamage 3500 tenths% (=350%) treated as the level-1 anchor. If combo stack >=3, damage +50% — assumed always active once Combo Attack is unlocked (Lv.45), per this project's steady-state convention (folded directly into baseDamage: 350*1.5=525 tenths%->3500... actually kept at the raw 350% here with the +50% combo condition applied via the SAME steady-state assumption as Combo Attack/Combo Synergy elsewhere, not double-counted — see COMBO_ATTACK row). 16s cooldown. Mastery Lv.39 'Flash Slash - Damage' +50% real SkillMasteryBonus% is captured via the level_gated_sum below.
A12: MAPLE_HERO_HELPER | B12: Maple Hero (helper) | C12: 4 | E12: FALSE | F12: 1 | G12: 1 | H12: 0 | I12: 0 | J12: 100 | K12: 1 | L12: 200 | M12: 23 | N12: TRUE | O12: 0 | P12: 0 | Q12: 0 | R12: 0 | T12: 0 | W12: Shared ratio-feeder row (see MAPLE_HERO_RATIOS) for Beam Blade/Rush/Flash Slash's own Final Damage chains — mirrors Shadower/Bowmaster's own Maple Hero mechanism. Confirmed via idle.maplestorywiki.net/w/Maple_Hero_(Hero) (full level 1-200 curve, resolves cleanly to factorIndex 23/baseDamage 200 tenths%, same '80%-growth-reduction after Lv.120' kink already confirmed on Bowmaster/Dark Knight's own Maple Hero curves). No independent DPS row of its own (Calc columns J-N blank/0, only D/E/F computed, read directly by each target row's own K-column formula).
A13: COMBO_ATTACK | B13: Combo Attack (Attack%) | C13: 2 | E13: FALSE | F13: 1 | G13: 1 | H13: 0 | I13: 0 | J13: 100 | K13: 1 | L13: 40 | M13: 22 | N13: TRUE | O13: 0 | P13: 0 | Q13: 0 | R13: 0 | S13: ATTACK | T13: 0 | W13: On attack, 40% chance to gain a combo stack (+4%->5.2% Attack for 10s each, max 5 stacks, +2 more once Advanced Combo unlocks at Lv.110). Modeled at steady-state MAX stacks (5, or 7 once Lv.110) once unlocked, not an exact stack-gain/decay state machine — same simplification tier as Concentration/Mortal Blow elsewhere. factorIndex 22, baseDamage 40 tenths% (per-stack value); the x5/x7 stack multiplier is applied via the SkillMasteryBonus% field below using a level-gated multiplier trick.
A14: COMBO_SYNERGY | B14: Combo Synergy (Final Damage per stack) | C14: 3 | E14: FALSE | F14: 1 | G14: 1 | H14: 0 | I14: 0 | J14: 100 | K14: 1 | L14: 50 | M14: 22 | N14: TRUE | O14: 0 | P14: 0 | Q14: 0 | R14: 0 | S14: FINAL_DAMAGE | T14: 0 | W14: +5%->8% Final Damage per combo stack, +10%p combo-stack-chance (not modeled, folded into the steady-state max-stacks assumption already used for Combo Attack). Modeled at steady-state MAX stacks (5, or 7 once Lv.110's Advanced Combo unlocks) — factorIndex 22, baseDamage 50 tenths% (per-stack value).
A15: SPIRIT_BLADE | B15: Spirit Blade | C15: 2 | D15: 45 | E15: TRUE | F15: 1 | G15: 1 | H15: 0 | I15: 0 | J15: 100 | K15: 1 | L15: 100 | M15: 21 | N15: TRUE | O15: 0 | P15: 0 | Q15: 0 | R15: 0 | S15: ATTACK | T15: 20 | W15: Self-inclusive ally buff (matches Bishop's own 'allied players' precedent) — +10%->14% Attack for 20s, 45s cooldown. Own damage-taken-reduction component (8%->11.2%) not modeled (no such mechanic for the character's own damage-taken exists). factorIndex 21, baseDamage 100 tenths%. Not patched.
A16: SCARING_SWORD | B16: Scaring Sword | C16: 3 | D16: 30 | E16: TRUE | F16: 1 | G16: 1 | H16: 0 | I16: 0 | J16: 35 | K16: 1 | L16: 200 | M16: 21 | N16: TRUE | O16: =SUMPRODUCT((Inputs!$B$3>={78})*{8}) | P16: 0 | Q16: 0 | R16: 0 | S16: MONSTER_DMG | T16: 10 | W16: On-attack proc (35% chance) that increases the target's damage taken by 20%->36% for 10s (own Attack-down component, 10%->18%, not modeled — no such mechanic exists). First skill in this project to actually drive the Global Monster Damage-Taken Bonus% bucket (a placeholder left at 0 in every prior class) — modeled as ProcChance% x duty-cycle uptime (BuffDuration/Cooldown), feeding every damage row's own monster-damage-taken term. factorIndex 21, baseDamage 200 tenths%. Mastery Lv.78 'Scaring Sword - Weaken' +8 (percentage points, real SkillMasteryBonus%). Not patched.
A17: ENRAGE_FD | B17: Enrage (Final Damage half) | C17: 4 | D17: 12 | E17: FALSE | F17: 1 | G17: 1 | H17: 0 | I17: 0 | J17: 100 | K17: 1 | L17: 120 | M17: 22 | N17: TRUE | O17: 0 | P17: 0 | Q17: 0 | R17: 0 | S17: FINAL_DAMAGE | T17: 7 | W17: Fires on its own fixed interval (not a player-cast cooldown — modeled the same way as any other duty-cycled buff, treating the interval as this row's own Cooldown(s)): +12%->19.2% Final Damage for 5s->7s (patched duration), interval 10s->12s (patched). factorIndex 22, baseDamage 120 tenths%. PATCHED: duration 5->7s (baked into BuffDuration(s)), interval 10->12s (baked into Cooldown(s)), new 'activates at combat start' behavior not modeled (no such mechanic exists).
A18: ENRAGE_CRITDMG | B18: Enrage (Crit Damage half) | C18: 4 | D18: 12 | E18: FALSE | F18: 1 | G18: 1 | H18: 0 | I18: 0 | J18: 100 | K18: 1 | L18: 150 | M18: 22 | N18: TRUE | O18: 0 | P18: 0 | Q18: 0 | R18: 0 | S18: CRIT_DAMAGE | T18: 7 | W18: Crit Damage half of Enrage — same interval/duration as ENRAGE_FD (+15%->24% Crit Damage). factorIndex 22, baseDamage 150 tenths%. Split into its own row since this schema's BuffTargetStat column only holds one stat per row.
A19: NIMBLE_FEET | B19: Nimble Feet | C19: 1 | D19: 60 | E19: TRUE | F19: 1 | G19: 1 | H19: 0 | I19: 0 | J19: 100 | K19: 1 | L19: 150 | M19: 0 | N19: FALSE | O19: 0 | P19: 0 | Q19: 0 | R19: 1 | S19: ATTACK_SPEED | T19: 15 | W19: Shared cross-tree verbatim w/ every class in this project (byte-identical wiki wording — '+15% Attack Speed, +10% Speed for 15 sec'). Flat +15% Attack Speed / +10% Speed for 15s, 60s cooldown, non-scaling. FactorIndex unused placeholder.
A20: WEAPON_ACCELERATION | B20: Weapon Acceleration | C20: 2 | E20: FALSE | F20: 1 | G20: 1 | H20: 0 | I20: 0 | J20: 100 | K20: 1 | L20: 50 | M20: 22 | N20: TRUE | O20: 0 | P20: 0 | Q20: 0 | R20: 0 | S20: ATTACK_SPEED | T20: 0 | W20: Magic Critical pattern — already baked into Inputs!ATTACK_SPEED%; feeds the 2nd-Job Skill Level Bonus delta. Reuses Bowmaster's own Bow Acceleration tuple directly (shared-value-different-key, byte-identical wiki wording — '+5% Attack Speed'). factorIndex 22, baseDamage 50 tenths% (5%->6.5%, levels 1-100).
A21: PHYSICAL_TRAINING | B21: Physical Training | C21: 2 | E21: FALSE | F21: 1 | G21: 1 | H21: 0 | I21: 0 | J21: 100 | K21: 1 | L21: 100 | M21: 22 | N21: TRUE | O21: 0 | P21: 0 | Q21: 0 | R21: 0 | S21: BASIC_ATTACK_DAMAGE | T21: 0 | W21: Magic Critical pattern — already baked into Inputs!BASIC_ATTACK_DAMAGE%; feeds the 2nd-Job Skill Level Bonus delta. Reuses Bowmaster's own Physical Training tuple directly (byte-identical wiki wording — '+10% Basic Attack Damage'). factorIndex 22, baseDamage 100 tenths% (10%->13%, levels 1-100).
A22: WEAPON_MASTERY | B22: Weapon Mastery | C22: 2 | E22: FALSE | F22: 1 | G22: 1 | H22: 0 | I22: 0 | J22: 100 | K22: 1 | L22: 150 | M22: 22 | N22: TRUE | O22: 0 | P22: 0 | Q22: 0 | R22: 0 | S22: MIN_DAMAGE | T22: 0 | W22: Magic Critical pattern — already baked into Inputs!MIN_DAMAGE%; feeds the 2nd-Job Skill Level Bonus delta. factorIndex 22, baseDamage 150 tenths% (15%->19.5%, levels 1-100).
A23: COMBAT_MASTERY_SKILL | B23: Combat Mastery (Skill Damage) | C23: 4 | E23: FALSE | F23: 1 | G23: 1 | H23: 0 | I23: 0 | J23: 100 | K23: 1 | L23: 150 | M23: 22 | N23: TRUE | O23: 0 | P23: 0 | Q23: 0 | R23: 0 | S23: SKILL_DAMAGE | T23: 0 | W23: Magic Critical pattern — already baked into Inputs!SKILL_DAMAGE%; feeds the 4th-Job Skill Level Bonus delta (Skill Damage side). factorIndex 22, baseDamage 150 tenths% (15%->24%, levels 1-200).
A24: COMBAT_MASTERY_MAXDMG | B24: Combat Mastery (Max Damage Multiplier) | C24: 4 | E24: FALSE | F24: 1 | G24: 1 | H24: 0 | I24: 0 | J24: 100 | K24: 1 | L24: 200 | M24: 22 | N24: TRUE | O24: 0 | P24: 0 | Q24: 0 | R24: 0 | S24: MAX_DAMAGE | T24: 0 | W24: Same skill as Combat Mastery (Skill Damage) above, +20%->32% Max Damage Multiplier. Magic Critical pattern — already baked into Inputs!MAX_DAMAGE%; feeds the 4th-Job Skill Level Bonus delta (Max Damage Multiplier side). factorIndex 22, baseDamage 200 tenths%.
A25: POWER_STANCE_FD | B25: Power Stance (Final Damage) | C25: 4 | E25: FALSE | F25: 1 | G25: 1 | H25: 0 | I25: 0 | J25: 100 | K25: 1 | L25: 150 | M25: 22 | N25: TRUE | O25: 0 | P25: 0 | Q25: 0 | R25: 0 | S25: FINAL_DAMAGE | T25: 0 | W25: Own damage-taken-reduction component (5%->8%) not modeled (no such mechanic exists). Magic Critical pattern — already baked into Inputs!FINAL_DAMAGE%; feeds the 4th-Job Skill Level Bonus delta. factorIndex 22, baseDamage 150 tenths% (15%->24%, levels 1-200).
A26: CHANCE_ATTACK_CRIT | B26: Chance Attack (Crit Rate) | C26: 3 | E26: FALSE | F26: 1 | G26: 1 | H26: 0 | I26: 0 | J26: 100 | K26: 1 | L26: 80 | M26: 22 | N26: TRUE | O26: 0 | P26: 0 | Q26: 0 | R26: 0 | S26: CRIT_RATE | T26: 0 | W26: Own Status Effect Damage component (12%->19.2%) not modeled (no such mechanic exists). Magic Critical pattern — already baked into Inputs!CRIT_RATE%; feeds the 3rd-Job Skill Level Bonus delta. factorIndex 22, baseDamage 80 tenths% (8%->12.8%, levels 1-200).

Sheet Artifacts
A1: Hero — Artifacts (Equip Effect)
A3: Book of Ancient — Crit Damage (from Crit Rate, reference only) | B3: =IF(ArtifactsInput!$M$24,CHOOSE(ArtifactsInput!$N$24+1,30,36,42,48,54,60)/100*(Inputs!$B$9+B5+B29),0)
A4: Ring of Cycles — Threshold Crit Rate (excl. self) | B4: =Inputs!$B$9+B29
A5: Ring of Cycles — Crit Rate (if threshold < 100%) | B5: =IF(AND(ArtifactsInput!$M$42,B4<100),CHOOSE(ArtifactsInput!$N$42+1,30,36,42,48,54,60),0)
A6: Ring of Cycles — Skill Damage (if threshold >= 100%) | B6: =IF(AND(ArtifactsInput!$M$42,B4>=100),CHOOSE(ArtifactsInput!$N$42+1,40,48,56,64,72,80),0)
A7: Ring of Cycles — Excess-100% Points (capped at 100) | B7: =IF(AND(ArtifactsInput!$M$42,B4>=100),MIN(100,B4-100),0)
A8: Ring of Cycles — Basic Attack Damage (excess points x per-point) | B8: =B7*CHOOSE(ArtifactsInput!$N$42+1,0.6,0.72,0.84,0.96,1.08,1.2)
A9: Candle — Effective Fight Duration | B9: =IF(Inputs!$B$38="pvp",15,Inputs!$B$43)
A10: Candle — Effective Active (fixed-duration or PvP) | B10: =IF(Inputs!$B$38="pvp",TRUE,AND(Inputs!$B$38<>"pvp",Inputs!$B$43>0))
A11: Candle — Final Damage (100% uptime, patched) | B11: =IF(AND(ArtifactsInput!$M$36,B10),CHOOSE(ArtifactsInput!$N$36+1,8,9.6,11.2,12.8,14.4,16),0)
A12: Candle — Boss Monster Damage (20-40s window / boss-present-time uptime, patched) | B12: =IF(AND(ArtifactsInput!$M$36,B10),MAX(0,MIN(40,B9)-MAX(20,B41))/(B9-B41)*CHOOSE(ArtifactsInput!$N$36+1,30,36,42,48,54,60),0)
A13: Peach Tree Herb Pouch — Proc Rate (per second) | B13: =0.2*Summary!$B$17
A14: Peach Tree Herb Pouch — Uptime (refreshing 5s timer) | B14: =1-EXP(-B13*5)
A15: Peach Tree Herb Pouch — Enemy Damage Taken | B15: =IF(AND(ArtifactsInput!$M$35,Inputs!$B$4<>"Chapter Hunt"),CHOOSE(ArtifactsInput!$N$35+1,15,18,21,24,27,30)*B14,0)
A16: Silver Pendant — Offered Load (rho = lambda x duration) | B16: =0.15*Summary!$B$17*5
A17: Silver Pendant — Erlang Loss Weight (n=0) | B17: =B16^0/1
A18: Silver Pendant — Erlang Loss Weight (n=1) | B18: =B16^1/1
A19: Silver Pendant — Erlang Loss Weight (n=2) | B19: =B16^2/2
A20: Silver Pendant — Erlang Loss Weight (n=3) | B20: =B16^3/6
A21: Silver Pendant — Erlang Loss Weight (n=4) | B21: =B16^4/24
A22: Silver Pendant — Erlang Loss Weight (n=5) | B22: =B16^5/120
A23: Silver Pendant — Average Stacks (Erlang-loss mean) | B23: =(0*B17+1*B18+2*B19+3*B20+4*B21+5*B22)/(B17+B18+B19+B20+B21+B22)
A24: Silver Pendant — Enemy Damage Taken | B24: =IF(AND(ArtifactsInput!$M$22,Inputs!$B$4<>"Chapter Hunt"),CHOOSE(ArtifactsInput!$N$22+1,10,12,14,16,18,20)*B23,0)
A25: Athena Pierce's Old Gloves — Max Damage (from Attack Speed, reference only) | B25: =IF(ArtifactsInput!$M$15,CHOOSE(ArtifactsInput!$N$15+1,25,30,35,40,45,50)/100*Inputs!$B$11,0)
A26: Hexagon Necklace — Average Stacks | B26: =IF(AND(Inputs!$B$38<>"pvp",Inputs!$B$43=0),3,IF(IF(Inputs!$B$38="pvp",15,Inputs!$B$43)<=20,0,IF(IF(Inputs!$B$38="pvp",15,Inputs!$B$43)<=40,(IF(Inputs!$B$38="pvp",15,Inputs!$B$43)-20)/IF(Inputs!$B$38="pvp",15,Inputs!$B$43),IF(IF(Inputs!$B$38="pvp",15,Inputs!$B$43)<=60,(2*IF(Inputs!$B$38="pvp",15,Inputs!$B$43)-60)/IF(Inputs!$B$38="pvp",15,Inputs!$B$43),(3*IF(Inputs!$B$38="pvp",15,Inputs!$B$43)-120)/IF(Inputs!$B$38="pvp",15,Inputs!$B$43)))))
A27: Hexagon Necklace — Damage % | B27: =IF(ArtifactsInput!$M$11,CHOOSE(ArtifactsInput!$N$11+1,15,18,21,24,27,30)*B26,0)
A28: Rainbow-colored Snail Shell — Uptime (0-15s window) | B28: =IF(Inputs!$B$38="pvp",MIN(15,15)/15,IF(AND(Inputs!$B$38<>"pvp",Inputs!$B$43>0),MIN(15,Inputs!$B$43)/Inputs!$B$43,0))
A29: Rainbow-colored Snail Shell — Crit Rate | B29: =IF(ArtifactsInput!$M$10,CHOOSE(ArtifactsInput!$N$10+1,15,18,21,24,27,30)*B28,0)
A30: Rainbow-colored Snail Shell — Crit Damage | B30: =IF(ArtifactsInput!$M$10,CHOOSE(ArtifactsInput!$N$10+1,20,24,28,32,36,40)*B28,0)
A32: TOTAL — Artifact Crit Rate Bonus | B32: =B5+B29
A33: TOTAL — Artifact Crit Damage Bonus | B33: =B30+B47
A34: TOTAL — Artifact Final Damage Bonus (equivalent %, each real source combines MULTIPLICATIVELY — Candle x Flaming Lava x Horn Flute, not summed) | B34: =((1+B11/100)*(1+B46/100)*(1+B55/100)-1)*100
A35: TOTAL — Artifact Boss Monster Damage Bonus | B35: =B12+B60
A36: TOTAL — Artifact Enemy Damage Taken Bonus | B36: =B15+B24
A38: TOTAL — Artifact Damage Bonus (own separate final multiplier, like Magic Guard/Meditation's Average Buff Multiplier — not blended into Inputs!DAMAGE%) | B38: =B27
A39: TOTAL — Artifact Skill Damage Bonus | B39: =B6
A40: TOTAL — Artifact Basic Attack Damage Bonus | B40: =B8
A41: Candle — Boss Appear Time (Breakthrough/Hero Dungeon only) | B41: =IF(Inputs!$B$4="Breakthrough",20,IF(Inputs!$B$4="Hero Dungeon",30,0))
A42: Clear Spring Water — Final Damage (reference only, Growth Dungeon types) | B42: =IF(AND(ArtifactsInput!$M$14,OR(Inputs!$B$4="Weapon Dungeon",Inputs!$B$4="Equipment Dungeon",Inputs!$B$4="Enhancement Dungeon",Inputs!$B$4="EXP Dungeon",Inputs!$B$4="Hero Dungeon")),CHOOSE(ArtifactsInput!$N$14+1,10,12,14,16,18,20),0)
A43: Old Music Box — Attack % (content-type uptime assumption) | B43: =IF(ArtifactsInput!$M$21,CHOOSE(ArtifactsInput!$N$21+1,25,30,35,40,45,50)*(IF(OR(Inputs!$B$4="Chapter Hunt",Inputs!$B$4="Breakthrough",Inputs!$B$4="Weapon Dungeon",Inputs!$B$4="Equipment Dungeon",Inputs!$B$4="Enhancement Dungeon",Inputs!$B$4="EXP Dungeon",Inputs!$B$4="Hero Dungeon"),0,IF(OR(Inputs!$B$4="World Boss",Inputs!$B$4="PvP"),1,IF(Inputs!$B$4="Chapter Boss",60/70,0)))),0)
...

Sheet Calc
A1: Key | B1: Name | C1: Unlocked | D1: InputLevel | E1: Factor | F1: CoefficientPercent | G1: EffectiveHits | H1: ProcProbability | I1: MapleHeroMultiplier | J1: BaseDamage | K1: BaseHitDamage | L1: NonCritAvg | M1: CritAvg | N1: ExpectedDamage(perHit) | O1: DPS | P1: % of Total | Q1: InvCooldown | R1: CastsInFight | S1: HitRate(perSec) | T1: BossOnlyDPS | V1: NormalOnlyDPS
A2: =Skills!A2 | B2: =Skills!B2 | C2: =Inputs!$B$3>=100 | F2: =Summary!$B$10+Skills!O2 | G2: =Skills!G2*IF(Skills!H2>0,Skills!I2/Skills!H2,1) | H2: =1-(1-Skills!J2/100)^Skills!K2 | I2: 1 | J2: =Summary!$B$6*(F2/100) | K2: =J2*(1+Summary!$B$7/100)*(1+Inputs!$B$15/100)*(1+Inputs!$B$16/100)*(5000/(6000+Inputs!$B$42*(1-Inputs!$B$19/100)))*(1+(Inputs!$B$24+Summary!$B$21)/100)*(1+Artifacts!$B$34/100)*(1+IF(Skills!A2="ENHANCED_RAGING_BLOW",IF(Inputs!$B$3>=134,MAX(0,IF(Inputs!$B$3>=110,7,5)-5)*50,0),0)/100)*(1+(IF(Skills!A2="RAGING_BLOW",Inputs!$B$17+Artifacts!$B$40,Inputs!$B$18+Artifacts!$B$39))/100)*(Summary!$B$13*(1+(Artifacts!$B$38+Artifacts!$B$36)/100)*I2) | L2: =K2*(MIN(Inputs!$B$22,Inputs!$B$23)/100+Inputs!$B$23/100)/2 | M2: =L2*(1+(Inputs!$B$10+Summary!$B$20+Artifacts!$B$33)/100) | N2: =L2*(1-MIN((Inputs!$B$9+Summary!$B$14+Artifacts!$B$32),100)/100)+M2*(MIN((Inputs!$B$9+Summary!$B$14+Artifacts!$B$32),100)/100) | O2: =(1-Summary!$B$11)*T2+Summary!$B$11*V2 | P2: =IF(Summary!$B$3=0,0,O2/Summary!$B$3) | Q2: 0 | R2: 0 | S2: =IFERROR(O2/N2,0) | T2: =IF(C2,(Skills!G2*N2*Summary!$B$19)*IF(Inputs!$B$38="pvp",1,1+(Inputs!$B$20+Skills!P2+Summary!$B$15+Artifacts!$B$35)/100)*((((5000/(6000+Inputs!$B$42*(1-(100*(1-(1-Inputs!$B$19/100)*(1-Artifacts!$B$51/100)^IF(Inputs!$B$38="pvp",1,2)))/100)))/(5000/(6000+Inputs!$B$42*(1-Inputs!$B$19/100))))*((L2*(1-MIN(100,(Inputs!$B$9+Summary!$B$14+Artifacts!$B$32)+Artifacts!$B$69)/100)+M2*(MIN(100,(Inputs!$B$9+Summary!$B$14+Artifacts!$B$32)+Artifacts!$B$69)/100))/(L2*(1-MIN(100,(Inputs!$B$9+Summary!$B$14+Artifacts!$B$32))/100)+M2*(MIN(100,(Inputs!$B$9+Summary!$B$14+Artifacts!$B$32))/100)))*(1+Artifacts!$B$81/100))),0) | V2: =IF(C2,(Skills!G2*N2*Summary!$B$19)*IF(Inputs!$B$38="pvp",1,(1+(Inputs!$B$21+Skills!Q2+Summary!$B$15+Artifacts!$B$80)/100)*(MIN(Skills!R2,Inputs!$B$37)))*((1+Artifacts!$B$53/100)),0)
A3: =Skills!A3 | B3: =Skills!B3 | C3: =Inputs!$B$3>=50 | D3: =IF(Skills!C3=1,60+Inputs!$B$25+Inputs!$B$29,IF(Skills!C3=2,90+Inputs!$B$26+Inputs!$B$29,IF(Skills!C3=3,120+Inputs!$B$27+Inputs!$B$29,MAX(0,(Inputs!$B$3-100)*3)+Inputs!$B$28+Inputs!$B$29))) | E3: =INDEX(FactorTable!$B$2:$Y$301, MATCH(ROUND(MIN(300,MAX(1,D3)),0), FactorTable!$A$2:$A$301,0), Skills!M3+1) | F3: =IF(Skills!N3=TRUE,(Skills!L3/10)*(E3/1000),Skills!L3/10)+Skills!O3 | I3: 1
A4: =Skills!A4 | B4: =Skills!B4 | C4: =Inputs!$B$3>=105 | D4: =IF(Skills!C4=1,60+Inputs!$B$25+Inputs!$B$29,IF(Skills!C4=2,90+Inputs!$B$26+Inputs!$B$29,IF(Skills!C4=3,120+Inputs!$B$27+Inputs!$B$29,MAX(0,(Inputs!$B$3-100)*3)+Inputs!$B$28+Inputs!$B$29))) | E4: =INDEX(FactorTable!$B$2:$Y$301, MATCH(ROUND(MIN(300,MAX(1,D4)),0), FactorTable!$A$2:$A$301,0), Skills!M4+1) | F4: =IF(Skills!N4=TRUE,(Skills!L4/10)*(E4/1000),Skills!L4/10)+Skills!O4 | I4: 1
A5: =Skills!A5 | B5: =Skills!B5 | C5: =Inputs!$B$3>=103 | D5: =IF(Skills!C5=1,60+Inputs!$B$25+Inputs!$B$29,IF(Skills!C5=2,90+Inputs!$B$26+Inputs!$B$29,IF(Skills!C5=3,120+Inputs!$B$27+Inputs!$B$29,MAX(0,(Inputs!$B$3-100)*3)+Inputs!$B$28+Inputs!$B$29))) | E5: =INDEX(FactorTable!$B$2:$Y$301, MATCH(ROUND(MIN(300,MAX(1,D5)),0), FactorTable!$A$2:$A$301,0), Skills!M5+1) | F5: =IF(Skills!N5=TRUE,(Skills!L5/10)*(E5/1000),Skills!L5/10)+Skills!O5 | G5: =Skills!G5*IF(Skills!H5>0,Skills!I5/Skills!H5,1) | H5: =1-(1-Skills!J5/100)^Skills!K5 | I5: 1 | J5: =Summary!$B$6*(F5/100) | K5: =J5*(1+Summary!$B$7/100)*(1+Inputs!$B$15/100)*(1+Inputs!$B$16/100)*(5000/(6000+Inputs!$B$42*(1-Inputs!$B$19/100)))*(1+(Inputs!$B$24+Summary!$B$21)/100)*(1+Artifacts!$B$34/100)*(1+IF(Skills!A5="ENHANCED_RAGING_BLOW",IF(Inputs!$B$3>=134,MAX(0,IF(Inputs!$B$3>=110,7,5)-5)*50,0),0)/100)*(1+(IF(Skills!A5="RAGING_BLOW",Inputs!$B$17+Artifacts!$B$40,Inputs!$B$18+Artifacts!$B$39))/100)*(Summary!$B$13*(1+(Artifacts!$B$38+Artifacts!$B$36)/100)*I5) | L5: =K5*(MIN(Inputs!$B$22,Inputs!$B$23)/100+Inputs!$B$23/100)/2 | M5: =L5*(1+(Inputs!$B$10+Summary!$B$20+Artifacts!$B$33)/100) | N5: =L5*(1-MIN((Inputs!$B$9+Summary!$B$14+Artifacts!$B$32),100)/100)+M5*(MIN((Inputs!$B$9+Summary!$B$14+Artifacts!$B$32),100)/100) | O5: =(1-Summary!$B$11)*T5+Summary!$B$11*V5 | P5: =IF(Summary!$B$3=0,0,O5/Summary!$B$3) | Q5: =IFERROR(1/(IF(Inputs!$B$38="pvp",15,MAX(0.1,Skills!D5-IF(Skills!E5=TRUE,Inputs!$B$32,0)))*(1-IF(AND(ArtifactsInput!$M$27,Inputs!$B$4="Chapter Hunt"),CHOOSE(ArtifactsInput!$N$27+1,20,24,28,32,36,40),0)/100)),0) | R5: =IF(AND(Inputs!$B$38<>"pvp",Inputs!$B$43>0),IF(MAX(0,Inputs!$B$43-Summary!$B$23)<=0,0,(INT(MAX(0,Inputs!$B$43-Summary!$B$23)/(IF(Inputs!$B$38="pvp",15,MAX(0.1,Skills!D5-IF(Skills!E5=TRUE,Inputs!$B$32,0)))*(1-IF(AND(ArtifactsInput!$M$27,Inputs!$B$4="Chapter Hunt"),CHOOSE(ArtifactsInput!$N$27+1,20,24,28,32,36,40),0)/100)))+1)),0) | S5: =IFERROR(O5/N5,0) | T5: =IF(C5,(H5*N5*IF(AND(Inputs!$B$38<>"pvp",Inputs!$B$43>0),((Skills!G5*((R5-1)*IF(Skills!H5>0,Skills!I5/Skills!H5,1)+IF(Skills!H5>0,MIN(Skills!I5,MAX(0,MAX(0,Inputs!$B$43-Summary!$B$23)-((R5-1)*(IF(Inputs!$B$38="pvp",15,MAX(0.1,Skills!D5-IF(Skills!E5=TRUE,Inputs!$B$32,0)))*(1-IF(AND(ArtifactsInput!$M$27,Inputs!$B$4="Chapter Hunt"),CHOOSE(ArtifactsInput!$N$27+1,20,24,28,32,36,40),0)/100)))))/Skills!H5,1)))/Inputs!$B$43),G5*Q5))*IF(Inputs!$B$38="pvp",1,1+(Inputs!$B$20+Skills!P5+Summary!$B$15+Artifacts!$B$35)/100)*((((5000/(6000+Inputs!$B$42*(1-(100*(1-(1-Inputs!$B$19/100)*(1-Artifacts!$B$51/100)^IF(Inputs!$B$38="pvp",1,2)))/100)))/(5000/(6000+Inputs!$B$42*(1-Inputs!$B$19/100))))*((L5*(1-MIN(100,(Inputs!$B$9+Summary!$B$14+Artifacts!$B$32)+Artifacts!$B$69)/100)+M5*(MIN(100,(Inputs!$B$9+Summary!$B$14+Artifacts!$B$32)+Artifacts!$B$69)/100))/(L5*(1-MIN(100,(Inputs!$B$9+Summary!$B$14+Artifacts!$B$32))/100)+M5*(MIN(100,(Inputs!$B$9+Summary!$B$14+Artifacts!$B$32))/100)))*(1+Artifacts!$B$81/100))),0) | V5: =IF(C5,(H5*N5*IF(AND(Inputs!$B$38<>"pvp",Inputs!$B$43>0),((Skills!G5*((R5-1)*IF(Skills!H5>0,Skills!I5/Skills!H5,1)+IF(Skills!H5>0,MIN(Skills!I5,MAX(0,MAX(0,Inputs!$B$43-Summary!$B$23)-((R5-1)*(IF(Inputs!$B$38="pvp",15,MAX(0.1,Skills!D5-IF(Skills!E5=TRUE,Inputs!$B$32,0)))*(1-IF(AND(ArtifactsInput!$M$27,Inputs!$B$4="Chapter Hunt"),CHOOSE(ArtifactsInput!$N$27+1,20,24,28,32,36,40),0)/100)))))/Skills!H5,1)))/Inputs!$B$43),G5*Q5))*IF(Inputs!$B$38="pvp",1,(1+(Inputs!$B$21+Skills!Q5+Summary!$B$15+Artifacts!$B$80)/100)*(MIN(Skills!R5,Inputs!$B$37)))*((1+Artifacts!$B$53/100)),0)
A6: =Skills!A6 | B6: =Skills!B6 | C6: =Inputs!$B$3>=103 | D6: =IF(Skills!C6=1,60+Inputs!$B$25+Inputs!$B$29,IF(Skills!C6=2,90+Inputs!$B$26+Inputs!$B$29,IF(Skills!C6=3,120+Inputs!$B$27+Inputs!$B$29,MAX(0,(Inputs!$B$3-100)*3)+Inputs!$B$28+Inputs!$B$29))) | E6: =INDEX(FactorTable!$B$2:$Y$301, MATCH(ROUND(MIN(300,MAX(1,D6)),0), FactorTable!$A$2:$A$301,0), Skills!M6+1) | F6: =IF(Skills!N6=TRUE,(Skills!L6/10)*(E6/1000),Skills!L6/10)+Skills!O6 | G6: =Skills!G6*IF(Skills!H6>0,Skills!I6/Skills!H6,1) | H6: =1-(1-Skills!J6/100)^Skills!K6 | I6: 1 | J6: =Summary!$B$6*(F6/100) | K6: =J6*(1+Summary!$B$7/100)*(1+Inputs!$B$15/100)*(1+Inputs!$B$16/100)*(5000/(6000+Inputs!$B$42*(1-Inputs!$B$19/100)))*(1+(Inputs!$B$24+Summary!$B$21)/100)*(1+Artifacts!$B$34/100)*(1+IF(Skills!A6="ENHANCED_RAGING_BLOW",IF(Inputs!$B$3>=134,MAX(0,IF(Inputs!$B$3>=110,7,5)-5)*50,0),0)/100)*(1+(IF(Skills!A6="RAGING_BLOW",Inputs!$B$17+Artifacts!$B$40,Inputs!$B$18+Artifacts!$B$39))/100)*(Summary!$B$13*(1+(Artifacts!$B$38+Artifacts!$B$36)/100)*I6) | L6: =K6*(MIN(Inputs!$B$22,Inputs!$B$23)/100+Inputs!$B$23/100)/2 | M6: =L6*(1+(Inputs!$B$10+Summary!$B$20+Artifacts!$B$33)/100) | N6: =L6*(1-MIN((Inputs!$B$9+Summary!$B$14+Artifacts!$B$32),100)/100)+M6*(MIN((Inputs!$B$9+Summary!$B$14+Artifacts!$B$32),100)/100) | O6: =(1-Summary!$B$11)*T6+Summary!$B$11*V6 | P6: =IF(Summary!$B$3=0,0,O6/Summary!$B$3) | Q6: =IFERROR(1/(IF(Inputs!$B$38="pvp",15,MAX(0.1,Skills!D6-IF(Skills!E6=TRUE,Inputs!$B$32,0)))*(1-IF(AND(ArtifactsInput!$M$27,Inputs!$B$4="Chapter Hunt"),CHOOSE(ArtifactsInput!$N$27+1,20,24,28,32,36,40),0)/100)),0) | R6: =IF(AND(Inputs!$B$38<>"pvp",Inputs!$B$43>0),IF(MAX(0,Inputs!$B$43-Summary!$B$23)<=0,0,(INT(MAX(0,Inputs!$B$43-Summary!$B$23)/(IF(Inputs!$B$38="pvp",15,MAX(0.1,Skills!D6-IF(Skills!E6=TRUE,Inputs!$B$32,0)))*(1-IF(AND(ArtifactsInput!$M$27,Inputs!$B$4="Chapter Hunt"),CHOOSE(ArtifactsInput!$N$27+1,20,24,28,32,36,40),0)/100)))+1)),0) | S6: =IFERROR(O6/N6,0) | T6: =IF(C6,(H6*N6*IF(AND(Inputs!$B$38<>"pvp",Inputs!$B$43>0),((Skills!G6*((R6-1)*IF(Skills!H6>0,Skills!I6/Skills!H6,1)+IF(Skills!H6>0,MIN(Skills!I6,MAX(0,MAX(0,Inputs!$B$43-Summary!$B$23)-((R6-1)*(IF(Inputs!$B$38="pvp",15,MAX(0.1,Skills!D6-IF(Skills!E6=TRUE,Inputs!$B$32,0)))*(1-IF(AND(ArtifactsInput!$M$27,Inputs!$B$4="Chapter Hunt"),CHOOSE(ArtifactsInput!$N$27+1,20,24,28,32,36,40),0)/100)))))/Skills!H6,1)))/Inputs!$B$43),G6*Q6))*IF(Inputs!$B$38="pvp",1,1+(Inputs!$B$20+Skills!P6+Summary!$B$15+Artifacts!$B$35)/100)*((((5000/(6000+Inputs!$B$42*(1-(100*(1-(1-Inputs!$B$19/100)*(1-Artifacts!$B$51/100)^IF(Inputs!$B$38="pvp",1,2)))/100)))/(5000/(6000+Inputs!$B$42*(1-Inputs!$B$19/100))))*((L6*(1-MIN(100,(Inputs!$B$9+Summary!$B$14+Artifacts!$B$32)+Artifacts!$B$69)/100)+M6*(MIN(100,(Inputs!$B$9+Summary!$B$14+Artifacts!$B$32)+Artifacts!$B$69)/100))/(L6*(1-MIN(100,(Inputs!$B$9+Summary!$B$14+Artifacts!$B$32))/100)+M6*(MIN(100,(Inputs!$B$9+Summary!$B$14+Artifacts!$B$32))/100)))*(1+Artifacts!$B$81/100))),0) | V6: =IF(C6,(H6*N6*IF(AND(Inputs!$B$38<>"pvp",Inputs!$B$43>0),((Skills!G6*((R6-1)*IF(Skills!H6>0,Skills!I6/Skills!H6,1)+IF(Skills!H6>0,MIN(Skills!I6,MAX(0,MAX(0,Inputs!$B$43-Summary!$B$23)-((R6-1)*(IF(Inputs!$B$38="pvp",15,MAX(0.1,Skills!D6-IF(Skills!E6=TRUE,Inputs!$B$32,0)))*(1-IF(AND(ArtifactsInput!$M$27,Inputs!$B$4="Chapter Hunt"),CHOOSE(ArtifactsInput!$N$27+1,20,24,28,32,36,40),0)/100)))))/Skills!H6,1)))/Inputs!$B$43),G6*Q6))*IF(Inputs!$B$38="pvp",1,(1+(Inputs!$B$21+Skills!Q6+Summary!$B$15+Artifacts!$B$80)/100)*(MIN(Skills!R6,Inputs!$B$37)))*((1+Artifacts!$B$53/100)),0)
A7: =Skills!A7 | B7: =Skills!B7 | C7: =Inputs!$B$3>=107 | D7: =IF(Skills!C7=1,60+Inputs!$B$25+Inputs!$B$29,IF(Skills!C7=2,90+Inputs!$B$26+Inputs!$B$29,IF(Skills!C7=3,120+Inputs!$B$27+Inputs!$B$29,MAX(0,(Inputs!$B$3-100)*3)+Inputs!$B$28+Inputs!$B$29))) | E7: =INDEX(FactorTable!$B$2:$Y$301, MATCH(ROUND(MIN(300,MAX(1,D7)),0), FactorTable!$A$2:$A$301,0), Skills!M7+1) | F7: =IF(Skills!N7=TRUE,(Skills!L7/10)*(E7/1000),Skills!L7/10)+Skills!O7 | G7: =Skills!G7*IF(Skills!H7>0,Skills!I7/Skills!H7,1) | H7: =1-(1-Skills!J7/100)^Skills!K7 | I7: 1 | J7: =Summary!$B$6*(F7/100) | K7: =J7*(1+Summary!$B$7/100)*(1+Inputs!$B$15/100)*(1+Inputs!$B$16/100)*(5000/(6000+Inputs!$B$42*(1-Inputs!$B$19/100)))*(1+(Inputs!$B$24+Summary!$B$21)/100)*(1+Artifacts!$B$34/100)*(1+IF(Skills!A7="ENHANCED_RAGING_BLOW",IF(Inputs!$B$3>=134,MAX(0,IF(Inputs!$B$3>=110,7,5)-5)*50,0),0)/100)*(1+(IF(Skills!A7="RAGING_BLOW",Inputs!$B$17+Artifacts!$B$40,Inputs!$B$18+Artifacts!$B$39))/100)*(Summary!$B$13*(1+(Artifacts!$B$38+Artifacts!$B$36)/100)*I7) | L7: =K7*(MIN(Inputs!$B$22,Inputs!$B$23)/100+Inputs!$B$23/100)/2 | M7: =L7*(1+(Inputs!$B$10+Summary!$B$20+Artifacts!$B$33)/100) | N7: =L7*(1-MIN((Inputs!$B$9+Summary!$B$14+Artifacts!$B$32),100)/100)+M7*(MIN((Inputs!$B$9+Summary!$B$14+Artifacts!$B$32),100)/100) | O7: =(1-Summary!$B$11)*T7+Summary!$B$11*V7 | P7: =IF(Summary!$B$3=0,0,O7/Summary!$B$3) | Q7: =IFERROR(1/(IF(Inputs!$B$38="pvp",15,MAX(0.1,Skills!D7-IF(Skills!E7=TRUE,Inputs!$B$32,0)))*(1-IF(AND(ArtifactsInput!$M$27,Inputs!$B$4="Chapter Hunt"),CHOOSE(ArtifactsInput!$N$27+1,20,24,28,32,36,40),0)/100)),0) | R7: =IF(AND(Inputs!$B$38<>"pvp",Inputs!$B$43>0),IF(MAX(0,Inputs!$B$43-Summary!$B$23)<=0,0,(INT(MAX(0,Inputs!$B$43-Summary!$B$23)/(IF(Inputs!$B$38="pvp",15,MAX(0.1,Skills!D7-IF(Skills!E7=TRUE,Inputs!$B$32,0)))*(1-IF(AND(ArtifactsInput!$M$27,Inputs!$B$4="Chapter Hunt"),CHOOSE(ArtifactsInput!$N$27+1,20,24,28,32,36,40),0)/100)))+1)),0) | S7: =IFERROR(O7/N7,0) | T7: =IF(C7,(H7*N7*IF(AND(Inputs!$B$38<>"pvp",Inputs!$B$43>0),((Skills!G7*((R7-1)*IF(Skills!H7>0,Skills!I7/Skills!H7,1)+IF(Skills!H7>0,MIN(Skills!I7,MAX(0,MAX(0,Inputs!$B$43-Summary!$B$23)-((R7-1)*(IF(Inputs!$B$38="pvp",15,MAX(0.1,Skills!D7-IF(Skills!E7=TRUE,Inputs!$B$32,0)))*(1-IF(AND(ArtifactsInput!$M$27,Inputs!$B$4="Chapter Hunt"),CHOOSE(ArtifactsInput!$N$27+1,20,24,28,32,36,40),0)/100)))))/Skills!H7,1)))/Inputs!$B$43),G7*Q7))*IF(Inputs!$B$38="pvp",1,1+(Inputs!$B$20+Skills!P7+Summary!$B$15+Artifacts!$B$35)/100)*((((5000/(6000+Inputs!$B$42*(1-(100*(1-(1-Inputs!$B$19/100)*(1-Artifacts!$B$51/100)^IF(Inputs!$B$38="pvp",1,2)))/100)))/(5000/(6000+Inputs!$B$42*(1-Inputs!$B$19/100))))*((L7*(1-MIN(100,(Inputs!$B$9+Summary!$B$14+Artifacts!$B$32)+Artifacts!$B$69)/100)+M7*(MIN(100,(Inputs!$B$9+Summary!$B$14+Artifacts!$B$32)+Artifacts!$B$69)/100))/(L7*(1-MIN(100,(Inputs!$B$9+Summary!$B$14+Artifacts!$B$32))/100)+M7*(MIN(100,(Inputs!$B$9+Summary!$B$14+Artifacts!$B$32))/100)))*(1+Artifacts!$B$81/100))),0) | V7: =IF(C7,(H7*N7*IF(AND(Inputs!$B$38<>"pvp",Inputs!$B$43>0),((Skills!G7*((R7-1)*IF(Skills!H7>0,Skills!I7/Skills!H7,1)+IF(Skills!H7>0,MIN(Skills!I7,MAX(0,MAX(0,Inputs!$B$43-Summary!$B$23)-((R7-1)*(IF(Inputs!$B$38="pvp",15,MAX(0.1,Skills!D7-IF(Skills!E7=TRUE,Inputs!$B$32,0)))*(1-IF(AND(ArtifactsInput!$M$27,Inputs!$B$4="Chapter Hunt"),CHOOSE(ArtifactsInput!$N$27+1,20,24,28,32,36,40),0)/100)))))/Skills!H7,1)))/Inputs!$B$43),G7*Q7))*IF(Inputs!$B$38="pvp",1,(1+(Inputs!$B$21+Skills!Q7+Summary!$B$15+Artifacts!$B$80)/100)*(MIN(Skills!R7,Inputs!$B$37)))*((1+Artifacts!$B$53/100)),0)
A8: =Skills!A8 | B8: =Skills!B8 | C8: =Inputs!$B$3>=117 | D8: =IF(Skills!C8=1,60+Inputs!$B$25+Inputs!$B$29,IF(Skills!C8=2,90+Inputs!$B$26+Inputs!$B$29,IF(Skills!C8=3,120+Inputs!$B$27+Inputs!$B$29,MAX(0,(Inputs!$B$3-100)*3)+Inputs!$B$28+Inputs!$B$29))) | E8: =INDEX(FactorTable!$B$2:$Y$301, MATCH(ROUND(MIN(300,MAX(1,D8)),0), FactorTable!$A$2:$A$301,0), Skills!M8+1) | F8: =IF(Skills!N8=TRUE,(Skills!L8/10)*(E8/1000),Skills!L8/10)+Skills!O8 | G8: =Skills!G8*IF(Skills!H8>0,Skills!I8/Skills!H8,1) | H8: =1-(1-Skills!J8/100)^Skills!K8 | I8: 1 | J8: =Summary!$B$6*(F8/100) | K8: =J8*(1+Summary!$B$7/100)*(1+Inputs!$B$15/100)*(1+Inputs!$B$16/100)*(5000/(6000+Inputs!$B$42*(1-Inputs!$B$19/100)))*(1+(Inputs!$B$24+Summary!$B$21)/100)*(1+Artifacts!$B$34/100)*(1+IF(Skills!A8="ENHANCED_RAGING_BLOW",IF(Inputs!$B$3>=134,MAX(0,IF(Inputs!$B$3>=110,7,5)-5)*50,0),0)/100)*(1+(IF(Skills!A8="RAGING_BLOW",Inputs!$B$17+Artifacts!$B$40,Inputs!$B$18+Artifacts!$B$39))/100)*(Summary!$B$13*(1+(Artifacts!$B$38+Artifacts!$B$36)/100)*I8) | L8: =K8*(MIN(Inputs!$B$22,Inputs!$B$23)/100+Inputs!$B$23/100)/2 | M8: =L8*(1+(Inputs!$B$10+Summary!$B$20+Artifacts!$B$33)/100) | N8: =L8*(1-MIN((Inputs!$B$9+Summary!$B$14+Artifacts!$B$32),100)/100)+M8*(MIN((Inputs!$B$9+Summary!$B$14+Artifacts!$B$32),100)/100) | O8: =(1-Summary!$B$11)*T8+Summary!$B$11*V8 | P8: =IF(Summary!$B$3=0,0,O8/Summary!$B$3) | Q8: =IFERROR(1/(IF(Inputs!$B$38="pvp",15,MAX(0.1,Skills!D8-IF(Skills!E8=TRUE,Inputs!$B$32,0)))*(1-IF(AND(ArtifactsInput!$M$27,Inputs!$B$4="Chapter Hunt"),CHOOSE(ArtifactsInput!$N$27+1,20,24,28,32,36,40),0)/100)),0) | R8: =IF(AND(Inputs!$B$38<>"pvp",Inputs!$B$43>0),IF(MAX(0,Inputs!$B$43-Summary!$B$23)<=0,0,(INT(MAX(0,Inputs!$B$43-Summary!$B$23)/(IF(Inputs!$B$38="pvp",15,MAX(0.1,Skills!D8-IF(Skills!E8=TRUE,Inputs!$B$32,0)))*(1-IF(AND(ArtifactsInput!$M$27,Inputs!$B$4="Chapter Hunt"),CHOOSE(ArtifactsInput!$N$27+1,20,24,28,32,36,40),0)/100)))+1)),0) | S8: =IFERROR(O8/N8,0) | T8: =IF(C8,(H8*N8*IF(AND(Inputs!$B$38<>"pvp",Inputs!$B$43>0),((Skills!G8*((R8-1)*IF(Skills!H8>0,Skills!I8/Skills!H8,1)+IF(Skills!H8>0,MIN(Skills!I8,MAX(0,MAX(0,Inputs!$B$43-Summary!$B$23)-((R8-1)*(IF(Inputs!$B$38="pvp",15,MAX(0.1,Skills!D8-IF(Skills!E8=TRUE,Inputs!$B$32,0)))*(1-IF(AND(ArtifactsInput!$M$27,Inputs!$B$4="Chapter Hunt"),CHOOSE(ArtifactsInput!$N$27+1,20,24,28,32,36,40),0)/100)))))/Skills!H8,1)))/Inputs!$B$43),G8*Q8))*IF(Inputs!$B$38="pvp",1,1+(Inputs!$B$20+Skills!P8+Summary!$B$15+Artifacts!$B$35)/100)*((((5000/(6000+Inputs!$B$42*(1-(100*(1-(1-Inputs!$B$19/100)*(1-Artifacts!$B$51/100)^IF(Inputs!$B$38="pvp",1,2)))/100)))/(5000/(6000+Inputs!$B$42*(1-Inputs!$B$19/100))))*((L8*(1-MIN(100,(Inputs!$B$9+Summary!$B$14+Artifacts!$B$32)+Artifacts!$B$69)/100)+M8*(MIN(100,(Inputs!$B$9+Summary!$B$14+Artifacts!$B$32)+Artifacts!$B$69)/100))/(L8*(1-MIN(100,(Inputs!$B$9+Summary!$B$14+Artifacts!$B$32))/100)+M8*(MIN(100,(Inputs!$B$9+Summary!$B$14+Artifacts!$B$32))/100)))*(1+Artifacts!$B$81/100))),0) | V8: =IF(C8,(H8*N8*IF(AND(Inputs!$B$38<>"pvp",Inputs!$B$43>0),((Skills!G8*((R8-1)*IF(Skills!H8>0,Skills!I8/Skills!H8,1)+IF(Skills!H8>0,MIN(Skills!I8,MAX(0,MAX(0,Inputs!$B$43-Summary!$B$23)-((R8-1)*(IF(Inputs!$B$38="pvp",15,MAX(0.1,Skills!D8-IF(Skills!E8=TRUE,Inputs!$B$32,0)))*(1-IF(AND(ArtifactsInput!$M$27,Inputs!$B$4="Chapter Hunt"),CHOOSE(ArtifactsInput!$N$27+1,20,24,28,32,36,40),0)/100)))))/Skills!H8,1)))/Inputs!$B$43),G8*Q8))*IF(Inputs!$B$38="pvp",1,(1+(Inputs!$B$21+Skills!Q8+Summary!$B$15+Artifacts!$B$80)/100)*(MIN(Skills!R8,Inputs!$B$37)))*((1+Artifacts!$B$53/100)),0)
A9: =Skills!A9 | B9: =Skills!B9 | C9: =Inputs!$B$3>=69 | D9: =IF(Skills!C9=1,60+Inputs!$B$25+Inputs!$B$29,IF(Skills!C9=2,90+Inputs!$B$26+Inputs!$B$29,IF(Skills!C9=3,120+Inputs!$B$27+Inputs!$B$29,MAX(0,(Inputs!$B$3-100)*3)+Inputs!$B$28+Inputs!$B$29))) | E9: =INDEX(FactorTable!$B$2:$Y$301, MATCH(ROUND(MIN(300,MAX(1,D9)),0), FactorTable!$A$2:$A$301,0), Skills!M9+1) | F9: =IF(Skills!N9=TRUE,(Skills!L9/10)*(E9/1000),Skills!L9/10)+Skills!O9 | G9: =Skills!G9*IF(Skills!H9>0,Skills!I9/Skills!H9,1) | H9: =1-(1-Skills!J9/100)^Skills!K9 | I9: 1 | J9: =Summary!$B$6*(F9/100) | K9: =J9*(1+Summary!$B$7/100)*(1+Inputs!$B$15/100)*(1+Inputs!$B$16/100)*(5000/(6000+Inputs!$B$42*(1-Inputs!$B$19/100)))*(1+(Inputs!$B$24+Summary!$B$21)/100)*(1+Artifacts!$B$34/100)*(1+1.0*IF(C12=TRUE,F12,0)/100)*(1+IF(Skills!A9="ENHANCED_RAGING_BLOW",IF(Inputs!$B$3>=134,MAX(0,IF(Inputs!$B$3>=110,7,5)-5)*50,0),0)/100)*(1+(IF(Skills!A9="RAGING_BLOW",Inputs!$B$17+Artifacts!$B$40,Inputs!$B$18+Artifacts!$B$39))/100)*(Summary!$B$13*(1+(Artifacts!$B$38+Artifacts!$B$36)/100)*I9) | L9: =K9*(MIN(Inputs!$B$22,Inputs!$B$23)/100+Inputs!$B$23/100)/2 | M9: =L9*(1+(Inputs!$B$10+Summary!$B$20+Artifacts!$B$33)/100) | N9: =L9*(1-MIN((Inputs!$B$9+Summary!$B$14+Artifacts!$B$32),100)/100)+M9*(MIN((Inputs!$B$9+Summary!$B$14+Artifacts!$B$32),100)/100) | O9: =(1-Summary!$B$11)*T9+Summary!$B$11*V9 | P9: =IF(Summary!$B$3=0,0,O9/Summary!$B$3) | Q9: =IFERROR(1/(IF(Inputs!$B$38="pvp",15,MAX(0.1,Skills!D9-IF(Skills!E9=TRUE,Inputs!$B$32,0)))*(1-IF(AND(ArtifactsInput!$M$27,Inputs!$B$4="Chapter Hunt"),CHOOSE(ArtifactsInput!$N$27+1,20,24,28,32,36,40),0)/100)),0) | R9: =IF(AND(Inputs!$B$38<>"pvp",Inputs!$B$43>0),IF(MAX(0,Inputs!$B$43-Summary!$B$23)<=0,0,(INT(MAX(0,Inputs!$B$43-Summary!$B$23)/(IF(Inputs!$B$38="pvp",15,MAX(0.1,Skills!D9-IF(Skills!E9=TRUE,Inputs!$B$32,0)))*(1-IF(AND(ArtifactsInput!$M$27,Inputs!$B$4="Chapter Hunt"),CHOOSE(ArtifactsInput!$N$27+1,20,24,28,32,36,40),0)/100)))+1)),0) | S9: =IFERROR(O9/N9,0) | T9: =IF(C9,(H9*N9*IF(AND(Inputs!$B$38<>"pvp",Inputs!$B$43>0),((Skills!G9*((R9-1)*IF(Skills!H9>0,Skills!I9/Skills!H9,1)+IF(Skills!H9>0,MIN(Skills!I9,MAX(0,MAX(0,Inputs!$B$43-Summary!$B$23)-((R9-1)*(IF(Inputs!$B$38="pvp",15,MAX(0.1,Skills!D9-IF(Skills!E9=TRUE,Inputs!$B$32,0)))*(1-IF(AND(ArtifactsInput!$M$27,Inputs!$B$4="Chapter Hunt"),CHOOSE(ArtifactsInput!$N$27+1,20,24,28,32,36,40),0)/100)))))/Skills!H9,1)))/Inputs!$B$43),G9*Q9))*IF(Inputs!$B$38="pvp",1,1+(Inputs!$B$20+Skills!P9+Summary!$B$15+Artifacts!$B$35)/100)*((((5000/(6000+Inputs!$B$42*(1-(100*(1-(1-Inputs!$B$19/100)*(1-Artifacts!$B$51/100)^IF(Inputs!$B$38="pvp",1,2)))/100)))/(5000/(6000+Inputs!$B$42*(1-Inputs!$B$19/100))))*((L9*(1-MIN(100,(Inputs!$B$9+Summary!$B$14+Artifacts!$B$32)+Artifacts!$B$69)/100)+M9*(MIN(100,(Inputs!$B$9+Summary!$B$14+Artifacts!$B$32)+Artifacts!$B$69)/100))/(L9*(1-MIN(100,(Inputs!$B$9+Summary!$B$14+Artifacts!$B$32))/100)+M9*(MIN(100,(Inputs!$B$9+Summary!$B$14+Artifacts!$B$32))/100)))*(1+Artifacts!$B$81/100))),0) | V9: =IF(C9,(H9*N9*IF(AND(Inputs!$B$38<>"pvp",Inputs!$B$43>0),((Skills!G9*((R9-1)*IF(Skills!H9>0,Skills!I9/Skills!H9,1)+IF(Skills!H9>0,MIN(Skills!I9,MAX(0,MAX(0,Inputs!$B$43-Summary!$B$23)-((R9-1)*(IF(Inputs!$B$38="pvp",15,MAX(0.1,Skills!D9-IF(Skills!E9=TRUE,Inputs!$B$32,0)))*(1-IF(AND(ArtifactsInput!$M$27,Inputs!$B$4="Chapter Hunt"),CHOOSE(ArtifactsInput!$N$27+1,20,24,28,32,36,40),0)/100)))))/Skills!H9,1)))/Inputs!$B$43),G9*Q9))*IF(Inputs!$B$38="pvp",1,(1+(Inputs!$B$21+Skills!Q9+Summary!$B$15+Artifacts!$B$80)/100)*(MIN(Skills!R9,Inputs!$B$37)))*((1+Artifacts!$B$53/100)),0)
