Workbook

Sheet README
A1: Night Lord — DPS Calculator: How to Use This Workbook
A3: How to use this workbook
A4: Only edit the yellow-highlighted cells on the Inputs sheet — every other sheet is computed from those values and will be overwritten if you rebuild the workbook.
A5: Summary shows Total DPS, a Per-Skill DPS Breakdown (damage-dealing skills only — buffs/passives that never deal their own damage are omitted), and a Marginal DPS & Stat Value table showing the DPS gained per +1 of each stat.
A6: Sensitivity has the full detail behind that marginal-value table — one self-contained block per stat, showing exactly how bumping that stat by +1 changes every downstream number.
A7: CubeData/PotentialCubes model your current gear's Potential Cube lines and drive cube-reroll expected-value decisions. For the full standalone Potential Cube EV calculator (exact optimal-stopping math, works from this workbook alone), see tools/potential_cubes_ev.py in the project repo.
A9: Design decisions & assumptions
A10: Venom/Toxic Venom assume the target is permanently afflicted with Venom's poison at steady state, not an exact on/off timer.
A11: Crit Rate pushed above 100% (e.g. by cube potential lines) automatically redirects its stat-value to Crit Damage's own per-unit DPS value on the PotentialCubes sheet, since excess Crit Rate cannot do anything past 100%.
A12: Buffs (Dark Sight, Frailty Curse, Nimble Feet) are modeled at steady-state duty-cycle average uptime, not as an exact moment-to-moment state machine. Alchemic Adrenaline's own action-rate-driven stack-up cycle is likewise modeled as a steady-state average uptime rather than an exact stack counter.
A13: Shadow Partner and Shadow Shifter are modeled as steady-state average multipliers (expected extra damage per hit / expected counterattack rate) rather than an exact proc-by-proc simulation.
A14: Content Type (Inputs) picks what you're fighting — Chapter Boss/Breakthrough/PvP/EXP Dungeon/Equipment Dungeon/Weapon Dungeon/Enhancement Dungeon/Hero Dungeon/World Boss/Chapter Hunt — and Monster Defense and Fixed Fight Duration are both auto-computed from it (plus Chapter/Stage for the chapter- and dungeon-based types); PvP still forces its own fixed 15-second window and uses your own Defense stat as the opponent's Defense estimate. See README.md's 'Content Type' section for the exact formulas.
A15: Not modeled (out of scope): crowd control, Accuracy/Evasion/Defense reduction, movement speed, the character's own Defense stat, and Companion Summoning Time.

Sheet Inputs
A1: Night Lord — DPS Calculator Inputs | N1: (none)
C2: Chapter Boss | D2: Breakthrough | E2: PvP | F2: EXP Dungeon | G2: Equipment Dungeon | H2: Weapon Dungeon | I2: Enhancement Dungeon | J2: Hero Dungeon | K2: World Boss | L2: Chapter Hunt | N2: Charm of the Undead
A3: Character Level | B3: 200 | N3: Pig's Ribbon
A4: Content Type | B4: Chapter Boss | N4: Shamaness Marble
A5: Chapter-Stage — 'chapter-substage' (e.g. '28-9') for Breakthrough/Chapter Hunt, just the chapter number for Chapter Boss, or just the stage number for Weapon/Equipment/Enhancement/EXP/Hero Dungeon. Not applicable to World Boss/PvP. | B5: =INDEX($C$5:$L$5,MATCH($B$4,$C$2:$L$2,0)) | C5: 28 | D5: 28-9 | F5: 80 | G5: 80 | H5: 80 | I5: 80 | J5: 80 | L5: 28-9 | N5: The Contract of Darkness
A6: Flat ATTACK | B6: =INDEX($C$6:$L$6,MATCH($B$4,$C$2:$L$2,0)) | C6: 10000 | D6: 10000 | E6: 10000 | F6: 10000 | G6: 10000 | H6: 10000 | I6: 10000 | J6: 10000 | K6: 10000 | L6: 10000 | N6: Rainbow-colored Snail Shell
A7: ATTACK % | B7: =INDEX($C$7:$L$7,MATCH($B$4,$C$2:$L$2,0)) | C7: 0 | D7: 0 | E7: 0 | F7: 0 | G7: 0 | H7: 0 | I7: 0 | J7: 0 | K7: 0 | L7: 0 | N7: Hexagon Necklace
A8: Defense (your own DEF stat; PvP assumes the opponent has the same Defense as you) | B8: =INDEX($C$8:$L$8,MATCH($B$4,$C$2:$L$2,0)) | C8: 0 | D8: 0 | E8: 0 | F8: 0 | G8: 0 | H8: 0 | I8: 0 | J8: 0 | K8: 0 | L8: 0 | N8: Arwen's Glass Shoes
A9: CRIT_RATE % | B9: =INDEX($C$9:$L$9,MATCH($B$4,$C$2:$L$2,0)) | C9: 0 | D9: 0 | E9: 0 | F9: 0 | G9: 0 | H9: 0 | I9: 0 | J9: 0 | K9: 0 | L9: 0 | N9: Mushmom's Cap
A10: CRIT_DAMAGE % | B10: =INDEX($C$10:$L$10,MATCH($B$4,$C$2:$L$2,0)) | C10: 0 | D10: 0 | E10: 0 | F10: 0 | G10: 0 | H10: 0 | I10: 0 | J10: 0 | K10: 0 | L10: 0 | N10: Clear Spring Water
A11: ATTACK_SPEED % (base, excludes Nimble Feet/Adrenalin) | B11: =INDEX($C$11:$L$11,MATCH($B$4,$C$2:$L$2,0)) | C11: 0 | D11: 0 | E11: 0 | F11: 0 | G11: 0 | H11: 0 | I11: 0 | J11: 0 | K11: 0 | L11: 0 | N11: Athena Pierce's Old Gloves
A12: Flat LUK | B12: =INDEX($C$12:$L$12,MATCH($B$4,$C$2:$L$2,0)) | C12: 0 | D12: 0 | E12: 0 | F12: 0 | G12: 0 | H12: 0 | I12: 0 | J12: 0 | K12: 0 | L12: 0 | N12: Zakum's Stone Piece
A13: LUK % | B13: =INDEX($C$13:$L$13,MATCH($B$4,$C$2:$L$2,0)) | C13: 0 | D13: 0 | E13: 0 | F13: 0 | G13: 0 | H13: 0 | I13: 0 | J13: 0 | K13: 0 | L13: 0 | N13: Horntail's Scale
A14: DEX | B14: =INDEX($C$14:$L$14,MATCH($B$4,$C$2:$L$2,0)) | C14: 0 | D14: 0 | E14: 0 | F14: 0 | G14: 0 | H14: 0 | I14: 0 | J14: 0 | K14: 0 | L14: 0 | N14: Pink Bean's Giant Rib
A15: DAMAGE % | B15: =INDEX($C$15:$L$15,MATCH($B$4,$C$2:$L$2,0)) | C15: 0 | D15: 0 | E15: 0 | F15: 0 | G15: 0 | H15: 0 | I15: 0 | J15: 0 | K15: 0 | L15: 0 | N15: Chalice
A16: DAMAGE_AMP % | B16: =INDEX($C$16:$L$16,MATCH($B$4,$C$2:$L$2,0)) | C16: 0 | D16: 0 | E16: 0 | F16: 0 | G16: 0 | H16: 0 | I16: 0 | J16: 0 | K16: 0 | L16: 0 | N16: Old Music Box
A17: BASIC_ATTACK_DAMAGE % | B17: =INDEX($C$17:$L$17,MATCH($B$4,$C$2:$L$2,0)) | C17: 0 | D17: 0 | E17: 0 | F17: 0 | G17: 0 | H17: 0 | I17: 0 | J17: 0 | K17: 0 | L17: 0 | N17: Silver Pendant
A18: SKILL_DAMAGE % | B18: =INDEX($C$18:$L$18,MATCH($B$4,$C$2:$L$2,0)) | C18: 0 | D18: 0 | E18: 0 | F18: 0 | G18: 0 | H18: 0 | I18: 0 | J18: 0 | K18: 0 | L18: 0 | N18: Star Rock
A19: DEF_PEN % | B19: =INDEX($C$19:$L$19,MATCH($B$4,$C$2:$L$2,0)) | C19: 0 | D19: 0 | E19: 0 | F19: 0 | G19: 0 | H19: 0 | I19: 0 | J19: 0 | K19: 0 | L19: 0 | N19: Book of Ancient
A20: BOSS_DAMAGE % | B20: =INDEX($C$20:$L$20,MATCH($B$4,$C$2:$L$2,0)) | C20: 0 | D20: 0 | E20: 0 | F20: 0 | G20: 0 | H20: 0 | I20: 0 | J20: 0 | K20: 0 | L20: 0 | N20: Lunar Dew
A21: NORMAL_DAMAGE % | B21: =INDEX($C$21:$L$21,MATCH($B$4,$C$2:$L$2,0)) | C21: 0 | D21: 0 | E21: 0 | F21: 0 | G21: 0 | H21: 0 | I21: 0 | J21: 0 | K21: 0 | L21: 0 | N21: Fire Flower
A22: MIN_DAMAGE % | B22: =INDEX($C$22:$L$22,MATCH($B$4,$C$2:$L$2,0)) | C22: 100 | D22: 100 | E22: 100 | F22: 100 | G22: 100 | H22: 100 | I22: 100 | J22: 100 | K22: 100 | L22: 100 | N22: Soul Contract
A23: MAX_DAMAGE % | B23: =INDEX($C$23:$L$23,MATCH($B$4,$C$2:$L$2,0)) | C23: 100 | D23: 100 | E23: 100 | F23: 100 | G23: 100 | H23: 100 | I23: 100 | J23: 100 | K23: 100 | L23: 100 | N23: Lit Lamp
A24: FINAL_DAMAGE % (base) | B24: =INDEX($C$24:$L$24,MATCH($B$4,$C$2:$L$2,0)) | C24: 0 | D24: 0 | E24: 0 | F24: 0 | G24: 0 | H24: 0 | I24: 0 | J24: 0 | K24: 0 | L24: 0 | N24: Soul Pouch
A25: Skill Level Bonus — 1st Job | B25: =INDEX($C$25:$L$25,MATCH($B$4,$C$2:$L$2,0)) | C25: 0 | D25: 0 | E25: 0 | F25: 0 | G25: 0 | H25: 0 | I25: 0 | J25: 0 | K25: 0 | L25: 0 | N25: Ancient Text Piece
A26: Skill Level Bonus — 2nd Job | B26: =INDEX($C$26:$L$26,MATCH($B$4,$C$2:$L$2,0)) | C26: 0 | D26: 0 | E26: 0 | F26: 0 | G26: 0 | H26: 0 | I26: 0 | J26: 0 | K26: 0 | L26: 0 | N26: Icy Soul Rock
A27: Skill Level Bonus — 3rd Job | B27: =INDEX($C$27:$L$27,MATCH($B$4,$C$2:$L$2,0)) | C27: 0 | D27: 0 | E27: 0 | F27: 0 | G27: 0 | H27: 0 | I27: 0 | J27: 0 | K27: 0 | L27: 0 | N27: Flaming Lava
A28: Skill Level Bonus — 4th Job | B28: =INDEX($C$28:$L$28,MATCH($B$4,$C$2:$L$2,0)) | C28: 0 | D28: 0 | E28: 0 | F28: 0 | G28: 0 | H28: 0 | I28: 0 | J28: 0 | K28: 0 | L28: 0 | N28: Sayram's Necklace
A29: Skill Level Bonus — All Skills | B29: =INDEX($C$29:$L$29,MATCH($B$4,$C$2:$L$2,0)) | C29: 0 | D29: 0 | E29: 0 | F29: 0 | G29: 0 | H29: 0 | I29: 0 | J29: 0 | K29: 0 | L29: 0 | N29: Bottle of Emotion
N30: Peach Tree Herb Pouch
A31: Additional Bonuses | N31: Candle
A32: Skill Cooldown Decrease (seconds, only skills the character actively casts) | B32: =INDEX($C$32:$L$32,MATCH($B$4,$C$2:$L$2,0)) | C32: 0 | D32: 0 | E32: 0 | F32: 0 | G32: 0 | H32: 0 | I32: 0 | J32: 0 | K32: 0 | L32: 0 | N32: Alliance Badge
A33: Basic Attack Target Increase (flat, adds to the 6-target Showdown base) | B33: =INDEX($C$33:$L$33,MATCH($B$4,$C$2:$L$2,0)) | C33: 1 | D33: 1 | E33: 1 | F33: 1 | G33: 1 | H33: 1 | I33: 1 | J33: 1 | K33: 1 | L33: 1 | N33: Horn Flute
A34: Buff Duration Increase % | B34: =INDEX($C$34:$L$34,MATCH($B$4,$C$2:$L$2,0)) | C34: 0 | D34: 0 | E34: 0 | F34: 0 | G34: 0 | H34: 0 | I34: 0 | J34: 0 | K34: 0 | L34: 0 | N34: Cursed Doll
A35: Companion Summoning Time Increase % (companions not modeled — always 0 DPS impact) | B35: =INDEX($C$35:$L$35,MATCH($B$4,$C$2:$L$2,0)) | C35: 0 | D35: 0 | E35: 0 | F35: 0 | G35: 0 | H35: 0 | I35: 0 | J35: 0 | K35: 0 | L35: 0 | N35: Reindeer's Spear
A36: Boss/Normal Emphasis (used when Content Type is Breakthrough or Hero Dungeon) | B36: =INDEX($C$36:$L$36,MATCH($B$4,$C$2:$L$2,0)) | D36: A Little More Normal | J36: A Little More Normal | N36: Secret Map
A37: Max Enemies Actually In Range (normal monsters only; default 999 = uncapped) | B37: =INDEX($C$37:$L$37,MATCH($B$4,$C$2:$L$2,0)) | D37: 999 | F37: 999 | G37: 999 | J37: 999 | L37: 999 | N37: Ring of Cycles
A38: Incoming Hit Rate (hits/sec taken — user-estimated, feeds Shadow Shifter's counterattack only) | B38: =INDEX($C$38:$L$38,MATCH($B$4,$C$2:$L$2,0)) | C38: 1 | D38: 1 | E38: 1 | F38: 1 | G38: 1 | H38: 1 | I38: 1 | J38: 1 | K38: 1 | L38: 1
A39: Monster Type (auto-computed from Content Type) — computed, do not edit | B39: =IF(Inputs!$B$4="PvP","pvp",IF(OR(Inputs!$B$4="Breakthrough",Inputs!$B$4="Hero Dungeon"),"breakthrough",IF(OR(Inputs!$B$4="EXP Dungeon",Inputs!$B$4="Equipment Dungeon",Inputs!$B$4="Chapter Hunt"),"normal","boss")))
A40: Chapter (parsed from Chapter-Stage) — computed, do not edit | B40: =IFERROR(IF(ISNUMBER(FIND("-",Inputs!$B$5)),VALUE(LEFT(Inputs!$B$5,FIND("-",Inputs!$B$5)-1)),VALUE(Inputs!$B$5)),28)
...

Sheet FactorTable
A1: Level | B1: F0 | C1: F1 | D1: F2 | E1: F3 | F1: F4 | G1: F5 | H1: F6 | I1: F7 | J1: F8 | K1: F9 | L1: F10 | M1: F11 | N1: F12 | O1: F13 | P1: F14 | Q1: F15 | R1: F16 | S1: F17 | T1: F18 | U1: F19 | V1: F20 | W1: F21 | X1: F22 | Y1: F23
A2: 1 | B2: 0 | C2: 1000 | D2: 1000 | E2: 1000 | F2: 1000 | G2: 1000 | H2: 1000 | I2: 1000 | J2: 1000 | K2: 1000 | L2: 1000 | M2: 1000 | N2: 1000 | O2: 1000 | P2: 1000 | Q2: 1000 | R2: 1000 | S2: 1000 | T2: 1000 | U2: 1000 | V2: 1000 | W2: 1000 | X2: 1000 | Y2: 1000
A3: 2 | B3: 0 | C3: 1015 | D3: 1020 | E3: 1030 | F3: 1040 | G3: 1050 | H3: 1060 | I3: 1070 | J3: 1020 | K3: 1020 | L3: 1020 | M3: 1000 | N3: 1010 | O3: 1020 | P3: 1030 | Q3: 1040 | R3: 1050 | S3: 1060 | T3: 1070 | U3: 1080 | V3: 1010 | W3: 1008 | X3: 1006 | Y3: 1100
A4: 3 | B4: 0 | C4: 1031 | D4: 1041 | E4: 1061 | F4: 1082 | G4: 1103 | H4: 1124 | I4: 1145 | J4: 1030 | K4: 1041 | L4: 1030 | M4: 1000 | N4: 1015 | O4: 1030 | P4: 1045 | Q4: 1060 | R4: 1075 | S4: 1090 | T4: 1105 | U4: 1120 | V4: 1020 | W4: 1012 | X4: 1009 | Y4: 1150
A5: 4 | B5: 0 | C5: 1047 | D5: 1062 | E5: 1093 | F5: 1126 | G5: 1159 | H5: 1192 | I5: 1226 | J5: 1040 | K5: 1062 | L5: 1040 | M5: 1000 | N5: 1020 | O5: 1040 | P5: 1060 | Q5: 1080 | R5: 1100 | S5: 1120 | T5: 1140 | U5: 1160 | V5: 1030 | W5: 1016 | X5: 1012 | Y5: 1200
A6: 5 | B6: 0 | C6: 1063 | D6: 1084 | E6: 1126 | F6: 1172 | G6: 1217 | H6: 1264 | I6: 1312 | J6: 1050 | K6: 1084 | L6: 1050 | M6: 1000 | N6: 1025 | O6: 1050 | P6: 1075 | Q6: 1100 | R6: 1125 | S6: 1150 | T6: 1175 | U6: 1200 | V6: 1040 | W6: 1020 | X6: 1015 | Y6: 1250
A7: 6 | B7: 0 | C7: 1079 | D7: 1106 | E7: 1160 | F7: 1219 | G7: 1278 | H7: 1340 | I7: 1404 | J7: 1060 | K7: 1106 | L7: 1060 | M7: 1000 | N7: 1030 | O7: 1060 | P7: 1090 | Q7: 1120 | R7: 1150 | S7: 1180 | T7: 1210 | U7: 1240 | V7: 1050 | W7: 1024 | X7: 1018 | Y7: 1300
A8: 7 | B8: 0 | C8: 1096 | D8: 1129 | E8: 1195 | F8: 1268 | G8: 1342 | H8: 1421 | I8: 1503 | J8: 1070 | K8: 1129 | L8: 1070 | M8: 1000 | N8: 1035 | O8: 1070 | P8: 1105 | Q8: 1140 | R8: 1175 | S8: 1210 | T8: 1245 | U8: 1280 | V8: 1060 | W8: 1028 | X8: 1021 | Y8: 1350
A9: 8 | B9: 0 | C9: 1113 | D9: 1152 | E9: 1231 | F9: 1319 | G9: 1410 | H9: 1507 | I9: 1609 | J9: 1080 | K9: 1152 | L9: 1080 | M9: 1000 | N9: 1040 | O9: 1080 | P9: 1120 | Q9: 1160 | R9: 1200 | S9: 1240 | T9: 1280 | U9: 1320 | V9: 1070 | W9: 1032 | X9: 1024 | Y9: 1400
A10: 9 | B10: 0 | C10: 1130 | D10: 1176 | E10: 1268 | F10: 1372 | G10: 1481 | H10: 1598 | I10: 1722 | J10: 1090 | K10: 1176 | L10: 1090 | M10: 1000 | N10: 1045 | O10: 1090 | P10: 1135 | Q10: 1180 | R10: 1225 | S10: 1270 | T10: 1315 | U10: 1360 | V10: 1080 | W10: 1036 | X10: 1027 | Y10: 1450
A11: 10 | B11: 0 | C11: 1147 | D11: 1200 | E11: 1307 | F11: 1427 | G11: 1556 | H11: 1694 | I11: 1843 | J11: 1100 | K11: 1200 | L11: 1100 | M11: 1000 | N11: 1050 | O11: 1100 | P11: 1150 | Q11: 1200 | R11: 1250 | S11: 1300 | T11: 1350 | U11: 1400 | V11: 1090 | W11: 1040 | X11: 1030 | Y11: 1500
A12: 11 | B12: 0 | C12: 1165 | D12: 1224 | E12: 1347 | F12: 1485 | G12: 1634 | H12: 1796 | I12: 1973 | J12: 1110 | K12: 1224 | L12: 1110 | M12: 1000 | N12: 1055 | O12: 1110 | P12: 1165 | Q12: 1220 | R12: 1275 | S12: 1330 | T12: 1385 | U12: 1440 | V12: 1100 | W12: 1044 | X12: 1033 | Y12: 1550
A13: 12 | B13: 0 | C13: 1183 | D13: 1249 | E13: 1388 | F13: 1545 | G13: 1716 | H13: 1904 | I13: 2112 | J13: 1120 | K13: 1249 | L13: 1120 | M13: 1000 | N13: 1060 | O13: 1120 | P13: 1180 | Q13: 1240 | R13: 1300 | S13: 1360 | T13: 1420 | U13: 1480 | V13: 1110 | W13: 1048 | X13: 1036 | Y13: 1600
... A301: 300 | B301: 0 | C301: 88573 | D301: 381637 | E301: 6991522 | F301: 125363453 | G301: 2185120762 | H301: 37157073039 | I301: 614631863830 | J301: 2000 | K301: 53326 | L301: 2500 | M301: 1100 | N301: 2500 | O301: 4000 | P301: 5500 | Q301: 7000 | R301: 8500 | S301: 10000 | T301: 11500 | U301: 13000 | V301: 7558 | W301: 2200 | X301: 1900 | Y301: 8800

Sheet Skills
A1: Key | B1: Name | C1: JobStep | D1: Cooldown(s) | E1: CostsActionSlot | F1: ActionsPerCast | G1: HitsPerCast | H1: ICD(s) | I1: ActiveWindow(s) | J1: ProcChance% | K1: RollsPerCast | L1: BaseDamage(tenths%) | M1: FactorIndex | N1: ScalesWithLevel | O1: SkillMasteryBonus% | P1: MasteryBossDamage% | Q1: MasteryNormalDamage% | R1: MasteryFinalDamage% | S1: MasteryMaxDamage% | T1: MasteryMinDamage% | U1: MasteryCooldownPct | V1: MasteryTargetIncrease | W1: NormalMonsterTargets | X1: BuffTargetStat | Y1: BuffDuration(s) | Z1: TriggersToxicVenom | AA1: MapleHeroBase(tenths%) | AB1: MapleHeroFactorIndex | AC1: Stacks | AD1: Note
A2: SHOWDOWN | B2: Showdown | C2: 4 | E2: FALSE | F2: 1 | G2: =IF(Inputs!$B$3>=134,6,5) | H2: 0 | I2: 0 | J2: 100 | K2: 1 | N2: TRUE | O2: =SUMPRODUCT((Inputs!$B$3>={98,104,113,118,126,130})*{10,1,1,1,1,1}) | P2: =SUMPRODUCT((Inputs!$B$3>={108,122})*{10,10}) | Q2: 0 | R2: 0 | S2: 0 | T2: 0 | U2: 0 | V2: 0 | W2: =6+Inputs!$B$33 | Y2: 0 | Z2: TRUE | AD2: 4th-job basic-attack effect (superseded from Lucky Seven/Shuriken Burst/Shuriken Challenge, per the project's job-tier-is-gone scope). 5 hits per activation (Mastery Lv.134 'Strike' -> 6), 6+Basic Attack Target Increase targets vs normal monsters. Reverse-engineered from the wiki's 290%->522% (levels 1-200) curve: factorIndex 21, baseDamage 2900 tenths%. Coefficient = Inputs!skill_coefficient (computed from this same factor) + SkillMasteryBonus%. SkillMasteryBonus% is the 6-tier 'Showdown - Damage' mastery chain (98/104/113/118/126/130), each entry showing the CUMULATIVE total (10%, 11%, ..., 15%) per the game's own tooltip convention (confirmed against the identically-shaped Shuriken Challenge/Boss-Damage mastery chains elsewhere in this table), so level_gated_sum uses DELTA increments (10, then +1 five times) to reproduce that curve, not the raw displayed percentages. MasteryBossDamage% is the 2-tier 'Showdown - Boss Monster Damage' chain (108, 122), each independently +10% (same two-tier stacking pattern as Shuriken Challenge's own Boss Damage masteries at 68/82), totaling +20%.
A3: GUST_CHARM | B3: Gust Charm | C3: 2 | D3: 24 | E3: TRUE | F3: 1 | G3: 1 | H3: 0 | I3: 0 | J3: 100 | K3: 1 | L3: 4000 | M3: 12 | N3: TRUE | O3: =SUMPRODUCT((Inputs!$B$3>={39})*{80}) | P3: 0 | Q3: 0 | R3: 0 | S3: 0 | T3: 0 | U3: 0 | V3: 0 | W3: 8 | Y3: 0 | Z3: TRUE | AA3: 1300 | AB3: 23 | AD3: Patched: targets 6->8, stun 1.5s->2s (stun not modeled), Mastery Lv.39 re-typed from '+50% stun duration' to '+80% Damage' (now a real SkillMasteryBonus%). Damage curve itself (400%->600%, levels 1-100) unpatched — factorIndex 12, baseDamage 4000 tenths%. Maple Hero (NL) target: 130%->1014% (levels 1-200), factorIndex 23.
A4: MARK_OF_ASSASSIN | B4: Assassin's Mark | C4: 2 | D4: =IF(Inputs!$B$3>=138,2,2.5) | E4: FALSE | F4: 1 | G4: 1 | H4: 0 | I4: 0 | J4: 100 | K4: 1 | L4: 1900 | M4: 21 | N4: TRUE | O4: =SUMPRODUCT((Inputs!$B$3>={42})*{80}) | P4: =IF(Inputs!$B$3>=122,8,0) | Q4: =IF(Inputs!$B$3>=122,8,0) | R4: =IF(Inputs!$B$3>=107,Calc!F31,0) | S4: 0 | T4: 0 | U4: 0 | V4: =IF(Inputs!$B$3>=107,3,0) | W4: =7+Skills!V4 | Y4: 0 | Z4: TRUE | AD4: Simplified to a periodic AoE tick per the approved plan — mark-application and mark-consumption collapsed into one instantaneous hit every effective cooldown, no mark-duty-cycle modeling. Patched: interval 5s->2.5s (then -0.5s more at Mastery Lv.138 -> 2s), duration 5s->2.5s (irrelevant under this simplification), damage 300%->190%. factorIndex 21 (from the unpatched 300%->420% wiki curve), baseDamage 1900 tenths% (190% patched base). Not a player-cast action (CostsActionSlot=False) — it's a passive, automatic AoE proc, not a deliberate cast. Base 7 targets, +3 (MasteryTargetIncrease) once Night Lord's Mark unlocks at level 107. MasteryFinalDamage% pulls Night Lord's Mark's own Calc!F live (a real, always-on contributor, not baked into Inputs). SkillMasteryBonus% is Mastery Lv.42 ('Mark of Assassin - Damage', +80%, unaffected by the patch). Mastery Lv.122 ('Weaken', patched): marked targets take +8% Damage Taken for 2s — since this row's own tick both places AND consumes the mark in the same instant (no separate 'hit that lands on an already-marked target' event exists in this simplified model), the +8% is folded directly into THIS row's own MasteryBossDamage%/MasteryNormalDamage% (applies only to Assassin's Mark's own hit, once per effective cooldown — not a duty-cycle-averaged window benefiting other skills' hits in between).
A5: TRIPLE_THROW | B5: Triple Throw | C5: 3 | D5: 13 | E5: TRUE | F5: 1 | G5: 3 | H5: 0 | I5: 0 | J5: 100 | K5: 1 | L5: 3600 | M5: 12 | N5: TRUE | O5: =SUMPRODUCT((Inputs!$B$3>={71})*{100}) | P5: 0 | Q5: 0 | R5: 0 | S5: 0 | T5: 0 | U5: 0 | V5: 0 | W5: 1 | Y5: 0 | Z5: TRUE | AD5: Single-target. factorIndex 12, baseDamage 3600 tenths% (360%->720%, levels 1-200). SkillMasteryBonus% is Mastery Lv.71 ('Triple Throw - Damage', +100%, unaffected by the patch).
A6: ADRENALIN_FD | B6: Alchemic Adrenaline (Final Damage) | C6: 3 | E6: FALSE | F6: 1 | G6: 1 | H6: 0 | I6: 0 | J6: 100 | K6: 1 | L6: 150 | M6: 22 | N6: TRUE | O6: 0 | P6: 0 | Q6: 0 | R6: 0 | S6: 0 | T6: 0 | U6: 0 | V6: 0 | W6: 1 | X6: FINAL_DAMAGE | Y6: =IF(Inputs!$B$3>=88,15,10) | Z6: FALSE | AD6: Patched: trigger 7 hits->5 hits, Final Damage base 10%->15% (curve shape/ratio preserved from the unpatched 10%->16% wiki curve; factorIndex 22, baseDamage 150 tenths%). Uptime is bespoke — see build_summary_sheet's AdrenalinUptime (action-rate-driven cycle, not the generic BuffDuration/Cooldown ratio) — so this row has no Cooldown(s) of its own and isn't consumed via the generic buff_uptime() helper. Mastery Lv.88 adds +5s to BuffDuration(s).
A7: ADRENALIN_AS | B7: Alchemic Adrenaline (Attack Speed) | C7: 3 | E7: FALSE | F7: 1 | G7: 1 | H7: 0 | I7: 0 | J7: 100 | K7: 1 | L7: 80 | M7: 22 | N7: TRUE | O7: 0 | P7: 0 | Q7: 0 | R7: 0 | S7: 0 | T7: 0 | U7: 0 | V7: 0 | W7: 1 | X7: ATTACK_SPEED | Y7: =IF(Inputs!$B$3>=88,15,10) | Z7: FALSE | AD7: Same trigger/uptime as Adrenalin (Final Damage) above (8%->12.8%, levels 1-200), split into its own row since BuffTargetStat only holds one target per row (mirrors Dark Sight's own Crit Rate / Attack split below).
A8: DARK_FLARE | B8: Dark Flare | C8: 3 | D8: =IF(Inputs!$B$3>=92,45*0.7,45) | E8: TRUE | F8: 1 | G8: =IF(Inputs!$B$3>=76,3,2) | H8: =IF(Inputs!$B$3>=104,2*0.75,2) | I8: 20 | J8: 100 | K8: 1 | L8: 3300 | M8: 12 | N8: TRUE | O8: 0 | P8: 0 | Q8: 0 | R8: 0 | S8: 0 | T8: 0 | U8: =IF(Inputs!$B$3>=92,30,0) | V8: 0 | W8: 8 | Y8: 0 | Z8: TRUE | AA8: 150 | AB8: 23 | AD8: Shared w/ Shadower, Maple Hero (NL) target (15%->117%, levels 1-200, factorIndex 23). Patched: hit interval 5s->2s, targets 5->8, damage 400%->330% (curve shape from the unpatched 400%->800% wiki curve; factorIndex 12, baseDamage 3300 tenths%). 20s active window / 2s interval = 10 tick-sets x 2 hits = 20 EffectiveHits (was 4x2=8 pre-patch); Mastery Lv.76 ('Dark Flare - Strike', +1 hit per tick-set, 2->3) brings this to 30 EffectiveHits once unlocked. Mastery Lv.92 (-30% cooldown) and Lv.104 (hit-interval -25%, patched from -40%) are both baked directly into the Cooldown(s)/ICD(s) cell formulas (MasteryCooldownPct column here is reference-only, documenting the 30% used above, per the 'ProcChance%/BuffDuration(s) reference-only' precedent already established in FP-Mage).
A9: VENOM | B9: Venom | C9: 3 | D9: 1 | E9: FALSE | F9: 1 | G9: 1 | H9: 0 | I9: 0 | J9: 100 | K9: 1 | L9: 450 | M9: 21 | N9: TRUE | O9: 0 | P9: 0 | Q9: 0 | R9: 0 | S9: 0 | T9: 0 | U9: 0 | V9: 0 | W9: 1 | Y9: 0 | Z9: FALSE | AA9: 500 | AB9: 23 | AD9: Shared w/ Shadower. Maple Hero (NL) target (50%->390%, levels 1-200, factorIndex 23). Patched: poison chance 30%->50% (modeled always-active at steady state regardless — Elemental-Drain-style simplification, even safer now at 50%). Cooldown=1 is the same 'always-on tick' trick FP-Mage's Elemental Drain uses (1 tick/sec forever, not a real cooldown). factorIndex 21, baseDamage 450 tenths% (45%->81%, levels 1-200). Mastery Lv.82 Weaken (+15%p Damage Taken while poisoned, patched from 12%) is a GLOBAL always-on monster-damage-taken bonus (not per-row) — see global_monster_dmg_bonus_expr in build_calc_sheet, not this row's own Mastery columns.
A10: TOXIC_VENOM | B10: Toxic Venom | C10: 4 | E10: FALSE | F10: 1 | G10: 1 | H10: 0 | I10: 0 | J10: 20 | K10: 1 | L10: 6000 | M10: 21 | N10: TRUE | O10: =SUMPRODUCT((Inputs!$B$3>={128})*{100}) | P10: 0 | Q10: 0 | R10: 0 | S10: 0 | T10: 0 | U10: 0 | V10: 0 | W10: 1 | Y10: 0 | Z10: FALSE | AD10: Shared w/ Shadower. No ICD — every attack against a (permanently poisoned, by the Venom assumption) target independently rolls the 20% chance. Trigger rate = the combined per-second hit rate (already target-count-multiplied) of every row with TriggersToxicVenom=TRUE (see build_calc_sheet's Calc!S 'HitRate' column and this row's own bespoke O-column formula) — deliberately excludes Venom itself, Toxic Venom itself, Shadow Partner (not an independent hit), and Shadow Shifter's counterattack (a defensive proc, scoped out for simplicity; flagged as an assumption). factorIndex 21, baseDamage 6000 tenths% (600%->1080%, levels 1-200). SkillMasteryBonus% is Mastery Lv.128 ('Toxic Venom - Damage', +100%, unaffected by the patch).
A11: SHADOW_PARTNER | B11: Shadow Partner | C11: 3 | E11: FALSE | F11: 1 | G11: 1 | H11: 0 | I11: 0 | J11: 25 | K11: 1 | L11: 840 | M11: 21 | N11: TRUE | O11: =SUMPRODUCT((Inputs!$B$3>={66})*{100}) | P11: 0 | Q11: 0 | R11: 0 | S11: 0 | T11: 0 | U11: 0 | V11: 0 | W11: 1 | Y11: 0 | Z11: FALSE | AA11: 500 | AB11: 23 | AD11: Shared w/ Shadower, Maple Hero (NL) target. Hybrid row: Calc columns D-I are computed exactly like a normal damage row (so Maple Hero (NL)'s MapleHeroMultiplier applies unchanged) but Calc!O is forced to 0 — it isn't an independent hit. Instead Summary!ShadowPartnerAvgMult reads this row's Calc!F/Calc!I directly and folds into the shared extra_mult chain every other row's K-column formula uses. factorIndex 21, baseDamage 840 tenths% (84%->151.2%, levels 1-200). ProcChance% is the real 25% proc rate. SkillMasteryBonus% is Mastery Lv.66 ('Shadow Partner - Damage', +100%, unaffected by the patch).
A12: QUAD_STAR | B12: Quad Star | C12: 4 | D12: =IF(Inputs!$B$3>=106,10*0.7,10) | E12: TRUE | F12: 1 | G12: 4 | H12: 0 | I12: 0 | J12: 100 | K12: 1 | L12: 11500 | M12: 12 | N12: TRUE | O12: =SUMPRODUCT((Inputs!$B$3>={132})*{50}) | P12: 0 | Q12: 0 | R12: 0 | S12: 0 | T12: 0 | U12: =IF(Inputs!$B$3>=106,30,0) | V12: 0 | W12: 1 | Y12: 0 | Z12: TRUE | AD12: Single-target. factorIndex 12, baseDamage 11500 tenths% (1150%->2300%, levels 1-200). Mastery Lv.106 (-30% cooldown, baked into the Cooldown(s) formula above, MasteryCooldownPct reference-only) and Lv.132 (+50% damage, real SkillMasteryBonus%).
A13: SUDDEN_RAID_BURST | B13: Sudden Raid (burst) | C13: 4 | D13: 19 | E13: TRUE | F13: 1 | G13: 3 | H13: 0 | I13: 0 | J13: 100 | K13: 1 | L13: 14000 | M13: 12 | N13: TRUE | O13: =SUMPRODUCT((Inputs!$B$3>={124})*{50}) | P13: 0 | Q13: 0 | R13: 0 | S13: 0 | T13: 0 | U13: 0 | V13: 0 | W13: 8 | Y13: 0 | Z13: TRUE | AD13: Shared w/ Shadower. factorIndex 12, baseDamage 14000 tenths% (1400%->2800%, levels 1-200). Mastery Lv.124 +50% damage (real SkillMasteryBonus%; does not apply to the DoT row below, matching FP-Mage's own Poison Mist burst-vs-fog precedent).
A14: SUDDEN_RAID_DOT | B14: Sudden Raid (DoT) | C14: 4 | D14: =Skills!D13 | E14: FALSE | F14: 1 | G14: 1 | H14: 1 | I14: 5 | J14: 100 | K14: 1 | L14: 3600 | M14: 12 | N14: TRUE | O14: 0 | P14: 0 | Q14: 0 | R14: 0 | S14: 0 | T14: 0 | U14: 0 | V14: 0 | W14: 8 | Y14: 0 | Z14: TRUE | AD14: Shares Sudden Raid (burst)'s live Cooldown(s) cell (same cross-reference pattern as FP-Mage's Mist Eruption <-> Poison Mist (burst)). factorIndex 12, baseDamage 3600 tenths% (360%->720%, levels 1-200), 5s window / 1s ICD = 5 EffectiveHits per cast.
A15: FRAILTY_CURSE_SELF_FD | B15: Frailty Curse (self buff) | C15: 4 | D15: 45 | E15: TRUE | F15: 1 | G15: 1 | H15: 0 | I15: 0 | J15: 100 | K15: 1 | L15: 130 | M15: 22 | N15: TRUE | O15: 0 | P15: 0 | Q15: 0 | R15: 0 | S15: 0 | T15: 0 | U15: 0 | V15: 0 | W15: 1 | X15: FINAL_DAMAGE | Y15: 20 | Z15: FALSE | AD15: 20s zone / 45s cooldown, self Final Damage. factorIndex 22, baseDamage 130 tenths% (13%->20.8%, levels 1-200). Mastery Lv.111 adds a minor crit-damage-taken debuff to the enemy-facing row below — deliberately not modeled (plan calls it minor/optional; flagged as a known gap).
A16: FRAILTY_CURSE_DEBUFF | B16: Frailty Curse (enemy debuff) | C16: 4 | D16: 45 | E16: FALSE | F16: 1 | G16: 1 | H16: 0 | I16: 0 | J16: 100 | K16: 1 | L16: 180 | M16: 21 | N16: TRUE | O16: 0 | P16: 0 | Q16: 0 | R16: 0 | S16: 0 | T16: 0 | U16: 0 | V16: 0 | W16: 1 | X16: MONSTER_DMG | Y16: 20 | Z16: FALSE | AD16: Same 20s zone / 45s cooldown as the self-buff row above (shares its Cooldown(s) literal, not a live cross-reference, since both are the same literal 45). Enemy Damage Taken +18%->32.4% (levels 1-200), factorIndex 21, baseDamage 180 tenths%. BuffTargetStat=MONSTER_DMG feeds global_monster_dmg_bonus_expr's boss/normal additive term (see build_calc_sheet), gated by the same uptime as the self-buff row (CostsActionSlot=False here — the self-buff row is the one that actually 'costs' the cast in the action economy).
A17: SHADOW_SHIFTER | B17: Shadow Shifter (counterattack) | C17: 4 | E17: FALSE | F17: 1 | G17: 1 | H17: 0 | I17: 0 | J17: 100 | K17: 1 | L17: 25000 | M17: 21 | N17: TRUE | O17: 0 | P17: 0 | Q17: 0 | R17: 0 | S17: 0 | T17: 0 | U17: 0 | V17: 0 | W17: 1 | Y17: 0 | Z17: FALSE | AD17: Shared w/ Shadower. Counterattack DPS = Inputs!incoming_hit_rate * 20% * ExpectedDamage(counterHit) — driven by damage TAKEN, not the character's own cast rate, so this row has no Cooldown(s)/rate machinery of its own (bespoke O-column branch). factorIndex 21, baseDamage 25000 tenths% (2500%->4500%, levels 1-200). The wiki's own 'Cooldown 12 sec' field on this skill is not modeled (the plan's formula treats the 20% chance as having no ICD at all) — flagged as an assumption to confirm.
A18: SHADOW_SHIFTER_SELF_ATK | B18: Shadow Shifter (self Attack%) | C18: 4 | E18: FALSE | F18: 1 | G18: 1 | H18: 0 | I18: 0 | J18: 100 | K18: 1 | L18: 100 | M18: 22 | N18: TRUE | O18: 0 | P18: 0 | Q18: 0 | R18: 0 | S18: 0 | T18: 0 | U18: 0 | V18: 0 | W18: 1 | X18: ATTACK | Y18: 0 | Z18: FALSE | AD18: Passive-mult delta-tracking row for Shadow Shifter's self Attack% (10%->16%, levels 1-200) — assumed already baked into Inputs!ATTACK_PCT (Magic Critical pattern), so not added to baseline DPS. factorIndex 22, baseDamage 100 tenths%. Per the plan, this buff's *uptime* is reduced below 1 by counterattack procs (disabled 3s per proc, pre-Mastery-116) — SelfAttackBuffUptime is computed in build_summary_sheet, but the Sensitivity sheet's own delta for this row is NOT scaled by that uptime in this pass (a known simplification — flagged for human review, see the plan's explicit note that this is 'the one passive-mult row that also needs a live uptime term multiplying its Sensitivity delta').
A19: NIMBLE_FEET | B19: Nimble Feet | C19: 1 | D19: 60 | E19: TRUE | F19: 1 | G19: 1 | H19: 0 | I19: 0 | J19: 100 | K19: 1 | L19: 150 | M19: 0 | N19: FALSE | O19: 0 | P19: 0 | Q19: 0 | R19: 0 | S19: 0 | T19: 0 | U19: 0 | V19: 0 | W19: 1 | X19: ATTACK_SPEED | Y19: 15 | Z19: FALSE | AD19: Shared Explorer skill, flat +15% Attack Speed / +10% Speed for 15s, 60s cooldown — confirmed non-scaling ('does not improve on enhancement' per its own wiki page), same convention as FP-Mage's own Nimble Feet row (FactorIndex unused placeholder).
A20: DARK_SIGHT_CRIT | B20: Dark Sight (Crit Rate) | C20: 1 | D20: 25 | E20: FALSE | F20: 1 | G20: 1 | H20: 0 | I20: 0 | J20: 100 | K20: 1 | L20: 60 | M20: 21 | N20: TRUE | O20: 0 | P20: 0 | Q20: 0 | R20: 0 | S20: 0 | T20: 0 | U20: 0 | V20: 0 | W20: 1 | X20: CRIT_RATE | Y20: =IF(Inputs!$B$3>=24,12,8) | Z20: FALSE | AD20: Two-stage activation (hide 8s, re-press within window) grants +6%->8.4% Crit Rate for 8s (levels 1-100, ->12s once Mastery Lv.24 'Dark Sight - Persistence' unlocks: +50% buff duration) — factorIndex 21, baseDamage 60 tenths%. This row is a passenger (CostsActionSlot=False) — the Attack-targeting row below is the one that counts toward the action economy (both presses of the 2-stage activation, via ActionsPerCast=2), per the plan's 'costs 2 action-slots per 25s cycle' assumption (flagged for human review).
A21: DARK_SIGHT_ATK | B21: Dark Sight (Attack) | C21: 1 | D21: 25 | E21: TRUE | F21: 2 | G21: 1 | H21: 0 | I21: 0 | J21: 100 | K21: 1 | L21: 100 | M21: 21 | N21: TRUE | O21: 0 | P21: 0 | Q21: 0 | R21: 0 | S21: 0 | T21: 0 | U21: 0 | V21: 0 | W21: 1 | X21: ATTACK | Y21: =IF(Inputs!$B$3>=24,12,8) | Z21: FALSE | AD21: Same 2-stage activation as the Crit Rate row above, +10%->14% Attack for 8s (levels 1-100, ->12s once Mastery Lv.24 unlocks, same as the Crit Rate row) — factorIndex 21, baseDamage 100 tenths%. ActionsPerCast=2 models both presses (hide + re-press) as separate action-slot costs within the same 25s cycle.
A22: AGILE_CLAWS | B22: Agile Claws (Claw Acceleration) | C22: 2 | E22: FALSE | F22: 1 | G22: 1 | H22: 0 | I22: 0 | J22: 100 | K22: 1 | L22: 50 | M22: 22 | N22: TRUE | O22: 0 | P22: 0 | Q22: 0 | R22: 0 | S22: 0 | T22: 0 | U22: 0 | V22: 0 | W22: 1 | X22: ATTACK_SPEED | Y22: 0 | Z22: FALSE | AD22: Permanent passive, +5%->6.5% Attack Speed (levels 1-100) — assumed already in Inputs!ATTACK_SPEED% (Magic Critical pattern); this row only feeds the 2nd-Job Skill Level Bonus Sensitivity delta. factorIndex 22, baseDamage 50 tenths%.
A23: PHYSICAL_TRAINING | B23: Physical Training | C23: 2 | E23: FALSE | F23: 1 | G23: 1 | H23: 0 | I23: 0 | J23: 100 | K23: 1 | L23: 100 | M23: 22 | N23: TRUE | O23: 0 | P23: 0 | Q23: 0 | R23: 0 | S23: 0 | T23: 0 | U23: 0 | V23: 0 | W23: 1 | X23: BASIC_ATTACK_DAMAGE | Y23: 0 | Z23: FALSE | AD23: Permanent passive, +10%->13% Basic Attack Damage (levels 1-100) — assumed already in Inputs!BASIC_ATTACK_DAMAGE% (Magic Critical pattern); feeds the 2nd-Job Skill Level Bonus delta. factorIndex 22, baseDamage 100 tenths%.
A24: CLAW_MASTERY | B24: Claw Mastery | C24: 2 | E24: FALSE | F24: 1 | G24: 1 | H24: 0 | I24: 0 | J24: 100 | K24: 1 | L24: 150 | M24: 22 | N24: TRUE | O24: 0 | P24: 0 | Q24: 0 | R24: 0 | S24: 0 | T24: 0 | U24: 0 | V24: 0 | W24: 1 | X24: MIN_DAMAGE | Y24: 0 | Z24: FALSE | AD24: Permanent passive, +15%->19.5% Min Damage Multiplier (levels 1-100) — assumed already in Inputs!MIN_DAMAGE% (Magic Critical pattern); feeds the 2nd-Job Skill Level Bonus delta. factorIndex 22, baseDamage 150 tenths%.
A25: CRITICAL_THROW_RATE | B25: Critical Throw (Crit Rate) | C25: 2 | E25: FALSE | F25: 1 | G25: 1 | H25: 0 | I25: 0 | J25: 100 | K25: 1 | L25: 60 | M25: 22 | N25: TRUE | O25: 0 | P25: 0 | Q25: 0 | R25: 0 | S25: 0 | T25: 0 | U25: 0 | V25: 0 | W25: 1 | X25: CRIT_RATE | Y25: 0 | Z25: FALSE | AD25: Permanent passive, +6%->7.8% Crit Rate (levels 1-100) — assumed already in Inputs!CRIT_RATE% (Magic Critical pattern); feeds the 2nd-Job Skill Level Bonus delta. factorIndex 22, baseDamage 60 tenths%. Mastery Lv.47's +8%p Crit Rate is a SEPARATE always-on mastery addition (global_crit_rate_bonus_expr in build_calc_sheet), NOT part of this delta.
A26: CRITICAL_THROW_DMG | B26: Critical Throw (Crit Damage) | C26: 2 | E26: FALSE | F26: 1 | G26: 1 | H26: 0 | I26: 0 | J26: 100 | K26: 1 | L26: 100 | M26: 22 | N26: TRUE | O26: 0 | P26: 0 | Q26: 0 | R26: 0 | S26: 0 | T26: 0 | U26: 0 | V26: 0 | W26: 1 | X26: CRIT_DAMAGE | Y26: 0 | Z26: FALSE | AD26: Same skill as the Crit Rate row above, +10%->13% Crit Damage (levels 1-100) — assumed already in Inputs!CRIT_DAMAGE% (Magic Critical pattern); feeds the 2nd-Job Skill Level Bonus delta. factorIndex 22, baseDamage 100 tenths%.
A27: ENVELOPING_DARKNESS | B27: Enveloping Darkness | C27: 3 | E27: FALSE | F27: 1 | G27: 1 | H27: 0 | I27: 0 | J27: 100 | K27: 1 | L27: 180 | M27: 22 | N27: TRUE | O27: 0 | P27: 0 | Q27: 0 | R27: 0 | S27: 0 | T27: 0 | U27: 0 | V27: 0 | W27: 1 | X27: BOSS_DAMAGE | Y27: 0 | Z27: FALSE | AD27: Permanent passive, +18%->28.8% Boss Monster Damage (levels 1-200; Max HP part dropped, no DPS relevance) — assumed already in Inputs!BOSS_DAMAGE% (Magic Critical pattern); feeds the 3rd-Job Skill Level Bonus delta. factorIndex 22, baseDamage 180 tenths%.
A28: EXPERT_THROWING_STAR_HANDLING | B28: Expert Throwing Star Handling | C28: 3 | E28: FALSE | F28: 1 | G28: 1 | H28: 0 | I28: 0 | J28: 100 | K28: 1 | L28: 180 | M28: 22 | N28: TRUE | O28: 0 | P28: 0 | Q28: 0 | R28: 0 | S28: 0 | T28: 0 | U28: 0 | V28: 0 | W28: 1 | X28: ATTACK | Y28: 0 | Z28: FALSE | AD28: Permanent passive, +18%->28.8% Attack (levels 1-200) — assumed already in Inputs!ATTACK% (Magic Critical pattern); feeds the 3rd-Job Skill Level Bonus delta. factorIndex 22, baseDamage 180 tenths%.
A29: CLAW_EXPERT | B29: Claw Expert | C29: 4 | E29: FALSE | F29: 1 | G29: 1 | H29: 0 | I29: 0 | J29: 100 | K29: 1 | L29: 150 | M29: 22 | N29: TRUE | O29: 0 | P29: 0 | Q29: 0 | R29: 0 | S29: 0 | T29: 0 | U29: 0 | V29: 0 | W29: 1 | X29: SKILL_DAMAGE | Y29: 0 | Z29: FALSE | AD29: Permanent passive, +15%->24% Skill Damage, +20%->32% Max Damage Multiplier (levels 1-200) — assumed already in Inputs!SKILL_DAMAGE%/MAX_DAMAGE% (Magic Critical pattern); feeds the 4th-Job Skill Level Bonus delta (Skill Damage side; Max Damage Multiplier isn't independently swept on the Sensitivity sheet, same as FP-Mage's own scope). factorIndex 22, baseDamage 150 tenths% (Skill Damage curve; Max Damage Multiplier curve is identical in shape, 20%->32%, not separately tracked as its own row).
A30: DARK_HARMONY | B30: Dark Harmony | C30: 4 | E30: FALSE | F30: 1 | G30: 1 | H30: 0 | I30: 0 | J30: 100 | K30: 1 | L30: 120 | M30: 22 | N30: TRUE | O30: 0 | P30: 0 | Q30: 0 | R30: 0 | S30: 0 | T30: 0 | U30: 0 | V30: 0 | W30: 1 | X30: FINAL_DAMAGE | Y30: 0 | Z30: FALSE | AD30: Permanent passive, Final Damage +15%(base)->patched 12% (curve shape unchanged, 12%->19.2%(@lvl100) scaled from the unpatched 15%->24% wiki curve), +20%->32% Min Damage Multiplier (levels 1-200) — assumed already in Inputs!FINAL_DAMAGE%/MIN_DAMAGE% (Magic Critical pattern); feeds the 4th-Job Skill Level Bonus delta (Final Damage side). factorIndex 22, baseDamage 120 tenths% (12% patched base).
A31: NIGHT_LORDS_MARK | B31: Night Lord's Mark | C31: 4 | E31: FALSE | F31: 1 | G31: 1 | H31: 0 | I31: 0 | J31: 100 | K31: 1 | L31: 3000 | M31: 21 | N31: TRUE | O31: 0 | P31: 0 | Q31: 0 | R31: 0 | S31: 0 | T31: 0 | U31: 0 | V31: 0 | W31: 1 | Y31: 0 | Z31: FALSE | AD31: Permanent passive feeding Assassin's Mark only (+3 max targets, +300%->540% Final Damage to Assassin's Mark, levels 1-200) — a real, always-on contributor, NOT baked into Inputs (unlike every 'passive-mult' row above) since it has no matching generic Inputs field; same Element-Amplification-style treatment FP-Mage uses. No independent DPS row (Calc columns G-O blank/0) — only D/E/F (its own scaling coefficient) are computed. factorIndex 21, baseDamage 3000 tenths%.

Sheet Calc
A1: Key | B1: Name | C1: Unlocked | D1: InputLevel | E1: Factor | F1: CoefficientPercent | G1: EffectiveHits | H1: ProcProbability | I1: MapleHeroMultiplier | J1: BaseDamage | K1: BaseHitDamage | L1: NonCritAvg | M1: CritAvg | N1: ExpectedDamage(perHit) | O1: DPS | P1: % of Total | Q1: InvCooldown | R1: CastsInFight | S1: HitRate(perSec) | T1: BossOnlyDPS | U1: Maple Hero (NL) helper (jobStep4, factorIndex23) | V1: NormalOnlyDPS
A2: =Skills!A2 | B2: =Skills!B2 | C2: =Inputs!$B$3>=100 | F2: =Summary!$B$10+Skills!O2 | G2: =Skills!G2*IF(Skills!H2>0,Skills!I2/Skills!H2,1) | H2: =1-(1-Skills!J2/100)^Skills!K2 | I2: =IF(Skills!AA2<>"",1+(Skills!AA2/10)*($U$3/1000)/100,1) | J2: =Summary!$B$6*(F2/100) | K2: =J2*(1+Summary!$B$7/100)*(1+Inputs!$B$15/100)*(1+Inputs!$B$16/100)*(5000/(6000+Inputs!$B$43*(1-Inputs!$B$19/100)))*(1+Inputs!$B$24/100)*(1+Skills!R2/100)*(1+Artifacts!$B$34/100)*(1+(IF(Skills!A2="SHOWDOWN",Inputs!$B$17+Artifacts!$B$40,Inputs!$B$18+Artifacts!$B$39))/100)*(Summary!$B$13*Summary!$B$16*(1+Artifacts!$B$38/100)*I2) | L2: =K2*(MIN(Inputs!$B$22,Inputs!$B$23)/100+Inputs!$B$23/100)/2 | M2: =L2*(1+(Inputs!$B$10+Summary!$B$24+Artifacts!$B$33)/100) | N2: =L2*(1-MIN((Inputs!$B$9+Summary!$B$14+Artifacts!$B$32),100)/100)+M2*(MIN((Inputs!$B$9+Summary!$B$14+Artifacts!$B$32),100)/100) | O2: =(1-Summary!$B$11)*T2+Summary!$B$11*V2 | P2: =IF(Summary!$B$3=0,0,O2/Summary!$B$3) | Q2: 0 | R2: 0 | S2: =IFERROR(O2/N2,0) | T2: =IF(C2,(Skills!G2*N2*Summary!$B$22)*IF(Inputs!$B$39="pvp",1,1+(Inputs!$B$20+Skills!P2+Summary!$B$15+Artifacts!$B$35+Artifacts!$B$36)/100)*((((5000/(6000+Inputs!$B$43*(1-(100*(1-(1-Inputs!$B$19/100)*(1-Artifacts!$B$51/100)^IF(Inputs!$B$39="pvp",1,2)))/100)))/(5000/(6000+Inputs!$B$43*(1-Inputs!$B$19/100))))*((L2*(1-MIN(100,(Inputs!$B$9+Summary!$B$14+Artifacts!$B$32)+Artifacts!$B$69)/100)+M2*(MIN(100,(Inputs!$B$9+Summary!$B$14+Artifacts!$B$32)+Artifacts!$B$69)/100))/(L2*(1-MIN(100,(Inputs!$B$9+Summary!$B$14+Artifacts!$B$32))/100)+M2*(MIN(100,(Inputs!$B$9+Summary!$B$14+Artifacts!$B$32))/100)))*(1+Artifacts!$B$81/100))),0) | U2: =MAX(0,(Inputs!$B$3-100)*3)+Inputs!$B$28+Inputs!$B$29 | V2: =IF(C2,(Skills!G2*N2*Summary!$B$22)*IF(Inputs!$B$39="pvp",1,(1+(Inputs!$B$21+Skills!Q2+Summary!$B$15+Artifacts!$B$80+Artifacts!$B$36)/100)*(MIN(Skills!W2,Inputs!$B$37)))*((1+Artifacts!$B$53/100)),0)
A3: =Skills!A3 | B3: =Skills!B3 | C3: =Inputs!$B$3>=35 | D3: =IF(Skills!C3=1,60+Inputs!$B$25+Inputs!$B$29,IF(Skills!C3=2,90+Inputs!$B$26+Inputs!$B$29,IF(Skills!C3=3,120+Inputs!$B$27+Inputs!$B$29,MAX(0,(Inputs!$B$3-100)*3)+Inputs!$B$28+Inputs!$B$29))) | E3: =INDEX(FactorTable!$B$2:$Y$301, MATCH(ROUND(MIN(300,MAX(1,D3)),0), FactorTable!$A$2:$A$301,0), Skills!M3+1) | F3: =IF(Skills!N3=TRUE,(Skills!L3/10)*(E3/1000),Skills!L3/10)+Skills!O3 | G3: =Skills!G3*IF(Skills!H3>0,Skills!I3/Skills!H3,1) | H3: =1-(1-Skills!J3/100)^Skills!K3 | I3: =IF(Skills!AA3<>"",1+(Skills!AA3/10)*($U$3/1000)/100,1) | J3: =Summary!$B$6*(F3/100) | K3: =J3*(1+Summary!$B$7/100)*(1+Inputs!$B$15/100)*(1+Inputs!$B$16/100)*(5000/(6000+Inputs!$B$43*(1-Inputs!$B$19/100)))*(1+Inputs!$B$24/100)*(1+Skills!R3/100)*(1+Artifacts!$B$34/100)*(1+(IF(Skills!A3="SHOWDOWN",Inputs!$B$17+Artifacts!$B$40,Inputs!$B$18+Artifacts!$B$39))/100)*(Summary!$B$13*Summary!$B$16*(1+Artifacts!$B$38/100)*I3) | L3: =K3*(MIN(Inputs!$B$22,Inputs!$B$23)/100+Inputs!$B$23/100)/2 | M3: =L3*(1+(Inputs!$B$10+Summary!$B$24+Artifacts!$B$33)/100) | N3: =L3*(1-MIN((Inputs!$B$9+Summary!$B$14+Artifacts!$B$32),100)/100)+M3*(MIN((Inputs!$B$9+Summary!$B$14+Artifacts!$B$32),100)/100) | O3: =(1-Summary!$B$11)*T3+Summary!$B$11*V3 | P3: =IF(Summary!$B$3=0,0,O3/Summary!$B$3) | Q3: =IFERROR(1/(IF(Inputs!$B$39="pvp",15,MAX(0.1,Skills!D3-IF(Skills!E3=TRUE,Inputs!$B$32,0)))*(1-IF(AND(ArtifactsInput!$M$27,Inputs!$B$4="Chapter Hunt"),CHOOSE(ArtifactsInput!$N$27+1,20,24,28,32,36,40),0)/100)),0) | R3: =IF(AND(Inputs!$B$39<>"pvp",Inputs!$B$44>0),IF(MAX(0,Inputs!$B$44-Summary!$B$26)<=0,0,(INT(MAX(0,Inputs!$B$44-Summary!$B$26)/(IF(Inputs!$B$39="pvp",15,MAX(0.1,Skills!D3-IF(Skills!E3=TRUE,Inputs!$B$32,0)))*(1-IF(AND(ArtifactsInput!$M$27,Inputs!$B$4="Chapter Hunt"),CHOOSE(ArtifactsInput!$N$27+1,20,24,28,32,36,40),0)/100)))+1)),0) | S3: =IFERROR(O3/N3,0) | T3: =IF(C3,(H3*N3*IF(AND(Inputs!$B$39<>"pvp",Inputs!$B$44>0),((Skills!G3*((R3-1)*IF(Skills!H3>0,Skills!I3/Skills!H3,1)+IF(Skills!H3>0,MIN(Skills!I3,MAX(0,MAX(0,Inputs!$B$44-Summary!$B$26)-((R3-1)*(IF(Inputs!$B$39="pvp",15,MAX(0.1,Skills!D3-IF(Skills!E3=TRUE,Inputs!$B$32,0)))*(1-IF(AND(ArtifactsInput!$M$27,Inputs!$B$4="Chapter Hunt"),CHOOSE(ArtifactsInput!$N$27+1,20,24,28,32,36,40),0)/100)))))/Skills!H3,1)))/Inputs!$B$44),G3*Q3))*IF(Inputs!$B$39="pvp",1,1+(Inputs!$B$20+Skills!P3+Summary!$B$15+Artifacts!$B$35+Artifacts!$B$36)/100)*((((5000/(6000+Inputs!$B$43*(1-(100*(1-(1-Inputs!$B$19/100)*(1-Artifacts!$B$51/100)^IF(Inputs!$B$39="pvp",1,2)))/100)))/(5000/(6000+Inputs!$B$43*(1-Inputs!$B$19/100))))*((L3*(1-MIN(100,(Inputs!$B$9+Summary!$B$14+Artifacts!$B$32)+Artifacts!$B$69)/100)+M3*(MIN(100,(Inputs!$B$9+Summary!$B$14+Artifacts!$B$32)+Artifacts!$B$69)/100))/(L3*(1-MIN(100,(Inputs!$B$9+Summary!$B$14+Artifacts!$B$32))/100)+M3*(MIN(100,(Inputs!$B$9+Summary!$B$14+Artifacts!$B$32))/100)))*(1+Artifacts!$B$81/100))),0) | U3: =INDEX(FactorTable!$B$2:$Y$301, MATCH(ROUND(MIN(300,MAX(1,U2)),0), FactorTable!$A$2:$A$301,0), 24) | V3: =IF(C3,(H3*N3*IF(AND(Inputs!$B$39<>"pvp",Inputs!$B$44>0),((Skills!G3*((R3-1)*IF(Skills!H3>0,Skills!I3/Skills!H3,1)+IF(Skills!H3>0,MIN(Skills!I3,MAX(0,MAX(0,Inputs!$B$44-Summary!$B$26)-((R3-1)*(IF(Inputs!$B$39="pvp",15,MAX(0.1,Skills!D3-IF(Skills!E3=TRUE,Inputs!$B$32,0)))*(1-IF(AND(ArtifactsInput!$M$27,Inputs!$B$4="Chapter Hunt"),CHOOSE(ArtifactsInput!$N$27+1,20,24,28,32,36,40),0)/100)))))/Skills!H3,1)))/Inputs!$B$44),G3*Q3))*IF(Inputs!$B$39="pvp",1,(1+(Inputs!$B$21+Skills!Q3+Summary!$B$15+Artifacts!$B$80+Artifacts!$B$36)/100)*(MIN(Skills!W3,Inputs!$B$37)))*((1+Artifacts!$B$53/100)),0)
A4: =Skills!A4 | B4: =Skills!B4 | C4: =Inputs!$B$3>=40 | D4: =IF(Skills!C4=1,60+Inputs!$B$25+Inputs!$B$29,IF(Skills!C4=2,90+Inputs!$B$26+Inputs!$B$29,IF(Skills!C4=3,120+Inputs!$B$27+Inputs!$B$29,MAX(0,(Inputs!$B$3-100)*3)+Inputs!$B$28+Inputs!$B$29))) | E4: =INDEX(FactorTable!$B$2:$Y$301, MATCH(ROUND(MIN(300,MAX(1,D4)),0), FactorTable!$A$2:$A$301,0), Skills!M4+1) | F4: =IF(Skills!N4=TRUE,(Skills!L4/10)*(E4/1000),Skills!L4/10)+Skills!O4 | G4: =Skills!G4*IF(Skills!H4>0,Skills!I4/Skills!H4,1) | H4: =1-(1-Skills!J4/100)^Skills!K4 | I4: =IF(Skills!AA4<>"",1+(Skills!AA4/10)*($U$3/1000)/100,1) | J4: =Summary!$B$6*(F4/100) | K4: =J4*(1+Summary!$B$7/100)*(1+Inputs!$B$15/100)*(1+Inputs!$B$16/100)*(5000/(6000+Inputs!$B$43*(1-Inputs!$B$19/100)))*(1+Inputs!$B$24/100)*(1+Skills!R4/100)*(1+Artifacts!$B$34/100)*(1+(IF(Skills!A4="SHOWDOWN",Inputs!$B$17+Artifacts!$B$40,Inputs!$B$18+Artifacts!$B$39))/100)*(Summary!$B$13*Summary!$B$16*(1+Artifacts!$B$38/100)*I4) | L4: =K4*(MIN(Inputs!$B$22,Inputs!$B$23)/100+Inputs!$B$23/100)/2 | M4: =L4*(1+(Inputs!$B$10+Summary!$B$24+Artifacts!$B$33)/100) | N4: =L4*(1-MIN((Inputs!$B$9+Summary!$B$14+Artifacts!$B$32),100)/100)+M4*(MIN((Inputs!$B$9+Summary!$B$14+Artifacts!$B$32),100)/100) | O4: =(1-Summary!$B$11)*T4+Summary!$B$11*V4 | P4: =IF(Summary!$B$3=0,0,O4/Summary!$B$3) | Q4: =IFERROR(1/(IF(Inputs!$B$39="pvp",15,MAX(0.1,Skills!D4-IF(Skills!E4=TRUE,Inputs!$B$32,0)))*(1-IF(AND(ArtifactsInput!$M$27,Inputs!$B$4="Chapter Hunt"),CHOOSE(ArtifactsInput!$N$27+1,20,24,28,32,36,40),0)/100)),0) | R4: =IF(AND(Inputs!$B$39<>"pvp",Inputs!$B$44>0),IF(MAX(0,Inputs!$B$44-Summary!$B$26)<=0,0,(INT(MAX(0,Inputs!$B$44-Summary!$B$26)/(IF(Inputs!$B$39="pvp",15,MAX(0.1,Skills!D4-IF(Skills!E4=TRUE,Inputs!$B$32,0)))*(1-IF(AND(ArtifactsInput!$M$27,Inputs!$B$4="Chapter Hunt"),CHOOSE(ArtifactsInput!$N$27+1,20,24,28,32,36,40),0)/100)))+1)),0) | S4: =IFERROR(O4/N4,0) | T4: =IF(C4,(H4*N4*IF(AND(Inputs!$B$39<>"pvp",Inputs!$B$44>0),((Skills!G4*((R4-1)*IF(Skills!H4>0,Skills!I4/Skills!H4,1)+IF(Skills!H4>0,MIN(Skills!I4,MAX(0,MAX(0,Inputs!$B$44-Summary!$B$26)-((R4-1)*(IF(Inputs!$B$39="pvp",15,MAX(0.1,Skills!D4-IF(Skills!E4=TRUE,Inputs!$B$32,0)))*(1-IF(AND(ArtifactsInput!$M$27,Inputs!$B$4="Chapter Hunt"),CHOOSE(ArtifactsInput!$N$27+1,20,24,28,32,36,40),0)/100)))))/Skills!H4,1)))/Inputs!$B$44),G4*Q4))*IF(Inputs!$B$39="pvp",1,1+(Inputs!$B$20+Skills!P4+Summary!$B$15+Artifacts!$B$35+Artifacts!$B$36)/100)*((((5000/(6000+Inputs!$B$43*(1-(100*(1-(1-Inputs!$B$19/100)*(1-Artifacts!$B$51/100)^IF(Inputs!$B$39="pvp",1,2)))/100)))/(5000/(6000+Inputs!$B$43*(1-Inputs!$B$19/100))))*((L4*(1-MIN(100,(Inputs!$B$9+Summary!$B$14+Artifacts!$B$32)+Artifacts!$B$69)/100)+M4*(MIN(100,(Inputs!$B$9+Summary!$B$14+Artifacts!$B$32)+Artifacts!$B$69)/100))/(L4*(1-MIN(100,(Inputs!$B$9+Summary!$B$14+Artifacts!$B$32))/100)+M4*(MIN(100,(Inputs!$B$9+Summary!$B$14+Artifacts!$B$32))/100)))*(1+Artifacts!$B$81/100))),0) | V4: =IF(C4,(H4*N4*IF(AND(Inputs!$B$39<>"pvp",Inputs!$B$44>0),((Skills!G4*((R4-1)*IF(Skills!H4>0,Skills!I4/Skills!H4,1)+IF(Skills!H4>0,MIN(Skills!I4,MAX(0,MAX(0,Inputs!$B$44-Summary!$B$26)-((R4-1)*(IF(Inputs!$B$39="pvp",15,MAX(0.1,Skills!D4-IF(Skills!E4=TRUE,Inputs!$B$32,0)))*(1-IF(AND(ArtifactsInput!$M$27,Inputs!$B$4="Chapter Hunt"),CHOOSE(ArtifactsInput!$N$27+1,20,24,28,32,36,40),0)/100)))))/Skills!H4,1)))/Inputs!$B$44),G4*Q4))*IF(Inputs!$B$39="pvp",1,(1+(Inputs!$B$21+Skills!Q4+Summary!$B$15+Artifacts!$B$80+Artifacts!$B$36)/100)*(MIN(Skills!W4,Inputs!$B$37)))*((1+Artifacts!$B$53/100)),0)
A5: =Skills!A5 | B5: =Skills!B5 | C5: =Inputs!$B$3>=63 | D5: =IF(Skills!C5=1,60+Inputs!$B$25+Inputs!$B$29,IF(Skills!C5=2,90+Inputs!$B$26+Inputs!$B$29,IF(Skills!C5=3,120+Inputs!$B$27+Inputs!$B$29,MAX(0,(Inputs!$B$3-100)*3)+Inputs!$B$28+Inputs!$B$29))) | E5: =INDEX(FactorTable!$B$2:$Y$301, MATCH(ROUND(MIN(300,MAX(1,D5)),0), FactorTable!$A$2:$A$301,0), Skills!M5+1) | F5: =IF(Skills!N5=TRUE,(Skills!L5/10)*(E5/1000),Skills!L5/10)+Skills!O5 | G5: =Skills!G5*IF(Skills!H5>0,Skills!I5/Skills!H5,1) | H5: =1-(1-Skills!J5/100)^Skills!K5 | I5: =IF(Skills!AA5<>"",1+(Skills!AA5/10)*($U$3/1000)/100,1) | J5: =Summary!$B$6*(F5/100) | K5: =J5*(1+Summary!$B$7/100)*(1+Inputs!$B$15/100)*(1+Inputs!$B$16/100)*(5000/(6000+Inputs!$B$43*(1-Inputs!$B$19/100)))*(1+Inputs!$B$24/100)*(1+Skills!R5/100)*(1+Artifacts!$B$34/100)*(1+(IF(Skills!A5="SHOWDOWN",Inputs!$B$17+Artifacts!$B$40,Inputs!$B$18+Artifacts!$B$39))/100)*(Summary!$B$13*Summary!$B$16*(1+Artifacts!$B$38/100)*I5) | L5: =K5*(MIN(Inputs!$B$22,Inputs!$B$23)/100+Inputs!$B$23/100)/2 | M5: =L5*(1+(Inputs!$B$10+Summary!$B$24+Artifacts!$B$33)/100) | N5: =L5*(1-MIN((Inputs!$B$9+Summary!$B$14+Artifacts!$B$32),100)/100)+M5*(MIN((Inputs!$B$9+Summary!$B$14+Artifacts!$B$32),100)/100) | O5: =(1-Summary!$B$11)*T5+Summary!$B$11*V5 | P5: =IF(Summary!$B$3=0,0,O5/Summary!$B$3) | Q5: =IFERROR(1/(IF(Inputs!$B$39="pvp",15,MAX(0.1,Skills!D5-IF(Skills!E5=TRUE,Inputs!$B$32,0)))*(1-IF(AND(ArtifactsInput!$M$27,Inputs!$B$4="Chapter Hunt"),CHOOSE(ArtifactsInput!$N$27+1,20,24,28,32,36,40),0)/100)),0) | R5: =IF(AND(Inputs!$B$39<>"pvp",Inputs!$B$44>0),IF(MAX(0,Inputs!$B$44-Summary!$B$26)<=0,0,(INT(MAX(0,Inputs!$B$44-Summary!$B$26)/(IF(Inputs!$B$39="pvp",15,MAX(0.1,Skills!D5-IF(Skills!E5=TRUE,Inputs!$B$32,0)))*(1-IF(AND(ArtifactsInput!$M$27,Inputs!$B$4="Chapter Hunt"),CHOOSE(ArtifactsInput!$N$27+1,20,24,28,32,36,40),0)/100)))+1)),0) | S5: =IFERROR(O5/N5,0) | T5: =IF(C5,(H5*N5*IF(AND(Inputs!$B$39<>"pvp",Inputs!$B$44>0),((Skills!G5*((R5-1)*IF(Skills!H5>0,Skills!I5/Skills!H5,1)+IF(Skills!H5>0,MIN(Skills!I5,MAX(0,MAX(0,Inputs!$B$44-Summary!$B$26)-((R5-1)*(IF(Inputs!$B$39="pvp",15,MAX(0.1,Skills!D5-IF(Skills!E5=TRUE,Inputs!$B$32,0)))*(1-IF(AND(ArtifactsInput!$M$27,Inputs!$B$4="Chapter Hunt"),CHOOSE(ArtifactsInput!$N$27+1,20,24,28,32,36,40),0)/100)))))/Skills!H5,1)))/Inputs!$B$44),G5*Q5))*IF(Inputs!$B$39="pvp",1,1+(Inputs!$B$20+Skills!P5+Summary!$B$15+Artifacts!$B$35+Artifacts!$B$36)/100)*((((5000/(6000+Inputs!$B$43*(1-(100*(1-(1-Inputs!$B$19/100)*(1-Artifacts!$B$51/100)^IF(Inputs!$B$39="pvp",1,2)))/100)))/(5000/(6000+Inputs!$B$43*(1-Inputs!$B$19/100))))*((L5*(1-MIN(100,(Inputs!$B$9+Summary!$B$14+Artifacts!$B$32)+Artifacts!$B$69)/100)+M5*(MIN(100,(Inputs!$B$9+Summary!$B$14+Artifacts!$B$32)+Artifacts!$B$69)/100))/(L5*(1-MIN(100,(Inputs!$B$9+Summary!$B$14+Artifacts!$B$32))/100)+M5*(MIN(100,(Inputs!$B$9+Summary!$B$14+Artifacts!$B$32))/100)))*(1+Artifacts!$B$81/100))),0) | V5: =IF(C5,(H5*N5*IF(AND(Inputs!$B$39<>"pvp",Inputs!$B$44>0),((Skills!G5*((R5-1)*IF(Skills!H5>0,Skills!I5/Skills!H5,1)+IF(Skills!H5>0,MIN(Skills!I5,MAX(0,MAX(0,Inputs!$B$44-Summary!$B$26)-((R5-1)*(IF(Inputs!$B$39="pvp",15,MAX(0.1,Skills!D5-IF(Skills!E5=TRUE,Inputs!$B$32,0)))*(1-IF(AND(ArtifactsInput!$M$27,Inputs!$B$4="Chapter Hunt"),CHOOSE(ArtifactsInput!$N$27+1,20,24,28,32,36,40),0)/100)))))/Skills!H5,1)))/Inputs!$B$44),G5*Q5))*IF(Inputs!$B$39="pvp",1,(1+(Inputs!$B$21+Skills!Q5+Summary!$B$15+Artifacts!$B$80+Artifacts!$B$36)/100)*(MIN(Skills!W5,Inputs!$B$37)))*((1+Artifacts!$B$53/100)),0)
A6: =Skills!A6 | B6: =Skills!B6 | C6: =Inputs!$B$3>=66 | D6: =IF(Skills!C6=1,60+Inputs!$B$25+Inputs!$B$29,IF(Skills!C6=2,90+Inputs!$B$26+Inputs!$B$29,IF(Skills!C6=3,120+Inputs!$B$27+Inputs!$B$29,MAX(0,(Inputs!$B$3-100)*3)+Inputs!$B$28+Inputs!$B$29))) | E6: =INDEX(FactorTable!$B$2:$Y$301, MATCH(ROUND(MIN(300,MAX(1,D6)),0), FactorTable!$A$2:$A$301,0), Skills!M6+1) | F6: =IF(Skills!N6=TRUE,(Skills!L6/10)*(E6/1000),Skills!L6/10)+Skills!O6 | G6: =Skills!G6*IF(Skills!H6>0,Skills!I6/Skills!H6,1) | H6: =1-(1-Skills!J6/100)^Skills!K6 | I6: =IF(Skills!AA6<>"",1+(Skills!AA6/10)*($U$3/1000)/100,1) | O6: =(1-Summary!$B$11)*T6+Summary!$B$11*V6 | P6: =IF(Summary!$B$3=0,0,O6/Summary!$B$3) | Q6: 0 | R6: 0 | S6: =IFERROR(O6/N6,0) | T6: 0 | V6: 0
A7: =Skills!A7 | B7: =Skills!B7 | C7: =Inputs!$B$3>=66 | D7: =IF(Skills!C7=1,60+Inputs!$B$25+Inputs!$B$29,IF(Skills!C7=2,90+Inputs!$B$26+Inputs!$B$29,IF(Skills!C7=3,120+Inputs!$B$27+Inputs!$B$29,MAX(0,(Inputs!$B$3-100)*3)+Inputs!$B$28+Inputs!$B$29))) | E7: =INDEX(FactorTable!$B$2:$Y$301, MATCH(ROUND(MIN(300,MAX(1,D7)),0), FactorTable!$A$2:$A$301,0), Skills!M7+1) | F7: =IF(Skills!N7=TRUE,(Skills!L7/10)*(E7/1000),Skills!L7/10)+Skills!O7 | G7: =Skills!G7*IF(Skills!H7>0,Skills!I7/Skills!H7,1) | H7: =1-(1-Skills!J7/100)^Skills!K7 | I7: =IF(Skills!AA7<>"",1+(Skills!AA7/10)*($U$3/1000)/100,1) | O7: =(1-Summary!$B$11)*T7+Summary!$B$11*V7 | P7: =IF(Summary!$B$3=0,0,O7/Summary!$B$3) | Q7: 0 | R7: 0 | S7: =IFERROR(O7/N7,0) | T7: 0 | V7: 0
A8: =Skills!A8 | B8: =Skills!B8 | C8: =Inputs!$B$3>=69 | D8: =IF(Skills!C8=1,60+Inputs!$B$25+Inputs!$B$29,IF(Skills!C8=2,90+Inputs!$B$26+Inputs!$B$29,IF(Skills!C8=3,120+Inputs!$B$27+Inputs!$B$29,MAX(0,(Inputs!$B$3-100)*3)+Inputs!$B$28+Inputs!$B$29))) | E8: =INDEX(FactorTable!$B$2:$Y$301, MATCH(ROUND(MIN(300,MAX(1,D8)),0), FactorTable!$A$2:$A$301,0), Skills!M8+1) | F8: =IF(Skills!N8=TRUE,(Skills!L8/10)*(E8/1000),Skills!L8/10)+Skills!O8 | G8: =Skills!G8*IF(Skills!H8>0,Skills!I8/Skills!H8,1) | H8: =1-(1-Skills!J8/100)^Skills!K8 | I8: =IF(Skills!AA8<>"",1+(Skills!AA8/10)*($U$3/1000)/100,1) | J8: =Summary!$B$6*(F8/100) | K8: =J8*(1+Summary!$B$7/100)*(1+Inputs!$B$15/100)*(1+Inputs!$B$16/100)*(5000/(6000+Inputs!$B$43*(1-Inputs!$B$19/100)))*(1+Inputs!$B$24/100)*(1+Skills!R8/100)*(1+Artifacts!$B$34/100)*(1+(IF(Skills!A8="SHOWDOWN",Inputs!$B$17+Artifacts!$B$40,Inputs!$B$18+Artifacts!$B$39))/100)*(Summary!$B$13*Summary!$B$16*(1+Artifacts!$B$38/100)*I8) | L8: =K8*(MIN(Inputs!$B$22,Inputs!$B$23)/100+Inputs!$B$23/100)/2 | M8: =L8*(1+(Inputs!$B$10+Summary!$B$24+Artifacts!$B$33)/100) | N8: =L8*(1-MIN((Inputs!$B$9+Summary!$B$14+Artifacts!$B$32),100)/100)+M8*(MIN((Inputs!$B$9+Summary!$B$14+Artifacts!$B$32),100)/100) | O8: =(1-Summary!$B$11)*T8+Summary!$B$11*V8 | P8: =IF(Summary!$B$3=0,0,O8/Summary!$B$3) | Q8: =IFERROR(1/(IF(Inputs!$B$39="pvp",15,MAX(0.1,Skills!D8-IF(Skills!E8=TRUE,Inputs!$B$32,0)))*(1-IF(AND(ArtifactsInput!$M$27,Inputs!$B$4="Chapter Hunt"),CHOOSE(ArtifactsInput!$N$27+1,20,24,28,32,36,40),0)/100)),0) | R8: =IF(AND(Inputs!$B$39<>"pvp",Inputs!$B$44>0),IF(MAX(0,Inputs!$B$44-Summary!$B$26)<=0,0,(INT(MAX(0,Inputs!$B$44-Summary!$B$26)/(IF(Inputs!$B$39="pvp",15,MAX(0.1,Skills!D8-IF(Skills!E8=TRUE,Inputs!$B$32,0)))*(1-IF(AND(ArtifactsInput!$M$27,Inputs!$B$4="Chapter Hunt"),CHOOSE(ArtifactsInput!$N$27+1,20,24,28,32,36,40),0)/100)))+1)),0) | S8: =IFERROR(O8/N8,0) | T8: =IF(C8,(H8*N8*IF(AND(Inputs!$B$39<>"pvp",Inputs!$B$44>0),((Skills!G8*((R8-1)*IF(Skills!H8>0,Skills!I8/Skills!H8,1)+IF(Skills!H8>0,MIN(Skills!I8,MAX(0,MAX(0,Inputs!$B$44-Summary!$B$26)-((R8-1)*(IF(Inputs!$B$39="pvp",15,MAX(0.1,Skills!D8-IF(Skills!E8=TRUE,Inputs!$B$32,0)))*(1-IF(AND(ArtifactsInput!$M$27,Inputs!$B$4="Chapter Hunt"),CHOOSE(ArtifactsInput!$N$27+1,20,24,28,32,36,40),0)/100)))))/Skills!H8,1)))/Inputs!$B$44),G8*Q8))*IF(Inputs!$B$39="pvp",1,1+(Inputs!$B$20+Skills!P8+Summary!$B$15+Artifacts!$B$35+Artifacts!$B$36)/100)*((((5000/(6000+Inputs!$B$43*(1-(100*(1-(1-Inputs!$B$19/100)*(1-Artifacts!$B$51/100)^IF(Inputs!$B$39="pvp",1,2)))/100)))/(5000/(6000+Inputs!$B$43*(1-Inputs!$B$19/100))))*((L8*(1-MIN(100,(Inputs!$B$9+Summary!$B$14+Artifacts!$B$32)+Artifacts!$B$69)/100)+M8*(MIN(100,(Inputs!$B$9+Summary!$B$14+Artifacts!$B$32)+Artifacts!$B$69)/100))/(L8*(1-MIN(100,(Inputs!$B$9+Summary!$B$14+Artifacts!$B$32))/100)+M8*(MIN(100,(Inputs!$B$9+Summary!$B$14+Artifacts!$B$32))/100)))*(1+Artifacts!$B$81/100))),0) | V8: =IF(C8,(H8*N8*IF(AND(Inputs!$B$39<>"pvp",Inputs!$B$44>0),((Skills!G8*((R8-1)*IF(Skills!H8>0,Skills!I8/Skills!H8,1)+IF(Skills!H8>0,MIN(Skills!I8,MAX(0,MAX(0,Inputs!$B$44-Summary!$B$26)-((R8-1)*(IF(Inputs!$B$39="pvp",15,MAX(0.1,Skills!D8-IF(Skills!E8=TRUE,Inputs!$B$32,0)))*(1-IF(AND(ArtifactsInput!$M$27,Inputs!$B$4="Chapter Hunt"),CHOOSE(ArtifactsInput!$N$27+1,20,24,28,32,36,40),0)/100)))))/Skills!H8,1)))/Inputs!$B$44),G8*Q8))*IF(Inputs!$B$39="pvp",1,(1+(Inputs!$B$21+Skills!Q8+Summary!$B$15+Artifacts!$B$80+Artifacts!$B$36)/100)*(MIN(Skills!W8,Inputs!$B$37)))*((1+Artifacts!$B$53/100)),0)
A9: =Skills!A9 | B9: =Skills!B9 | C9: =Inputs!$B$3>=72 | D9: =IF(Skills!C9=1,60+Inputs!$B$25+Inputs!$B$29,IF(Skills!C9=2,90+Inputs!$B$26+Inputs!$B$29,IF(Skills!C9=3,120+Inputs!$B$27+Inputs!$B$29,MAX(0,(Inputs!$B$3-100)*3)+Inputs!$B$28+Inputs!$B$29))) | E9: =INDEX(FactorTable!$B$2:$Y$301, MATCH(ROUND(MIN(300,MAX(1,D9)),0), FactorTable!$A$2:$A$301,0), Skills!M9+1) | F9: =IF(Skills!N9=TRUE,(Skills!L9/10)*(E9/1000),Skills!L9/10)+Skills!O9 | G9: =Skills!G9*IF(Skills!H9>0,Skills!I9/Skills!H9,1) | H9: =1-(1-Skills!J9/100)^Skills!K9 | I9: =IF(Skills!AA9<>"",1+(Skills!AA9/10)*($U$3/1000)/100,1) | J9: =Summary!$B$6*(F9/100) | K9: =J9*(1+Summary!$B$7/100)*(1+Inputs!$B$15/100)*(1+Inputs!$B$16/100)*(5000/(6000+Inputs!$B$43*(1-Inputs!$B$19/100)))*(1+Inputs!$B$24/100)*(1+Skills!R9/100)*(1+Artifacts!$B$34/100)*(1+(IF(Skills!A9="SHOWDOWN",Inputs!$B$17+Artifacts!$B$40,Inputs!$B$18+Artifacts!$B$39))/100)*(Summary!$B$13*Summary!$B$16*(1+Artifacts!$B$38/100)*I9) | L9: =K9*(MIN(Inputs!$B$22,Inputs!$B$23)/100+Inputs!$B$23/100)/2 | M9: =L9*(1+(Inputs!$B$10+Summary!$B$24+Artifacts!$B$33)/100) | N9: =L9*(1-MIN((Inputs!$B$9+Summary!$B$14+Artifacts!$B$32),100)/100)+M9*(MIN((Inputs!$B$9+Summary!$B$14+Artifacts!$B$32),100)/100) | O9: =(1-Summary!$B$11)*T9+Summary!$B$11*V9 | P9: =IF(Summary!$B$3=0,0,O9/Summary!$B$3) | Q9: =IFERROR(1/(IF(Inputs!$B$39="pvp",15,MAX(0.1,Skills!D9-IF(Skills!E9=TRUE,Inputs!$B$32,0)))*(1-IF(AND(ArtifactsInput!$M$27,Inputs!$B$4="Chapter Hunt"),CHOOSE(ArtifactsInput!$N$27+1,20,24,28,32,36,40),0)/100)),0) | R9: =IF(AND(Inputs!$B$39<>"pvp",Inputs!$B$44>0),IF(MAX(0,Inputs!$B$44-Summary!$B$26)<=0,0,(INT(MAX(0,Inputs!$B$44-Summary!$B$26)/(IF(Inputs!$B$39="pvp",15,MAX(0.1,Skills!D9-IF(Skills!E9=TRUE,Inputs!$B$32,0)))*(1-IF(AND(ArtifactsInput!$M$27,Inputs!$B$4="Chapter Hunt"),CHOOSE(ArtifactsInput!$N$27+1,20,24,28,32,36,40),0)/100)))+1)),0) | S9: =IFERROR(O9/N9,0) | T9: =IF(C9,(H9*N9*IF(AND(Inputs!$B$39<>"pvp",Inputs!$B$44>0),((Skills!G9*((R9-1)*IF(Skills!H9>0,Skills!I9/Skills!H9,1)+IF(Skills!H9>0,MIN(Skills!I9,MAX(0,MAX(0,Inputs!$B$44-Summary!$B$26)-((R9-1)*(IF(Inputs!$B$39="pvp",15,MAX(0.1,Skills!D9-IF(Skills!E9=TRUE,Inputs!$B$32,0)))*(1-IF(AND(ArtifactsInput!$M$27,Inputs!$B$4="Chapter Hunt"),CHOOSE(ArtifactsInput!$N$27+1,20,24,28,32,36,40),0)/100)))))/Skills!H9,1)))/Inputs!$B$44),G9*Q9))*IF(Inputs!$B$39="pvp",1,1+(Inputs!$B$20+Skills!P9+Summary!$B$15+Artifacts!$B$35+Artifacts!$B$36)/100)*((((5000/(6000+Inputs!$B$43*(1-(100*(1-(1-Inputs!$B$19/100)*(1-Artifacts!$B$51/100)^IF(Inputs!$B$39="pvp",1,2)))/100)))/(5000/(6000+Inputs!$B$43*(1-Inputs!$B$19/100))))*((L9*(1-MIN(100,(Inputs!$B$9+Summary!$B$14+Artifacts!$B$32)+Artifacts!$B$69)/100)+M9*(MIN(100,(Inputs!$B$9+Summary!$B$14+Artifacts!$B$32)+Artifacts!$B$69)/100))/(L9*(1-MIN(100,(Inputs!$B$9+Summary!$B$14+Artifacts!$B$32))/100)+M9*(MIN(100,(Inputs!$B$9+Summary!$B$14+Artifacts!$B$32))/100)))*(1+Artifacts!$B$81/100))),0) | V9: =IF(C9,(H9*N9*IF(AND(Inputs!$B$39<>"pvp",Inputs!$B$44>0),((Skills!G9*((R9-1)*IF(Skills!H9>0,Skills!I9/Skills!H9,1)+IF(Skills!H9>0,MIN(Skills!I9,MAX(0,MAX(0,Inputs!$B$44-Summary!$B$26)-((R9-1)*(IF(Inputs!$B$39="pvp",15,MAX(0.1,Skills!D9-IF(Skills!E9=TRUE,Inputs!$B$32,0)))*(1-IF(AND(ArtifactsInput!$M$27,Inputs!$B$4="Chapter Hunt"),CHOOSE(ArtifactsInput!$N$27+1,20,24,28,32,36,40),0)/100)))))/Skills!H9,1)))/Inputs!$B$44),G9*Q9))*IF(Inputs!$B$39="pvp",1,(1+(Inputs!$B$21+Skills!Q9+Summary!$B$15+Artifacts!$B$80+Artifacts!$B$36)/100)*(MIN(Skills!W9,Inputs!$B$37)))*((1+Artifacts!$B$53/100)),0)
