Workbook

Sheet README
A1: Shadower — DPS Calculator: How to Use This Workbook
A3: How to use this workbook
A4: Only edit the yellow-highlighted cells on the Inputs sheet — every other sheet is computed from those values and will be overwritten if you rebuild the workbook.
A5: Summary shows Total DPS, a Per-Skill DPS Breakdown (damage-dealing skills only — buffs/passives that never deal their own damage are omitted), and a Marginal DPS & Stat Value table showing the DPS gained per +1 of each stat.
A6: Sensitivity has the full detail behind that marginal-value table — one self-contained block per stat, showing exactly how bumping that stat by +1 changes every downstream number.
A7: CubeData/PotentialCubes model your current gear's Potential Cube lines and drive cube-reroll expected-value decisions. For the full standalone Potential Cube EV calculator (exact optimal-stopping math, works from this workbook alone), see tools/potential_cubes_ev.py in the project repo.
A9: Design decisions & assumptions
A10: Venom/Toxic Venom assume the target is permanently afflicted with Venom's poison at steady state, not an exact on/off timer — matches every other DoT-uptime assumption in this project.
A11: Crit Rate pushed above 100% (e.g. by cube potential lines) automatically redirects its stat-value to Crit Damage's own per-unit DPS value on the PotentialCubes sheet, since excess Crit Rate cannot do anything past 100%.
A12: Buffs and stacking resources (Dark Sight Attack, Into Darkness, Smokescreen, Meso Explosion/Blood Money stacks) are modeled at steady-state duty-cycle average uptime, not as an exact moment-to-moment state machine.
A13: Assassinate's finishing blow is modeled as landing on average every 2nd cast (a flat 50% average multiplier), and Mastery Lv.108 Murderous Intent's finisher-doubling is a steady-state average multiplier based on relative cast rates, not an exact alternating state machine.
A14: Channel Karma, Shadow Shifter's own Attack buff, Dagger Mastery, Critical Edge, Physical Training, Dagger Expert, and Shadower Instinct are always-on passives assumed to already be reflected in your own Inputs stat entries — only their Sensitivity marginal delta (what changes if their mastery level differs from what you assumed) is modeled live.
... A16: Not modeled (out of scope): all forms of crowd control (Phase Dash/Dark Sight/Assassinate stuns), Accuracy/Evasion/Defense reduction (Smokescreen, Steal, Assassinate), movement speed (Nimble Feet, Haste), the character's own Defense stat (Shield Mastery), and Companion Summoning Time.

Sheet Inputs
A1: Shadower — DPS Calculator Inputs | N1: (none)
C2: Chapter Boss | D2: Breakthrough | E2: PvP | F2: EXP Dungeon | G2: Equipment Dungeon | H2: Weapon Dungeon | I2: Enhancement Dungeon | J2: Hero Dungeon | K2: World Boss | L2: Chapter Hunt | N2: Charm of the Undead
A3: Character Level | B3: 113 | N3: Pig's Ribbon
A4: Content Type | B4: Chapter Boss | N4: Shamaness Marble
A5: Chapter-Stage — 'chapter-substage' (e.g. '28-9') for Breakthrough/Chapter Hunt, just the chapter number for Chapter Boss, or just the stage number for Weapon/Equipment/Enhancement/EXP/Hero Dungeon. Not applicable to World Boss/PvP. | B5: =INDEX($C$5:$L$5,MATCH($B$4,$C$2:$L$2,0)) | C5: 28 | D5: 28-9 | F5: 80 | G5: 80 | H5: 80 | I5: 80 | J5: 80 | L5: 28-9 | N5: The Contract of Darkness
A6: Flat ATTACK | B6: =INDEX($C$6:$L$6,MATCH($B$4,$C$2:$L$2,0)) | C6: 28374.5 | D6: 28374.5 | E6: 28374.5 | F6: 28374.5 | G6: 28374.5 | H6: 28374.5 | I6: 28374.5 | J6: 28374.5 | K6: 28374.5 | L6: 28374.5 | N6: Rainbow-colored Snail Shell
A7: ATTACK % | B7: =INDEX($C$7:$L$7,MATCH($B$4,$C$2:$L$2,0)) | C7: 0 | D7: 0 | E7: 0 | F7: 0 | G7: 0 | H7: 0 | I7: 0 | J7: 0 | K7: 0 | L7: 0 | N7: Hexagon Necklace
A8: Defense (your own DEF stat; PvP assumes the opponent has the same Defense as you) | B8: =INDEX($C$8:$L$8,MATCH($B$4,$C$2:$L$2,0)) | C8: 99.1 | D8: 99.1 | E8: 99.1 | F8: 99.1 | G8: 99.1 | H8: 99.1 | I8: 99.1 | J8: 99.1 | K8: 99.1 | L8: 99.1 | N8: Arwen's Glass Shoes
A9: CRIT_RATE % | B9: =INDEX($C$9:$L$9,MATCH($B$4,$C$2:$L$2,0)) | C9: 244.4 | D9: 244.4 | E9: 244.4 | F9: 244.4 | G9: 244.4 | H9: 244.4 | I9: 244.4 | J9: 244.4 | K9: 244.4 | L9: 244.4 | N9: Mushmom's Cap
A10: CRIT_DAMAGE % | B10: =INDEX($C$10:$L$10,MATCH($B$4,$C$2:$L$2,0)) | C10: 75.9 | D10: 75.9 | E10: 75.9 | F10: 75.9 | G10: 75.9 | H10: 75.9 | I10: 75.9 | J10: 75.9 | K10: 75.9 | L10: 75.9 | N10: Clear Spring Water
A11: ATTACK_SPEED % (base, excludes Nimble Feet/Agile Daggers) | B11: =INDEX($C$11:$L$11,MATCH($B$4,$C$2:$L$2,0)) | C11: 45069 | D11: 45069 | E11: 45069 | F11: 45069 | G11: 45069 | H11: 45069 | I11: 45069 | J11: 45069 | K11: 45069 | L11: 45069 | N11: Athena Pierce's Old Gloves
A12: Flat LUK | B12: =INDEX($C$12:$L$12,MATCH($B$4,$C$2:$L$2,0)) | C12: 292.9 | D12: 292.9 | E12: 292.9 | F12: 292.9 | G12: 292.9 | H12: 292.9 | I12: 292.9 | J12: 292.9 | K12: 292.9 | L12: 292.9 | N12: Zakum's Stone Piece
A13: LUK % | B13: =INDEX($C$13:$L$13,MATCH($B$4,$C$2:$L$2,0)) | C13: 302 | D13: 302 | E13: 302 | F13: 302 | G13: 302 | H13: 302 | I13: 302 | J13: 302 | K13: 302 | L13: 302 | N13: Horntail's Scale
A14: DEX | B14: =INDEX($C$14:$L$14,MATCH($B$4,$C$2:$L$2,0)) | C14: 840.7 | D14: 840.7 | E14: 840.7 | F14: 840.7 | G14: 840.7 | H14: 840.7 | I14: 840.7 | J14: 840.7 | K14: 840.7 | L14: 840.7 | N14: Pink Bean's Giant Rib
A15: DAMAGE % | B15: =INDEX($C$15:$L$15,MATCH($B$4,$C$2:$L$2,0)) | C15: 65 | D15: 65 | E15: 65 | F15: 65 | G15: 65 | H15: 65 | I15: 65 | J15: 65 | K15: 65 | L15: 65 | N15: Chalice
A16: DAMAGE_AMP % | B16: =INDEX($C$16:$L$16,MATCH($B$4,$C$2:$L$2,0)) | C16: 58 | D16: 58 | E16: 58 | F16: 58 | G16: 58 | H16: 58 | I16: 58 | J16: 58 | K16: 58 | L16: 58 | N16: Old Music Box
A17: BASIC_ATTACK_DAMAGE % | B17: =INDEX($C$17:$L$17,MATCH($B$4,$C$2:$L$2,0)) | C17: 70.8 | D17: 70.8 | E17: 70.8 | F17: 70.8 | G17: 70.8 | H17: 70.8 | I17: 70.8 | J17: 70.8 | K17: 70.8 | L17: 70.8 | N17: Silver Pendant
A18: SKILL_DAMAGE % | B18: =INDEX($C$18:$L$18,MATCH($B$4,$C$2:$L$2,0)) | C18: 24.6 | D18: 24.6 | E18: 24.6 | F18: 24.6 | G18: 24.6 | H18: 24.6 | I18: 24.6 | J18: 24.6 | K18: 24.6 | L18: 24.6 | N18: Star Rock
A19: DEF_PEN % | B19: =INDEX($C$19:$L$19,MATCH($B$4,$C$2:$L$2,0)) | C19: 324.2 | D19: 324.2 | E19: 324.2 | F19: 324.2 | G19: 324.2 | H19: 324.2 | I19: 324.2 | J19: 324.2 | K19: 324.2 | L19: 324.2 | N19: Book of Ancient
A20: BOSS_DAMAGE % | B20: =INDEX($C$20:$L$20,MATCH($B$4,$C$2:$L$2,0)) | C20: 235.2 | D20: 235.2 | E20: 235.2 | F20: 235.2 | G20: 235.2 | H20: 235.2 | I20: 235.2 | J20: 235.2 | K20: 235.2 | L20: 235.2 | N20: Lunar Dew
A21: NORMAL_DAMAGE % | B21: =INDEX($C$21:$L$21,MATCH($B$4,$C$2:$L$2,0)) | C21: 250.4 | D21: 250.4 | E21: 250.4 | F21: 250.4 | G21: 250.4 | H21: 250.4 | I21: 250.4 | J21: 250.4 | K21: 250.4 | L21: 250.4 | N21: Fire Flower
A22: MIN_DAMAGE % | B22: =INDEX($C$22:$L$22,MATCH($B$4,$C$2:$L$2,0)) | C22: 311 | D22: 311 | E22: 311 | F22: 311 | G22: 311 | H22: 311 | I22: 311 | J22: 311 | K22: 311 | L22: 311 | N22: Soul Contract
A23: MAX_DAMAGE % | B23: =INDEX($C$23:$L$23,MATCH($B$4,$C$2:$L$2,0)) | C23: 10.9 | D23: 10.9 | E23: 10.9 | F23: 10.9 | G23: 10.9 | H23: 10.9 | I23: 10.9 | J23: 10.9 | K23: 10.9 | L23: 10.9 | N23: Lit Lamp
A24: FINAL_DAMAGE % (base, excludes Into Darkness/Smokescreen) | B24: =INDEX($C$24:$L$24,MATCH($B$4,$C$2:$L$2,0)) | C24: 20 | D24: 20 | E24: 20 | F24: 20 | G24: 20 | H24: 20 | I24: 20 | J24: 20 | K24: 20 | L24: 20 | N24: Soul Pouch
A25: Skill Level Bonus — 1st Job | B25: =INDEX($C$25:$L$25,MATCH($B$4,$C$2:$L$2,0)) | C25: 20 | D25: 20 | E25: 20 | F25: 20 | G25: 20 | H25: 20 | I25: 20 | J25: 20 | K25: 20 | L25: 20 | N25: Ancient Text Piece
A26: Skill Level Bonus — 2nd Job | B26: =INDEX($C$26:$L$26,MATCH($B$4,$C$2:$L$2,0)) | C26: 27 | D26: 27 | E26: 27 | F26: 27 | G26: 27 | H26: 27 | I26: 27 | J26: 27 | K26: 27 | L26: 27 | N26: Icy Soul Rock
A27: Skill Level Bonus — 3rd Job | B27: =INDEX($C$27:$L$27,MATCH($B$4,$C$2:$L$2,0)) | C27: 67 | D27: 67 | E27: 67 | F27: 67 | G27: 67 | H27: 67 | I27: 67 | J27: 67 | K27: 67 | L27: 67 | N27: Flaming Lava
A28: Skill Level Bonus — 4th Job | B28: =INDEX($C$28:$L$28,MATCH($B$4,$C$2:$L$2,0)) | C28: 25 | D28: 25 | E28: 25 | F28: 25 | G28: 25 | H28: 25 | I28: 25 | J28: 25 | K28: 25 | L28: 25 | N28: Sayram's Necklace
A29: Skill Level Bonus — All Skills | B29: =INDEX($C$29:$L$29,MATCH($B$4,$C$2:$L$2,0)) | C29: 0 | D29: 0 | E29: 0 | F29: 0 | G29: 0 | H29: 0 | I29: 0 | J29: 0 | K29: 0 | L29: 0 | N29: Bottle of Emotion
N30: Peach Tree Herb Pouch
A31: Additional Bonuses | N31: Candle
A32: Skill Cooldown Decrease (seconds; applies to every cooldown — skills, buffs and passives) | B32: =INDEX($C$32:$L$32,MATCH($B$4,$C$2:$L$2,0)) | C32: 1 | D32: 1 | E32: 1 | F32: 1 | G32: 1 | H32: 1 | I32: 1 | J32: 1 | K32: 1 | L32: 1 | N32: Alliance Badge
A33: Basic Attack Target Increase (flat, adds to the 6-target normal-monster base) | B33: =INDEX($C$33:$L$33,MATCH($B$4,$C$2:$L$2,0)) | C33: 0 | D33: 0 | E33: 0 | F33: 0 | G33: 0 | H33: 0 | I33: 0 | J33: 0 | K33: 0 | L33: 0 | N33: Horn Flute
A34: Buff Duration Increase % | B34: =INDEX($C$34:$L$34,MATCH($B$4,$C$2:$L$2,0)) | C34: 12 | D34: 12 | E34: 12 | F34: 12 | G34: 12 | H34: 12 | I34: 12 | J34: 12 | K34: 12 | L34: 12 | N34: Cursed Doll
A35: Companion Summoning Time Increase % (companions not modeled — always 0 DPS impact) | B35: =INDEX($C$35:$L$35,MATCH($B$4,$C$2:$L$2,0)) | C35: 0 | D35: 0 | E35: 0 | F35: 0 | G35: 0 | H35: 0 | I35: 0 | J35: 0 | K35: 0 | L35: 0 | N35: Reindeer's Spear
A36: Boss/Normal Emphasis (Breakthrough/Hero Dungeon only) | B36: =INDEX($C$36:$L$36,MATCH($B$4,$C$2:$L$2,0)) | D36: A Little More Normal | J36: A Little More Normal | N36: Secret Map
A37: Max Enemies Actually In Range (normal-monster content only; default 999 = uncapped) | B37: =INDEX($C$37:$L$37,MATCH($B$4,$C$2:$L$2,0)) | D37: 999 | F37: 999 | G37: 999 | J37: 999 | L37: 999 | N37: Ring of Cycles
A38: Incoming Hit Rate (hits/sec taken — user-estimated, feeds Shadow Shifter's counterattack only) | B38: =INDEX($C$38:$L$38,MATCH($B$4,$C$2:$L$2,0)) | C38: 1 | D38: 1 | E38: 1 | F38: 1 | G38: 1 | H38: 1 | I38: 1 | J38: 1 | K38: 1 | L38: 1
A39: Monster Type (auto-computed from Content Type) — computed, do not edit | B39: =IF(Inputs!$B$4="PvP","pvp",IF(OR(Inputs!$B$4="Breakthrough",Inputs!$B$4="Hero Dungeon"),"breakthrough",IF(OR(Inputs!$B$4="EXP Dungeon",Inputs!$B$4="Equipment Dungeon",Inputs!$B$4="Chapter Hunt"),"normal","boss")))
A40: Chapter (parsed from Chapter-Stage) — computed, do not edit | B40: =IFERROR(IF(ISNUMBER(FIND("-",Inputs!$B$5)),VALUE(LEFT(Inputs!$B$5,FIND("-",Inputs!$B$5)-1)),VALUE(Inputs!$B$5)),28)
...

Sheet FactorTable
A1: Level | B1: F0 | C1: F1 | D1: F2 | E1: F3 | F1: F4 | G1: F5 | H1: F6 | I1: F7 | J1: F8 | K1: F9 | L1: F10 | M1: F11 | N1: F12 | O1: F13 | P1: F14 | Q1: F15 | R1: F16 | S1: F17 | T1: F18 | U1: F19 | V1: F20 | W1: F21 | X1: F22 | Y1: F23
A2: 1 | B2: 0 | C2: 1000 | D2: 1000 | E2: 1000 | F2: 1000 | G2: 1000 | H2: 1000 | I2: 1000 | J2: 1000 | K2: 1000 | L2: 1000 | M2: 1000 | N2: 1000 | O2: 1000 | P2: 1000 | Q2: 1000 | R2: 1000 | S2: 1000 | T2: 1000 | U2: 1000 | V2: 1000 | W2: 1000 | X2: 1000 | Y2: 1000
A3: 2 | B3: 0 | C3: 1015 | D3: 1020 | E3: 1030 | F3: 1040 | G3: 1050 | H3: 1060 | I3: 1070 | J3: 1020 | K3: 1020 | L3: 1020 | M3: 1000 | N3: 1010 | O3: 1020 | P3: 1030 | Q3: 1040 | R3: 1050 | S3: 1060 | T3: 1070 | U3: 1080 | V3: 1010 | W3: 1008 | X3: 1006 | Y3: 1100
A4: 3 | B4: 0 | C4: 1031 | D4: 1041 | E4: 1061 | F4: 1082 | G4: 1103 | H4: 1124 | I4: 1145 | J4: 1030 | K4: 1041 | L4: 1030 | M4: 1000 | N4: 1015 | O4: 1030 | P4: 1045 | Q4: 1060 | R4: 1075 | S4: 1090 | T4: 1105 | U4: 1120 | V4: 1020 | W4: 1012 | X4: 1009 | Y4: 1150
A5: 4 | B5: 0 | C5: 1047 | D5: 1062 | E5: 1093 | F5: 1126 | G5: 1159 | H5: 1192 | I5: 1226 | J5: 1040 | K5: 1062 | L5: 1040 | M5: 1000 | N5: 1020 | O5: 1040 | P5: 1060 | Q5: 1080 | R5: 1100 | S5: 1120 | T5: 1140 | U5: 1160 | V5: 1030 | W5: 1016 | X5: 1012 | Y5: 1200
A6: 5 | B6: 0 | C6: 1063 | D6: 1084 | E6: 1126 | F6: 1172 | G6: 1217 | H6: 1264 | I6: 1312 | J6: 1050 | K6: 1084 | L6: 1050 | M6: 1000 | N6: 1025 | O6: 1050 | P6: 1075 | Q6: 1100 | R6: 1125 | S6: 1150 | T6: 1175 | U6: 1200 | V6: 1040 | W6: 1020 | X6: 1015 | Y6: 1250
A7: 6 | B7: 0 | C7: 1079 | D7: 1106 | E7: 1160 | F7: 1219 | G7: 1278 | H7: 1340 | I7: 1404 | J7: 1060 | K7: 1106 | L7: 1060 | M7: 1000 | N7: 1030 | O7: 1060 | P7: 1090 | Q7: 1120 | R7: 1150 | S7: 1180 | T7: 1210 | U7: 1240 | V7: 1050 | W7: 1024 | X7: 1018 | Y7: 1300
A8: 7 | B8: 0 | C8: 1096 | D8: 1129 | E8: 1195 | F8: 1268 | G8: 1342 | H8: 1421 | I8: 1503 | J8: 1070 | K8: 1129 | L8: 1070 | M8: 1000 | N8: 1035 | O8: 1070 | P8: 1105 | Q8: 1140 | R8: 1175 | S8: 1210 | T8: 1245 | U8: 1280 | V8: 1060 | W8: 1028 | X8: 1021 | Y8: 1350
A9: 8 | B9: 0 | C9: 1113 | D9: 1152 | E9: 1231 | F9: 1319 | G9: 1410 | H9: 1507 | I9: 1609 | J9: 1080 | K9: 1152 | L9: 1080 | M9: 1000 | N9: 1040 | O9: 1080 | P9: 1120 | Q9: 1160 | R9: 1200 | S9: 1240 | T9: 1280 | U9: 1320 | V9: 1070 | W9: 1032 | X9: 1024 | Y9: 1400
A10: 9 | B10: 0 | C10: 1130 | D10: 1176 | E10: 1268 | F10: 1372 | G10: 1481 | H10: 1598 | I10: 1722 | J10: 1090 | K10: 1176 | L10: 1090 | M10: 1000 | N10: 1045 | O10: 1090 | P10: 1135 | Q10: 1180 | R10: 1225 | S10: 1270 | T10: 1315 | U10: 1360 | V10: 1080 | W10: 1036 | X10: 1027 | Y10: 1450
A11: 10 | B11: 0 | C11: 1147 | D11: 1200 | E11: 1307 | F11: 1427 | G11: 1556 | H11: 1694 | I11: 1843 | J11: 1100 | K11: 1200 | L11: 1100 | M11: 1000 | N11: 1050 | O11: 1100 | P11: 1150 | Q11: 1200 | R11: 1250 | S11: 1300 | T11: 1350 | U11: 1400 | V11: 1090 | W11: 1040 | X11: 1030 | Y11: 1500
A12: 11 | B12: 0 | C12: 1165 | D12: 1224 | E12: 1347 | F12: 1485 | G12: 1634 | H12: 1796 | I12: 1973 | J12: 1110 | K12: 1224 | L12: 1110 | M12: 1000 | N12: 1055 | O12: 1110 | P12: 1165 | Q12: 1220 | R12: 1275 | S12: 1330 | T12: 1385 | U12: 1440 | V12: 1100 | W12: 1044 | X12: 1033 | Y12: 1550
A13: 12 | B13: 0 | C13: 1183 | D13: 1249 | E13: 1388 | F13: 1545 | G13: 1716 | H13: 1904 | I13: 2112 | J13: 1120 | K13: 1249 | L13: 1120 | M13: 1000 | N13: 1060 | O13: 1120 | P13: 1180 | Q13: 1240 | R13: 1300 | S13: 1360 | T13: 1420 | U13: 1480 | V13: 1110 | W13: 1048 | X13: 1036 | Y13: 1600
... A301: 300 | B301: 0 | C301: 88573 | D301: 381637 | E301: 6991522 | F301: 125363453 | G301: 2185120762 | H301: 37157073039 | I301: 614631863830 | J301: 2000 | K301: 53326 | L301: 2500 | M301: 1100 | N301: 2500 | O301: 4000 | P301: 5500 | Q301: 7000 | R301: 8500 | S301: 10000 | T301: 11500 | U301: 13000 | V301: 7558 | W301: 2200 | X301: 1900 | Y301: 8800

Sheet Skills
A1: Key | B1: Name | C1: JobStep | D1: Cooldown(s) | E1: CostsActionSlot | F1: ActionsPerCast | G1: HitsPerCast | H1: ICD(s) | I1: ActiveWindow(s) | J1: ProcChance% | K1: RollsPerCast | L1: BaseDamage(tenths%) | M1: FactorIndex | N1: ScalesWithLevel | O1: SkillMasteryBonus% | P1: MasteryBossDamage% | Q1: MasteryNormalDamage% | R1: MasteryFinalDamage% | S1: MasteryMaxDamage% | T1: MasteryMinDamage% | U1: MasteryCooldownPct | V1: MasteryTargetIncrease | W1: NormalMonsterTargets | X1: BuffTargetStat | Y1: BuffDuration(s) | Z1: TriggersToxicVenom | AA1: MapleHeroBase(tenths%) | AB1: MapleHeroFactorIndex | AC1: Stacks | AD1: Note
A2: CRUEL_STAB | B2: Cruel Stab | C2: 4 | E2: FALSE | F2: 1 | G2: =IF(Inputs!$B$3>=136,6,5) | H2: 0 | I2: 0 | J2: 100 | K2: 1 | N2: TRUE | O2: =SUMPRODUCT((Inputs!$B$3>={102,106,116,120,128,132})*{10,11,12,13,14,15}) | P2: =SUMPRODUCT((Inputs!$B$3>={111,124})*{10,10}) | Q2: 0 | R2: 0 | S2: 0 | T2: 0 | U2: 0 | V2: 0 | W2: =6+Inputs!$B$33 | Y2: 0 | Z2: TRUE | AD2: 4th-job basic-attack effect (supersedes Double Stab/Savage Blow/Midnight Carnival). HIGH-CONFIDENCE REUSE of the universal 4th-job basic-attack constant confirmed identical across every class built so far (Showdown/Chain Lightning/Big Bang/Cruel Stab all share this exact wiki-documented 290%->522% curve) — factorIndex 21, baseDamage 2900 tenths%, matching Inputs!skill_coefficient exactly. SkillMasteryBonus% is the 6-tier 'Cruel Stab - Damage' mastery chain (102-132, cumulative totals 10%->15%, DELTA increments). MasteryBossDamage% is the 2-tier 'Cruel Stab - Boss Monster Damage' chain (111/124, +20% total). HitsPerCast 5->6 once the level-136 'Strike' mastery unlocks. Triggers Toxic Venom.
A3: STEAL | B3: Steal (self Attack%) | C3: 2 | E3: FALSE | F3: 1 | G3: 1 | H3: 0 | I3: 0 | J3: 100 | K3: 1 | L3: 50 | M3: 22 | N3: TRUE | O3: 0 | P3: 0 | Q3: 0 | R3: 0 | S3: 0 | T3: 0 | U3: 0 | V3: 0 | W3: 1 | X3: ATTACK | Y3: 0 | Z3: FALSE | AD3: Own self-Attack-buff component only (target-debuff component out of scope — not the caster's own damage). 5%->6.5% Attack per stack (levels 1-100), stacks up to 3 — modeled at steady-state max stacks (mirrors Elemental Drain's always-max-stacks convention), so this row's own contribution is 3x its own F-value, always-on once unlocked (no uptime averaging — see build_summary_sheet). factorIndex 22, baseDamage 50 tenths%. Mastery Lv.39 '+5%p activation chance' (10%->15%) has zero DPS effect under the always-max-stacks assumption (same no-op tier as Bishop's own Elemental-Reset-chance-doubling mastery). Mastery Lv.54 '+50% Attack reduction on target' is a target-debuff, out of scope.
A4: MESO_EXPLOSION | B4: Meso Explosion | C4: 3 | D4: 11 | E4: TRUE | F4: 1 | G4: 3 | H4: 0 | I4: 0 | J4: 100 | K4: 1 | L4: 2700 | M4: 12 | N4: TRUE | O4: =SUMPRODUCT((Inputs!$B$3>={90})*{100}) | P4: 0 | Q4: 0 | R4: 0 | S4: 0 | T4: 0 | U4: 0 | V4: 0 | Y4: 0 | Z4: TRUE | AD4: Resource-gated activated skill: 50% chance per attack to generate a Meso stack (max 10); own cast (this row's own 11s cooldown) deals damage to (stack count) targets. Modeled at steady state: average stack count at cast time = MIN(10, 0.5*attack_rate*cooldown), computed as a bespoke NormalMonsterTargets-equivalent formula in build_calc_sheet (left blank here, NOT a Skills-sheet literal, since it depends on the live Summary attack-rate cell) — same 'assume steady accumulation' simplification tier as Frost stacks/Elemental Drain elsewhere. factorIndex 12, baseDamage 2700 tenths% (270% level-1). SkillMasteryBonus% is Mastery Lv.90 'Meso Explosion damage +100%' (content-based — the wiki mislabels this row 'Meso Explosion - Strike', ignore the label, the description is unambiguous). Triggers Toxic Venom.
A5: MESO_MASTERY | B5: Meso Mastery (Attack buff) | C5: 3 | E5: FALSE | F5: 1 | G5: 1 | H5: 0 | I5: 0 | J5: 100 | K5: 1 | L5: 250 | M5: 0 | N5: FALSE | O5: 0 | P5: 0 | Q5: 0 | R5: 0 | S5: 0 | T5: 0 | U5: 0 | V5: 0 | W5: 1 | X5: ATTACK | Y5: 0 | Z5: FALSE | AD5: NEW (audit 2026-10-21): Lv75 passive 'Meso Mastery': Meso generation chance +25%p (50% -> 75%, applied in the Meso Explosion / Blood Money stack formulas) AND 'whenever Meso is generated, Attack +25% for 5 sec'. The 25% is modeled as a flat Attack% term in the Attack% bucket, time-averaged as a 5s buff refreshed by Meso-generation events (rate = 0.75 x attack lines/s): uptime = 1-exp(-0.75*APS*5).
A6: PHASE_DASH | B6: Phase Dash | C6: 3 | D6: 23 | E6: TRUE | F6: 1 | G6: 2 | H6: 0 | I6: 0 | J6: 100 | K6: 1 | L6: 4500 | M6: 12 | N6: TRUE | O6: =SUMPRODUCT((Inputs!$B$3>={73})*{80}) | P6: 0 | Q6: 0 | R6: 0 | S6: 0 | T6: 0 | U6: 0 | V6: 0 | W6: 9 | Y6: 0 | Z6: TRUE | AD6: 450%->... to 7 target(s) (patched Aug 13 2026 -> 9, confirmed no tick/interval mechanic exists on this skill's own wiki page to change, despite an initially-mis-paired patch-note line — see the plan's Context section), 2 hits, cooldown 23s, stun not modeled. factorIndex 12, baseDamage 4500 tenths%. Mastery Lv.73 'Phase Dash - Damage' +80% (real SkillMasteryBonus%). Triggers Toxic Venom.
A7: DARK_FLARE | B7: Dark Flare | C7: 3 | D7: =IF(Inputs!$B$3>=94,45*0.7,45) | E7: TRUE | F7: 1 | G7: =IF(Inputs!$B$3>=78,3,2) | H7: =IF(Inputs!$B$3>=104,2*0.75,2) | I7: 20 | J7: 100 | K7: 1 | L7: 3300 | M7: 12 | N7: TRUE | O7: 0 | P7: 0 | Q7: 0 | R7: 0 | S7: 0 | T7: 0 | U7: =IF(Inputs!$B$3>=94,30,0) | V7: 0 | W7: 8 | Y7: 0 | Z7: TRUE | AD7: Shared verbatim w/ Night Lord (identical wiki wording AND identical patch corrections: hit interval 5s->2s, targets 5->8, damage 400%->330%). factorIndex 12, baseDamage 3300 tenths%. Mastery Lv.104 (Shadower's own 'Dark Flare - Strike Interval', -25%, matches Night Lord's own mastery of the same name exactly) baked into the ICD(s) formula; Lv.92 -30% cooldown baked into Cooldown(s). Maple Hero (Shadower) target — see MAPLE_HERO_SHADOWER_RATIOS, NOT the generic MapleHeroBase mechanism (unlike Night Lord's own copy of this row, which uses the generic 'additional damage%' mechanism instead — the two classes' Maple Hero effects are structurally different even though the base skill is identical). Triggers Toxic Venom.
A8: SHADOW_PARTNER | B8: Shadow Partner | C8: 3 | E8: FALSE | F8: 1 | G8: 1 | H8: 0 | I8: 0 | J8: 25 | K8: 1 | L8: 600 | M8: 21 | N8: TRUE | O8: =SUMPRODUCT((Inputs!$B$3>={68})*{100}) | P8: 0 | Q8: 0 | R8: 0 | S8: 0 | T8: 0 | U8: 0 | V8: 0 | W8: 1 | Y8: 0 | Z8: FALSE | AD8: Shared verbatim w/ Night Lord. Hybrid row: Calc columns D-I computed like a normal damage row but Calc!O forced to 0 — not an independent hit; Summary reads this row's Calc!F directly and folds into the shared extra_mult chain. factorIndex 21, baseDamage 840 tenths%. ProcChance% is the real 25% proc rate. SkillMasteryBonus% is Mastery Lv.68 'Shadow Partner - Damage' +100%. Maple Hero (Shadower) target — see MAPLE_HERO_SHADOWER_RATIOS (structurally different from Night Lord's own copy, same caveat as Dark Flare above).
A9: VENOM | B9: Venom | C9: 3 | D9: 1 | E9: FALSE | F9: 1 | G9: 1 | H9: 0 | I9: 0 | J9: 100 | K9: 1 | L9: 450 | M9: 21 | N9: TRUE | O9: 0 | P9: 0 | Q9: 0 | R9: 0 | S9: 0 | T9: 0 | U9: 0 | V9: 0 | W9: 1 | Y9: 0 | Z9: FALSE | AD9: Shared verbatim w/ Night Lord (patched poison chance 30%->50%, modeled always-active at steady state — matches Night Lord's own treatment exactly, including the Cooldown=1 'always-on tick' trick). factorIndex 21, baseDamage 450 tenths% (45%->81%, levels 1-200) — reverse-engineered fresh this session and confirmed to resolve to the EXACT same tuple Night Lord already uses, cross-validating the shared-skill-reuse premise. Mastery Lv.82 Weaken (+15%p Damage Taken while poisoned, patched from 12% — matches Night Lord's own Venom - Weaken mastery exactly, confirmed via the patch note despite the wiki mastery table mislabeling this row 'Meso Explosion - Damage') is a GLOBAL always-on monster-damage-taken bonus, not a per-row Mastery column — see build_summary_sheet. Maple Hero (Shadower) target — see MAPLE_HERO_SHADOWER_RATIOS (structurally different from Night Lord's own copy, same caveat as Dark Flare above).
A10: TOXIC_VENOM | B10: Toxic Venom | C10: 4 | E10: FALSE | F10: 1 | G10: 1 | H10: 0 | I10: 0 | J10: 20 | K10: 1 | L10: 6000 | M10: 21 | N10: TRUE | O10: =SUMPRODUCT((Inputs!$B$3>={130})*{100}) | P10: 0 | Q10: 0 | R10: 0 | S10: 0 | T10: 0 | U10: 0 | V10: 0 | W10: 1 | Y10: 0 | Z10: FALSE | AD10: Shared verbatim w/ Night Lord. No ICD — every attack against a (permanently poisoned) target independently rolls the 20% chance. Trigger rate = the combined per-second hit rate of every row with TriggersToxicVenom=TRUE. factorIndex 21, baseDamage 6000 tenths% (600%->1080%, levels 1-200). SkillMasteryBonus% is Mastery Lv.130 'Toxic Venom - Damage' +100% (Shadower's own tier — same mastery name/effect as Night Lord's own Lv.128 tier, just at a different level in this class's own mastery table).
A11: INTO_DARKNESS | B11: Into Darkness | C11: 3 | D11: 40 | E11: TRUE | F11: 1 | G11: 1 | H11: 0 | I11: 0 | J11: 100 | K11: 1 | L11: 200 | M11: 21 | N11: TRUE | O11: 0 | P11: 0 | Q11: 0 | R11: 0 | S11: 0 | T11: 0 | U11: 0 | V11: 0 | W11: 1 | X11: FINAL_DAMAGE | Y11: 13 | Z11: FALSE | AD11: FLAGGED (full curve exists, but a genuinely new skill with no cross-class precedent to sanity-check against): +20%->28% Final Damage for 13s, cooldown 40s. Basic-attack-damage immunity component (defensive) not modeled. factorIndex 21, baseDamage 200 tenths%.
A12: ASSASSINATE | B12: Assassinate | C12: 4 | D12: 13 | E12: TRUE | F12: 1 | G12: 2 | H12: 0 | I12: 0 | J12: 100 | K12: 1 | L12: 14000 | M12: 12 | N12: TRUE | O12: 0 | P12: 0 | Q12: 0 | R12: 0 | S12: 0 | T12: 0 | U12: 0 | V12: 0 | W12: 1 | Y12: 0 | Z12: TRUE | AD12: 2-part damage structure: base 1400%->1680%(lvl50, curve continues) x2 hits (factorIndex 21, baseDamage 14000 tenths%), PLUS a periodic finishing blow (+3000%->3750%(lvl50) additional damage, factorIndex 12, baseDamage 30000 tenths% — see FINISHER constants below) landing on average every 2nd cast (modeled as a flat 50% average multiplier, not an exact odd/even cast counter). This row needs a BESPOKE Calc!F formula (two independent FactorTable lookups combined additively, the finisher term halved for its average-every-2nd-cast frequency) — see build_calc_sheet. Mastery Lv.108 'Murderous Intent' doubles the NEXT finishing blow after a Blood Money attack — modeled as a steady-state average multiplier on the finisher term (probability = MIN(1, Blood-Money's own cast rate / Assassinate's own finisher rate)), not an exact alternating-state machine. Mastery Lv.134 'Assassinate - Damage' +50% (real, applies to the base-hit term only, matching the wiki's own 'Assassinate damage' wording which doesn't call out the finisher specifically). Curve confidence note: the patch's own qualitative text ('base hit damage now increases more significantly with skill level') has no numeric override — using the wiki's own current curve as the best available data. Triggers Toxic Venom (a genuine independent attack, unlike Venom/Shadow Partner/Shadow Shifter's own deliberate exclusions).
A13: SUDDEN_RAID_BURST | B13: Sudden Raid (burst) | C13: 4 | D13: 19 | E13: TRUE | F13: 1 | G13: 3 | H13: 0 | I13: 0 | J13: 100 | K13: 1 | L13: 14000 | M13: 12 | N13: TRUE | O13: =SUMPRODUCT((Inputs!$B$3>={126})*{50}) | P13: 0 | Q13: 0 | R13: 0 | S13: 0 | T13: 0 | U13: 0 | V13: 0 | W13: 8 | Y13: 0 | Z13: TRUE | AD13: Shared verbatim w/ Night Lord. factorIndex 12, baseDamage 14000 tenths% (1400%->2800%, levels 1-200). Mastery Lv.126 'Sudden Raid - Damage' +50% (Shadower's own tier, at a different level than Night Lord's own Lv.124 tier for the same mastery name — each class's mastery TABLE assigns its own level to a shared base skill's mastery, confirmed not an error). Does not apply to the DoT row below.
A14: SUDDEN_RAID_DOT | B14: Sudden Raid (DoT) | C14: 4 | D14: =Skills!D13 | E14: FALSE | F14: 1 | G14: 1 | H14: 1 | I14: 5 | J14: 100 | K14: 1 | L14: 3600 | M14: 12 | N14: TRUE | O14: 0 | P14: 0 | Q14: 0 | R14: 0 | S14: 0 | T14: 0 | U14: 0 | V14: 0 | W14: 8 | Y14: 0 | Z14: TRUE | AD14: Shared verbatim w/ Night Lord. Shares Sudden Raid (burst)'s live Cooldown(s) cell. factorIndex 12, baseDamage 3600 tenths% (360%->720%, levels 1-200), 5s window / 1s ICD = 5 EffectiveHits per cast.
A15: BLOOD_MONEY | B15: Blood Money | C15: 4 | D15: =Skills!D4 | E15: FALSE | F15: 1 | G15: 3 | H15: 0 | I15: 0 | J15: 100 | K15: 1 | L15: 36000 | M15: 12 | N15: TRUE | O15: =SUMPRODUCT((Inputs!$B$3>={122,138})*{50,50}) | P15: 0 | Q15: 0 | R15: 0 | S15: 0 | T15: 0 | U15: 0 | V15: =IF(Inputs!$B$3>=138,3,IF(Inputs!$B$3>=122,2,1)) | Y15: 0 | Z15: TRUE | AD15: PATCHED (Aug 13 2026): base damage 2800%->3600% (curve rescaled 1.2857x before reverse-engineering — factorIndex 12, baseDamage 36000 tenths% already reflects the patched value), single-target +5%/stack bonus REMOVED. Triggers alongside Meso Explosion's own cast (shares its live Cooldown(s) cell, no independent cooldown) — 50% chance PER meso-generation-roll to also create a Blood Money stack (max 5), modeled at steady state: MIN(5, 0.25*attack_rate*11) (0.5 meso-chance x 0.5 blood-money-chance), a bespoke NormalMonsterTargets-equivalent formula in build_calc_sheet (left blank here, same treatment as Meso Explosion's own targets formula). MasteryTargetIncrease field repurposed here as the stack-to-targets MULTIPLIER (1x pre-122, 2x at 122, 3x at 138 — both Lv.122 and Lv.138 masteries renamed 'Damage & Target' by the patch, see the plan's Context section for the full before/after reconciliation). SkillMasteryBonus% is the combined +50%(122)+50%(138) = +100% total once both unlock. Triggers Toxic Venom.
A16: SMOKESCREEN | B16: Smokescreen | C16: 4 | D16: 45 | E16: TRUE | F16: 1 | G16: 1 | H16: 0 | I16: 0 | J16: 100 | K16: 1 | L16: 130 | M16: 22 | N16: TRUE | O16: 0 | P16: 0 | Q16: 0 | R16: 0 | S16: 0 | T16: 0 | U16: 0 | V16: 0 | W16: 1 | X16: FINAL_DAMAGE | Y16: 20 | Z16: FALSE | AD16: Enemy-debuff components (Accuracy/Evasion/Defense reduction) and ally-damage-taken-reduction not modeled (no such mechanics exist anywhere in this calculator). Self Final Damage component only: +13%->14.9%(lvl50, curve continues) for 20s, cooldown 45s. factorIndex 22, baseDamage 130 tenths% — confirmed via exact-floor curve matching (the naive mean-based resolver initially suggested 129, off by one due to this being a small-magnitude curve, same class of rounding issue flagged in this project's own memory notes for FP-Mage — resolved by checking which integer base reproduces every sampled level's value exactly under floor-to-1-decimal rounding, not just within a loose tolerance). Mastery Lv.113 'Smokescreen - Critical': -10% enemy Critical Resistance in range (not modeled) + allies' Critical Damage +30% (self-inclusive, feeds a Crit-Damage-bonus accumulator in build_summary_sheet, duty-cycle-averaged off this row's own uptime).
A17: SHADOW_SHIFTER | B17: Shadow Shifter (counterattack) | C17: 4 | E17: FALSE | F17: 1 | G17: 1 | H17: 0 | I17: 0 | J17: 100 | K17: 1 | L17: 25000 | M17: 21 | N17: TRUE | O17: 0 | P17: 0 | Q17: 0 | R17: 0 | S17: 0 | T17: 0 | U17: 0 | V17: 0 | W17: 1 | Y17: 0 | Z17: FALSE | AD17: Shared verbatim w/ Night Lord. Counterattack DPS = Inputs!incoming_hit_rate * 20% * ExpectedDamage(counterHit) — bespoke O-column branch, no Cooldown(s)/rate machinery of its own. factorIndex 21, baseDamage 25000 tenths% (2500%->4500%, levels 1-200).
A18: SHADOW_SHIFTER_SELF_ATK | B18: Shadow Shifter (self Final Damage%) | C18: 4 | E18: FALSE | F18: 1 | G18: 1 | H18: 0 | I18: 0 | J18: 100 | K18: 1 | L18: 100 | M18: 22 | N18: TRUE | O18: =SUMPRODUCT((Inputs!$B$3>={118})*{10}) | P18: 0 | Q18: 0 | R18: 0 | S18: 0 | T18: 0 | U18: 0 | V18: 0 | W18: 1 | X18: FINAL_DAMAGE | Y18: 0 | Z18: FALSE | AD18: AUDIT 2026-10-21: per the site (user decision) Shadow Shifter's passive is +10% FINAL DAMAGE (wiki said Attack); Mastery Lv118 adds +10%p. Baked-in-Inputs delta row, now feeding the Final Damage Sensitivity slot. Shared verbatim w/ Night Lord. Passive-mult delta-tracking row (10%->16% self Attack) — assumed already baked into Inputs!ATTACK_PCT (Magic Critical pattern). factorIndex 22, baseDamage 100 tenths%.
A19: MAPLE_HERO_SHADOWER | B19: Maple Hero | C19: 4 | E19: FALSE | F19: 1 | G19: 1 | H19: 0 | I19: 0 | J19: 100 | K19: 1 | L19: 150 | M19: 23 | N19: TRUE | O19: 0 | P19: 0 | Q19: 0 | R19: 0 | S19: 0 | T19: 0 | U19: 0 | V19: 0 | W19: 1 | Y19: 0 | Z19: FALSE | AD19: Shared curve feeding Dark Flare/Venom/Shadow Partner/Phase Dash's own Final Damage chains (see MAPLE_HERO_SHADOWER_RATIOS) — confirmed via reverse-engineering that all 4 target values scale proportionally across the full level range (factorIndex 23, baseDamage 150 tenths%, representing Dark Flare's own 1x share; Venom/Shadow Partner are 3.3333x, Phase Dash is 2.6667x). No independent DPS row of its own (Calc columns J-N stay blank/0, same 'no independent row' pattern as Night Lord's own Night Lord's Mark) — only D/E/F are computed, read directly by each target row's own K-column formula.
A20: NIMBLE_FEET | B20: Nimble Feet | C20: 1 | D20: 60 | E20: TRUE | F20: 1 | G20: 1 | H20: 0 | I20: 0 | J20: 100 | K20: 1 | L20: 150 | M20: 0 | N20: FALSE | O20: 0 | P20: 0 | Q20: 0 | R20: 0 | S20: 0 | T20: 0 | U20: 0 | V20: 0 | W20: 1 | X20: ATTACK_SPEED | Y20: 15 | Z20: FALSE | AD20: Shared verbatim w/ Night Lord/FP-Mage. Flat +15% Attack Speed / +10% Speed for 15s, 60s cooldown, non-scaling. FactorIndex unused placeholder.
A21: DARK_SIGHT_CRIT | B21: Dark Sight (Crit Rate) | C21: 1 | D21: 25 | E21: FALSE | F21: 1 | G21: 1 | H21: 0 | I21: 0 | J21: 100 | K21: 1 | L21: 60 | M21: 21 | N21: TRUE | O21: 0 | P21: 0 | Q21: 0 | R21: 0 | S21: 0 | T21: 0 | U21: 0 | V21: 0 | W21: 1 | X21: CRIT_RATE | Y21: =IF(Inputs!$B$3>=24,12,8) | Z21: FALSE | AD21: Shared verbatim w/ Night Lord (identical wording). Two-stage activation grants +6%->8.4% Crit Rate for 8s (->12s once Mastery Lv.24 'Dark Sight - Persistence' unlocks). factorIndex 21, baseDamage 60 tenths%. Passenger row (CostsActionSlot=False).
A22: DARK_SIGHT_ATK | B22: Dark Sight (Attack) | C22: 1 | D22: 25 | E22: TRUE | F22: 2 | G22: 1 | H22: 0 | I22: 0 | J22: 100 | K22: 1 | L22: 100 | M22: 21 | N22: TRUE | O22: 0 | P22: 0 | Q22: 0 | R22: 0 | S22: 0 | T22: 0 | U22: 0 | V22: 0 | W22: 1 | X22: ATTACK | Y22: =IF(Inputs!$B$3>=24,12,8) | Z22: FALSE | AD22: Shared verbatim w/ Night Lord. Same 2-stage activation, +10%->14% Attack for 8s (->12s at Mastery Lv.24). factorIndex 21, baseDamage 100 tenths%. ActionsPerCast=2.
A23: AGILE_DAGGERS | B23: Agile Daggers | C23: 2 | E23: FALSE | F23: 1 | G23: 1 | H23: 0 | I23: 0 | J23: 100 | K23: 1 | L23: 50 | M23: 22 | N23: TRUE | O23: 0 | P23: 0 | Q23: 0 | R23: 0 | S23: 0 | T23: 0 | U23: 0 | V23: 0 | W23: 1 | X23: ATTACK_SPEED | Y23: 0 | Z23: FALSE | AD23: HIGH-CONFIDENCE REUSE (no individual wiki page exists for this specific skill, but its level-1 text '+5% Attack Speed' is word-for-word identical to Night Lord's own Agile Claws): reuses that exact factorIndex 22/baseDamage 50 tenths% pair. Magic Critical pattern — already baked into Inputs!ATTACK_SPEED%; feeds the 2nd-Job Skill Level Bonus Sensitivity delta only.
A24: CHANNEL_KARMA | B24: Channel Karma (self Attack%) | C24: 2 | E24: FALSE | F24: 1 | G24: 1 | H24: 0 | I24: 0 | J24: 100 | K24: 1 | L24: 80 | M24: 22 | N24: TRUE | O24: 0 | P24: 0 | Q24: 0 | R24: 0 | S24: 0 | T24: 0 | U24: 0 | V24: 0 | W24: 1 | X24: ATTACK | Y24: 0 | Z24: FALSE | AD24: FLAGGED ASSUMPTION (no individual wiki page exists): factorIndex 22 (convention), baseDamage 80 tenths% (8% level-1 Attack component). Critical Resistance component not modeled (no such mechanic exists). Magic Critical pattern — already baked into Inputs!ATTACK_PCT; feeds the 2nd-Job Skill Level Bonus delta only.
A25: DAGGER_MASTERY | B25: Dagger Mastery | C25: 2 | E25: FALSE | F25: 1 | G25: 1 | H25: 0 | I25: 0 | J25: 100 | K25: 1 | L25: 150 | M25: 22 | N25: TRUE | O25: 0 | P25: 0 | Q25: 0 | R25: 0 | S25: 0 | T25: 0 | U25: 0 | V25: 0 | W25: 1 | X25: MIN_DAMAGE | Y25: 0 | Z25: FALSE | AD25: Magic Critical pattern — already baked into Inputs!MIN_DAMAGE%; feeds the 2nd-Job Skill Level Bonus delta. factorIndex 22, baseDamage 150 tenths%.
A26: CRITICAL_EDGE_RATE | B26: Critical Edge (Crit Rate) | C26: 2 | E26: FALSE | F26: 1 | G26: 1 | H26: 0 | I26: 0 | J26: 100 | K26: 1 | L26: 60 | M26: 22 | N26: TRUE | O26: 0 | P26: 0 | Q26: 0 | R26: 0 | S26: 0 | T26: 0 | U26: 0 | V26: 0 | W26: 1 | X26: CRIT_RATE | Y26: 0 | Z26: FALSE | AD26: Magic Critical pattern — already baked into Inputs!CRIT_RATE%; feeds the 2nd-Job Skill Level Bonus delta. factorIndex 22, baseDamage 60 tenths%.
A27: CRITICAL_EDGE_DMG | B27: Critical Edge (Crit Damage) | C27: 2 | E27: FALSE | F27: 1 | G27: 1 | H27: 0 | I27: 0 | J27: 100 | K27: 1 | L27: 100 | M27: 22 | N27: TRUE | O27: 0 | P27: 0 | Q27: 0 | R27: 0 | S27: 0 | T27: 0 | U27: 0 | V27: 0 | W27: 1 | X27: CRIT_DAMAGE | Y27: 0 | Z27: FALSE | AD27: Same skill as Critical Edge (Crit Rate) above. Magic Critical pattern — already baked into Inputs!CRIT_DAMAGE%; feeds the 2nd-Job Skill Level Bonus delta. factorIndex 22, baseDamage 100 tenths%.
A28: PHYSICAL_TRAINING | B28: Physical Training | C28: 2 | E28: FALSE | F28: 1 | G28: 1 | H28: 0 | I28: 0 | J28: 100 | K28: 1 | L28: 100 | M28: 22 | N28: TRUE | O28: 0 | P28: 0 | Q28: 0 | R28: 0 | S28: 0 | T28: 0 | U28: 0 | V28: 0 | W28: 1 | X28: BASIC_ATTACK_DAMAGE | Y28: 0 | Z28: FALSE | AD28: Magic Critical pattern — already baked into Inputs!BASIC_ATTACK_DAMAGE%; feeds the 2nd-Job Skill Level Bonus delta. factorIndex 22, baseDamage 100 tenths%.
A29: DAGGER_EXPERT_SKILL | B29: Dagger Expert (Skill Damage) | C29: 4 | E29: FALSE | F29: 1 | G29: 1 | H29: 0 | I29: 0 | J29: 100 | K29: 1 | L29: 150 | M29: 22 | N29: TRUE | O29: 0 | P29: 0 | Q29: 0 | R29: 0 | S29: 0 | T29: 0 | U29: 0 | V29: 0 | W29: 1 | X29: SKILL_DAMAGE | Y29: 0 | Z29: FALSE | AD29: Magic Critical pattern — already baked into Inputs!SKILL_DAMAGE%; feeds the 4th-Job Skill Level Bonus delta (Skill Damage side). factorIndex 22, baseDamage 150 tenths%.
A30: DAGGER_EXPERT_MAXDMG | B30: Dagger Expert (Max Damage Multiplier) | C30: 4 | E30: FALSE | F30: 1 | G30: 1 | H30: 0 | I30: 0 | J30: 100 | K30: 1 | L30: 200 | M30: 22 | N30: TRUE | O30: 0 | P30: 0 | Q30: 0 | R30: 0 | S30: 0 | T30: 0 | U30: 0 | V30: 0 | W30: 1 | X30: MAX_DAMAGE | Y30: 0 | Z30: FALSE | AD30: Same skill as Dagger Expert (Skill Damage) above, +20%->23% Max Damage Multiplier. Magic Critical pattern — already baked into Inputs!MAX_DAMAGE%; feeds the 4th-Job Skill Level Bonus delta (Max Damage Multiplier side). factorIndex 22, baseDamage 200 tenths%.
A31: SHADOWER_INSTINCT | B31: Shadower Instinct | C31: 4 | E31: FALSE | F31: 1 | G31: 1 | H31: 0 | I31: 0 | J31: 100 | K31: 1 | L31: 200 | M31: 22 | N31: TRUE | O31: 0 | P31: 0 | Q31: 0 | R31: 0 | S31: 0 | T31: 0 | U31: 0 | V31: 0 | W31: 1 | X31: FINAL_DAMAGE | Y31: 0 | Z31: FALSE | AD31: Magic Critical pattern — already baked into Inputs!FINAL_DAMAGE%; feeds the 4th-Job Skill Level Bonus delta. factorIndex 22, baseDamage 200 tenths%.

Sheet Artifacts
A1: Shadower — Artifacts (Equip Effect)
A3: Book of Ancient — Crit Damage (from Crit Rate, reference only) | B3: =IF(ArtifactsInput!$M$24,CHOOSE(ArtifactsInput!$N$24+1,30,36,42,48,54,60)/100*(Inputs!$B$9+Summary!$B$14+B5+B29),0)
A4: Ring of Cycles — Threshold Crit Rate (excl. self) | B4: =Inputs!$B$9+Summary!$B$14+B29
A5: Ring of Cycles — Crit Rate (if threshold < 100%) | B5: =IF(AND(Inputs!$B$39<>"pvp",Inputs!$B$44=0),1,IF(IF(Inputs!$B$39="pvp",15,Inputs!$B$44)-(Summary!$B$26)<=0,1,MAX(0,IF(Inputs!$B$39="pvp",15,Inputs!$B$44)-MAX(5,Summary!$B$26))/(IF(Inputs!$B$39="pvp",15,Inputs!$B$44)-(Summary!$B$26))))*IF(AND(ArtifactsInput!$M$42,B4<100),CHOOSE(ArtifactsInput!$N$42+1,30,36,42,48,54,60),0)
A6: Ring of Cycles — Skill Damage (if threshold >= 100%) | B6: =IF(AND(Inputs!$B$39<>"pvp",Inputs!$B$44=0),1,IF(IF(Inputs!$B$39="pvp",15,Inputs!$B$44)-(Summary!$B$26)<=0,1,MAX(0,IF(Inputs!$B$39="pvp",15,Inputs!$B$44)-MAX(5,Summary!$B$26))/(IF(Inputs!$B$39="pvp",15,Inputs!$B$44)-(Summary!$B$26))))*IF(AND(ArtifactsInput!$M$42,B4>=100),CHOOSE(ArtifactsInput!$N$42+1,40,48,56,64,72,80),0)
A7: Ring of Cycles — Excess-100% Points (capped at 100) | B7: =IF(AND(ArtifactsInput!$M$42,B4>=100),MIN(100,B4-100),0)
A8: Ring of Cycles — Basic Attack Damage (excess points x per-point) | B8: =IF(AND(Inputs!$B$39<>"pvp",Inputs!$B$44=0),1,IF(IF(Inputs!$B$39="pvp",15,Inputs!$B$44)-(Summary!$B$26)<=0,1,MAX(0,IF(Inputs!$B$39="pvp",15,Inputs!$B$44)-MAX(5,Summary!$B$26))/(IF(Inputs!$B$39="pvp",15,Inputs!$B$44)-(Summary!$B$26))))*B7*CHOOSE(ArtifactsInput!$N$42+1,0.6,0.72,0.84,0.96,1.08,1.2)
A9: Candle — Effective Fight Duration | B9: =IF(Inputs!$B$39="pvp",15,Inputs!$B$44)
A10: Candle — Effective Active (fixed-duration or PvP) | B10: =IF(Inputs!$B$39="pvp",TRUE,AND(Inputs!$B$39<>"pvp",Inputs!$B$44>0))
A11: Candle — Final Damage (100% uptime, patched) | B11: =IF(AND(ArtifactsInput!$M$36,B10),CHOOSE(ArtifactsInput!$N$36+1,8,9.6,11.2,12.8,14.4,16),0)
A12: Candle — Boss Monster Damage (20-40s window / boss-present-time uptime, patched) | B12: =IF(AND(ArtifactsInput!$M$36,B10),MAX(0,MIN(40,B9)-MAX(20,B41))/(B9-B41)*CHOOSE(ArtifactsInput!$N$36+1,30,36,42,48,54,60),0)
A13: Peach Tree Herb Pouch — Proc Rate (per second) | B13: =0.2*Summary!$B$18
A14: Peach Tree Herb Pouch — Uptime (refreshing 5s timer) | B14: =1-EXP(-B13*5)
A15: Peach Tree Herb Pouch — Enemy Damage Taken | B15: =IF(AND(ArtifactsInput!$M$35,Inputs!$B$4<>"Chapter Hunt"),CHOOSE(ArtifactsInput!$N$35+1,15,18,21,24,27,30)*B14,0)
A16: Silver Pendant — Offered Load (rho = lambda x duration) | B16: =0.15*Summary!$B$18*5
A17: Silver Pendant — Erlang Loss Weight (n=0) | B17: =B16^0/1
A18: Silver Pendant — Erlang Loss Weight (n=1) | B18: =B16^1/1
A19: Silver Pendant — Erlang Loss Weight (n=2) | B19: =B16^2/2
A20: Silver Pendant — Erlang Loss Weight (n=3) | B20: =B16^3/6
A21: Silver Pendant — Erlang Loss Weight (n=4) | B21: =B16^4/24
A22: Silver Pendant — Erlang Loss Weight (n=5) | B22: =B16^5/120
A23: Silver Pendant — Average Stacks (Erlang-loss mean) | B23: =(0*B17+1*B18+2*B19+3*B20+4*B21+5*B22)/(B17+B18+B19+B20+B21+B22)
A24: Silver Pendant — Enemy Damage Taken | B24: =IF(AND(ArtifactsInput!$M$22,Inputs!$B$4<>"Chapter Hunt"),CHOOSE(ArtifactsInput!$N$22+1,10,12,14,16,18,20)*B23,0)
A25: Athena Pierce's Old Gloves — Max Damage (from Attack Speed, reference only) | B25: =IF(ArtifactsInput!$M$15,CHOOSE(ArtifactsInput!$N$15+1,25,30,35,40,45,50)/100*Inputs!$B$11,0)
A26: Hexagon Necklace — Average Stacks | B26: =IF(AND(Inputs!$B$39<>"pvp",Inputs!$B$44=0),3,IF(IF(Inputs!$B$39="pvp",15,Inputs!$B$44)<=20,0,IF(IF(Inputs!$B$39="pvp",15,Inputs!$B$44)<=40,(IF(Inputs!$B$39="pvp",15,Inputs!$B$44)-20)/IF(Inputs!$B$39="pvp",15,Inputs!$B$44),IF(IF(Inputs!$B$39="pvp",15,Inputs!$B$44)<=60,(2*IF(Inputs!$B$39="pvp",15,Inputs!$B$44)-60)/IF(Inputs!$B$39="pvp",15,Inputs!$B$44),(3*IF(Inputs!$B$39="pvp",15,Inputs!$B$44)-120)/IF(Inputs!$B$39="pvp",15,Inputs!$B$44)))))
A27: Hexagon Necklace — Damage % | B27: =IF(ArtifactsInput!$M$11,CHOOSE(ArtifactsInput!$N$11+1,15,18,21,24,27,30)*B26,0)
A28: Rainbow-colored Snail Shell — Uptime (0-15s window) | B28: =IF(Inputs!$B$39="pvp",MIN(15,15)/15,IF(AND(Inputs!$B$39<>"pvp",Inputs!$B$44>0),MIN(15,Inputs!$B$44)/Inputs!$B$44,0))
A29: Rainbow-colored Snail Shell — Crit Rate | B29: =IF(ArtifactsInput!$M$10,CHOOSE(ArtifactsInput!$N$10+1,15,18,21,24,27,30)*B28,0)
A30: Rainbow-colored Snail Shell — Crit Damage | B30: =IF(ArtifactsInput!$M$10,CHOOSE(ArtifactsInput!$N$10+1,20,24,28,32,36,40)*B28,0)
A32: TOTAL — Artifact Crit Rate Bonus | B32: =B5+B29
A33: TOTAL — Artifact Crit Damage Bonus | B33: =B30+B47
A34: TOTAL — Artifact Final Damage Bonus (equivalent %, each real source combines MULTIPLICATIVELY — Candle x Flaming Lava x Horn Flute, not summed) | B34: =((1+B11/100)*(1+B46/100)*(1+B55/100)-1)*100
A35: TOTAL — Artifact Boss Monster Damage Bonus | B35: =B12+B60
A36: TOTAL — Artifact Enemy Damage Taken Bonus | B36: =B15+B24
A38: TOTAL — Artifact Damage Bonus (own separate final multiplier, like Magic Guard/Meditation's Average Buff Multiplier — not blended into Inputs!DAMAGE%) | B38: =B27
A39: TOTAL — Artifact Skill Damage Bonus | B39: =B6
A40: TOTAL — Artifact Basic Attack Damage Bonus | B40: =B8
A41: Candle — Boss Appear Time (Breakthrough/Hero Dungeon only) | B41: =IF(Inputs!$B$4="Breakthrough",20,IF(Inputs!$B$4="Hero Dungeon",30,0))
A42: Clear Spring Water — Final Damage (reference only, Growth Dungeon types) | B42: =IF(AND(ArtifactsInput!$M$14,OR(Inputs!$B$4="Weapon Dungeon",Inputs!$B$4="Equipment Dungeon",Inputs!$B$4="Enhancement Dungeon",Inputs!$B$4="EXP Dungeon",Inputs!$B$4="Hero Dungeon")),CHOOSE(ArtifactsInput!$N$14+1,10,12,14,16,18,20),0)
A43: Old Music Box — Attack % (content-type uptime assumption) | B43: =IF(ArtifactsInput!$M$21,CHOOSE(ArtifactsInput!$N$21+1,25,30,35,40,45,50)*(IF(OR(Inputs!$B$4="Chapter Hunt",Inputs!$B$4="Breakthrough",Inputs!$B$4="Weapon Dungeon",Inputs!$B$4="Equipment Dungeon",Inputs!$B$4="Enhancement Dungeon",Inputs!$B$4="EXP Dungeon",Inputs!$B$4="Hero Dungeon"),0,IF(OR(Inputs!$B$4="World Boss",Inputs!$B$4="PvP"),1,IF(Inputs!$B$4="Chapter Boss",60/70,0)))),0)
...

Sheet Calc
A1: Key | B1: Name | C1: Unlocked | D1: InputLevel | E1: Factor | F1: CoefficientPercent | G1: EffectiveHits | H1: ProcProbability | I1: MapleHeroMultiplier | J1: BaseDamage | K1: BaseHitDamage | L1: NonCritAvg | M1: CritAvg | N1: ExpectedDamage(perHit) | O1: DPS | P1: % of Total | Q1: InvCooldown | R1: CastsInFight | S1: HitRate(perSec) | T1: BossOnlyDPS | U1: Maple Hero (Shadower) helper — unused (see MAPLE_HERO_SHADOWER row's own Note) | V1: NormalOnlyDPS
A2: =Skills!A2 | B2: =Skills!B2 | C2: =Inputs!$B$3>=100 | F2: =Summary!$B$10+Skills!O2 | G2: =Skills!G2*IF(Skills!H2>0,IF(Inputs!$B$39="pvp",MIN(Skills!I2,15),Skills!I2)/Skills!H2,1) | H2: =1-(1-Skills!J2/100)^Skills!K2 | I2: 1 | J2: =Summary!$B$6*(F2/100) | K2: =J2*(1+Summary!$B$7/100)*(1+Inputs!$B$15/100)*(1+Inputs!$B$16/100)*(5000/(6000+Inputs!$B$43*(1-Inputs!$B$19/100)))*(1+Inputs!$B$24/100)*(1+Artifacts!$B$34/100)*(1+(IF(Skills!A2="CRUEL_STAB",Inputs!$B$17+Artifacts!$B$40,Inputs!$B$18+Artifacts!$B$39))/100)*(Summary!$B$13*Summary!$B$16*(1+Artifacts!$B$38/100)*I2) | L2: =K2*(MIN(Inputs!$B$22,Inputs!$B$23)/100+Inputs!$B$23/100)/2 | M2: =L2*(1+(Inputs!$B$10+Summary!$B$21+Artifacts!$B$33)/100) | N2: =L2*(1-MIN((Inputs!$B$9+Summary!$B$14+Artifacts!$B$32),100)/100)+M2*(MIN((Inputs!$B$9+Summary!$B$14+Artifacts!$B$32),100)/100) | O2: =(1-Summary!$B$11)*T2+Summary!$B$11*V2 | P2: =IF(Summary!$B$3=0,0,O2/Summary!$B$3) | Q2: 0 | R2: 0 | S2: =IFERROR(O2/N2,0) | T2: =IF(C2,(Skills!G2*N2*Summary!$B$20)*IF(Inputs!$B$39="pvp",1,1+(Inputs!$B$20+Skills!P2+Summary!$B$15+Artifacts!$B$35)/100)*((((5000/(6000+Inputs!$B$43*(1-(100*(1-(1-Inputs!$B$19/100)*(1-Artifacts!$B$51/100)^IF(Inputs!$B$39="pvp",1,2)))/100)))/(5000/(6000+Inputs!$B$43*(1-Inputs!$B$19/100))))*((L2*(1-MIN(100,(Inputs!$B$9+Summary!$B$14+Artifacts!$B$32)+Artifacts!$B$69)/100)+M2*(MIN(100,(Inputs!$B$9+Summary!$B$14+Artifacts!$B$32)+Artifacts!$B$69)/100))/(L2*(1-MIN(100,(Inputs!$B$9+Summary!$B$14+Artifacts!$B$32))/100)+M2*(MIN(100,(Inputs!$B$9+Summary!$B$14+Artifacts!$B$32))/100)))*(1+Artifacts!$B$81/100))),0) | V2: =IF(C2,(Skills!G2*N2*Summary!$B$20)*IF(Inputs!$B$39="pvp",1,(1+(Inputs!$B$21+Skills!Q2+Summary!$B$15+Artifacts!$B$80)/100)*(MIN(Skills!W2,Inputs!$B$37)))*((1+Artifacts!$B$53/100)),0)
A3: =Skills!A3 | B3: =Skills!B3 | C3: =Inputs!$B$3>=35 | D3: =IF(Skills!C3=1,60+Inputs!$B$25+Inputs!$B$29,IF(Skills!C3=2,90+Inputs!$B$26+Inputs!$B$29,IF(Skills!C3=3,120+Inputs!$B$27+Inputs!$B$29,MAX(0,(Inputs!$B$3-100)*3)+Inputs!$B$28+Inputs!$B$29))) | E3: =INDEX(FactorTable!$B$2:$Y$301, MATCH(ROUND(MIN(300,MAX(1,D3)),0), FactorTable!$A$2:$A$301,0), Skills!M3+1) | F3: =IF(Skills!N3=TRUE,(Skills!L3/10)*(E3/1000),Skills!L3/10)+Skills!O3 | G3: =Skills!G3*IF(Skills!H3>0,IF(Inputs!$B$39="pvp",MIN(Skills!I3,15),Skills!I3)/Skills!H3,1) | H3: =1-(1-Skills!J3/100)^Skills!K3 | I3: 1 | O3: =(1-Summary!$B$11)*T3+Summary!$B$11*V3 | P3: =IF(Summary!$B$3=0,0,O3/Summary!$B$3) | Q3: 0 | R3: 0 | S3: =IFERROR(O3/N3,0) | T3: 0 | V3: 0
A4: =Skills!A4 | B4: =Skills!B4 | C4: =Inputs!$B$3>=66 | D4: =IF(Skills!C4=1,60+Inputs!$B$25+Inputs!$B$29,IF(Skills!C4=2,90+Inputs!$B$26+Inputs!$B$29,IF(Skills!C4=3,120+Inputs!$B$27+Inputs!$B$29,MAX(0,(Inputs!$B$3-100)*3)+Inputs!$B$28+Inputs!$B$29))) | E4: =INDEX(FactorTable!$B$2:$Y$301, MATCH(ROUND(MIN(300,MAX(1,D4)),0), FactorTable!$A$2:$A$301,0), Skills!M4+1) | F4: =IF(Skills!N4=TRUE,(Skills!L4/10)*(E4/1000),Skills!L4/10)+Skills!O4 | G4: =Skills!G4*IF(Skills!H4>0,IF(Inputs!$B$39="pvp",MIN(Skills!I4,15),Skills!I4)/Skills!H4,1) | H4: =1-(1-Skills!J4/100)^Skills!K4 | I4: 1 | J4: =Summary!$B$6*(F4/100) | K4: =J4*(1+Summary!$B$7/100)*(1+Inputs!$B$15/100)*(1+Inputs!$B$16/100)*(5000/(6000+Inputs!$B$43*(1-Inputs!$B$19/100)))*(1+Inputs!$B$24/100)*(1+Artifacts!$B$34/100)*(1+(IF(Skills!A4="CRUEL_STAB",Inputs!$B$17+Artifacts!$B$40,Inputs!$B$18+Artifacts!$B$39))/100)*(Summary!$B$13*Summary!$B$16*(1+Artifacts!$B$38/100)*I4) | L4: =K4*(MIN(Inputs!$B$22,Inputs!$B$23)/100+Inputs!$B$23/100)/2 | M4: =L4*(1+(Inputs!$B$10+Summary!$B$21+Artifacts!$B$33)/100) | N4: =L4*(1-MIN((Inputs!$B$9+Summary!$B$14+Artifacts!$B$32),100)/100)+M4*(MIN((Inputs!$B$9+Summary!$B$14+Artifacts!$B$32),100)/100) | O4: =(1-Summary!$B$11)*T4+Summary!$B$11*V4 | P4: =IF(Summary!$B$3=0,0,O4/Summary!$B$3) | Q4: =IFERROR(1/IF(Inputs!$B$39="pvp",15,MAX(0.1,Skills!D4-IF(TRUE=TRUE,Inputs!$B$32,0))),0) | R4: =IF(AND(Inputs!$B$39<>"pvp",Inputs!$B$44>0),IF(MAX(0,Inputs!$B$44-Summary!$B$26)<=0,0,(INT(MAX(0,Inputs!$B$44-Summary!$B$26)/IF(Inputs!$B$39="pvp",15,MAX(0.1,Skills!D4-IF(TRUE=TRUE,Inputs!$B$32,0))))+1)),0) | S4: =IFERROR(O4/N4,0) | T4: =IF(C4,(H4*N4*IF(AND(Inputs!$B$39<>"pvp",Inputs!$B$44>0),((Skills!G4*((R4-1)*IF(Skills!H4>0,Skills!I4/Skills!H4,1)+IF(Skills!H4>0,MIN(Skills!I4,MAX(0,MAX(0,Inputs!$B$44-Summary!$B$26)-((R4-1)*IF(Inputs!$B$39="pvp",15,MAX(0.1,Skills!D4-IF(TRUE=TRUE,Inputs!$B$32,0))))))/Skills!H4,1)))/Inputs!$B$44),G4*Q4))*IF(Inputs!$B$39="pvp",1,1+(Inputs!$B$20+Skills!P4+Summary!$B$15+Artifacts!$B$35)/100)*((((5000/(6000+Inputs!$B$43*(1-(100*(1-(1-Inputs!$B$19/100)*(1-Artifacts!$B$51/100)^IF(Inputs!$B$39="pvp",1,2)))/100)))/(5000/(6000+Inputs!$B$43*(1-Inputs!$B$19/100))))*((L4*(1-MIN(100,(Inputs!$B$9+Summary!$B$14+Artifacts!$B$32)+Artifacts!$B$69)/100)+M4*(MIN(100,(Inputs!$B$9+Summary!$B$14+Artifacts!$B$32)+Artifacts!$B$69)/100))/(L4*(1-MIN(100,(Inputs!$B$9+Summary!$B$14+Artifacts!$B$32))/100)+M4*(MIN(100,(Inputs!$B$9+Summary!$B$14+Artifacts!$B$32))/100)))*(1+Artifacts!$B$81/100))),0) | V4: =IF(C4,(H4*N4*IF(AND(Inputs!$B$39<>"pvp",Inputs!$B$44>0),((Skills!G4*((R4-1)*IF(Skills!H4>0,Skills!I4/Skills!H4,1)+IF(Skills!H4>0,MIN(Skills!I4,MAX(0,MAX(0,Inputs!$B$44-Summary!$B$26)-((R4-1)*IF(Inputs!$B$39="pvp",15,MAX(0.1,Skills!D4-IF(TRUE=TRUE,Inputs!$B$32,0))))))/Skills!H4,1)))/Inputs!$B$44),G4*Q4))*IF(Inputs!$B$39="pvp",1,(1+(Inputs!$B$21+Skills!Q4+Summary!$B$15+Artifacts!$B$80)/100)*(MIN(MIN(10,IF(Inputs!$B$3>=75,0.75,0.5)*Summary!$B$18*(1/Calc!Q4)),Inputs!$B$37)))*((1+Artifacts!$B$53/100)),0)
A5: =Skills!A5 | B5: =Skills!B5 | C5: =Inputs!$B$3>=75 | D5: =IF(Skills!C5=1,60+Inputs!$B$25+Inputs!$B$29,IF(Skills!C5=2,90+Inputs!$B$26+Inputs!$B$29,IF(Skills!C5=3,120+Inputs!$B$27+Inputs!$B$29,MAX(0,(Inputs!$B$3-100)*3)+Inputs!$B$28+Inputs!$B$29))) | E5: =INDEX(FactorTable!$B$2:$Y$301, MATCH(ROUND(MIN(300,MAX(1,D5)),0), FactorTable!$A$2:$A$301,0), Skills!M5+1) | F5: =IF(Skills!N5=TRUE,(Skills!L5/10)*(E5/1000),Skills!L5/10)+Skills!O5 | G5: =Skills!G5*IF(Skills!H5>0,IF(Inputs!$B$39="pvp",MIN(Skills!I5,15),Skills!I5)/Skills!H5,1) | H5: =1-(1-Skills!J5/100)^Skills!K5 | I5: 1 | O5: =(1-Summary!$B$11)*T5+Summary!$B$11*V5 | P5: =IF(Summary!$B$3=0,0,O5/Summary!$B$3) | Q5: 0 | R5: 0 | S5: =IFERROR(O5/N5,0) | T5: 0 | V5: 0
A6: =Skills!A6 | B6: =Skills!B6 | C6: =Inputs!$B$3>=63 | D6: =IF(Skills!C6=1,60+Inputs!$B$25+Inputs!$B$29,IF(Skills!C6=2,90+Inputs!$B$26+Inputs!$B$29,IF(Skills!C6=3,120+Inputs!$B$27+Inputs!$B$29,MAX(0,(Inputs!$B$3-100)*3)+Inputs!$B$28+Inputs!$B$29))) | E6: =INDEX(FactorTable!$B$2:$Y$301, MATCH(ROUND(MIN(300,MAX(1,D6)),0), FactorTable!$A$2:$A$301,0), Skills!M6+1) | F6: =IF(Skills!N6=TRUE,(Skills!L6/10)*(E6/1000),Skills!L6/10)+Skills!O6 | G6: =Skills!G6*IF(Skills!H6>0,IF(Inputs!$B$39="pvp",MIN(Skills!I6,15),Skills!I6)/Skills!H6,1) | H6: =1-(1-Skills!J6/100)^Skills!K6 | I6: 1 | J6: =Summary!$B$6*(F6/100) | K6: =J6*(1+Summary!$B$7/100)*(1+Inputs!$B$15/100)*(1+Inputs!$B$16/100)*(5000/(6000+Inputs!$B$43*(1-Inputs!$B$19/100)))*(1+Inputs!$B$24/100)*(1+Artifacts!$B$34/100)*(1+2.6666666666666665*IF(C19=TRUE,F19,0)/100)*(1+(IF(Skills!A6="CRUEL_STAB",Inputs!$B$17+Artifacts!$B$40,Inputs!$B$18+Artifacts!$B$39))/100)*(Summary!$B$13*Summary!$B$16*(1+Artifacts!$B$38/100)*I6) | L6: =K6*(MIN(Inputs!$B$22,Inputs!$B$23)/100+Inputs!$B$23/100)/2 | M6: =L6*(1+(Inputs!$B$10+Summary!$B$21+Artifacts!$B$33)/100) | N6: =L6*(1-MIN((Inputs!$B$9+Summary!$B$14+Artifacts!$B$32),100)/100)+M6*(MIN((Inputs!$B$9+Summary!$B$14+Artifacts!$B$32),100)/100) | O6: =(1-Summary!$B$11)*T6+Summary!$B$11*V6 | P6: =IF(Summary!$B$3=0,0,O6/Summary!$B$3) | Q6: =IFERROR(1/IF(Inputs!$B$39="pvp",15,MAX(0.1,Skills!D6-IF(TRUE=TRUE,Inputs!$B$32,0))),0) | R6: =IF(AND(Inputs!$B$39<>"pvp",Inputs!$B$44>0),IF(MAX(0,Inputs!$B$44-Summary!$B$26)<=0,0,(INT(MAX(0,Inputs!$B$44-Summary!$B$26)/IF(Inputs!$B$39="pvp",15,MAX(0.1,Skills!D6-IF(TRUE=TRUE,Inputs!$B$32,0))))+1)),0) | S6: =IFERROR(O6/N6,0) | T6: =IF(C6,(H6*N6*IF(AND(Inputs!$B$39<>"pvp",Inputs!$B$44>0),((Skills!G6*((R6-1)*IF(Skills!H6>0,Skills!I6/Skills!H6,1)+IF(Skills!H6>0,MIN(Skills!I6,MAX(0,MAX(0,Inputs!$B$44-Summary!$B$26)-((R6-1)*IF(Inputs!$B$39="pvp",15,MAX(0.1,Skills!D6-IF(TRUE=TRUE,Inputs!$B$32,0))))))/Skills!H6,1)))/Inputs!$B$44),G6*Q6))*IF(Inputs!$B$39="pvp",1,1+(Inputs!$B$20+Skills!P6+Summary!$B$15+Artifacts!$B$35)/100)*((((5000/(6000+Inputs!$B$43*(1-(100*(1-(1-Inputs!$B$19/100)*(1-Artifacts!$B$51/100)^IF(Inputs!$B$39="pvp",1,2)))/100)))/(5000/(6000+Inputs!$B$43*(1-Inputs!$B$19/100))))*((L6*(1-MIN(100,(Inputs!$B$9+Summary!$B$14+Artifacts!$B$32)+Artifacts!$B$69)/100)+M6*(MIN(100,(Inputs!$B$9+Summary!$B$14+Artifacts!$B$32)+Artifacts!$B$69)/100))/(L6*(1-MIN(100,(Inputs!$B$9+Summary!$B$14+Artifacts!$B$32))/100)+M6*(MIN(100,(Inputs!$B$9+Summary!$B$14+Artifacts!$B$32))/100)))*(1+Artifacts!$B$81/100))),0) | V6: =IF(C6,(H6*N6*IF(AND(Inputs!$B$39<>"pvp",Inputs!$B$44>0),((Skills!G6*((R6-1)*IF(Skills!H6>0,Skills!I6/Skills!H6,1)+IF(Skills!H6>0,MIN(Skills!I6,MAX(0,MAX(0,Inputs!$B$44-Summary!$B$26)-((R6-1)*IF(Inputs!$B$39="pvp",15,MAX(0.1,Skills!D6-IF(TRUE=TRUE,Inputs!$B$32,0))))))/Skills!H6,1)))/Inputs!$B$44),G6*Q6))*IF(Inputs!$B$39="pvp",1,(1+(Inputs!$B$21+Skills!Q6+Summary!$B$15+Artifacts!$B$80)/100)*(MIN(Skills!W6,Inputs!$B$37)))*((1+Artifacts!$B$53/100)),0)
A7: =Skills!A7 | B7: =Skills!B7 | C7: =Inputs!$B$3>=69 | D7: =IF(Skills!C7=1,60+Inputs!$B$25+Inputs!$B$29,IF(Skills!C7=2,90+Inputs!$B$26+Inputs!$B$29,IF(Skills!C7=3,120+Inputs!$B$27+Inputs!$B$29,MAX(0,(Inputs!$B$3-100)*3)+Inputs!$B$28+Inputs!$B$29))) | E7: =INDEX(FactorTable!$B$2:$Y$301, MATCH(ROUND(MIN(300,MAX(1,D7)),0), FactorTable!$A$2:$A$301,0), Skills!M7+1) | F7: =IF(Skills!N7=TRUE,(Skills!L7/10)*(E7/1000),Skills!L7/10)+Skills!O7 | G7: =Skills!G7*IF(Skills!H7>0,IF(Inputs!$B$39="pvp",MIN(Skills!I7,15),Skills!I7)/Skills!H7,1) | H7: =1-(1-Skills!J7/100)^Skills!K7 | I7: 1 | J7: =Summary!$B$6*(F7/100) | K7: =J7*(1+Summary!$B$7/100)*(1+Inputs!$B$15/100)*(1+Inputs!$B$16/100)*(5000/(6000+Inputs!$B$43*(1-Inputs!$B$19/100)))*(1+Inputs!$B$24/100)*(1+Artifacts!$B$34/100)*(1+1.0*IF(C19=TRUE,F19,0)/100)*(1+(IF(Skills!A7="CRUEL_STAB",Inputs!$B$17+Artifacts!$B$40,Inputs!$B$18+Artifacts!$B$39))/100)*(Summary!$B$13*Summary!$B$16*(1+Artifacts!$B$38/100)*I7) | L7: =K7*(MIN(Inputs!$B$22,Inputs!$B$23)/100+Inputs!$B$23/100)/2 | M7: =L7*(1+(Inputs!$B$10+Summary!$B$21+Artifacts!$B$33)/100) | N7: =L7*(1-MIN((Inputs!$B$9+Summary!$B$14+Artifacts!$B$32),100)/100)+M7*(MIN((Inputs!$B$9+Summary!$B$14+Artifacts!$B$32),100)/100) | O7: =(1-Summary!$B$11)*T7+Summary!$B$11*V7 | P7: =IF(Summary!$B$3=0,0,O7/Summary!$B$3) | Q7: =IFERROR(1/IF(Inputs!$B$39="pvp",15,MAX(0.1,Skills!D7-IF(TRUE=TRUE,Inputs!$B$32,0))),0) | R7: =IF(AND(Inputs!$B$39<>"pvp",Inputs!$B$44>0),IF(MAX(0,Inputs!$B$44-Summary!$B$26)<=0,0,(INT(MAX(0,Inputs!$B$44-Summary!$B$26)/IF(Inputs!$B$39="pvp",15,MAX(0.1,Skills!D7-IF(TRUE=TRUE,Inputs!$B$32,0))))+1)),0) | S7: =IFERROR(O7/N7,0) | T7: =IF(C7,(H7*N7*IF(AND(Inputs!$B$39<>"pvp",Inputs!$B$44>0),((Skills!G7*((R7-1)*IF(Skills!H7>0,Skills!I7/Skills!H7,1)+IF(Skills!H7>0,MIN(Skills!I7,MAX(0,MAX(0,Inputs!$B$44-Summary!$B$26)-((R7-1)*IF(Inputs!$B$39="pvp",15,MAX(0.1,Skills!D7-IF(TRUE=TRUE,Inputs!$B$32,0))))))/Skills!H7,1)))/Inputs!$B$44),G7*Q7))*IF(Inputs!$B$39="pvp",1,1+(Inputs!$B$20+Skills!P7+Summary!$B$15+Artifacts!$B$35)/100)*((((5000/(6000+Inputs!$B$43*(1-(100*(1-(1-Inputs!$B$19/100)*(1-Artifacts!$B$51/100)^IF(Inputs!$B$39="pvp",1,2)))/100)))/(5000/(6000+Inputs!$B$43*(1-Inputs!$B$19/100))))*((L7*(1-MIN(100,(Inputs!$B$9+Summary!$B$14+Artifacts!$B$32)+Artifacts!$B$69)/100)+M7*(MIN(100,(Inputs!$B$9+Summary!$B$14+Artifacts!$B$32)+Artifacts!$B$69)/100))/(L7*(1-MIN(100,(Inputs!$B$9+Summary!$B$14+Artifacts!$B$32))/100)+M7*(MIN(100,(Inputs!$B$9+Summary!$B$14+Artifacts!$B$32))/100)))*(1+Artifacts!$B$81/100))),0) | V7: =IF(C7,(H7*N7*IF(AND(Inputs!$B$39<>"pvp",Inputs!$B$44>0),((Skills!G7*((R7-1)*IF(Skills!H7>0,Skills!I7/Skills!H7,1)+IF(Skills!H7>0,MIN(Skills!I7,MAX(0,MAX(0,Inputs!$B$44-Summary!$B$26)-((R7-1)*IF(Inputs!$B$39="pvp",15,MAX(0.1,Skills!D7-IF(TRUE=TRUE,Inputs!$B$32,0))))))/Skills!H7,1)))/Inputs!$B$44),G7*Q7))*IF(Inputs!$B$39="pvp",1,(1+(Inputs!$B$21+Skills!Q7+Summary!$B$15+Artifacts!$B$80)/100)*(MIN(Skills!W7,Inputs!$B$37)))*((1+Artifacts!$B$53/100)),0)
A8: =Skills!A8 | B8: =Skills!B8 | C8: =Inputs!$B$3>=60 | D8: =IF(Skills!C8=1,60+Inputs!$B$25+Inputs!$B$29,IF(Skills!C8=2,90+Inputs!$B$26+Inputs!$B$29,IF(Skills!C8=3,120+Inputs!$B$27+Inputs!$B$29,MAX(0,(Inputs!$B$3-100)*3)+Inputs!$B$28+Inputs!$B$29))) | E8: =INDEX(FactorTable!$B$2:$Y$301, MATCH(ROUND(MIN(300,MAX(1,D8)),0), FactorTable!$A$2:$A$301,0), Skills!M8+1) | F8: =IF(Skills!N8=TRUE,(Skills!L8/10)*(E8/1000),Skills!L8/10)+Skills!O8 | G8: =Skills!G8*IF(Skills!H8>0,IF(Inputs!$B$39="pvp",MIN(Skills!I8,15),Skills!I8)/Skills!H8,1) | H8: =1-(1-Skills!J8/100)^Skills!K8 | I8: 1 | O8: =(1-Summary!$B$11)*T8+Summary!$B$11*V8 | P8: =IF(Summary!$B$3=0,0,O8/Summary!$B$3) | Q8: 0 | R8: 0 | S8: =IFERROR(O8/N8,0) | T8: 0 | V8: 0
