Workbook

Sheet README
A1: Corsair — DPS Calculator: How to Use This Workbook
A3: How to use this workbook
A4: Only edit the yellow-highlighted cells on the Inputs sheet — every other sheet is computed from those values and will be overwritten if you rebuild the workbook.
A5: Summary shows Total DPS, a Per-Skill DPS Breakdown (damage-dealing skills only — buffs/passives that never deal their own damage are omitted), and a Marginal DPS & Stat Value table showing the DPS gained per +1 of each stat.
A6: Sensitivity has the full detail behind that marginal-value table — one self-contained block per stat, showing exactly how bumping that stat by +1 changes every downstream number.
A7: CubeData/PotentialCubes model your current gear's Potential Cube lines and drive cube-reroll expected-value decisions. For the full standalone Potential Cube EV calculator (exact optimal-stopping math, works from this workbook alone), see tools/potential_cubes_ev.py in the project repo.
A9: Design decisions & assumptions
A10: Data source (2026-10-21 audit): Corsair's numbers come from maplestoryidle.info's GAME CAPTURE (skill text + the game's own tables: ratios, factorIndices, hit/target counts, cooldowns, trigger rules), which beats the wiki (no Req.Level/Cooldown/Mastery data there). The real mastery table is used (Blackboot Bill +50, Scurvy +50, All Aboard +50 and -30% intervals, Siege Bomber +50/Setup, Rapid Fire +70, Brain Scrambler +100, Broadside Bombardment/Setup, Swift Fire Weaken, ...); the earlier 'role-mapped from Buccaneer' masteries are gone. The Broadside bombardment line (1900% x3 on 8 targets) uses factorIndex 12 as a FLAGGED ASSUMPTION (no table ratio).
A11: Shadow Heart, Quick Motion (AS component only), Agile Guns, Gun Mastery, Physical Training, Infinity Blast, Fullmetal Jacket, Cross Cut Blast, and Quickdraw's own flat +25% Basic Attack Damage component are always-on passives assumed to already be reflected in your own Inputs stat entries — only their Sensitivity marginal delta is modeled live, matching this project's established convention.
A12: Eight-Legs Easton (basic attack) reuses the universal 4th-job-basic-attack constant (baseDamage 2900, factorIndex 21). Quickdraw (Lv125) is modeled: every 3rd cast deals double damage (x(1+1/3) on average) and each 3 casts cut 1.5s from Brain Scrambler or Rapid Fire (assumed split evenly -> both cooldowns are divided by 1 + 0.25*B*, with B* the Easton cast rate solved in closed form). Nautilus Strike and Roll of the Dice are shared verbatim with Buccaneer.
A13: Scurvy Summons / All Aboard crews and Siege Bomber / Broadside turrets use the standard ActiveWindow/ICD tick machinery; crew windows lengthen with Buff Duration Increase from Lv104, strike intervals drop 30% at Lv94, and the Siege Bomber / Broadside Setup masteries (+1 setup) let two instances coexist so their windows are no longer capped at the cooldown. Broadside's Lv118 Bombardment replaces the Battleship's 330% ticks with 1900% x3 hits on 8 targets.
A14: Majestic Presence procs off three sources (Easton, Brain Scrambler, Rapid Fire) at 25% with a 0.5s internal cooldown: (c*R)/(1+ICD*c*R). Nautilus Strike - Final Attack is the same kind of any-attack proc (30%, 1s ICD). Ahoy Mateys (+250%/+100% FD to the Dual Pistol / Sharpshooter crews) is its own helper row. Swift Fire's Lv54 Weaken (+3% per strike, 3 stacks) feeds the damage-taken bucket.
... A17: Not modeled (out of scope): all forms of crowd control (Blackboot Bill's stun), Accuracy, Evasion, Defense, movement speed, and Companion Summoning Time.

Sheet Inputs
A1: Corsair — DPS Calculator Inputs | N1: (none)
C2: Chapter Boss | D2: Breakthrough | E2: PvP | F2: EXP Dungeon | G2: Equipment Dungeon | H2: Weapon Dungeon | I2: Enhancement Dungeon | J2: Hero Dungeon | K2: World Boss | L2: Chapter Hunt | N2: Charm of the Undead
A3: Character Level | B3: 200 | N3: Pig's Ribbon
A4: Content Type | B4: Chapter Boss | N4: Shamaness Marble
A5: Chapter-Stage — 'chapter-substage' (e.g. '28-9') for Breakthrough/Chapter Hunt, just the chapter number for Chapter Boss, or just the stage number for Weapon/Equipment/Enhancement/EXP/Hero Dungeon. Not applicable to World Boss/PvP. | B5: =INDEX($C$5:$L$5,MATCH($B$4,$C$2:$L$2,0)) | C5: 28 | D5: 28-9 | F5: 80 | G5: 80 | H5: 80 | I5: 80 | J5: 80 | L5: 28-9 | N5: The Contract of Darkness
A6: Flat ATTACK | B6: =INDEX($C$6:$L$6,MATCH($B$4,$C$2:$L$2,0)) | C6: 10000 | D6: 10000 | E6: 10000 | F6: 10000 | G6: 10000 | H6: 10000 | I6: 10000 | J6: 10000 | K6: 10000 | L6: 10000 | N6: Rainbow-colored Snail Shell
A7: ATTACK % | B7: =INDEX($C$7:$L$7,MATCH($B$4,$C$2:$L$2,0)) | C7: 0 | D7: 0 | E7: 0 | F7: 0 | G7: 0 | H7: 0 | I7: 0 | J7: 0 | K7: 0 | L7: 0 | N7: Hexagon Necklace
A8: Defense (your own DEF stat; PvP assumes the opponent has the same Defense as you) | B8: =INDEX($C$8:$L$8,MATCH($B$4,$C$2:$L$2,0)) | C8: 0 | D8: 0 | E8: 0 | F8: 0 | G8: 0 | H8: 0 | I8: 0 | J8: 0 | K8: 0 | L8: 0 | N8: Arwen's Glass Shoes
A9: CRIT_RATE % | B9: =INDEX($C$9:$L$9,MATCH($B$4,$C$2:$L$2,0)) | C9: 0 | D9: 0 | E9: 0 | F9: 0 | G9: 0 | H9: 0 | I9: 0 | J9: 0 | K9: 0 | L9: 0 | N9: Mushmom's Cap
A10: CRIT_DAMAGE % | B10: =INDEX($C$10:$L$10,MATCH($B$4,$C$2:$L$2,0)) | C10: 0 | D10: 0 | E10: 0 | F10: 0 | G10: 0 | H10: 0 | I10: 0 | J10: 0 | K10: 0 | L10: 0 | N10: Clear Spring Water
A11: ATTACK_SPEED % (base, excludes Weapon Acceleration) | B11: =INDEX($C$11:$L$11,MATCH($B$4,$C$2:$L$2,0)) | C11: 0 | D11: 0 | E11: 0 | F11: 0 | G11: 0 | H11: 0 | I11: 0 | J11: 0 | K11: 0 | L11: 0 | N11: Athena Pierce's Old Gloves
A12: Flat DEX | B12: =INDEX($C$12:$L$12,MATCH($B$4,$C$2:$L$2,0)) | C12: 0 | D12: 0 | E12: 0 | F12: 0 | G12: 0 | H12: 0 | I12: 0 | J12: 0 | K12: 0 | L12: 0 | N12: Zakum's Stone Piece
A13: DEX % | B13: =INDEX($C$13:$L$13,MATCH($B$4,$C$2:$L$2,0)) | C13: 0 | D13: 0 | E13: 0 | F13: 0 | G13: 0 | H13: 0 | I13: 0 | J13: 0 | K13: 0 | L13: 0 | N13: Horntail's Scale
A14: STR | B14: =INDEX($C$14:$L$14,MATCH($B$4,$C$2:$L$2,0)) | C14: 0 | D14: 0 | E14: 0 | F14: 0 | G14: 0 | H14: 0 | I14: 0 | J14: 0 | K14: 0 | L14: 0 | N14: Pink Bean's Giant Rib
A15: DAMAGE % | B15: =INDEX($C$15:$L$15,MATCH($B$4,$C$2:$L$2,0)) | C15: 0 | D15: 0 | E15: 0 | F15: 0 | G15: 0 | H15: 0 | I15: 0 | J15: 0 | K15: 0 | L15: 0 | N15: Chalice
A16: DAMAGE_AMP % | B16: =INDEX($C$16:$L$16,MATCH($B$4,$C$2:$L$2,0)) | C16: 0 | D16: 0 | E16: 0 | F16: 0 | G16: 0 | H16: 0 | I16: 0 | J16: 0 | K16: 0 | L16: 0 | N16: Old Music Box
A17: BASIC_ATTACK_DAMAGE % | B17: =INDEX($C$17:$L$17,MATCH($B$4,$C$2:$L$2,0)) | C17: 0 | D17: 0 | E17: 0 | F17: 0 | G17: 0 | H17: 0 | I17: 0 | J17: 0 | K17: 0 | L17: 0 | N17: Silver Pendant
A18: SKILL_DAMAGE % | B18: =INDEX($C$18:$L$18,MATCH($B$4,$C$2:$L$2,0)) | C18: 0 | D18: 0 | E18: 0 | F18: 0 | G18: 0 | H18: 0 | I18: 0 | J18: 0 | K18: 0 | L18: 0 | N18: Star Rock
A19: DEF_PEN % | B19: =INDEX($C$19:$L$19,MATCH($B$4,$C$2:$L$2,0)) | C19: 0 | D19: 0 | E19: 0 | F19: 0 | G19: 0 | H19: 0 | I19: 0 | J19: 0 | K19: 0 | L19: 0 | N19: Book of Ancient
A20: BOSS_DAMAGE % | B20: =INDEX($C$20:$L$20,MATCH($B$4,$C$2:$L$2,0)) | C20: 0 | D20: 0 | E20: 0 | F20: 0 | G20: 0 | H20: 0 | I20: 0 | J20: 0 | K20: 0 | L20: 0 | N20: Lunar Dew
A21: NORMAL_DAMAGE % | B21: =INDEX($C$21:$L$21,MATCH($B$4,$C$2:$L$2,0)) | C21: 0 | D21: 0 | E21: 0 | F21: 0 | G21: 0 | H21: 0 | I21: 0 | J21: 0 | K21: 0 | L21: 0 | N21: Fire Flower
A22: MIN_DAMAGE % | B22: =INDEX($C$22:$L$22,MATCH($B$4,$C$2:$L$2,0)) | C22: 100 | D22: 100 | E22: 100 | F22: 100 | G22: 100 | H22: 100 | I22: 100 | J22: 100 | K22: 100 | L22: 100 | N22: Soul Contract
A23: MAX_DAMAGE % | B23: =INDEX($C$23:$L$23,MATCH($B$4,$C$2:$L$2,0)) | C23: 100 | D23: 100 | E23: 100 | F23: 100 | G23: 100 | H23: 100 | I23: 100 | J23: 100 | K23: 100 | L23: 100 | N23: Lit Lamp
A24: FINAL_DAMAGE % (base) | B24: =INDEX($C$24:$L$24,MATCH($B$4,$C$2:$L$2,0)) | C24: 0 | D24: 0 | E24: 0 | F24: 0 | G24: 0 | H24: 0 | I24: 0 | J24: 0 | K24: 0 | L24: 0 | N24: Soul Pouch
A25: Skill Level Bonus — 1st Job | B25: =INDEX($C$25:$L$25,MATCH($B$4,$C$2:$L$2,0)) | C25: 0 | D25: 0 | E25: 0 | F25: 0 | G25: 0 | H25: 0 | I25: 0 | J25: 0 | K25: 0 | L25: 0 | N25: Ancient Text Piece
A26: Skill Level Bonus — 2nd Job | B26: =INDEX($C$26:$L$26,MATCH($B$4,$C$2:$L$2,0)) | C26: 0 | D26: 0 | E26: 0 | F26: 0 | G26: 0 | H26: 0 | I26: 0 | J26: 0 | K26: 0 | L26: 0 | N26: Icy Soul Rock
A27: Skill Level Bonus — 3rd Job | B27: =INDEX($C$27:$L$27,MATCH($B$4,$C$2:$L$2,0)) | C27: 0 | D27: 0 | E27: 0 | F27: 0 | G27: 0 | H27: 0 | I27: 0 | J27: 0 | K27: 0 | L27: 0 | N27: Flaming Lava
A28: Skill Level Bonus — 4th Job | B28: =INDEX($C$28:$L$28,MATCH($B$4,$C$2:$L$2,0)) | C28: 0 | D28: 0 | E28: 0 | F28: 0 | G28: 0 | H28: 0 | I28: 0 | J28: 0 | K28: 0 | L28: 0 | N28: Sayram's Necklace
A29: Skill Level Bonus — All Skills | B29: =INDEX($C$29:$L$29,MATCH($B$4,$C$2:$L$2,0)) | C29: 0 | D29: 0 | E29: 0 | F29: 0 | G29: 0 | H29: 0 | I29: 0 | J29: 0 | K29: 0 | L29: 0 | N29: Bottle of Emotion
N30: Peach Tree Herb Pouch
A31: Additional Bonuses | N31: Candle
A32: Skill Cooldown Decrease (seconds; applies to every cooldown — skills, buffs and passives) | B32: =INDEX($C$32:$L$32,MATCH($B$4,$C$2:$L$2,0)) | C32: 0 | D32: 0 | E32: 0 | F32: 0 | G32: 0 | H32: 0 | I32: 0 | J32: 0 | K32: 0 | L32: 0 | N32: Alliance Badge
A33: Basic Attack Target Increase (flat, adds to the 6-target normal-monster base) | B33: =INDEX($C$33:$L$33,MATCH($B$4,$C$2:$L$2,0)) | C33: 1 | D33: 1 | E33: 1 | F33: 1 | G33: 1 | H33: 1 | I33: 1 | J33: 1 | K33: 1 | L33: 1 | N33: Horn Flute
A34: Buff Duration Increase % | B34: =INDEX($C$34:$L$34,MATCH($B$4,$C$2:$L$2,0)) | C34: 0 | D34: 0 | E34: 0 | F34: 0 | G34: 0 | H34: 0 | I34: 0 | J34: 0 | K34: 0 | L34: 0 | N34: Cursed Doll
A35: Companion Summoning Time Increase % (companions not modeled — always 0 DPS impact) | B35: =INDEX($C$35:$L$35,MATCH($B$4,$C$2:$L$2,0)) | C35: 0 | D35: 0 | E35: 0 | F35: 0 | G35: 0 | H35: 0 | I35: 0 | J35: 0 | K35: 0 | L35: 0 | N35: Reindeer's Spear
A36: Boss/Normal Emphasis (Breakthrough/Hero Dungeon only) | B36: =INDEX($C$36:$L$36,MATCH($B$4,$C$2:$L$2,0)) | D36: A Little More Normal | J36: A Little More Normal | N36: Secret Map
A37: Max Enemies Actually In Range (normal-monster content only; default 999 = uncapped) | B37: =INDEX($C$37:$L$37,MATCH($B$4,$C$2:$L$2,0)) | D37: 999 | F37: 999 | G37: 999 | J37: 999 | L37: 999 | N37: Ring of Cycles
A38: Monster Type (auto-computed from Content Type) — computed, do not edit | B38: =IF(Inputs!$B$4="PvP","pvp",IF(OR(Inputs!$B$4="Breakthrough",Inputs!$B$4="Hero Dungeon"),"breakthrough",IF(OR(Inputs!$B$4="EXP Dungeon",Inputs!$B$4="Equipment Dungeon",Inputs!$B$4="Chapter Hunt"),"normal","boss")))
A39: Chapter (parsed from Chapter-Stage) — computed, do not edit | B39: =IFERROR(IF(ISNUMBER(FIND("-",Inputs!$B$5)),VALUE(LEFT(Inputs!$B$5,FIND("-",Inputs!$B$5)-1)),VALUE(Inputs!$B$5)),28)
A40: Stage (parsed from Chapter-Stage) — computed, do not edit | B40: =IFERROR(IF(ISNUMBER(FIND("-",Inputs!$B$5)),VALUE(MID(Inputs!$B$5,FIND("-",Inputs!$B$5)+1,50)),VALUE(Inputs!$B$5)),9)
...

Sheet FactorTable
A1: Level | B1: F0 | C1: F1 | D1: F2 | E1: F3 | F1: F4 | G1: F5 | H1: F6 | I1: F7 | J1: F8 | K1: F9 | L1: F10 | M1: F11 | N1: F12 | O1: F13 | P1: F14 | Q1: F15 | R1: F16 | S1: F17 | T1: F18 | U1: F19 | V1: F20 | W1: F21 | X1: F22 | Y1: F23
A2: 1 | B2: 0 | C2: 1000 | D2: 1000 | E2: 1000 | F2: 1000 | G2: 1000 | H2: 1000 | I2: 1000 | J2: 1000 | K2: 1000 | L2: 1000 | M2: 1000 | N2: 1000 | O2: 1000 | P2: 1000 | Q2: 1000 | R2: 1000 | S2: 1000 | T2: 1000 | U2: 1000 | V2: 1000 | W2: 1000 | X2: 1000 | Y2: 1000
A3: 2 | B3: 0 | C3: 1015 | D3: 1020 | E3: 1030 | F3: 1040 | G3: 1050 | H3: 1060 | I3: 1070 | J3: 1020 | K3: 1020 | L3: 1020 | M3: 1000 | N3: 1010 | O3: 1020 | P3: 1030 | Q3: 1040 | R3: 1050 | S3: 1060 | T3: 1070 | U3: 1080 | V3: 1010 | W3: 1008 | X3: 1006 | Y3: 1100
A4: 3 | B4: 0 | C4: 1031 | D4: 1041 | E4: 1061 | F4: 1082 | G4: 1103 | H4: 1124 | I4: 1145 | J4: 1030 | K4: 1041 | L4: 1030 | M4: 1000 | N4: 1015 | O4: 1030 | P4: 1045 | Q4: 1060 | R4: 1075 | S4: 1090 | T4: 1105 | U4: 1120 | V4: 1020 | W4: 1012 | X4: 1009 | Y4: 1150
A5: 4 | B5: 0 | C5: 1047 | D5: 1062 | E5: 1093 | F5: 1126 | G5: 1159 | H5: 1192 | I5: 1226 | J5: 1040 | K5: 1062 | L5: 1040 | M5: 1000 | N5: 1020 | O5: 1040 | P5: 1060 | Q5: 1080 | R5: 1100 | S5: 1120 | T5: 1140 | U5: 1160 | V5: 1030 | W5: 1016 | X5: 1012 | Y5: 1200
A6: 5 | B6: 0 | C6: 1063 | D6: 1084 | E6: 1126 | F6: 1172 | G6: 1217 | H6: 1264 | I6: 1312 | J6: 1050 | K6: 1084 | L6: 1050 | M6: 1000 | N6: 1025 | O6: 1050 | P6: 1075 | Q6: 1100 | R6: 1125 | S6: 1150 | T6: 1175 | U6: 1200 | V6: 1040 | W6: 1020 | X6: 1015 | Y6: 1250
A7: 6 | B7: 0 | C7: 1079 | D7: 1106 | E7: 1160 | F7: 1219 | G7: 1278 | H7: 1340 | I7: 1404 | J7: 1060 | K7: 1106 | L7: 1060 | M7: 1000 | N7: 1030 | O7: 1060 | P7: 1090 | Q7: 1120 | R7: 1150 | S7: 1180 | T7: 1210 | U7: 1240 | V7: 1050 | W7: 1024 | X7: 1018 | Y7: 1300
A8: 7 | B8: 0 | C8: 1096 | D8: 1129 | E8: 1195 | F8: 1268 | G8: 1342 | H8: 1421 | I8: 1503 | J8: 1070 | K8: 1129 | L8: 1070 | M8: 1000 | N8: 1035 | O8: 1070 | P8: 1105 | Q8: 1140 | R8: 1175 | S8: 1210 | T8: 1245 | U8: 1280 | V8: 1060 | W8: 1028 | X8: 1021 | Y8: 1350
A9: 8 | B9: 0 | C9: 1113 | D9: 1152 | E9: 1231 | F9: 1319 | G9: 1410 | H9: 1507 | I9: 1609 | J9: 1080 | K9: 1152 | L9: 1080 | M9: 1000 | N9: 1040 | O9: 1080 | P9: 1120 | Q9: 1160 | R9: 1200 | S9: 1240 | T9: 1280 | U9: 1320 | V9: 1070 | W9: 1032 | X9: 1024 | Y9: 1400
A10: 9 | B10: 0 | C10: 1130 | D10: 1176 | E10: 1268 | F10: 1372 | G10: 1481 | H10: 1598 | I10: 1722 | J10: 1090 | K10: 1176 | L10: 1090 | M10: 1000 | N10: 1045 | O10: 1090 | P10: 1135 | Q10: 1180 | R10: 1225 | S10: 1270 | T10: 1315 | U10: 1360 | V10: 1080 | W10: 1036 | X10: 1027 | Y10: 1450
A11: 10 | B11: 0 | C11: 1147 | D11: 1200 | E11: 1307 | F11: 1427 | G11: 1556 | H11: 1694 | I11: 1843 | J11: 1100 | K11: 1200 | L11: 1100 | M11: 1000 | N11: 1050 | O11: 1100 | P11: 1150 | Q11: 1200 | R11: 1250 | S11: 1300 | T11: 1350 | U11: 1400 | V11: 1090 | W11: 1040 | X11: 1030 | Y11: 1500
A12: 11 | B12: 0 | C12: 1165 | D12: 1224 | E12: 1347 | F12: 1485 | G12: 1634 | H12: 1796 | I12: 1973 | J12: 1110 | K12: 1224 | L12: 1110 | M12: 1000 | N12: 1055 | O12: 1110 | P12: 1165 | Q12: 1220 | R12: 1275 | S12: 1330 | T12: 1385 | U12: 1440 | V12: 1100 | W12: 1044 | X12: 1033 | Y12: 1550
A13: 12 | B13: 0 | C13: 1183 | D13: 1249 | E13: 1388 | F13: 1545 | G13: 1716 | H13: 1904 | I13: 2112 | J13: 1120 | K13: 1249 | L13: 1120 | M13: 1000 | N13: 1060 | O13: 1120 | P13: 1180 | Q13: 1240 | R13: 1300 | S13: 1360 | T13: 1420 | U13: 1480 | V13: 1110 | W13: 1048 | X13: 1036 | Y13: 1600
... A301: 300 | B301: 0 | C301: 88573 | D301: 381637 | E301: 6991522 | F301: 125363453 | G301: 2185120762 | H301: 37157073039 | I301: 614631863830 | J301: 2000 | K301: 53326 | L301: 2500 | M301: 1100 | N301: 2500 | O301: 4000 | P301: 5500 | Q301: 7000 | R301: 8500 | S301: 10000 | T301: 11500 | U301: 13000 | V301: 7558 | W301: 2200 | X301: 1900 | Y301: 8800

Sheet Skills
A1: Key | B1: Name | C1: JobStep | D1: Cooldown(s) | E1: CostsActionSlot | F1: ActionsPerCast | G1: HitsPerCast | H1: ICD(s) | I1: ActiveWindow(s) | J1: ProcChance% | K1: RollsPerCast | L1: BaseDamage(tenths%) | M1: FactorIndex | N1: ScalesWithLevel | O1: SkillMasteryBonus% | P1: MasteryBossDamage% | Q1: MasteryNormalDamage% | R1: NormalMonsterTargets | S1: BuffTargetStat | T1: BuffDuration(s) | U1: MapleHeroBase(tenths%) | V1: MapleHeroFactorIndex | W1: Note
A2: EIGHT_LEGS_EASTON | B2: Eight-Legs Easton | C2: 4 | E2: FALSE | F2: 1 | G2: =IF(Inputs!$B$3>=136,6,5) | H2: 0 | I2: 0 | J2: 100 | K2: 1 | L2: 2900 | M2: 21 | N2: TRUE | O2: =SUMPRODUCT((Inputs!$B$3>={102,106,116,120,128,132})*{10,11,12,13,14,15}) | P2: =SUMPRODUCT((Inputs!$B$3>={111,124})*{10,10}) | Q2: 0 | R2: =6+Inputs!$B$33 | T2: 0 | W2: 4th-job basic-attack effect (supersedes Double Shot/Rapid Blast/Blunderbuster): 290% damage to 6 target(s) in front 5 time(s). factorIndex 21, baseDamage 2900 tenths% (game table). HitsPerCast=5, 6 once Mastery Lv.136 'Eight-Legs Easton - Strike' unlocks. Damage chain 102/106/116/120/128/132 and Boss Monster Damage chain 111/124 now confirmed from the game capture's real mastery table (an earlier version mapped them from Buccaneer): every tier is its own add-on (user-confirmed 2026-10-21: raw +10/+11/+12/+13/+14/+15 = 75% at max). Quickdraw (Lv125): every 3rd cast deals double damage (game table lists a second 5800% line) => the DPS formula multiplies by (1 + 1/3) once Quickdraw is unlocked; its cooldown effect on Brain Scrambler / Rapid Fire is in Summary!QD_FACTOR.
A3: SWIFT_FIRE | B3: Swift Fire | C3: 2 | D3: 17 | E3: TRUE | F3: 1 | G3: 3 | H3: 0 | I3: 0 | J3: 100 | K3: 1 | L3: 1800 | M3: 12 | N3: TRUE | O3: =SUMPRODUCT((Inputs!$B$3>={39})*{50}) | P3: 0 | Q3: 0 | R3: 8 | T3: 0 | U3: 200 | V3: 23 | W3: Game capture: 'Fires three bullets consecutively ahead to attack up to 8 target(s), dealing 180% damage each', 17s cooldown, Lv.33 unlock (was 35). factorIndex 12, baseDamage 1800 tenths%, 3 hits. Mastery Lv.39 'Swift Fire - Damage' +50% (confirmed from the real mastery table; was role-mapped). Mastery Lv.54 'Swift Fire - Weaken': +3% damage taken per strike, max 3 stacks (9%) for 8s, scaled by the 8s/cooldown uptime — now modeled in Summary's monster-damage-taken bucket. Maple Hero target (80% share, ratio 80/20) — see MAPLE_HERO_RATIOS.
A4: SCURVY_SUMMONS | B4: Scurvy Summons | C4: 2 | D4: 35 | E4: TRUE | F4: 1 | G4: 2 | H4: =IF(Inputs!$B$3>=94,1.5*0.7,1.5) | I4: =IF(Inputs!$B$3>=104,MIN(35,20*(1+Inputs!$B$34/100)),20) | J4: 100 | K4: 1 | L4: 950 | M4: 12 | N4: TRUE | O4: =SUMPRODUCT((Inputs!$B$3>={49})*{50}) | P4: 0 | Q4: 0 | R4: 3 | T4: 0 | W4: Game capture: 'Summons the Dual Pistol Crew of the Nautilus for 20 sec. The Dual Pistol Crew attacks up to 3 nearby target(s) for 95% damage 2 time(s) every 1.5 sec.' 35s cooldown, Lv.35 unlock (was 40). factorIndex 12, baseDamage 950 tenths%. Masteries (real table, were missing): Lv.49 'Scurvy Summons - Damage' +50% (Dual Pistol Crew damage); Lv.94 'All Aboard - Strike Interval' -30% on BOTH crews (1.5s -> 1.05s); Lv.104 'All Aboard - Persistence': the Buff Duration Increase stat lengthens the crews' 20s duration (ActiveWindow = MIN(35, 20*(1+BDI)), read live by Calc/Sensitivity). Ahoy Mateys: +250% Final Damage (ratio 1.0, see AHOY_MATEYS_RATIOS) and the Lv.122 +20% FD-for-20s proc (Summary).
A5: ALL_ABOARD | B5: All Aboard | C5: 3 | D5: =Skills!D4 | E5: FALSE | F5: 1 | G5: 3 | H5: =IF(Inputs!$B$3>=94,2*0.7,2) | I5: =IF(Inputs!$B$3>=104,MIN(35,20*(1+Inputs!$B$34/100)),20) | J5: 100 | K5: 1 | L5: 1100 | M5: 12 | N5: TRUE | O5: =SUMPRODUCT((Inputs!$B$3>={78})*{50}) | P5: 0 | Q5: 0 | R5: 8 | T5: 0 | W5: Game capture: 'Summons the Sharpshooter Crew upon using Scurvy Summons. The Sharpshooter Crew fires bullets every 2 sec to deal 110% damage to 8 target(s) near the main target 3 time(s).' A 3rd-job skill (JobStep 3; was 2), Lv.69 unlock (was 45). Cooldown is a LIVE reference to Scurvy Summons' (and inherits its CDR eligibility); window/ICD follow Scurvy Summons' crew rules. Masteries: Lv.78 'All Aboard - Damage' +50% (Sharpshooter Crew), Lv.94 strike interval -30% (2s -> 1.4s), Lv.104 BDI lengthens the crew window. factorIndex 12, baseDamage 1100 tenths%. Ahoy Mateys: +100% Final Damage (ratio 100/250 of the 250 base).
A6: BLACKBOOT_BILL | B6: Blackboot Bill | C6: 3 | D6: 23 | E6: TRUE | F6: 1 | G6: 4 | H6: 0 | I6: 0 | J6: 100 | K6: 1 | L6: 1700 | M6: 12 | N6: TRUE | O6: =SUMPRODUCT((Inputs!$B$3>={73})*{50}) | P6: 0 | Q6: 0 | R6: 9 | T6: 0 | U6: 400 | V6: 23 | W6: Game capture: 'Fires a giant bullet to deal 170% damage to 9 target(s) in front 4 time(s) and stun them for 2 sec' (stun not modeled), 23s cooldown, Lv.66 unlock (was 63). factorIndex 12, baseDamage 1700 tenths%. Mastery Lv.73 'Blackboot Bill - Damage' is +50% (real table; the earlier +80% was role-mapped from Buccaneer's Corkscrew Blow). Maple Hero target (40% share, ratio 40/20).
A7: SIEGE_BOMBER | B7: Siege Bomber | C7: 3 | D7: 22 | E7: TRUE | F7: 1 | G7: 1 | H7: 1.5 | I7: =IF(Inputs!$B$3>=68,30,22) | J7: 100 | K7: 1 | L7: 1900 | M7: 12 | N7: TRUE | O7: =SUMPRODUCT((Inputs!$B$3>={82})*{50}) | P7: 0 | Q7: 0 | R7: 6 | T7: 0 | U7: 100 | V7: 23 | W7: Game capture: 'Installs a fixed cannon for 30 sec to deal 190% damage to up to 6 target(s) near the main target every 1.5 sec. Its range is increased by 50% and it can immediately replace itself in auto mode.' 22s cooldown, Lv.63 unlock (was 66). Because the cooldown (22s) is shorter than the 30s duration, with a single setup a recast replaces the still-active cannon, capping the useful window at 22s; Mastery Lv.68 'Siege Bomber - Setup' (+1 max setup count) lets two cannons coexist, so the window becomes the full 30s (ActiveWindow `IF(L>=68,30,22)`). Its other effect (first setup after combat starts gets -15s cooldown) only shifts the first cast and is not modeled. Mastery Lv.82 'Siege Bomber - Damage' +50% (real table). factorIndex 12, baseDamage 1900 tenths%. Maple Hero target (20% share, ratio 1.0).
A8: BRAIN_SCRAMBLER | B8: Brain Scrambler | C8: 4 | D8: 18 | E8: TRUE | F8: 1 | G8: 2 | H8: 0 | I8: 0 | J8: 100 | K8: 1 | L8: 29000 | M8: 12 | N8: TRUE | O8: =SUMPRODUCT((Inputs!$B$3>={108})*{100}) | P8: 0 | Q8: 0 | R8: 1 | T8: 0 | W8: Game capture: 'Hits the target's head to deal 2900% damage 2 time(s).' 18s cooldown, Lv.103 unlock (was 100). factorIndex 12, baseDamage 29000 tenths%, single target. Mastery Lv.108 'Brain Scrambler - Damage' +100%. Quickdraw (Lv125) shortens its effective cooldown (Summary!QD_FACTOR). Also a trigger source for Majestic Presence and Nautilus Strike - Final Attack.
A9: NAUTILUS_STRIKE | B9: Nautilus Strike | C9: 4 | D9: 33 | E9: TRUE | F9: 1 | G9: 5 | H9: 0 | I9: 0 | J9: 100 | K9: 1 | L9: 19500 | M9: 12 | N9: TRUE | O9: =SUMPRODUCT((Inputs!$B$3>={126})*{50}) | P9: 0 | Q9: 0 | R9: 15 | T9: 0 | W9: Shared verbatim with Buccaneer: 'Orders the Nautilus to attack to deal 1950% damage to 15 nearby target(s) 5 time(s).' 33s cooldown, Lv.105 unlock (was 103). factorIndex 12, baseDamage 19500 tenths%. Mastery Lv.126 'Nautilus Strike - Damage' +50%.
A10: NAUTILUS_FINAL_ATTACK | B10: Nautilus Strike - Final Attack | C10: 4 | E10: FALSE | F10: 1 | G10: 1 | H10: 1 | I10: 0 | J10: 30 | K10: 1 | L10: 8500 | M10: 21 | N10: TRUE | O10: 0 | P10: 0 | Q10: 0 | R10: 1 | T10: 0 | W10: Shared verbatim with Buccaneer: Mastery Lv.113 '[Nautilus Strike in Slot] When attacking, deals 850% additional damage with a 30% chance and a 1-sec cooldown.' ANY attack can trigger it, so it is a steady-state proc: rate = (Chance*R)/(1+ICD*Chance*R), R = combined cast rate of Eight-Legs Easton + Swift Fire + Blackboot Bill + Brain Scrambler + Nautilus Strike + Rapid Fire (Summary!NAUTILUS_TRIGGER_RATE); summons/turrets/crews are not counted (ASSUMPTION mirroring FP-Mage's user-confirmed trigger set). No cooldown of its own (ICD(s)=1 is the internal cooldown, RollsPerCast=1). factorIndex 21, baseDamage 8500 tenths% (literal percent).
A11: RAPID_FIRE | B11: Rapid Fire | C11: 4 | D11: 17 | E11: TRUE | F11: 1 | G11: 7 | H11: 0 | I11: 0 | J11: 100 | K11: 1 | L11: 18000 | M11: 12 | N11: TRUE | O11: =SUMPRODUCT((Inputs!$B$3>={130})*{70}) | P11: 0 | Q11: 0 | R11: 9 | T11: 0 | W11: Game capture (post-Aug-13): 'Fires bullets at a very high speed 7 time(s) to deal 1800% damage each to up to 9 targets in front', 17s cooldown, Lv.117 unlock (was 107). factorIndex 12, baseDamage 18000 tenths%. Mastery Lv.130 'Rapid Fire - Damage' +70% (real table; was missing). Quickdraw (Lv125) shortens its effective cooldown (Summary!QD_FACTOR). Trigger source for Majestic Presence and Nautilus Strike - Final Attack.
A12: BROADSIDE_BURST | B12: Broadside (initial burst) | C12: 4 | D12: 20 | E12: TRUE | F12: 1 | G12: 2 | H12: 0 | I12: 0 | J12: 100 | K12: 1 | L12: 50000 | M12: 12 | N12: TRUE | O12: 0 | P12: 0 | Q12: 0 | R12: 10 | T12: 0 | W12: Game capture (post-Aug-13): 'Summons the Nautilus's Battleship. The Battleship arrives behind 3 sec later and deals 5000% damage to 10 nearby target(s) 2 time(s). Afterward, it stays for 30 sec and deals 330% damage to target(s) in front of the Battleship every 2 sec. During auto-combat, the Battleship immediately replaces itself even when already deployed.' 20s cooldown, Lv.110 unlock. factorIndex 12, baseDamage 50000 tenths%. The 3s arrival delay is folded into a same-cast hit. No flat damage mastery exists for Broadside (the earlier +100% was a role-mapped phantom); its real masteries are Lv.118 'Bombardment' and Lv.138 'Setup' — both modeled on BROADSIDE_SUSTAINED.
A13: BROADSIDE_SUSTAINED | B13: Broadside (sustained turret) | C13: 4 | D13: =Skills!D12 | E13: FALSE | F13: 1 | G13: =IF(Inputs!$B$3>=118,3,1) | H13: 2 | I13: =IF(Inputs!$B$3>=138,30,20) | J13: 100 | K13: 1 | L13: =IF(Inputs!$B$3>=118,19000,3300) | M13: 12 | N13: TRUE | O13: 0 | P13: 0 | Q13: 0 | R13: =IF(Inputs!$B$3>=118,8,5) | T13: 0 | W13: Battleship ticks: 330% damage to 5 target(s) in front of the Battleship every 2s while it stays (a 10x magnitude bug on the wiki, 3300%, was fixed earlier). Mastery Lv.118 'Broadside - Bombardment' (Aug-13 note: 'After: all attacks changed to bombardment'): the Battleship's attacks all become bombardments dealing 1900% to 8 target(s) near the main target 3 time(s) — modeled as BaseDamage 19000 / 3 hits / 8 targets once Lv118 (the 2s tick interval is unchanged); an earlier version ignored this swap, a very large undercount for 118+. Mastery Lv.138 'Broadside - Setup' (+1 max setup count): two Battleships can coexist, so the window is the full 30s instead of being capped at the 20s cooldown by the replacement rule (its first-setup -15s cooldown only shifts the first cast, not modeled). Shares Broadside (burst)'s live cooldown/CDR eligibility. factorIndex 12 (bombardment line has no ratio in the tables — FLAGGED ASSUMPTION).
A14: MAJESTIC_PRESENCE | B14: Majestic Presence | C14: 4 | E14: FALSE | F14: 1 | G14: 1 | H14: 0.5 | I14: 0 | J14: 25 | K14: 1 | L14: 18000 | M14: 21 | N14: TRUE | O14: =SUMPRODUCT((Inputs!$B$3>={134})*{50}) | P14: 0 | Q14: 0 | R14: 6 | T14: 0 | W14: Game capture: 'When attacking with Basic Attacks, Brain Scrambler, or Rapid Fire, deals 1800% additional damage to up to 6 nearby targets with a 25% chance', 0.5s internal cooldown (game table cooldownMs 500; an earlier version had no cooldown), Lv.120 unlock (was 125). factorIndex 21 (game table; was 12), baseDamage 18000 tenths%. Procs off three independent sources (Easton's cast rate + Brain Scrambler + Rapid Fire hit rates); steady-state proc rate = (c*R)/(1+ICD*c*R) with c=25%, ICD=0.5s. Mastery Lv.134 'Majestic Presence - Damage' +50%. No cooldown of its own in the Skills sense (CostsActionSlot=False); ICD(s) is the proc's internal cooldown and ActiveWindow=0, so EffectiveHits is unused.
A15: MAPLE_HERO_HELPER | B15: Maple Hero (helper) | C15: 4 | E15: FALSE | F15: 1 | G15: 1 | H15: 0 | I15: 0 | J15: 100 | K15: 1 | L15: 200 | M15: 23 | N15: TRUE | O15: 0 | P15: 0 | Q15: 0 | R15: 0 | T15: 0 | W15: Shared ratio-feeder row (see MAPLE_HERO_RATIOS) for Siege Bomber/Blackboot Bill/Swift Fire's Final Damage chains: 'Increases Final Damage of the following skills: Siege Bomber 20%, Blackboot Bill 40%, Swift Fire 80%' (game table: ModSkillStat FinalDamage x factorIndex 23). baseDamage 200 tenths% = the 20% Siege Bomber share (ratio 1.0). No independent DPS row (Calc J-N blank; D/E/F read by each target row's K formula).
A16: AHOY_MATEYS_HELPER | B16: Ahoy Mateys (helper) | C16: 4 | E16: FALSE | F16: 1 | G16: 1 | H16: 0 | I16: 0 | J16: 100 | K16: 1 | L16: 2500 | M16: 21 | N16: TRUE | O16: 0 | P16: 0 | Q16: 0 | R16: 0 | T16: 0 | W16: Shared ratio-feeder row (see AHOY_MATEYS_RATIOS) for Scurvy Summons / All Aboard: 'Increases Final Damage of Dual Pistol Crew by 250% and Sharpshooter Crew by 100%' — Lv.107 unlock (was 120), factorIndex 21 (game table ModSkillStat, valueLevelFactors [3, 21]; was 22), baseDamage 2500 tenths% = the 250% Dual Pistol Crew share (ratio 1.0; Sharpshooter 100/250). No independent DPS row.
A17: ROLL_OF_THE_DICE_DICE | B17: Roll of the Dice (dice component) | C17: 3 | E17: FALSE | F17: 1 | G17: 1 | H17: 0 | I17: 0 | J17: 100 | K17: 1 | L17: 25 | M17: 22 | N17: TRUE | O17: 0 | P17: 0 | Q17: 0 | R17: 0 | S17: ATTACK | T17: 0 | W17: Shared verbatim with Buccaneer: 'Increases Attack by 20%. Rolls a six-sided die every 7 sec to increase Attack by 0-5% ... for 5 sec.' Lv.74 unlock (was 66). Only the random dice component is modeled: mean roll exactly 2.5% (baseDamage 25 tenths%), active 5 of every 7 seconds (x5/7 at the use site), factorIndex 22. The flat +20% Attack (and the Lv.90 +5%p mastery) are inside your Inputs!ATTACK_PCT.
A18: JOLLY_ROGER_FD | B18: Jolly Roger | C18: 4 | D18: 42 | E18: TRUE | F18: 1 | G18: 1 | H18: 0 | I18: 0 | J18: 100 | K18: 1 | L18: 150 | M18: 21 | N18: TRUE | O18: 0 | P18: 0 | Q18: 0 | R18: 0 | S18: FINAL_DAMAGE | T18: 18 | W18: Active cast (42s cooldown, 18s duration): 'Increases Final Damage by 15% for 18 sec, but decreases Evasion by 5' (Evasion not modeled). PATCHED 18% -> 15%. Lv.115 unlock. factorIndex 21 (game table; was 22), baseDamage 150 tenths%. Duty-cycle averaged by buff_uptime(); feeds R_FD_BONUS.
A19: SHADOW_HEART | B19: Shadow Heart | C19: 1 | E19: FALSE | F19: 1 | G19: 1 | H19: 0 | I19: 0 | J19: 100 | K19: 1 | L19: 50 | M19: 22 | N19: TRUE | O19: 0 | P19: 0 | Q19: 0 | R19: 0 | S19: CRIT_RATE | T19: 0 | W19: Magic Critical pattern — already baked into Inputs!CRIT_RATE%; feeds the 1st-Job Skill Level Bonus delta. Level-1 value 5% (game table: 50 x f22; the site text's 5.4% was captured at a higher skill level — earlier version stored 54). Lv.10 unlock (was 15).
A20: QUICK_MOTION | B20: Quick Motion | C20: 1 | E20: FALSE | F20: 1 | G20: 1 | H20: 0 | I20: 0 | J20: 100 | K20: 1 | L20: 60 | M20: 22 | N20: TRUE | O20: =SUMPRODUCT((Inputs!$B$3>={24})*{5}) | P20: 0 | Q20: 0 | R20: 0 | S20: ATTACK_SPEED | T20: 0 | W20: Magic Critical pattern — already baked into Inputs!ATTACK_SPEED%; feeds the 1st-Job Skill Level Bonus delta. Level-1 value 6% (game table: 60 x f22; the site text's 6.5% was captured at a higher skill level — earlier version stored 65). Lv.15 unlock (was 10). Mastery Lv.24 'Quick Motion - Speed' +5%p.
A21: AGILE_GUNS | B21: Agile Guns | C21: 2 | E21: FALSE | F21: 1 | G21: 1 | H21: 0 | I21: 0 | J21: 100 | K21: 1 | L21: 50 | M21: 22 | N21: TRUE | O21: =SUMPRODUCT((Inputs!$B$3>={44})*{7}) | P21: 0 | Q21: 0 | R21: 0 | S21: ATTACK_SPEED | T21: 0 | W21: Magic Critical pattern — already baked into Inputs!ATTACK_SPEED%; feeds the 2nd-Job Skill Level Bonus delta. 'Increases Attack Speed by 5%.' Lv.40 unlock (was 33). Mastery Lv.44 'Agile Guns - Speed' +7%p (confirmed real table). factorIndex 22, baseDamage 50 tenths%.
A22: GUN_MASTERY | B22: Gun Mastery | C22: 2 | E22: FALSE | F22: 1 | G22: 1 | H22: 0 | I22: 0 | J22: 100 | K22: 1 | L22: 150 | M22: 22 | N22: TRUE | O22: 0 | P22: 0 | Q22: 0 | R22: 0 | S22: MIN_DAMAGE | T22: 0 | W22: Magic Critical pattern — already baked into Inputs!MIN_DAMAGE%; feeds the 2nd-Job Skill Level Bonus delta. 'Increases Min Damage Multiplier by 15%.' Lv.43. factorIndex 22, baseDamage 150 tenths%.
A23: PHYSICAL_TRAINING | B23: Physical Training | C23: 2 | E23: FALSE | F23: 1 | G23: 1 | H23: 0 | I23: 0 | J23: 100 | K23: 1 | L23: 100 | M23: 22 | N23: TRUE | O23: 0 | P23: 0 | Q23: 0 | R23: 0 | S23: BASIC_ATTACK_DAMAGE | T23: 0 | W23: Magic Critical pattern — already baked into Inputs!BASIC_ATTACK_DAMAGE%; feeds the 2nd-Job Skill Level Bonus delta. 'Increases Basic Attack Damage by 10%.' Lv.38. factorIndex 22, baseDamage 100 tenths%.
A24: INFINITY_BLAST_ATK | B24: Infinity Blast | C24: 2 | E24: FALSE | F24: 1 | G24: 1 | H24: 0 | I24: 0 | J24: 100 | K24: 1 | L24: 120 | M24: 22 | N24: TRUE | O24: 0 | P24: 0 | Q24: 0 | R24: 0 | S24: ATTACK | T24: 0 | W24: Magic Critical pattern — already baked into Inputs!ATTACK_PCT (folds into the attack_mult delta bucket). 'Increases Attack by 12%.' (PATCHED 10% -> 12%). Lv.45 unlock (was 40). factorIndex 22, baseDamage 120 tenths% (game table: f22).
A25: FULLMETAL_JACKET_CD | B25: Fullmetal Jacket | C25: 3 | E25: FALSE | F25: 1 | G25: 1 | H25: 0 | I25: 0 | J25: 100 | K25: 1 | L25: 100 | M25: 22 | N25: TRUE | O25: 0 | P25: 0 | Q25: 0 | R25: 0 | S25: CRIT_DAMAGE | T25: 0 | W25: Magic Critical pattern — already baked into Inputs!CRIT_DAMAGE%; feeds the 3rd-Job Skill Level Bonus delta. 'Increases Critical Damage by 10%.' Lv.72. factorIndex 22, baseDamage 100 tenths%. Mastery Lv.98 'Fullmetal Jacket - Defense Penetration' (Def Pen = half of this Crit Damage boost) is a character-sheet stat, assumed inside your Inputs!DEF_PEN.
A26: CROSS_CUT_BLAST_FD | B26: Cross Cut Blast | C26: 3 | E26: FALSE | F26: 1 | G26: 1 | H26: 0 | I26: 0 | J26: 100 | K26: 1 | L26: 120 | M26: 22 | N26: TRUE | O26: 0 | P26: 0 | Q26: 0 | R26: 0 | S26: FINAL_DAMAGE | T26: 0 | W26: Magic Critical pattern — already baked into Inputs!FINAL_DAMAGE%; feeds the 3rd-Job Skill Level Bonus delta. 'Increases Final Damage by 12%.' (PATCHED 10% -> 12%). Lv.75. factorIndex 22, baseDamage 120 tenths%.
A27: QUICKDRAW_BAD | B27: Quickdraw | C27: 4 | E27: FALSE | F27: 1 | G27: 1 | H27: 0 | I27: 0 | J27: 100 | K27: 1 | L27: 250 | M27: 22 | N27: TRUE | O27: 0 | P27: 0 | Q27: 0 | R27: 0 | S27: BASIC_ATTACK_DAMAGE | T27: 0 | W27: 'Increases Basic Attack Damage by 25%. Every time Eight-Legs Easton is used 3 times, doubles the damage and decreases the cooldown of Brain Scrambler or Rapid Fire by 1.5 sec.' Lv.125 unlock (was 117). The flat +25% Basic Attack Damage is Magic-Critical-pattern (baked into Inputs!BASIC_ATTACK_DAMAGE%; feeds the 4th-Job Skill Level Bonus delta). The second effect is now MODELED (user decision 2026-10-21): Easton damage x(1+1/3) on average, and Brain Scrambler / Rapid Fire cooldowns divided by Summary!QD_FACTOR = 1 + 0.25*B* (see the build script's Quickdraw comment: 1.5s cut per 3 Easton casts, split evenly between the two skills — the split is an ASSUMPTION). factorIndex 22, baseDamage 250 tenths%.
A28: NIMBLE_FEET | B28: Nimble Feet | C28: 1 | D28: 60 | E28: TRUE | F28: 1 | G28: 1 | H28: 0 | I28: 0 | J28: 100 | K28: 1 | L28: 150 | M28: 0 | N28: FALSE | O28: 0 | P28: 0 | Q28: 0 | R28: 1 | S28: ATTACK_SPEED | T28: 15 | W28: Universal 1st-Job Explorer skill (identical wording on both idle.maplestorywiki.net and maplestoryidle.info — 'Increases Attack Speed by 15% and Speed by 10% for 15 sec', 60s cooldown, reqLevel 5) — was missing from this workbook entirely (a real gap found by cross-class comparison, not a class-design difference: Bowmaster/Dark Knight/FP-Mage/Hero/Marksman/Night Lord/Paladin/Shadower all already have it; Corsair's own Quick Motion is a separate, unrelated flat passive, same as Buccaneer). Flat +15% Attack Speed / +10% Speed for 15s, non-scaling. Speed component not modeled (no Speed stat anywhere in this project). FactorIndex unused placeholder.

Sheet Artifacts
A1: Fire/Poison Arch Mage — Artifacts (Equip Effect)
A3: Book of Ancient — Crit Damage (from Crit Rate, reference only) | B3: =IF(ArtifactsInput!$M$24,CHOOSE(ArtifactsInput!$N$24+1,30,36,42,48,54,60)/100*(Inputs!$B$9+B5+B29),0)
A4: Ring of Cycles — Threshold Crit Rate (excl. self) | B4: =Inputs!$B$9+B29
A5: Ring of Cycles — Crit Rate (if threshold < 100%) | B5: =IF(AND(Inputs!$B$38<>"pvp",Inputs!$B$43=0),1,IF(IF(Inputs!$B$38="pvp",15,Inputs!$B$43)-(Summary!$B$23)<=0,1,MAX(0,IF(Inputs!$B$38="pvp",15,Inputs!$B$43)-MAX(5,Summary!$B$23))/(IF(Inputs!$B$38="pvp",15,Inputs!$B$43)-(Summary!$B$23))))*IF(AND(ArtifactsInput!$M$42,B4<100),CHOOSE(ArtifactsInput!$N$42+1,30,36,42,48,54,60),0)
A6: Ring of Cycles — Skill Damage (if threshold >= 100%) | B6: =IF(AND(Inputs!$B$38<>"pvp",Inputs!$B$43=0),1,IF(IF(Inputs!$B$38="pvp",15,Inputs!$B$43)-(Summary!$B$23)<=0,1,MAX(0,IF(Inputs!$B$38="pvp",15,Inputs!$B$43)-MAX(5,Summary!$B$23))/(IF(Inputs!$B$38="pvp",15,Inputs!$B$43)-(Summary!$B$23))))*IF(AND(ArtifactsInput!$M$42,B4>=100),CHOOSE(ArtifactsInput!$N$42+1,40,48,56,64,72,80),0)
A7: Ring of Cycles — Excess-100% Points (capped at 100) | B7: =IF(AND(ArtifactsInput!$M$42,B4>=100),MIN(100,B4-100),0)
A8: Ring of Cycles — Basic Attack Damage (excess points x per-point) | B8: =IF(AND(Inputs!$B$38<>"pvp",Inputs!$B$43=0),1,IF(IF(Inputs!$B$38="pvp",15,Inputs!$B$43)-(Summary!$B$23)<=0,1,MAX(0,IF(Inputs!$B$38="pvp",15,Inputs!$B$43)-MAX(5,Summary!$B$23))/(IF(Inputs!$B$38="pvp",15,Inputs!$B$43)-(Summary!$B$23))))*B7*CHOOSE(ArtifactsInput!$N$42+1,0.6,0.72,0.84,0.96,1.08,1.2)
A9: Candle — Effective Fight Duration | B9: =IF(Inputs!$B$38="pvp",15,Inputs!$B$43)
A10: Candle — Effective Active (fixed-duration or PvP) | B10: =IF(Inputs!$B$38="pvp",TRUE,AND(Inputs!$B$38<>"pvp",Inputs!$B$43>0))
A11: Candle — Final Damage (100% uptime, patched) | B11: =IF(AND(ArtifactsInput!$M$36,B10),CHOOSE(ArtifactsInput!$N$36+1,8,9.6,11.2,12.8,14.4,16),0)
A12: Candle — Boss Monster Damage (20-40s window / boss-present-time uptime, patched) | B12: =IF(AND(ArtifactsInput!$M$36,B10),MAX(0,MIN(40,B9)-MAX(20,B41))/(B9-B41)*CHOOSE(ArtifactsInput!$N$36+1,30,36,42,48,54,60),0)
A13: Peach Tree Herb Pouch — Proc Rate (per second) | B13: =0.2*Summary!$B$17
A14: Peach Tree Herb Pouch — Uptime (refreshing 5s timer) | B14: =1-EXP(-B13*5)
A15: Peach Tree Herb Pouch — Enemy Damage Taken | B15: =IF(AND(ArtifactsInput!$M$35,Inputs!$B$4<>"Chapter Hunt"),CHOOSE(ArtifactsInput!$N$35+1,15,18,21,24,27,30)*B14,0)
A16: Silver Pendant — Offered Load (rho = lambda x duration) | B16: =0.15*Summary!$B$17*5
A17: Silver Pendant — Erlang Loss Weight (n=0) | B17: =B16^0/1
A18: Silver Pendant — Erlang Loss Weight (n=1) | B18: =B16^1/1
A19: Silver Pendant — Erlang Loss Weight (n=2) | B19: =B16^2/2
A20: Silver Pendant — Erlang Loss Weight (n=3) | B20: =B16^3/6
A21: Silver Pendant — Erlang Loss Weight (n=4) | B21: =B16^4/24
A22: Silver Pendant — Erlang Loss Weight (n=5) | B22: =B16^5/120
A23: Silver Pendant — Average Stacks (Erlang-loss mean) | B23: =(0*B17+1*B18+2*B19+3*B20+4*B21+5*B22)/(B17+B18+B19+B20+B21+B22)
A24: Silver Pendant — Enemy Damage Taken | B24: =IF(AND(ArtifactsInput!$M$22,Inputs!$B$4<>"Chapter Hunt"),CHOOSE(ArtifactsInput!$N$22+1,10,12,14,16,18,20)*B23,0)
A25: Athena Pierce's Old Gloves — Max Damage (from Attack Speed, reference only) | B25: =IF(ArtifactsInput!$M$15,CHOOSE(ArtifactsInput!$N$15+1,25,30,35,40,45,50)/100*Inputs!$B$11,0)
A26: Hexagon Necklace — Average Stacks | B26: =IF(AND(Inputs!$B$38<>"pvp",Inputs!$B$43=0),3,IF(IF(Inputs!$B$38="pvp",15,Inputs!$B$43)<=20,0,IF(IF(Inputs!$B$38="pvp",15,Inputs!$B$43)<=40,(IF(Inputs!$B$38="pvp",15,Inputs!$B$43)-20)/IF(Inputs!$B$38="pvp",15,Inputs!$B$43),IF(IF(Inputs!$B$38="pvp",15,Inputs!$B$43)<=60,(2*IF(Inputs!$B$38="pvp",15,Inputs!$B$43)-60)/IF(Inputs!$B$38="pvp",15,Inputs!$B$43),(3*IF(Inputs!$B$38="pvp",15,Inputs!$B$43)-120)/IF(Inputs!$B$38="pvp",15,Inputs!$B$43)))))
A27: Hexagon Necklace — Damage % | B27: =IF(ArtifactsInput!$M$11,CHOOSE(ArtifactsInput!$N$11+1,15,18,21,24,27,30)*B26,0)
A28: Rainbow-colored Snail Shell — Uptime (0-15s window) | B28: =IF(Inputs!$B$38="pvp",MIN(15,15)/15,IF(AND(Inputs!$B$38<>"pvp",Inputs!$B$43>0),MIN(15,Inputs!$B$43)/Inputs!$B$43,0))
A29: Rainbow-colored Snail Shell — Crit Rate | B29: =IF(ArtifactsInput!$M$10,CHOOSE(ArtifactsInput!$N$10+1,15,18,21,24,27,30)*B28,0)
A30: Rainbow-colored Snail Shell — Crit Damage | B30: =IF(ArtifactsInput!$M$10,CHOOSE(ArtifactsInput!$N$10+1,20,24,28,32,36,40)*B28,0)
A32: TOTAL — Artifact Crit Rate Bonus | B32: =B5+B29
A33: TOTAL — Artifact Crit Damage Bonus | B33: =B30+B47
A34: TOTAL — Artifact Final Damage Bonus (equivalent %, each real source combines MULTIPLICATIVELY — Candle x Flaming Lava x Horn Flute, not summed) | B34: =((1+B11/100)*(1+B46/100)*(1+B55/100)-1)*100
A35: TOTAL — Artifact Boss Monster Damage Bonus | B35: =B12+B60
A36: TOTAL — Artifact Enemy Damage Taken Bonus | B36: =B15+B24
A38: TOTAL — Artifact Damage Bonus (own separate final multiplier, like Magic Guard/Meditation's Average Buff Multiplier — not blended into Inputs!DAMAGE%) | B38: =B27
A39: TOTAL — Artifact Skill Damage Bonus | B39: =B6
A40: TOTAL — Artifact Basic Attack Damage Bonus | B40: =B8
A41: Candle — Boss Appear Time (Breakthrough/Hero Dungeon only) | B41: =IF(Inputs!$B$4="Breakthrough",20,IF(Inputs!$B$4="Hero Dungeon",30,0))
A42: Clear Spring Water — Final Damage (reference only, Growth Dungeon types) | B42: =IF(AND(ArtifactsInput!$M$14,OR(Inputs!$B$4="Weapon Dungeon",Inputs!$B$4="Equipment Dungeon",Inputs!$B$4="Enhancement Dungeon",Inputs!$B$4="EXP Dungeon",Inputs!$B$4="Hero Dungeon")),CHOOSE(ArtifactsInput!$N$14+1,10,12,14,16,18,20),0)
A43: Old Music Box — Attack % (content-type uptime assumption) | B43: =IF(ArtifactsInput!$M$21,CHOOSE(ArtifactsInput!$N$21+1,25,30,35,40,45,50)*(IF(OR(Inputs!$B$4="Chapter Hunt",Inputs!$B$4="Breakthrough",Inputs!$B$4="Weapon Dungeon",Inputs!$B$4="Equipment Dungeon",Inputs!$B$4="Enhancement Dungeon",Inputs!$B$4="EXP Dungeon",Inputs!$B$4="Hero Dungeon"),0,IF(OR(Inputs!$B$4="World Boss",Inputs!$B$4="PvP"),1,IF(Inputs!$B$4="Chapter Boss",60/70,0)))),0)
...

Sheet Calc
A1: Key | B1: Name | C1: Unlocked | D1: InputLevel | E1: Factor | F1: CoefficientPercent | G1: EffectiveHits | H1: ProcProbability | I1: MapleHeroMultiplier | J1: BaseDamage | K1: BaseHitDamage | L1: NonCritAvg | M1: CritAvg | N1: ExpectedDamage(perHit) | O1: DPS | P1: % of Total | Q1: InvCooldown | R1: CastsInFight | S1: HitRate(perSec) | T1: BossOnlyDPS | V1: NormalOnlyDPS
A2: =Skills!A2 | B2: =Skills!B2 | C2: =Inputs!$B$3>=100 | F2: =Summary!$B$10+Skills!O2 | G2: =Skills!G2*IF(Skills!H2>0,INT(IF(Inputs!$B$38="pvp",MIN(Skills!I2,15),Skills!I2)/Skills!H2+0.000000001),1) | H2: =1-(1-Skills!J2/100)^Skills!K2 | I2: 1 | J2: =Summary!$B$6*(F2/100) | K2: =J2*(1+Summary!$B$7/100)*(1+Inputs!$B$15/100)*(1+Inputs!$B$16/100)*(5000/(6000+Inputs!$B$42*(1-Inputs!$B$19/100)))*(1+(Inputs!$B$24+Summary!$B$21)/100)*(1+Artifacts!$B$34/100)*(1+(IF(Skills!A2="EIGHT_LEGS_EASTON",Inputs!$B$17+Artifacts!$B$40,Inputs!$B$18+Artifacts!$B$39))/100)*(Summary!$B$13*(1+Artifacts!$B$38/100)*I2) | L2: =K2*(MIN(Inputs!$B$22,Inputs!$B$23)/100+Inputs!$B$23/100)/2 | M2: =L2*(1+(Inputs!$B$10+Summary!$B$20+Artifacts!$B$33)/100) | N2: =L2*(1-MIN((Inputs!$B$9+Summary!$B$14+Artifacts!$B$32),100)/100)+M2*(MIN((Inputs!$B$9+Summary!$B$14+Artifacts!$B$32),100)/100) | O2: =(1-Summary!$B$11)*T2+Summary!$B$11*V2 | P2: =IF(Summary!$B$3=0,0,O2/Summary!$B$3) | Q2: 0 | R2: 0 | S2: =IFERROR(O2/N2,0) | T2: =IF(C2,(Skills!G2*N2*Summary!$B$19*(1+IF(C27=TRUE,1/3,0)))*IF(Inputs!$B$38="pvp",1,1+(Inputs!$B$20+Skills!P2+Summary!$B$15+Artifacts!$B$35)/100)*((((5000/(6000+Inputs!$B$42*(1-(100*(1-(1-Inputs!$B$19/100)*(1-Artifacts!$B$51/100)^IF(Inputs!$B$38="pvp",1,2)))/100)))/(5000/(6000+Inputs!$B$42*(1-Inputs!$B$19/100))))*((L2*(1-MIN(100,(Inputs!$B$9+Summary!$B$14+Artifacts!$B$32)+Artifacts!$B$69)/100)+M2*(MIN(100,(Inputs!$B$9+Summary!$B$14+Artifacts!$B$32)+Artifacts!$B$69)/100))/(L2*(1-MIN(100,(Inputs!$B$9+Summary!$B$14+Artifacts!$B$32))/100)+M2*(MIN(100,(Inputs!$B$9+Summary!$B$14+Artifacts!$B$32))/100)))*(1+Artifacts!$B$81/100))),0) | V2: =IF(C2,(Skills!G2*N2*Summary!$B$19*(1+IF(C27=TRUE,1/3,0)))*IF(Inputs!$B$38="pvp",1,(1+(Inputs!$B$21+Skills!Q2+Summary!$B$15+Artifacts!$B$80)/100)*(MIN(Skills!R2,Inputs!$B$37)))*((1+Artifacts!$B$53/100)),0)
A3: =Skills!A3 | B3: =Skills!B3 | C3: =Inputs!$B$3>=33 | D3: =IF(Skills!C3=1,60+Inputs!$B$25+Inputs!$B$29,IF(Skills!C3=2,90+Inputs!$B$26+Inputs!$B$29,IF(Skills!C3=3,120+Inputs!$B$27+Inputs!$B$29,MAX(0,(Inputs!$B$3-100)*3)+Inputs!$B$28+Inputs!$B$29))) | E3: =INDEX(FactorTable!$B$2:$Y$301, MATCH(ROUND(MIN(300,MAX(1,D3)),0), FactorTable!$A$2:$A$301,0), Skills!M3+1) | F3: =IF(Skills!N3=TRUE,(Skills!L3/10)*(E3/1000),Skills!L3/10)+Skills!O3 | G3: =Skills!G3*IF(Skills!H3>0,INT(IF(Inputs!$B$38="pvp",MIN(Skills!I3,15),Skills!I3)/Skills!H3+0.000000001),1) | H3: =1-(1-Skills!J3/100)^Skills!K3 | I3: 1 | J3: =Summary!$B$6*(F3/100) | K3: =J3*(1+Summary!$B$7/100)*(1+Inputs!$B$15/100)*(1+Inputs!$B$16/100)*(5000/(6000+Inputs!$B$42*(1-Inputs!$B$19/100)))*(1+(Inputs!$B$24+Summary!$B$21)/100)*(1+Artifacts!$B$34/100)*(1+4.0*IF(C15=TRUE,F15,0)/100)*(1+(IF(Skills!A3="EIGHT_LEGS_EASTON",Inputs!$B$17+Artifacts!$B$40,Inputs!$B$18+Artifacts!$B$39))/100)*(Summary!$B$13*(1+Artifacts!$B$38/100)*I3) | L3: =K3*(MIN(Inputs!$B$22,Inputs!$B$23)/100+Inputs!$B$23/100)/2 | M3: =L3*(1+(Inputs!$B$10+Summary!$B$20+Artifacts!$B$33)/100) | N3: =L3*(1-MIN((Inputs!$B$9+Summary!$B$14+Artifacts!$B$32),100)/100)+M3*(MIN((Inputs!$B$9+Summary!$B$14+Artifacts!$B$32),100)/100) | O3: =(1-Summary!$B$11)*T3+Summary!$B$11*V3 | P3: =IF(Summary!$B$3=0,0,O3/Summary!$B$3) | Q3: =IFERROR(1/(IF(Inputs!$B$38="pvp",15,MAX(0.1,Skills!D3-IF(TRUE=TRUE,Inputs!$B$32,0)))*(1-IF(AND(ArtifactsInput!$M$27,Inputs!$B$4="Chapter Hunt"),CHOOSE(ArtifactsInput!$N$27+1,20,24,28,32,36,40),0)/100)),0) | R3: =IF(AND(Inputs!$B$38<>"pvp",Inputs!$B$43>0),IF(MAX(0,Inputs!$B$43-Summary!$B$23)<=0,0,(INT(MAX(0,Inputs!$B$43-Summary!$B$23)/(IF(Inputs!$B$38="pvp",15,MAX(0.1,Skills!D3-IF(TRUE=TRUE,Inputs!$B$32,0)))*(1-IF(AND(ArtifactsInput!$M$27,Inputs!$B$4="Chapter Hunt"),CHOOSE(ArtifactsInput!$N$27+1,20,24,28,32,36,40),0)/100)))+1)),0) | S3: =IFERROR(O3/N3,0) | T3: =IF(C3,(H3*N3*IF(AND(Inputs!$B$38<>"pvp",Inputs!$B$43>0),((Skills!G3*((R3-1)*IF(Skills!H3>0,INT(Skills!I3/Skills!H3+0.000000001),1)+IF(Skills!H3>0,INT(MIN(Skills!I3,MAX(0,MAX(0,Inputs!$B$43-Summary!$B$23)-((R3-1)*(IF(Inputs!$B$38="pvp",15,MAX(0.1,Skills!D3-IF(TRUE=TRUE,Inputs!$B$32,0)))*(1-IF(AND(ArtifactsInput!$M$27,Inputs!$B$4="Chapter Hunt"),CHOOSE(ArtifactsInput!$N$27+1,20,24,28,32,36,40),0)/100)))))/Skills!H3+0.000000001),1)))/Inputs!$B$43),G3*Q3))*IF(Inputs!$B$38="pvp",1,1+(Inputs!$B$20+Skills!P3+Summary!$B$15+Artifacts!$B$35)/100)*((((5000/(6000+Inputs!$B$42*(1-(100*(1-(1-Inputs!$B$19/100)*(1-Artifacts!$B$51/100)^IF(Inputs!$B$38="pvp",1,2)))/100)))/(5000/(6000+Inputs!$B$42*(1-Inputs!$B$19/100))))*((L3*(1-MIN(100,(Inputs!$B$9+Summary!$B$14+Artifacts!$B$32)+Artifacts!$B$69)/100)+M3*(MIN(100,(Inputs!$B$9+Summary!$B$14+Artifacts!$B$32)+Artifacts!$B$69)/100))/(L3*(1-MIN(100,(Inputs!$B$9+Summary!$B$14+Artifacts!$B$32))/100)+M3*(MIN(100,(Inputs!$B$9+Summary!$B$14+Artifacts!$B$32))/100)))*(1+Artifacts!$B$81/100))),0) | V3: =IF(C3,(H3*N3*IF(AND(Inputs!$B$38<>"pvp",Inputs!$B$43>0),((Skills!G3*((R3-1)*IF(Skills!H3>0,INT(Skills!I3/Skills!H3+0.000000001),1)+IF(Skills!H3>0,INT(MIN(Skills!I3,MAX(0,MAX(0,Inputs!$B$43-Summary!$B$23)-((R3-1)*(IF(Inputs!$B$38="pvp",15,MAX(0.1,Skills!D3-IF(TRUE=TRUE,Inputs!$B$32,0)))*(1-IF(AND(ArtifactsInput!$M$27,Inputs!$B$4="Chapter Hunt"),CHOOSE(ArtifactsInput!$N$27+1,20,24,28,32,36,40),0)/100)))))/Skills!H3+0.000000001),1)))/Inputs!$B$43),G3*Q3))*IF(Inputs!$B$38="pvp",1,(1+(Inputs!$B$21+Skills!Q3+Summary!$B$15+Artifacts!$B$80)/100)*(MIN(Skills!R3,Inputs!$B$37)))*((1+Artifacts!$B$53/100)),0)
A4: =Skills!A4 | B4: =Skills!B4 | C4: =Inputs!$B$3>=35 | D4: =IF(Skills!C4=1,60+Inputs!$B$25+Inputs!$B$29,IF(Skills!C4=2,90+Inputs!$B$26+Inputs!$B$29,IF(Skills!C4=3,120+Inputs!$B$27+Inputs!$B$29,MAX(0,(Inputs!$B$3-100)*3)+Inputs!$B$28+Inputs!$B$29))) | E4: =INDEX(FactorTable!$B$2:$Y$301, MATCH(ROUND(MIN(300,MAX(1,D4)),0), FactorTable!$A$2:$A$301,0), Skills!M4+1) | F4: =IF(Skills!N4=TRUE,(Skills!L4/10)*(E4/1000),Skills!L4/10)+Skills!O4 | G4: =Skills!G4*IF(Skills!H4>0,INT(IF(Inputs!$B$38="pvp",MIN(IF(Inputs!$B$3>=104,MIN(35,20*(1+Inputs!$B$34/100)),20),15),IF(Inputs!$B$3>=104,MIN(35,20*(1+Inputs!$B$34/100)),20))/Skills!H4+0.000000001),1) | H4: =1-(1-Skills!J4/100)^Skills!K4 | I4: 1 | J4: =Summary!$B$6*(F4/100) | K4: =J4*(1+Summary!$B$7/100)*(1+Inputs!$B$15/100)*(1+Inputs!$B$16/100)*(5000/(6000+Inputs!$B$42*(1-Inputs!$B$19/100)))*(1+(Inputs!$B$24+Summary!$B$21)/100)*(1+Artifacts!$B$34/100)*(1+1.0*IF(C16=TRUE,F16,0)/100)*(1+(IF(Skills!A4="EIGHT_LEGS_EASTON",Inputs!$B$17+Artifacts!$B$40,Inputs!$B$18+Artifacts!$B$39))/100)*(Summary!$B$13*(1+Artifacts!$B$38/100)*I4) | L4: =K4*(MIN(Inputs!$B$22,Inputs!$B$23)/100+Inputs!$B$23/100)/2 | M4: =L4*(1+(Inputs!$B$10+Summary!$B$20+Artifacts!$B$33)/100) | N4: =L4*(1-MIN((Inputs!$B$9+Summary!$B$14+Artifacts!$B$32),100)/100)+M4*(MIN((Inputs!$B$9+Summary!$B$14+Artifacts!$B$32),100)/100) | O4: =(1-Summary!$B$11)*T4+Summary!$B$11*V4 | P4: =IF(Summary!$B$3=0,0,O4/Summary!$B$3) | Q4: =IFERROR(1/(IF(Inputs!$B$38="pvp",15,MAX(0.1,Skills!D4-IF(TRUE=TRUE,Inputs!$B$32,0)))*(1-IF(AND(ArtifactsInput!$M$27,Inputs!$B$4="Chapter Hunt"),CHOOSE(ArtifactsInput!$N$27+1,20,24,28,32,36,40),0)/100)),0) | R4: =IF(AND(Inputs!$B$38<>"pvp",Inputs!$B$43>0),IF(MAX(0,Inputs!$B$43-Summary!$B$23)<=0,0,(INT(MAX(0,Inputs!$B$43-Summary!$B$23)/(IF(Inputs!$B$38="pvp",15,MAX(0.1,Skills!D4-IF(TRUE=TRUE,Inputs!$B$32,0)))*(1-IF(AND(ArtifactsInput!$M$27,Inputs!$B$4="Chapter Hunt"),CHOOSE(ArtifactsInput!$N$27+1,20,24,28,32,36,40),0)/100)))+1)),0) | S4: =IFERROR(O4/N4,0) | T4: =IF(C4,(H4*N4*IF(AND(Inputs!$B$38<>"pvp",Inputs!$B$43>0),((Skills!G4*((R4-1)*IF(Skills!H4>0,INT(IF(Inputs!$B$3>=104,MIN(35,20*(1+Inputs!$B$34/100)),20)/Skills!H4+0.000000001),1)+IF(Skills!H4>0,INT(MIN(IF(Inputs!$B$3>=104,MIN(35,20*(1+Inputs!$B$34/100)),20),MAX(0,MAX(0,Inputs!$B$43-Summary!$B$23)-((R4-1)*(IF(Inputs!$B$38="pvp",15,MAX(0.1,Skills!D4-IF(TRUE=TRUE,Inputs!$B$32,0)))*(1-IF(AND(ArtifactsInput!$M$27,Inputs!$B$4="Chapter Hunt"),CHOOSE(ArtifactsInput!$N$27+1,20,24,28,32,36,40),0)/100)))))/Skills!H4+0.000000001),1)))/Inputs!$B$43),G4*Q4))*IF(Inputs!$B$38="pvp",1,1+(Inputs!$B$20+Skills!P4+Summary!$B$15+Artifacts!$B$35)/100)*((((5000/(6000+Inputs!$B$42*(1-(100*(1-(1-Inputs!$B$19/100)*(1-Artifacts!$B$51/100)^IF(Inputs!$B$38="pvp",1,2)))/100)))/(5000/(6000+Inputs!$B$42*(1-Inputs!$B$19/100))))*((L4*(1-MIN(100,(Inputs!$B$9+Summary!$B$14+Artifacts!$B$32)+Artifacts!$B$69)/100)+M4*(MIN(100,(Inputs!$B$9+Summary!$B$14+Artifacts!$B$32)+Artifacts!$B$69)/100))/(L4*(1-MIN(100,(Inputs!$B$9+Summary!$B$14+Artifacts!$B$32))/100)+M4*(MIN(100,(Inputs!$B$9+Summary!$B$14+Artifacts!$B$32))/100)))*(1+Artifacts!$B$81/100))),0) | V4: =IF(C4,(H4*N4*IF(AND(Inputs!$B$38<>"pvp",Inputs!$B$43>0),((Skills!G4*((R4-1)*IF(Skills!H4>0,INT(IF(Inputs!$B$3>=104,MIN(35,20*(1+Inputs!$B$34/100)),20)/Skills!H4+0.000000001),1)+IF(Skills!H4>0,INT(MIN(IF(Inputs!$B$3>=104,MIN(35,20*(1+Inputs!$B$34/100)),20),MAX(0,MAX(0,Inputs!$B$43-Summary!$B$23)-((R4-1)*(IF(Inputs!$B$38="pvp",15,MAX(0.1,Skills!D4-IF(TRUE=TRUE,Inputs!$B$32,0)))*(1-IF(AND(ArtifactsInput!$M$27,Inputs!$B$4="Chapter Hunt"),CHOOSE(ArtifactsInput!$N$27+1,20,24,28,32,36,40),0)/100)))))/Skills!H4+0.000000001),1)))/Inputs!$B$43),G4*Q4))*IF(Inputs!$B$38="pvp",1,(1+(Inputs!$B$21+Skills!Q4+Summary!$B$15+Artifacts!$B$80)/100)*(MIN(Skills!R4,Inputs!$B$37)))*((1+Artifacts!$B$53/100)),0)
A5: =Skills!A5 | B5: =Skills!B5 | C5: =Inputs!$B$3>=69 | D5: =IF(Skills!C5=1,60+Inputs!$B$25+Inputs!$B$29,IF(Skills!C5=2,90+Inputs!$B$26+Inputs!$B$29,IF(Skills!C5=3,120+Inputs!$B$27+Inputs!$B$29,MAX(0,(Inputs!$B$3-100)*3)+Inputs!$B$28+Inputs!$B$29))) | E5: =INDEX(FactorTable!$B$2:$Y$301, MATCH(ROUND(MIN(300,MAX(1,D5)),0), FactorTable!$A$2:$A$301,0), Skills!M5+1) | F5: =IF(Skills!N5=TRUE,(Skills!L5/10)*(E5/1000),Skills!L5/10)+Skills!O5 | G5: =Skills!G5*IF(Skills!H5>0,INT(IF(Inputs!$B$38="pvp",MIN(IF(Inputs!$B$3>=104,MIN(35,20*(1+Inputs!$B$34/100)),20),15),IF(Inputs!$B$3>=104,MIN(35,20*(1+Inputs!$B$34/100)),20))/Skills!H5+0.000000001),1) | H5: =1-(1-Skills!J5/100)^Skills!K5 | I5: 1 | J5: =Summary!$B$6*(F5/100) | K5: =J5*(1+Summary!$B$7/100)*(1+Inputs!$B$15/100)*(1+Inputs!$B$16/100)*(5000/(6000+Inputs!$B$42*(1-Inputs!$B$19/100)))*(1+(Inputs!$B$24+Summary!$B$21)/100)*(1+Artifacts!$B$34/100)*(1+0.4*IF(C16=TRUE,F16,0)/100)*(1+(IF(Skills!A5="EIGHT_LEGS_EASTON",Inputs!$B$17+Artifacts!$B$40,Inputs!$B$18+Artifacts!$B$39))/100)*(Summary!$B$13*(1+Artifacts!$B$38/100)*I5) | L5: =K5*(MIN(Inputs!$B$22,Inputs!$B$23)/100+Inputs!$B$23/100)/2 | M5: =L5*(1+(Inputs!$B$10+Summary!$B$20+Artifacts!$B$33)/100) | N5: =L5*(1-MIN((Inputs!$B$9+Summary!$B$14+Artifacts!$B$32),100)/100)+M5*(MIN((Inputs!$B$9+Summary!$B$14+Artifacts!$B$32),100)/100) | O5: =(1-Summary!$B$11)*T5+Summary!$B$11*V5 | P5: =IF(Summary!$B$3=0,0,O5/Summary!$B$3) | Q5: =IFERROR(1/(IF(Inputs!$B$38="pvp",15,MAX(0.1,Skills!D5-IF(TRUE=TRUE,Inputs!$B$32,0)))*(1-IF(AND(ArtifactsInput!$M$27,Inputs!$B$4="Chapter Hunt"),CHOOSE(ArtifactsInput!$N$27+1,20,24,28,32,36,40),0)/100)),0) | R5: =IF(AND(Inputs!$B$38<>"pvp",Inputs!$B$43>0),IF(MAX(0,Inputs!$B$43-Summary!$B$23)<=0,0,(INT(MAX(0,Inputs!$B$43-Summary!$B$23)/(IF(Inputs!$B$38="pvp",15,MAX(0.1,Skills!D5-IF(TRUE=TRUE,Inputs!$B$32,0)))*(1-IF(AND(ArtifactsInput!$M$27,Inputs!$B$4="Chapter Hunt"),CHOOSE(ArtifactsInput!$N$27+1,20,24,28,32,36,40),0)/100)))+1)),0) | S5: =IFERROR(O5/N5,0) | T5: =IF(C5,(H5*N5*IF(AND(Inputs!$B$38<>"pvp",Inputs!$B$43>0),((Skills!G5*((R5-1)*IF(Skills!H5>0,INT(IF(Inputs!$B$3>=104,MIN(35,20*(1+Inputs!$B$34/100)),20)/Skills!H5+0.000000001),1)+IF(Skills!H5>0,INT(MIN(IF(Inputs!$B$3>=104,MIN(35,20*(1+Inputs!$B$34/100)),20),MAX(0,MAX(0,Inputs!$B$43-Summary!$B$23)-((R5-1)*(IF(Inputs!$B$38="pvp",15,MAX(0.1,Skills!D5-IF(TRUE=TRUE,Inputs!$B$32,0)))*(1-IF(AND(ArtifactsInput!$M$27,Inputs!$B$4="Chapter Hunt"),CHOOSE(ArtifactsInput!$N$27+1,20,24,28,32,36,40),0)/100)))))/Skills!H5+0.000000001),1)))/Inputs!$B$43),G5*Q5))*IF(Inputs!$B$38="pvp",1,1+(Inputs!$B$20+Skills!P5+Summary!$B$15+Artifacts!$B$35)/100)*((((5000/(6000+Inputs!$B$42*(1-(100*(1-(1-Inputs!$B$19/100)*(1-Artifacts!$B$51/100)^IF(Inputs!$B$38="pvp",1,2)))/100)))/(5000/(6000+Inputs!$B$42*(1-Inputs!$B$19/100))))*((L5*(1-MIN(100,(Inputs!$B$9+Summary!$B$14+Artifacts!$B$32)+Artifacts!$B$69)/100)+M5*(MIN(100,(Inputs!$B$9+Summary!$B$14+Artifacts!$B$32)+Artifacts!$B$69)/100))/(L5*(1-MIN(100,(Inputs!$B$9+Summary!$B$14+Artifacts!$B$32))/100)+M5*(MIN(100,(Inputs!$B$9+Summary!$B$14+Artifacts!$B$32))/100)))*(1+Artifacts!$B$81/100))),0) | V5: =IF(C5,(H5*N5*IF(AND(Inputs!$B$38<>"pvp",Inputs!$B$43>0),((Skills!G5*((R5-1)*IF(Skills!H5>0,INT(IF(Inputs!$B$3>=104,MIN(35,20*(1+Inputs!$B$34/100)),20)/Skills!H5+0.000000001),1)+IF(Skills!H5>0,INT(MIN(IF(Inputs!$B$3>=104,MIN(35,20*(1+Inputs!$B$34/100)),20),MAX(0,MAX(0,Inputs!$B$43-Summary!$B$23)-((R5-1)*(IF(Inputs!$B$38="pvp",15,MAX(0.1,Skills!D5-IF(TRUE=TRUE,Inputs!$B$32,0)))*(1-IF(AND(ArtifactsInput!$M$27,Inputs!$B$4="Chapter Hunt"),CHOOSE(ArtifactsInput!$N$27+1,20,24,28,32,36,40),0)/100)))))/Skills!H5+0.000000001),1)))/Inputs!$B$43),G5*Q5))*IF(Inputs!$B$38="pvp",1,(1+(Inputs!$B$21+Skills!Q5+Summary!$B$15+Artifacts!$B$80)/100)*(MIN(Skills!R5,Inputs!$B$37)))*((1+Artifacts!$B$53/100)),0)
A6: =Skills!A6 | B6: =Skills!B6 | C6: =Inputs!$B$3>=66 | D6: =IF(Skills!C6=1,60+Inputs!$B$25+Inputs!$B$29,IF(Skills!C6=2,90+Inputs!$B$26+Inputs!$B$29,IF(Skills!C6=3,120+Inputs!$B$27+Inputs!$B$29,MAX(0,(Inputs!$B$3-100)*3)+Inputs!$B$28+Inputs!$B$29))) | E6: =INDEX(FactorTable!$B$2:$Y$301, MATCH(ROUND(MIN(300,MAX(1,D6)),0), FactorTable!$A$2:$A$301,0), Skills!M6+1) | F6: =IF(Skills!N6=TRUE,(Skills!L6/10)*(E6/1000),Skills!L6/10)+Skills!O6 | G6: =Skills!G6*IF(Skills!H6>0,INT(IF(Inputs!$B$38="pvp",MIN(Skills!I6,15),Skills!I6)/Skills!H6+0.000000001),1) | H6: =1-(1-Skills!J6/100)^Skills!K6 | I6: 1 | J6: =Summary!$B$6*(F6/100) | K6: =J6*(1+Summary!$B$7/100)*(1+Inputs!$B$15/100)*(1+Inputs!$B$16/100)*(5000/(6000+Inputs!$B$42*(1-Inputs!$B$19/100)))*(1+(Inputs!$B$24+Summary!$B$21)/100)*(1+Artifacts!$B$34/100)*(1+2.0*IF(C15=TRUE,F15,0)/100)*(1+(IF(Skills!A6="EIGHT_LEGS_EASTON",Inputs!$B$17+Artifacts!$B$40,Inputs!$B$18+Artifacts!$B$39))/100)*(Summary!$B$13*(1+Artifacts!$B$38/100)*I6) | L6: =K6*(MIN(Inputs!$B$22,Inputs!$B$23)/100+Inputs!$B$23/100)/2 | M6: =L6*(1+(Inputs!$B$10+Summary!$B$20+Artifacts!$B$33)/100) | N6: =L6*(1-MIN((Inputs!$B$9+Summary!$B$14+Artifacts!$B$32),100)/100)+M6*(MIN((Inputs!$B$9+Summary!$B$14+Artifacts!$B$32),100)/100) | O6: =(1-Summary!$B$11)*T6+Summary!$B$11*V6 | P6: =IF(Summary!$B$3=0,0,O6/Summary!$B$3) | Q6: =IFERROR(1/(IF(Inputs!$B$38="pvp",15,MAX(0.1,Skills!D6-IF(TRUE=TRUE,Inputs!$B$32,0)))*(1-IF(AND(ArtifactsInput!$M$27,Inputs!$B$4="Chapter Hunt"),CHOOSE(ArtifactsInput!$N$27+1,20,24,28,32,36,40),0)/100)),0) | R6: =IF(AND(Inputs!$B$38<>"pvp",Inputs!$B$43>0),IF(MAX(0,Inputs!$B$43-Summary!$B$23)<=0,0,(INT(MAX(0,Inputs!$B$43-Summary!$B$23)/(IF(Inputs!$B$38="pvp",15,MAX(0.1,Skills!D6-IF(TRUE=TRUE,Inputs!$B$32,0)))*(1-IF(AND(ArtifactsInput!$M$27,Inputs!$B$4="Chapter Hunt"),CHOOSE(ArtifactsInput!$N$27+1,20,24,28,32,36,40),0)/100)))+1)),0) | S6: =IFERROR(O6/N6,0) | T6: =IF(C6,(H6*N6*IF(AND(Inputs!$B$38<>"pvp",Inputs!$B$43>0),((Skills!G6*((R6-1)*IF(Skills!H6>0,INT(Skills!I6/Skills!H6+0.000000001),1)+IF(Skills!H6>0,INT(MIN(Skills!I6,MAX(0,MAX(0,Inputs!$B$43-Summary!$B$23)-((R6-1)*(IF(Inputs!$B$38="pvp",15,MAX(0.1,Skills!D6-IF(TRUE=TRUE,Inputs!$B$32,0)))*(1-IF(AND(ArtifactsInput!$M$27,Inputs!$B$4="Chapter Hunt"),CHOOSE(ArtifactsInput!$N$27+1,20,24,28,32,36,40),0)/100)))))/Skills!H6+0.000000001),1)))/Inputs!$B$43),G6*Q6))*IF(Inputs!$B$38="pvp",1,1+(Inputs!$B$20+Skills!P6+Summary!$B$15+Artifacts!$B$35)/100)*((((5000/(6000+Inputs!$B$42*(1-(100*(1-(1-Inputs!$B$19/100)*(1-Artifacts!$B$51/100)^IF(Inputs!$B$38="pvp",1,2)))/100)))/(5000/(6000+Inputs!$B$42*(1-Inputs!$B$19/100))))*((L6*(1-MIN(100,(Inputs!$B$9+Summary!$B$14+Artifacts!$B$32)+Artifacts!$B$69)/100)+M6*(MIN(100,(Inputs!$B$9+Summary!$B$14+Artifacts!$B$32)+Artifacts!$B$69)/100))/(L6*(1-MIN(100,(Inputs!$B$9+Summary!$B$14+Artifacts!$B$32))/100)+M6*(MIN(100,(Inputs!$B$9+Summary!$B$14+Artifacts!$B$32))/100)))*(1+Artifacts!$B$81/100))),0) | V6: =IF(C6,(H6*N6*IF(AND(Inputs!$B$38<>"pvp",Inputs!$B$43>0),((Skills!G6*((R6-1)*IF(Skills!H6>0,INT(Skills!I6/Skills!H6+0.000000001),1)+IF(Skills!H6>0,INT(MIN(Skills!I6,MAX(0,MAX(0,Inputs!$B$43-Summary!$B$23)-((R6-1)*(IF(Inputs!$B$38="pvp",15,MAX(0.1,Skills!D6-IF(TRUE=TRUE,Inputs!$B$32,0)))*(1-IF(AND(ArtifactsInput!$M$27,Inputs!$B$4="Chapter Hunt"),CHOOSE(ArtifactsInput!$N$27+1,20,24,28,32,36,40),0)/100)))))/Skills!H6+0.000000001),1)))/Inputs!$B$43),G6*Q6))*IF(Inputs!$B$38="pvp",1,(1+(Inputs!$B$21+Skills!Q6+Summary!$B$15+Artifacts!$B$80)/100)*(MIN(Skills!R6,Inputs!$B$37)))*((1+Artifacts!$B$53/100)),0)
