Workbook

Sheet README
A1: Fire/Poison Arch Mage — DPS Calculator: How to Use This Workbook
A3: How to use this workbook
A4: Only edit the yellow-highlighted cells on the Inputs sheet — every other sheet is computed from those values and will be overwritten if you rebuild the workbook.
A5: Summary shows Total DPS, a Per-Skill DPS Breakdown (damage-dealing skills only — buffs/passives that never deal their own damage are omitted), and a Marginal DPS & Stat Value table showing the DPS gained per +1 of each stat.
A6: Sensitivity has the full detail behind that marginal-value table — one self-contained block per stat, showing exactly how bumping that stat by +1 changes every downstream number.
A7: CubeData/PotentialCubes model your current gear's Potential Cube lines and drive cube-reroll expected-value decisions. For the full standalone Potential Cube EV calculator (exact optimal-stopping math, works from this workbook alone), see tools/potential_cubes_ev.py in the project repo.
A9: Design decisions & assumptions
A10: Poison/DoT skills (Poison Breath, Poison Mist, Creeping Toxin, Ignite) and Burning Magic/Elemental Decrease assume the target is permanently afflicted at steady state, not an exact on/off timer.
A11: Crit Rate pushed above 100% (e.g. by cube potential lines) automatically redirects its stat-value to Crit Damage's own per-unit DPS value on the PotentialCubes sheet, since excess Crit Rate cannot do anything past 100%.
A12: Buffs (Meditation, Magic Guard, Infinity, Nimble Feet) are modeled at steady-state duty-cycle average uptime, not as an exact moment-to-moment state machine.
A13: Meteor Proc's trigger rate is the combined cast rate of every attack that can trigger it (including Basic Attack), averaged rather than simulated hit-by-hit.
A14: Ifrit is a summon skill (own cooldown/duration/DoT-tick mechanism), not part of the game's separate Companion roster system — its damage is modeled as a real DPS source like any other skill.
... A16: Not modeled (out of scope): crowd control, Accuracy/Evasion/Defense reduction, movement speed, the character's own Defense stat, and Companion Summoning Time (the Companion roster system, unrelated to Ifrit).

Sheet Inputs
A1: Fire/Poison Arch Mage — DPS Calculator Inputs | N1: (none)
C2: Chapter Boss | D2: Breakthrough | E2: PvP | F2: EXP Dungeon | G2: Equipment Dungeon | H2: Weapon Dungeon | I2: Enhancement Dungeon | J2: Hero Dungeon | K2: World Boss | L2: Chapter Hunt | N2: Charm of the Undead
A3: Character Level | B3: 117 | N3: Pig's Ribbon
A4: Content Type | B4: Breakthrough | N4: Shamaness Marble
A5: Chapter-Stage — 'chapter-substage' (e.g. '28-9') for Breakthrough/Chapter Hunt, just the chapter number for Chapter Boss, or just the stage number for Weapon/Equipment/Enhancement/EXP/Hero Dungeon. Not applicable to World Boss/PvP. | B5: =INDEX($C$5:$L$5,MATCH($B$4,$C$2:$L$2,0)) | C5: 36 | D5: 36-6 | F5: 112 | G5: 110 | H5: 112 | I5: 92 | J5: 111 | L5: 36-5 | N5: The Contract of Darkness
A6: Flat ATTACK | B6: =INDEX($C$6:$L$6,MATCH($B$4,$C$2:$L$2,0)) | C6: 972067 | D6: 1030606 | E6: 972067 | F6: 1066466 | G6: 972067 | H6: 1018641 | I6: 972067 | J6: 972067 | K6: 1069391 | L6: 972067 | N6: Rainbow-colored Snail Shell
A7: ATTACK % | B7: =INDEX($C$7:$L$7,MATCH($B$4,$C$2:$L$2,0)) | C7: 32236.6 | D7: 32663.8 | E7: 32236.6 | F7: 32236.6 | G7: 32236.6 | H7: 32236.6 | I7: 32236.6 | J7: 32236.6 | K7: 32236.6 | L7: 32236.6 | N7: Hexagon Necklace
A8: Defense (your own DEF stat; PvP assumes the opponent has the same Defense as you) | B8: =INDEX($C$8:$L$8,MATCH($B$4,$C$2:$L$2,0)) | C8: 54763 | D8: 55812 | E8: 54763 | F8: 54763 | G8: 54763 | H8: 54763 | I8: 54763 | J8: 54763 | K8: 54763 | L8: 54763 | N8: Arwen's Glass Shoes
A9: CRIT_RATE % | B9: =INDEX($C$9:$L$9,MATCH($B$4,$C$2:$L$2,0)) | C9: 172.8 | D9: 191.7 | E9: 172.8 | F9: 177.6 | G9: 172.8 | H9: 153.8 | I9: 172.8 | J9: 172.8 | K9: 146.8 | L9: 172.8 | N9: Mushmom's Cap
A10: CRIT_DAMAGE % | B10: =INDEX($C$10:$L$10,MATCH($B$4,$C$2:$L$2,0)) | C10: 327.6 | D10: 346.9 | E10: 327.6 | F10: 322.9 | G10: 327.6 | H10: 351.3 | I10: 327.6 | J10: 327.6 | K10: 295.8 | L10: 327.6 | N10: Clear Spring Water
A11: ATTACK_SPEED % (base, excludes Nimble Feet) | B11: =INDEX($C$11:$L$11,MATCH($B$4,$C$2:$L$2,0)) | C11: 70 | D11: 69.9 | E11: 70 | F11: 61.5 | G11: 70 | H11: 61.7 | I11: 70 | J11: 70 | K11: 71.9 | L11: 70 | N11: Athena Pierce's Old Gloves
A12: Flat INT | B12: =INDEX($C$12:$L$12,MATCH($B$4,$C$2:$L$2,0)) | C12: 59700 | D12: 64664 | E12: 59700 | F12: 63549 | G12: 59700 | H12: 63549 | I12: 59700 | J12: 59700 | K12: 63234 | L12: 59700 | N12: Zakum's Stone Piece
A13: INT % | B13: =INDEX($C$13:$L$13,MATCH($B$4,$C$2:$L$2,0)) | C13: 248.1 | D13: 253.7 | E13: 248.1 | F13: 243 | G13: 248.1 | H13: 262.3 | I13: 248.1 | J13: 248.1 | K13: 248.3 | L13: 248.1 | N13: Horntail's Scale
A14: LUK | B14: =INDEX($C$14:$L$14,MATCH($B$4,$C$2:$L$2,0)) | C14: 944 | D14: 896 | E14: 944 | F14: 944 | G14: 944 | H14: 944 | I14: 944 | J14: 944 | K14: 944 | L14: 944 | N14: Pink Bean's Giant Rib
A15: DAMAGE % | B15: =INDEX($C$15:$L$15,MATCH($B$4,$C$2:$L$2,0)) | C15: 957.7 | D15: 930.9 | E15: 957.7 | F15: 902 | G15: 957.7 | H15: 904.4 | I15: 957.7 | J15: 957.7 | K15: 912.2 | L15: 957.7 | N15: Chalice
A16: DAMAGE_AMP % | B16: =INDEX($C$16:$L$16,MATCH($B$4,$C$2:$L$2,0)) | C16: 85.7 | D16: 87.6 | E16: 85.7 | F16: 85.7 | G16: 85.7 | H16: 85.7 | I16: 85.7 | J16: 85.7 | K16: 85.7 | L16: 85.7 | N16: Old Music Box
A17: BASIC_ATTACK_DAMAGE % | B17: =INDEX($C$17:$L$17,MATCH($B$4,$C$2:$L$2,0)) | C17: 45.6 | D17: 34.6 | E17: 45.6 | F17: 33.6 | G17: 45.6 | H17: 33.6 | I17: 45.6 | J17: 45.6 | K17: 31.6 | L17: 45.6 | N17: Silver Pendant
A18: SKILL_DAMAGE % | B18: =INDEX($C$18:$L$18,MATCH($B$4,$C$2:$L$2,0)) | C18: 105.4 | D18: 105.4 | E18: 105.4 | F18: 105.4 | G18: 105.4 | H18: 104.6 | I18: 105.4 | J18: 105.4 | K18: 104.6 | L18: 105.4 | N18: Star Rock
A19: DEF_PEN % | B19: =INDEX($C$19:$L$19,MATCH($B$4,$C$2:$L$2,0)) | C19: 49.6 | D19: 44.8 | E19: 49.6 | F19: 45.1 | G19: 49.6 | H19: 41.1 | I19: 49.6 | J19: 49.6 | K19: 66.8 | L19: 49.6 | N19: Book of Ancient
A20: BOSS_DAMAGE % | B20: =INDEX($C$20:$L$20,MATCH($B$4,$C$2:$L$2,0)) | C20: 192.1 | D20: 228.5 | E20: 192.1 | F20: 66 | G20: 192.1 | H20: 379.3 | I20: 192.1 | J20: 192.1 | K20: 248.5 | L20: 192.1 | N20: Lunar Dew
A21: NORMAL_DAMAGE % | B21: =INDEX($C$21:$L$21,MATCH($B$4,$C$2:$L$2,0)) | C21: 223.8 | D21: 214.6 | E21: 223.8 | F21: 356.1 | G21: 223.8 | H21: 72 | I21: 223.8 | J21: 223.8 | K21: 52 | L21: 223.8 | N21: Fire Flower
A22: MIN_DAMAGE % | B22: =INDEX($C$22:$L$22,MATCH($B$4,$C$2:$L$2,0)) | C22: 307.7 | D22: 309.5 | E22: 307.7 | F22: 285.8 | G22: 307.7 | H22: 245.9 | I22: 307.7 | J22: 307.7 | K22: 208.9 | L22: 307.7 | N22: Soul Contract
A23: MAX_DAMAGE % | B23: =INDEX($C$23:$L$23,MATCH($B$4,$C$2:$L$2,0)) | C23: 313.5 | D23: 307.4 | E23: 313.5 | F23: 292.6 | G23: 313.5 | H23: 314.4 | I23: 313.5 | J23: 313.5 | K23: 268.4 | L23: 313.5 | N23: Lit Lamp
A24: FINAL_DAMAGE % (base, excludes Infinity) | B24: =INDEX($C$24:$L$24,MATCH($B$4,$C$2:$L$2,0)) | C24: 91.4 | D24: 104.3 | E24: 91.4 | F24: 134.9 | G24: 91.4 | H24: 133.6 | I24: 91.4 | J24: 91.4 | K24: 97.9 | L24: 91.4 | N24: Soul Pouch
A25: Skill Level Bonus — 1st Job | B25: =INDEX($C$25:$L$25,MATCH($B$4,$C$2:$L$2,0)) | C25: 0 | D25: 12 | E25: 0 | F25: 12 | G25: 0 | H25: 0 | I25: 0 | J25: 0 | K25: 0 | L25: 0 | N25: Ancient Text Piece
A26: Skill Level Bonus — 2nd Job | B26: =INDEX($C$26:$L$26,MATCH($B$4,$C$2:$L$2,0)) | C26: 19 | D26: 13 | E26: 19 | F26: 21 | G26: 19 | H26: 35 | I26: 19 | J26: 19 | K26: 35 | L26: 19 | N26: Icy Soul Rock
A27: Skill Level Bonus — 3rd Job | B27: =INDEX($C$27:$L$27,MATCH($B$4,$C$2:$L$2,0)) | C27: 22 | D27: 9 | E27: 22 | F27: 23 | G27: 22 | H27: 9 | I27: 22 | J27: 22 | K27: 9 | L27: 22 | N27: Flaming Lava
A28: Skill Level Bonus — 4th Job | B28: =INDEX($C$28:$L$28,MATCH($B$4,$C$2:$L$2,0)) | C28: 54 | D28: 45 | E28: 54 | F28: 46 | G28: 54 | H28: 63 | I28: 54 | J28: 54 | K28: 76 | L28: 54 | N28: Sayram's Necklace
A29: Skill Level Bonus — All Skills | B29: =INDEX($C$29:$L$29,MATCH($B$4,$C$2:$L$2,0)) | C29: 55 | D29: 55 | E29: 55 | F29: 55 | G29: 55 | H29: 55 | I29: 55 | J29: 55 | K29: 55 | L29: 55 | N29: Bottle of Emotion
N30: Peach Tree Herb Pouch
A31: Additional Bonuses | N31: Candle
A32: Skill Cooldown Decrease (seconds, only skills/buffs the character actively casts) | B32: =INDEX($C$32:$L$32,MATCH($B$4,$C$2:$L$2,0)) | C32: 0 | D32: 0 | E32: 0 | F32: 0 | G32: 0 | H32: 0 | I32: 0 | J32: 0 | K32: 0 | L32: 0 | N32: Alliance Badge
A33: Basic Attack Target Increase (flat, adds to the 6-target normal-monster base) | B33: =INDEX($C$33:$L$33,MATCH($B$4,$C$2:$L$2,0)) | C33: 6 | D33: 6 | E33: 6 | F33: 6 | G33: 6 | H33: 6 | I33: 6 | J33: 6 | K33: 6 | L33: 6 | N33: Horn Flute
A34: Buff Duration Increase % | B34: =INDEX($C$34:$L$34,MATCH($B$4,$C$2:$L$2,0)) | C34: 20 | D34: 34.5 | E34: 20 | F34: 20 | G34: 20 | H34: 20 | I34: 20 | J34: 20 | K34: 20 | L34: 20 | N34: Cursed Doll
A35: Companion Summoning Time Increase % (companions not modeled — always 0 DPS impact) | B35: =INDEX($C$35:$L$35,MATCH($B$4,$C$2:$L$2,0)) | C35: 0 | D35: 0 | E35: 0 | F35: 0 | G35: 0 | H35: 0 | I35: 0 | J35: 0 | K35: 0 | L35: 0 | N35: Reindeer's Spear
A36: Boss/Normal Emphasis (Breakthrough/Hero Dungeon only) | B36: =INDEX($C$36:$L$36,MATCH($B$4,$C$2:$L$2,0)) | D36: Equal | J36: Equal | N36: Secret Map
A37: Max Enemies Actually In Range (normal-monster content only; default 999 = uncapped) | B37: =INDEX($C$37:$L$37,MATCH($B$4,$C$2:$L$2,0)) | D37: 999 | F37: 999 | G37: 999 | J37: 999 | L37: 999 | N37: Ring of Cycles
A38: Monster Type (auto-computed from Content Type) — computed, do not edit | B38: =IF(Inputs!$B$4="PvP","pvp",IF(OR(Inputs!$B$4="Breakthrough",Inputs!$B$4="Hero Dungeon"),"breakthrough",IF(OR(Inputs!$B$4="EXP Dungeon",Inputs!$B$4="Equipment Dungeon",Inputs!$B$4="Chapter Hunt"),"normal","boss")))
A39: Chapter (parsed from Chapter-Stage) — computed, do not edit | B39: =IFERROR(IF(ISNUMBER(FIND("-",Inputs!$B$5)),VALUE(LEFT(Inputs!$B$5,FIND("-",Inputs!$B$5)-1)),VALUE(Inputs!$B$5)),28)
A40: Stage (parsed from Chapter-Stage) — computed, do not edit | B40: =IFERROR(IF(ISNUMBER(FIND("-",Inputs!$B$5)),VALUE(MID(Inputs!$B$5,FIND("-",Inputs!$B$5)+1,50)),VALUE(Inputs!$B$5)),9)
...

Sheet FactorTable
A1: Level | B1: F0 | C1: F1 | D1: F2 | E1: F3 | F1: F4 | G1: F5 | H1: F6 | I1: F7 | J1: F8 | K1: F9 | L1: F10 | M1: F11 | N1: F12 | O1: F13 | P1: F14 | Q1: F15 | R1: F16 | S1: F17 | T1: F18 | U1: F19 | V1: F20 | W1: F21 | X1: F22 | Y1: F23
A2: 1 | B2: 0 | C2: 1000 | D2: 1000 | E2: 1000 | F2: 1000 | G2: 1000 | H2: 1000 | I2: 1000 | J2: 1000 | K2: 1000 | L2: 1000 | M2: 1000 | N2: 1000 | O2: 1000 | P2: 1000 | Q2: 1000 | R2: 1000 | S2: 1000 | T2: 1000 | U2: 1000 | V2: 1000 | W2: 1000 | X2: 1000 | Y2: 1000
A3: 2 | B3: 0 | C3: 1015 | D3: 1020 | E3: 1030 | F3: 1040 | G3: 1050 | H3: 1060 | I3: 1070 | J3: 1020 | K3: 1020 | L3: 1020 | M3: 1000 | N3: 1010 | O3: 1020 | P3: 1030 | Q3: 1040 | R3: 1050 | S3: 1060 | T3: 1070 | U3: 1080 | V3: 1010 | W3: 1008 | X3: 1006 | Y3: 1100
A4: 3 | B4: 0 | C4: 1031 | D4: 1041 | E4: 1061 | F4: 1082 | G4: 1103 | H4: 1124 | I4: 1145 | J4: 1030 | K4: 1041 | L4: 1030 | M4: 1000 | N4: 1015 | O4: 1030 | P4: 1045 | Q4: 1060 | R4: 1075 | S4: 1090 | T4: 1105 | U4: 1120 | V4: 1020 | W4: 1012 | X4: 1009 | Y4: 1150
A5: 4 | B5: 0 | C5: 1047 | D5: 1062 | E5: 1093 | F5: 1126 | G5: 1159 | H5: 1192 | I5: 1226 | J5: 1040 | K5: 1062 | L5: 1040 | M5: 1000 | N5: 1020 | O5: 1040 | P5: 1060 | Q5: 1080 | R5: 1100 | S5: 1120 | T5: 1140 | U5: 1160 | V5: 1030 | W5: 1016 | X5: 1012 | Y5: 1200
A6: 5 | B6: 0 | C6: 1063 | D6: 1084 | E6: 1126 | F6: 1172 | G6: 1217 | H6: 1264 | I6: 1312 | J6: 1050 | K6: 1084 | L6: 1050 | M6: 1000 | N6: 1025 | O6: 1050 | P6: 1075 | Q6: 1100 | R6: 1125 | S6: 1150 | T6: 1175 | U6: 1200 | V6: 1040 | W6: 1020 | X6: 1015 | Y6: 1250
A7: 6 | B7: 0 | C7: 1079 | D7: 1106 | E7: 1160 | F7: 1219 | G7: 1278 | H7: 1340 | I7: 1404 | J7: 1060 | K7: 1106 | L7: 1060 | M7: 1000 | N7: 1030 | O7: 1060 | P7: 1090 | Q7: 1120 | R7: 1150 | S7: 1180 | T7: 1210 | U7: 1240 | V7: 1050 | W7: 1024 | X7: 1018 | Y7: 1300
A8: 7 | B8: 0 | C8: 1096 | D8: 1129 | E8: 1195 | F8: 1268 | G8: 1342 | H8: 1421 | I8: 1503 | J8: 1070 | K8: 1129 | L8: 1070 | M8: 1000 | N8: 1035 | O8: 1070 | P8: 1105 | Q8: 1140 | R8: 1175 | S8: 1210 | T8: 1245 | U8: 1280 | V8: 1060 | W8: 1028 | X8: 1021 | Y8: 1350
A9: 8 | B9: 0 | C9: 1113 | D9: 1152 | E9: 1231 | F9: 1319 | G9: 1410 | H9: 1507 | I9: 1609 | J9: 1080 | K9: 1152 | L9: 1080 | M9: 1000 | N9: 1040 | O9: 1080 | P9: 1120 | Q9: 1160 | R9: 1200 | S9: 1240 | T9: 1280 | U9: 1320 | V9: 1070 | W9: 1032 | X9: 1024 | Y9: 1400
A10: 9 | B10: 0 | C10: 1130 | D10: 1176 | E10: 1268 | F10: 1372 | G10: 1481 | H10: 1598 | I10: 1722 | J10: 1090 | K10: 1176 | L10: 1090 | M10: 1000 | N10: 1045 | O10: 1090 | P10: 1135 | Q10: 1180 | R10: 1225 | S10: 1270 | T10: 1315 | U10: 1360 | V10: 1080 | W10: 1036 | X10: 1027 | Y10: 1450
A11: 10 | B11: 0 | C11: 1147 | D11: 1200 | E11: 1307 | F11: 1427 | G11: 1556 | H11: 1694 | I11: 1843 | J11: 1100 | K11: 1200 | L11: 1100 | M11: 1000 | N11: 1050 | O11: 1100 | P11: 1150 | Q11: 1200 | R11: 1250 | S11: 1300 | T11: 1350 | U11: 1400 | V11: 1090 | W11: 1040 | X11: 1030 | Y11: 1500
A12: 11 | B12: 0 | C12: 1165 | D12: 1224 | E12: 1347 | F12: 1485 | G12: 1634 | H12: 1796 | I12: 1973 | J12: 1110 | K12: 1224 | L12: 1110 | M12: 1000 | N12: 1055 | O12: 1110 | P12: 1165 | Q12: 1220 | R12: 1275 | S12: 1330 | T12: 1385 | U12: 1440 | V12: 1100 | W12: 1044 | X12: 1033 | Y12: 1550
A13: 12 | B13: 0 | C13: 1183 | D13: 1249 | E13: 1388 | F13: 1545 | G13: 1716 | H13: 1904 | I13: 2112 | J13: 1120 | K13: 1249 | L13: 1120 | M13: 1000 | N13: 1060 | O13: 1120 | P13: 1180 | Q13: 1240 | R13: 1300 | S13: 1360 | T13: 1420 | U13: 1480 | V13: 1110 | W13: 1048 | X13: 1036 | Y13: 1600
... A301: 300 | B301: 0 | C301: 88573 | D301: 381637 | E301: 6991522 | F301: 125363453 | G301: 2185120762 | H301: 37157073039 | I301: 614631863830 | J301: 2000 | K301: 53326 | L301: 2500 | M301: 1100 | N301: 2500 | O301: 4000 | P301: 5500 | Q301: 7000 | R301: 8500 | S301: 10000 | T301: 11500 | U301: 13000 | V301: 7558 | W301: 2200 | X301: 1900 | Y301: 8800

Sheet Skills
A1: Key | B1: Name | C1: JobStep | D1: Element | E1: Cooldown(s) | F1: CostsActionSlot | G1: HitsPerCast | H1: ICD(s) | I1: ActiveWindow(s) | J1: ProcChance% | K1: RollsPerCast | L1: BaseDamage(tenths%) | M1: FactorIndex | N1: ScalesWithLevel | O1: SkillMasteryBonus% | P1: MasteryBossDamage% | Q1: MasteryNormalDamage% | R1: NormalMonsterTargets | S1: BuffTargetStat | T1: BuffDuration(s) | U1: TriggersElementalDecrease | V1: TriggersMeteorProc | W1: MeteorProcTriggersPerCast | X1: MapleHeroBase(tenths%) | Y1: MapleHeroFactorIndex | Z1: Stacks | AA1: Note
A2: BASIC_ATTACK | B2: Basic Attack | C2: 4 | D2: Fire | F2: FALSE | G2: 5 | H2: 0 | I2: 0 | J2: 100 | K2: 1 | N2: TRUE | O2: =SUMPRODUCT((Inputs!$B$3>={102,106,116,120,128,132})*{10,11,12,13,14,15}) | P2: =SUMPRODUCT((Inputs!$B$3>={111,124})*{10,10}) | Q2: 0 | R2: =6+Inputs!$B$33+IF(Inputs!$B$3>=136,1,0) | T2: 0 | U2: FALSE | V2: FALSE | W2: 1 | AA2: 5 lines of damage per attack cycle — 5 independent full-damage hits (HitsPerCast=5), each using the same expected-damage-per-hit; no cooldown, DPS uses Basic Attacks/sec from the action-economy block. Basic Attack Mastery (level-gated sum: +10@102, +11@106, +12@116, +13@120, +14@128, +15@132 — 75% total once every tier is unlocked) and Boss Mastery (level-gated sum: +10@111, +10@124 — 20% total) are just this row's SkillMasteryBonus%/MasteryBossDamage% — same mechanism as every other skill, no separate Inputs-sheet fields. Basic Attack's own cast rate (Summary!Basic Attacks Per Second) is always added into the Meteor Proc trigger rate directly, so it does not need TriggersMeteorProc=TRUE here. Hits 6+Basic Attack Target Increase targets vs normal monsters (confirmed by the user), +1 more once Flame Sweep Strike Count is unlocked at level 136.
A3: IGNITE | B3: Ignite | C3: 2 | E3: 1 | F3: FALSE | G3: 3 | H3: 0 | I3: 0 | J3: 100 | K3: 1 | L3: 130 | M3: 21 | N3: TRUE | O3: 100 | P3: 0 | Q3: 0 | R3: 3 | T3: 0 | U3: FALSE | V3: FALSE | W3: 1 | X3: 500 | Y3: 23 | AA3: 3 walls of fire assumed permanently maintained (max instances). +250% vs Normal Monster not modeled. Skill Mastery: +100% added directly to the coefficient%. Hits 3 targets vs normal monsters.
A4: POISON_BREATH | B4: Poison Breath | C4: 2 | D4: Poison | E4: 18 | F4: TRUE | G4: 3 | H4: 0 | I4: 0 | J4: 100 | K4: 1 | L4: 2000 | M4: 12 | N4: TRUE | O4: 70 | P4: 0 | Q4: 0 | R4: 6 | T4: 0 | U4: TRUE | V4: TRUE | W4: 1 | X4: 800 | Y4: 23 | AA4: Skill Mastery: +70% added directly to the coefficient%. Hits 6 targets vs normal monsters.
A5: ELEMENTAL_DRAIN | B5: Elemental Drain | C5: 2 | E5: 1 | F5: FALSE | G5: 5 | H5: 0 | I5: 0 | J5: 100 | K5: 1 | L5: 120 | M5: 21 | N5: TRUE | O5: 0 | P5: 0 | Q5: 0 | R5: 1 | T5: 0 | U5: FALSE | V5: FALSE | W5: 1 | X5: 1500 | Y5: 23 | AA5: Poison assumed permanently at 5 stacks (max instances).
A6: MEDITATION | B6: Meditation | C6: 2 | E6: 30 | F6: TRUE | G6: 1 | H6: 0 | I6: 0 | J6: 100 | K6: 1 | L6: 200 | M6: 22 | N6: TRUE | O6: 0 | P6: 0 | Q6: 0 | R6: 1 | S6: ATTACK | T6: 19.5 | U6: FALSE | V6: FALSE | W6: 1 | AA6: Buff — averaged Attack% = BaseDamage/10 * Factor/1000 * Duration/Cooldown.
A7: POISON_MIST_BURST | B7: Poison Mist (burst) | C7: 3 | D7: Poison | E7: 24.5 | F7: TRUE | G7: 3 | H7: 0 | I7: 0 | J7: 100 | K7: 1 | L7: 1600 | M7: 12 | N7: TRUE | O7: 50 | P7: 0 | Q7: 0 | R7: 10 | T7: 0 | U7: TRUE | V7: TRUE | W7: 1 | X7: 100 | Y7: 23 | AA7: Skill Mastery: +50% added directly to the coefficient%. (Does not apply to the fog DoT — see that row.) Hits 10 targets vs normal monsters.
A8: POISON_MIST_DOT | B8: Poison Mist (fog DoT) | C8: 3 | D8: Poison | E8: 24.5 | F8: FALSE | G8: 1 | H8: =IF(Inputs!$B$3>=104,0.4,0.8) | I8: 20 | J8: 100 | K8: 1 | L8: 700 | M8: 12 | N8: TRUE | O8: 0 | P8: 0 | Q8: 0 | R8: 10 | T8: 0 | U8: FALSE | V8: FALSE | W8: 1 | X8: 100 | Y8: 23 | AA8: EffectiveHits = 1 * (ActiveWindow/ICD) = duration/tick-interval ticks per cast. Skill Mastery's +50% damage bonus does NOT apply to the fog DoT, only the burst — SkillMasteryBonus% intentionally left at 0 here. Hits 10 targets vs normal monsters, same as the burst. Tick interval is 0.8s below level 104, 0.4s once the level-104 mastery is unlocked.
A9: MIST_ERUPTION | B9: Mist Eruption | C9: 4 | E9: =Skills!E7 | F9: FALSE | G9: =IF(Inputs!$B$38="pvp",0,(1-Summary!$B$11)*(1)+Summary!$B$11*(IF(Inputs!$B$3>=108,4,3))) | H9: 0 | I9: 0 | J9: 100 | K9: 1 | L9: 30000 | M9: 12 | N9: TRUE | O9: =IF(Inputs!$B$3>=122,100,0) | P9: 0 | Q9: 0 | R9: 10 | T9: 0 | U9: FALSE | V9: FALSE | W9: 1 | AA9: A skill of its own — only related to Poison Mist in that it's triggered while the fog is active, so it fires at the same rate as Poison Mist's own cast (Cooldown mirrors Skills!Poison Mist (burst) row's Cooldown live). Vs boss: 1 explosion per Poison Mist cast (when the fog expires, since bosses don't die mid-fog). Vs normal monster: 3 explosions per cast (base), +1 (4 total) once the level-108 mastery is unlocked, hitting 10 targets each. Vs Chapter Breakthrough: weighted average of the boss and normal counts by Inputs!normal_weight_frac. Vs PvP: 0 — it only triggers when the fog naturally expires at the end of its full duration, which never happens within the 15s PvP fight (confirmed by the user). Not affected by Poison Mist's Skill Mastery or Maple Hero bonus (confirmed by the user) — it's jobStep 4, using its own 4th-job skill level, same factorIndex 12. Its own SkillMasteryBonus% is the level-122 mastery (+100% damage), unrelated to Poison Mist's.
A10: CREEPING_TOXIN | B10: Creeping Toxin | C10: 3 | D10: Poison | E10: 27 | F10: TRUE | G10: 2 | H10: 2 | I10: 15 | J10: 100 | K10: 1 | L10: 1200 | M10: 12 | N10: TRUE | O10: 50 | P10: 0 | Q10: 100 | R10: 1 | T10: 0 | U10: TRUE | V10: FALSE | W10: 1 | X10: 100 | Y10: 23 | AA10: Assumes a qualifying Fire-element hit is always available within the 2s ICD window. Skill Mastery: +50% added directly to the coefficient%, plus +100% Normal Monster Damage mastery. Deliberately excluded from Meteor Proc's trigger set (confirmed by the user).
A11: BURNING_MAGIC | B11: Burning Magic | C11: 3 | F11: FALSE | G11: 1 | H11: 0 | I11: 0 | J11: 100 | K11: 1 | L11: 50 | M11: 0 | N11: FALSE | O11: 0 | P11: 0 | Q11: 0 | R11: 1 | T11: 0 | U11: FALSE | V11: FALSE | W11: 1 | Z11: 5 | AA11: Global always-on multiplier: 1 + (BaseDamage/10 * Stacks)/100. Does not scale with level.
A12: ELEMENTAL_DECREASE | B12: Elemental Decrease | C12: 3 | F12: FALSE | G12: 1 | H12: 0 | I12: 0 | J12: 50 | K12: 1 | L12: 120 | M12: 22 | N12: TRUE | O12: 0 | P12: 0 | Q12: 0 | R12: 1 | T12: 7 | U12: FALSE | V12: FALSE | W12: 1 | AA12: Modeled as always-on (flat multiplier, like Burning Magic): at 50% chance per qualifying hit and a 7s duration, it gets reapplied well before it expires, so uptime is treated as 100% (confirmed by the user). ProcChance%/BuffDuration(s) are the real skill values for reference only — they no longer feed the Summary-sheet formula.
A13: METEOR_SHOWER_BURST | B13: Meteor Shower (burst) | C13: 4 | D13: Fire | E13: 33 | F13: TRUE | G13: 9 | H13: 0 | I13: 0 | J13: 100 | K13: 1 | L13: 6000 | M13: 12 | N13: TRUE | O13: =IF(Inputs!$B$3>=134,50,0) | P13: 0 | Q13: 0 | R13: 7 | T13: 0 | U13: TRUE | V13: TRUE | W13: 3 | AA13: 3 meteorites x 3 hits collapsed into one 9-hit burst. Hits 7 targets vs normal monsters. MeteorProcTriggersPerCast=3 (not 1) — each of the 3 meteors is an independent Meteor Proc trigger opportunity even though all 3 land from a single cast (confirmed by the user). Skill Mastery: +50% damage once the level-134 mastery is unlocked.
A14: METEOR_PROC | B14: Meteor Proc (30% on-hit, 1s ICD) | C14: 4 | D14: Fire | F14: FALSE | G14: 1 | H14: 1 | I14: 0 | J14: 30 | K14: 1 | L14: 9500 | M14: 21 | N14: TRUE | O14: 0 | P14: 0 | Q14: 0 | R14: 1 | T14: 0 | U14: FALSE | V14: FALSE | W14: 1 | AA14: A skill of its own, NOT tied to Meteor Shower specifically — every cast of Basic Attack, Poison Breath, Poison Mist (burst), Meteor Shower, or Flame Haze (burst) has an independent 30% chance to trigger this meteor drop, gated by a 1s internal cooldown (ICD(s) column) after each trigger. Steady-state proc rate = (Chance% * R) / (1 + ICD * Chance% * R), where R is the combined cast rate of those qualifying attacks (Summary!B21) — NOT the simple EffectiveHits*ProcProbability/Cooldown pattern every other row uses, since this proc has no cooldown of its own to divide by. Creeping Toxin deliberately excluded from the trigger set. 4th job only.
A15: FLAME_HAZE_BURST | B15: Flame Haze (burst) | C15: 4 | D15: Fire | E15: 25 | F15: TRUE | G15: 3 | H15: 0 | I15: 0 | J15: 100 | K15: 1 | L15: 12000 | M15: 12 | N15: TRUE | O15: 0 | P15: 0 | Q15: 0 | R15: 10 | T15: 0 | U15: TRUE | V15: TRUE | W15: 1 | AA15: Hits 10 targets vs normal monsters.
A16: FLAME_HAZE_DOT | B16: Flame Haze (burn DoT) | C16: 4 | D16: Fire | E16: 25 | F16: FALSE | G16: 1 | H16: 0.5 | I16: =IF(Inputs!$B$38="pvp",10,(1-Summary!$B$11)*(20)+Summary!$B$11*(10)) | J16: 100 | K16: 1 | L16: 1500 | M16: 12 | N16: TRUE | O16: 0 | P16: 0 | Q16: 0 | R16: 10 | T16: 0 | U16: FALSE | V16: FALSE | W16: 1 | AA16: Burn duration is 20s vs boss, 10s vs normal monsters and PvP (confirmed by the user); Chapter Breakthrough blends the two by Inputs!normal_weight_frac. Hits 10 targets vs normal monsters, same as the burst.
A17: MAGIC_GUARD | B17: Magic Guard | C17: 1 | E17: 21 | F17: TRUE | G17: 1 | H17: 0 | I17: 0 | J17: 100 | K17: 1 | L17: 120 | M17: 21 | N17: TRUE | O17: 0 | P17: 0 | Q17: 0 | R17: 1 | S17: ATTACK | T17: 15 | U17: FALSE | V17: FALSE | W17: 1 | AA17: Buff — only the Attack component is modeled (Defense component doesn't affect own damage).
A18: NIMBLE_FEET | B18: Nimble Feet | C18: 1 | E18: 60 | F18: TRUE | G18: 1 | H18: 0 | I18: 0 | J18: 100 | K18: 1 | L18: 150 | M18: 0 | N18: FALSE | O18: 0 | P18: 0 | Q18: 0 | R18: 1 | S18: ATTACK_SPEED | T18: 15 | U18: FALSE | V18: FALSE | W18: 1 | AA18: Buff — flat +15% Attack Speed, does not scale with level (FactorIndex is an unused placeholder here, same as Burning Magic). Averaged into effective Attack Speed before the 150% cap.
A19: INFINITY | B19: Infinity | C19: 4 | E19: 30 | F19: TRUE | G19: 1 | H19: 0 | I19: 0 | J19: 100 | K19: 1 | L19: 216.67 | M19: 21 | N19: TRUE | O19: 0 | P19: 0 | Q19: 0 | R19: 1 | S19: FINAL_DAMAGE | T19: 15 | U19: FALSE | V19: FALSE | W19: 1 | AA19: Ramps +15%->+25% Final Damage over 10s of its 15s duration; time-averaged while active = 21.6667% at factor 1000, now scaled by FactorTable[level][21]/1000 like Magic Guard/Meditation.
A20: MAGIC_CRITICAL_RATE | B20: Magic Critical (Crit Rate) | C20: 3 | F20: FALSE | G20: 1 | H20: 0 | I20: 0 | J20: 100 | K20: 1 | L20: 80 | M20: 22 | N20: TRUE | O20: 0 | P20: 0 | Q20: 0 | R20: 1 | S20: CRIT_RATE | T20: 0 | U20: FALSE | V20: FALSE | W20: 1 | AA20: Passive, always on (3rd job) — no cooldown/duration, not a damage row (Calc columns J-O stay blank/0). Its current contribution is already baked into Inputs!CRIT_RATE% by the user, so this row's own Calc!F value is NOT added to the baseline calculation — it's only used by the Sensitivity sheet to compute the marginal delta (this row's F at the swept level minus this row's F at the current level) when 'Skill Level Bonus — 3rd Job' is the stat being tested.
A21: MAGIC_CRITICAL_DAMAGE | B21: Magic Critical (Crit Damage) | C21: 3 | F21: FALSE | G21: 1 | H21: 0 | I21: 0 | J21: 100 | K21: 1 | L21: 120 | M21: 22 | N21: TRUE | O21: 0 | P21: 0 | Q21: 0 | R21: 1 | S21: CRIT_DAMAGE | T21: 0 | U21: FALSE | V21: FALSE | W21: 1 | AA21: Same mechanism as Magic Critical (Crit Rate) above, targeting CRIT_DAMAGE% instead.
A22: SPELL_MASTERY | B22: Spell Mastery | C22: 2 | F22: FALSE | G22: 1 | H22: 0 | I22: 0 | J22: 100 | K22: 1 | L22: 150 | M22: 22 | N22: TRUE | O22: 0 | P22: 0 | Q22: 0 | R22: 1 | S22: MIN_DAMAGE | T22: 0 | U22: FALSE | V22: FALSE | W22: 1 | AA22: Passive, always on (2nd job) — no cooldown/duration, not a damage row. Its current contribution is already baked into Inputs!MIN_DAMAGE% by the user; this row's Calc!F is only used by the Sensitivity sheet to compute the marginal delta when 'Skill Level Bonus — 2nd Job' is swept.
A23: ELEMENT_AMPLIFICATION | B23: Element Amplification | C23: 4 | F23: FALSE | G23: 1 | H23: 0 | I23: 0 | J23: 100 | K23: 1 | L23: 150 | M23: 22 | N23: TRUE | O23: 0 | P23: 0 | Q23: 0 | R23: 1 | S23: FINAL_DAMAGE | T23: 0 | U23: FALSE | V23: FALSE | W23: 1 | AA23: Passive, always on (4th job) — no cooldown/duration, not a damage row. Unlike the two rows above, this one is NOT reflected anywhere in Inputs, so its current-level value (Calc!F23) is added directly into every hit's Final Damage term in both the main Calc sheet and every Sensitivity block — combined MULTIPLICATIVELY with Inputs!FINAL_DAMAGE% (Final Damage sources always stack as (1+a/100)*(1+b/100), never as (1+(a+b)/100)).
A24: IFRIT | B24: Ifrit | C24: 4 | D24: Fire | E24: 80 | F24: TRUE | G24: 1 | H24: 4 | I24: =IF(Inputs!$B$3>=138,40,30) | J24: 100 | K24: 1 | L24: 35000 | M24: 12 | N24: TRUE | O24: 0 | P24: 0 | Q24: 0 | R24: =IF(Inputs!$B$3>=138,6,3) | T24: 0 | U24: FALSE | V24: FALSE | W24: 1 | AA24: Summon, 80s cooldown. EffectiveHits = HitsPerCast*(ActiveWindow/ICD) — same mechanism as Poison Mist's fog DoT/Flame Haze's burn DoT, no new Calc-sheet machinery needed: attacks every 4s (ICD) for its 30s duration (ActiveWindow), hitting 3 targets vs normal monsters, for the whole 80s cast cycle (Cooldown/InvCooldown). Duration -> 40s and targets -> 6 once the level-138 mastery is unlocked. Deliberately excluded from Meteor Proc's trigger set (confirmed by the user) — it only counts as a trigger source for the level-126 Flame Haze burn-proc mastery (see build_calc_sheet) and for Fervent Drain (via DAMAGE_ROW_KEYS, same as every other non-Basic-Attack skill). Gains a level-130 mastery multiplier (1+20%*Flame Haze burn stacks) — see flame_haze_total_stacks_expr.
A25: BUFF_MASTERY | B25: Buff Mastery | C25: 4 | F25: FALSE | G25: 1 | H25: 0 | I25: 0 | J25: 100 | K25: 1 | L25: 100 | M25: 22 | N25: TRUE | O25: 0 | P25: 0 | Q25: 0 | R25: 1 | T25: 0 | U25: FALSE | V25: FALSE | W25: 1 | AA25: Passive, always on (4th job, unlocked level 117) — no cooldown/duration, not a damage row. Not reflected anywhere in Inputs, so its current value (Calc!F) is added directly into every uptime_fraction_expr call's Buff Duration Increase % term, in both the main Calc sheet and every Sensitivity block (see bdi_with_buff_mastery_expr) — +10% base.
A26: ARCANE_AIM | B26: Arcane Aim | C26: 4 | F26: FALSE | G26: 1 | H26: 0 | I26: 0 | J26: 100 | K26: 1 | L26: 30 | M26: 22 | N26: TRUE | O26: 0 | P26: 0 | Q26: 0 | R26: 1 | T26: 0 | U26: FALSE | V26: FALSE | W26: 1 | AA26: Passive, always on (4th job, unlocked level 120) — no cooldown/duration, not a damage row. 25% chance per attack for +3% Final Damage for 10s, stacking up to 5 times; modeled as always at max 5 stacks (confirmed by the user, same precedent as Burning Magic/Elemental Decrease always-on). Combined MULTIPLICATIVELY into the Final Damage chain as (1+Calc!F/100)^5, alongside Element Amplification — stacks are multiplicative with each other, not additive (1.03^5, not 1+5*0.03).
A27: FERVENT_DRAIN | B27: Fervent Drain | C27: 4 | F27: FALSE | G27: 1 | H27: 0 | I27: 0 | J27: 100 | K27: 1 | L27: 40 | M27: 22 | N27: TRUE | O27: 0 | P27: 0 | Q27: 0 | R27: 1 | T27: 0 | U27: FALSE | V27: FALSE | W27: 1 | AA27: Passive, always on (4th job, unlocked level 125) — no cooldown/duration, not a damage row. +4% fire/poison skill damage per Poison stack on target; reuses Elemental Drain's permanently-5-stacks assumption, so its effective contribution is Calc!F*5. Added additively inside the skill_damage term of the hit-damage formula — confirmed by the user to boost skill damage only, NOT Basic Attack (Flame Sweep), even though it does cover both fire- and poison-element skills otherwise. Structurally excluded from Basic Attack's own term, not just numerically zero.
A28: FLAME_HAZE_FOG | B28: Flame Haze (poison fog DoT) | C28: 4 | D28: Poison | E28: =Skills!E15 | F28: FALSE | G28: 1 | H28: =IF(Inputs!$B$3>=104,0.4,0.8) | I28: 20 | J28: 100 | K28: 1 | L28: 700 | M28: 12 | N28: TRUE | O28: 0 | P28: 0 | Q28: 0 | R28: 10 | T28: 0 | U28: FALSE | V28: FALSE | W28: 1 | AA28: Unlocked level 118: Flame Haze creates a second, fully independent poisonous fog that triggers Poison Mist's DoT mechanic too — same damage/duration/ICD-mastery-gate math as POISON_MIST_DOT, tied to Flame Haze (burst)'s own live Cooldown cell (same live-cross-reference pattern MIST_ERUPTION uses for POISON_MIST_BURST). Independent of the existing Poison Mist fog — both can be active at the same time (confirmed by the user). No Maple Hero bonus (MapleHeroBase blank), matching its jobStep-4 sibling FLAME_HAZE_DOT rather than the jobStep-3 POISON_MIST_DOT.

Sheet Artifacts
A1: Fire/Poison Arch Mage — Artifacts (Equip Effect)
A3: Book of Ancient — Crit Damage (from Crit Rate, reference only) | B3: =IF(ArtifactsInput!$M$24,CHOOSE(ArtifactsInput!$N$24+1,30,36,42,48,54,60)/100*(Inputs!$B$9+B5+B29),0)
A4: Ring of Cycles — Threshold Crit Rate (excl. self) | B4: =Inputs!$B$9+B29
A5: Ring of Cycles — Crit Rate (if threshold < 100%) | B5: =IF(AND(ArtifactsInput!$M$42,B4<100),CHOOSE(ArtifactsInput!$N$42+1,30,36,42,48,54,60),0)
A6: Ring of Cycles — Skill Damage (if threshold >= 100%) | B6: =IF(AND(ArtifactsInput!$M$42,B4>=100),CHOOSE(ArtifactsInput!$N$42+1,40,48,56,64,72,80),0)
A7: Ring of Cycles — Excess-100% Points (capped at 100) | B7: =IF(AND(ArtifactsInput!$M$42,B4>=100),MIN(100,B4-100),0)
A8: Ring of Cycles — Basic Attack Damage (excess points x per-point) | B8: =B7*CHOOSE(ArtifactsInput!$N$42+1,0.6,0.72,0.84,0.96,1.08,1.2)
A9: Candle — Effective Fight Duration | B9: =IF(Inputs!$B$38="pvp",15,Inputs!$B$43)
A10: Candle — Effective Active (fixed-duration or PvP) | B10: =IF(Inputs!$B$38="pvp",TRUE,AND(Inputs!$B$38<>"pvp",Inputs!$B$43>0))
A11: Candle — Final Damage (100% uptime, patched) | B11: =IF(AND(ArtifactsInput!$M$36,B10),CHOOSE(ArtifactsInput!$N$36+1,8,9.6,11.2,12.8,14.4,16),0)
A12: Candle — Boss Monster Damage (20-40s window / boss-present-time uptime, patched) | B12: =IF(AND(ArtifactsInput!$M$36,B10),MAX(0,MIN(40,B9)-MAX(20,B41))/(B9-B41)*CHOOSE(ArtifactsInput!$N$36+1,30,36,42,48,54,60),0)
A13: Peach Tree Herb Pouch — Proc Rate (per second) | B13: =0.2*Summary!$B$17
A14: Peach Tree Herb Pouch — Uptime (refreshing 5s timer) | B14: =1-EXP(-B13*5)
A15: Peach Tree Herb Pouch — Enemy Damage Taken | B15: =IF(AND(ArtifactsInput!$M$35,Inputs!$B$4<>"Chapter Hunt"),CHOOSE(ArtifactsInput!$N$35+1,15,18,21,24,27,30)*B14,0)
A16: Silver Pendant — Offered Load (rho = lambda x duration) | B16: =0.15*Summary!$B$17*5
A17: Silver Pendant — Erlang Loss Weight (n=0) | B17: =B16^0/1
A18: Silver Pendant — Erlang Loss Weight (n=1) | B18: =B16^1/1
A19: Silver Pendant — Erlang Loss Weight (n=2) | B19: =B16^2/2
A20: Silver Pendant — Erlang Loss Weight (n=3) | B20: =B16^3/6
A21: Silver Pendant — Erlang Loss Weight (n=4) | B21: =B16^4/24
A22: Silver Pendant — Erlang Loss Weight (n=5) | B22: =B16^5/120
A23: Silver Pendant — Average Stacks (Erlang-loss mean) | B23: =(0*B17+1*B18+2*B19+3*B20+4*B21+5*B22)/(B17+B18+B19+B20+B21+B22)
A24: Silver Pendant — Enemy Damage Taken | B24: =IF(AND(ArtifactsInput!$M$22,Inputs!$B$4<>"Chapter Hunt"),CHOOSE(ArtifactsInput!$N$22+1,10,12,14,16,18,20)*B23,0)
A25: Athena Pierce's Old Gloves — Max Damage (from Attack Speed, reference only) | B25: =IF(ArtifactsInput!$M$15,CHOOSE(ArtifactsInput!$N$15+1,25,30,35,40,45,50)/100*Inputs!$B$11,0)
A26: Hexagon Necklace — Average Stacks | B26: =IF(AND(Inputs!$B$38<>"pvp",Inputs!$B$43=0),3,IF(IF(Inputs!$B$38="pvp",15,Inputs!$B$43)<=20,0,IF(IF(Inputs!$B$38="pvp",15,Inputs!$B$43)<=40,(IF(Inputs!$B$38="pvp",15,Inputs!$B$43)-20)/IF(Inputs!$B$38="pvp",15,Inputs!$B$43),IF(IF(Inputs!$B$38="pvp",15,Inputs!$B$43)<=60,(2*IF(Inputs!$B$38="pvp",15,Inputs!$B$43)-60)/IF(Inputs!$B$38="pvp",15,Inputs!$B$43),(3*IF(Inputs!$B$38="pvp",15,Inputs!$B$43)-120)/IF(Inputs!$B$38="pvp",15,Inputs!$B$43)))))
A27: Hexagon Necklace — Damage % | B27: =IF(ArtifactsInput!$M$11,CHOOSE(ArtifactsInput!$N$11+1,15,18,21,24,27,30)*B26,0)
A28: Rainbow-colored Snail Shell — Uptime (0-15s window) | B28: =IF(Inputs!$B$38="pvp",MIN(15,15)/15,IF(AND(Inputs!$B$38<>"pvp",Inputs!$B$43>0),MIN(15,Inputs!$B$43)/Inputs!$B$43,0))
A29: Rainbow-colored Snail Shell — Crit Rate | B29: =IF(ArtifactsInput!$M$10,CHOOSE(ArtifactsInput!$N$10+1,15,18,21,24,27,30)*B28,0)
A30: Rainbow-colored Snail Shell — Crit Damage | B30: =IF(ArtifactsInput!$M$10,CHOOSE(ArtifactsInput!$N$10+1,20,24,28,32,36,40)*B28,0)
A32: TOTAL — Artifact Crit Rate Bonus | B32: =B5+B29
A33: TOTAL — Artifact Crit Damage Bonus | B33: =B30+B47
A34: TOTAL — Artifact Final Damage Bonus (equivalent %, each real source combines MULTIPLICATIVELY — Candle x Flaming Lava x Horn Flute, not summed) | B34: =((1+B11/100)*(1+B46/100)*(1+B55/100)-1)*100
A35: TOTAL — Artifact Boss Monster Damage Bonus | B35: =B12+B60
A36: TOTAL — Artifact Enemy Damage Taken Bonus | B36: =B15+B24
A38: TOTAL — Artifact Damage Bonus (own separate final multiplier, like Magic Guard/Meditation's Average Buff Multiplier — not blended into Inputs!DAMAGE%) | B38: =B27
A39: TOTAL — Artifact Skill Damage Bonus | B39: =B6
A40: TOTAL — Artifact Basic Attack Damage Bonus | B40: =B8
A41: Candle — Boss Appear Time (Breakthrough/Hero Dungeon only) | B41: =IF(Inputs!$B$4="Breakthrough",20,IF(Inputs!$B$4="Hero Dungeon",30,0))
A42: Clear Spring Water — Final Damage (reference only, Growth Dungeon types) | B42: =IF(AND(ArtifactsInput!$M$14,OR(Inputs!$B$4="Weapon Dungeon",Inputs!$B$4="Equipment Dungeon",Inputs!$B$4="Enhancement Dungeon",Inputs!$B$4="EXP Dungeon",Inputs!$B$4="Hero Dungeon")),CHOOSE(ArtifactsInput!$N$14+1,10,12,14,16,18,20),0)
A43: Old Music Box — Attack % (content-type uptime assumption) | B43: =IF(ArtifactsInput!$M$21,CHOOSE(ArtifactsInput!$N$21+1,25,30,35,40,45,50)*(IF(OR(Inputs!$B$4="Chapter Hunt",Inputs!$B$4="Breakthrough",Inputs!$B$4="Weapon Dungeon",Inputs!$B$4="Equipment Dungeon",Inputs!$B$4="Enhancement Dungeon",Inputs!$B$4="EXP Dungeon",Inputs!$B$4="Hero Dungeon"),0,IF(OR(Inputs!$B$4="World Boss",Inputs!$B$4="PvP"),1,IF(Inputs!$B$4="Chapter Boss",60/70,0)))),0)
...

Sheet Calc
A1: Key | B1: Name | C1: Unlocked | D1: InputLevel | E1: Factor | F1: CoefficientPercent | G1: EffectiveHits | H1: ProcProbability | I1: MapleHeroMultiplier | J1: BaseDamage | K1: BaseHitDamage | L1: NonCritAvg | M1: CritAvg | N1: ExpectedDamage(perHit) | O1: DPS | P1: % of Total | Q1: InvCooldown | R1: CastsInFight | S1: BossOnlyDPS | U1: NormalOnlyDPS | Z1: Maple Hero helper (jobStep4, factorIndex23)
A2: =Skills!A2 | B2: =Skills!B2 | C2: =TRUE | F2: =Summary!$B$10+Skills!O2 | G2: =Skills!G2*IF(Skills!H2>0,Skills!I2/Skills!H2,1) | H2: =1-(1-Skills!J2/100)^Skills!K2 | I2: =IF(Skills!X2<>"",1+(Skills!X2/10)*($Z$3/1000)/100,1) | J2: =Summary!$B$6*(F2/100) | K2: =J2*(1+Summary!$B$7/100)*(1+Inputs!$B$15/100)*(1+Inputs!$B$16/100)*(5000/(6000+Inputs!$B$42*(1-Inputs!$B$19/100)))*(1+Inputs!$B$24/100)*(1+Artifacts!$B$34/100)*(1+F23/100)*(1+IF(Inputs!$B$3>=120,F26,0)/100)^5*(1+(IF(Skills!A2="BASIC_ATTACK",Inputs!$B$17+Artifacts!$B$40,Inputs!$B$18+Artifacts!$B$39+IF(Inputs!$B$3>=125,F27*5,0)))/100)*(Summary!$B$13*Summary!$B$14*Summary!$B$15*(1+Artifacts!$B$38/100)*I2) | L2: =K2*(MIN(Inputs!$B$22,Inputs!$B$23)/100+Inputs!$B$23/100)/2 | M2: =L2*(1+(Inputs!$B$10+Artifacts!$B$33)/100) | N2: =L2*(1-MIN((Inputs!$B$9+Artifacts!$B$32),100)/100)+M2*(MIN((Inputs!$B$9+Artifacts!$B$32),100)/100) | O2: =(1-Summary!$B$11)*S2+Summary!$B$11*U2 | P2: =IF(Summary!$B$3=0,0,O2/Summary!$B$3) | Q2: =IFERROR(1/(IF(Inputs!$B$38="pvp",15,MAX(0.1,Skills!E2-IF(Skills!F2=TRUE,Inputs!$B$32,0)))*(1-IF(AND(ArtifactsInput!$M$27,Inputs!$B$4="Chapter Hunt"),CHOOSE(ArtifactsInput!$N$27+1,20,24,28,32,36,40),0)/100)),0) | R2: 0 | S2: =(Skills!G2*N2*Summary!$B$19)*IF(Inputs!$B$38="pvp",1,1+(Inputs!$B$20+Skills!P2+Artifacts!$B$35)/100)*((((5000/(6000+Inputs!$B$42*(1-(100*(1-(1-Inputs!$B$19/100)*(1-Artifacts!$B$51/100)^IF(Inputs!$B$38="pvp",1,2)))/100)))/(5000/(6000+Inputs!$B$42*(1-Inputs!$B$19/100))))*((L2*(1-MIN(100,(Inputs!$B$9+Artifacts!$B$32)+Artifacts!$B$69)/100)+M2*(MIN(100,(Inputs!$B$9+Artifacts!$B$32)+Artifacts!$B$69)/100))/(L2*(1-MIN(100,(Inputs!$B$9+Artifacts!$B$32))/100)+M2*(MIN(100,(Inputs!$B$9+Artifacts!$B$32))/100)))*(1+Artifacts!$B$81/100))) | U2: =(Skills!G2*N2*Summary!$B$19)*IF(Inputs!$B$38="pvp",1,(1+(Inputs!$B$21+Skills!Q2+Artifacts!$B$80)/100)*(MIN(Skills!R2,Inputs!$B$37)))*((1+Artifacts!$B$53/100)) | Z2: =MAX(0,(Inputs!$B$3-100)*3)+Inputs!$B$28+Inputs!$B$29
A3: =Skills!A3 | B3: =Skills!B3 | C3: =TRUE | D3: =IF(Skills!C3=1,60+Inputs!$B$25+Inputs!$B$29,IF(Skills!C3=2,90+Inputs!$B$26+Inputs!$B$29,IF(Skills!C3=3,120+Inputs!$B$27+Inputs!$B$29,MAX(0,(Inputs!$B$3-100)*3)+Inputs!$B$28+Inputs!$B$29))) | E3: =INDEX(FactorTable!$B$2:$Y$301, MATCH(ROUND(MIN(300,MAX(1,D3)),0), FactorTable!$A$2:$A$301,0), Skills!M3+1) | F3: =IF(Skills!N3=TRUE,(Skills!L3/10)*(E3/1000),Skills!L3/10)+Skills!O3 | G3: =Skills!G3*IF(Skills!H3>0,Skills!I3/Skills!H3,1) | H3: =1-(1-Skills!J3/100)^Skills!K3 | I3: =IF(Skills!X3<>"",1+(Skills!X3/10)*($Z$3/1000)/100,1) | J3: =Summary!$B$6*(F3/100) | K3: =J3*(1+Summary!$B$7/100)*(1+Inputs!$B$15/100)*(1+Inputs!$B$16/100)*(5000/(6000+Inputs!$B$42*(1-Inputs!$B$19/100)))*(1+Inputs!$B$24/100)*(1+Artifacts!$B$34/100)*(1+F23/100)*(1+IF(Inputs!$B$3>=120,F26,0)/100)^5*(1+(IF(Skills!A3="BASIC_ATTACK",Inputs!$B$17+Artifacts!$B$40,Inputs!$B$18+Artifacts!$B$39+IF(Inputs!$B$3>=125,F27*5,0)))/100)*(Summary!$B$13*Summary!$B$14*Summary!$B$15*(1+Artifacts!$B$38/100)*I3) | L3: =K3*(MIN(Inputs!$B$22,Inputs!$B$23)/100+Inputs!$B$23/100)/2 | M3: =L3*(1+(Inputs!$B$10+Artifacts!$B$33)/100) | N3: =L3*(1-MIN((Inputs!$B$9+Artifacts!$B$32),100)/100)+M3*(MIN((Inputs!$B$9+Artifacts!$B$32),100)/100) | O3: =(1-Summary!$B$11)*S3+Summary!$B$11*U3 | P3: =IF(Summary!$B$3=0,0,O3/Summary!$B$3) | Q3: =IFERROR(1/(IF(Inputs!$B$38="pvp",15,MAX(0.1,Skills!E3-IF(Skills!F3=TRUE,Inputs!$B$32,0)))*(1-IF(AND(ArtifactsInput!$M$27,Inputs!$B$4="Chapter Hunt"),CHOOSE(ArtifactsInput!$N$27+1,20,24,28,32,36,40),0)/100)),0) | R3: =IF(AND(Inputs!$B$38<>"pvp",Inputs!$B$43>0),IF(MAX(0,Inputs!$B$43-Summary!$B$22)<=0,0,(INT(MAX(0,Inputs!$B$43-Summary!$B$22)/(IF(Inputs!$B$38="pvp",15,MAX(0.1,Skills!E3-IF(Skills!F3=TRUE,Inputs!$B$32,0)))*(1-IF(AND(ArtifactsInput!$M$27,Inputs!$B$4="Chapter Hunt"),CHOOSE(ArtifactsInput!$N$27+1,20,24,28,32,36,40),0)/100)))+1)),0) | S3: =IF(C3,(H3*N3*IF(AND(Inputs!$B$38<>"pvp",Inputs!$B$43>0),((Skills!G3*((R3-1)*IF(Skills!H3>0,Skills!I3/Skills!H3,1)+IF(Skills!H3>0,MIN(Skills!I3,MAX(0,MAX(0,Inputs!$B$43-Summary!$B$22)-((R3-1)*(IF(Inputs!$B$38="pvp",15,MAX(0.1,Skills!E3-IF(Skills!F3=TRUE,Inputs!$B$32,0)))*(1-IF(AND(ArtifactsInput!$M$27,Inputs!$B$4="Chapter Hunt"),CHOOSE(ArtifactsInput!$N$27+1,20,24,28,32,36,40),0)/100)))))/Skills!H3,1)))/Inputs!$B$43),G3*Q3))*IF(Inputs!$B$38="pvp",1,1+(Inputs!$B$20+Skills!P3+Artifacts!$B$35)/100)*((((5000/(6000+Inputs!$B$42*(1-(100*(1-(1-Inputs!$B$19/100)*(1-Artifacts!$B$51/100)^IF(Inputs!$B$38="pvp",1,2)))/100)))/(5000/(6000+Inputs!$B$42*(1-Inputs!$B$19/100))))*((L3*(1-MIN(100,(Inputs!$B$9+Artifacts!$B$32)+Artifacts!$B$69)/100)+M3*(MIN(100,(Inputs!$B$9+Artifacts!$B$32)+Artifacts!$B$69)/100))/(L3*(1-MIN(100,(Inputs!$B$9+Artifacts!$B$32))/100)+M3*(MIN(100,(Inputs!$B$9+Artifacts!$B$32))/100)))*(1+Artifacts!$B$81/100))),0) | U3: =IF(C3,(H3*N3*IF(AND(Inputs!$B$38<>"pvp",Inputs!$B$43>0),((Skills!G3*((R3-1)*IF(Skills!H3>0,Skills!I3/Skills!H3,1)+IF(Skills!H3>0,MIN(Skills!I3,MAX(0,MAX(0,Inputs!$B$43-Summary!$B$22)-((R3-1)*(IF(Inputs!$B$38="pvp",15,MAX(0.1,Skills!E3-IF(Skills!F3=TRUE,Inputs!$B$32,0)))*(1-IF(AND(ArtifactsInput!$M$27,Inputs!$B$4="Chapter Hunt"),CHOOSE(ArtifactsInput!$N$27+1,20,24,28,32,36,40),0)/100)))))/Skills!H3,1)))/Inputs!$B$43),G3*Q3))*IF(Inputs!$B$38="pvp",1,(1+(Inputs!$B$21+Skills!Q3+Artifacts!$B$80)/100)*(MIN(Skills!R3,Inputs!$B$37)))*((1+Artifacts!$B$53/100)),0) | Z3: =INDEX(FactorTable!$B$2:$Y$301, MATCH(ROUND(MIN(300,MAX(1,Z2)),0), FactorTable!$A$2:$A$301,0), 24)
A4: =Skills!A4 | B4: =Skills!B4 | C4: =TRUE | D4: =IF(Skills!C4=1,60+Inputs!$B$25+Inputs!$B$29,IF(Skills!C4=2,90+Inputs!$B$26+Inputs!$B$29,IF(Skills!C4=3,120+Inputs!$B$27+Inputs!$B$29,MAX(0,(Inputs!$B$3-100)*3)+Inputs!$B$28+Inputs!$B$29))) | E4: =INDEX(FactorTable!$B$2:$Y$301, MATCH(ROUND(MIN(300,MAX(1,D4)),0), FactorTable!$A$2:$A$301,0), Skills!M4+1) | F4: =IF(Skills!N4=TRUE,(Skills!L4/10)*(E4/1000),Skills!L4/10)+Skills!O4 | G4: =Skills!G4*IF(Skills!H4>0,Skills!I4/Skills!H4,1) | H4: =1-(1-Skills!J4/100)^Skills!K4 | I4: =IF(Skills!X4<>"",1+(Skills!X4/10)*($Z$3/1000)/100,1) | J4: =Summary!$B$6*(F4/100) | K4: =J4*(1+Summary!$B$7/100)*(1+Inputs!$B$15/100)*(1+Inputs!$B$16/100)*(5000/(6000+Inputs!$B$42*(1-Inputs!$B$19/100)))*(1+Inputs!$B$24/100)*(1+Artifacts!$B$34/100)*(1+F23/100)*(1+IF(Inputs!$B$3>=120,F26,0)/100)^5*(1+(IF(Skills!A4="BASIC_ATTACK",Inputs!$B$17+Artifacts!$B$40,Inputs!$B$18+Artifacts!$B$39+IF(Inputs!$B$3>=125,F27*5,0)))/100)*(Summary!$B$13*Summary!$B$14*Summary!$B$15*(1+Artifacts!$B$38/100)*I4) | L4: =K4*(MIN(Inputs!$B$22,Inputs!$B$23)/100+Inputs!$B$23/100)/2 | M4: =L4*(1+(Inputs!$B$10+Artifacts!$B$33)/100) | N4: =L4*(1-MIN((Inputs!$B$9+Artifacts!$B$32),100)/100)+M4*(MIN((Inputs!$B$9+Artifacts!$B$32),100)/100) | O4: =(1-Summary!$B$11)*S4+Summary!$B$11*U4 | P4: =IF(Summary!$B$3=0,0,O4/Summary!$B$3) | Q4: =IFERROR(1/(IF(Inputs!$B$38="pvp",15,MAX(0.1,Skills!E4-IF(Skills!F4=TRUE,Inputs!$B$32,0)))*(1-IF(AND(ArtifactsInput!$M$27,Inputs!$B$4="Chapter Hunt"),CHOOSE(ArtifactsInput!$N$27+1,20,24,28,32,36,40),0)/100)),0) | R4: =IF(AND(Inputs!$B$38<>"pvp",Inputs!$B$43>0),IF(MAX(0,Inputs!$B$43-Summary!$B$22)<=0,0,(INT(MAX(0,Inputs!$B$43-Summary!$B$22)/(IF(Inputs!$B$38="pvp",15,MAX(0.1,Skills!E4-IF(Skills!F4=TRUE,Inputs!$B$32,0)))*(1-IF(AND(ArtifactsInput!$M$27,Inputs!$B$4="Chapter Hunt"),CHOOSE(ArtifactsInput!$N$27+1,20,24,28,32,36,40),0)/100)))+1)),0) | S4: =IF(C4,(H4*N4*IF(AND(Inputs!$B$38<>"pvp",Inputs!$B$43>0),((Skills!G4*((R4-1)*IF(Skills!H4>0,Skills!I4/Skills!H4,1)+IF(Skills!H4>0,MIN(Skills!I4,MAX(0,MAX(0,Inputs!$B$43-Summary!$B$22)-((R4-1)*(IF(Inputs!$B$38="pvp",15,MAX(0.1,Skills!E4-IF(Skills!F4=TRUE,Inputs!$B$32,0)))*(1-IF(AND(ArtifactsInput!$M$27,Inputs!$B$4="Chapter Hunt"),CHOOSE(ArtifactsInput!$N$27+1,20,24,28,32,36,40),0)/100)))))/Skills!H4,1)))/Inputs!$B$43),G4*Q4))*IF(Inputs!$B$38="pvp",1,1+(Inputs!$B$20+Skills!P4+Artifacts!$B$35)/100)*((((5000/(6000+Inputs!$B$42*(1-(100*(1-(1-Inputs!$B$19/100)*(1-Artifacts!$B$51/100)^IF(Inputs!$B$38="pvp",1,2)))/100)))/(5000/(6000+Inputs!$B$42*(1-Inputs!$B$19/100))))*((L4*(1-MIN(100,(Inputs!$B$9+Artifacts!$B$32)+Artifacts!$B$69)/100)+M4*(MIN(100,(Inputs!$B$9+Artifacts!$B$32)+Artifacts!$B$69)/100))/(L4*(1-MIN(100,(Inputs!$B$9+Artifacts!$B$32))/100)+M4*(MIN(100,(Inputs!$B$9+Artifacts!$B$32))/100)))*(1+Artifacts!$B$81/100))),0) | U4: =IF(C4,(H4*N4*IF(AND(Inputs!$B$38<>"pvp",Inputs!$B$43>0),((Skills!G4*((R4-1)*IF(Skills!H4>0,Skills!I4/Skills!H4,1)+IF(Skills!H4>0,MIN(Skills!I4,MAX(0,MAX(0,Inputs!$B$43-Summary!$B$22)-((R4-1)*(IF(Inputs!$B$38="pvp",15,MAX(0.1,Skills!E4-IF(Skills!F4=TRUE,Inputs!$B$32,0)))*(1-IF(AND(ArtifactsInput!$M$27,Inputs!$B$4="Chapter Hunt"),CHOOSE(ArtifactsInput!$N$27+1,20,24,28,32,36,40),0)/100)))))/Skills!H4,1)))/Inputs!$B$43),G4*Q4))*IF(Inputs!$B$38="pvp",1,(1+(Inputs!$B$21+Skills!Q4+Artifacts!$B$80)/100)*(MIN(Skills!R4,Inputs!$B$37)))*((1+Artifacts!$B$53/100)),0)
A5: =Skills!A5 | B5: =Skills!B5 | C5: =TRUE | D5: =IF(Skills!C5=1,60+Inputs!$B$25+Inputs!$B$29,IF(Skills!C5=2,90+Inputs!$B$26+Inputs!$B$29,IF(Skills!C5=3,120+Inputs!$B$27+Inputs!$B$29,MAX(0,(Inputs!$B$3-100)*3)+Inputs!$B$28+Inputs!$B$29))) | E5: =INDEX(FactorTable!$B$2:$Y$301, MATCH(ROUND(MIN(300,MAX(1,D5)),0), FactorTable!$A$2:$A$301,0), Skills!M5+1) | F5: =IF(Skills!N5=TRUE,(Skills!L5/10)*(E5/1000),Skills!L5/10)+Skills!O5 | G5: =Skills!G5*IF(Skills!H5>0,Skills!I5/Skills!H5,1) | H5: =1-(1-Skills!J5/100)^Skills!K5 | I5: =IF(Skills!X5<>"",1+(Skills!X5/10)*($Z$3/1000)/100,1) | J5: =Summary!$B$6*(F5/100) | K5: =J5*(1+Summary!$B$7/100)*(1+Inputs!$B$15/100)*(1+Inputs!$B$16/100)*(5000/(6000+Inputs!$B$42*(1-Inputs!$B$19/100)))*(1+Inputs!$B$24/100)*(1+Artifacts!$B$34/100)*(1+F23/100)*(1+IF(Inputs!$B$3>=120,F26,0)/100)^5*(1+(IF(Skills!A5="BASIC_ATTACK",Inputs!$B$17+Artifacts!$B$40,Inputs!$B$18+Artifacts!$B$39+IF(Inputs!$B$3>=125,F27*5,0)))/100)*(Summary!$B$13*Summary!$B$14*Summary!$B$15*(1+Artifacts!$B$38/100)*I5) | L5: =K5*(MIN(Inputs!$B$22,Inputs!$B$23)/100+Inputs!$B$23/100)/2 | M5: =L5*(1+(Inputs!$B$10+Artifacts!$B$33)/100) | N5: =L5*(1-MIN((Inputs!$B$9+Artifacts!$B$32),100)/100)+M5*(MIN((Inputs!$B$9+Artifacts!$B$32),100)/100) | O5: =(1-Summary!$B$11)*S5+Summary!$B$11*U5 | P5: =IF(Summary!$B$3=0,0,O5/Summary!$B$3) | Q5: =IFERROR(1/(IF(Inputs!$B$38="pvp",15,MAX(0.1,Skills!E5-IF(Skills!F5=TRUE,Inputs!$B$32,0)))*(1-IF(AND(ArtifactsInput!$M$27,Inputs!$B$4="Chapter Hunt"),CHOOSE(ArtifactsInput!$N$27+1,20,24,28,32,36,40),0)/100)),0) | R5: =IF(AND(Inputs!$B$38<>"pvp",Inputs!$B$43>0),IF(MAX(0,Inputs!$B$43-Summary!$B$22)<=0,0,(INT(MAX(0,Inputs!$B$43-Summary!$B$22)/(IF(Inputs!$B$38="pvp",15,MAX(0.1,Skills!E5-IF(Skills!F5=TRUE,Inputs!$B$32,0)))*(1-IF(AND(ArtifactsInput!$M$27,Inputs!$B$4="Chapter Hunt"),CHOOSE(ArtifactsInput!$N$27+1,20,24,28,32,36,40),0)/100)))+1)),0) | S5: =IF(C5,(H5*N5*IF(AND(Inputs!$B$38<>"pvp",Inputs!$B$43>0),((Skills!G5*((R5-1)*IF(Skills!H5>0,Skills!I5/Skills!H5,1)+IF(Skills!H5>0,MIN(Skills!I5,MAX(0,MAX(0,Inputs!$B$43-Summary!$B$22)-((R5-1)*(IF(Inputs!$B$38="pvp",15,MAX(0.1,Skills!E5-IF(Skills!F5=TRUE,Inputs!$B$32,0)))*(1-IF(AND(ArtifactsInput!$M$27,Inputs!$B$4="Chapter Hunt"),CHOOSE(ArtifactsInput!$N$27+1,20,24,28,32,36,40),0)/100)))))/Skills!H5,1)))/Inputs!$B$43),G5*Q5))*IF(Inputs!$B$38="pvp",1,1+(Inputs!$B$20+Skills!P5+Artifacts!$B$35)/100)*((((5000/(6000+Inputs!$B$42*(1-(100*(1-(1-Inputs!$B$19/100)*(1-Artifacts!$B$51/100)^IF(Inputs!$B$38="pvp",1,2)))/100)))/(5000/(6000+Inputs!$B$42*(1-Inputs!$B$19/100))))*((L5*(1-MIN(100,(Inputs!$B$9+Artifacts!$B$32)+Artifacts!$B$69)/100)+M5*(MIN(100,(Inputs!$B$9+Artifacts!$B$32)+Artifacts!$B$69)/100))/(L5*(1-MIN(100,(Inputs!$B$9+Artifacts!$B$32))/100)+M5*(MIN(100,(Inputs!$B$9+Artifacts!$B$32))/100)))*(1+Artifacts!$B$81/100))),0) | U5: =IF(C5,(H5*N5*IF(AND(Inputs!$B$38<>"pvp",Inputs!$B$43>0),((Skills!G5*((R5-1)*IF(Skills!H5>0,Skills!I5/Skills!H5,1)+IF(Skills!H5>0,MIN(Skills!I5,MAX(0,MAX(0,Inputs!$B$43-Summary!$B$22)-((R5-1)*(IF(Inputs!$B$38="pvp",15,MAX(0.1,Skills!E5-IF(Skills!F5=TRUE,Inputs!$B$32,0)))*(1-IF(AND(ArtifactsInput!$M$27,Inputs!$B$4="Chapter Hunt"),CHOOSE(ArtifactsInput!$N$27+1,20,24,28,32,36,40),0)/100)))))/Skills!H5,1)))/Inputs!$B$43),G5*Q5))*IF(Inputs!$B$38="pvp",1,(1+(Inputs!$B$21+Skills!Q5+Artifacts!$B$80)/100)*(MIN(Skills!R5,Inputs!$B$37)))*((1+Artifacts!$B$53/100)),0)
A6: =Skills!A6 | B6: =Skills!B6 | C6: =TRUE | D6: =IF(Skills!C6=1,60+Inputs!$B$25+Inputs!$B$29,IF(Skills!C6=2,90+Inputs!$B$26+Inputs!$B$29,IF(Skills!C6=3,120+Inputs!$B$27+Inputs!$B$29,MAX(0,(Inputs!$B$3-100)*3)+Inputs!$B$28+Inputs!$B$29))) | E6: =INDEX(FactorTable!$B$2:$Y$301, MATCH(ROUND(MIN(300,MAX(1,D6)),0), FactorTable!$A$2:$A$301,0), Skills!M6+1) | F6: =IF(Skills!N6=TRUE,(Skills!L6/10)*(E6/1000),Skills!L6/10)+Skills!O6 | G6: =Skills!G6*IF(Skills!H6>0,Skills!I6/Skills!H6,1) | H6: =1-(1-Skills!J6/100)^Skills!K6 | I6: =IF(Skills!X6<>"",1+(Skills!X6/10)*($Z$3/1000)/100,1) | O6: =(1-Summary!$B$11)*S6+Summary!$B$11*U6 | P6: =IF(Summary!$B$3=0,0,O6/Summary!$B$3) | Q6: =IFERROR(1/(IF(Inputs!$B$38="pvp",15,MAX(0.1,Skills!E6-IF(Skills!F6=TRUE,Inputs!$B$32,0)))*(1-IF(AND(ArtifactsInput!$M$27,Inputs!$B$4="Chapter Hunt"),CHOOSE(ArtifactsInput!$N$27+1,20,24,28,32,36,40),0)/100)),0) | R6: =IF(AND(Inputs!$B$38<>"pvp",Inputs!$B$43>0),IF(Inputs!$B$43<=0,0,(INT(Inputs!$B$43/(IF(Inputs!$B$38="pvp",15,MAX(0.1,Skills!E6-IF(Skills!F6=TRUE,Inputs!$B$32,0)))*(1-IF(AND(ArtifactsInput!$M$27,Inputs!$B$4="Chapter Hunt"),CHOOSE(ArtifactsInput!$N$27+1,20,24,28,32,36,40),0)/100)))+1)),0) | S6: 0 | U6: 0
A7: =Skills!A7 | B7: =Skills!B7 | C7: =TRUE | D7: =IF(Skills!C7=1,60+Inputs!$B$25+Inputs!$B$29,IF(Skills!C7=2,90+Inputs!$B$26+Inputs!$B$29,IF(Skills!C7=3,120+Inputs!$B$27+Inputs!$B$29,MAX(0,(Inputs!$B$3-100)*3)+Inputs!$B$28+Inputs!$B$29))) | E7: =INDEX(FactorTable!$B$2:$Y$301, MATCH(ROUND(MIN(300,MAX(1,D7)),0), FactorTable!$A$2:$A$301,0), Skills!M7+1) | F7: =IF(Skills!N7=TRUE,(Skills!L7/10)*(E7/1000),Skills!L7/10)+Skills!O7 | G7: =Skills!G7*IF(Skills!H7>0,Skills!I7/Skills!H7,1) | H7: =1-(1-Skills!J7/100)^Skills!K7 | I7: =IF(Skills!X7<>"",1+(Skills!X7/10)*($Z$3/1000)/100,1) | J7: =Summary!$B$6*(F7/100) | K7: =J7*(1+Summary!$B$7/100)*(1+Inputs!$B$15/100)*(1+Inputs!$B$16/100)*(5000/(6000+Inputs!$B$42*(1-Inputs!$B$19/100)))*(1+Inputs!$B$24/100)*(1+Artifacts!$B$34/100)*(1+F23/100)*(1+IF(Inputs!$B$3>=120,F26,0)/100)^5*(1+(IF(Skills!A7="BASIC_ATTACK",Inputs!$B$17+Artifacts!$B$40,Inputs!$B$18+Artifacts!$B$39+IF(Inputs!$B$3>=125,F27*5,0)))/100)*(Summary!$B$13*Summary!$B$14*Summary!$B$15*(1+Artifacts!$B$38/100)*I7) | L7: =K7*(MIN(Inputs!$B$22,Inputs!$B$23)/100+Inputs!$B$23/100)/2 | M7: =L7*(1+(Inputs!$B$10+Artifacts!$B$33)/100) | N7: =L7*(1-MIN((Inputs!$B$9+Artifacts!$B$32),100)/100)+M7*(MIN((Inputs!$B$9+Artifacts!$B$32),100)/100) | O7: =(1-Summary!$B$11)*S7+Summary!$B$11*U7 | P7: =IF(Summary!$B$3=0,0,O7/Summary!$B$3) | Q7: =IFERROR(1/(IF(Inputs!$B$38="pvp",15,MAX(0.1,Skills!E7-IF(Skills!F7=TRUE,Inputs!$B$32,0)))*(1-IF(AND(ArtifactsInput!$M$27,Inputs!$B$4="Chapter Hunt"),CHOOSE(ArtifactsInput!$N$27+1,20,24,28,32,36,40),0)/100)),0) | R7: =IF(AND(Inputs!$B$38<>"pvp",Inputs!$B$43>0),IF(MAX(0,Inputs!$B$43-Summary!$B$22)<=0,0,(INT(MAX(0,Inputs!$B$43-Summary!$B$22)/(IF(Inputs!$B$38="pvp",15,MAX(0.1,Skills!E7-IF(Skills!F7=TRUE,Inputs!$B$32,0)))*(1-IF(AND(ArtifactsInput!$M$27,Inputs!$B$4="Chapter Hunt"),CHOOSE(ArtifactsInput!$N$27+1,20,24,28,32,36,40),0)/100)))+1)),0) | S7: =IF(C7,(H7*N7*IF(AND(Inputs!$B$38<>"pvp",Inputs!$B$43>0),((Skills!G7*((R7-1)*IF(Skills!H7>0,Skills!I7/Skills!H7,1)+IF(Skills!H7>0,MIN(Skills!I7,MAX(0,MAX(0,Inputs!$B$43-Summary!$B$22)-((R7-1)*(IF(Inputs!$B$38="pvp",15,MAX(0.1,Skills!E7-IF(Skills!F7=TRUE,Inputs!$B$32,0)))*(1-IF(AND(ArtifactsInput!$M$27,Inputs!$B$4="Chapter Hunt"),CHOOSE(ArtifactsInput!$N$27+1,20,24,28,32,36,40),0)/100)))))/Skills!H7,1)))/Inputs!$B$43),G7*Q7))*IF(Inputs!$B$38="pvp",1,1+(Inputs!$B$20+Skills!P7+Artifacts!$B$35)/100)*((((5000/(6000+Inputs!$B$42*(1-(100*(1-(1-Inputs!$B$19/100)*(1-Artifacts!$B$51/100)^IF(Inputs!$B$38="pvp",1,2)))/100)))/(5000/(6000+Inputs!$B$42*(1-Inputs!$B$19/100))))*((L7*(1-MIN(100,(Inputs!$B$9+Artifacts!$B$32)+Artifacts!$B$69)/100)+M7*(MIN(100,(Inputs!$B$9+Artifacts!$B$32)+Artifacts!$B$69)/100))/(L7*(1-MIN(100,(Inputs!$B$9+Artifacts!$B$32))/100)+M7*(MIN(100,(Inputs!$B$9+Artifacts!$B$32))/100)))*(1+Artifacts!$B$81/100))),0) | U7: =IF(C7,(H7*N7*IF(AND(Inputs!$B$38<>"pvp",Inputs!$B$43>0),((Skills!G7*((R7-1)*IF(Skills!H7>0,Skills!I7/Skills!H7,1)+IF(Skills!H7>0,MIN(Skills!I7,MAX(0,MAX(0,Inputs!$B$43-Summary!$B$22)-((R7-1)*(IF(Inputs!$B$38="pvp",15,MAX(0.1,Skills!E7-IF(Skills!F7=TRUE,Inputs!$B$32,0)))*(1-IF(AND(ArtifactsInput!$M$27,Inputs!$B$4="Chapter Hunt"),CHOOSE(ArtifactsInput!$N$27+1,20,24,28,32,36,40),0)/100)))))/Skills!H7,1)))/Inputs!$B$43),G7*Q7))*IF(Inputs!$B$38="pvp",1,(1+(Inputs!$B$21+Skills!Q7+Artifacts!$B$80)/100)*(MIN(Skills!R7,Inputs!$B$37)))*((1+Artifacts!$B$53/100)),0)
A8: =Skills!A8 | B8: =Skills!B8 | C8: =TRUE | D8: =IF(Skills!C8=1,60+Inputs!$B$25+Inputs!$B$29,IF(Skills!C8=2,90+Inputs!$B$26+Inputs!$B$29,IF(Skills!C8=3,120+Inputs!$B$27+Inputs!$B$29,MAX(0,(Inputs!$B$3-100)*3)+Inputs!$B$28+Inputs!$B$29))) | E8: =INDEX(FactorTable!$B$2:$Y$301, MATCH(ROUND(MIN(300,MAX(1,D8)),0), FactorTable!$A$2:$A$301,0), Skills!M8+1) | F8: =IF(Skills!N8=TRUE,(Skills!L8/10)*(E8/1000),Skills!L8/10)+Skills!O8 | G8: =Skills!G8*IF(Skills!H8>0,Skills!I8/Skills!H8,1) | H8: =1-(1-Skills!J8/100)^Skills!K8 | I8: =IF(Skills!X8<>"",1+(Skills!X8/10)*($Z$3/1000)/100,1) | J8: =Summary!$B$6*(F8/100) | K8: =J8*(1+Summary!$B$7/100)*(1+Inputs!$B$15/100)*(1+Inputs!$B$16/100)*(5000/(6000+Inputs!$B$42*(1-Inputs!$B$19/100)))*(1+Inputs!$B$24/100)*(1+Artifacts!$B$34/100)*(1+F23/100)*(1+IF(Inputs!$B$3>=120,F26,0)/100)^5*(1+(IF(Skills!A8="BASIC_ATTACK",Inputs!$B$17+Artifacts!$B$40,Inputs!$B$18+Artifacts!$B$39+IF(Inputs!$B$3>=125,F27*5,0)))/100)*(Summary!$B$13*Summary!$B$14*Summary!$B$15*(1+Artifacts!$B$38/100)*I8) | L8: =K8*(MIN(Inputs!$B$22,Inputs!$B$23)/100+Inputs!$B$23/100)/2 | M8: =L8*(1+(Inputs!$B$10+Artifacts!$B$33)/100) | N8: =L8*(1-MIN((Inputs!$B$9+Artifacts!$B$32),100)/100)+M8*(MIN((Inputs!$B$9+Artifacts!$B$32),100)/100) | O8: =(1-Summary!$B$11)*S8+Summary!$B$11*U8 | P8: =IF(Summary!$B$3=0,0,O8/Summary!$B$3) | Q8: =IFERROR(1/(IF(Inputs!$B$38="pvp",15,MAX(0.1,Skills!E8-IF(Skills!F8=TRUE,Inputs!$B$32,0)))*(1-IF(AND(ArtifactsInput!$M$27,Inputs!$B$4="Chapter Hunt"),CHOOSE(ArtifactsInput!$N$27+1,20,24,28,32,36,40),0)/100)),0) | R8: =IF(AND(Inputs!$B$38<>"pvp",Inputs!$B$43>0),IF(MAX(0,Inputs!$B$43-Summary!$B$22)<=0,0,(INT(MAX(0,Inputs!$B$43-Summary!$B$22)/(IF(Inputs!$B$38="pvp",15,MAX(0.1,Skills!E8-IF(Skills!F8=TRUE,Inputs!$B$32,0)))*(1-IF(AND(ArtifactsInput!$M$27,Inputs!$B$4="Chapter Hunt"),CHOOSE(ArtifactsInput!$N$27+1,20,24,28,32,36,40),0)/100)))+1)),0) | S8: =IF(C8,(H8*N8*IF(AND(Inputs!$B$38<>"pvp",Inputs!$B$43>0),((Skills!G8*((R8-1)*IF(Skills!H8>0,Skills!I8/Skills!H8,1)+IF(Skills!H8>0,MIN(Skills!I8,MAX(0,MAX(0,Inputs!$B$43-Summary!$B$22)-((R8-1)*(IF(Inputs!$B$38="pvp",15,MAX(0.1,Skills!E8-IF(Skills!F8=TRUE,Inputs!$B$32,0)))*(1-IF(AND(ArtifactsInput!$M$27,Inputs!$B$4="Chapter Hunt"),CHOOSE(ArtifactsInput!$N$27+1,20,24,28,32,36,40),0)/100)))))/Skills!H8,1)))/Inputs!$B$43),G8*Q8))*IF(Inputs!$B$38="pvp",1,1+(Inputs!$B$20+Skills!P8+Artifacts!$B$35)/100)*((((5000/(6000+Inputs!$B$42*(1-(100*(1-(1-Inputs!$B$19/100)*(1-Artifacts!$B$51/100)^IF(Inputs!$B$38="pvp",1,2)))/100)))/(5000/(6000+Inputs!$B$42*(1-Inputs!$B$19/100))))*((L8*(1-MIN(100,(Inputs!$B$9+Artifacts!$B$32)+Artifacts!$B$69)/100)+M8*(MIN(100,(Inputs!$B$9+Artifacts!$B$32)+Artifacts!$B$69)/100))/(L8*(1-MIN(100,(Inputs!$B$9+Artifacts!$B$32))/100)+M8*(MIN(100,(Inputs!$B$9+Artifacts!$B$32))/100)))*(1+Artifacts!$B$81/100))),0) | U8: =IF(C8,(H8*N8*IF(AND(Inputs!$B$38<>"pvp",Inputs!$B$43>0),((Skills!G8*((R8-1)*IF(Skills!H8>0,Skills!I8/Skills!H8,1)+IF(Skills!H8>0,MIN(Skills!I8,MAX(0,MAX(0,Inputs!$B$43-Summary!$B$22)-((R8-1)*(IF(Inputs!$B$38="pvp",15,MAX(0.1,Skills!E8-IF(Skills!F8=TRUE,Inputs!$B$32,0)))*(1-IF(AND(ArtifactsInput!$M$27,Inputs!$B$4="Chapter Hunt"),CHOOSE(ArtifactsInput!$N$27+1,20,24,28,32,36,40),0)/100)))))/Skills!H8,1)))/Inputs!$B$43),G8*Q8))*IF(Inputs!$B$38="pvp",1,(1+(Inputs!$B$21+Skills!Q8+Artifacts!$B$80)/100)*(MIN(Skills!R8,Inputs!$B$37)))*((1+Artifacts!$B$53/100)),0)
